File: Manufatura Aditiva/Dados/Ensaios AMR/Ensaios/Ensaios PP/Tracao_OLABI_22_05_2018_Polipropileno_Taxa_50mm.is_metal_RawData/Specimen_RawData_2.csv
Time,Extension,Load,Strain 1,Tensile strain,Tensile stress
(sec),(mm),(N),(mm/mm),(%),(MPa)
0.00000,0.00006,12.00072,0.00082,0.08153,0.56501
0.10000,0.02415,18.48454,0.00102,0.10209,0.87027
0.20000,0.07157,39.94533,0.00173,0.17272,1.88067
0.30000,0.11922,61.41968,0.00247,0.24655,2.89170
0.40000,0.16418,80.83704,0.00317,0.31688,3.80589
0.50000,0.20741,99.23155,0.00385,0.38456,4.67192
0.60000,0.24962,116.02548,0.00450,0.45005,5.46259
0.70000,0.29171,131.97490,0.00514,0.51417,6.21351
0.80000,0.33345,148.28249,0.00579,0.57864,6.98129
0.90000,0.37506,163.52672,0.00643,0.64314,7.69900
1.00000,0.41673,178.45328,0.00709,0.70878,8.40176
1.10000,0.45835,192.72459,0.00774,0.77410,9.07366
1.20000,0.50002,207.16696,0.00841,0.84148,9.75362
1.30000,0.54169,219.34239,0.00909,0.90850,10.32685
1.40000,0.58343,232.91556,0.00976,0.97630,10.96589
1.50000,0.62492,245.68120,0.01045,1.04526,11.56691
1.60000,0.66659,258.15580,0.01115,1.11477,12.15423
1.70000,0.70833,269.48510,0.01185,1.18473,12.68762
1.80000,0.75006,279.95836,0.01257,1.25713,13.18071
1.90000,0.79167,290.95376,0.01329,1.32918,13.69839
2.00000,0.83341,300.71682,0.01403,1.40319,14.15804
2.10000,0.87502,310.58989,0.01478,1.47777,14.62288
2.20000,0.91669,318.40499,0.01553,1.55271,14.99082
2.30000,0.95831,327.37197,0.01629,1.62897,15.41299
2.40000,0.99998,335.27892,0.01706,1.70565,15.78526
2.50000,1.04159,343.37158,0.01783,1.78346,16.16627
2.60000,1.08339,351.10088,0.01861,1.86146,16.53017
2.70000,1.12500,358.28934,0.01940,1.93961,16.86861
2.80000,1.16673,364.03772,0.02019,2.01874,17.13925
2.90000,1.20847,370.80988,0.02099,2.09928,17.45809
3.00000,1.25002,377.89787,0.02181,2.18060,17.79180
3.10000,1.29163,382.98063,0.02261,2.26106,18.03110
3.20000,1.33331,388.90056,0.02342,2.34163,18.30982
3.30000,1.37492,395.13316,0.02423,2.42338,18.60326
3.40000,1.41671,400.35252,0.02506,2.50597,18.84899
3.50000,1.45833,405.22786,0.02589,2.58913,19.07852
3.60000,1.50000,410.58334,0.02672,2.67170,19.33067
3.70000,1.54161,415.46957,0.02755,2.75517,19.56071
3.80000,1.58323,420.30010,0.02840,2.83952,19.78814
3.90000,1.62490,425.22615,0.02925,2.92475,20.02006
4.00000,1.66675,428.90110,0.03010,3.01043,20.19308
4.10000,1.70842,434.09080,0.03098,3.09751,20.43742
4.20000,1.75004,437.43807,0.03184,3.18425,20.59501
4.30000,1.79165,441.16396,0.03273,3.27295,20.77043
4.40000,1.83344,445.62668,0.03363,3.36284,20.98054
4.50000,1.87512,448.36220,0.03454,3.52953,21.10933
4.60000,1.91661,452.19790,0.03546,3.69551,21.28992
4.70000,1.95817,455.32701,0.03640,3.86172,21.43724
4.70800,1.96145,455.40482,0.03647,3.87488,21.44090
4.80800,2.00331,458.00731,0.03743,4.04229,21.56343
4.90800,2.04492,460.62418,0.03840,4.20874,21.68664
5.00800,2.08677,462.52715,0.03940,4.37615,21.77623
5.10800,2.12833,463.99171,0.04042,4.54237,21.84518
5.20800,2.17006,465.74501,0.04147,4.70930,21.92773
5.30800,2.21161,466.49571,0.04254,4.87551,21.96307
5.40800,2.25341,467.53404,0.04363,5.04269,22.01196
5.50800,2.29502,468.07639,0.04475,5.20914,22.03749
5.60800,2.33675,468.32147,0.04590,5.37607,22.04903
5.70800,2.37849,468.90038,0.04709,5.54300,22.07629
5.80800,2.42004,468.70308,0.04829,5.70922,22.06700
5.90800,2.46159,468.27295,0.04952,5.87543,22.04675
6.00800,2.50327,467.57553,0.05077,6.04213,22.01391
6.10800,2.54494,466.77440,0.05204,6.20882,21.97620
6.20800,2.58661,465.76425,0.05334,6.37551,21.92864
6.30800,2.62835,464.55381,0.05465,6.54244,21.87165
6.40800,2.66996,464.06989,0.05596,6.70890,21.84887
6.50800,2.71175,462.52077,0.05755,6.87607,21.77593
6.60800,2.75343,462.02042,0.05826,7.04276,21.75237
6.70800,2.79510,460.33049,0.06108,7.20946,21.67281
6.80800,2.83671,459.04275,0.02633,7.37591,21.61218
6.90800,2.87827,458.87339,0.00897,7.54213,21.60421
7.00800,2.91994,457.00539,0.00359,7.70882,21.51626
7.10800,2.96167,456.11658,0.00378,7.87575,21.47441
7.20800,3.00352,455.14670,0.00391,8.04316,21.42875
7.30800,3.04496,453.76862,0.00413,8.20890,21.36387
7.40800,3.08651,453.15167,0.00142,8.37511,21.33482
7.50800,3.12825,452.72699,0.00472,8.54205,21.31483
7.60800,3.16998,452.10076,0.00467,8.70898,21.28535
7.70800,3.21165,450.74304,0.00666,8.87567,21.22142
7.80800,3.25333,450.26955,0.00588,9.04236,21.19913
7.90800,3.29494,448.94931,0.00877,9.20882,21.13697
8.00800,3.33661,448.99117,0.01352,9.37551,21.13894
8.10800,3.37835,447.59610,0.16933,9.54244,21.07326
8.20800,3.42002,446.98422,0.02099,9.70914,21.04445
8.30800,3.46169,447.27591,0.01692,9.87583,21.05819
8.40800,3.50331,446.01709,0.02557,10.04228,20.99892
8.50800,3.54504,445.45946,0.01049,10.20922,20.97267
8.60800,3.58665,444.73335,0.01676,10.37567,20.93848
8.70800,3.62833,444.57004,0.01313,10.54236,20.93079
8.80800,3.67006,443.65204,-0.02598,10.70929,20.88757
8.90800,3.71173,442.85115,-0.12935,10.87599,20.84986
9.00800,3.75329,442.61003,-0.13855,11.04220,20.83851
9.10800,3.79502,442.45292,-0.13872,11.20913,20.83112
9.20800,3.83657,442.20076,-0.13873,11.37535,20.81924
9.30800,3.87831,440.94916,-0.13874,11.54228,20.76032
9.40800,3.91998,440.90827,-0.13875,11.70897,20.75839
9.50800,3.96165,439.88870,-0.13875,11.87567,20.71039
9.60800,4.00338,439.87199,-0.13875,12.04260,20.70960
9.70800,4.04500,439.44675,-0.13875,12.20905,20.68958
9.80800,4.08673,439.19189,-0.13876,12.37599,20.67758
9.90800,4.12840,438.80395,-0.13876,12.54268,20.65932
10.00800,4.17002,438.89787,-0.13876,12.70913,20.66374
10.10800,4.21163,437.89423,-0.13876,12.87559,20.61649
10.20800,4.25336,437.57232,-0.13876,13.04252,20.60133
10.30800,4.29504,436.88160,-0.13876,13.20921,20.56881
10.40800,4.33671,436.94619,-0.13877,13.37591,20.57185
10.50800,4.37815,435.96299,-0.13877,13.54164,20.52556
10.60800,4.41994,436.34945,-0.13877,13.70881,20.54376
10.70800,4.46155,436.37808,-0.13877,13.87527,20.54511
10.80800,4.50346,435.41784,-0.13877,14.04292,20.49990
10.90800,4.54508,434.73933,-0.13878,14.20937,20.46795
11.00800,4.58675,434.71148,-0.13877,14.37606,20.46664
11.10800,4.62830,434.75749,-0.13878,14.54228,20.46881
11.20800,4.67016,434.29993,-0.13878,14.70969,20.44727
11.30800,4.71183,433.93276,-0.13878,14.87638,20.42998
11.40800,4.75332,433.56442,-0.13878,15.04236,20.41264
11.50800,4.79494,433.65173,-0.13878,15.20881,20.41675
11.60800,4.83661,433.29494,-0.13878,15.37551,20.39995
11.70800,4.87828,432.52627,-0.13878,15.54220,20.36376
11.80800,4.92002,432.88660,-0.13878,15.70913,20.38073
11.90800,4.96163,432.33959,-0.13878,15.87559,20.35497
12.00800,5.00336,431.99416,-0.13878,16.04252,20.33871
12.10800,5.04498,431.11565,-0.13878,16.20897,20.29735
12.20800,5.08665,431.44026,-0.13878,16.37566,20.31263
12.30800,5.12838,431.26596,-0.13879,16.54260,20.30442
12.40800,5.17000,431.35076,-0.13878,16.70905,20.30842
12.50800,5.21161,430.53082,-0.13879,16.87550,20.26981
12.60800,5.25322,430.67755,-0.13879,17.04196,20.27672
12.70800,5.29502,429.98912,-0.13879,17.20913,20.24431
12.80800,5.33663,430.07894,-0.13879,17.37558,20.24854
12.90800,5.37830,429.24946,-0.13879,17.54228,20.20948
13.00800,5.42004,429.75964,-0.13879,17.70921,20.23351
13.10800,5.46165,429.48104,-0.13879,17.87566,20.22039
13.20800,5.50332,428.47311,-0.13879,18.04236,20.17293
13.30800,5.54500,428.70399,-0.13879,18.20905,20.18380
13.40800,5.58673,428.28606,-0.13878,18.37598,20.16413
13.50800,5.62834,428.43353,-0.13879,18.54244,20.17107
13.60800,5.67002,427.98040,-0.13879,18.70913,20.14974
13.70800,5.71157,427.78100,-0.13879,18.87534,20.14035
13.80800,5.75324,427.63841,-0.13879,19.04203,20.13363
13.90800,5.79498,427.77024,-0.13879,19.20897,20.13984
14.00800,5.83671,427.25229,-0.13879,19.37590,20.11546
14.10800,5.87844,427.27026,-0.13879,19.54283,20.11630
14.20800,5.92000,426.96134,-0.13879,19.70905,20.10176
14.30800,5.96179,426.09568,-0.13879,19.87622,20.06100
14.40800,6.00340,426.90546,-0.13879,20.04267,20.09913
14.50800,6.04508,426.20320,-0.13879,20.20937,20.06606
14.60800,6.08663,426.40134,-0.13880,20.37558,20.07539
14.70800,6.12836,425.88832,-0.13879,20.54251,20.05124
14.80800,6.16992,425.65954,-0.13879,20.70873,20.04047
14.90800,6.21177,425.19998,-0.13879,20.87614,20.01883
15.00800,6.25326,425.22205,-0.13879,21.04211,20.01987
15.10800,6.29506,425.00086,-0.13879,21.20929,20.00946
15.20800,6.33661,424.60011,-0.13879,21.37550,19.99059
15.30800,6.37834,424.93409,-0.13879,21.54243,20.00631
15.40800,6.42008,424.47364,-0.13879,21.70937,19.98463
15.50800,6.46181,424.26405,-0.13879,21.87630,19.97477
15.60800,6.50336,423.95326,-0.13880,22.04251,19.96013
15.70800,6.54510,424.19252,-0.13879,22.20944,19.97140
15.80800,6.58677,423.67410,-0.13879,22.37614,19.94699
15.90800,6.62832,423.63028,-0.13879,22.54235,19.94493
16.00800,6.66988,423.49519,-0.13879,22.70857,19.93857
16.10800,6.71155,423.63917,-0.13879,22.87526,19.94535
16.20800,6.75328,422.77407,-0.13879,23.04219,19.90462
16.30800,6.79490,422.81500,-0.13879,23.20865,19.90654
16.40800,6.83669,422.50827,-0.13880,23.37582,19.89210
16.50800,6.87830,422.91922,-0.13879,23.54227,19.91145
16.60800,6.92010,421.99399,-0.13880,23.70944,19.86789
16.70800,6.96165,422.38082,-0.13880,23.87566,19.88610
16.80800,7.00338,422.21597,-0.13880,24.04259,19.87834
16.90800,7.04500,421.59762,-0.13880,24.20904,19.84923
17.00800,7.08673,421.63543,-0.13879,24.37598,19.85101
17.10800,7.12834,420.86295,-0.13880,24.54243,19.81464
17.20800,7.17002,421.22710,-0.13880,24.70912,19.83178
17.30800,7.21157,421.27324,-0.13879,24.87534,19.83396
17.40800,7.25324,421.14030,-0.13879,25.04203,19.82770
17.50800,7.29498,420.50071,-0.13879,25.20896,19.79758
17.60800,7.33665,420.70546,-0.13879,25.37566,19.80722
17.70800,7.37832,420.80875,-0.13880,25.54235,19.81209
17.80800,7.42006,420.47873,-0.13880,25.70928,19.79655
17.90800,7.46167,419.67770,-0.13880,25.87574,19.75884
18.00800,7.50340,419.55891,-0.13879,26.04267,19.75324
18.10800,7.54507,419.83379,-0.13880,26.20936,19.76619
18.20800,7.58675,419.81847,-0.13880,26.37606,19.76546
18.30800,7.62836,419.19267,-0.13879,26.54251,19.73600
18.40800,7.66992,419.08496,-0.13880,26.70873,19.73093
18.50800,7.71177,418.61776,-0.13880,26.87613,19.70893
18.60800,7.75338,418.31317,-0.13880,27.04259,19.69459
18.70800,7.79500,418.81269,-0.13879,27.20904,19.71811
18.80800,7.83667,418.41627,-0.13880,27.37573,19.69945
18.90800,7.87834,418.20914,-0.13880,27.54243,19.68970
19.00800,7.91995,418.08463,-0.13880,27.70888,19.68383
19.10800,7.96157,418.27061,-0.13879,27.87534,19.69259
19.20800,8.00330,417.34236,-0.13880,28.04227,19.64889
19.30800,8.04498,417.68099,-0.13880,28.20896,19.66483
19.40800,8.08665,417.20616,-0.13880,28.37565,19.64248
19.50800,8.12832,417.34027,-0.13879,28.54235,19.64879
19.60800,8.16999,417.32183,-0.13880,28.70904,19.64792
19.70800,8.21161,417.15978,-0.13879,28.87549,19.64029
19.80800,8.25328,416.39307,-0.13880,29.04218,19.60419
19.90800,8.29507,416.28000,-0.13880,29.20936,19.59887
20.00800,8.33675,416.25248,-0.13880,29.37605,19.59757
20.10800,8.37842,416.26878,-0.13880,29.54275,19.59834
20.20800,8.42003,416.19670,-0.13880,29.70920,19.59495
20.30800,8.46177,414.94477,-0.13880,29.87613,19.53601
20.40800,8.50338,415.15143,-0.13880,30.04259,19.54574
20.50800,8.54494,415.37234,-0.13880,30.20880,19.55614
20.60800,8.58655,416.00261,-0.13880,30.37525,19.58581
20.70800,8.62834,415.59399,-0.13880,30.54242,19.56657
20.80800,8.67001,415.25220,-0.13880,30.70912,19.55048
20.90800,8.71175,415.27753,-0.13880,30.87605,19.55167
21.00800,8.75318,414.67920,-0.13880,31.04179,19.52350
21.10800,8.79497,414.09996,-0.13880,31.20896,19.49623
21.20800,8.83659,414.77764,-0.13880,31.37541,19.52814
21.30800,8.87838,413.86653,-0.13880,31.54259,19.48524
21.40800,8.91999,413.68390,-0.13880,31.70904,19.47664
21.50800,8.96173,413.73731,-0.13880,31.87597,19.47916
21.60800,9.00340,413.84473,-0.13880,32.04266,19.48421
21.70800,9.04501,413.18247,-0.13880,32.20912,19.45304
21.80800,9.08657,412.92799,-0.13880,32.37533,19.44105
21.90800,9.12830,413.17544,-0.13880,32.54226,19.45270
22.00800,9.16991,413.14946,-0.13880,32.70872,19.45148
22.10800,9.21159,413.10140,-0.13880,32.87541,19.44922
22.20800,9.25338,412.68584,-0.13880,33.04258,19.42965
22.30800,9.29505,412.83648,-0.13880,33.20928,19.43675
22.40800,9.33673,411.66777,-0.13880,33.37597,19.38172
22.50800,9.37840,412.21930,-0.13880,33.54266,19.40769
22.60800,9.42001,412.02730,-0.13880,33.70912,19.39865
22.70800,9.46169,411.83713,-0.13880,33.87581,19.38970
22.80800,9.50336,412.29036,-0.13880,34.04250,19.41103
22.90800,9.54497,412.08356,-0.13880,34.20895,19.40130
23.00800,9.58671,411.02003,-0.13880,34.37589,19.35122
23.10800,9.62832,410.87228,-0.13880,34.54234,19.34427
23.20800,9.66993,411.29957,-0.13880,34.70879,19.36439
23.30800,9.71155,410.80411,-0.13880,34.87525,19.34106
23.40800,9.75334,411.08355,-0.13880,35.04242,19.35422
23.50800,9.79501,410.41230,-0.13880,35.20912,19.32261
23.60800,9.83669,410.59083,-0.13880,35.37581,19.33102
23.70800,9.87830,410.59060,-0.13880,35.54226,19.33101
23.80800,9.92003,409.48517,-0.13880,35.70920,19.27896
23.90800,9.96171,409.76619,-0.13880,35.87589,19.29219
24.00800,10.00344,409.81630,-0.13880,36.04282,19.29455
24.10800,10.04505,409.34836,-0.13880,36.20927,19.27252
24.20800,10.08667,409.78789,-0.13880,36.37573,19.29321
24.30800,10.12840,408.90737,-0.13880,36.54266,19.25176
24.40800,10.17001,408.58947,-0.13880,36.70911,19.23679
24.50800,10.21163,408.55026,-0.13880,36.87557,19.23495
24.60800,10.25336,407.95510,-0.13880,37.04250,19.20693
24.70800,10.29497,408.01601,-0.13880,37.20895,19.20979
24.80800,10.33665,407.47575,-0.13880,37.37565,19.18436
24.90800,10.37826,408.07268,-0.13880,37.54210,19.21246
25.00800,10.42005,407.70024,-0.13880,37.70927,19.19493
25.10800,10.46155,407.86164,-0.13880,37.87525,19.20253
25.20800,10.50328,407.07667,-0.13880,38.04218,19.16557
25.30800,10.54489,407.06513,-0.13880,38.20863,19.16502
25.40800,10.58669,406.80249,-0.13880,38.37580,19.15266
25.50800,10.62836,406.55788,-0.13880,38.54250,19.14114
25.60800,10.67003,406.35066,-0.13880,38.70919,19.13139
25.70800,10.71171,406.16454,-0.13880,38.87588,19.12262
25.80800,10.75344,405.64681,-0.13880,39.04281,19.09825
25.90800,10.79493,405.57152,-0.13880,39.20879,19.09470
26.00800,10.83661,405.40523,-0.13880,39.37548,19.08688
26.10800,10.87834,405.57701,-0.13880,39.54242,19.09496
26.20800,10.92001,404.55363,-0.13880,39.70911,19.04678
26.30800,10.96157,404.67968,-0.13880,39.87532,19.05272
26.40800,11.00330,404.40653,-0.13880,40.04226,19.03986
26.50800,11.04491,404.20969,-0.13880,40.20871,19.03059
26.60800,11.08665,403.79087,-0.13880,40.37564,19.01087
26.70800,11.12838,403.38580,-0.13880,40.54258,18.99180
26.80800,11.16993,402.62169,-0.13880,40.70879,18.95582
26.90800,11.21173,403.23427,-0.13880,40.87597,18.98466
27.00800,11.25328,402.22663,-0.13880,41.04218,18.93722
27.10800,11.29513,401.85601,-0.13880,41.20959,18.91978
27.20800,11.33668,402.02583,-0.13880,41.37580,18.92777
27.30800,11.37842,401.49665,-0.13881,41.54274,18.90285
27.40800,11.41991,401.13879,-0.13880,41.70871,18.88601
27.50800,11.46171,400.80016,-0.13880,41.87588,18.87006
27.60800,11.50332,400.07872,-0.13880,42.04234,18.83610
27.70800,11.54499,399.53915,-0.13880,42.20903,18.81069
27.80800,11.58655,399.54064,-0.13880,42.37524,18.81076
27.90800,11.62828,398.74949,-0.13880,42.54218,18.77352
28.00800,11.66995,397.87376,-0.13880,42.70887,18.73229
28.10800,11.71175,397.56130,-0.13880,42.87604,18.71758
28.20800,11.75330,397.35399,-0.13880,43.04226,18.70782
28.30800,11.79497,396.40865,-0.13880,43.20895,18.66331
28.40800,11.83658,395.67961,-0.13880,43.37540,18.62898
28.50800,11.87838,394.89097,-0.13880,43.54257,18.59185
28.60800,11.92005,394.48868,-0.13880,43.70927,18.57291
28.70800,11.96167,393.18274,-0.13880,43.87572,18.51143
28.80800,12.00334,392.51009,-0.13880,44.04241,18.47976
28.90800,12.04501,392.13770,-0.13880,44.20911,18.46223
29.00800,12.08668,390.85690,-0.13880,44.37580,18.40193
29.10800,12.12830,390.52253,-0.13880,44.54225,18.38618
29.20800,12.17009,388.79775,-0.13880,44.70942,18.30498
29.30800,12.21170,387.89250,-0.13880,44.87588,18.26236
29.40800,12.25338,386.75854,-0.13880,45.04257,18.20897
29.50800,12.29499,385.77639,-0.13880,45.20903,18.16273
29.60800,12.33655,384.61557,-0.13880,45.37524,18.10808
29.70800,12.37828,383.87026,-0.13880,45.54217,18.07299
29.80800,12.41995,382.17588,-0.13881,45.70887,17.99322
29.90800,12.46168,380.78150,-0.13880,45.87580,17.92757
30.00800,12.50330,380.03675,-0.13880,46.04225,17.89250
30.10800,12.54503,377.80225,-0.13880,46.20919,17.78730
30.20800,12.58670,376.43851,-0.13880,46.37588,17.72309
30.30800,12.62838,375.37336,-0.13880,46.54257,17.67295
30.40800,12.66999,373.36061,-0.13880,46.70903,17.57818
30.50800,12.71160,371.56290,-0.13880,46.87548,17.49355
30.60800,12.75328,369.50544,-0.13880,47.04217,17.39668
30.70800,12.79495,367.74871,-0.13881,47.20887,17.31397
30.80800,12.83674,365.91275,-0.13881,47.37604,17.22753
30.90800,12.87830,364.59179,-0.13881,47.54225,17.16534
31.00800,12.92009,362.48534,-0.13881,47.70942,17.06617
31.10800,12.96158,360.00439,-0.13881,47.87540,16.94936
31.20800,13.00332,357.39550,-0.13881,48.04233,16.82653
31.30800,13.04499,355.02815,-0.13881,48.20903,16.71507
31.40800,13.08678,352.61572,-0.13881,48.37619,16.60149
31.50800,13.12834,349.37984,-0.13880,48.54241,16.44914
31.60800,13.17013,346.92332,-0.13880,48.70958,16.33349
31.70800,13.21162,343.97028,-0.13881,48.87556,16.19446
31.80800,13.25330,340.36662,-0.13881,49.04225,16.02479
31.90800,13.29485,337.55179,-0.13881,49.20847,15.89227
32.00800,13.33664,334.58571,-0.13881,49.37564,15.75262
32.10800,13.37826,330.48603,-0.13880,49.54209,15.55961
32.20800,13.41993,326.79983,-0.13881,49.70878,15.38606
32.30800,13.46166,321.94920,-0.13881,49.87572,15.15768
32.40800,13.50340,316.77450,-0.13881,50.04265,14.91405
32.50800,13.54501,311.28251,-0.13881,50.20911,14.65549
32.60800,13.58662,305.22966,-0.13880,50.37556,14.37051
32.70800,13.62842,299.77472,-0.13881,50.54272,14.11369
32.80800,13.67009,293.82543,-0.13880,50.70942,13.83359
32.90800,13.71182,288.79982,-0.13880,50.87635,13.59698
33.00800,13.75338,283.05594,-0.13880,51.04256,13.32655
33.10800,13.79499,277.33734,-0.13881,51.20902,13.05731
33.20800,13.83654,272.55993,-0.13881,51.37523,12.83239
33.30800,13.87834,267.42248,-0.13881,51.54241,12.59051
33.40800,13.91989,262.56146,-0.13881,51.70863,12.36165
33.50800,13.96168,257.63919,-0.13881,51.87579,12.12991
33.60800,14.00330,252.54944,-0.13881,52.04225,11.89028
33.70800,14.04503,248.43474,-0.13880,52.20918,11.69655
33.80800,14.08664,243.02811,-0.13880,52.37564,11.44200
33.90800,14.12844,237.66581,-0.13881,52.54281,11.18954
34.00800,14.17005,233.64313,-0.13881,52.70926,11.00015
34.10800,14.21178,228.70745,-0.13881,52.87619,10.76777
34.20800,14.25322,223.94771,-0.13881,53.04193,10.54368
34.30800,14.29495,219.63317,-0.13881,53.20886,10.34054
34.40800,14.33674,214.61002,-0.13881,53.37603,10.10405
34.50800,14.37830,209.58544,-0.13881,53.54225,9.86749
34.60800,14.42003,204.27543,-0.13881,53.70918,9.61749
34.70800,14.46164,199.26012,-0.13881,53.87564,9.38136
34.80800,14.50332,193.59958,-0.13881,54.04233,9.11486
34.90800,14.54499,187.54362,-0.13881,54.20902,8.82974
35.00800,14.58672,181.13537,-0.13881,54.37595,8.52803
35.10800,14.62834,175.58584,-0.13881,54.54240,8.26675
35.20800,14.67007,168.80922,-0.13881,54.70934,7.94770
35.30800,14.71168,163.41447,-0.13881,54.87580,7.69371
35.40800,14.75330,158.27869,-0.13881,55.04225,7.45192
35.50800,14.79509,153.67453,-0.13881,55.20942,7.23515
35.60800,14.83664,149.15463,-0.13881,55.37563,7.02235
35.70800,14.87832,144.91739,-0.13881,55.54233,6.82285
35.80800,14.91999,141.46006,-0.13881,55.70902,6.66008
35.90800,14.96178,138.32854,-0.13881,55.87619,6.51264
36.00800,15.00340,135.22747,-0.13880,56.04265,6.36664
36.10800,15.04507,131.99209,-0.13881,56.20934,6.21432
36.20800,15.08668,130.14135,-0.13881,56.37580,6.12718
36.30800,15.12830,127.48762,-0.13881,56.54225,6.00224
36.40800,15.16991,124.93246,-0.13881,56.70870,5.88194
36.50800,15.21158,123.79902,-0.13881,56.87539,5.82858
36.60800,15.25332,121.60601,-0.13881,57.04232,5.72533
36.70800,15.29499,120.15705,-0.13881,57.20902,5.65711
36.80800,15.33666,119.22690,-0.13881,57.37571,5.61332
36.90800,15.37828,117.73029,-0.13881,57.54217,5.54286
37.00800,15.42001,116.51919,-0.13881,57.70910,5.48584
37.10800,15.46168,115.08545,-0.13881,57.87579,5.41834
37.20800,15.50341,114.40311,-0.13881,58.04272,5.38621
37.30800,15.54497,113.44856,-0.13881,58.20894,5.34127
37.40800,15.58664,112.74763,-0.13881,58.37563,5.30827
37.50800,15.62832,111.53670,-0.13881,58.54232,5.25126
37.60800,15.67005,110.68591,-0.13881,58.70925,5.21120
37.70800,15.71160,110.11958,-0.13881,58.87547,5.18454
37.80800,15.75327,109.36515,-0.13881,59.04216,5.14902
37.90800,15.79489,109.07281,-0.13881,59.20861,5.13525
38.00800,15.83668,107.95773,-0.13881,59.37578,5.08276
38.10800,15.87835,107.54470,-0.13881,59.54248,5.06331
38.20800,15.92009,107.35408,-0.13881,59.70941,5.05434
38.30800,15.96176,106.44988,-0.13881,59.87610,5.01176
38.40800,16.00332,106.34816,-0.13881,60.04232,5.00698
38.50800,16.04505,106.25416,-0.13880,60.20925,5.00255
38.60800,16.08678,105.09447,-0.13881,60.37619,4.94795
38.70800,16.12840,105.11612,-0.13881,60.54264,4.94897
38.80800,16.16989,104.19127,-0.13881,60.70862,4.90543
38.90800,16.21162,104.00995,-0.13881,60.87555,4.89689
39.00800,16.25329,103.63730,-0.13881,61.04224,4.87935
39.10800,16.29497,104.02605,-0.13881,61.20893,4.89765
39.20800,16.33658,103.28796,-0.13881,61.37539,4.86290
39.30800,16.37838,102.57614,-0.13881,61.54256,4.82938
39.40800,16.41993,102.78034,-0.13881,61.70877,4.83900
39.50800,16.46166,102.69133,-0.13881,61.87571,4.83481
39.60800,16.50333,102.51546,-0.13881,62.04240,4.82653
39.70800,16.54507,102.56395,-0.13881,62.20933,4.82881
39.80800,16.58668,102.03805,-0.13881,62.37578,4.80405
39.90800,16.62841,101.88948,-0.13881,62.54272,4.79706
40.00800,16.66997,102.05359,-0.13881,62.70894,4.80478
40.10800,16.71164,101.10157,-0.13881,62.87563,4.75996
40.20800,16.75349,101.54459,-0.13881,63.04303,4.78082
40.30800,16.79499,101.23957,-0.13881,63.20901,4.76646
40.40800,16.83654,101.51502,-0.13881,63.37523,4.77943
40.50800,16.87833,101.09871,-0.13881,63.54240,4.75983
40.60800,16.91995,101.09815,-0.13881,63.70885,4.75980
40.70800,16.96168,100.54628,-0.13881,63.87578,4.73382
40.80800,17.00335,100.30189,-0.13881,64.04248,4.72231
40.90800,17.04503,100.88714,-0.13881,64.20917,4.74987
41.00800,17.08658,100.35890,-0.13881,64.37538,4.72500
41.10800,17.12819,100.54912,-0.13881,64.54184,4.73395
41.20800,17.16999,100.54242,-0.13881,64.70901,4.73364
41.30800,17.21178,100.63153,-0.13881,64.87619,4.73783
41.40800,17.25345,100.44720,-0.13880,65.04287,4.72915
41.50800,17.29501,100.79886,-0.13881,65.20909,4.74571
41.60800,17.33668,100.36646,-0.13881,65.37578,4.72535
41.70800,17.37835,100.52419,-0.13881,65.54247,4.73278
41.80800,17.41997,100.08792,-0.13881,65.70892,4.71224
41.90800,17.46170,100.43083,-0.13881,65.87586,4.72838
42.00800,17.50331,100.45227,-0.13881,66.04232,4.72939
42.10800,17.54499,100.52602,-0.13881,66.20901,4.73286
42.20800,17.58666,100.33513,-0.13881,66.37570,4.72388
42.30800,17.62833,99.55956,-0.13881,66.54239,4.68736
42.40800,17.66995,100.38491,-0.13881,66.70884,4.72622
42.50800,17.71162,99.77529,-0.13881,66.87555,4.69752
42.60800,17.75329,99.99652,-0.13881,67.04224,4.70793
42.70800,17.79503,98.86461,-0.13881,67.20917,4.65464
42.80800,17.83670,100.06606,-0.13881,67.37586,4.71121
42.90800,17.87843,99.40834,-0.13881,67.54279,4.68024
43.00800,17.92017,99.38906,-0.13881,67.70973,4.67933
43.10800,17.96160,99.41485,-0.13881,67.87547,4.68055
43.20800,18.00327,98.63793,-0.13881,68.04216,4.64397
43.30800,18.04483,98.81197,-0.13881,68.20837,4.65216
43.40800,18.08662,98.60011,-0.13880,68.37554,4.64219
43.50800,18.12823,98.26922,-0.13880,68.54200,4.62661
43.60800,18.17003,97.52642,-0.13880,68.70916,4.59164
43.70800,18.21158,97.69540,-0.13880,68.87538,4.59960
43.80800,18.25337,97.50800,-0.13880,69.04255,4.59077
43.90800,18.29499,98.18628,-0.13880,69.20901,4.62271
44.00800,18.33678,97.56128,-0.13880,69.37618,4.59328
44.10800,18.37833,97.09985,-0.13880,69.54239,4.57156
44.20800,18.42001,96.99549,-0.13880,69.70908,4.56664
44.30800,18.46162,96.61680,-0.13880,69.87554,4.54881
44.40800,18.50335,95.97197,-0.13880,70.04247,4.51845
44.50800,18.54509,96.04912,-0.13880,70.20940,4.52209
44.60800,18.58664,95.59641,-0.13880,70.37562,4.50077
44.70800,18.62825,95.51113,-0.13880,70.54207,4.49676
44.80800,18.66987,94.79949,-0.13880,70.70853,4.46325
44.90800,18.71166,94.86022,-0.13880,70.87570,4.46611
45.00800,18.75327,93.98399,-0.13880,71.04216,4.42486
45.10800,18.79507,93.81783,-0.13880,71.20932,4.41704
45.20800,18.83662,92.85499,-0.13880,71.37554,4.37170
45.30800,18.87835,92.82287,-0.13880,71.54247,4.37019
45.40800,18.92003,91.22764,-0.13880,71.70916,4.29509
45.50800,18.96164,90.76029,-0.13880,71.87561,4.27308
45.60800,19.00325,89.46419,-0.13880,72.04208,4.21206
45.70800,19.04505,88.11293,-0.13880,72.20924,4.14844
45.80800,19.08666,87.64135,-0.13880,72.37570,4.12624
45.90800,19.12833,86.20298,-0.13880,72.54239,4.05852
46.00800,19.17006,84.68385,-0.13880,72.70932,3.98700
46.10800,19.21174,82.68662,-0.13880,72.87602,3.89297
46.20800,19.25335,80.78852,-0.13880,73.04247,3.80360
46.30800,19.29497,78.21189,-0.13880,73.20893,3.68229
46.40800,19.33658,75.59239,-0.13880,73.37538,3.55896
46.50800,19.37831,72.23546,-0.13880,73.54231,3.40092
46.60800,19.41998,64.86988,-0.13880,73.70900,3.05414
46.67600,19.44838,8.52215,-0.13880,73.82260,0.40123