File: Manufatura Aditiva/Dados/Ensaios AMR/Ensaios/Ensaios PP/Tracao_OLABI_22_05_2018_Polipropileno_Taxa_50mm.is_metal_RawData/Specimen_RawData_4.csv
Time,Extension,Load,Strain 1,Tensile strain,Tensile stress
(sec),(mm),(N),(mm/mm),(%),(MPa)
0.00000,0.00006,11.82462,0.00110,0.10982,0.55671
0.10000,0.02415,18.69842,0.00130,0.12969,0.88034
0.20000,0.07157,39.66932,0.00199,0.19875,1.86767
0.30000,0.11922,61.64986,0.00271,0.27102,2.90254
0.40000,0.16418,80.55241,0.00337,0.33735,3.79249
0.50000,0.20741,99.06481,0.00402,0.40250,4.66407
0.60000,0.24962,116.52147,0.00466,0.46632,5.48594
0.70000,0.29165,132.40471,0.00528,0.52799,6.23374
0.80000,0.33345,148.78800,0.00591,0.59134,7.00508
0.90000,0.37506,164.03291,0.00654,0.65389,7.72283
1.00000,0.41673,179.96046,0.00718,0.71787,8.47271
1.10000,0.45835,194.50423,0.00782,0.78190,9.15745
1.20000,0.50002,208.65607,0.00847,0.84731,9.82373
1.30000,0.54169,222.40910,0.00913,0.91283,10.47124
1.40000,0.58343,235.73320,0.00979,0.97919,11.09855
1.50000,0.62492,248.55328,0.01047,1.04671,11.70213
1.60000,0.66659,261.46930,0.01115,1.11478,12.31023
1.70000,0.70833,272.45714,0.01184,1.18360,12.82755
1.80000,0.75006,283.73746,0.01254,1.25357,13.35864
1.90000,0.79167,293.77525,0.01325,1.32467,13.83123
2.00000,0.83341,303.20778,0.01396,1.39643,14.27532
2.10000,0.87502,313.36239,0.01469,1.46882,14.75341
2.20000,0.91669,321.77905,0.01542,1.54209,15.14967
2.30000,0.95831,331.18615,0.01617,1.61660,15.59257
2.40000,0.99998,339.23271,0.01692,1.69167,15.97141
2.50000,1.04159,345.90205,0.01767,1.76734,16.28541
2.60000,1.08339,353.52467,0.01844,1.84450,16.64429
2.70000,1.12500,360.74750,0.01921,1.92103,16.98434
2.80000,1.16673,367.25239,0.01999,1.99891,17.29060
2.90000,1.20847,374.24604,0.02077,2.07721,17.61987
3.00000,1.25002,380.04066,0.02156,2.15550,17.89269
3.10000,1.29163,386.54797,0.02234,2.23429,18.19906
3.20000,1.33331,392.19148,0.02313,2.31343,18.46476
3.30000,1.37492,397.61304,0.02393,2.39286,18.72001
3.40000,1.41671,403.12884,0.02473,2.47251,18.97970
3.50000,1.45833,407.88227,0.02553,2.55277,19.20350
3.60000,1.50000,413.05139,0.02633,2.63346,19.44686
3.70000,1.54161,417.81906,0.02715,2.71452,19.67133
3.80000,1.58323,422.70962,0.02796,2.79601,19.90158
3.90000,1.62490,426.80614,0.02878,2.87814,20.09445
4.00000,1.66669,430.90680,0.02961,2.96090,20.28751
4.10000,1.70842,435.11293,0.03045,3.04508,20.48554
4.20000,1.75004,438.41386,0.03128,3.12800,20.64095
4.30000,1.79165,442.00639,0.03213,3.21261,20.81009
4.40000,1.83344,445.71273,0.03298,3.29796,20.98459
4.50000,1.87512,448.76924,0.03385,3.38546,21.12849
4.60000,1.91661,451.27878,0.03472,3.55143,21.24665
4.70000,1.95817,454.18153,0.03562,3.71765,21.38331
4.80000,1.99996,456.05260,0.03651,3.88482,21.47140
4.81200,2.00492,456.27640,0.03662,3.90467,21.48194
4.91200,2.04659,457.20153,0.03754,4.07136,21.52550
5.01200,2.08839,458.84852,0.03846,4.23853,21.60304
5.11200,2.13000,458.82715,0.03941,4.40499,21.60203
5.21200,2.17173,459.35144,0.04035,4.57192,21.62671
5.31200,2.21329,459.42026,0.04131,4.73813,21.62996
5.41200,2.25508,459.72858,0.04228,4.90531,21.64447
5.51200,2.29663,459.34599,0.04324,5.07152,21.62646
5.61200,2.33843,457.68814,0.04420,5.23869,21.54841
5.71200,2.38004,457.28274,0.04517,5.40515,21.52932
5.81200,2.42171,456.10457,0.04613,5.57184,21.47385
5.91200,2.46327,454.53794,0.04707,5.73805,21.40009
6.01200,2.50494,453.85137,0.04797,5.90475,21.36777
6.11200,2.54661,452.49835,0.04884,6.07144,21.30407
6.21200,2.58829,451.46644,0.04985,6.23813,21.25548
6.31200,2.63002,450.19365,0.05176,6.40507,21.19556
6.41200,2.67163,448.38497,0.05145,6.57152,21.11040
6.51200,2.71337,448.30195,0.05107,6.73845,21.10649
6.61200,2.75510,445.56367,0.05640,6.90538,20.97757
6.71200,2.79665,443.58331,0.06248,7.07160,20.88434
6.81200,2.83839,442.76766,0.06996,7.23853,20.84593
6.91200,2.87994,442.31061,0.07046,7.40474,20.82442
7.01200,2.92161,441.87284,0.06924,7.57144,20.80381
7.11200,2.96341,441.23898,0.06904,7.73861,20.77396
7.21200,3.00514,441.34022,0.06908,7.90554,20.77873
7.31200,3.04663,439.84591,0.06810,8.07152,20.70838
7.41200,3.08819,439.55594,0.19634,8.23773,20.69473
7.51200,3.12986,438.93713,0.18145,8.40443,20.66559
7.61200,3.17165,438.15519,0.07850,8.57160,20.62877
7.71200,3.21333,437.13609,0.07813,8.73829,20.58080
7.81200,3.25500,436.99765,0.09259,8.90498,20.57428
7.91200,3.29661,436.25883,0.09640,9.07144,20.53949
8.01200,3.33829,435.70176,0.06598,9.23813,20.51327
8.11200,3.37996,435.60048,0.09580,9.40482,20.50850
8.21200,3.42169,434.23264,0.07885,9.57176,20.44410
8.31200,3.46337,434.10892,0.09276,9.73845,20.43827
8.41200,3.50498,433.29485,0.09351,9.90490,20.39995
8.51200,3.54671,433.07813,0.08636,10.07183,20.38974
8.61200,3.58833,432.97568,0.07764,10.23829,20.38492
8.71200,3.63000,431.96334,-0.01214,10.40498,20.33726
8.81200,3.67173,431.98676,-0.07531,10.57191,20.33836
8.91200,3.71341,430.87867,-0.07487,10.73861,20.28619
9.01200,3.75496,430.18269,-0.07487,10.90482,20.25342
9.11200,3.79669,430.49115,-0.07488,11.07175,20.26794
9.21200,3.83825,430.27680,-0.07488,11.23797,20.25785
9.31200,3.87998,429.12918,-0.07489,11.40490,20.20382
9.41200,3.92165,428.95596,-0.07489,11.57159,20.19567
9.51200,3.96333,428.52210,-0.07489,11.73829,20.17524
9.61200,4.00500,428.08922,-0.07489,11.90498,20.15486
9.71200,4.04667,427.27799,-0.07489,12.07167,20.11667
9.81200,4.08835,427.84093,-0.07489,12.23837,20.14317
9.91200,4.13008,427.39441,-0.07489,12.40530,20.12215
10.01200,4.17169,426.96246,-0.07490,12.57175,20.10181
10.11200,4.21331,426.64693,-0.07490,12.73821,20.08696
10.21200,4.25504,426.01209,-0.07490,12.90514,20.05707
10.31200,4.29671,425.49879,-0.07491,13.07183,20.03290
10.41200,4.33833,425.24613,-0.07490,13.23829,20.02100
10.51200,4.37988,425.14149,-0.07490,13.40450,20.01608
10.61200,4.42161,425.08990,-0.07491,13.57143,20.01365
10.71200,4.46329,424.89804,-0.07491,13.73813,20.00462
10.81200,4.50508,424.22507,-0.07491,13.90530,19.97293
10.91200,4.54675,423.67154,-0.07491,14.07199,19.94687
11.01200,4.58842,423.47158,-0.07491,14.23868,19.93746
11.11200,4.62998,423.24658,-0.07491,14.40490,19.92686
11.21200,4.67183,422.95884,-0.07491,14.57231,19.91332
11.31200,4.71344,422.83190,-0.07492,14.73876,19.90734
11.41200,4.75500,422.81216,-0.07491,14.90498,19.90641
11.51200,4.79661,422.68359,-0.07491,15.07143,19.90036
11.61200,4.83823,421.93253,-0.07491,15.23789,19.86500
11.71200,4.87996,421.47101,-0.07491,15.40482,19.84327
11.81200,4.92163,420.98258,-0.07492,15.57151,19.82027
11.91200,4.96330,420.68176,-0.07492,15.73820,19.80611
12.01200,5.00498,420.78500,-0.07491,15.90490,19.81097
12.11200,5.04665,420.22457,-0.07491,16.07159,19.78458
12.21200,5.08832,420.45848,-0.07491,16.23828,19.79560
12.31200,5.13006,419.75435,-0.07492,16.40522,19.76245
12.41200,5.17167,419.83495,-0.07492,16.57167,19.76624
12.51200,5.21328,419.30745,-0.07492,16.73812,19.74141
12.61200,5.25496,418.87476,-0.07492,16.90482,19.72103
12.71200,5.29663,418.58610,-0.07491,17.07151,19.70744
12.81200,5.33830,418.66107,-0.07492,17.23820,19.71097
12.91200,5.38004,418.92626,-0.07492,17.40513,19.72346
13.01200,5.42171,418.27750,-0.07492,17.57183,19.69291
13.11200,5.46332,418.00137,-0.07492,17.73828,19.67991
13.21200,5.50500,417.80495,-0.07492,17.90497,19.67067
13.31200,5.54661,417.64644,-0.07492,18.07143,19.66320
13.41200,5.58840,417.03479,-0.07492,18.23860,19.63441
13.51200,5.62996,416.92080,-0.07492,18.40482,19.62904
13.61200,5.67169,416.43134,-0.07492,18.57175,19.60600
13.71200,5.71324,416.66953,-0.07492,18.73796,19.61721
13.81200,5.75492,416.10007,-0.07492,18.90465,19.59040
13.91200,5.79659,415.93239,-0.07492,19.07135,19.58250
14.01200,5.83838,415.78240,-0.07492,19.23852,19.57544
14.11200,5.88006,415.10710,-0.07492,19.40521,19.54365
14.21200,5.92167,415.15920,-0.07492,19.57166,19.54610
14.31200,5.96340,414.83650,-0.07492,19.73860,19.53091
14.41200,6.00508,414.66979,-0.07492,19.90529,19.52306
14.51200,6.04675,414.48986,-0.07492,20.07198,19.51459
14.61200,6.08830,414.42462,-0.07492,20.23820,19.51152
14.71200,6.13004,414.35170,-0.07492,20.40513,19.50808
14.81200,6.17159,413.70518,-0.07492,20.57135,19.47764
14.91200,6.21338,413.82490,-0.07492,20.73852,19.48328
15.01200,6.25494,413.20431,-0.07492,20.90473,19.45406
15.11200,6.29673,413.50243,-0.07492,21.07190,19.46810
15.21200,6.33822,412.60263,-0.07492,21.23788,19.42574
15.31200,6.38002,412.98256,-0.07492,21.40505,19.44362
15.41200,6.42175,412.66140,-0.07492,21.57198,19.42850
15.51200,6.46348,412.58419,-0.07492,21.73892,19.42487
15.61200,6.50504,411.96439,-0.07492,21.90513,19.39569
15.71200,6.54677,411.73766,-0.07492,22.07206,19.38501
15.81200,6.58838,412.04365,-0.07492,22.23852,19.39942
15.91200,6.63000,411.52490,-0.07492,22.40497,19.37500
16.01200,6.67155,411.53012,-0.07492,22.57119,19.37524
16.11200,6.71322,411.27088,-0.07492,22.73788,19.36304
16.21200,6.75490,411.18301,-0.07492,22.90457,19.35890
16.31200,6.79663,410.27763,-0.07492,23.07151,19.31627
16.41200,6.83830,410.09053,-0.07492,23.23820,19.30746
16.51200,6.87998,410.42296,-0.07492,23.40489,19.32311
16.61200,6.92171,410.37337,-0.07492,23.57182,19.32078
16.71200,6.96332,409.81383,-0.07492,23.73828,19.29444
16.81200,7.00500,409.44568,-0.07492,23.90497,19.27710
16.91200,7.04667,408.84661,-0.07492,24.07167,19.24890
17.01200,7.08840,409.56521,-0.07492,24.23860,19.28273
17.11200,7.13002,408.91790,-0.07492,24.40505,19.25225
17.21200,7.17163,408.55240,-0.07492,24.57151,19.23505
17.31200,7.21330,408.24343,-0.07492,24.73820,19.22050
17.41200,7.25492,408.33084,-0.07492,24.90465,19.22462
17.51200,7.29659,408.62355,-0.07492,25.07134,19.23840
17.61200,7.33832,407.81619,-0.07492,25.23828,19.20039
17.71200,7.38000,407.97605,-0.07492,25.40497,19.20791
17.81200,7.42167,407.57549,-0.07492,25.57167,19.18905
17.91200,7.46328,407.77223,-0.07492,25.73812,19.19832
18.01200,7.50502,406.79350,-0.07492,25.90505,19.15224
18.11200,7.54675,406.65362,-0.07492,26.07198,19.14565
18.21200,7.58842,406.44975,-0.07493,26.23867,19.13605
18.31200,7.62998,406.15075,-0.07492,26.40489,19.12197
18.41200,7.67159,406.42507,-0.07492,26.57134,19.13489
18.51200,7.71344,405.86181,-0.07492,26.73875,19.10837
18.61200,7.75506,405.74907,-0.07492,26.90521,19.10306
18.71200,7.79667,404.99344,-0.07492,27.07166,19.06749
18.81200,7.83840,404.69067,-0.07492,27.23859,19.05323
18.91200,7.87996,405.14357,-0.07492,27.40481,19.07456
19.01200,7.92157,404.27470,-0.07492,27.57126,19.03365
19.11200,7.96318,404.32145,-0.07492,27.73771,19.03585
19.21200,8.00504,404.30273,-0.07492,27.90512,19.03497
19.31200,8.04665,403.92461,-0.07493,28.07158,19.01717
19.41200,8.08838,403.77011,-0.07492,28.23851,19.00989
19.51200,8.12994,403.72778,-0.07492,28.40473,19.00790
19.61200,8.17167,402.83203,-0.07492,28.57166,18.96573
19.71200,8.21328,402.40348,-0.07492,28.73811,18.94555
19.81200,8.25502,402.75641,-0.07492,28.90505,18.96217
19.91200,8.29669,402.32292,-0.07492,29.07174,18.94176
20.01200,8.33842,401.68827,-0.07492,29.23867,18.91188
20.11200,8.38009,402.39226,-0.07492,29.40536,18.94502
20.21200,8.42171,401.03747,-0.07493,29.57182,18.88124
20.31200,8.46338,401.09707,-0.07493,29.73851,18.88404
20.41200,8.50505,401.02322,-0.07492,29.90520,18.88057
20.51200,8.54661,400.91318,-0.07492,30.07142,18.87539
20.61200,8.58822,400.25380,-0.07492,30.23787,18.84434
20.71200,8.62996,400.12319,-0.07493,30.40481,18.83819
20.81200,8.67163,399.65403,-0.07492,30.57150,18.81610
20.91200,8.71342,399.37319,-0.07492,30.73867,18.80288
21.01200,8.75486,399.18902,-0.07492,30.90441,18.79421
21.11200,8.79665,398.01588,-0.07493,31.07158,18.73898
21.21200,8.83826,398.72159,-0.07492,31.23803,18.77220
21.31200,8.88011,398.51149,-0.07492,31.40544,18.76231
21.41200,8.92167,397.91074,-0.07492,31.57166,18.73403
21.51200,8.96340,396.80828,-0.07492,31.73859,18.68212
21.61200,9.00502,397.36014,-0.07493,31.90504,18.70811
21.71200,9.04669,396.82472,-0.07492,32.07173,18.68290
21.81200,9.08824,396.33382,-0.07492,32.23795,18.65978
21.91200,9.12998,396.04781,-0.07492,32.40488,18.64632
22.01200,9.17159,395.25805,-0.07492,32.57134,18.60914
22.11200,9.21326,395.73866,-0.07492,32.73803,18.63176
22.21200,9.25499,395.03016,-0.07492,32.90496,18.59841
22.31200,9.29673,394.67700,-0.07493,33.07189,18.58178
22.41200,9.33840,394.22833,-0.07492,33.23859,18.56066
22.51200,9.38007,393.85944,-0.07492,33.40528,18.54329
22.61200,9.42163,393.47252,-0.07492,33.57150,18.52507
22.71200,9.46336,393.14865,-0.07493,33.73843,18.50982
22.81200,9.50503,392.42567,-0.07492,33.90512,18.47578
22.91200,9.54671,392.63940,-0.07492,34.07182,18.48585
23.01200,9.58832,391.72634,-0.07492,34.23827,18.44286
23.11200,9.62999,391.44661,-0.07493,34.40496,18.42969
23.21200,9.67161,391.14691,-0.07493,34.57142,18.41558
23.31200,9.71322,390.50446,-0.07493,34.73787,18.38533
23.41200,9.75495,389.66162,-0.07493,34.90480,18.34565
23.51200,9.79669,389.37936,-0.07493,35.07173,18.33236
23.61200,9.83836,388.95835,-0.07493,35.23842,18.31254
23.71200,9.87997,388.49579,-0.07493,35.40488,18.29076
23.81200,9.92171,388.97430,-0.07492,35.57181,18.31329
23.91200,9.96332,387.91078,-0.07493,35.73827,18.26322
24.01200,10.00505,387.61501,-0.07493,35.90520,18.24929
24.11200,10.04673,386.37368,-0.07492,36.07189,18.19085
24.21200,10.08834,386.61573,-0.07492,36.23834,18.20225
24.31200,10.13007,385.94350,-0.07493,36.40528,18.17060
24.41200,10.17175,385.05783,-0.07493,36.57197,18.12890
24.51200,10.21330,385.01450,-0.07492,36.73818,18.12686
24.61200,10.25503,383.23642,-0.07493,36.90512,18.04315
24.71200,10.29665,383.34331,-0.07492,37.07157,18.04818
24.81200,10.33832,383.11775,-0.07493,37.23826,18.03756
24.91200,10.37993,382.07714,-0.07493,37.40472,17.98857
25.01200,10.42173,381.17885,-0.07493,37.57189,17.94627
25.11200,10.46316,381.11028,-0.07493,37.73763,17.94304
25.21200,10.50495,380.26948,-0.07493,37.90480,17.90346
25.31200,10.54657,378.84752,-0.07493,38.07125,17.83651
25.41200,10.58836,378.70021,-0.07493,38.23842,17.82958
25.51200,10.62997,377.32637,-0.07493,38.40488,17.76489
25.61200,10.67177,376.94233,-0.07493,38.57205,17.74681
25.71200,10.71332,376.33437,-0.07492,38.73827,17.71819
25.81200,10.75505,374.58728,-0.07492,38.90520,17.63593
25.91200,10.79661,373.73030,-0.07492,39.07141,17.59559
26.01200,10.83834,373.33141,-0.07493,39.23834,17.57681
26.11200,10.88001,371.70576,-0.07493,39.40504,17.50027
26.21200,10.92169,370.62902,-0.07493,39.57173,17.44958
26.31200,10.96318,369.28882,-0.07493,39.73771,17.38648
26.41200,11.00497,367.20696,-0.07493,39.90488,17.28846
26.51200,11.04659,366.69399,-0.07493,40.07133,17.26431
26.61200,11.08832,365.63752,-0.07493,40.23826,17.21457
26.71200,11.13005,363.63788,-0.07493,40.40520,17.12043
26.81200,11.17161,362.03025,-0.07493,40.57141,17.04474
26.91200,11.21340,360.49075,-0.07493,40.73858,16.97226
27.01200,11.25495,357.74405,-0.07493,40.90480,16.84294
27.11200,11.29681,355.87850,-0.07493,41.07220,16.75511
27.21200,11.33836,354.21939,-0.07492,41.23842,16.67700
27.31200,11.38003,351.58165,-0.07493,41.40511,16.55281
27.41200,11.42165,349.03013,-0.07493,41.57157,16.43268
27.51200,11.46338,346.51060,-0.07493,41.73850,16.31406
27.61200,11.50499,343.38289,-0.07493,41.90495,16.16680
27.71200,11.54667,340.89417,-0.07493,42.07165,16.04963
27.81200,11.58822,337.84686,-0.07493,42.23786,15.90616
27.91200,11.62995,334.79286,-0.07493,42.40479,15.76238
28.01200,11.67163,331.53337,-0.07493,42.57149,15.60892
28.11200,11.71336,328.31167,-0.07493,42.73842,15.45724
28.21200,11.75497,325.09714,-0.07493,42.90487,15.30589
28.31200,11.79665,320.14423,-0.07493,43.07157,15.07270
28.41200,11.83826,315.65882,-0.07493,43.23803,14.86153
28.51200,11.88005,310.90905,-0.07493,43.40519,14.63790
28.61200,11.92166,306.22962,-0.07493,43.57164,14.41759
28.71200,11.96334,300.44245,-0.07493,43.73834,14.14512
28.81200,12.00501,295.64044,-0.07493,43.90503,13.91904
28.91200,12.04662,289.77001,-0.07493,44.07148,13.64266
29.01200,12.08836,284.71996,-0.07493,44.23842,13.40489
29.11200,12.13003,278.64217,-0.07493,44.40511,13.11875
29.21200,12.17171,273.69678,-0.07493,44.57181,12.88591
29.31200,12.21338,269.08177,-0.07493,44.73850,12.66863
29.41200,12.25499,263.78203,-0.07493,44.90495,12.41912
29.51200,12.29667,258.26329,-0.07493,45.07164,12.15929
29.61200,12.33822,253.46824,-0.07493,45.23786,11.93353
29.71200,12.37995,248.77759,-0.07493,45.40479,11.71269
29.81200,12.42163,243.41112,-0.07493,45.57149,11.46003
29.91200,12.46336,239.08538,-0.07493,45.73842,11.25637
30.01200,12.50497,233.68383,-0.07493,45.90487,11.00206
30.11200,12.54670,228.81075,-0.07493,46.07180,10.77263
30.21200,12.58838,224.23652,-0.07493,46.23850,10.55727
30.31200,12.63005,219.50204,-0.07493,46.40519,10.33437
30.41200,12.67166,215.29146,-0.07493,46.57164,10.13613
30.51200,12.71334,210.74717,-0.07493,46.73834,9.92218
30.61200,12.75495,206.43466,-0.07493,46.90479,9.71915
30.71200,12.79662,201.12367,-0.07493,47.07148,9.46910
30.81200,12.83842,196.75952,-0.07493,47.23866,9.26363
30.91200,12.88003,191.88614,-0.07493,47.40511,9.03419
31.01200,12.92170,187.31372,-0.07493,47.57181,8.81891
31.11200,12.96326,181.91058,-0.07493,47.73802,8.56453
31.21200,13.00499,176.86919,-0.07493,47.90495,8.32718
31.31200,13.04667,172.28024,-0.07493,48.07164,8.11112
31.41200,13.08846,167.54291,-0.07493,48.23882,7.88808
31.51200,13.13001,162.09501,-0.07493,48.40503,7.63159
31.61200,13.17174,156.57801,-0.07493,48.57196,7.37185
31.71200,13.21324,151.42860,-0.07493,48.73794,7.12941
31.81200,13.25503,145.09382,-0.07493,48.90511,6.83116
31.91200,13.29652,139.01126,-0.07493,49.07109,6.54479
32.01200,13.33832,132.34321,-0.07493,49.23826,6.23085
32.11200,13.37993,124.66168,-0.07493,49.40471,5.86919
32.21200,13.42166,114.86820,-0.07493,49.57164,5.40811
32.31200,13.46334,100.77852,-0.07493,49.73834,4.74475
32.37800,13.49078,9.60593,-0.07493,49.84811,0.45226