File: Manufatura Aditiva/Dados/Ensaios AMR/Ensaios/Ensaios PP/Tracao_OLABI_22_05_2018_Polipropileno_Taxa_50mm.is_metal_RawData/Specimen_RawData_1.csv
Time,Extension,Load,Strain 1,Tensile strain,Tensile stress
(sec),(mm),(N),(mm/mm),(%),(MPa)
0.00000,0.00006,17.19703,-0.00309,-0.30877,0.78849
0.10000,0.04921,32.67612,-0.00268,-0.26755,1.49822
0.20000,0.14403,78.10655,-0.00132,-0.13188,3.58123
0.30000,0.23880,123.57881,0.00013,0.01327,5.66615
0.40000,0.32854,164.15245,0.00151,0.15087,7.52648
0.50000,0.41482,200.20679,0.00287,0.28662,9.17959
0.60000,0.49924,234.33925,0.00420,0.41985,10.74458
0.70000,0.58301,265.59695,0.00556,0.55600,12.17776
0.80000,0.66653,292.80509,0.00694,0.69370,13.42527
0.90000,0.74994,317.95092,0.00835,0.83527,14.57822
1.00000,0.83335,340.13561,0.00981,0.98135,15.59540
1.10000,0.91669,360.22936,0.01131,1.13135,16.51671
1.20000,0.99998,377.44460,0.01284,1.28362,17.30603
1.30000,1.08333,394.09916,0.01439,1.43870,18.06965
1.40000,1.16667,408.46854,0.01596,1.59635,18.72850
1.50000,1.25002,422.86846,0.01754,1.75355,19.38874
1.60000,1.33337,435.36322,0.01912,1.91232,19.96163
1.70000,1.41671,449.25595,0.02072,2.07194,20.59862
1.80000,1.50000,460.40975,0.02233,2.23290,21.11003
1.90000,1.58323,470.97718,0.02394,2.39386,21.59455
2.00000,1.66663,481.52753,0.02554,2.55442,22.07829
2.10000,1.75010,490.65412,0.02717,2.71724,22.49675
2.20000,1.83344,501.04428,0.02880,2.87955,22.97314
2.30000,1.91667,509.30195,0.03043,3.04331,23.35176
2.40000,1.99990,517.98481,0.03207,3.20717,23.74988
2.50000,2.08331,525.15548,0.03373,3.37251,24.07866
2.60000,2.16665,532.31143,0.03539,3.53941,24.40676
2.70000,2.25000,538.95917,0.03707,3.87280,24.71156
2.80000,2.33346,546.01920,0.03877,4.20666,25.03527
2.90000,2.41675,551.55838,0.04049,4.53981,25.28924
2.92000,2.43343,552.74116,0.04084,4.60653,25.34347
3.02000,2.51660,557.73947,0.04256,4.93920,25.57265
3.12000,2.59995,563.07660,0.04431,5.27259,25.81736
3.22000,2.68329,567.74728,0.04608,5.60597,26.03151
3.32000,2.76670,572.05311,0.04788,5.93960,26.22894
3.42000,2.85005,575.13267,0.04969,6.27299,26.37014
3.52000,2.93339,578.40687,0.05151,6.60637,26.52026
3.62000,3.01674,581.59949,0.05337,6.93976,26.66664
3.72000,3.09991,583.99909,0.05523,7.27243,26.77667
3.82000,3.18325,586.67865,0.05712,7.60581,26.89952
3.92000,3.26660,587.50538,0.05904,7.93920,26.93743
4.02000,3.34995,589.40551,0.06096,8.27259,27.02455
4.12000,3.43341,590.73307,0.06292,8.60645,27.08542
4.22000,3.51664,591.61605,0.06489,8.93936,27.12591
4.32000,3.60016,592.53131,0.06688,9.27346,27.16787
4.42000,3.68327,592.08819,0.06888,9.60589,27.14756
4.52000,3.76662,591.79249,0.07089,9.93928,27.13400
4.62000,3.84985,592.08642,0.07292,10.27219,27.14747
4.72000,3.93331,592.04772,0.07495,10.60605,27.14570
4.82000,4.01660,591.10248,0.07700,10.93920,27.10236
4.92000,4.10006,590.42028,0.07906,11.27306,27.07108
5.02000,4.18335,589.96370,0.08113,11.60621,27.05015
5.12000,4.26670,588.36131,0.08321,11.93959,26.97668
5.22000,4.34998,587.60685,0.08528,12.27274,26.94208
5.32000,4.43321,586.92144,0.08736,12.60565,26.91066
5.42000,4.51668,585.58746,0.08943,12.93952,26.84949
5.52000,4.60008,584.33106,0.09148,13.27314,26.79189
5.62000,4.68349,582.60751,0.09357,13.60677,26.71286
5.72000,4.76678,580.81755,0.09568,13.93991,26.63079
5.82000,4.85000,580.11785,0.09790,14.27282,26.59871
5.92000,4.93329,577.88966,0.10045,14.60597,26.49655
6.02000,5.01664,576.30432,0.10321,14.93935,26.42386
6.12000,5.09998,574.42687,0.10399,15.27274,26.33777
6.22000,5.18339,574.41476,0.09951,15.60637,26.33722
6.32000,5.26668,574.62770,0.09167,15.93951,26.34698
6.42000,5.35002,571.52011,0.06028,16.27290,26.20450
6.52000,5.43337,568.05266,0.00177,16.60628,26.04551
6.62000,5.51666,566.57973,0.00177,16.93943,25.97798
6.72000,5.60006,565.43583,0.00206,17.27306,25.92553
6.82000,5.68335,564.56262,0.00198,17.60620,25.88549
6.92000,5.76658,562.98398,0.00195,17.93911,25.81311
7.02000,5.84998,561.96526,0.00134,18.27274,25.76640
7.12000,5.93333,560.94849,0.00753,18.60612,25.71978
7.22000,6.01686,559.62633,0.01117,18.94023,25.65916
7.32000,6.09996,558.70516,0.02588,19.27266,25.61693
7.42000,6.18325,557.18012,0.00982,19.60580,25.54700
7.52000,6.26660,555.68339,0.00362,19.93919,25.47838
7.62000,6.34988,554.52306,-0.01065,20.27234,25.42517
7.72000,6.43329,553.35183,-0.02845,20.60596,25.37147
7.82000,6.51682,551.45156,-0.01826,20.94007,25.28434
7.92000,6.60016,550.84084,0.00659,21.27345,25.25634
8.02000,6.68333,549.26220,0.02199,21.60612,25.18396
8.12000,6.76656,548.50820,-0.02435,21.93903,25.14939
8.22000,6.84990,546.54251,-0.03033,22.27242,25.05926
8.32000,6.93337,545.88323,-0.08083,22.60628,25.02903
8.42000,7.01672,544.21416,-0.08953,22.93967,24.95251
8.52000,7.10012,543.41117,-0.07795,23.27329,24.91569
8.62000,7.18341,541.88743,-0.07570,23.60644,24.84583
8.72000,7.26664,541.11257,-0.12155,23.93934,24.81030
8.82000,7.34998,539.71410,-0.09967,24.27273,24.74618
8.92000,7.43333,538.77956,-0.03957,24.60612,24.70333
9.02000,7.51673,536.99571,-0.05068,24.93974,24.62154
9.12000,7.60008,535.56566,-0.08615,25.27313,24.55597
9.22000,7.68325,535.03825,-0.07380,25.60580,24.53179
9.32000,7.76672,533.42595,-0.07414,25.93966,24.45786
9.42000,7.85006,531.83869,-0.07416,26.27305,24.38508
9.52000,7.93329,530.39812,-0.07418,26.60596,24.31903
9.62000,8.01663,528.33552,-0.07420,26.93934,24.22446
9.72000,8.10004,527.96388,-0.07421,27.27297,24.20742
9.82000,8.18339,526.32103,-0.07422,27.60635,24.13210
9.92000,8.26661,525.23119,-0.07423,27.93926,24.08213
10.02000,8.35002,523.53819,-0.07424,28.27289,24.00450
10.12000,8.43343,522.01762,-0.07425,28.60651,23.93478
10.22000,8.51671,520.55619,-0.07426,28.93966,23.86777
10.32000,8.59994,519.31301,-0.07426,29.27257,23.81078
10.42000,8.68323,517.64213,-0.07427,29.60572,23.73417
10.52000,8.76657,516.63667,-0.07427,29.93910,23.68806
10.62000,8.84992,514.59679,-0.07428,30.27249,23.59453
10.72000,8.93339,513.22561,-0.07428,30.60635,23.53166
10.82000,9.01673,511.14839,-0.07428,30.93974,23.43642
10.92000,9.09996,509.59839,-0.07428,31.27265,23.36535
11.02000,9.18331,508.06198,-0.07429,31.60603,23.29491
11.12000,9.26659,506.34658,-0.07429,31.93918,23.21626
11.22000,9.35006,504.07099,-0.07430,32.27304,23.11192
11.32000,9.43341,501.85979,-0.07430,32.60643,23.01054
11.42000,9.51669,500.52842,-0.07430,32.93958,22.94949
11.52000,9.60010,497.93227,-0.07430,33.27320,22.83046
11.62000,9.68333,496.46683,-0.07431,33.60611,22.76327
11.72000,9.76661,494.56093,-0.07431,33.93926,22.67588
11.82000,9.84996,491.62693,-0.07431,34.27264,22.54135
11.92000,9.93337,489.69411,-0.07431,34.60627,22.45273
12.02000,10.01671,487.44935,-0.07432,34.93966,22.34981
12.12000,10.10006,485.81092,-0.07432,35.27304,22.27469
12.22000,10.18347,482.47026,-0.07432,35.60666,22.12152
12.32000,10.26669,480.15276,-0.07432,35.93957,22.01526
12.42000,10.35004,478.02320,-0.07433,36.27296,21.91762
12.52000,10.43339,476.11194,-0.07433,36.60635,21.82998
12.62000,10.51655,472.92192,-0.07433,36.93902,21.68372
12.72000,10.60002,471.12987,-0.07434,37.27288,21.60155
12.82000,10.68337,468.74909,-0.07433,37.60627,21.49239
12.92000,10.76671,465.98488,-0.07434,37.93965,21.36565
13.02000,10.85000,464.61737,-0.07434,38.27280,21.30295
13.12000,10.93329,462.40008,-0.07434,38.60595,21.20129
13.22000,11.01657,460.48863,-0.07434,38.93909,21.11365
13.32000,11.09992,457.52181,-0.07434,39.27248,20.97762
13.42000,11.18344,456.10666,-0.07434,39.60658,20.91273
13.52000,11.26661,453.85789,-0.07434,39.93925,20.80962
13.62000,11.35014,452.14356,-0.07434,40.27336,20.73102
13.72000,11.43330,450.02420,-0.07434,40.60602,20.63385
13.82000,11.51659,448.53669,-0.07435,40.93917,20.56564
13.92000,11.59988,446.76359,-0.07434,41.27232,20.48435
14.02000,11.68328,445.21326,-0.07435,41.60594,20.41326
14.12000,11.76669,443.74368,-0.07435,41.93957,20.34588
14.22000,11.84998,442.84859,-0.07435,42.27271,20.30484
14.32000,11.93332,441.60713,-0.07435,42.60610,20.24792
14.42000,12.01673,440.75521,-0.07435,42.93973,20.20886
14.52000,12.09996,439.16204,-0.07435,43.27263,20.13581
14.62000,12.18336,438.70327,-0.07435,43.60626,20.11478
14.72000,12.26665,437.24142,-0.07435,43.93941,20.04775
14.82000,12.34994,436.80794,-0.07435,44.27256,20.02787
14.92000,12.43328,435.95922,-0.07435,44.60594,19.98896
15.02000,12.51669,435.02077,-0.07435,44.93957,19.94593
15.12000,12.60004,434.79572,-0.07435,45.27296,19.93561
15.22000,12.68332,433.86216,-0.07436,45.60610,19.89281
15.32000,12.76661,433.42127,-0.07436,45.93925,19.87259
15.42000,12.85002,432.86621,-0.07436,46.27287,19.84714
15.52000,12.93336,432.07495,-0.07436,46.60626,19.81087
15.62000,13.01665,431.73535,-0.07436,46.93941,19.79529
15.72000,13.10012,430.79681,-0.07436,47.27327,19.75226
15.82000,13.18346,430.67439,-0.07436,47.60665,19.74665
15.92000,13.26669,429.81645,-0.07436,47.93957,19.70731
16.02000,13.34992,429.52825,-0.07436,48.27248,19.69410
16.12000,13.43326,429.32206,-0.07436,48.60586,19.68464
16.22000,13.51667,429.51792,-0.07436,48.93949,19.69362
16.32000,13.59996,428.69942,-0.07436,49.27263,19.65610
16.42000,13.68330,428.30762,-0.07436,49.60602,19.63813
16.52000,13.76689,428.81332,-0.07436,49.94036,19.66132
16.62000,13.84994,427.95539,-0.07436,50.27255,19.62198
16.72000,13.93328,428.11912,-0.07436,50.60594,19.62949
16.82000,14.01663,428.25365,-0.07436,50.93932,19.63566
16.92000,14.09998,428.32065,-0.07436,51.27271,19.63873
17.02000,14.18338,428.58892,-0.07436,51.60633,19.65103
17.12000,14.26661,428.75600,-0.07437,51.93924,19.65869
17.22000,14.34996,428.31218,-0.07437,52.27263,19.63834
17.32000,14.43336,428.63907,-0.07437,52.60625,19.65333
17.42000,14.51653,428.68387,-0.07436,52.93892,19.65538
17.52000,14.60000,428.76001,-0.07437,53.27279,19.65887
17.62000,14.68334,428.00326,-0.07437,53.60618,19.62418
17.72000,14.76669,428.42012,-0.07437,53.93956,19.64329
17.82000,14.85004,428.20564,-0.07437,54.27295,19.63345
17.92000,14.93332,428.21146,-0.07437,54.60609,19.63372
18.02000,15.01679,428.18421,-0.07437,54.93996,19.63247
18.12000,15.10002,427.92610,-0.07437,55.27287,19.62064
18.22000,15.18324,427.97928,-0.07437,55.60578,19.62308
18.32000,15.26665,427.60372,-0.07437,55.93940,19.60586
18.42000,15.35000,427.07496,-0.07437,56.27279,19.58161
18.52000,15.43334,426.94826,-0.07437,56.60617,19.57580
18.62000,15.51675,427.77047,-0.07437,56.93980,19.61350
18.72000,15.59998,427.35916,-0.07437,57.27271,19.59464
18.82000,15.68332,426.54295,-0.07437,57.60610,19.55722
18.92000,15.76667,426.83892,-0.07437,57.93948,19.57079
19.02000,15.84995,427.02598,-0.07437,58.27262,19.57937
19.12000,15.93336,426.28059,-0.07437,58.60625,19.54519
19.22000,16.01665,425.82843,-0.07437,58.93939,19.52446
19.32000,16.10006,426.01707,-0.07437,59.27302,19.53311
19.42000,16.18334,425.53367,-0.07437,59.60617,19.51094
19.52000,16.26669,425.40948,-0.07437,59.93955,19.50525
19.62000,16.34997,426.28492,-0.07437,60.27270,19.54539
19.72000,16.43326,425.86755,-0.07437,60.60585,19.52625
19.82000,16.51661,425.88380,-0.07437,60.93923,19.52700
19.92000,16.60001,425.66261,-0.07437,61.27286,19.51686
20.02000,16.68336,425.99109,-0.07437,61.60625,19.53192
20.12000,16.76677,425.67560,-0.07437,61.93987,19.51745
20.22000,16.84993,426.14136,-0.07437,62.27254,19.53881
20.32000,16.93328,425.87523,-0.07438,62.60593,19.52660
20.42000,17.01669,425.76683,-0.07438,62.93955,19.52163
20.52000,17.09991,425.83398,-0.07438,63.27246,19.52471
20.62000,17.18326,426.39440,-0.07438,63.60585,19.55041
20.72000,17.26667,425.86918,-0.07438,63.93947,19.52633
20.82000,17.35007,426.09493,-0.07438,64.27310,19.53668
20.92000,17.43336,426.26844,-0.07438,64.60625,19.54463
21.02000,17.51659,425.88268,-0.07438,64.93915,19.52695
21.12000,17.59999,426.00106,-0.07438,65.27278,19.53237
21.22000,17.68328,426.02201,-0.07438,65.60593,19.53333
21.32000,17.76663,426.28353,-0.07438,65.93931,19.54532
21.42000,17.85009,426.25577,-0.07438,66.27317,19.54405
21.52000,17.93344,426.21735,-0.07438,66.60656,19.54229
21.62000,18.01667,426.74197,-0.07438,66.93947,19.56635
21.72000,18.09995,426.29042,-0.07438,67.27262,19.54564
21.82000,18.18330,425.71533,-0.07438,67.60601,19.51927
21.92000,18.26671,425.98047,-0.07438,67.93963,19.53143
22.02000,18.35005,425.14428,-0.07438,68.27301,19.49309
22.12000,18.43334,425.86946,-0.07438,68.60617,19.52634
22.22000,18.51669,425.32827,-0.07438,68.93955,19.50153
22.32000,18.59997,425.73065,-0.07438,69.27270,19.51997
22.42000,18.68314,425.04398,-0.07438,69.60536,19.48849
22.52000,18.76667,424.80677,-0.07438,69.93946,19.47762
22.62000,18.85001,424.69851,-0.07438,70.27285,19.47265
22.72000,18.93336,424.76403,-0.07438,70.60624,19.47565
22.82000,19.01659,424.91034,-0.07438,70.93915,19.48236
22.92000,19.09999,424.35564,-0.07438,71.27277,19.45693
23.02000,19.18334,424.27890,-0.07438,71.60616,19.45341
23.12000,19.26669,425.01097,-0.07438,71.93955,19.48698
23.22000,19.34997,424.93627,-0.07438,72.27269,19.48355
23.32000,19.43332,423.93566,-0.07438,72.60607,19.43767
23.42000,19.51661,424.76878,-0.07438,72.93923,19.47587
23.52000,19.59989,424.11252,-0.07438,73.27237,19.44578
23.62000,19.68330,424.83020,-0.07439,73.60600,19.47869
23.72000,19.76682,424.86526,-0.07439,73.94010,19.48030
23.82000,19.85005,425.08794,-0.07439,74.27301,19.49051
23.92000,19.93328,425.09912,-0.07438,74.60591,19.49102
24.02000,20.01663,425.11155,-0.07438,74.93930,19.49159
24.12000,20.09997,424.61976,-0.07439,75.27269,19.46904
24.22000,20.18326,424.54065,-0.07439,75.60583,19.46541
24.32000,20.26672,424.97278,-0.07439,75.93970,19.48523
24.42000,20.35013,424.74880,-0.07439,76.27332,19.47496
24.52000,20.43324,424.85655,-0.07439,76.60576,19.47990
24.62000,20.51665,425.31854,-0.07438,76.93939,19.50108
24.72000,20.59993,424.97884,-0.07439,77.27253,19.48550
24.82000,20.68340,425.11648,-0.07439,77.60639,19.49182
24.92000,20.76674,425.15923,-0.07439,77.93978,19.49377
25.02000,20.85009,425.58429,-0.07439,78.27316,19.51326
25.12000,20.93338,425.33292,-0.07439,78.60631,19.50174
25.22000,21.01667,425.53749,-0.07439,78.93947,19.51112
25.32000,21.09989,425.52222,-0.07439,79.27237,19.51042
25.42000,21.18336,425.88948,-0.07439,79.60623,19.52726
25.52000,21.26664,426.05652,-0.07439,79.93937,19.53492
25.62000,21.34999,426.40022,-0.07439,80.27276,19.55067
25.72000,21.43334,426.12469,-0.07439,80.60615,19.53804
25.82000,21.51662,426.91687,-0.07439,80.93929,19.57436
25.92000,21.59997,426.40753,-0.07439,81.27269,19.55101
26.02000,21.68332,426.91831,-0.07439,81.60607,19.57443
26.12000,21.76666,427.01159,-0.07439,81.93945,19.57871
26.22000,21.84995,426.30266,-0.07439,82.27260,19.54620
26.32000,21.93330,426.43361,-0.07439,82.60599,19.55221
26.42000,22.01658,426.20995,-0.07439,82.93913,19.54195
26.52000,22.09999,426.55258,-0.07439,83.27276,19.55766
26.62000,22.18340,425.65893,-0.07439,83.60639,19.51669
26.72000,22.26662,425.25209,-0.07439,83.93929,19.49803
26.82000,22.34991,425.02382,-0.07439,84.27244,19.48757
26.92000,22.43320,424.56733,-0.07439,84.60559,19.46664
27.02000,22.51660,424.32942,-0.07439,84.93921,19.45573
27.12000,22.59995,424.28477,-0.07439,85.27261,19.45368
27.22000,22.68336,424.55271,-0.07439,85.60623,19.46597
27.32000,22.76670,423.71261,-0.07439,85.93961,19.42745
27.42000,22.84993,423.61300,-0.07439,86.27252,19.42288
27.52000,22.93328,423.49147,-0.07439,86.60591,19.41731
27.62000,23.01662,423.62525,-0.07439,86.93929,19.42344
27.72000,23.09997,423.68737,-0.07439,87.27268,19.42629
27.82000,23.18332,423.99406,-0.07439,87.60607,19.44035
27.92000,23.26672,423.82739,-0.07439,87.93969,19.43271
28.02000,23.35001,423.80351,-0.07439,88.27285,19.43161
28.12000,23.43330,423.96989,-0.07439,88.60599,19.43924
28.22000,23.51664,423.91666,-0.07439,88.93936,19.43680
28.32000,23.60011,424.02549,-0.07439,89.27323,19.44179
28.42000,23.68345,423.97212,-0.07439,89.60662,19.43935
28.52000,23.76656,424.00151,-0.07439,89.93905,19.44069
28.62000,23.85003,424.31457,-0.07439,90.27292,19.45505
28.72000,23.93343,424.25445,-0.07439,90.60655,19.45229
28.82000,24.01666,424.13995,-0.07439,90.93944,19.44704
28.92000,24.09995,423.88607,-0.07439,91.27259,19.43540
29.02000,24.18329,424.68836,-0.07439,91.60599,19.47219
29.12000,24.26670,424.59155,-0.07439,91.93960,19.46775
29.22000,24.34993,425.16496,-0.07439,92.27251,19.49404
29.32000,24.43339,424.66521,-0.07439,92.60638,19.47112
29.42000,24.51680,424.85027,-0.07440,92.94000,19.47961
29.52000,24.60003,425.11108,-0.07439,93.27292,19.49157
29.62000,24.68325,425.51979,-0.07439,93.60582,19.51031
29.72000,24.76654,426.05363,-0.07439,93.93896,19.53478
29.82000,24.84989,426.37582,-0.07439,94.27235,19.54956
29.92000,24.93329,426.37056,-0.07439,94.60598,19.54931
30.02000,25.01664,426.09163,-0.07440,94.93936,19.53653
30.12000,25.10005,426.15118,-0.07439,95.27299,19.53926
30.22000,25.18339,426.69363,-0.07440,95.60637,19.56413
30.32000,25.26656,426.74793,-0.07439,95.93905,19.56662
30.42000,25.35003,426.18425,-0.07439,96.27290,19.54077
30.52000,25.43337,426.73349,-0.07439,96.60630,19.56596
30.62000,25.51672,426.97242,-0.07440,96.93969,19.57691
30.72000,25.60006,427.03976,-0.07440,97.27306,19.58000
30.82000,25.68335,426.67352,-0.07440,97.60622,19.56321
30.92000,25.76676,427.36512,-0.07439,97.93984,19.59492
31.02000,25.84993,426.76535,-0.07439,98.27251,19.56742
31.12000,25.93327,427.34351,-0.07439,98.60590,19.59393
31.22000,26.01662,426.88735,-0.07439,98.93928,19.57301
31.32000,26.09997,426.76283,-0.07439,99.27267,19.56730
31.42000,26.18325,426.48553,-0.07440,99.60581,19.55459
31.52000,26.26666,425.92012,-0.07440,99.93944,19.52866
31.62000,26.35007,426.20045,-0.07440,100.27307,19.54152
31.72000,26.43341,426.03929,-0.07439,100.60645,19.53413
31.82000,26.51670,425.29465,-0.07440,100.93961,19.49998
31.92000,26.59993,425.03714,-0.07440,101.27251,19.48818
32.02000,26.68333,424.57567,-0.07440,101.60613,19.46702
32.12000,26.76656,424.00756,-0.07440,101.93905,19.44097
32.22000,26.85009,424.78866,-0.07439,102.27314,19.47678
32.32000,26.93343,424.21692,-0.07439,102.60653,19.45057
32.42000,27.01672,424.23485,-0.07440,102.93968,19.45139
32.52000,27.10001,423.39102,-0.07440,103.27283,19.41270
32.62000,27.18323,423.72532,-0.07440,103.60574,19.42803
32.72000,27.26664,423.85124,-0.07440,103.93935,19.43380
32.82000,27.35010,423.52956,-0.07440,104.27322,19.41905
32.92000,27.43339,423.33021,-0.07440,104.60637,19.40991
33.02000,27.51680,423.33901,-0.07440,104.94000,19.41032
33.12000,27.59991,423.62860,-0.07440,105.27242,19.42360
33.22000,27.68319,423.42073,-0.07440,105.60557,19.41406
33.32000,27.76654,424.07452,-0.07440,105.93896,19.44404
33.42000,27.84989,424.26637,-0.07440,106.27235,19.45284
33.52000,27.93329,424.69171,-0.07440,106.60597,19.47234
33.62000,28.01676,424.28887,-0.07440,106.93984,19.45387
33.72000,28.10004,424.57557,-0.07440,107.27298,19.46701
33.82000,28.18339,424.90908,-0.07440,107.60636,19.48231
33.92000,28.26662,424.58163,-0.07440,107.93928,19.46729
34.02000,28.34996,425.33167,-0.07440,108.27266,19.50168
34.12000,28.43325,425.51192,-0.07440,108.60580,19.50995
34.22000,28.51660,425.80436,-0.07440,108.93919,19.52335
34.32000,28.60000,426.36879,-0.07440,109.27281,19.54923
34.42000,28.68335,426.36325,-0.07440,109.60621,19.54898
34.52000,28.76664,425.94331,-0.07440,109.93936,19.52973
34.62000,28.84998,426.14769,-0.07440,110.27274,19.53910
34.72000,28.93333,425.99216,-0.07440,110.60613,19.53197
34.82000,29.01662,426.56902,-0.07440,110.93928,19.55841
34.92000,29.10008,426.90760,-0.07440,111.27315,19.57394
35.02000,29.18337,426.71277,-0.07440,111.60629,19.56501
35.12000,29.26678,426.79822,-0.07440,111.93991,19.56892
35.22000,29.35012,425.78359,-0.07440,112.27330,19.52240
35.32000,29.43329,425.64906,-0.07440,112.60597,19.51623
35.42000,29.51664,426.22508,-0.07440,112.93936,19.54264
35.52000,29.59993,425.85819,-0.07439,113.27250,19.52582
35.62000,29.68333,425.77232,-0.07439,113.60612,19.52188
35.72000,29.76668,425.68687,-0.07440,113.93952,19.51797
35.82000,29.84996,424.45799,-0.07440,114.27267,19.46162
35.92000,29.93343,424.66493,-0.07440,114.60652,19.47111
36.02000,30.01666,424.56691,-0.07440,114.93943,19.46662
36.12000,30.09995,424.01184,-0.07440,115.27258,19.44117
36.22000,30.18335,423.67824,-0.07440,115.60620,19.42587
36.32000,30.26670,423.64970,-0.07440,115.93959,19.42456
36.42000,30.34998,423.47647,-0.07440,116.27275,19.41662
36.52000,30.43333,423.01253,-0.07440,116.60613,19.39535
36.62000,30.51674,422.72755,-0.07440,116.93976,19.38228
36.72000,30.60008,421.69373,-0.07440,117.27314,19.33488
36.82000,30.68331,422.33234,-0.07440,117.60604,19.36416
36.92000,30.76660,421.90151,-0.07440,117.93919,19.34441
37.02000,30.85000,421.10863,-0.07439,118.27282,19.30805
37.12000,30.93329,420.88260,-0.07440,118.60597,19.29769
37.22000,31.01676,421.09140,-0.07440,118.93983,19.30726
37.32000,31.10010,420.69475,-0.07440,119.27321,19.28908
37.42000,31.18339,420.68427,-0.07440,119.60636,19.28860
37.52000,31.26662,420.58579,-0.07440,119.93927,19.28408
37.62000,31.34990,420.19067,-0.07440,120.27241,19.26596
37.72000,31.43337,420.52763,-0.07440,120.60627,19.28141
37.82000,31.51665,420.73824,-0.07440,120.93941,19.29107
37.92000,31.60000,419.98546,-0.07440,121.27281,19.25656
38.02000,31.68347,419.99961,-0.07440,121.60667,19.25720
38.12000,31.76669,420.39333,-0.07440,121.93958,19.27526
38.22000,31.84992,421.01289,-0.07440,122.27249,19.30366
38.32000,31.93333,420.49200,-0.07440,122.60611,19.27978
38.42000,32.01667,420.11146,-0.07440,122.93949,19.26233
38.52000,32.10014,420.29265,-0.07440,123.27337,19.27064
38.62000,32.18343,420.14965,-0.07440,123.60651,19.26408
38.72000,32.26666,420.12488,-0.07440,123.93943,19.26295
38.82000,32.34994,420.13177,-0.07440,124.27257,19.26326
38.92000,32.43323,420.32562,-0.07440,124.60572,19.27215
39.02000,32.51663,420.25051,-0.07440,124.93933,19.26871
39.12000,32.59992,419.83603,-0.07440,125.27249,19.24970
39.22000,32.68333,420.10178,-0.07440,125.60612,19.26189
39.32000,32.76667,419.89367,-0.07440,125.93950,19.25235
39.42000,32.85008,420.02904,-0.07440,126.27312,19.25855
39.52000,32.93343,419.68790,-0.07440,126.60651,19.24291
39.62000,33.01671,419.76855,-0.07440,126.93965,19.24661
39.72000,33.10000,420.06089,-0.07440,127.27280,19.26001
39.82000,33.18329,419.66932,-0.07440,127.60596,19.24206
39.92000,33.26664,419.96315,-0.07440,127.93934,19.25553
40.02000,33.34992,419.64659,-0.07440,128.27249,19.24102
40.12000,33.43333,419.37800,-0.07440,128.60610,19.22870
40.22000,33.51679,418.79443,-0.07440,128.93996,19.20195
40.32000,33.59996,418.73157,-0.07440,129.27264,19.19906
40.42000,33.68331,418.62978,-0.07440,129.60604,19.19440
40.52000,33.76659,418.38996,-0.07440,129.93919,19.18340
40.62000,33.84994,417.92551,-0.07440,130.27257,19.16211
40.72000,33.93335,418.03461,-0.07440,130.60619,19.16711
40.82000,34.01675,417.86367,-0.07440,130.93981,19.15927
40.92000,34.10016,417.60528,-0.07440,131.27345,19.14742
41.02000,34.18333,417.56891,-0.07440,131.60611,19.14575
41.12000,34.26667,417.48262,-0.07440,131.93949,19.14180
41.22000,34.34996,417.06394,-0.07440,132.27264,19.12260
41.32000,34.43337,417.42660,-0.07440,132.60627,19.13923
41.42000,34.51671,416.86073,-0.07440,132.93965,19.11329
41.52000,34.60006,416.92285,-0.07440,133.27303,19.11613
41.62000,34.68335,416.41542,-0.07440,133.60620,19.09287
41.72000,34.76669,416.59107,-0.07440,133.93958,19.10092
41.82000,34.84992,415.88033,-0.07440,134.27249,19.06833
41.92000,34.93333,415.49546,-0.07440,134.60611,19.05069
42.02000,35.01667,415.57634,-0.07440,134.93949,19.05439
42.12000,35.09996,415.86049,-0.07440,135.27263,19.06742
42.22000,35.18324,415.71162,-0.07440,135.60578,19.06060
42.32000,35.26677,415.85839,-0.07440,135.93990,19.06733
42.42000,35.34994,415.62114,-0.07440,136.27256,19.05645
42.52000,35.43328,415.41136,-0.07440,136.60594,19.04683
42.62000,35.51657,415.36065,-0.07440,136.93908,19.04450
42.72000,35.59992,414.83622,-0.07440,137.27248,19.02046
42.82000,35.68332,415.51008,-0.07440,137.60610,19.05136
42.92000,35.76667,415.14919,-0.07440,137.93950,19.03481
43.02000,35.85008,414.62169,-0.07440,138.27312,19.01062
43.12000,35.93342,414.90071,-0.07440,138.60650,19.02342
43.22000,36.01653,414.87468,-0.07440,138.93894,19.02222
43.32000,36.09988,414.91310,-0.07440,139.27231,19.02398
43.42000,36.18322,414.70686,-0.07440,139.60570,19.01453
43.52000,36.26663,414.77391,-0.07440,139.93933,19.01760
43.62000,36.35004,414.40995,-0.07440,140.27296,19.00092
43.72000,36.43338,414.47529,-0.07441,140.60634,19.00391
43.82000,36.51673,413.61311,-0.07440,140.93972,18.96438
43.92000,36.60002,413.82127,-0.07440,141.27287,18.97392
44.02000,36.68330,414.12390,-0.07440,141.60602,18.98780
44.12000,36.76671,413.23123,-0.07440,141.93965,18.94687
44.22000,36.85006,413.91854,-0.07440,142.27303,18.97838
44.32000,36.93340,413.29907,-0.07440,142.60641,18.94998
44.42000,37.01675,412.91425,-0.07440,142.93981,18.93234
44.52000,37.10010,412.98619,-0.07440,143.27319,18.93563
44.62000,37.18332,412.15541,-0.07440,143.60609,18.89754
44.72000,37.26667,411.76365,-0.07440,143.93950,18.87958
44.82000,37.35002,411.64136,-0.07440,144.27288,18.87397
44.92000,37.43336,411.03847,-0.07440,144.60626,18.84633
45.02000,37.51659,410.55302,-0.07440,144.93917,18.82407
45.12000,37.59994,410.37952,-0.07440,145.27255,18.81612
45.22000,37.68346,408.49214,-0.07440,145.60665,18.72958
45.32000,37.76669,407.03812,-0.07440,145.93958,18.66291
45.42000,37.85010,405.12849,-0.07440,146.27320,18.57536
45.52000,37.93320,402.50625,-0.07440,146.60562,18.45512
45.62000,38.01661,400.38382,-0.07440,146.93924,18.35781
45.72000,38.10002,396.07324,-0.07440,147.27286,18.16017
45.82000,38.18330,392.31228,-0.07440,147.60602,17.98772
45.92000,38.26665,387.38404,-0.07440,147.93940,17.76176
46.02000,38.35006,381.19769,-0.07440,148.27303,17.47812
46.12000,38.43322,373.86382,-0.07440,148.60570,17.14185
46.22000,38.51657,367.25814,-0.07440,148.93909,16.83898
46.32000,38.59992,356.71380,-0.07441,149.27247,16.35552
46.42000,38.68332,347.00041,-0.07440,149.60608,15.91015
46.52000,38.76673,335.91951,-0.07440,149.93972,15.40209
46.59000,38.82514,9.47118,-0.07440,150.17338,0.43426