File: Manufatura Aditiva/Classificação Direção/Ensaios/Ensaios SLS/Tracao_OLABI_06_06_2018_SLS_XY1.is_metal_RawData/Specimen_RawData_2.csv
Time,Extension,Load,Strain 1,Tensile strain,Tensile stress
(sec),(mm),(N),(mm/mm),(%),(MPa)
0.00000,0.00006,19.08743,0.00105,0.10494,0.85760
0.20000,0.01381,25.99802,0.00123,0.12266,1.16809
0.40000,0.03270,36.95826,0.00152,0.15241,1.66054
0.60000,0.04986,45.96459,0.00180,0.17981,2.06519
0.80000,0.06673,54.23483,0.00206,0.20644,2.43678
1.00000,0.08335,63.55120,0.00233,0.23342,2.85536
1.20000,0.10003,72.20726,0.00260,0.26019,3.24428
1.40000,0.11677,80.78066,0.00287,0.28720,3.62948
1.60000,0.13339,88.30978,0.00312,0.31206,3.96777
1.80000,0.14995,96.15947,0.00338,0.33845,4.32045
2.00000,0.16657,104.59299,0.00366,0.36557,4.69937
2.20000,0.18325,112.62840,0.00392,0.39246,5.06040
2.40000,0.19994,118.47874,0.00414,0.41441,5.32326
2.60000,0.21668,126.59641,0.00442,0.44167,5.68799
2.80000,0.23336,134.34688,0.00469,0.46874,6.03622
3.00000,0.24998,142.14169,0.00495,0.49539,6.38644
3.20000,0.26672,150.10022,0.00523,0.52269,6.74402
3.40000,0.28340,157.99848,0.00550,0.55020,7.09889
3.60000,0.30002,165.81152,0.00577,0.57728,7.44993
3.80000,0.31665,172.83922,0.00604,0.60411,7.76568
4.00000,0.33327,180.30867,0.00631,0.63132,8.10128
4.20000,0.34995,188.36667,0.00658,0.65848,8.46333
4.40000,0.36663,196.00512,0.00686,0.68580,8.80653
4.60000,0.38331,203.27747,0.00713,0.71285,9.13328
4.80000,0.39999,209.96023,0.00739,0.73904,9.43353
5.00000,0.41661,216.52742,0.00763,0.76326,9.72860
5.20000,0.43335,224.04650,0.00790,0.79020,10.06643
5.40000,0.45004,231.77301,0.00818,0.81781,10.41358
5.60000,0.46666,238.65087,0.00845,0.84542,10.72260
5.80000,0.48334,246.50651,0.00873,0.87329,11.07556
6.00000,0.50002,253.20817,0.00900,0.90045,11.37667
6.20000,0.51664,260.38694,0.00928,0.92818,11.69921
6.40000,0.53326,267.20895,0.00956,0.95563,12.00572
6.60000,0.55000,275.02058,0.00983,0.98319,12.35670
6.80000,0.56674,281.23818,0.01010,1.00968,12.63606
7.00000,0.58331,287.38626,0.01034,1.03401,12.91229
7.20000,0.59993,294.12427,0.01061,1.06109,13.21503
7.40000,0.61673,300.87451,0.01089,1.08886,13.51832
7.60000,0.63335,307.50688,0.01116,1.11645,13.81631
7.80000,0.64991,313.81249,0.01144,1.14384,14.09962
8.00000,0.66671,321.38820,0.01173,1.17316,14.44000
8.20000,0.68333,327.70103,0.01200,1.20025,14.72364
8.40000,0.70002,334.06748,0.01228,1.22822,15.00968
8.60000,0.71664,340.75361,0.01256,1.25615,15.31009
8.80000,0.73344,346.05542,0.01280,1.28043,15.54830
9.00000,0.75000,352.40771,0.01308,1.30800,15.83371
9.20000,0.76662,358.60611,0.01336,1.33611,16.11220
9.40000,0.78336,364.47966,0.01364,1.36431,16.37610
9.60000,0.79998,370.66957,0.01392,1.39243,16.65422
9.80000,0.81660,376.62277,0.01420,1.42048,16.92169
10.00000,0.83335,383.00285,0.01449,1.44896,17.20835
10.20000,0.84997,388.42512,0.01477,1.47725,17.45197
10.40000,0.86671,394.37586,0.01505,1.50528,17.71934
10.60000,0.88333,399.07196,0.01529,1.52924,17.93034
10.80000,0.90007,405.07261,0.01558,1.55752,18.19995
11.00000,0.91669,410.46212,0.01586,1.58599,18.44210
11.20000,0.93331,416.75856,0.01614,1.61445,18.72500
11.40000,0.95000,422.12768,0.01643,1.64347,18.96623
11.60000,0.96656,428.08242,0.01672,1.67183,19.23378
11.80000,0.98330,434.15190,0.01701,1.70119,19.50648
12.00000,1.00004,439.17564,0.01730,1.73001,19.73220
12.20000,1.01666,444.55365,0.01758,1.75811,19.97383
12.40000,1.03334,449.48752,0.01785,1.78454,20.19551
12.60000,1.04996,455.31308,0.01814,1.81371,20.45726
12.80000,1.06664,460.81576,0.01843,1.84283,20.70449
13.00000,1.08333,465.32694,0.01872,1.87213,20.90718
13.20000,1.10001,470.48442,0.01902,1.90198,21.13891
13.40000,1.11675,474.95025,0.01932,1.93200,21.33956
13.60000,1.13319,481.11062,0.01961,1.96145,21.61634
13.80000,1.14993,485.55387,0.01992,1.99173,21.81598
14.00000,1.16673,489.91637,0.02018,2.01812,22.01199
14.20000,1.18329,494.12828,0.02048,2.04758,22.20123
14.40000,1.19998,498.41739,0.02078,2.07818,22.39394
14.60000,1.21672,503.48332,0.02109,2.10909,22.62155
14.80000,1.23334,508.00950,0.02139,2.13944,22.82491
15.00000,1.24990,511.98336,0.02170,2.16967,23.00346
15.20000,1.26664,517.46131,0.02201,2.20077,23.24958
15.40000,1.28344,521.75382,0.02232,2.23192,23.44245
15.60000,1.29994,524.85149,0.02262,2.26169,23.58162
15.80000,1.31656,528.80319,0.02289,2.28927,23.75917
16.00000,1.33343,532.98478,0.02321,2.32070,23.94705
16.20000,1.34993,536.66206,0.02352,2.35217,24.11227
16.40000,1.36667,540.97883,0.02383,2.38342,24.30623
16.60000,1.38341,544.54207,0.02415,2.41452,24.46632
16.80000,1.39997,548.01246,0.02446,2.44576,24.62225
17.00000,1.41659,551.67372,0.02475,2.47548,24.78675
17.20000,1.43333,555.64442,0.02507,2.50740,24.96515
17.40000,1.45001,559.35476,0.02539,2.53932,25.13186
17.60000,1.46664,561.89699,0.02567,2.56725,25.24608
17.80000,1.48326,565.50736,0.02599,2.59901,25.40830
18.00000,1.50000,569.35796,0.02632,2.63154,25.58130
18.20000,1.51656,572.31379,0.02663,2.66331,25.71411
18.40000,1.53330,576.37878,0.02696,2.69591,25.89675
18.60000,1.55004,579.65554,0.02729,2.72859,26.04398
18.80000,1.56666,583.12663,0.02761,2.76146,26.19993
19.00000,1.58341,586.81150,0.02794,2.79442,26.36549
19.20000,1.60003,589.58014,0.02828,2.82770,26.48989
19.40000,1.61665,592.46984,0.02860,2.86044,26.61972
19.60000,1.63339,594.22436,0.02890,2.88996,26.69855
19.80000,1.65001,597.74239,0.02923,2.92292,26.85662
20.00000,1.66663,601.06106,0.02956,2.95589,27.00573
20.20000,1.68325,603.82383,0.02989,2.98906,27.12986
20.40000,1.69993,607.16760,0.03022,3.02233,27.28009
20.60000,1.71668,609.82527,0.03056,3.07269,27.39950
20.80000,1.73330,612.15679,0.03089,3.13918,27.50426
21.00000,1.74992,615.83002,0.03123,3.20566,27.66930
21.20000,1.76666,618.37910,0.03157,3.27263,27.78383
21.40000,1.78334,620.74293,0.03191,3.33935,27.89004
21.60000,1.80002,623.94827,0.03225,3.40608,28.03405
21.80000,1.81676,625.68435,0.03256,3.47304,28.11205
22.00000,1.83339,628.41317,0.03289,3.53953,28.23466
22.20000,1.84995,630.74012,0.03323,3.60578,28.33921
22.40000,1.86669,633.73405,0.03357,3.67274,28.47373
22.60000,1.88337,636.32419,0.03391,3.73947,28.59010
22.80000,1.89993,638.27988,0.03426,3.80571,28.67797
23.00000,1.91667,641.16335,0.03434,3.87268,28.80753
23.20000,1.93335,643.39694,0.03514,3.93940,28.90788
23.40000,1.94997,647.47534,0.02970,4.00589,29.09112
23.60000,1.96666,651.57106,0.02088,4.07261,29.27515
23.80000,1.98340,649.74814,0.00781,4.13958,29.19324
24.00000,2.00008,651.90149,0.00905,4.20630,29.28999
24.20000,2.01664,654.01201,0.00790,4.27255,29.38482
24.40000,2.03338,656.24579,0.03062,4.33951,29.48518
24.60000,2.05000,658.53680,0.04415,4.40600,29.58812
24.80000,2.06662,660.72484,0.04523,4.47248,29.68643
25.00000,2.08325,662.95220,0.04596,4.53897,29.78650
25.20000,2.09999,664.76711,0.05024,4.60593,29.86805
25.40000,2.11661,667.63787,0.04996,4.67242,29.99703
25.60000,2.13329,670.15225,0.05254,4.73915,30.11000
25.80000,2.14991,670.74136,-0.03825,4.80563,30.13647
26.00000,2.16671,673.40294,-0.04178,4.87283,30.25605
26.20000,2.18339,676.47970,-0.04222,4.93956,30.39429
26.40000,2.20001,677.92083,-0.13912,5.00605,30.45904
26.60000,2.21670,679.88844,-0.13819,5.07277,30.54745
26.80000,2.23338,682.09954,-0.13820,5.13950,30.64679
27.00000,2.25000,682.60259,-0.13820,5.20598,30.66940
27.20000,2.26674,684.47930,-0.13820,5.27295,30.75372
27.40000,2.28336,686.52271,-0.13820,5.33943,30.84553
27.60000,2.29998,688.80850,-0.13821,5.40592,30.94823
27.80000,2.31666,690.74314,-0.13821,5.47264,31.03515
28.00000,2.33334,692.99550,-0.13821,5.53937,31.13635
28.20000,2.35003,694.04128,-0.13821,5.60609,31.18334
28.40000,2.36665,695.87068,-0.13822,5.67258,31.26553
28.60000,2.38327,697.63898,-0.13822,5.73906,31.34498
28.80000,2.39995,700.08943,-0.13822,5.80579,31.45508
29.00000,2.41663,702.14565,-0.13821,5.87252,31.54747
29.20000,2.43343,704.30981,-0.13822,5.93972,31.64470
29.40000,2.44999,705.28444,-0.13822,6.00597,31.68849
29.60000,2.46668,707.57098,-0.13822,6.07269,31.79123
29.80000,2.48342,709.09830,-0.13822,6.13965,31.85985
30.00000,2.49998,711.07894,-0.13822,6.20590,31.94884
30.20000,2.51666,712.49143,-0.13822,6.27263,32.01230
30.40000,2.53340,712.38931,-0.13822,6.33959,32.00771
30.60000,2.55002,714.32036,-0.13822,6.40608,32.09448
30.80000,2.56658,716.17840,-0.13822,6.47232,32.17796
31.00000,2.58326,717.58707,-0.13822,6.53905,32.24125
31.20000,2.60001,718.97600,-0.13822,6.60601,32.30365
31.40000,2.61663,721.21951,-0.13822,6.67250,32.40446
31.60000,2.63331,722.80103,-0.13822,6.73922,32.47551
31.80000,2.64999,723.91499,-0.13822,6.80595,32.52557
32.00000,2.66655,725.74411,-0.13823,6.87220,32.60775
32.20000,2.68335,727.72899,-0.13822,6.93940,32.69693
32.40000,2.70003,728.84131,-0.13822,7.00612,32.74691
32.60000,2.71671,730.75108,-0.13822,7.07285,32.83271
32.80000,2.73334,732.18336,-0.13823,7.13934,32.89706
33.00000,2.74996,733.61988,-0.13823,7.20582,32.96161
33.20000,2.76670,735.08988,-0.13823,7.27279,33.02765
33.40000,2.78338,736.61613,-0.13822,7.33951,33.09623
33.60000,2.80000,737.98518,-0.13823,7.40600,33.15774
33.80000,2.81668,739.69327,-0.13823,7.47272,33.23449
34.00000,2.83324,740.83912,-0.13823,7.53897,33.28597
34.20000,2.84993,740.43963,-0.13823,7.60569,33.26802
34.40000,2.86667,742.39452,-0.13822,7.67266,33.35585
34.60000,2.88341,744.15393,-0.13823,7.73962,33.43490
34.80000,2.90009,745.38323,-0.13823,7.80635,33.49014
35.00000,2.91665,746.85682,-0.13823,7.87259,33.55634
35.20000,2.93339,748.09282,-0.13823,7.93956,33.61188
35.40000,2.94989,749.71057,-0.13823,8.00556,33.68456
35.60000,2.96669,751.27399,-0.13823,8.07277,33.75481
35.80000,2.98344,752.25513,-0.13823,8.13973,33.79889
36.00000,2.99994,752.92140,-0.13823,8.20574,33.82883
36.20000,3.01656,754.34595,-0.13823,8.27223,33.89283
36.40000,3.03336,755.87262,-0.13823,8.33943,33.96143
36.60000,3.04998,756.93596,-0.13823,8.40591,34.00920
36.80000,3.06666,758.58887,-0.13823,8.47264,34.08347
37.00000,3.08340,759.85170,-0.13823,8.53961,34.14021
37.20000,3.10003,761.00319,-0.13823,8.60609,34.19194
37.40000,3.11665,762.29805,-0.13823,8.67258,34.25012
37.60000,3.13333,763.75240,-0.13823,8.73930,34.31546
37.80000,3.15013,764.75400,-0.13823,8.80650,34.36047
38.00000,3.16657,766.11512,-0.13823,8.87227,34.42162
38.20000,3.18325,767.34787,-0.13823,8.93900,34.47701
38.40000,3.19999,768.55537,-0.13823,9.00596,34.53126
38.60000,3.21661,768.89116,-0.13823,9.07245,34.54635
38.80000,3.23330,769.03114,-0.13823,9.13917,34.55264
39.00000,3.24998,770.60862,-0.13823,9.20590,34.62351
39.20000,3.26666,771.19539,-0.13823,9.27262,34.64988
39.40000,3.28328,772.86139,-0.13823,9.33911,34.72473
39.60000,3.29996,773.74331,-0.13823,9.40583,34.76435
39.80000,3.31670,775.14849,-0.13823,9.47280,34.82749
40.00000,3.33332,776.06733,-0.13823,9.53929,34.86877
40.20000,3.35007,776.67055,-0.13823,9.60625,34.89588
40.40000,3.36669,778.81259,-0.13823,9.67274,34.99212
40.60000,3.38331,779.01189,-0.13823,9.73922,35.00107
40.80000,3.39999,780.53311,-0.13823,9.80595,35.06942
41.00000,3.41673,781.13489,-0.13823,9.87291,35.09646
41.20000,3.43335,782.12256,-0.13823,9.93940,35.14083
41.40000,3.44991,783.29584,-0.13823,10.00564,35.19355
41.60000,3.46665,784.42628,-0.13823,10.07261,35.24434
41.80000,3.48334,785.72165,-0.13823,10.13933,35.30254
42.00000,3.49996,786.56301,-0.13823,10.20582,35.34035
42.20000,3.51670,787.76153,-0.13823,10.27278,35.39420
42.40000,3.53344,788.49560,-0.13823,10.33975,35.42718
42.60000,3.54994,789.43828,-0.13823,10.40575,35.46953
42.80000,3.56662,790.67163,-0.13823,10.47248,35.52495
43.00000,3.58348,791.27206,-0.13823,10.53992,35.55192
43.20000,3.59999,792.40343,-0.13823,10.60593,35.60276
43.40000,3.61655,793.16711,-0.13823,10.67218,35.63707
43.60000,3.63335,793.79259,-0.13823,10.73938,35.66517
43.80000,3.65003,795.28699,-0.13823,10.80611,35.73232
44.00000,3.66659,795.86385,-0.13823,10.87235,35.75823
44.20000,3.68333,795.43376,-0.13823,10.93932,35.73891
44.40000,3.70013,796.45840,-0.13823,11.00652,35.78495
44.60000,3.71657,797.38116,-0.13823,11.07229,35.82640
44.80000,3.73332,797.85557,-0.13823,11.13925,35.84772
45.00000,3.75012,799.53335,-0.13824,11.20646,35.92310
45.20000,3.76662,800.20064,-0.13823,11.27246,35.95309
45.40000,3.78324,801.01248,-0.13823,11.33895,35.98956
45.60000,3.80004,802.26837,-0.13824,11.40615,36.04599
45.80000,3.81672,802.49738,-0.13823,11.47288,36.05628
46.00000,3.83322,803.53944,-0.13823,11.53888,36.10310
46.20000,3.85002,804.34438,-0.13823,11.60609,36.13926
46.40000,3.86677,805.23882,-0.13823,11.67305,36.17945
46.60000,3.88333,806.17703,-0.13823,11.73930,36.22161
46.80000,3.89995,806.66021,-0.13823,11.80579,36.24331
47.00000,3.91669,807.37611,-0.13823,11.87275,36.27548
47.20000,3.93331,808.14390,-0.13823,11.93924,36.30998
47.40000,3.94999,809.01356,-0.13823,12.00596,36.34905
47.60000,3.96667,810.50694,-0.13823,12.07268,36.41615
47.80000,3.98324,810.85125,-0.13823,12.13893,36.43162
48.00000,3.99992,811.04729,-0.13823,12.20566,36.44043
48.20000,4.01666,812.58891,-0.13823,12.27262,36.50969
48.40000,4.03334,813.21113,-0.13823,12.33935,36.53765
48.60000,4.05002,814.15102,-0.13823,12.40607,36.57988
48.80000,4.06664,814.52643,-0.13823,12.47256,36.59674
49.00000,4.08338,815.65557,-0.13824,12.53952,36.64748
49.20000,4.09994,816.28393,-0.13823,12.60577,36.67571
49.40000,4.11663,816.40771,-0.13823,12.67249,36.68127
49.60000,4.13337,817.36380,-0.13824,12.73946,36.72423
49.80000,4.14999,818.20181,-0.13823,12.80594,36.76188
50.00000,4.16661,818.77876,-0.13823,12.87243,36.78780
50.20000,4.18335,819.52922,-0.13823,12.93939,36.82152
50.40000,4.19997,820.50115,-0.13824,13.00588,36.86519
50.60000,4.21671,820.58646,-0.13823,13.07284,36.86902
50.80000,4.23334,821.39987,-0.13823,13.13933,36.90557
51.00000,4.25002,822.55909,-0.13823,13.20606,36.95765
51.20000,4.26664,822.92091,-0.13823,13.27254,36.97391
51.40000,4.28332,824.20716,-0.13823,13.33927,37.03170
51.60000,4.30006,822.26796,-0.13823,13.40623,36.94457
51.80000,4.31662,823.11863,-0.13823,13.47248,36.98279
52.00000,4.33330,823.76432,-0.13823,13.53920,37.01180
52.20000,4.35004,824.86747,-0.13823,13.60617,37.06137
52.40000,4.36667,826.07111,-0.13823,13.67265,37.11545
52.60000,4.38329,826.65579,-0.13823,13.73914,37.14172
52.80000,4.39997,827.00429,-0.13823,13.80586,37.15738
53.00000,4.41677,827.58777,-0.13824,13.87307,37.18359
53.20000,4.43333,827.96449,-0.13824,13.93931,37.20052
53.40000,4.44995,829.22466,-0.13823,14.00580,37.25714
53.60000,4.46669,829.55873,-0.13824,14.07276,37.27215
53.80000,4.48331,829.47826,-0.13823,14.13925,37.26853
54.00000,4.50000,830.47822,-0.13824,14.20597,37.31346
54.20000,4.51662,831.59627,-0.13823,14.27246,37.36369
54.40000,4.53330,832.24270,-0.13823,14.33918,37.39274
54.60000,4.54998,832.56336,-0.13824,14.40591,37.40715
54.80000,4.56660,833.08155,-0.13823,14.47240,37.43043
55.00000,4.58340,833.89087,-0.13823,14.53960,37.46679
55.20000,4.60002,833.95867,-0.13823,14.60609,37.46984
55.40000,4.61665,834.68752,-0.13823,14.67257,37.50258
55.60000,4.63339,835.20049,-0.13824,14.73954,37.52563
55.80000,4.65001,835.41330,-0.13824,14.80602,37.53519
56.00000,4.66669,836.33410,-0.13824,14.87275,37.57656
56.20000,4.68343,837.33229,-0.13824,14.93971,37.62141
56.40000,4.69999,837.55217,-0.13823,15.00596,37.63129
56.60000,4.71667,837.40642,-0.13824,15.07268,37.62474
56.80000,4.73324,838.19265,-0.13824,15.13893,37.66007
57.00000,4.74998,839.30548,-0.13824,15.20589,37.71007
57.20000,4.76672,839.08653,-0.13823,15.27286,37.70023
57.40000,4.78328,839.41007,-0.13824,15.33910,37.71477
57.60000,4.80002,839.95713,-0.13824,15.40607,37.73935
57.80000,4.81664,840.82214,-0.13823,15.47256,37.77821
58.00000,4.83332,840.67071,-0.13824,15.53928,37.77141
58.20000,4.85012,841.19691,-0.13823,15.60648,37.79505
58.40000,4.86669,842.02234,-0.13824,15.67273,37.83214
58.60000,4.88337,842.94872,-0.13823,15.73946,37.87376
58.80000,4.89999,842.72726,-0.13823,15.80594,37.86381
59.00000,4.91661,843.45974,-0.13823,15.87242,37.89672
59.20000,4.93335,843.76251,-0.13824,15.93939,37.91032
59.40000,4.94997,843.99423,-0.13823,16.00588,37.92073
59.60000,4.96665,844.55283,-0.13824,16.07260,37.94584
59.80000,4.98327,844.76611,-0.13823,16.13909,37.95542
60.00000,4.99996,845.48853,-0.13824,16.20581,37.98787
60.20000,5.01670,845.58344,-0.13824,16.27278,37.99214
60.40000,5.03338,845.93268,-0.13824,16.33950,38.00783
60.60000,5.05000,846.51280,-0.13824,16.40599,38.03389
60.80000,5.06662,846.47061,-0.13824,16.47247,38.03200
61.00000,5.08330,846.91010,-0.13824,16.53920,38.05175
61.20000,5.09998,846.92864,-0.13824,16.60592,38.05258
61.40000,5.11667,847.60496,-0.13824,16.67265,38.08297
61.60000,5.13335,848.09754,-0.13824,16.73937,38.10510
61.80000,5.14997,848.76763,-0.13824,16.80586,38.13520
62.00000,5.16665,848.93359,-0.13823,16.87258,38.14266
62.20000,5.18333,848.87035,-0.13823,16.93931,38.13982
62.40000,5.20001,848.80805,-0.13824,17.00604,38.13702
62.60000,5.21669,849.59101,-0.13824,17.07276,38.17220
62.80000,5.23331,850.08768,-0.13824,17.13925,38.19452
63.00000,5.24994,850.66138,-0.13823,17.20573,38.22029
63.20000,5.26662,850.98557,-0.13824,17.27246,38.23486
63.40000,5.28336,851.15004,-0.13824,17.33942,38.24225
63.60000,5.30010,851.07684,-0.13823,17.40639,38.23896
63.80000,5.31666,851.53403,-0.13824,17.47263,38.25950
64.00000,5.33328,852.03703,-0.13824,17.53912,38.28210
64.20000,5.35002,851.64672,-0.13824,17.60608,38.26456
64.40000,5.36664,850.25048,-0.13824,17.67257,38.20183
64.60001,5.38333,850.80760,-0.13824,17.73929,38.22686
64.80000,5.40007,851.10571,-0.13824,17.80626,38.24025
65.00000,5.41663,851.92984,-0.13824,17.87250,38.27728
65.20000,5.43325,851.92164,-0.13823,17.93899,38.27692
65.40000,5.44999,852.33646,-0.13823,18.00596,38.29555
65.60001,5.46667,853.25409,-0.13823,18.07268,38.33678
65.80000,5.48335,853.42601,-0.13824,18.13940,38.34451
66.00000,5.50004,853.65856,-0.13824,18.20613,38.35495
66.20001,5.51666,854.41871,-0.13824,18.27262,38.38911
66.40000,5.53334,854.61577,-0.13824,18.33934,38.39796
66.60001,5.55002,854.66653,-0.13824,18.40607,38.40024
66.80000,5.56676,854.84525,-0.13824,18.47303,38.40827
67.00000,5.58332,855.14281,-0.13824,18.53928,38.42164
67.20001,5.60000,855.87772,-0.13823,18.60600,38.45466
67.40000,5.61668,855.53834,-0.13824,18.67273,38.43941
67.60001,5.63331,856.08019,-0.13824,18.73921,38.46376
67.80000,5.64999,856.04982,-0.13824,18.80594,38.46239
68.00000,5.66661,856.48214,-0.13824,18.87242,38.48182
68.20001,5.68329,856.54939,-0.13824,18.93915,38.48484
68.40000,5.69997,856.30538,-0.13824,19.00587,38.47388
68.60001,5.71665,856.82711,-0.13824,19.07260,38.49732
68.80000,5.73333,857.11898,-0.13824,19.13933,38.51043
69.00000,5.75002,857.29081,-0.13824,19.20605,38.51815
69.20001,5.76664,857.95512,-0.13824,19.27253,38.54800
69.40000,5.78338,857.94237,-0.13824,19.33950,38.54743
69.60001,5.79994,857.79326,-0.13824,19.40575,38.54073
69.80000,5.81668,857.88211,-0.13824,19.47271,38.54472
70.00000,5.83336,858.27764,-0.13824,19.53944,38.56249
70.20001,5.84998,858.60770,-0.13824,19.60592,38.57732
70.40000,5.86654,858.97772,-0.13824,19.67217,38.59394
70.60001,5.88323,858.91550,-0.13824,19.73889,38.59115
70.80000,5.90003,859.25562,-0.13824,19.80610,38.60643
71.00000,5.91671,859.13222,-0.13824,19.87282,38.60089
71.20001,5.93327,859.41246,-0.13824,19.93907,38.61348
71.40000,5.95007,859.35220,-0.13824,20.00627,38.61077
71.60001,5.96663,859.83109,-0.13824,20.07252,38.63229
71.80000,5.98331,859.50065,-0.13824,20.13925,38.61744
72.00000,6.00011,859.92431,-0.13824,20.20645,38.63647
72.20001,6.01668,860.56488,-0.13824,20.27269,38.66526
72.40000,6.03330,860.49587,-0.13824,20.33918,38.66216
72.60001,6.04998,860.50062,-0.13824,20.40590,38.66237
72.80000,6.06672,860.61275,-0.13824,20.47287,38.66741
73.00000,6.08328,860.83803,-0.13823,20.53912,38.67753
73.20001,6.09996,861.02914,-0.13824,20.60584,38.68612
73.40000,6.11676,860.63780,-0.13824,20.67304,38.66853
73.60001,6.13327,860.61470,-0.13824,20.73905,38.66750
73.80000,6.14995,861.25731,-0.13824,20.80578,38.69637
74.00000,6.16675,861.78062,-0.13824,20.87298,38.71988
74.20001,6.18337,860.84772,-0.13824,20.93947,38.67796
74.40000,6.19999,861.37354,-0.13824,21.00595,38.70159
74.60001,6.21667,861.20535,-0.13824,21.07268,38.69403
74.80000,6.23335,861.59566,-0.13824,21.13940,38.71157
75.00000,6.24991,861.90030,-0.13824,21.20565,38.72526
75.20001,6.26666,861.39739,-0.13824,21.27261,38.70266
75.40000,6.28340,862.01355,-0.13824,21.33958,38.73035
75.60001,6.29990,861.47431,-0.13824,21.40559,38.70612
75.80000,6.31658,862.00414,-0.13824,21.47231,38.72992
76.00000,6.33338,862.01057,-0.13824,21.53951,38.73021
76.20001,6.34994,861.90039,-0.13824,21.60576,38.72526
76.40000,6.36674,862.30570,-0.13824,21.67297,38.74347
76.60001,6.38337,862.33532,-0.13824,21.73945,38.74480
76.80000,6.39999,862.89374,-0.13824,21.80593,38.76989
77.00000,6.41661,862.06319,-0.13824,21.87242,38.73257
77.20001,6.43329,862.37462,-0.13824,21.93915,38.74657
77.40000,6.45003,862.76196,-0.13824,22.00611,38.76397
77.60001,6.46665,862.38086,-0.13824,22.07260,38.74685
77.80000,6.48327,862.25728,-0.13824,22.13908,38.74129
78.00000,6.50007,863.25863,-0.13824,22.20629,38.78629
78.20001,6.51664,863.07814,-0.13823,22.27253,38.77818
78.40000,6.53326,862.91982,-0.13824,22.33902,38.77106
78.60001,6.55012,863.17807,-0.13823,22.40646,38.78267
78.80000,6.56674,863.41929,-0.13824,22.47295,38.79351
79.00000,6.58330,863.05998,-0.13824,22.53919,38.77736
79.20001,6.59998,862.52457,-0.13824,22.60592,38.75330
79.40000,6.61672,863.13067,-0.13824,22.67288,38.78054
79.60001,6.63329,863.35344,-0.13824,22.73913,38.79055
79.80000,6.65003,863.32671,-0.13824,22.80609,38.78934
80.00000,6.66677,863.62073,-0.13824,22.87306,38.80256
80.20001,6.68327,863.28667,-0.13824,22.93907,38.78755
80.40000,6.69995,863.35158,-0.13824,23.00579,38.79046
80.60001,6.71681,862.93304,-0.13824,23.07324,38.77166
80.80000,6.73331,863.16699,-0.13824,23.13924,38.78217
81.00001,6.74987,863.41500,-0.13824,23.20549,38.79331
81.20001,6.76668,863.16913,-0.13824,23.27269,38.78226
81.40000,6.78336,863.46352,-0.13824,23.33942,38.79549
81.60001,6.79992,863.39908,-0.13824,23.40567,38.79260
81.80000,6.81666,863.54250,-0.13824,23.47263,38.79904
82.00001,6.83328,863.18571,-0.13824,23.53912,38.78301
82.20001,6.84990,863.17854,-0.13824,23.60560,38.78269
82.40000,6.86664,863.54874,-0.13824,23.67256,38.79932
82.60001,6.88332,863.35279,-0.13824,23.73929,38.79052
82.80000,6.90001,863.21086,-0.13824,23.80601,38.78414
83.00001,6.91669,863.37961,-0.13824,23.87274,38.79172
83.20001,6.93331,863.11102,-0.13824,23.93923,38.77966
83.40000,6.94999,863.27791,-0.13824,24.00595,38.78715
83.60001,6.96661,863.62744,-0.13824,24.07244,38.80286
83.80000,6.98329,863.40308,-0.13824,24.13916,38.79278
84.00001,7.00003,862.74566,-0.13824,24.20613,38.76324
84.20001,7.01666,863.74320,-0.13824,24.27261,38.80806
84.40000,7.03334,863.30567,-0.13824,24.33933,38.78840
84.60001,7.05002,863.49268,-0.13824,24.40606,38.79680
84.80000,7.06670,863.12275,-0.13824,24.47279,38.78018
85.00001,7.08338,863.04536,-0.13824,24.53951,38.77670
85.20001,7.10006,862.92317,-0.13824,24.60624,38.77121
85.40000,7.11668,863.08643,-0.13824,24.67272,38.77855
85.60001,7.13330,863.40141,-0.13824,24.73921,38.79270
85.80000,7.14999,863.44797,-0.13824,24.80593,38.79479
86.00001,7.16673,863.61133,-0.13824,24.87290,38.80213
86.20001,7.18329,862.93407,-0.13824,24.93914,38.77171
86.40000,7.19997,862.64564,-0.13824,25.00587,38.75874
86.60001,7.21671,862.92792,-0.13824,25.07284,38.77143
86.80000,7.23327,862.81803,-0.13824,25.13908,38.76649
87.00001,7.25001,862.81709,-0.13824,25.20604,38.76645
87.20001,7.26681,862.33933,-0.13824,25.27325,38.74498
87.40000,7.28332,862.61733,-0.13824,25.33926,38.75747
87.60001,7.29994,862.62031,-0.13824,25.40574,38.75761
87.80000,7.31668,862.68373,-0.13824,25.47271,38.76046
88.00001,7.33336,862.51656,-0.13824,25.53943,38.75294
88.20001,7.34992,863.21002,-0.13824,25.60568,38.78410
88.40000,7.36660,862.61900,-0.13824,25.67240,38.75755
88.60001,7.38334,862.70273,-0.13824,25.73937,38.76131
88.80000,7.39991,862.48033,-0.13824,25.80561,38.75132
89.00001,7.41665,862.18659,-0.13824,25.87258,38.73812
89.20001,7.43339,862.39316,-0.13824,25.93954,38.74740
89.40000,7.45007,862.10733,-0.13824,26.00627,38.73456
89.60001,7.46669,862.13872,-0.13824,26.07276,38.73597
89.80000,7.48337,862.50538,-0.13824,26.13948,38.75244
90.00001,7.49999,862.61211,-0.13824,26.20597,38.75724
90.20001,7.51673,861.94528,-0.13824,26.27293,38.72728
90.40000,7.53336,862.44596,-0.13824,26.33941,38.74977
90.60001,7.55004,861.70584,-0.13824,26.40614,38.71652
90.80000,7.56666,861.97676,-0.13824,26.47263,38.72869
91.00001,7.58328,861.06621,-0.13824,26.53911,38.68778
91.20001,7.60002,861.45913,-0.13824,26.60608,38.70544
91.40000,7.61670,861.37662,-0.13824,26.67280,38.70173
91.60001,7.63332,861.20255,-0.13824,26.73929,38.69391
91.80000,7.64995,861.33722,-0.13824,26.80577,38.69996
92.00001,7.66669,861.49257,-0.13824,26.87274,38.70694
92.20001,7.68331,861.71618,-0.13824,26.93923,38.71698
92.40000,7.69999,860.83570,-0.13824,27.00595,38.67743
92.60001,7.71673,860.89550,-0.13824,27.07291,38.68011
92.80000,7.73335,861.36498,-0.13824,27.13940,38.70121
93.00001,7.74991,860.81559,-0.13824,27.20565,38.67652
93.20001,7.76666,861.16511,-0.13824,27.27261,38.69223
93.40000,7.78322,860.70225,-0.13824,27.33886,38.67143
93.60001,7.80002,860.90742,-0.13824,27.40606,38.68064
93.80000,7.81670,860.90537,-0.13824,27.47279,38.68055
94.00001,7.83326,860.73261,-0.13824,27.53903,38.67279
94.20001,7.84994,860.12771,-0.13824,27.60575,38.64561
94.40000,7.86668,860.49177,-0.13824,27.67272,38.66197
94.60001,7.88342,860.17884,-0.13824,27.73969,38.64791
94.80000,7.90005,860.49400,-0.13824,27.80617,38.66207
95.00001,7.91661,860.30653,-0.13824,27.87242,38.65365
95.20001,7.93335,859.65516,-0.13824,27.93938,38.62438
95.40000,7.94997,860.41577,-0.13824,28.00587,38.65856
95.60001,7.96665,859.02549,-0.13824,28.07259,38.59609
95.80000,7.98333,859.12896,-0.13824,28.13931,38.60074
96.00001,7.99995,859.57330,-0.13824,28.20580,38.62070
96.20001,8.01663,858.75439,-0.13824,28.27253,38.58391
96.40000,8.03326,858.77236,-0.13824,28.33901,38.58472
96.60001,8.05000,858.66991,-0.13824,28.40598,38.58012
96.80000,8.06668,858.94177,-0.13824,28.47270,38.59233
97.00001,8.08324,858.96226,-0.13824,28.53895,38.59325
97.20001,8.09998,859.21204,-0.13824,28.60591,38.60447
97.40000,8.11660,858.41939,-0.13824,28.67240,38.56886
97.60001,8.13334,858.59988,-0.13824,28.73936,38.57697
97.80000,8.15003,858.21906,-0.13824,28.80609,38.55986
98.00001,8.16671,858.13012,-0.13824,28.87281,38.55586
98.20001,8.18339,857.48639,-0.13824,28.93954,38.52694
98.40000,8.20001,857.81729,-0.13824,29.00603,38.54181
98.60001,8.21669,857.57561,-0.13824,29.07275,38.53095
98.80000,8.23337,857.94413,-0.13824,29.13947,38.54750
99.00001,8.24999,857.36960,-0.13824,29.20596,38.52169
99.20001,8.26667,857.46367,-0.13824,29.27269,38.52592
99.40000,8.28330,857.39521,-0.13824,29.33917,38.52284
99.60001,8.29986,857.53165,-0.13824,29.40542,38.52897
99.80000,8.31672,857.13184,-0.13824,29.47286,38.51101
100.00001,8.33334,856.40084,-0.13824,29.53935,38.47816
100.20001,8.35002,857.04867,-0.13824,29.60607,38.50727
100.40000,8.36664,855.94011,-0.13824,29.67256,38.45747
100.60001,8.38332,856.30501,-0.13824,29.73928,38.47386
100.80000,8.40000,856.36526,-0.13824,29.80601,38.47657
101.00001,8.41669,855.34193,-0.13824,29.87273,38.43059
101.20001,8.43337,855.74333,-0.13824,29.93946,38.44862
101.40000,8.44993,855.63697,-0.13824,30.00571,38.44384
101.60001,8.46667,855.39026,-0.13824,30.07267,38.43276
101.80000,8.48341,855.00646,-0.13824,30.13963,38.41552
102.00001,8.49991,855.39725,-0.13824,30.20564,38.43307
102.20001,8.51665,855.47473,-0.13824,30.27261,38.43655
102.40000,8.53340,853.95975,-0.13824,30.33957,38.36849
102.60001,8.55002,854.75435,-0.13824,30.40605,38.40419
102.80000,8.56658,854.78621,-0.13824,30.47230,38.40562
103.00001,8.58338,854.04217,-0.13824,30.53951,38.37219
103.20001,8.60006,854.17721,-0.13824,30.60623,38.37826
103.40000,8.61668,853.79053,-0.13824,30.67272,38.36089
103.60001,8.63330,853.79807,-0.13824,30.73921,38.36122
103.80000,8.65004,853.32692,-0.13824,30.80617,38.34005
104.00001,8.66667,853.21320,-0.13824,30.87265,38.33495
104.20001,8.68329,853.10992,-0.13824,30.93914,38.33030
104.40000,8.69997,853.40356,-0.13824,31.00586,38.34350
104.60001,8.71653,853.22047,-0.13824,31.07211,38.33527
104.80000,8.73327,852.56938,-0.13824,31.13908,38.30602
105.00001,8.75001,852.25897,-0.13824,31.20604,38.29207
105.20001,8.76669,852.59927,-0.13824,31.27277,38.30736
105.40000,8.78337,852.52877,-0.13824,31.33949,38.30419
105.60001,8.80000,851.94632,-0.13824,31.40598,38.27802
105.80000,8.81668,851.49854,-0.13824,31.47270,38.25790
106.00001,8.83330,850.71605,-0.13824,31.53919,38.22275
106.20001,8.84998,850.82371,-0.13824,31.60591,38.22758
106.40000,8.86678,851.05710,-0.13824,31.67312,38.23807
106.60001,8.88334,850.93742,-0.13824,31.73936,38.23269
106.80000,8.89990,850.89495,-0.13824,31.80561,38.23079
107.00001,8.91665,850.61621,-0.13824,31.87258,38.21826
107.20001,8.93327,850.22384,-0.13824,31.93906,38.20063
107.40000,8.94995,849.91977,-0.13824,32.00578,38.18697
107.60001,8.96675,849.58542,-0.13824,32.07299,38.17195
107.80000,8.98337,848.86691,-0.13824,32.13947,38.13966
108.00001,8.99993,848.90127,-0.13824,32.20572,38.14121
108.20001,9.01667,849.04684,-0.13824,32.27268,38.14775
108.40000,9.03341,848.74826,-0.13824,32.33965,38.13433
108.60001,9.04998,848.27617,-0.13824,32.40589,38.11312
108.80000,9.06666,847.78359,-0.13824,32.47262,38.09099
109.00001,9.08340,847.93558,-0.13824,32.53959,38.09782
109.20001,9.09996,847.87207,-0.13824,32.60583,38.09497
109.40000,9.11658,846.96533,-0.13824,32.67232,38.05423
109.60001,9.13338,847.37707,-0.13824,32.73952,38.07273
109.80000,9.15000,847.27425,-0.13824,32.80601,38.06811
110.00001,9.16657,846.34293,-0.13824,32.87225,38.02626
110.20001,9.18331,846.34125,-0.13824,32.93922,38.02619
110.40000,9.20005,846.12304,-0.13824,33.00618,38.01638
110.60001,9.21667,845.60867,-0.13824,33.07267,37.99327
110.80000,9.23335,845.15624,-0.13824,33.13939,37.97295
111.00001,9.25003,844.62026,-0.13824,33.20612,37.94886
111.20001,9.26665,845.24704,-0.13824,33.27260,37.97702
111.40000,9.28328,844.78538,-0.13824,33.33909,37.95628
111.60001,9.30002,844.34152,-0.13824,33.40605,37.93634
111.80000,9.31664,843.36940,-0.13824,33.47254,37.89266
112.00001,9.33332,843.13778,-0.13824,33.53927,37.88226
112.20001,9.35000,843.16870,-0.13824,33.60599,37.88364
112.40000,9.36662,842.71347,-0.13824,33.67248,37.86319
112.60001,9.38330,842.52711,-0.13824,33.73920,37.85482
112.80000,9.39998,842.49303,-0.13824,33.80593,37.85329
113.00001,9.41679,841.87398,-0.13824,33.87313,37.82547
113.20001,9.43329,841.39546,-0.13824,33.93914,37.80397
113.40001,9.44997,840.98857,-0.13824,34.00586,37.78569
113.60001,9.46671,841.35206,-0.13824,34.07283,37.80202
113.80000,9.48339,840.83220,-0.13824,34.13955,37.77866
114.00001,9.50001,840.06870,-0.13824,34.20604,37.74436
114.20001,9.51663,839.85794,-0.13824,34.27252,37.73489
114.40001,9.53332,839.26748,-0.13824,34.33925,37.70836
114.60001,9.55000,839.36667,-0.13824,34.40597,37.71282
114.80000,9.56668,838.44773,-0.13824,34.47270,37.67153
115.00001,9.58342,838.00163,-0.13824,34.53966,37.65149
115.20001,9.59998,837.18998,-0.13824,34.60591,37.61502
115.40001,9.61660,837.67893,-0.13824,34.67239,37.63699
115.60001,9.63340,837.36237,-0.13824,34.73960,37.62276
115.80000,9.64990,836.79352,-0.13824,34.80561,37.59721
116.00001,9.66671,836.45387,-0.13824,34.87281,37.58195
116.20001,9.68333,835.87607,-0.13824,34.93930,37.55598
116.40001,9.70001,835.25861,-0.13824,35.00602,37.52824
116.60001,9.71663,835.34224,-0.13824,35.07251,37.53200
116.80000,9.73331,834.84612,-0.13824,35.13923,37.50971
117.00001,9.75005,834.00905,-0.13825,35.20620,37.47210
117.20001,9.76667,834.16970,-0.13824,35.27268,37.47932
117.40001,9.78329,832.64783,-0.13824,35.33917,37.41094
117.60001,9.79998,833.00341,-0.13824,35.40589,37.42692
117.80000,9.81660,832.84797,-0.13824,35.47238,37.41993
118.00001,9.83322,831.70859,-0.13824,35.53886,37.36874
118.20001,9.85002,831.39529,-0.13824,35.60607,37.35466
118.40001,9.86664,830.70137,-0.13824,35.67255,37.32349
118.60001,9.88332,830.10131,-0.13824,35.73928,37.29652
118.80000,9.89994,830.29876,-0.13824,35.80576,37.30540
119.00001,9.91668,829.11598,-0.13824,35.87273,37.25225
119.20001,9.93337,829.05320,-0.13824,35.93946,37.24944
119.40001,9.95005,828.26596,-0.13824,36.00618,37.21406
119.60001,9.96673,828.14675,-0.13824,36.07290,37.20871
119.80000,9.98329,827.54521,-0.13824,36.13915,37.18168
120.00001,9.99991,826.71074,-0.13824,36.20564,37.14419
120.20001,10.01665,826.66259,-0.13824,36.27260,37.14202
120.40001,10.03333,825.18551,-0.13824,36.33933,37.07566
120.60001,10.05001,824.89066,-0.13824,36.40605,37.06241
120.80000,10.06664,824.76353,-0.13824,36.47254,37.05670
121.00001,10.08332,823.78583,-0.13824,36.53927,37.01277
121.20001,10.10000,823.29791,-0.13825,36.60598,36.99085
121.40001,10.11668,823.39719,-0.13824,36.67271,36.99531
121.60001,10.13336,822.32030,-0.13824,36.73944,36.94692
121.80000,10.14998,821.52365,-0.13824,36.80592,36.91113
122.00001,10.16660,821.81208,-0.13824,36.87241,36.92409
122.20001,10.18341,819.95204,-0.13824,36.93961,36.84052
122.40001,10.20003,819.48880,-0.13824,37.00610,36.81971
122.60001,10.21671,819.28587,-0.13824,37.07282,36.81059
122.80000,10.23333,817.97419,-0.13824,37.13931,36.75165
123.00001,10.24995,818.30965,-0.13824,37.20579,36.76672
123.20001,10.26657,817.96702,-0.13824,37.27228,36.75133
123.40001,10.28337,817.18331,-0.13824,37.33948,36.71612
123.60001,10.30011,816.42689,-0.13824,37.40645,36.68213
123.80000,10.31662,815.48356,-0.13824,37.47245,36.63975
124.00001,10.33330,814.85119,-0.13824,37.53918,36.61134
124.20001,10.35004,814.42073,-0.13824,37.60615,36.59200
124.40001,10.36666,813.16056,-0.13825,37.67263,36.53538
124.60001,10.38340,813.14892,-0.13824,37.73960,36.53485
124.80000,10.40002,811.21940,-0.13824,37.80608,36.44816
125.00001,10.41658,811.78108,-0.13824,37.87233,36.47340
125.20001,10.43327,810.67281,-0.13824,37.93905,36.42360
125.40001,10.44995,810.05525,-0.13825,38.00578,36.39585
125.60001,10.46663,809.52924,-0.13824,38.07250,36.37222
125.80000,10.48331,808.42534,-0.13824,38.13923,36.32262
126.00001,10.49999,807.69323,-0.13824,38.20595,36.28973
126.20001,10.51661,806.92712,-0.13824,38.27244,36.25531
126.40001,10.53329,806.12730,-0.13825,38.33916,36.21937
126.60001,10.54998,805.84064,-0.13824,38.40589,36.20649
126.80000,10.56666,804.45055,-0.13824,38.47262,36.14404
127.00001,10.58334,803.44137,-0.13824,38.53934,36.09869
127.20001,10.59996,802.79838,-0.13824,38.60583,36.06980
127.40001,10.61658,801.89407,-0.13824,38.67231,36.02917
127.60001,10.63326,801.12759,-0.13825,38.73903,35.99473
127.80000,10.65000,800.62067,-0.13824,38.80600,35.97196
128.00000,10.66668,799.21624,-0.13824,38.87273,35.90886
128.20002,10.68337,797.78917,-0.13824,38.93945,35.84474
128.40001,10.69993,797.36244,-0.13825,39.00570,35.82557
128.60001,10.71661,796.16793,-0.13824,39.07242,35.77190
128.80000,10.73341,795.13770,-0.13825,39.13963,35.72561
129.00000,10.75003,794.63273,-0.13824,39.20611,35.70292
129.20002,10.76665,793.75422,-0.13824,39.27260,35.66345
129.40001,10.78333,791.59858,-0.13825,39.33932,35.56659
129.60001,10.79996,790.86870,-0.13825,39.40581,35.53380
129.80000,10.81664,790.49254,-0.13825,39.47254,35.51690
130.00000,10.83338,789.26776,-0.13825,39.53950,35.46187
130.20002,10.85006,788.13313,-0.13824,39.60622,35.41089
130.40001,10.86662,787.02150,-0.13824,39.67247,35.36095
130.60001,10.88324,785.51453,-0.13824,39.73895,35.29324
130.80000,10.90010,784.71452,-0.13824,39.80640,35.25729
131.00000,10.91666,783.10296,-0.13825,39.87265,35.18489
131.20002,10.93323,782.02533,-0.13824,39.93889,35.13647
131.40002,10.94997,780.43384,-0.13824,40.00586,35.06496
131.60000,10.96659,779.91751,-0.13825,40.07235,35.04176
131.80000,10.98333,778.14739,-0.13824,40.13931,34.96223
132.00000,11.00007,776.60475,-0.13824,40.20627,34.89292
132.20002,11.01675,776.07059,-0.13824,40.27299,34.86892
132.40002,11.03331,773.80454,-0.13825,40.33924,34.76711
132.60000,11.04999,772.33361,-0.13824,40.40597,34.70102
132.80000,11.06668,771.47242,-0.13825,40.47269,34.66232
133.00000,11.08330,770.03730,-0.13825,40.53918,34.59784
133.20002,11.10004,768.38476,-0.13824,40.60615,34.52359
133.40002,11.11666,766.98898,-0.13824,40.67263,34.46088
133.60000,11.13322,765.65514,-0.13824,40.73888,34.40096
133.80000,11.14996,762.83095,-0.13825,40.80584,34.27406
134.00000,11.16670,761.89162,-0.13824,40.87280,34.23186
134.20002,11.18339,760.33007,-0.13825,40.93953,34.16170
134.40002,11.20007,758.11371,-0.13824,41.00626,34.06211
134.60000,11.21663,756.18671,-0.13824,41.07250,33.97554
134.80000,11.23337,753.64136,-0.13824,41.13947,33.86117
135.00000,11.24999,751.93145,-0.13824,41.20595,33.78435
135.20002,11.26661,749.04542,-0.13824,41.27244,33.65468
135.40002,11.28347,746.11865,-0.13824,41.33988,33.52318
135.60000,11.29998,743.10461,-0.13824,41.40589,33.38776
135.80000,11.31660,740.11097,-0.13824,41.47237,33.25325
136.00000,11.33340,736.90936,-0.13824,41.53958,33.10940
136.20002,11.35002,733.43795,-0.13824,41.60607,32.95343
136.40002,11.36664,728.92844,-0.13824,41.67255,32.75082
136.60000,11.38332,724.72673,-0.13824,41.73927,32.56203
136.80000,11.40006,718.17446,-0.13824,41.80624,32.26764
137.00000,11.41662,711.31978,-0.13824,41.87248,31.95966
137.20002,11.43330,702.67790,-0.13825,41.93921,31.57138
137.40002,11.45017,691.28349,-0.13825,42.00665,31.05943
137.60000,11.46667,674.68984,-0.13824,42.07266,30.31388
137.73202,11.47779,3.44625,-0.13824,42.11714,0.15484