File: Manufatura Aditiva/Classificação Orientação/Ensaios/Ensaios FDM/Tracao_OLABI_28_05_2018_FDM_ZY4.is_metal_RawData/Specimen_RawData_4.csv
Time,Extension,Load,Strain 1,Tensile strain,Tensile stress
(sec),(mm),(N),(mm/mm),(%),(MPa)
0.00000,0.00006,-1.28208,0.00000,-0.00029,-0.06677
0.10000,0.00407,0.71430,0.00003,0.00264,0.03720
0.20000,0.01369,3.60125,0.00017,0.01701,0.18757
0.30000,0.02350,8.09874,0.00033,0.03280,0.42181
0.40000,0.03259,11.78286,0.00047,0.04702,0.61369
0.50000,0.04143,14.87009,0.00061,0.06125,0.77448
0.60000,0.04986,17.50103,0.00074,0.07382,0.91151
0.70000,0.05823,20.79522,0.00087,0.08714,1.08308
0.80000,0.06667,23.84668,0.00100,0.10042,1.24201
0.90000,0.07498,27.38603,0.00114,0.11355,1.42636
1.00000,0.08323,30.19031,0.00126,0.12638,1.57241
1.10000,0.09172,33.31794,0.00140,0.14013,1.73531
1.20000,0.10003,36.45296,0.00153,0.15318,1.89859
1.30000,0.10834,40.51226,0.00167,0.16671,2.11001
1.40000,0.11677,43.42751,0.00180,0.18038,2.26185
1.50000,0.12508,46.53664,0.00194,0.19379,2.42378
1.60000,0.13339,49.37555,0.00207,0.20735,2.57164
1.70000,0.14170,52.91918,0.00221,0.22067,2.75621
1.80000,0.14995,55.86368,0.00233,0.23347,2.90957
1.90000,0.15832,58.84690,0.00247,0.24702,3.06494
2.00000,0.16663,61.42720,0.00260,0.26024,3.19933
2.10000,0.17494,64.75901,0.00274,0.27439,3.37287
2.20000,0.18325,68.18812,0.00288,0.28807,3.55146
2.30000,0.19163,71.03651,0.00302,0.30202,3.69982
2.40000,0.20000,74.20531,0.00315,0.31500,3.86486
2.50000,0.20837,77.70180,0.00329,0.32869,4.04697
2.60000,0.21668,80.64684,0.00342,0.34234,4.20036
2.70000,0.22499,84.23266,0.00356,0.35559,4.38712
2.80000,0.23336,87.38869,0.00369,0.36909,4.55149
2.90000,0.24161,90.35444,0.00383,0.38267,4.70596
3.00000,0.24998,93.31230,0.00397,0.39655,4.86002
3.10000,0.25841,96.25137,0.00411,0.41075,5.01309
3.20000,0.26672,99.10535,0.00424,0.42436,5.16174
3.30000,0.27503,102.34675,0.00438,0.43829,5.33056
3.40000,0.28340,106.00948,0.00452,0.45177,5.52133
3.50000,0.29165,107.83677,0.00465,0.46481,5.61650
3.60000,0.30002,111.56170,0.00479,0.47908,5.81051
3.70000,0.30839,114.96403,0.00493,0.49292,5.98771
3.80000,0.31670,117.37559,0.00507,0.50681,6.11331
3.90000,0.32502,120.05514,0.00520,0.52050,6.25287
4.00000,0.33339,123.62780,0.00535,0.53458,6.43895
4.10000,0.34164,126.63085,0.00548,0.54824,6.59536
4.20000,0.35001,129.37540,0.00562,0.56189,6.73830
4.30000,0.35832,132.61411,0.00576,0.57572,6.90698
4.40000,0.36663,135.80092,0.00590,0.58989,7.07296
4.50000,0.37500,138.26672,0.00603,0.60331,7.20139
4.60000,0.38331,141.73357,0.00618,0.61785,7.38196
4.70000,0.39162,144.76124,0.00631,0.63100,7.53965
4.80000,0.40005,147.81300,0.00645,0.64483,7.69859
4.90000,0.40836,150.63625,0.00659,0.65865,7.84564
5.00000,0.41661,153.70634,0.00673,0.67269,8.00554
5.10000,0.42504,156.61111,0.00686,0.68646,8.15683
5.20000,0.43329,159.92821,0.00701,0.70055,8.32959
5.30000,0.44155,162.65902,0.00714,0.71437,8.47182
5.40000,0.45010,165.84398,0.00728,0.72827,8.63771
5.50000,0.45829,168.52476,0.00742,0.74199,8.77733
5.60000,0.46666,171.24679,0.00756,0.75563,8.91910
5.70000,0.47509,174.90934,0.00770,0.77007,9.10986
5.80000,0.48328,177.30367,0.00784,0.78384,9.23457
5.90000,0.49159,179.89221,0.00798,0.79757,9.36939
6.00000,0.50008,183.08451,0.00812,0.81173,9.53565
6.10000,0.50827,186.04398,0.00827,0.82650,9.68979
6.20000,0.51664,188.80896,0.00840,0.84004,9.83380
6.30000,0.52507,192.39340,0.00855,0.85458,10.02049
6.40000,0.53332,194.98529,0.00868,0.86777,10.15548
6.50000,0.54169,198.09376,0.00882,0.88199,10.31738
6.60000,0.55000,200.87140,0.00896,0.89633,10.46205
6.70000,0.55825,204.02102,0.00910,0.91010,10.62609
6.80000,0.56674,205.88806,0.00924,0.92421,10.72334
6.90000,0.57506,209.89913,0.00939,0.93871,10.93225
7.00000,0.58331,212.77131,0.00953,0.95251,11.08184
7.10000,0.59174,215.18180,0.00967,0.96712,11.20739
7.20000,0.59999,218.10464,0.00981,0.98060,11.35962
7.30000,0.60824,220.84666,0.00994,0.99418,11.50243
7.40000,0.61673,224.18059,0.01009,1.00896,11.67607
7.50000,0.62498,227.15877,0.01023,1.02284,11.83119
7.60000,0.63323,229.51441,0.01037,1.03700,11.95388
7.70000,0.64166,232.49448,0.01051,1.05062,12.10909
7.80000,0.64997,235.39984,0.01064,1.06438,12.26041
7.90000,0.65828,237.96172,0.01079,1.07859,12.39384
8.00000,0.66671,241.10221,0.01093,1.09289,12.55741
8.10000,0.67496,244.04470,0.01107,1.10713,12.71066
8.20000,0.68327,246.29566,0.01120,1.12045,12.82790
8.30000,0.69170,249.16104,0.01135,1.13509,12.97714
8.40000,0.70002,252.62958,0.01149,1.14861,13.15779
8.50000,0.70839,254.82846,0.01162,1.16240,13.27232
8.60000,0.71664,257.95356,0.01177,1.17669,13.43508
8.70000,0.72501,261.07205,0.01191,1.19057,13.59750
8.80000,0.73338,263.21134,0.01205,1.20472,13.70892
8.90000,0.74169,266.27732,0.01219,1.21931,13.86861
9.00000,0.75000,269.02552,0.01233,1.23346,14.01175
9.10000,0.75837,272.18335,0.01248,1.24759,14.17622
9.20000,0.76662,274.87194,0.01261,1.26129,14.31625
9.30000,0.77493,277.32635,0.01275,1.27539,14.44408
9.40000,0.78336,280.82987,0.01290,1.28967,14.62656
9.50000,0.79167,283.23676,0.01303,1.30342,14.75191
9.60000,0.79992,286.21296,0.01318,1.31804,14.90693
9.70000,0.80835,288.94227,0.01332,1.33248,15.04908
9.80000,0.81666,291.52560,0.01347,1.34676,15.18363
9.90000,0.82498,294.78560,0.01361,1.36066,15.35342
10.00000,0.83341,296.92450,0.01375,1.37492,15.46482
10.10000,0.84172,300.21877,0.01389,1.38930,15.63639
10.20000,0.85003,302.43353,0.01404,1.40351,15.75175
10.30000,0.85840,305.27532,0.01418,1.41787,15.89976
10.40000,0.86665,308.05382,0.01432,1.43174,16.04447
10.50000,0.87496,311.02851,0.01446,1.44622,16.19940
10.60000,0.88333,313.41338,0.01461,1.46093,16.32361
10.70000,0.89158,316.38090,0.01475,1.47471,16.47817
10.80000,0.89995,319.02737,0.01489,1.48893,16.61601
10.90000,0.90832,321.31979,0.01503,1.50325,16.73540
11.00000,0.91669,324.52336,0.01517,1.51729,16.90226
11.10000,0.92506,327.22536,0.01532,1.53189,17.04299
11.20000,0.93337,329.21492,0.01546,1.54611,17.14661
11.30000,0.94168,332.35967,0.01560,1.56041,17.31040
11.40000,0.95006,334.77764,0.01575,1.57498,17.43633
11.50000,0.95825,337.51428,0.01589,1.58881,17.57887
11.60000,0.96650,340.32266,0.01603,1.60327,17.72514
11.70000,0.97505,342.51043,0.01618,1.61772,17.83908
11.80000,0.98330,345.34726,0.01632,1.63217,17.98684
11.90000,0.99161,348.48480,0.01647,1.64668,18.15025
12.00000,1.00010,350.94314,0.01661,1.66116,18.27829
12.10000,1.00829,353.35685,0.01676,1.67604,18.40400
12.20000,1.01666,355.71761,0.01690,1.69002,18.52696
12.30000,1.02509,358.73146,0.01705,1.70454,18.68393
12.40000,1.03328,361.23120,0.01719,1.71904,18.81413
12.50000,1.04159,363.67169,0.01733,1.73340,18.94123
12.60000,1.05008,365.69678,0.01749,1.74853,19.04671
12.70000,1.05827,368.90737,0.01763,1.76294,19.21393
12.80000,1.06664,371.42548,0.01777,1.77709,19.34508
12.90000,1.07502,374.12804,0.01792,1.79239,19.48584
13.00000,1.08327,376.50391,0.01806,1.80616,19.60958
13.10000,1.09164,378.50335,0.01821,1.82099,19.71372
13.20000,1.10001,380.58290,0.01836,1.83608,19.82203
13.30000,1.10832,383.58881,0.01850,1.85041,19.97858
13.40000,1.11675,386.26199,0.01865,1.86529,20.11781
13.50000,1.12506,388.72184,0.01880,1.87987,20.24593
13.60000,1.13325,390.90374,0.01894,1.89422,20.35957
13.70000,1.14168,393.17245,0.01909,1.90900,20.47773
13.80000,1.14993,396.02746,0.01924,1.92361,20.62643
13.90000,1.15824,398.47614,0.01938,1.93847,20.75397
14.00000,1.16679,401.11644,0.01953,1.95334,20.89148
14.10000,1.17492,403.36032,0.01968,1.96803,21.00835
14.20000,1.18323,406.05390,0.01983,1.98283,21.14864
14.30000,1.19178,407.81065,0.01997,1.99730,21.24014
14.40000,1.20003,410.90660,0.02012,2.01228,21.40139
14.50000,1.20841,412.90284,0.02027,2.02710,21.50536
14.60000,1.21678,415.85295,0.02042,2.04241,21.65901
14.70000,1.22497,417.80747,0.02057,2.05675,21.76081
14.80000,1.23328,420.42853,0.02072,2.07159,21.89732
14.90000,1.24171,423.10916,0.02086,2.08628,22.03694
15.00000,1.24990,425.19192,0.02101,2.10054,22.14541
15.10000,1.25833,427.16893,0.02116,2.11556,22.24838
15.20000,1.26670,429.74222,0.02130,2.13042,22.38241
15.30000,1.27495,431.66601,0.02145,2.14513,22.48260
15.40000,1.28338,433.94994,0.02160,2.16025,22.60156
15.50000,1.29175,436.43722,0.02175,2.17514,22.73111
15.60000,1.29994,439.79739,0.02190,2.18988,22.90611
15.70000,1.30831,441.05705,0.02205,2.20459,22.97172
15.80000,1.31656,443.37860,0.02220,2.21953,23.09264
15.90000,1.32494,445.28446,0.02234,2.23434,23.19190
16.00000,1.33337,447.61742,0.02250,2.24970,23.31341
16.10000,1.34156,450.09102,0.02265,2.26526,23.44224
16.20000,1.34993,451.67105,0.02280,2.28001,23.52453
16.30000,1.35836,454.28602,0.02295,2.29511,23.66073
16.40000,1.36667,456.84441,0.02310,2.30985,23.79398
16.50000,1.37498,458.73150,0.02325,2.32496,23.89227
16.60000,1.38341,461.36118,0.02340,2.34045,24.02923
16.70000,1.39166,463.65093,0.02355,2.35529,24.14849
16.80000,1.39997,465.92182,0.02371,2.37069,24.26676
16.90000,1.40840,467.98228,0.02386,2.38598,24.37408
17.00000,1.41671,470.42249,0.02401,2.40112,24.50117
17.10000,1.42496,472.02208,0.02417,2.41650,24.58448
17.20000,1.43339,474.46699,0.02432,2.43155,24.71182
17.30000,1.44164,476.94170,0.02447,2.44690,24.84071
17.40000,1.45001,479.01138,0.02462,2.46234,24.94851
17.50000,1.45839,481.08324,0.02478,2.47758,25.05642
17.60000,1.46670,483.42552,0.02493,2.49325,25.17841
17.70000,1.47507,485.49143,0.02509,2.50881,25.28601
17.80000,1.48338,487.16352,0.02524,2.52385,25.37310
17.90000,1.49163,489.77323,0.02539,2.53916,25.50902
18.00000,1.49994,491.66298,0.02555,2.55472,25.60745
18.10000,1.50825,493.68036,0.02570,2.57010,25.71252
18.20000,1.51662,495.71930,0.02586,2.58631,25.81871
18.30000,1.52505,498.09744,0.02602,2.60165,25.94258
18.40000,1.53330,499.36678,0.02617,2.61655,26.00869
18.50000,1.54161,502.03828,0.02632,2.63216,26.14783
18.60000,1.55004,503.85753,0.02648,2.64788,26.24258
18.70000,1.55829,506.05829,0.02664,2.66359,26.35720
18.80000,1.56666,507.78394,0.02679,2.67905,26.44708
18.90000,1.57509,509.91927,0.02695,2.69527,26.55830
19.00000,1.58323,512.27305,0.02711,2.71071,26.68089
19.10000,1.59160,513.96592,0.02726,2.72650,26.76906
19.20000,1.60003,515.68928,0.02742,2.74192,26.85882
19.30000,1.60828,517.84567,0.02758,2.75774,26.97113
19.40000,1.61665,519.83907,0.02774,2.77378,27.07495
19.50000,1.62502,521.39093,0.02790,2.78984,27.15578
19.60000,1.63333,523.58620,0.02806,2.80571,27.27011
19.70000,1.64176,524.83277,0.02822,2.82177,27.33504
19.80000,1.65013,526.89631,0.02837,2.83749,27.44252
19.90000,1.65838,528.76882,0.02853,2.85306,27.54004
20.00000,1.66669,530.78681,0.02869,2.86897,27.64515
20.10000,1.67500,532.65183,0.02886,2.88574,27.74228
20.20000,1.68325,534.11829,0.02902,2.90175,27.81866
20.30000,1.69168,535.97251,0.02918,2.91819,27.91524
20.40000,1.69999,537.78971,0.02934,2.93424,28.00988
20.50000,1.70825,540.11601,0.02950,2.95037,28.13104
20.60000,1.71674,541.07471,0.02967,2.96681,28.18097
20.70000,1.72499,542.38248,0.02983,2.98290,28.24909
20.80000,1.73330,544.79921,0.02999,2.99893,28.37496
20.90000,1.74179,546.37073,0.03015,3.01510,28.45681
21.00000,1.74998,548.14359,0.03031,3.03127,28.54914
21.10000,1.75829,549.60879,0.03047,3.06452,28.62546
21.20000,1.76672,551.19134,0.03064,3.09824,28.70788
21.30000,1.77491,552.51671,0.03077,3.13100,28.77691
21.36400,1.78023,553.48654,0.03088,3.15229,28.82743
21.46400,1.78872,555.51948,0.03105,3.18625,28.93331
21.56400,1.79697,556.64293,0.03121,3.21925,28.99182
21.66400,1.80534,558.37696,0.03137,3.25273,29.08213
21.76400,1.81383,560.40501,0.03154,3.28669,29.18776
21.86400,1.82202,561.44623,0.03170,3.31946,29.24199
21.96400,1.83034,562.76685,0.03187,3.35270,29.31077
22.06400,1.83877,565.52305,0.03204,3.38642,29.45432
22.16400,1.84696,566.55300,0.03221,3.41919,29.50797
22.26400,1.85527,567.69918,0.03238,3.45243,29.56767
22.36400,1.86370,569.65309,0.03255,3.48615,29.66943
22.46400,1.87201,570.68807,0.03271,3.51939,29.72334
22.56400,1.88032,572.79272,0.03289,3.55264,29.83295
22.66400,1.88875,574.08577,0.03306,3.58636,29.90030
22.76400,1.89694,575.42166,0.03323,3.61912,29.96988
22.86400,1.90525,576.71107,0.03339,3.65237,30.03703
22.96400,1.91362,578.33102,0.03356,3.68585,30.12141
23.06400,1.92193,579.94602,0.03373,3.71909,30.20552
23.16400,1.93030,581.40224,0.03395,3.75257,30.28137
23.26400,1.93855,582.32141,0.03407,3.78558,30.32924
23.36400,1.94693,584.14368,0.03437,3.81906,30.42415
23.46400,1.95524,585.74919,0.03409,3.85230,30.50777
23.56400,1.96355,586.38947,0.03528,3.88554,30.54112
23.66400,1.97192,588.58828,0.02594,3.91903,30.65564
23.76400,1.98035,589.17454,0.02289,3.95275,30.68617
23.86400,1.98866,589.37683,0.00740,3.98599,30.69671
23.96400,1.99703,590.19090,0.00694,4.01947,30.73911
24.06400,2.00540,592.79073,0.00737,4.05296,30.87452
24.16400,2.01371,593.35069,0.00687,4.08620,30.90368
24.26400,2.02202,594.78567,0.00520,4.11944,30.97842
24.36400,2.03033,596.65805,0.00428,4.15268,31.07594
24.46400,2.03870,597.55491,0.00351,4.18617,31.12265
24.56400,2.04701,599.08773,0.00294,4.21941,31.20249
24.66400,2.05538,599.74710,0.00291,4.25289,31.23683
24.76400,2.06369,600.55363,0.00213,4.28613,31.27884
24.86400,2.07206,602.21194,-0.01329,4.31962,31.36521
24.96400,2.08038,603.23328,-0.02237,4.35286,31.41840
25.06400,2.08875,603.29000,-0.02273,4.38634,31.42135
25.16400,2.09706,604.68582,-0.02812,4.41958,31.49405
25.26400,2.10537,606.27847,-0.03836,4.45283,31.57700
25.36400,2.11368,607.48663,-0.14156,4.48607,31.63993
25.46400,2.12205,608.33055,-0.13979,4.51955,31.68388
25.56400,2.13030,608.90866,-0.13980,4.55256,31.71399
25.66400,2.13867,609.85293,-0.13980,4.58604,31.76317
25.76400,2.14698,610.91399,-0.13980,4.61928,31.81844
25.86400,2.15529,611.99330,-0.13980,4.65253,31.87465
25.96400,2.16366,613.23647,-0.13980,4.68601,31.93940
26.06400,2.17203,614.05082,-0.13980,4.71949,31.98181
26.16400,2.18034,614.74899,-0.13980,4.75273,32.01818
26.26400,2.18865,615.81200,-0.13980,4.78598,32.07354
26.36400,2.19702,615.96483,-0.13980,4.81946,32.08150
26.46400,2.20528,618.07279,-0.13980,4.85246,32.19129
26.56400,2.21365,618.07223,-0.13980,4.88594,32.19126
26.66400,2.22202,619.08471,-0.13980,4.91943,32.24400
26.76400,2.23033,620.71676,-0.13980,4.95267,32.32900
26.86400,2.23864,620.56049,-0.13980,4.98591,32.32086
26.96400,2.24701,621.46303,-0.13980,5.01939,32.36787
27.06400,2.25532,622.09894,-0.13980,5.05264,32.40099
27.16400,2.26369,623.27748,-0.13981,5.08612,32.46237
27.26400,2.27206,624.04322,-0.13980,5.11960,32.50225
27.36400,2.28037,624.38017,-0.13980,5.15284,32.51980
27.46400,2.28868,625.55000,-0.13980,5.18609,32.58073
27.56400,2.29699,625.92737,-0.13980,5.21933,32.60038
27.66400,2.30530,626.74838,-0.13981,5.25257,32.64315
27.76400,2.31367,627.65833,-0.13980,5.28605,32.69054
27.86400,2.32192,627.81996,-0.13980,5.31906,32.69896
27.96400,2.33030,628.62081,-0.13981,5.35254,32.74067
28.06400,2.33867,628.88316,-0.13981,5.38602,32.75433
28.16400,2.34698,629.48549,-0.13981,5.41927,32.78570
28.26400,2.35529,629.83884,-0.13981,5.45251,32.80411
28.36400,2.36372,630.01132,-0.13981,5.48623,32.81309
28.46400,2.37203,631.39643,-0.13980,5.51947,32.88523
28.56400,2.38034,631.45561,-0.13981,5.55272,32.88831
28.66400,2.38871,631.89617,-0.13980,5.58620,32.91126
28.76400,2.39690,632.87802,-0.13981,5.61896,32.96240
28.86400,2.40527,632.65711,-0.13981,5.65244,32.95089
28.96400,2.41364,632.79527,-0.13981,5.68593,32.95809
29.06400,2.42195,634.08883,-0.13981,5.71917,33.02546
29.16400,2.43032,634.98458,-0.13981,5.75265,33.07211
29.26400,2.43863,634.36059,-0.13981,5.78589,33.03962
29.36400,2.44694,634.95170,-0.13981,5.81914,33.07040
29.46400,2.45532,635.42170,-0.13981,5.85262,33.09488
29.56400,2.46369,635.32433,-0.13981,5.88610,33.08981
29.66400,2.47200,636.06477,-0.13981,5.91934,33.12837
29.76400,2.48031,636.20270,-0.13981,5.95259,33.13556
29.86400,2.48856,636.71772,-0.13981,5.98559,33.16238
29.96400,2.49693,636.36415,-0.13981,6.01907,33.14397
30.06400,2.50530,636.91512,-0.13981,6.05255,33.17266
30.16400,2.51367,637.12075,-0.13981,6.08604,33.18337
30.26400,2.52198,637.64360,-0.13981,6.11928,33.21061
30.36400,2.53035,637.52043,-0.13981,6.15276,33.20419
30.46400,2.53872,637.63368,-0.13981,6.18625,33.21009
30.56400,2.54703,637.84597,-0.13981,6.21949,33.22115
30.66400,2.55534,637.78996,-0.13981,6.25273,33.21823
30.76400,2.56365,637.38683,-0.13981,6.28597,33.19723
30.86400,2.57196,637.67252,-0.13981,6.31922,33.21211
30.96400,2.58034,638.18302,-0.13981,6.35270,33.23870
31.06400,2.58865,637.84118,-0.13981,6.38594,33.22089
31.16400,2.59696,637.97962,-0.13981,6.41918,33.22810
31.26400,2.60533,636.96932,-0.13981,6.45267,33.17548
31.36400,2.61370,637.55312,-0.13981,6.48615,33.20589
31.46400,2.62207,637.65566,-0.13981,6.51963,33.21123
31.56400,2.63032,637.33743,-0.13981,6.55264,33.19466
31.66400,2.63869,637.18338,-0.13981,6.58612,33.18663
31.76400,2.64700,636.28466,-0.13981,6.61936,33.13983
31.86400,2.65531,635.67776,-0.13981,6.65260,33.10822
31.96400,2.66362,635.15031,-0.13981,6.68585,33.08075
32.06400,2.67199,635.37578,-0.13981,6.71933,33.09249
32.16400,2.68030,634.03714,-0.13981,6.75257,33.02277
32.26400,2.68867,633.48925,-0.13981,6.78605,32.99423
32.36400,2.69704,632.87914,-0.13981,6.81954,32.96246
32.46400,2.70541,631.82740,-0.13981,6.85302,32.90768
32.56400,2.71373,630.79535,-0.13981,6.88626,32.85392
32.66400,2.72210,629.10835,-0.13981,6.91974,32.76606
32.76400,2.73035,627.31127,-0.13981,6.95275,32.67246
32.86400,2.73866,625.22707,-0.13981,6.98599,32.56391
32.96400,2.74709,622.10476,-0.13981,7.01971,32.40129
33.06400,2.75534,615.20766,-0.13981,7.05272,32.04206
33.13200,2.76102,2.76919,-0.13981,7.07543,0.14423