File: Manufatura Aditiva/Classificação Orientação/Ensaios/Ensaios FDM/Tracao_OLABI_28_05_2018_FDM_ZY4.is_metal_RawData/Specimen_RawData_1.csv
Time,Extension,Load,Strain 1,Tensile strain,Tensile stress
(sec),(mm),(N),(mm/mm),(%),(MPa)
0.00000,0.00006,12.25873,0.00091,0.09055,0.59212
0.10000,0.00251,12.32956,0.00091,0.09150,0.59554
0.20000,0.01214,16.18808,0.00107,0.10692,0.78192
0.30000,0.02266,20.30995,0.00126,0.12620,0.98102
0.40000,0.03217,23.87610,0.00143,0.14337,1.15327
0.50000,0.04119,28.26193,0.00160,0.16021,1.36511
0.60000,0.04980,32.10843,0.00176,0.17573,1.55091
0.70000,0.05823,34.69291,0.00191,0.19111,1.67574
0.80000,0.06667,38.90239,0.00207,0.20657,1.87907
0.90000,0.07498,41.45591,0.00221,0.22147,2.00241
1.00000,0.08329,44.44931,0.00236,0.23605,2.14700
1.10000,0.09178,48.23315,0.00251,0.25129,2.32977
1.20000,0.10003,52.09986,0.00266,0.26626,2.51654
1.30000,0.10834,55.03183,0.00281,0.28127,2.65816
1.40000,0.11677,58.54428,0.00297,0.29662,2.82782
1.50000,0.12508,61.68237,0.00312,0.31171,2.97939
1.60000,0.13339,65.06225,0.00327,0.32653,3.14265
1.70000,0.14170,68.40074,0.00341,0.34132,3.30390
1.80000,0.14995,72.03738,0.00356,0.35568,3.47956
1.90000,0.15832,75.55156,0.00370,0.37046,3.64931
2.00000,0.16663,78.66153,0.00385,0.38539,3.79952
2.10000,0.17494,81.86577,0.00400,0.40042,3.95429
2.20000,0.18325,85.22754,0.00415,0.41547,4.11668
2.30000,0.19163,88.58882,0.00431,0.43076,4.27903
2.40000,0.20000,92.20048,0.00445,0.44510,4.45348
2.50000,0.20837,95.28946,0.00460,0.45994,4.60269
2.60000,0.21668,98.23376,0.00475,0.47517,4.74490
2.70000,0.22499,101.58655,0.00490,0.48980,4.90685
2.80000,0.23330,104.75834,0.00505,0.50478,5.06006
2.90000,0.24161,108.39569,0.00520,0.51988,5.23575
3.00000,0.24998,110.71411,0.00535,0.53484,5.34773
3.10000,0.25841,114.37031,0.00549,0.54949,5.52434
3.20000,0.26672,117.18421,0.00564,0.56396,5.66025
3.30000,0.27503,120.94484,0.00579,0.57936,5.84190
3.40000,0.28340,124.30527,0.00594,0.59430,6.00422
3.50000,0.29165,127.20528,0.00609,0.60921,6.14429
3.60000,0.30002,130.77183,0.00624,0.62401,6.31656
3.70000,0.30839,133.51005,0.00639,0.63864,6.44883
3.80000,0.31670,137.24404,0.00653,0.65326,6.62919
3.90000,0.32502,140.14763,0.00668,0.66798,6.76944
4.00000,0.33339,143.47817,0.00683,0.68298,6.93031
4.10000,0.34164,147.06809,0.00698,0.69818,7.10371
4.20000,0.34995,149.57770,0.00713,0.71267,7.22493
4.30000,0.35832,153.07509,0.00727,0.72743,7.39386
4.40000,0.36663,155.96724,0.00742,0.74214,7.53356
4.50000,0.37500,159.47485,0.00757,0.75706,7.70298
4.60000,0.38331,162.30431,0.00772,0.77204,7.83965
4.70000,0.39162,165.63786,0.00787,0.78653,8.00067
4.80000,0.40005,168.75408,0.00802,0.80167,8.15119
4.90000,0.40836,172.10077,0.00817,0.81712,8.31284
5.00000,0.41667,175.07226,0.00832,0.83190,8.45637
5.10000,0.42510,178.53194,0.00847,0.84698,8.62348
5.20000,0.43329,181.35849,0.00861,0.86148,8.76001
5.30000,0.44155,184.50278,0.00876,0.87591,8.91189
5.40000,0.45010,187.67876,0.00891,0.89116,9.06529
5.50000,0.45829,191.01066,0.00906,0.90553,9.22623
5.60000,0.46666,194.11127,0.00921,0.92054,9.37600
5.70000,0.47509,197.74016,0.00936,0.93588,9.55128
5.80000,0.48328,199.92907,0.00951,0.95066,9.65701
5.90000,0.49159,203.35829,0.00965,0.96530,9.82265
6.00000,0.50008,206.29456,0.00980,0.97970,9.96448
6.10000,0.50827,210.42011,0.00995,0.99453,10.16375
6.20000,0.51664,212.66900,0.01009,1.00939,10.27238
6.30000,0.52507,216.17571,0.01024,1.02437,10.44176
6.40000,0.53332,218.63698,0.01039,1.03886,10.56064
6.50000,0.54169,221.78430,0.01054,1.05413,10.71266
6.60000,0.55000,224.96025,0.01069,1.06912,10.86607
6.70000,0.55825,228.43927,0.01084,1.08365,11.03411
6.80000,0.56674,231.03443,0.01099,1.09868,11.15947
6.90000,0.57506,235.06708,0.01114,1.11393,11.35425
7.00000,0.58331,237.97459,0.01128,1.12830,11.49469
7.10000,0.59174,240.93022,0.01144,1.14365,11.63745
7.20000,0.59999,244.89430,0.01158,1.15839,11.82893
7.30000,0.60824,246.91273,0.01173,1.17271,11.92642
7.40000,0.61667,250.05613,0.01188,1.18784,12.07826
7.50000,0.62498,253.27348,0.01203,1.20268,12.23366
7.60000,0.63323,256.57753,0.01218,1.21780,12.39325
7.70000,0.64166,259.31234,0.01233,1.23253,12.52535
7.80000,0.64997,262.07964,0.01248,1.24765,12.65902
7.90000,0.65828,265.37969,0.01262,1.26226,12.81842
8.00000,0.66671,268.41429,0.01277,1.27687,12.96500
8.10000,0.67496,272.22410,0.01292,1.29183,13.14902
8.20000,0.68327,274.43727,0.01306,1.30639,13.25592
8.30000,0.69170,278.13730,0.01322,1.32166,13.43464
8.40000,0.70002,280.68477,0.01336,1.33642,13.55769
8.50000,0.70839,283.41122,0.01351,1.35129,13.68938
8.60000,0.71664,287.15779,0.01367,1.36685,13.87035
8.70000,0.72501,290.03692,0.01381,1.38114,14.00942
8.80000,0.73338,293.26170,0.01396,1.39595,14.16518
8.90000,0.74169,296.13348,0.01411,1.41055,14.30389
9.00000,0.75000,298.73096,0.01426,1.42562,14.42936
9.10000,0.75837,302.61208,0.01441,1.44086,14.61682
9.20000,0.76662,305.41627,0.01455,1.45539,14.75227
9.30000,0.77499,307.68933,0.01470,1.47030,14.86206
9.40000,0.78336,311.37681,0.01485,1.48528,15.04018
9.50000,0.79167,313.65503,0.01500,1.50015,15.15022
9.60000,0.79992,316.69755,0.01515,1.51531,15.29718
9.70000,0.80835,319.39717,0.01530,1.52990,15.42758
9.80000,0.81666,322.41256,0.01545,1.54482,15.57323
9.90000,0.82498,325.88106,0.01560,1.55971,15.74077
10.00000,0.83341,328.72427,0.01575,1.57464,15.87810
10.10000,0.84172,331.46101,0.01590,1.58982,16.01029
10.20000,0.85003,333.97011,0.01604,1.60428,16.13148
10.30000,0.85840,338.01585,0.01620,1.61982,16.32690
10.40000,0.86665,339.70333,0.01635,1.63470,16.40841
10.50000,0.87502,343.30734,0.01650,1.64952,16.58249
10.60000,0.88333,345.78876,0.01664,1.66442,16.70235
10.70000,0.89158,349.15116,0.01679,1.67915,16.86476
10.80000,0.89995,351.61639,0.01694,1.69372,16.98384
10.90000,0.90832,354.88321,0.01709,1.70918,17.14163
11.00000,0.91669,357.32544,0.01724,1.72394,17.25960
11.10000,0.92506,360.34314,0.01739,1.73905,17.40536
11.20000,0.93337,363.07729,0.01755,1.75458,17.53742
11.30000,0.94168,366.08421,0.01769,1.76939,17.68266
11.40000,0.95006,368.75275,0.01784,1.78424,17.81156
11.50000,0.95825,371.87515,0.01799,1.79900,17.96238
11.60000,0.96650,374.77594,0.01814,1.81391,18.10250
11.70000,0.97499,376.56834,0.01829,1.82916,18.18907
11.80000,0.98330,379.67330,0.01844,1.84448,18.33905
11.90000,0.99161,383.38965,0.01860,1.86004,18.51855
12.00000,1.00010,385.43935,0.01875,1.87512,18.61756
12.10000,1.00829,388.54491,0.01890,1.89014,18.76757
12.20000,1.01666,391.13038,0.01905,1.90492,18.89245
12.30000,1.02515,393.68682,0.01920,1.91993,19.01593
12.40000,1.03328,396.84833,0.01935,1.93503,19.16864
12.50000,1.04159,400.10768,0.01950,1.95010,19.32607
12.60000,1.05008,401.82094,0.01966,1.96553,19.40883
12.70000,1.05827,404.43689,0.01981,1.98068,19.53518
12.80000,1.06664,407.79030,0.01996,1.99577,19.69716
12.90000,1.07507,410.41318,0.02011,2.01095,19.82385
13.00000,1.08327,412.92375,0.02026,2.02595,19.94512
13.10000,1.09164,416.36466,0.02041,2.04118,20.11132
13.20000,1.10001,418.44430,0.02056,2.05604,20.21177
13.30000,1.10832,421.60363,0.02071,2.07149,20.36437
13.40000,1.11675,423.50162,0.02087,2.08677,20.45605
13.50000,1.12506,426.34308,0.02102,2.10186,20.59330
13.60000,1.13325,429.21491,0.02117,2.11714,20.73202
13.70000,1.14168,431.80841,0.02133,2.13252,20.85729
13.80000,1.14993,434.67395,0.02148,2.14764,20.99570
13.90000,1.15824,437.60925,0.02163,2.16328,21.13748
14.00000,1.16679,440.04512,0.02179,2.17856,21.25514
14.10000,1.17492,442.32090,0.02194,2.19403,21.36506
14.20000,1.18323,445.50523,0.02209,2.20894,21.51887
14.30000,1.19178,447.11689,0.02224,2.22441,21.59672
14.40000,1.20003,450.32133,0.02240,2.23971,21.75150
14.50000,1.20841,453.21099,0.02256,2.25560,21.89108
14.60000,1.21678,455.77926,0.02271,2.27132,22.01513
14.70000,1.22497,458.28819,0.02286,2.28624,22.13632
14.80000,1.23328,460.42260,0.02302,2.30191,22.23941
14.90000,1.24171,463.34276,0.02318,2.31771,22.38046
15.00000,1.24990,465.60816,0.02333,2.33269,22.48989
15.10000,1.25833,468.38732,0.02348,2.34785,22.62413
15.20000,1.26670,470.82156,0.02363,2.36311,22.74171
15.30000,1.27495,473.75951,0.02379,2.37872,22.88362
15.40000,1.28338,475.85904,0.02395,2.39481,22.98503
15.50000,1.29169,479.17617,0.02410,2.41034,23.14525
15.60000,1.29994,480.83826,0.02426,2.42598,23.22554
15.70000,1.30831,483.54864,0.02441,2.44089,23.35645
15.80000,1.31656,486.13520,0.02456,2.45619,23.48139
15.90000,1.32494,488.58863,0.02472,2.47224,23.59990
16.00000,1.33337,491.41389,0.02488,2.48777,23.73636
16.10000,1.34156,493.62583,0.02504,2.50379,23.84320
16.20000,1.34993,496.67112,0.02519,2.51902,23.99030
16.30000,1.35836,498.67271,0.02535,2.53505,24.08698
16.40000,1.36667,501.12857,0.02550,2.55042,24.20560
16.50000,1.37498,503.60234,0.02566,2.56566,24.32509
16.60000,1.38341,505.98690,0.02582,2.58216,24.44027
16.70000,1.39166,508.79815,0.02598,2.59770,24.57606
16.80000,1.39997,510.43257,0.02613,2.61330,24.65500
16.90000,1.40840,512.91985,0.02629,2.62936,24.77515
17.00000,1.41671,515.51643,0.02646,2.64551,24.90057
17.10000,1.42496,517.96837,0.02661,2.66071,25.01900
17.20000,1.43339,520.08023,0.02677,2.67712,25.12101
17.30000,1.44164,522.77204,0.02693,2.69331,25.25103
17.40000,1.45001,525.03338,0.02709,2.70885,25.36026
17.50000,1.45833,527.63652,0.02725,2.72462,25.48599
17.60000,1.46670,529.55397,0.02741,2.74092,25.57861
17.70000,1.47507,531.86612,0.02756,2.75648,25.69029
17.80000,1.48338,534.12504,0.02773,2.77267,25.79940
17.90000,1.49163,536.64106,0.02789,2.78864,25.92093
18.00000,1.49994,538.74287,0.02805,2.80472,26.02245
18.10000,1.50825,541.41120,0.02821,2.82075,26.15134
18.20000,1.51662,543.37955,0.02837,2.83668,26.24642
18.30000,1.52505,545.55838,0.02853,2.85299,26.35166
18.40000,1.53330,547.32044,0.02869,2.86881,26.43677
18.50000,1.54161,549.56153,0.02885,2.88514,26.54502
18.60000,1.55004,551.53910,0.02901,2.90135,26.64054
18.70000,1.55829,554.26727,0.02918,2.91754,26.77232
18.80000,1.56666,556.29206,0.02934,2.93401,26.87012
18.90000,1.57503,558.42889,0.02950,2.95039,26.97333
19.00000,1.58323,560.71440,0.02966,2.96647,27.08373
19.10000,1.59160,562.40959,0.02983,2.98311,27.16561
19.20000,1.60003,565.13813,0.02999,2.99937,27.29740
19.30000,1.60828,566.91444,0.03016,3.01584,27.38320
19.40000,1.61665,568.97085,0.03032,3.03210,27.48253
19.50000,1.62502,571.04472,0.03049,3.04870,27.58270
19.60000,1.63333,573.46723,0.03065,3.06509,27.69972
19.70000,1.64170,574.86524,0.03082,3.08160,27.76724
19.80000,1.65013,577.57092,0.03098,3.11532,27.89793
19.90000,1.65838,579.29019,0.03115,3.14833,27.98098
20.00000,1.66669,581.56876,0.03131,3.18157,28.09104
20.00600,1.66717,581.64918,0.03132,3.18348,28.09492
20.10600,1.67554,583.60831,0.03150,3.21696,28.18955
20.20600,1.68379,585.30453,0.03166,3.24997,28.27148
20.30600,1.69222,587.79297,0.03183,3.28369,28.39168
20.40600,1.70053,589.31047,0.03200,3.31693,28.46498
20.50600,1.70878,590.97190,0.03210,3.34994,28.54523
20.60600,1.71721,592.86677,0.03228,3.38366,28.63676
20.70600,1.72552,594.75936,0.03244,3.41690,28.72817
20.80600,1.73378,596.66354,0.03261,3.44990,28.82015
20.90600,1.74227,598.83296,0.03278,3.48386,28.92494
21.00600,1.75052,600.55805,0.03295,3.51687,29.00826
21.10600,1.75877,602.08035,0.03312,3.54987,29.08179
21.20600,1.76720,603.95882,0.03330,3.58359,29.17253
21.30600,1.77545,605.96452,0.03346,3.61660,29.26941
21.40600,1.78382,607.12136,0.03360,3.65008,29.32528
21.50600,1.79219,610.07757,0.03312,3.68356,29.46807
21.60600,1.80050,610.71292,0.03418,3.71680,29.49876
21.70600,1.80887,613.06842,0.03552,3.75029,29.61254
21.80600,1.81724,615.09316,0.03295,3.78377,29.71034
21.90600,1.82561,617.55283,0.01854,3.81725,29.82915
22.00600,1.83386,617.63376,0.00334,3.85025,29.83306
22.10600,1.84217,619.96258,0.00263,3.88350,29.94554
22.20600,1.85048,622.16520,0.00261,3.91674,30.05194
22.30600,1.85886,622.99971,0.00262,3.95022,30.09224
22.40600,1.86717,625.41836,0.00195,3.98347,30.20907
22.50600,1.87548,627.24515,0.00171,4.01671,30.29731
22.60600,1.88385,629.30929,0.00183,4.05019,30.39701
22.70600,1.89216,630.49928,0.00189,4.08343,30.45449
22.80600,1.90041,632.15038,0.00323,4.11644,30.53424
22.90600,1.90884,633.98075,0.00330,4.15016,30.62265
23.00600,1.91709,635.73886,0.00337,4.18316,30.70757
23.10600,1.92546,636.97752,0.00239,4.21664,30.76740
23.20600,1.93377,638.42987,0.00388,4.24989,30.83755
23.30600,1.94208,640.02885,-0.01041,4.28313,30.91479
23.40600,1.95045,641.72735,-0.01303,4.31661,30.99683
23.50600,1.95876,642.99996,-0.01377,4.34985,31.05830
23.60600,1.96707,645.05949,-0.01660,4.38310,31.15778
23.70600,1.97544,646.59971,-0.01992,4.41658,31.23217
23.80600,1.98376,647.66943,-0.02338,4.44982,31.28384
23.90600,1.99225,649.81189,-0.02820,4.48378,31.38733
24.00600,2.00056,650.81003,-0.03604,4.51703,31.43554
24.10600,2.00887,651.88766,-0.14176,4.55027,31.48759
24.20600,2.01724,653.27496,-0.13881,4.58375,31.55460
24.30600,2.02555,655.46851,-0.13893,4.61699,31.66056
24.40600,2.03386,656.24225,-0.13893,4.65024,31.69793
24.50600,2.04217,658.13391,-0.13893,4.68348,31.78930
24.60600,2.05054,659.28046,-0.13893,4.71696,31.84468
24.70600,2.05885,660.42114,-0.13893,4.75021,31.89978
24.80600,2.06722,662.25682,-0.13894,4.78369,31.98845
24.90600,2.07559,663.64533,-0.13893,4.81717,32.05552
25.00600,2.08384,664.80422,-0.13894,4.85017,32.11149
25.10600,2.09221,665.89718,-0.13894,4.88366,32.16428
25.20600,2.10058,666.98762,-0.13894,4.91714,32.21695
25.30600,2.10884,668.52025,-0.13894,4.95014,32.29099
25.40600,2.11721,669.78508,-0.13894,4.98362,32.35208
25.50600,2.12552,671.68856,-0.13894,5.01687,32.44402
25.60600,2.13383,672.34784,-0.13894,5.05011,32.47586
25.70600,2.14214,673.18585,-0.13894,5.08335,32.51634
25.80600,2.15051,674.50781,-0.13894,5.11683,32.58020
25.90600,2.15888,676.45684,-0.13894,5.15032,32.67434
26.00600,2.16719,677.12455,-0.13894,5.18356,32.70659
26.10600,2.17550,678.33196,-0.13894,5.21680,32.76491
26.20600,2.18387,678.79348,-0.13894,5.25028,32.78720
26.30600,2.19212,680.14753,-0.13894,5.28329,32.85261
26.40600,2.20049,681.40267,-0.13894,5.31677,32.91323
26.50600,2.20880,682.03337,-0.13894,5.35001,32.94370
26.60600,2.21711,683.14779,-0.13894,5.38326,32.99753
26.70600,2.22548,684.66882,-0.13895,5.41674,33.07100
26.80600,2.23386,685.21188,-0.13894,5.45022,33.09723
26.90600,2.24217,686.93738,-0.13895,5.48346,33.18057
27.00600,2.25048,687.76663,-0.13894,5.51671,33.22063
27.10600,2.25879,688.38056,-0.13895,5.54995,33.25028
27.20600,2.26722,689.05940,-0.13895,5.58367,33.28307
27.30600,2.27553,690.20586,-0.13894,5.61691,33.33845
27.40600,2.28384,690.54542,-0.13895,5.65016,33.35485
27.50600,2.29227,691.80205,-0.13895,5.68388,33.41555
27.60600,2.30046,693.04602,-0.13895,5.71664,33.47563
27.70600,2.30883,692.96435,-0.13895,5.75012,33.47169
27.80600,2.31726,694.58364,-0.13895,5.78385,33.54990
27.90600,2.32551,695.39975,-0.13895,5.81685,33.58932
28.00600,2.33382,695.88618,-0.13894,5.85009,33.61282
28.10600,2.34219,696.82174,-0.13895,5.88358,33.65801
28.20600,2.35050,697.64149,-0.13895,5.91682,33.69761
28.30600,2.35887,698.01477,-0.13895,5.95030,33.71563
28.40600,2.36725,698.48024,-0.13895,5.98378,33.73812
28.50600,2.37550,699.79620,-0.13895,6.01679,33.80168
28.60600,2.38387,700.28445,-0.13895,6.05027,33.82526
28.70600,2.39206,700.44822,-0.13895,6.08303,33.83318
28.80600,2.40043,701.99966,-0.13895,6.11652,33.90811
28.90600,2.40886,702.17503,-0.13895,6.15024,33.91658
29.00600,2.41711,703.20573,-0.13895,6.18324,33.96637
29.10600,2.42548,703.22906,-0.13895,6.21672,33.96749
29.20600,2.43385,704.22799,-0.13895,6.25020,34.01575
29.30600,2.44210,704.47866,-0.13895,6.28321,34.02785
29.40600,2.45047,704.69962,-0.13895,6.31669,34.03853
29.50600,2.45884,705.22116,-0.13895,6.35017,34.06372
29.60600,2.46715,706.14247,-0.13895,6.38342,34.10822
29.70600,2.47546,706.24766,-0.13895,6.41666,34.11330
29.80600,2.48383,706.69386,-0.13895,6.45014,34.13485
29.90600,2.49209,707.57284,-0.13895,6.48314,34.17731
30.00600,2.50040,707.91636,-0.13895,6.51639,34.19390
30.10600,2.50883,707.94937,-0.13895,6.55011,34.19550
30.20600,2.51720,708.03100,-0.13895,6.58359,34.19944
30.30600,2.52551,709.19874,-0.13895,6.61683,34.25584
30.40600,2.53388,709.02142,-0.13895,6.65032,34.24728
30.50600,2.54219,708.84237,-0.13895,6.68356,34.23863
30.60600,2.55056,709.57583,-0.13895,6.71704,34.27406
30.70600,2.55887,709.84280,-0.13895,6.75028,34.28695
30.80600,2.56718,709.70966,-0.13895,6.78353,34.28052
30.90600,2.57549,710.30511,-0.13896,6.81677,34.30928
31.00600,2.58380,709.94566,-0.13895,6.85001,34.29192
31.10600,2.59217,710.54026,-0.13895,6.88349,34.32064
31.20600,2.60048,711.06455,-0.13895,6.91674,34.34597
31.30600,2.60885,710.80038,-0.13895,6.95022,34.33321
31.40600,2.61717,710.96933,-0.13895,6.98346,34.34137
31.50600,2.62554,711.59932,-0.13895,7.01694,34.37180
31.60600,2.63385,711.41617,-0.13895,7.05019,34.36295
31.70600,2.64216,710.92080,-0.13895,7.08343,34.33902
31.80600,2.65053,711.37557,-0.13895,7.11691,34.36099
31.90600,2.65878,712.03024,-0.13895,7.14992,34.39261
32.00600,2.66709,712.04449,-0.13895,7.18316,34.39330
32.10600,2.67552,711.26944,-0.13896,7.21688,34.35587
32.20600,2.68383,711.38511,-0.13896,7.25012,34.36145
32.30600,2.69220,711.81487,-0.13896,7.28361,34.38221
32.40600,2.70057,711.57524,-0.13896,7.31709,34.37064
32.50600,2.70888,711.58600,-0.13896,7.35033,34.37115
32.60600,2.71725,711.87266,-0.13896,7.38381,34.38500
32.70600,2.72556,711.41478,-0.13896,7.41706,34.36288
32.80600,2.73387,711.65818,-0.13896,7.45030,34.37464
32.90600,2.74219,711.64761,-0.13896,7.48354,34.37413
33.00600,2.75050,711.43135,-0.13896,7.51678,34.36369
33.10600,2.75887,711.48500,-0.13895,7.55027,34.36628
33.20600,2.76718,711.04122,-0.13896,7.58351,34.34484
33.30600,2.77549,711.22143,-0.13896,7.61675,34.35355
33.40600,2.78374,711.11168,-0.13896,7.64976,34.34824
33.50600,2.79217,710.50483,-0.13896,7.68348,34.31893
33.60600,2.80054,710.05486,-0.13896,7.71696,34.29720
33.70600,2.80885,710.65365,-0.13896,7.75020,34.32612
33.80600,2.81728,710.54483,-0.13895,7.78392,34.32086
33.90600,2.82547,711.06455,-0.13896,7.81669,34.34597
34.00600,2.83372,709.64186,-0.13896,7.84969,34.27725
34.10600,2.84221,709.93239,-0.13896,7.88365,34.29128
34.20600,2.85034,709.47418,-0.13896,7.91618,34.26915
34.30600,2.85871,710.44588,-0.13895,7.94966,34.31608
34.40600,2.86720,709.27339,-0.13896,7.98362,34.25945
34.50600,2.87540,709.12181,-0.13896,8.01639,34.25213
34.60600,2.88377,708.91175,-0.13896,8.04987,34.24198
34.70600,2.89226,708.11785,-0.13896,8.08383,34.20364
34.80600,2.90051,707.51649,-0.13896,8.11683,34.17459
34.90600,2.90888,707.76637,-0.13896,8.15031,34.18666
35.00600,2.91725,708.11426,-0.13896,8.18380,34.20346
35.10600,2.92544,707.58779,-0.13896,8.21656,34.17803
35.20600,2.93387,706.72943,-0.13896,8.25028,34.13657
35.30600,2.94224,706.86890,-0.13896,8.28376,34.14331
35.40600,2.95049,706.71123,-0.13896,8.31677,34.13569
35.50600,2.95892,706.54191,-0.13896,8.35049,34.12751
35.60600,2.96723,705.96882,-0.13896,8.38373,34.09983
35.70600,2.97548,705.56505,-0.13895,8.41674,34.08033
35.80600,2.98397,705.68160,-0.13896,8.45070,34.08596
35.90600,2.99216,704.95210,-0.13896,8.48346,34.05072
36.00600,3.00042,705.04434,-0.13896,8.51647,34.05518
36.10600,3.00885,704.57160,-0.13896,8.55019,34.03234
36.20600,3.01710,704.24336,-0.13896,8.58319,34.01649
36.30600,3.02541,703.26100,-0.13896,8.61643,33.96904
36.40600,3.03384,703.54310,-0.13896,8.65015,33.98267
36.50600,3.04209,702.64144,-0.13896,8.68316,33.93911
36.60600,3.05040,702.73234,-0.13896,8.71640,33.94350
36.70600,3.05889,702.04698,-0.13896,8.75036,33.91040
36.80600,3.06714,702.39599,-0.13896,8.78337,33.92726
36.90600,3.07539,701.85540,-0.13896,8.81637,33.90115
37.00600,3.08382,700.46410,-0.13896,8.85009,33.83394
37.10600,3.09213,700.66615,-0.13896,8.88333,33.84370
37.20600,3.10050,700.34750,-0.13896,8.91682,33.82831
37.30600,3.10887,699.30758,-0.13896,8.95030,33.77808
37.40600,3.11713,699.58894,-0.13896,8.98330,33.79167
37.50600,3.12550,698.81794,-0.13896,9.01678,33.75443
37.60600,3.13381,698.43843,-0.13896,9.05003,33.73610
37.70600,3.14212,698.41966,-0.13896,9.08327,33.73519
37.80600,3.15055,697.86375,-0.13896,9.11699,33.70834
37.90600,3.15880,697.71907,-0.13896,9.14999,33.70135
38.00600,3.16717,697.11157,-0.13896,9.18348,33.67201
38.10600,3.17560,696.68656,-0.13896,9.21720,33.65148
38.20600,3.18391,695.72129,-0.13896,9.25044,33.60485
38.30600,3.19216,695.51761,-0.13896,9.28344,33.59502
38.40600,3.20053,695.14699,-0.13896,9.31693,33.57711
38.50600,3.20878,694.35979,-0.13896,9.34993,33.53909
38.60600,3.21709,694.79737,-0.13896,9.38317,33.56023
38.70600,3.22552,694.13120,-0.13896,9.41689,33.52805
38.80600,3.23383,693.38009,-0.13896,9.45014,33.49177
38.90600,3.24214,693.13697,-0.13897,9.48338,33.48003
39.00600,3.25058,693.06507,-0.13896,9.51710,33.47655
39.10600,3.25883,692.13388,-0.13896,9.55011,33.43158
39.20600,3.26714,691.85589,-0.13896,9.58335,33.41815
39.30600,3.27551,691.86869,-0.13896,9.61683,33.41877
39.40600,3.28376,690.94477,-0.13896,9.64983,33.37414
39.50600,3.29213,691.20629,-0.13896,9.68332,33.38677
39.60600,3.30050,690.24041,-0.13896,9.71680,33.34011
39.70600,3.30875,689.37298,-0.13896,9.74980,33.29822
39.80600,3.31718,688.59602,-0.13896,9.78352,33.26069
39.90600,3.32549,688.55560,-0.13896,9.81677,33.25874
40.00600,3.33380,688.05572,-0.13896,9.85001,33.23459
40.10600,3.34223,687.30721,-0.13896,9.88373,33.19844
40.20600,3.35054,686.52192,-0.13896,9.91697,33.16050
40.30600,3.35885,686.34590,-0.13896,9.95022,33.15200
40.40600,3.36728,685.14035,-0.13897,9.98394,33.09377
40.50600,3.37548,684.96545,-0.13896,10.01670,33.08532
40.60600,3.38373,684.08293,-0.13896,10.04971,33.04269
40.70600,3.39222,683.31552,-0.13896,10.08367,33.00563
40.80600,3.40041,683.41726,-0.13896,10.11643,33.01054
40.90600,3.40878,682.51328,-0.13896,10.14991,32.96688
41.00600,3.41733,681.78964,-0.13896,10.18411,32.93192
41.10600,3.42552,680.60174,-0.13896,10.21688,32.87455
41.20600,3.43383,679.67377,-0.13896,10.25012,32.82972
41.30600,3.44232,678.92424,-0.13897,10.28408,32.79352
41.40600,3.45039,677.50090,-0.13897,10.31637,32.72477
41.50600,3.45882,676.48198,-0.13896,10.35009,32.67555
41.60600,3.46719,674.76807,-0.13896,10.38357,32.59277
41.70600,3.47538,673.72555,-0.13896,10.41634,32.54241
41.80600,3.48381,671.31212,-0.13896,10.45006,32.42584
41.90600,3.49218,669.08197,-0.13896,10.48354,32.31812
42.00600,3.50044,666.70836,-0.13896,10.51654,32.20346
42.10600,3.50887,664.15500,-0.13896,10.55027,32.08013
42.20600,3.51724,660.70370,-0.13897,10.58375,31.91343
42.30600,3.52543,656.94987,-0.13896,10.61651,31.73211
42.40600,3.53398,651.45548,-0.13897,10.65071,31.46672
42.50600,3.54217,644.93562,-0.13896,10.68348,31.15180
42.60600,3.55042,614.78564,-0.13897,10.71648,29.69549
42.66200,3.55526,9.64752,-0.13896,10.73585,0.46600