File: Manufatura Aditiva/Dados/Ensaios AMR/Ensaios/Ensaios SLS/Tracao_OLABI_21_12_2018_SLS_45.is_metal_RawData/Specimen_RawData_2.csv
Time,Extension,Load,Strain 1,Tensile strain,Tensile stress
(sec),(mm),(N),(mm/mm),(%),(MPa)
0.00000,0.00006,20.44942,0.00078,0.07750,1.03910
0.20000,0.01369,26.94925,0.00096,0.09584,1.36937
0.40000,0.03265,38.05698,0.00128,0.12796,1.93379
0.60000,0.04986,46.96614,0.00157,0.15732,2.38649
0.80000,0.06667,56.16821,0.00185,0.18509,2.85408
1.00000,0.08341,65.31783,0.00213,0.21332,3.31900
1.20000,0.10003,73.47714,0.00240,0.24038,3.73359
1.40000,0.11671,82.60728,0.00269,0.26883,4.19752
1.60000,0.13333,91.52182,0.00296,0.29638,4.65050
1.80000,0.14995,101.28370,0.00324,0.32416,5.14653
2.00000,0.16663,108.56452,0.00352,0.35222,5.51649
2.20000,0.18331,116.80644,0.00380,0.37970,5.93529
2.40000,0.19994,125.50782,0.00408,0.40781,6.37743
2.60000,0.21662,134.00100,0.00436,0.43595,6.80899
2.80000,0.23330,142.05744,0.00464,0.46370,7.21837
3.00000,0.25004,150.20533,0.00492,0.49158,7.63238
3.20000,0.26672,157.53378,0.00519,0.51867,8.00477
3.40000,0.28334,165.36473,0.00543,0.54331,8.40268
3.60000,0.29996,172.86761,0.00571,0.57135,8.78392
3.80000,0.31659,180.86456,0.00599,0.59890,9.19027
4.00000,0.33339,189.46091,0.00627,0.62668,9.62708
4.20000,0.35001,197.36446,0.00655,0.65497,10.02868
4.40000,0.36669,204.87146,0.00683,0.68334,10.41014
4.60000,0.38337,213.24654,0.00712,0.71201,10.83570
4.80000,0.39993,220.33285,0.00740,0.73978,11.19578
5.00000,0.41667,228.21268,0.00769,0.76853,11.59617
5.20000,0.43341,236.37088,0.00797,0.79672,12.01072
5.40000,0.45004,243.86931,0.00825,0.82484,12.39173
5.60000,0.46660,252.10222,0.00853,0.85339,12.81007
5.80000,0.48328,259.03410,0.00880,0.88013,13.16230
6.00000,0.50008,266.54396,0.00907,0.90743,13.54390
6.20000,0.51658,274.56465,0.00936,0.93577,13.95146
6.40000,0.53332,282.06406,0.00965,0.96453,14.33252
6.60000,0.55012,289.85699,0.00993,0.99276,14.72851
6.80000,0.56662,296.40889,0.01021,1.02084,15.06143
7.00000,0.58325,302.58889,0.01046,1.04580,15.37545
7.20000,0.59999,310.42746,0.01075,1.07497,15.77375
7.40000,0.61667,317.34731,0.01103,1.10324,16.12537
7.60000,0.63329,324.55793,0.01132,1.13155,16.49176
7.80000,0.64991,331.68423,0.01160,1.15978,16.85387
8.00000,0.66665,338.18136,0.01189,1.18877,17.18401
8.20000,0.68333,345.67222,0.01217,1.21746,17.56465
8.40000,0.70002,352.60799,0.01246,1.24553,17.91707
8.60000,0.71676,359.76919,0.01275,1.27470,18.28095
8.80000,0.73326,366.39983,0.01303,1.30308,18.61788
9.00000,0.75000,373.12405,0.01332,1.33199,18.95955
9.20000,0.76668,379.00272,0.01362,1.36196,19.25827
9.40000,0.78330,385.85372,0.01391,1.39081,19.60639
9.60000,0.80004,392.72052,0.01419,1.41909,19.95531
9.80000,0.81660,399.55601,0.01448,1.44825,20.30264
10.00000,0.83329,405.52509,0.01478,1.47791,20.60595
10.20000,0.84991,411.92397,0.01506,1.50641,20.93110
10.40000,0.86665,417.89808,0.01532,1.53193,21.23466
10.60000,0.88345,423.89529,0.01562,1.56178,21.53939
10.80000,0.90001,430.02730,0.01591,1.59089,21.85098
11.00000,0.91657,437.50061,0.01621,1.62078,22.23072
11.20000,0.93331,443.27066,0.01650,1.65006,22.52392
11.40000,0.94994,449.58210,0.01680,1.67960,22.84462
11.60000,0.96662,455.93730,0.01710,1.70984,23.16755
11.80000,0.98330,461.56021,0.01740,1.73976,23.45326
12.00000,0.99998,468.08035,0.01770,1.76986,23.78457
12.20000,1.01660,473.15722,0.01800,1.79997,24.04254
12.40000,1.03328,478.96300,0.01830,1.83021,24.33755
12.60000,1.05008,485.00020,0.01861,1.86110,24.64432
12.80000,1.06664,490.49286,0.01891,1.89122,24.92342
13.00000,1.08333,495.91628,0.01922,1.92168,25.19900
13.20000,1.10001,500.95948,0.01952,1.95190,25.45526
13.40000,1.11663,506.07803,0.01983,1.98305,25.71535
13.60000,1.13331,511.33991,0.02014,2.01401,25.98272
13.80000,1.14999,515.05761,0.02041,2.04104,26.17163
14.00000,1.16679,520.72085,0.02072,2.07234,26.45939
14.20000,1.18329,525.14016,0.02103,2.10324,26.68395
14.40000,1.19998,531.09461,0.02135,2.13489,26.98652
14.60000,1.21672,534.68850,0.02166,2.16624,27.16913
14.80000,1.23328,539.92369,0.02198,2.19782,27.43515
15.00000,1.24996,544.14263,0.02230,2.23031,27.64952
15.20000,1.26664,548.86346,0.02262,2.26167,27.88940
15.40000,1.28326,553.78363,0.02293,2.29333,28.13941
15.60000,1.29994,558.35503,0.02326,2.32562,28.37170
15.80000,1.31668,561.69000,0.02358,2.35757,28.54116
16.00000,1.33337,566.36739,0.02390,2.39038,28.77883
16.20000,1.35005,570.57636,0.02423,2.42269,28.99270
16.40000,1.36673,574.42007,0.02455,2.45528,29.18801
16.60000,1.38341,578.32515,0.02488,2.48777,29.38644
16.80000,1.39997,582.53226,0.02521,2.52146,29.60022
17.00000,1.41665,586.08134,0.02555,2.55462,29.78056
17.20000,1.43333,590.18880,0.02587,2.58724,29.98927
17.40000,1.44995,593.55437,0.02620,2.62049,30.16028
17.60000,1.46664,597.18764,0.02654,2.65444,30.34490
17.80000,1.48338,600.84141,0.02687,2.68699,30.53056
18.00000,1.50000,603.08236,0.02716,2.71628,30.64443
18.20000,1.51668,606.63619,0.02750,2.75021,30.82501
18.40000,1.53330,610.06467,0.02784,2.78362,30.99922
18.60000,1.54998,612.04769,0.02815,2.81453,31.09998
18.80000,1.56660,615.62057,0.02849,2.84925,31.28153
19.00000,1.58329,619.01608,0.02883,2.88298,31.45407
19.20000,1.60003,622.75436,0.02918,2.91767,31.64402
19.40000,1.61671,626.50675,0.02952,2.95230,31.83469
19.60000,1.63333,629.51976,0.02987,2.98652,31.98779
19.80000,1.65001,631.72579,0.03021,3.02122,32.09989
20.00000,1.66663,635.29247,0.03057,3.07208,32.28112
20.20000,1.68331,638.34689,0.03091,3.13880,32.43633
20.31400,1.69288,640.27975,0.03111,3.17707,32.53454
20.51400,1.70950,642.61071,0.03146,3.24355,32.65298
20.71400,1.72612,645.96483,0.03182,3.31004,32.82342
20.91400,1.74286,648.33970,0.03216,3.37701,32.94409
21.11400,1.75949,650.67373,0.03252,3.44349,33.06269
21.31400,1.77617,652.99892,0.03287,3.51022,33.18084
21.51400,1.79291,655.69426,0.03352,3.57718,33.31780
21.71400,1.80947,659.08609,0.03304,3.64343,33.49015
21.91400,1.82621,660.58310,0.02586,3.71039,33.56622
22.11400,1.84289,661.27474,0.00732,3.77712,33.60136
22.31400,1.85951,665.42570,0.00771,3.84360,33.81228
22.51400,1.87619,667.76853,0.00814,3.91033,33.93133
22.71400,1.89282,670.32110,0.00531,3.97681,34.06103
22.91400,1.90944,672.95618,0.00590,4.04330,34.19493
23.11400,1.92612,675.03001,0.00571,4.11002,34.30030
23.31400,1.94280,677.29596,0.01122,4.17675,34.41544
23.51400,1.95954,680.19321,0.02773,4.24371,34.56266
23.71400,1.97616,681.90214,0.11936,4.31020,34.64950
23.91400,1.99284,683.04432,-0.00581,4.37692,34.70753
24.11400,2.00946,685.63796,-0.04216,4.44341,34.83933
24.31400,2.02621,686.64793,-0.05083,4.51038,34.89065
24.51400,2.04295,687.88803,-0.03264,4.57734,34.95366
24.71400,2.05951,690.70095,-0.06707,4.64359,35.09659
24.91400,2.07619,692.82758,-0.04732,4.71031,35.20465
25.11400,2.09281,695.24702,-0.06782,4.77680,35.32759
25.31400,2.10943,697.55041,-0.06737,4.84328,35.44463
25.51400,2.12617,699.49091,-0.06749,4.91025,35.54324
25.71400,2.14274,701.55114,-0.06764,4.97649,35.64792
25.91400,2.15942,702.47198,-0.06763,5.04322,35.69471
26.11400,2.17616,704.68909,-0.06763,5.11018,35.80737
26.31400,2.19284,707.13600,-0.06766,5.17691,35.93171
26.51400,2.20952,708.78435,-0.06767,5.24363,36.01546
26.71400,2.22620,710.35195,-0.06768,5.31036,36.09512
26.91400,2.24288,712.33660,-0.06767,5.37708,36.19596
27.11400,2.25950,713.67775,-0.06767,5.44357,36.26411
27.31400,2.27613,715.85127,-0.06768,5.51005,36.37456
27.51400,2.29287,717.33077,-0.06769,5.57702,36.44973
27.71400,2.30949,719.23072,-0.06768,5.64351,36.54628
27.91400,2.32623,720.60334,-0.06771,5.71047,36.61602
28.11400,2.34285,722.62418,-0.06770,5.77696,36.71871
28.31400,2.35947,724.21320,-0.06770,5.84344,36.79945
28.51400,2.37615,725.40832,-0.06771,5.91017,36.86018
28.71400,2.39278,727.45960,-0.06771,5.97665,36.96441
28.91400,2.40946,728.78543,-0.06769,6.04338,37.03178
29.11400,2.42626,729.93860,-0.06769,6.11058,37.09037
29.31400,2.44282,731.67263,-0.06773,6.17683,37.17849
29.51400,2.45950,733.11985,-0.06771,6.24355,37.25203
29.71400,2.47618,734.23772,-0.06770,6.31028,37.30883
29.91400,2.49286,736.05021,-0.06771,6.37700,37.40092
30.11400,2.50954,737.73204,-0.06772,6.44373,37.48639
30.31400,2.52623,739.15608,-0.06773,6.51045,37.55874
30.51400,2.54285,740.91698,-0.06774,6.57694,37.64822
30.71400,2.55947,741.73170,-0.06775,6.64342,37.68962
30.91400,2.57615,742.61301,-0.06774,6.71015,37.73440
31.11400,2.59283,744.33503,-0.06772,6.77688,37.82190
31.31400,2.60939,745.36423,-0.06774,6.84312,37.87420
31.51400,2.62607,747.00988,-0.06773,6.90985,37.95782
31.71400,2.64281,747.55140,-0.06773,6.97681,37.98534
31.91400,2.65956,749.39951,-0.06773,7.04377,38.07924
32.11400,2.67618,750.57936,-0.06774,7.11026,38.13919
32.31400,2.69286,751.82337,-0.06773,7.17699,38.20241
32.51400,2.70948,753.54604,-0.06773,7.24347,38.28994
32.71400,2.72616,754.49115,-0.06772,7.31020,38.33796
32.91400,2.74278,756.40110,-0.06773,7.37668,38.43502
33.11400,2.75952,757.15194,-0.06771,7.44365,38.47317
33.31400,2.77627,757.61550,-0.06773,7.51061,38.49672
33.51400,2.79283,759.54311,-0.06775,7.57686,38.59467
33.71400,2.80945,760.71429,-0.06774,7.64334,38.65418
33.91400,2.82613,761.50256,-0.06772,7.71007,38.69424
34.11400,2.84281,762.38238,-0.06773,7.77679,38.73894
34.31400,2.85955,763.51762,-0.06771,7.84376,38.79663
34.51400,2.87617,764.62361,-0.06772,7.91024,38.85283
34.71400,2.89285,766.25505,-0.06773,7.97697,38.93573
34.91400,2.90948,766.95597,-0.06774,8.04346,38.97134
35.11400,2.92610,766.24569,-0.06773,8.10994,38.93525
35.31400,2.94296,767.88748,-0.06773,8.17738,39.01867
35.51400,2.95952,769.17191,-0.06773,8.24363,39.08394
35.71400,2.97608,770.20549,-0.06777,8.30988,39.13646
35.91400,2.99282,772.37003,-0.06777,8.37684,39.24644
36.11400,3.00950,772.11480,-0.06774,8.44357,39.23347
36.31400,3.02613,773.82587,-0.06773,8.51005,39.32042
36.51400,3.04281,775.56549,-0.06776,8.57678,39.40881
36.71400,3.05949,775.62761,-0.06775,8.64350,39.41197
36.91400,3.07611,776.74938,-0.06772,8.70999,39.46897
37.11400,3.09279,777.54557,-0.06774,8.77671,39.50943
37.31400,3.10953,778.60532,-0.06773,8.84368,39.56328
37.51400,3.12621,779.86284,-0.06772,8.91040,39.62718
37.71400,3.14289,780.84860,-0.06772,8.97713,39.67727
37.91400,3.15952,781.90034,-0.06771,9.04361,39.73071
38.11400,3.17614,783.01933,-0.06773,9.11010,39.78757
38.31400,3.19282,783.38748,-0.06773,9.17682,39.80627
38.51400,3.20950,784.00075,-0.06773,9.24355,39.83744
38.71400,3.22612,785.34465,-0.06773,9.31004,39.90572
38.91400,3.24274,786.51980,-0.06774,9.37652,39.96544
39.11400,3.25942,786.89838,-0.06773,9.44325,39.98467
39.31400,3.27623,788.07278,-0.06774,9.51045,40.04435
39.51400,3.29285,788.23259,-0.06772,9.57694,40.05247
39.71400,3.30947,789.50459,-0.06774,9.64342,40.11710
39.91400,3.32621,790.07139,-0.06773,9.71039,40.14590
40.11400,3.34277,791.28221,-0.06772,9.77663,40.20743
40.31400,3.35945,792.29353,-0.06774,9.84336,40.25882
40.51400,3.37619,792.96073,-0.06772,9.91032,40.29272
40.71400,3.39293,793.76716,-0.06771,9.97729,40.33370
40.91400,3.40950,794.40568,-0.06775,10.04353,40.36614
41.11400,3.42612,795.62003,-0.06774,10.11002,40.42785
41.31400,3.44286,796.16560,-0.06774,10.17698,40.45557
41.51400,3.45942,796.86204,-0.06773,10.24323,40.49096
41.71400,3.47616,797.83872,-0.06773,10.31019,40.54058
41.91400,3.49290,798.19327,-0.06773,10.37716,40.55860
42.11400,3.50946,799.10904,-0.06772,10.44341,40.60513
42.31400,3.52615,799.94649,-0.06773,10.51013,40.64769
42.51400,3.54283,800.78887,-0.06773,10.57686,40.69049
42.71400,3.55957,801.31292,-0.06772,10.64382,40.71712
42.91400,3.57613,801.62054,-0.06773,10.71007,40.73275
43.11400,3.59281,802.87270,-0.06772,10.77679,40.79638
43.31400,3.60949,803.66917,-0.06772,10.84352,40.83685
43.51400,3.62605,803.94521,-0.06772,10.90976,40.85088
43.71400,3.64279,804.49190,-0.06774,10.97673,40.87865
43.91400,3.65960,805.52977,-0.06774,11.04393,40.93139
44.11400,3.67616,806.20246,-0.06773,11.11018,40.96557
44.31400,3.69278,806.98673,-0.06773,11.17666,41.00542
44.51400,3.70946,807.58575,-0.06774,11.24339,41.03586
44.71400,3.72614,808.46502,-0.06773,11.31011,41.08054
44.91400,3.74288,808.83680,-0.06773,11.37708,41.09943
45.11400,3.75950,809.36756,-0.06772,11.44357,41.12640
45.31400,3.77618,809.71876,-0.06773,11.51029,41.14425
45.51400,3.79281,810.84985,-0.06773,11.57678,41.20172
45.71400,3.80949,811.53875,-0.06772,11.64350,41.23672
45.91400,3.82617,812.15799,-0.06773,11.71023,41.26819
46.11400,3.84279,812.33280,-0.06773,11.77671,41.27707
46.31400,3.85947,812.97802,-0.06772,11.84344,41.30986
46.51400,3.87615,813.72159,-0.06772,11.91016,41.34764
46.71400,3.89283,814.16098,-0.06772,11.97689,41.36997
46.91400,3.90952,814.44448,-0.06773,12.04361,41.38437
47.11400,3.92614,815.41799,-0.06774,12.11010,41.43384
47.31400,3.94288,816.41823,-0.06776,12.17706,41.48466
47.51400,3.95950,816.49497,-0.06773,12.24355,41.48857
47.71400,3.97612,817.04557,-0.06772,12.31003,41.51654
47.91400,3.99286,817.64692,-0.06773,12.37700,41.54710
48.11400,4.00954,817.75030,-0.06772,12.44372,41.55235
48.31400,4.02622,818.69531,-0.06773,12.51045,41.60037
48.51400,4.04285,819.07380,-0.06774,12.57693,41.61960
48.71400,4.05947,819.95949,-0.06773,12.64342,41.66461
48.91400,4.07615,820.04629,-0.06773,12.71014,41.66902
49.11400,4.09283,821.02409,-0.06774,12.77687,41.71870
49.31400,4.10957,821.79690,-0.06774,12.84383,41.75797
49.51400,4.12613,821.38982,-0.06778,12.91008,41.73729
49.71400,4.14281,822.94317,-0.06778,12.97681,41.81622
49.91400,4.15955,822.46670,-0.06777,13.04377,41.79201
50.11400,4.17612,823.74616,-0.06777,13.11002,41.85702
50.31400,4.19286,823.90727,-0.06775,13.17698,41.86521
50.51400,4.20954,824.65773,-0.06775,13.24371,41.90334
50.71400,4.22616,824.82193,-0.06772,13.31019,41.91168
50.91400,4.24278,824.99366,-0.06773,13.37668,41.92041
51.11400,4.25952,825.79078,-0.06775,13.44364,41.96091
51.31400,4.27620,826.43367,-0.06775,13.51037,41.99358
51.51400,4.29283,826.75433,-0.06774,13.57685,42.00988
51.71400,4.30939,826.87968,-0.06773,13.64310,42.01624
51.91400,4.32613,827.58665,-0.06773,13.71006,42.05217
52.11400,4.34275,827.68435,-0.06773,13.77655,42.05713
52.31400,4.35949,828.55718,-0.06774,13.84351,42.10148
52.51400,4.37617,828.61446,-0.06773,13.91024,42.10439
52.71400,4.39285,828.85204,-0.06772,13.97696,42.11647
52.91400,4.40947,829.70131,-0.06773,14.04345,42.15962
53.11400,4.42616,830.62602,-0.06773,14.11017,42.20661
53.31400,4.44284,830.71077,-0.06773,14.17690,42.21091
53.51400,4.45952,830.70742,-0.06775,14.24363,42.21074
53.71400,4.47620,831.79874,-0.06775,14.31035,42.26620
53.91400,4.49288,830.98868,-0.06775,14.37708,42.22503
54.11400,4.50950,832.12713,-0.06773,14.44356,42.28288
54.31400,4.52612,832.71656,-0.06773,14.51005,42.31283
54.51400,4.54287,832.81649,-0.06773,14.57701,42.31791
54.71400,4.55949,833.89319,-0.06773,14.64350,42.37262
54.91400,4.57611,833.54600,-0.06772,14.70998,42.35498
55.11400,4.59279,834.37730,-0.06772,14.77671,42.39722
55.31400,4.60953,834.47024,-0.06773,14.84367,42.40194
55.51400,4.62621,834.92603,-0.06778,14.91040,42.42510
55.71400,4.64283,835.39682,-0.06773,14.97689,42.44902
55.91400,4.65957,835.42746,-0.06773,15.04385,42.45058
56.11400,4.67620,835.20142,-0.06775,15.11033,42.43910
56.31400,4.69282,836.21265,-0.06776,15.17682,42.49048
56.51400,4.70950,836.77517,-0.06775,15.24355,42.51906
56.71400,4.72618,837.28358,-0.06773,15.31027,42.54490
56.91400,4.74280,837.45513,-0.06773,15.37676,42.55362
57.11400,4.75948,837.85830,-0.06774,15.44348,42.57410
57.31400,4.77616,837.77327,-0.06775,15.51021,42.56978
57.51400,4.79279,838.54571,-0.06774,15.57669,42.60903
57.71400,4.80947,838.85519,-0.06775,15.64342,42.62476
57.91400,4.82621,839.00495,-0.06775,15.71038,42.63237
58.11400,4.84283,839.77971,-0.06774,15.77687,42.67173
58.31400,4.85945,839.81603,-0.06775,15.84335,42.67358
58.51400,4.87613,839.91149,-0.06774,15.91008,42.67843
58.71400,4.89287,840.50670,-0.06773,15.97704,42.70868
58.91400,4.90949,840.56053,-0.06774,16.04353,42.71141
59.11400,4.92612,840.95988,-0.06773,16.11001,42.73170
59.31400,4.94280,841.05469,-0.06773,16.17674,42.73652
59.51400,4.95954,841.29265,-0.06772,16.24370,42.74861
59.71400,4.97610,841.56916,-0.06774,16.30995,42.76266
59.91400,4.99284,841.50946,-0.06773,16.37691,42.75963
60.11400,5.00952,841.89586,-0.06772,16.44364,42.77926
60.31400,5.02608,842.69987,-0.06773,16.50988,42.82011
60.51400,5.04277,842.61401,-0.06773,16.57661,42.81575
60.71400,5.05951,842.86686,-0.06772,16.64357,42.82860
60.91400,5.07613,843.49588,-0.06774,16.71006,42.86056
61.11400,5.09293,843.33466,-0.06779,16.77727,42.85237
61.31400,5.10949,843.70375,-0.06780,16.84351,42.87112
61.51400,5.12611,843.76223,-0.06779,16.91000,42.87410
61.71400,5.14285,843.13937,-0.06780,16.97696,42.84245
61.91400,5.15947,843.27022,-0.06779,17.04345,42.84910
62.11400,5.17616,842.99576,-0.06779,17.11017,42.83515
62.31400,5.19284,843.90026,-0.06779,17.17690,42.88111
62.51400,5.20946,843.99041,-0.06777,17.24338,42.88569
62.71400,5.22614,844.64103,-0.06775,17.31011,42.91875
62.91400,5.24276,845.04867,-0.06774,17.37660,42.93946
63.11400,5.25956,845.59191,-0.06775,17.44380,42.96707
63.31400,5.27618,846.03373,-0.06774,17.51028,42.98952
63.51400,5.29287,845.76886,-0.06772,17.57701,42.97606
63.71400,5.30955,846.35420,-0.06775,17.64373,43.00580
63.91400,5.32617,846.16169,-0.06776,17.71022,42.99602
64.11401,5.34285,846.07452,-0.06774,17.77695,42.99159
64.31400,5.35959,847.15299,-0.06779,17.84391,43.04639
64.51400,5.37621,847.22331,-0.06779,17.91040,43.04996
64.71400,5.39283,846.65082,-0.06779,17.97688,43.02087
64.91400,5.40945,846.95108,-0.06774,18.04337,43.03613
65.11401,5.42620,846.97623,-0.06774,18.11033,43.03741
65.31400,5.44282,847.73516,-0.06776,18.17682,43.07597
65.51400,5.45944,848.10080,-0.06775,18.24330,43.09455
65.71401,5.47618,847.91388,-0.06774,18.31027,43.08506
65.91400,5.49280,848.35226,-0.06773,18.37675,43.10733
66.11401,5.50948,847.76552,-0.06773,18.44348,43.07751
66.31400,5.52616,848.85024,-0.06774,18.51020,43.13263
66.51400,5.54290,848.71221,-0.06775,18.57717,43.12562
66.71401,5.55953,848.69023,-0.06774,18.64365,43.12450
66.91400,5.57609,848.77862,-0.06773,18.70990,43.12899
67.11401,5.59283,849.53289,-0.06774,18.77686,43.16732
67.31400,5.60951,849.06016,-0.06775,18.84359,43.14330
67.51400,5.62619,849.30230,-0.06774,18.91032,43.15561
67.71401,5.64287,850.29472,-0.06774,18.97704,43.20603
67.91400,5.65949,849.82878,-0.06773,19.04353,43.18236
68.11401,5.67612,849.94836,-0.06774,19.11001,43.18843
68.31400,5.69286,849.39683,-0.06774,19.17698,43.16041
68.51400,5.70948,849.91381,-0.06773,19.24346,43.18668
68.71401,5.72610,850.49663,-0.06773,19.30995,43.21629
68.91400,5.74278,850.50939,-0.06773,19.37667,43.21694
69.11401,5.75958,850.64108,-0.06773,19.44388,43.22363
69.31400,5.77620,850.26119,-0.06773,19.51036,43.20433
69.51400,5.79288,850.18016,-0.06774,19.57709,43.20021
69.71401,5.80963,850.61295,-0.06774,19.64405,43.22220
69.91400,5.82613,850.51991,-0.06774,19.71006,43.21748
70.11401,5.84275,850.46394,-0.06773,19.77654,43.21463
70.31400,5.85955,850.69975,-0.06773,19.84375,43.22661
70.51400,5.87611,851.53151,-0.06774,19.90999,43.26888
70.71401,5.89285,851.41240,-0.06776,19.97696,43.26283
70.91400,5.90953,851.09072,-0.06777,20.04368,43.24648
71.11401,5.92622,851.57435,-0.06776,20.11041,43.27105
71.31400,5.94278,851.49920,-0.06776,20.17666,43.26723
71.51400,5.95952,851.55675,-0.06776,20.24362,43.27016
71.71401,5.97626,851.76239,-0.06773,20.31059,43.28061
71.91400,5.99282,851.47787,-0.06775,20.37683,43.26615
72.11401,6.00950,851.92490,-0.06774,20.44356,43.28887
72.31400,6.02618,851.44257,-0.06774,20.51028,43.26436
72.51400,6.04280,851.97324,-0.06774,20.57677,43.29132
72.71401,6.05955,851.77105,-0.06775,20.64373,43.28105
72.91400,6.07617,852.13883,-0.06774,20.71022,43.29974
73.11401,6.09279,851.81156,-0.06774,20.77670,43.28311
73.31400,6.10947,852.21399,-0.06773,20.84343,43.30355
73.51400,6.12615,851.78576,-0.06774,20.91015,43.28180
73.71401,6.14289,852.83825,-0.06775,20.97712,43.33528
73.91400,6.15957,852.25366,-0.06772,21.04384,43.30557
74.11401,6.17613,851.95005,-0.06776,21.11009,43.29015
74.31400,6.19276,853.11625,-0.06775,21.17658,43.34940
74.51400,6.20944,852.14656,-0.06774,21.24330,43.30013
74.71401,6.22612,852.76058,-0.06774,21.31003,43.33133
74.91400,6.24292,852.81339,-0.06775,21.37723,43.33401
75.11401,6.25960,852.00798,-0.06774,21.44395,43.29309
75.31400,6.27610,852.66391,-0.06775,21.50996,43.32642
75.51400,6.29278,853.16766,-0.06775,21.57668,43.35202
75.71401,6.30947,853.06223,-0.06775,21.64341,43.34666
75.91400,6.32609,853.13544,-0.06773,21.70990,43.35038
76.11401,6.34289,852.92216,-0.06773,21.77710,43.33954
76.31400,6.35963,853.70466,-0.06774,21.84407,43.37930
76.51400,6.37613,853.40869,-0.06774,21.91007,43.36426
76.71401,6.39281,853.95249,-0.06773,21.97680,43.39190
76.91400,6.40955,853.43607,-0.06775,22.04376,43.36565
77.11401,6.42617,853.02703,-0.06773,22.11025,43.34487
77.31400,6.44286,852.68645,-0.06774,22.17697,43.32756
77.51400,6.45954,853.13320,-0.06774,22.24370,43.35027
77.71401,6.47616,853.75169,-0.06774,22.31019,43.38169
77.91400,6.49278,853.30391,-0.06776,22.37667,43.35894
78.11401,6.50952,853.13162,-0.06775,22.44363,43.35019
78.31400,6.52620,853.32403,-0.06776,22.51036,43.35996
78.51400,6.54270,854.20022,-0.06776,22.57637,43.40448
78.71401,6.55945,853.59411,-0.06773,22.64333,43.37368
78.91400,6.57619,853.56645,-0.06774,22.71030,43.37228
79.11401,6.59287,853.96571,-0.06774,22.77702,43.39257
79.31400,6.60949,853.51262,-0.06775,22.84351,43.36954
79.51401,6.62623,853.36510,-0.06775,22.91047,43.36205
79.71401,6.64279,853.96096,-0.06775,22.97672,43.39233
79.91400,6.65941,853.36911,-0.06775,23.04320,43.36225
80.11401,6.67615,853.89176,-0.06775,23.11017,43.38881
80.31400,6.69284,853.52212,-0.06774,23.17689,43.37003
80.51401,6.70946,852.89022,-0.06774,23.24338,43.33792
80.71401,6.72614,853.07127,-0.06774,23.31010,43.34712
80.91400,6.74282,853.29274,-0.06773,23.37683,43.35837
81.11401,6.75944,853.83011,-0.06774,23.44332,43.38568
81.31400,6.77612,853.50266,-0.06776,23.51004,43.36904
81.51401,6.79286,853.02033,-0.06775,23.57700,43.34453
81.71401,6.80943,852.80212,-0.06774,23.64325,43.33344
81.91400,6.82617,853.07751,-0.06775,23.71022,43.34743
82.11401,6.84285,853.13199,-0.06776,23.77694,43.35020
82.31400,6.85959,852.99071,-0.06776,23.84391,43.34303
82.51401,6.87621,853.27392,-0.06775,23.91039,43.35741
82.71401,6.89283,852.61809,-0.06776,23.97688,43.32409
82.91400,6.90951,852.81059,-0.06774,24.04360,43.33387
83.11401,6.92607,853.09995,-0.06773,24.10985,43.34858
83.31400,6.94276,852.78498,-0.06773,24.17658,43.33257
83.51401,6.95956,853.41390,-0.06774,24.24378,43.36453
83.71401,6.97618,852.53939,-0.06774,24.31026,43.32009
83.91400,6.99280,853.55667,-0.06774,24.37675,43.37178
84.11401,7.00948,852.85464,-0.06774,24.44347,43.33611
84.31400,7.02616,853.38838,-0.06773,24.51020,43.36323
84.51401,7.04284,852.59285,-0.06775,24.57692,43.32281
84.71401,7.05952,853.41586,-0.06775,24.64365,43.36463
84.91400,7.07621,852.82652,-0.06775,24.71037,43.33468
85.11401,7.09277,852.77427,-0.06779,24.77662,43.33203
85.31400,7.10951,852.70712,-0.06777,24.84359,43.32861
85.51401,7.12625,852.71802,-0.06777,24.91055,43.32917
85.71401,7.14281,852.90605,-0.06777,24.97679,43.33872
85.91400,7.15949,853.14820,-0.06777,25.04352,43.35102
86.11401,7.17611,852.87914,-0.06775,25.11001,43.33735
86.31400,7.19280,852.89245,-0.06775,25.17673,43.33803
86.51401,7.20948,852.75946,-0.06774,25.24346,43.33127
86.71401,7.22610,853.04854,-0.06773,25.30994,43.34596
86.91400,7.24284,852.24379,-0.06773,25.37691,43.30507
87.11401,7.25952,852.80817,-0.06773,25.44363,43.33375
87.31400,7.27614,851.95117,-0.06774,25.51012,43.29020
87.51401,7.29282,852.45129,-0.06774,25.57684,43.31561
87.71401,7.30950,852.04160,-0.06774,25.64357,43.29480
87.91400,7.32619,852.39280,-0.06774,25.71030,43.31264
88.11401,7.34281,852.01627,-0.06776,25.77678,43.29351
88.31400,7.35949,852.03592,-0.06774,25.84350,43.29451
88.51401,7.37623,852.15392,-0.06774,25.91047,43.30050
88.71401,7.39285,852.12430,-0.06775,25.97695,43.29900
88.91400,7.40947,851.88914,-0.06773,26.04344,43.28705
89.11401,7.42615,851.95573,-0.06773,26.11017,43.29043
89.31400,7.44278,851.15088,-0.06773,26.17665,43.24954
89.51401,7.45952,851.74469,-0.06774,26.24362,43.27971
89.71401,7.47614,851.51000,-0.06772,26.31010,43.26778
89.91400,7.49288,851.28546,-0.06773,26.37707,43.25637
90.11401,7.50956,851.43801,-0.06773,26.44379,43.26413
90.31400,7.52618,851.84425,-0.06774,26.51028,43.28477
90.51401,7.54286,850.78590,-0.06774,26.57700,43.23099
90.71401,7.55948,851.07861,-0.06774,26.64349,43.24586
90.91400,7.57617,851.50292,-0.06773,26.71021,43.26743
91.11401,7.59285,851.36872,-0.06773,26.77694,43.26060
91.31400,7.60947,851.14855,-0.06773,26.84343,43.24942
91.51401,7.62615,851.34655,-0.06774,26.91015,43.25948
91.71401,7.64277,850.57989,-0.06773,26.97664,43.22052
91.91400,7.65945,851.19409,-0.06773,27.04336,43.25173
92.11401,7.67625,850.78171,-0.06773,27.11056,43.23078
92.31400,7.69282,850.49849,-0.06772,27.17681,43.21638
92.51401,7.70950,850.44391,-0.06773,27.24354,43.21362
92.71401,7.72618,850.47577,-0.06774,27.31026,43.21523
92.91400,7.74286,850.50119,-0.06774,27.37699,43.21652
93.11401,7.75948,850.86580,-0.06772,27.44347,43.23505
93.31400,7.77616,850.11246,-0.06772,27.51020,43.19677
93.51401,7.79284,849.89285,-0.06774,27.57692,43.18561
93.71401,7.80946,850.35553,-0.06775,27.64341,43.20912
93.91400,7.82615,850.27926,-0.06776,27.71013,43.20525
94.11401,7.84283,849.88819,-0.06775,27.77686,43.18538
94.31400,7.85951,849.61215,-0.06775,27.84358,43.17135
94.51401,7.87613,849.86016,-0.06778,27.91007,43.18395
94.71401,7.89275,849.44684,-0.06777,27.97655,43.16295
94.91400,7.90949,849.65229,-0.06777,28.04352,43.17339
95.11401,7.92617,849.21001,-0.06777,28.11024,43.15091
95.31400,7.94285,849.76116,-0.06775,28.17697,43.17892
95.51401,7.95954,848.99496,-0.06775,28.24369,43.13999
95.71401,7.97622,849.09722,-0.06778,28.31042,43.14518
95.91400,7.99284,848.76139,-0.06777,28.37690,43.12812
96.11401,8.00946,849.01722,-0.06775,28.44339,43.14112
96.31400,8.02614,848.21275,-0.06775,28.51011,43.10024
96.51401,8.04282,848.57065,-0.06774,28.57684,43.11843
96.71401,8.05950,848.65233,-0.06774,28.64357,43.12258
96.91400,8.07612,847.94173,-0.06776,28.71005,43.08647
97.11401,8.09275,849.12367,-0.06776,28.77654,43.14653
97.31400,8.10949,848.66844,-0.06774,28.84350,43.12340
97.51401,8.12623,848.52315,-0.06774,28.91047,43.11601
97.71401,8.14285,847.72743,-0.06776,28.97695,43.07558
97.91400,8.15947,848.63184,-0.06774,29.04344,43.12154
98.11401,8.17615,847.52310,-0.06774,29.11016,43.06520
98.31400,8.19277,847.60599,-0.06773,29.17665,43.06941
98.51401,8.20952,847.72939,-0.06774,29.24361,43.07568
98.71401,8.22626,847.35211,-0.06774,29.31058,43.05651
98.91400,8.24276,847.06582,-0.06776,29.37658,43.04196
99.11401,8.25950,847.18531,-0.06775,29.44355,43.04803
99.31400,8.27618,847.27621,-0.06773,29.51027,43.05265
99.51401,8.29286,846.65287,-0.06776,29.57700,43.02098
99.71401,8.30954,847.07662,-0.06776,29.64372,43.04251
99.91400,8.32623,846.20509,-0.06774,29.71045,42.99823
100.11401,8.34291,845.72351,-0.06774,29.77718,42.97375
100.31400,8.35947,846.00812,-0.06774,29.84342,42.98822
100.51401,8.37609,846.05096,-0.06772,29.90991,42.99039
100.71401,8.39289,845.81543,-0.06773,29.97711,42.97843
100.91400,8.40951,846.47061,-0.06773,30.04360,43.01172
101.11401,8.42613,846.24905,-0.06773,30.11008,43.00046
101.31400,8.44281,845.90307,-0.06773,30.17681,42.98288
101.51401,8.45950,845.15419,-0.06773,30.24353,42.94483
101.71401,8.47618,845.50623,-0.06774,30.31026,42.96272
101.91400,8.49286,844.91568,-0.06775,30.37698,42.93271
102.11401,8.50948,845.67592,-0.06775,30.44347,42.97134
102.31400,8.52610,845.10790,-0.06775,30.50995,42.94247
102.51401,8.54278,844.72429,-0.06775,30.57668,42.92298
102.71401,8.55952,844.99167,-0.06773,30.64364,42.93657
102.91400,8.57620,844.72140,-0.06774,30.71037,42.92284
103.11401,8.59283,844.02114,-0.06773,30.77686,42.88725
103.31400,8.60957,844.17034,-0.06775,30.84382,42.89483
103.51401,8.62613,843.66295,-0.06775,30.91007,42.86905
103.71401,8.64287,844.28927,-0.06775,30.97703,42.90088
103.91400,8.65955,844.25882,-0.06775,31.04375,42.89933
104.11401,8.67617,843.27478,-0.06775,31.11024,42.84933
104.31400,8.69279,843.25690,-0.06775,31.17673,42.84842
104.51401,8.70936,843.26854,-0.06776,31.24297,42.84901
104.71401,8.72616,843.35981,-0.06776,31.31018,42.85365
104.91400,8.74284,842.84907,-0.06773,31.37690,42.82770
105.11401,8.75946,842.44739,-0.06775,31.44339,42.80729
105.31400,8.77620,842.58784,-0.06775,31.51035,42.81442
105.51401,8.79276,842.98281,-0.06774,31.57660,42.83449
105.71401,8.80950,842.56660,-0.06776,31.64356,42.81334
105.91400,8.82624,842.58392,-0.06775,31.71052,42.81422
106.11401,8.84287,841.88217,-0.06775,31.77702,42.77856
106.31400,8.85949,841.77107,-0.06775,31.84350,42.77292
106.51401,8.87617,841.38745,-0.06774,31.91022,42.75343
106.71401,8.89285,841.33558,-0.06773,31.97695,42.75079
106.91400,8.90947,841.20380,-0.06773,32.04344,42.74409
107.11401,8.92615,841.16822,-0.06775,32.11016,42.74229
107.31400,8.94289,840.81572,-0.06773,32.17713,42.72438
107.51401,8.95939,841.06522,-0.06774,32.24313,42.73705
107.71401,8.97614,841.16030,-0.06775,32.31010,42.74189
107.91400,8.99294,840.00397,-0.06775,32.37730,42.68313
108.11401,9.00956,840.96156,-0.06774,32.44379,42.73178
108.31400,9.02612,840.10391,-0.06777,32.51003,42.68821
108.51401,9.04286,839.48253,-0.06777,32.57700,42.65663
108.71401,9.05954,839.74041,-0.06777,32.64372,42.66973
108.91400,9.07616,839.18525,-0.06775,32.71021,42.64153
109.11401,9.09285,838.34147,-0.06775,32.77693,42.59865
109.31400,9.10959,839.23545,-0.06774,32.84390,42.64408
109.51401,9.12615,838.50008,-0.06775,32.91014,42.60671
109.71401,9.14277,839.14977,-0.06775,32.97663,42.63972
109.91400,9.15951,838.13649,-0.06774,33.04359,42.58824
110.11401,9.17607,838.41570,-0.06775,33.10984,42.60242
110.31400,9.19281,837.46472,-0.06776,33.17680,42.55410
110.51401,9.20955,837.96335,-0.06775,33.24377,42.57944
110.71401,9.22618,838.25802,-0.06774,33.31026,42.59441
110.91400,9.24286,837.61448,-0.06774,33.37698,42.56171
111.11401,9.25954,836.65447,-0.06773,33.44371,42.51293
111.31400,9.27628,836.88432,-0.06774,33.51067,42.52461
111.51401,9.29284,836.81960,-0.06775,33.57691,42.52132
111.71401,9.30934,836.86765,-0.06774,33.64292,42.52376
111.91401,9.32614,836.39035,-0.06774,33.71013,42.49951
112.11401,9.34282,836.20902,-0.06777,33.77685,42.49030
112.31400,9.35957,835.89135,-0.06775,33.84382,42.47416
112.51401,9.37625,835.96092,-0.06776,33.91054,42.47769
112.71401,9.39281,835.63020,-0.06775,33.97679,42.46088
112.91401,9.40943,835.39775,-0.06775,34.04327,42.44907
113.11401,9.42617,835.62136,-0.06775,34.11024,42.46043
113.31400,9.44291,834.52323,-0.06774,34.17720,42.40464
113.51401,9.45948,834.09697,-0.06775,34.24345,42.38298
113.71401,9.47610,835.04748,-0.06775,34.30994,42.43127
113.91401,9.49290,834.02833,-0.06775,34.37714,42.37949
114.11401,9.50946,834.11178,-0.06775,34.44339,42.38373
114.31400,9.52614,833.88621,-0.06777,34.51011,42.37226
114.51401,9.54288,833.51871,-0.06774,34.57708,42.35359
114.71401,9.55950,833.59741,-0.06774,34.64356,42.35759
114.91401,9.57612,833.23447,-0.06774,34.71005,42.33915
115.11401,9.59281,833.25133,-0.06772,34.77677,42.34001
115.31400,9.60949,832.86269,-0.06773,34.84350,42.32026
115.51401,9.62611,832.14473,-0.06774,34.90998,42.28378
115.71401,9.64285,831.74324,-0.06775,34.97694,42.26337
115.91401,9.65947,832.02263,-0.06772,35.04344,42.27757
116.11401,9.67615,831.50072,-0.06773,35.11016,42.25105
116.31400,9.69283,830.95385,-0.06775,35.17688,42.22326
116.51401,9.70951,831.33727,-0.06774,35.24361,42.24275
116.71401,9.72620,831.20335,-0.06774,35.31033,42.23594
116.91401,9.74288,831.13257,-0.06775,35.37706,42.23235
117.11401,9.75950,830.82700,-0.06775,35.44354,42.21682
117.31400,9.77612,830.30770,-0.06774,35.51003,42.19043
117.51401,9.79280,829.98322,-0.06775,35.57675,42.17394
117.71401,9.80948,830.05354,-0.06776,35.64348,42.17752
117.91401,9.82616,829.24068,-0.06776,35.71020,42.13622
118.11401,9.84284,829.23090,-0.06777,35.77693,42.13572
118.31400,9.85947,829.17474,-0.06777,35.84341,42.13286
118.51401,9.87621,828.44673,-0.06775,35.91038,42.09587
118.71401,9.89283,828.34587,-0.06775,35.97687,42.09074
118.91401,9.90945,828.86089,-0.06779,36.04335,42.11692
119.11401,9.92619,827.70418,-0.06779,36.11031,42.05814
119.31400,9.94287,827.38800,-0.06775,36.17704,42.04207
119.51401,9.95949,827.62670,-0.06775,36.24353,42.05420
119.71401,9.97624,827.19093,-0.06774,36.31049,42.03206
119.91401,9.99292,827.37682,-0.06775,36.37722,42.04150
120.11401,10.00948,826.80481,-0.06774,36.44346,42.01244
120.31400,10.02616,826.51014,-0.06774,36.51019,41.99747
120.51401,10.04284,826.13453,-0.06774,36.57691,41.97838
120.71401,10.05946,825.85253,-0.06776,36.64340,41.96405
120.91401,10.07614,825.82161,-0.06774,36.71012,41.96248
121.11401,10.09288,825.36098,-0.06774,36.77709,41.93908
121.31400,10.10951,825.06016,-0.06773,36.84358,41.92379
121.51401,10.12613,824.64162,-0.06774,36.91006,41.90252
121.71401,10.14287,824.86747,-0.06776,36.97702,41.91400
121.91401,10.15955,823.95906,-0.06776,37.04375,41.86784
122.11401,10.17623,824.30113,-0.06776,37.11047,41.88522
122.31400,10.19279,823.97535,-0.06778,37.17672,41.86867
122.51401,10.20953,823.55207,-0.06775,37.24369,41.84716
122.71401,10.22616,823.42103,-0.06774,37.31017,41.84050
122.91401,10.24272,822.70689,-0.06775,37.37642,41.80421
123.11401,10.25946,822.51662,-0.06776,37.44338,41.79454
123.31400,10.27614,821.91546,-0.06776,37.51011,41.76400
123.51401,10.29282,821.81059,-0.06777,37.57683,41.75867
123.71401,10.30950,821.81953,-0.06776,37.64355,41.75912
123.91401,10.32612,821.14413,-0.06777,37.71005,41.72480
124.11401,10.34286,820.65314,-0.06775,37.77701,41.69986
124.31400,10.35949,820.20955,-0.06774,37.84349,41.67731
124.51401,10.37623,819.90398,-0.06776,37.91046,41.66179
124.71401,10.39279,820.10617,-0.06774,37.97670,41.67206
124.91401,10.40947,819.25606,-0.06773,38.04343,41.62886
125.11401,10.42615,818.92870,-0.06776,38.11016,41.61223
125.31400,10.44283,818.88512,-0.06777,38.17688,41.61002
125.51401,10.45951,818.23329,-0.06775,38.24360,41.57689
125.71401,10.47620,818.61597,-0.06775,38.31033,41.59634
125.91401,10.49282,817.18983,-0.06777,38.37682,41.52387
126.11401,10.50950,817.19644,-0.06775,38.44354,41.52421
126.31400,10.52618,816.58401,-0.06774,38.51027,41.49309
126.51401,10.54292,816.54666,-0.06776,38.57723,41.49119
126.71401,10.55948,816.13977,-0.06776,38.64347,41.47052
126.91401,10.57616,815.55387,-0.06777,38.71020,41.44075
127.11401,10.59290,815.37347,-0.06774,38.77717,41.43158
127.31400,10.60941,815.09445,-0.06775,38.84317,41.41740
127.51401,10.62621,814.75610,-0.06774,38.91038,41.40021
127.71401,10.64289,813.86212,-0.06775,38.97710,41.35478
127.91401,10.65945,813.77104,-0.06775,39.04335,41.35015
128.11402,10.67613,812.94784,-0.06777,39.11008,41.30833
128.31401,10.69287,812.99208,-0.06776,39.17704,41.31057
128.51401,10.70955,812.24693,-0.06776,39.24377,41.27271
128.71401,10.72612,811.85214,-0.06774,39.31001,41.25265
128.91400,10.74286,811.68395,-0.06775,39.37697,41.24410
129.11402,10.75954,811.62881,-0.06776,39.44370,41.24130
129.31401,10.77610,810.87677,-0.06774,39.50994,41.20309
129.51401,10.79284,810.26983,-0.06774,39.57691,41.17225
129.71401,10.80958,810.49744,-0.06774,39.64388,41.18381
129.91400,10.82614,809.42838,-0.06774,39.71012,41.12949
130.11402,10.84282,808.74376,-0.06775,39.77685,41.09470
130.31401,10.85945,808.02189,-0.06775,39.84333,41.05802
130.51401,10.87619,807.77416,-0.06774,39.91030,41.04544
130.71401,10.89287,807.04642,-0.06777,39.97702,41.00846
130.91400,10.90943,806.67203,-0.06776,40.04327,40.98943
131.11402,10.92611,806.01936,-0.06774,40.10999,40.95627
131.31402,10.94279,805.68306,-0.06775,40.17672,40.93918
131.51400,10.95947,804.89349,-0.06777,40.24344,40.89906
131.71400,10.97627,804.54191,-0.06775,40.31065,40.88120
131.91400,10.99284,804.38247,-0.06775,40.37689,40.87309
132.11402,11.00946,803.66237,-0.06775,40.44338,40.83650
132.31402,11.02614,802.86833,-0.06775,40.51011,40.79615
132.51400,11.04288,802.39838,-0.06773,40.57707,40.77227
132.71400,11.05950,801.13169,-0.06774,40.64355,40.70791
132.91400,11.07618,800.65094,-0.06775,40.71028,40.68348
133.11402,11.09286,800.63539,-0.06774,40.77700,40.68269
133.31402,11.10943,800.11794,-0.06774,40.84325,40.65640
133.51400,11.12611,798.67281,-0.06774,40.90998,40.58297
133.71400,11.14285,798.50880,-0.06774,40.97694,40.57463
133.91400,11.15947,798.06512,-0.06772,41.04343,40.55209
134.11402,11.17621,797.62191,-0.06773,41.11039,40.52957
134.31402,11.19289,796.16457,-0.06774,41.17712,40.45552
134.51400,11.20945,795.66641,-0.06773,41.24336,40.43020
134.71400,11.22608,794.86500,-0.06774,41.30985,40.38948
134.91400,11.24294,794.13699,-0.06774,41.37729,40.35249
135.11402,11.25956,793.86467,-0.06774,41.44377,40.33865
135.31402,11.27612,792.70452,-0.06775,41.51002,40.27970
135.51400,11.29280,792.16491,-0.06774,41.57675,40.25228
135.71400,11.30954,791.22921,-0.06776,41.64371,40.20473
135.91400,11.32622,790.08136,-0.06776,41.71044,40.14641
136.11402,11.34284,789.87442,-0.06778,41.77693,40.13589
136.31402,11.35952,788.75879,-0.06776,41.84365,40.07921
136.51400,11.37609,788.30039,-0.06775,41.90990,40.05592
136.71400,11.39277,787.40995,-0.06775,41.97662,40.01067
136.91400,11.40951,786.22876,-0.06774,42.04358,39.95065
137.11402,11.42625,785.52626,-0.06775,42.11055,39.91495
137.31402,11.44281,784.47536,-0.06774,42.17680,39.86155
137.51400,11.45943,783.55083,-0.06775,42.24328,39.81458
137.71400,11.47617,782.92042,-0.06775,42.31025,39.78254
137.91400,11.49280,781.83943,-0.06774,42.37674,39.72762
138.11402,11.50948,780.24673,-0.06774,42.44346,39.64668
138.31402,11.52616,779.51965,-0.06775,42.51018,39.60974
138.51400,11.54278,779.02689,-0.06774,42.57667,39.58470
138.71400,11.55940,777.94446,-0.06773,42.64316,39.52970
138.91400,11.57614,776.28191,-0.06774,42.71012,39.44522
139.11402,11.59282,775.37559,-0.06774,42.77685,39.39917
139.31402,11.60951,774.34923,-0.06775,42.84357,39.34702
139.51400,11.62619,774.10717,-0.06775,42.91030,39.33471
139.71400,11.64287,772.70675,-0.06776,42.97702,39.26355
139.91400,11.65949,771.50585,-0.06775,43.04351,39.20253
140.11402,11.67611,770.48489,-0.06776,43.10999,39.15065
140.31402,11.69291,768.92143,-0.06775,43.17719,39.07121
140.51400,11.70953,768.10024,-0.06776,43.24368,39.02948
140.71400,11.72609,767.70228,-0.06775,43.30993,39.00926
140.91400,11.74284,765.90530,-0.06774,43.37689,38.91795
141.11402,11.75946,764.94692,-0.06774,43.44338,38.86926
141.31402,11.77614,763.50905,-0.06775,43.51010,38.79619
141.51400,11.79288,761.95970,-0.06775,43.57707,38.71746
141.71400,11.80950,761.26652,-0.06775,43.64356,38.68224
141.91400,11.82606,759.41873,-0.06775,43.70980,38.58835
142.11402,11.84286,758.56615,-0.06774,43.77700,38.54503
142.31402,11.85960,757.42984,-0.06774,43.84397,38.48729
142.51400,11.87611,755.97740,-0.06775,43.90997,38.41349
142.71400,11.89285,754.55764,-0.06774,43.97694,38.34134
142.91400,11.90959,752.45635,-0.06774,44.04390,38.23457
143.11402,11.92615,751.49969,-0.06775,44.11015,38.18596
143.31402,11.94283,748.75141,-0.06776,44.17688,38.04631
143.51400,11.95957,747.36429,-0.06775,44.24384,37.97583
143.71400,11.97619,744.36078,-0.06776,44.31033,37.82321
143.91400,11.99275,739.89425,-0.06775,44.37657,37.59625
144.11402,12.00944,731.62038,-0.06775,44.44330,37.17583
144.31402,12.02618,706.35211,-0.06777,44.51026,35.89188
144.38600,12.03222,2.13464,-0.06775,44.53442,0.10847