File: Manufatura Aditiva/Dados/Ensaios AMR/Ensaios/Ensaios SLS/Tracao_OLABI_21_12_2018_SLS_45.is_metal_RawData/Specimen_RawData_5.csv
Time,Extension,Load,Strain 1,Tensile strain,Tensile stress
(sec),(mm),(N),(mm/mm),(%),(MPa)
0.00000,0.00006,27.88230,0.00088,0.08829,1.31207
0.20000,0.01369,34.99235,0.00107,0.10686,1.64665
0.40000,0.03265,46.66051,0.00139,0.13916,2.19573
0.60000,0.04986,55.97319,0.00168,0.16803,2.63396
0.80000,0.06667,66.04053,0.00195,0.19533,3.10770
1.00000,0.08341,75.84114,0.00224,0.22374,3.56889
1.20000,0.10003,84.39873,0.00252,0.25186,3.97159
1.40000,0.11671,93.35983,0.00279,0.27941,4.39328
1.60000,0.13333,102.79554,0.00307,0.30708,4.83730
1.80000,0.14995,111.67992,0.00335,0.33486,5.25538
2.00000,0.16663,120.57978,0.00362,0.36244,5.67418
2.20000,0.18331,129.46129,0.00390,0.39029,6.09212
2.40000,0.19994,138.65795,0.00418,0.41788,6.52490
2.60000,0.21668,146.64570,0.00446,0.44592,6.90078
2.80000,0.23330,155.08762,0.00473,0.47324,7.29803
3.00000,0.25004,163.54976,0.00500,0.50043,7.69624
3.20000,0.26672,171.05666,0.00525,0.52477,8.04950
3.40000,0.28334,179.50634,0.00553,0.55300,8.44712
3.60000,0.29996,187.33239,0.00580,0.58049,8.81539
3.80000,0.31659,196.80792,0.00608,0.60787,9.26129
4.00000,0.33339,204.95432,0.00636,0.63586,9.64464
4.20000,0.35001,212.80244,0.00664,0.66415,10.01395
4.40000,0.36669,221.73275,0.00692,0.69185,10.43419
4.60000,0.38337,230.25558,0.00720,0.71967,10.83525
4.80000,0.39993,238.46591,0.00747,0.74742,11.22161
5.00000,0.41667,246.37743,0.00776,0.77572,11.59390
5.20000,0.43341,254.95645,0.00804,0.80375,11.99761
5.40000,0.44998,262.83276,0.00831,0.83139,12.36825
5.60000,0.46660,270.59922,0.00861,0.86077,12.73372
5.80000,0.48328,278.37111,0.00889,0.88861,13.09945
6.00000,0.50002,286.99923,0.00917,0.91691,13.50546
6.20000,0.51658,294.01744,0.00945,0.94491,13.83572
6.40000,0.53332,302.57055,0.00973,0.97320,14.23821
6.60000,0.55012,310.50490,0.01002,1.00197,14.61158
6.80000,0.56668,318.28692,0.01029,1.02948,14.97779
7.00000,0.58325,325.75270,0.01058,1.05801,15.32911
7.20000,0.59999,333.13693,0.01086,1.08624,15.67659
7.40000,0.61667,339.27921,0.01110,1.10991,15.96563
7.60000,0.63329,346.71945,0.01139,1.13863,16.31575
7.80000,0.64991,353.92707,0.01167,1.16740,16.65492
8.00000,0.66665,361.49472,0.01196,1.19594,17.01104
8.20000,0.68333,368.74893,0.01224,1.22423,17.35240
8.40000,0.70002,375.32670,0.01253,1.25252,17.66193
8.60000,0.71676,382.30591,0.01282,1.28174,17.99036
8.80000,0.73332,389.27887,0.01310,1.30997,18.31849
9.00000,0.75000,396.74551,0.01339,1.33876,18.66985
9.20000,0.76668,404.18631,0.01367,1.36709,19.01999
9.40000,0.78330,411.10381,0.01396,1.39572,19.34551
9.60000,0.80004,416.77533,0.01421,1.42134,19.61240
9.80000,0.81666,422.90185,0.01451,1.45051,19.90070
10.00000,0.83329,430.23373,0.01480,1.47980,20.24572
10.20000,0.84991,438.28092,0.01509,1.50851,20.62440
10.40000,0.86659,444.90783,0.01537,1.53738,20.93625
10.60000,0.88345,451.24455,0.01567,1.56675,21.23444
10.80000,0.90001,457.84167,0.01596,1.59615,21.54488
11.00000,0.91657,463.68977,0.01625,1.62526,21.82008
11.20000,0.93337,470.74263,0.01655,1.65452,22.15197
11.40000,0.94994,475.88591,0.01681,1.68134,22.39400
11.60000,0.96662,481.86136,0.01710,1.70968,22.67519
11.80000,0.98330,487.75598,0.01739,1.73896,22.95257
12.00000,0.99998,494.55184,0.01769,1.76863,23.27237
12.20000,1.01660,499.70839,0.01798,1.79847,23.51502
12.40000,1.03328,505.84674,0.01829,1.82932,23.80388
12.60000,1.05008,511.29595,0.01859,1.85891,24.06031
12.80000,1.06664,517.30555,0.01889,1.88877,24.34310
13.00000,1.08333,523.10871,0.01919,1.91936,24.61619
13.20000,1.10001,528.49883,0.01950,1.95002,24.86983
13.40000,1.11663,533.89492,0.01980,1.98026,25.12376
13.60000,1.13331,538.88867,0.02011,2.01127,25.35875
13.80000,1.15005,544.46915,0.02042,2.04168,25.62136
14.00000,1.16679,549.24404,0.02073,2.07288,25.84605
14.20000,1.18329,554.43849,0.02104,2.10427,26.09049
14.40000,1.19998,559.71593,0.02136,2.13628,26.33883
14.60000,1.21672,564.77007,0.02167,2.16678,26.57666
14.80000,1.23328,569.89519,0.02198,2.19848,26.81784
15.00000,1.24996,574.16693,0.02230,2.23028,27.01886
15.20000,1.26664,578.66960,0.02262,2.26180,27.23074
15.40000,1.28326,584.00068,0.02294,2.29377,27.48161
15.60000,1.29994,588.30953,0.02326,2.32568,27.68437
15.80000,1.31668,592.79334,0.02358,2.35766,27.89537
16.00000,1.33337,596.54117,0.02390,2.38956,28.07173
16.20000,1.35005,600.79047,0.02422,2.42210,28.27169
16.40000,1.36673,603.77209,0.02449,2.44939,28.41200
16.60000,1.38341,608.46433,0.02482,2.48204,28.63281
16.80000,1.39997,611.93174,0.02515,2.51484,28.79597
17.00000,1.41665,616.36055,0.02548,2.54798,29.00438
17.20000,1.43339,620.64948,0.02581,2.58062,29.20621
17.40000,1.44995,623.47939,0.02614,2.61384,29.33938
17.60000,1.46664,627.73810,0.02647,2.64707,29.53978
17.80000,1.48338,631.48369,0.02680,2.68020,29.71604
18.00000,1.50000,634.71054,0.02713,2.71331,29.86789
18.20000,1.51668,638.93707,0.02748,2.74751,30.06678
18.40000,1.53330,642.73286,0.02781,2.78092,30.24540
18.60000,1.54998,645.78420,0.02814,2.81444,30.38899
18.80000,1.56666,648.93025,0.02849,2.84933,30.53703
19.00000,1.58329,652.64646,0.02883,2.88303,30.71191
19.20000,1.60003,655.78260,0.02918,2.91778,30.85949
19.40000,1.61671,658.61922,0.02952,2.95173,30.99297
19.60000,1.63333,662.27093,0.02986,2.98650,31.16481
19.80000,1.65001,664.89670,0.03021,3.02123,31.28837
20.00000,1.66663,667.87908,0.03056,3.07206,31.42872
20.19600,1.68295,671.42365,0.03090,3.13735,31.59551
20.39600,1.69970,674.12341,0.03125,3.20432,31.72256
20.59600,1.71638,677.19137,0.03160,3.27104,31.86693
20.79600,1.73294,680.46725,0.03195,3.33729,32.02108
20.99600,1.74968,682.98476,0.03230,3.40425,32.13955
21.19600,1.76636,686.06436,0.03266,3.47098,32.28447
21.39600,1.78304,688.54131,0.03302,3.53770,32.40103
21.59600,1.79966,691.20997,0.03337,3.60419,32.52661
21.79600,1.81635,693.94396,0.03373,3.67091,32.65527
21.99600,1.83303,696.64940,0.03408,3.73764,32.78258
22.19600,1.84971,698.84136,0.03444,3.80436,32.88572
22.39600,1.86639,701.78309,0.03480,3.87109,33.02415
22.59600,1.88301,703.84862,0.03516,3.93757,33.12135
22.79600,1.89963,706.37441,0.03552,4.00406,33.24021
22.99600,1.91625,708.54193,0.03588,4.07055,33.34221
23.19600,1.93293,711.31499,0.03624,4.13727,33.47270
23.39600,1.94968,713.63025,0.03660,4.20424,33.58165
23.59600,1.96636,715.22626,0.03697,4.27096,33.65676
23.79600,1.98304,717.15317,0.03730,4.33769,33.74743
23.99600,1.99972,718.54102,0.03763,4.40441,33.81274
24.19600,2.01634,720.83417,0.03799,4.47090,33.92065
24.39600,2.03302,722.65016,0.03835,4.53762,34.00611
24.59600,2.04970,725.58997,0.03872,4.60435,34.14445
24.79600,2.06638,727.03734,0.03909,4.67107,34.21255
24.99600,2.08301,728.97724,0.03945,4.73756,34.30384
25.19600,2.09969,731.76576,0.03982,4.80428,34.43506
25.39600,2.11631,733.60489,0.04019,4.87077,34.52161
25.59600,2.13293,735.21133,0.04055,4.93725,34.59720
25.79600,2.14961,737.84669,0.04093,5.00398,34.72122
25.99600,2.16629,739.67073,0.04129,5.07070,34.80705
26.19600,2.18297,741.28783,0.04166,5.13743,34.88315
26.39600,2.19972,742.97679,0.04204,5.20439,34.96263
26.59600,2.21634,744.81792,0.04241,5.27088,35.04927
26.79600,2.23308,747.19824,0.04278,5.33784,35.16128
26.99600,2.24970,748.79392,0.04316,5.40433,35.23637
27.19600,2.26632,751.02206,0.04353,5.47082,35.34122
27.39600,2.28300,752.64480,0.04391,5.53754,35.41758
27.59600,2.29962,754.15093,0.04428,5.60403,35.48845
27.79600,2.31642,756.17274,0.04466,5.67123,35.58360
27.99600,2.33305,757.43799,0.04504,5.73772,35.64314
28.19600,2.34955,759.78744,0.04541,5.80372,35.75369
28.39600,2.36629,761.61083,0.04579,5.87069,35.83950
28.59600,2.38297,762.48967,0.04617,5.93741,35.88086
28.79600,2.39965,764.23837,0.04655,6.00414,35.96314
28.99600,2.41633,765.89114,0.04692,6.07086,36.04092
29.19600,2.43301,767.81353,0.04731,6.13759,36.13138
29.39600,2.44964,769.40237,0.04768,6.20407,36.20615
29.59600,2.46632,770.13006,0.04806,6.27080,36.24039
29.79600,2.48306,771.90255,0.04845,6.33776,36.32380
29.99600,2.49968,774.04398,0.04883,6.40425,36.42457
30.19600,2.51636,775.66365,0.04921,6.47097,36.50079
30.39600,2.53298,776.81630,0.04959,6.53746,36.55503
30.59600,2.54966,778.04546,0.04997,6.60419,36.61287
30.79600,2.56634,779.65758,0.05035,6.67091,36.68873
30.99600,2.58303,780.98839,0.05073,6.73764,36.75136
31.19600,2.59959,782.90282,0.05111,6.80388,36.84145
31.39600,2.61627,784.03978,0.05150,6.87061,36.89495
31.59600,2.63295,785.67779,0.05188,6.93733,36.97203
31.79600,2.64963,786.69591,0.05227,7.00406,37.01994
31.99600,2.66643,788.33709,0.05266,7.07126,37.09717
32.19600,2.68299,789.30538,0.05304,7.13751,37.14273
32.39600,2.69968,790.38879,0.05343,7.20423,37.19372
32.59600,2.71630,792.10885,0.05381,7.27072,37.27466
32.79600,2.73292,792.77018,0.05420,7.33720,37.30578
32.99600,2.74966,794.44805,0.05459,7.40417,37.38474
33.19600,2.76640,795.51684,0.05498,7.47113,37.43503
33.39600,2.78302,796.71675,0.05536,7.53762,37.49149
33.59600,2.79970,798.22335,0.05575,7.60434,37.56239
33.79600,2.81626,799.45168,0.05614,7.67059,37.62019
33.99600,2.83295,801.04647,0.05653,7.73732,37.69524
34.19600,2.84969,802.13780,0.05692,7.80428,37.74659
34.39600,2.86643,803.27410,0.05731,7.87124,37.80007
34.59600,2.88293,803.90163,0.05771,7.93725,37.82960
34.79600,2.89961,805.90155,0.05810,8.00398,37.92371
34.99600,2.91641,806.77168,0.05849,8.07118,37.96465
35.19600,2.93303,808.01575,0.05888,8.13767,38.02320
35.39600,2.94971,808.98721,0.05927,8.20439,38.06891
35.59600,2.96634,809.86703,0.05967,8.27088,38.11031
35.79600,2.98296,811.06508,0.06006,8.33736,38.16669
35.99600,2.99958,812.69592,0.06045,8.40385,38.24343
36.19600,3.01632,813.19809,0.06085,8.47081,38.26706
36.39600,3.03300,814.51135,0.06124,8.53754,38.32887
36.59600,3.04962,814.93994,0.06163,8.60402,38.34903
36.79600,3.06624,816.68599,0.06203,8.67051,38.43120
36.99600,3.08299,817.52772,0.06242,8.73747,38.47081
37.19600,3.09961,818.47748,0.06282,8.80396,38.51550
37.39600,3.11635,819.96163,0.06322,8.87093,38.58534
37.59600,3.13303,820.47246,0.06361,8.93765,38.60938
37.79600,3.14971,820.06231,0.06394,9.00438,38.59008
37.99600,3.16627,821.39112,0.06433,9.07062,38.65261
38.19600,3.18301,823.25637,0.06472,9.13759,38.74038
38.39600,3.19963,823.44878,0.06511,9.20407,38.74944
38.59600,3.21632,824.35738,0.06551,9.27080,38.79219
38.79600,3.23294,825.82701,0.06591,9.33728,38.86135
38.99600,3.24962,827.00690,0.06631,9.40401,38.91687
39.19600,3.26624,827.32886,0.06670,9.47049,38.93202
39.39600,3.28298,828.76682,0.06710,9.53746,38.99969
39.59600,3.29972,830.29037,0.06750,9.60442,39.07138
39.79600,3.31634,830.19836,0.06790,9.67091,39.06705
39.99600,3.33297,832.36694,0.06830,9.73739,39.16910
40.19600,3.34971,832.86176,0.06870,9.80436,39.19239
40.39600,3.36633,834.21431,0.06910,9.87084,39.25603
40.59600,3.38301,835.37828,0.06951,9.93757,39.31081
40.79600,3.39975,835.61037,0.06991,10.00453,39.32173
40.99600,3.41637,836.91925,0.07031,10.07102,39.38332
41.19600,3.43293,837.70743,0.07072,10.13727,39.42041
41.39600,3.44967,838.74920,0.07112,10.20423,39.46944
41.59600,3.46642,840.01701,0.07153,10.27119,39.52909
41.79600,3.48298,840.78638,0.07193,10.33744,39.56530
41.99600,3.49960,841.08813,0.07234,10.40393,39.57950
42.19600,3.51640,841.87901,0.07275,10.47113,39.61672
42.39600,3.53302,842.90626,0.07315,10.53762,39.66506
42.59600,3.54964,844.15711,0.07356,10.60410,39.72392
42.79600,3.56644,844.97491,0.07397,10.67131,39.76240
42.99600,3.58306,845.26353,0.07437,10.73779,39.77599
43.19600,3.59963,846.22577,0.07478,10.80404,39.82127
43.39600,3.61631,846.68482,0.07587,10.87076,39.84286
43.59600,3.63299,848.29470,0.07102,10.93749,39.91862
43.79600,3.64961,846.97818,0.00764,11.00397,39.85667
43.99600,3.66629,846.34479,0.00933,11.07070,39.82687
44.19600,3.68297,849.36125,0.00918,11.13743,39.96881
44.39600,3.69959,849.71562,0.00942,11.20391,39.98549
44.59600,3.71634,850.27888,0.00769,11.27088,40.01199
44.79600,3.73302,851.67615,0.00803,11.33760,40.07775
44.99600,3.74970,851.56867,0.00792,11.40433,40.07269
45.19600,3.76632,852.79597,0.00747,11.47081,40.13044
45.39600,3.78294,853.53935,0.00730,11.53730,40.16542
45.59600,3.79968,853.73521,0.01104,11.60426,40.17464
45.79600,3.81636,854.49582,-0.00383,11.67099,40.21043
45.99600,3.83292,855.09801,-0.07427,11.73723,40.23877
46.19600,3.84967,855.98417,0.01200,11.80420,40.28047
46.39600,3.86629,856.42328,-0.02817,11.87068,40.30114
46.59600,3.88297,856.89612,-0.07419,11.93741,40.32338
46.79600,3.89965,857.75964,-0.08169,12.00413,40.36402
46.99600,3.91633,858.45497,-0.02957,12.07086,40.39674
47.19600,3.93301,858.52761,-0.08125,12.13758,40.40016
47.39600,3.94963,859.75099,-0.06258,12.20407,40.45773
47.59600,3.96637,859.84599,-0.09264,12.27103,40.46220
47.79600,3.98294,861.06546,-0.08646,12.33728,40.51958
47.99600,3.99968,860.28837,-0.08853,12.40424,40.48302
48.19600,4.01648,861.20069,-0.08857,12.47145,40.52595
48.39600,4.03298,862.01448,-0.09206,12.53745,40.56424
48.59600,4.04960,862.73924,-0.08750,12.60394,40.59835
48.79600,4.06640,863.32867,-0.07127,12.67114,40.62608
48.99600,4.08296,863.73156,-0.07767,12.73739,40.64504
49.19600,4.09965,864.67331,-0.07124,12.80412,40.68936
49.39600,4.11633,864.81571,-0.08775,12.87084,40.69606
49.59600,4.13301,865.44249,-0.06268,12.93757,40.72556
49.79600,4.14969,865.81195,-0.04520,13.00429,40.74294
49.99600,4.16631,866.92320,-0.05613,13.07078,40.79523
50.19600,4.18305,867.05051,-0.05322,13.13774,40.80122
50.39600,4.19967,867.33615,-0.05609,13.20423,40.81467
50.59600,4.21630,867.67310,-0.05359,13.27071,40.83052
50.79600,4.23298,868.18188,-0.05712,13.33744,40.85447
50.99600,4.24966,869.39381,-0.05533,13.40416,40.91150
51.19600,4.26628,869.88080,-0.05243,13.47065,40.93441
51.39600,4.28302,869.95680,-0.05429,13.53762,40.93799
51.59600,4.29970,870.24150,-0.05512,13.60434,40.95139
51.79600,4.31632,870.47461,-0.05415,13.67083,40.96236
51.99600,4.33294,871.41395,-0.05590,13.73731,41.00656
52.19600,4.34963,872.03942,-0.05557,13.80404,41.03599
52.39600,4.36631,872.24338,-0.05552,13.87076,41.04559
52.59600,4.38305,872.59850,-0.05549,13.93773,41.06230
52.79600,4.39967,873.18541,-0.05550,14.00421,41.08992
52.99600,4.41635,873.55245,-0.05553,14.07094,41.10719
53.19600,4.43303,873.94742,-0.05551,14.13766,41.12578
53.39600,4.44965,874.40116,-0.05551,14.20415,41.14713
53.59600,4.46639,874.63930,-0.05550,14.27111,41.15833
53.79600,4.48302,874.63008,-0.05552,14.33760,41.15790
53.99600,4.49964,874.93164,-0.02653,14.40408,41.17209
54.19600,4.51638,875.68304,-0.00407,14.47105,41.20745
54.39600,4.53300,876.53585,-0.05517,14.53753,41.24758
54.59600,4.54968,876.75592,-0.05604,14.60426,41.25794
54.79600,4.56636,876.95690,-0.05533,14.67098,41.26740
54.99600,4.58292,877.42358,-0.05270,14.73723,41.28936
55.19600,4.59961,877.88543,-0.01715,14.80396,41.31109
55.39600,4.61635,878.42634,-0.01373,14.87092,41.33654
55.59600,4.63303,879.03617,0.01251,14.93765,41.36524
55.79600,4.64965,879.03356,-0.01398,15.00413,41.36512
55.99600,4.66639,879.20669,-0.01731,15.07109,41.37326
56.19600,4.68307,879.88675,-0.01075,15.13782,41.40527
56.39600,4.69963,880.08093,0.02567,15.20407,41.41440
56.59600,4.71631,880.28302,0.01507,15.27079,41.42391
56.79600,4.73306,880.26142,0.02673,15.33776,41.42290
56.99600,4.74968,880.89537,0.12149,15.40424,41.45273
57.19600,4.76624,882.23973,0.14593,15.47049,41.51599
57.39600,4.78298,881.67181,0.17543,15.53745,41.48927
57.59600,4.79960,882.11596,0.17731,15.60394,41.51017
57.79600,4.81640,882.00886,0.22576,15.67114,41.50513
57.99600,4.83302,882.95527,0.14255,15.73763,41.54966
58.19600,4.84970,882.91988,-0.01142,15.80435,41.54800
58.39600,4.86633,883.59956,-0.04906,15.87084,41.57998
58.59600,4.88295,883.02745,0.00526,15.93733,41.55306
58.79600,4.89969,883.83956,0.00576,16.00429,41.59127
58.99600,4.91637,884.06643,0.00645,16.07101,41.60195
59.19600,4.93293,884.20687,0.00679,16.13726,41.60856
59.39600,4.94967,884.20752,0.00675,16.20422,41.60859
59.59600,4.96629,884.72413,0.00719,16.27071,41.63290
59.79600,4.98292,884.85563,0.00650,16.33720,41.63909
59.99600,4.99966,885.28330,-0.03226,16.40416,41.65921
60.19600,5.01634,885.74411,-0.06480,16.47089,41.68090
60.39600,5.03296,885.83268,-0.05250,16.53737,41.68507
60.59600,5.04964,885.77066,-0.05453,16.60410,41.68215
60.79600,5.06632,886.12726,-0.05542,16.67082,41.69893
60.99600,5.08306,886.05992,-0.05532,16.73779,41.69576
61.19600,5.09968,886.68801,-0.05470,16.80427,41.72532
61.39600,5.11631,886.73728,-0.05430,16.87076,41.72763
61.59600,5.13299,887.36704,-0.05436,16.93748,41.75727
61.79600,5.14961,887.68695,-0.05465,17.00397,41.77232
61.99600,5.16641,887.61570,-0.05481,17.07117,41.76897
62.19600,5.18297,887.91829,-0.05479,17.13742,41.78321
62.39600,5.19965,886.89448,-0.05470,17.20415,41.73503
62.59600,5.21627,887.91121,-0.05466,17.27063,41.78288
62.79600,5.23296,888.67657,-0.05466,17.33736,41.81889
62.99600,5.24964,888.16080,-0.05471,17.40408,41.79462
63.19600,5.26638,888.60039,-0.05479,17.47105,41.81531
63.39600,5.28306,888.57180,-0.05483,17.53777,41.81396
63.59600,5.29968,888.13715,-0.05483,17.60426,41.79351
63.79600,5.31636,889.25436,-0.05486,17.67098,41.84608
63.99600,5.33304,889.28044,-0.05486,17.73770,41.84731
64.19601,5.34972,889.54419,-0.05488,17.80443,41.85972
64.39600,5.36635,889.23974,-0.05487,17.87092,41.84539
64.59600,5.38303,889.33995,-0.05486,17.93764,41.85011
64.79600,5.39959,890.20152,-0.05487,18.00389,41.89065
64.99600,5.41633,890.00138,-0.05488,18.07085,41.88124
65.19601,5.43301,890.17106,-0.05489,18.13758,41.88922
65.39600,5.44969,889.75523,-0.05489,18.20430,41.86965
65.59600,5.46631,890.30853,-0.05490,18.27079,41.89569
65.79601,5.48300,890.94024,-0.05491,18.33751,41.92542
65.99600,5.49968,891.20409,-0.05490,18.40424,41.93783
66.19601,5.51630,890.85819,-0.05491,18.47073,41.92155
66.39600,5.53310,890.97889,-0.05491,18.53793,41.92723
66.59600,5.54972,890.94071,-0.05492,18.60441,41.92544
66.79601,5.56628,891.63063,-0.05493,18.67066,41.95790
66.99600,5.58296,891.17577,-0.05494,18.73739,41.93650
67.19601,5.59958,891.38011,-0.05494,18.80387,41.94611
67.39600,5.61639,891.57009,-0.05493,18.87107,41.95506
67.59600,5.63307,892.07999,-0.05494,18.93780,41.97905
67.79601,5.64969,891.65773,-0.05499,19.00429,41.95918
67.99600,5.66637,891.82165,-0.05499,19.07101,41.96689
68.19601,5.68293,892.33033,-0.05498,19.13726,41.99083
68.39600,5.69961,891.84558,-0.05499,19.20398,41.96802
68.59600,5.71635,892.19362,-0.05497,19.27095,41.98440
68.79601,5.73292,892.39227,-0.05496,19.33719,41.99374
68.99600,5.74960,893.01663,-0.05498,19.40392,42.02312
69.19601,5.76640,892.50030,-0.05500,19.47112,41.99883
69.39600,5.78308,892.93215,-0.05501,19.53785,42.01915
69.59600,5.79970,892.77951,-0.05500,19.60433,42.01197
69.79601,5.81632,892.53113,-0.05500,19.67082,42.00028
69.99600,5.83306,892.69308,-0.05501,19.73778,42.00790
70.19601,5.84956,892.87357,-0.05504,19.80379,42.01639
70.39600,5.86631,893.46804,-0.05502,19.87076,42.04437
70.59600,5.88311,893.61286,-0.05503,19.93796,42.05118
70.79601,5.89967,893.12568,-0.05501,20.00420,42.02826
70.99600,5.91635,893.82101,-0.05501,20.07093,42.06098
71.19601,5.93303,893.60587,-0.05501,20.13766,42.05085
71.39600,5.94971,893.24117,-0.05502,20.20438,42.03369
71.59600,5.96633,893.48126,-0.05502,20.27087,42.04499
71.79601,5.98301,893.79614,-0.05501,20.33759,42.05981
71.99600,5.99970,894.32513,-0.05503,20.40432,42.08470
72.19601,6.01632,893.93416,-0.05503,20.47080,42.06630
72.39600,6.03294,894.34944,-0.05504,20.53729,42.08585
72.59600,6.04974,893.85947,-0.05507,20.60449,42.06279
72.79601,6.06630,893.70906,-0.05508,20.67074,42.05571
72.99600,6.08298,894.37943,-0.05508,20.73746,42.08725
73.19601,6.09966,894.28127,-0.05505,20.80419,42.08264
73.39600,6.11629,894.50320,-0.05504,20.87068,42.09308
73.59600,6.13297,894.49119,-0.05505,20.93740,42.09251
73.79601,6.14965,894.52993,-0.05505,21.00413,42.09434
73.99600,6.16645,894.24588,-0.05504,21.07133,42.08097
74.19601,6.18289,894.81706,-0.05505,21.13710,42.10785
74.39600,6.19957,894.32616,-0.05506,21.20382,42.08475
74.59600,6.21637,893.75796,-0.05506,21.27103,42.05801
74.79601,6.23300,894.13244,-0.05505,21.33751,42.07563
74.99600,6.24974,894.62725,-0.05505,21.40447,42.09892
75.19601,6.26642,894.63778,-0.05506,21.47120,42.09941
75.39600,6.28298,894.70642,-0.05506,21.53745,42.10264
75.59600,6.29960,895.45138,-0.05509,21.60393,42.13770
75.79601,6.31628,894.91596,-0.05510,21.67066,42.11250
75.99600,6.33302,894.69701,-0.05509,21.73762,42.10220
76.19601,6.34964,894.10273,-0.05508,21.80411,42.07423
76.39600,6.36633,894.43196,-0.05508,21.87084,42.08973
76.59600,6.38313,894.39107,-0.05508,21.93804,42.08780
76.79601,6.39963,894.37440,-0.05508,22.00404,42.08702
76.99600,6.41637,894.81650,-0.05508,22.07101,42.10782
77.19601,6.43311,895.03145,-0.05509,22.13797,42.11794
77.39600,6.44967,894.90367,-0.05509,22.20422,42.11192
77.59600,6.46623,894.23712,-0.05510,22.27047,42.08056
77.79601,6.48303,894.46465,-0.05511,22.33767,42.09127
77.99600,6.49972,895.01143,-0.05512,22.40440,42.11700
78.19601,6.51628,895.34800,-0.05510,22.47064,42.13284
78.39600,6.53302,894.89287,-0.05511,22.53761,42.11142
78.59600,6.54964,895.17888,-0.05511,22.60409,42.12487
78.79601,6.56626,894.73715,-0.05510,22.67058,42.10409
78.99600,6.58300,894.66609,-0.05510,22.73754,42.10075
79.19601,6.59974,895.02092,-0.05510,22.80451,42.11744
79.39600,6.61636,894.12648,-0.05509,22.87099,42.07535
79.59600,6.63299,894.91997,-0.05510,22.93748,42.11269
79.79601,6.64967,894.24690,-0.05511,23.00420,42.08102
79.99600,6.66629,894.91084,-0.05510,23.07069,42.11226
80.19601,6.68297,894.42143,-0.05510,23.13742,42.08923
80.39600,6.69965,894.88719,-0.05511,23.20414,42.11115
80.59600,6.71633,894.72057,-0.05511,23.27086,42.10331
80.79601,6.73295,894.31470,-0.05512,23.33735,42.08421
80.99600,6.74958,894.83922,-0.05511,23.40384,42.10889
81.19601,6.76632,894.17687,-0.05511,23.47080,42.07772
81.39600,6.78300,894.48430,-0.05510,23.53753,42.09219
81.59600,6.79968,894.25724,-0.05511,23.60425,42.08150
81.79601,6.81630,894.71480,-0.05513,23.67074,42.10304
81.99600,6.83298,894.86241,-0.05511,23.73746,42.10998
82.19601,6.84966,894.32728,-0.05510,23.80419,42.08480
82.39600,6.86640,894.43382,-0.05512,23.87115,42.08981
82.59600,6.88303,894.29338,-0.05512,23.93764,42.08321
82.79601,6.89965,894.50656,-0.05512,24.00412,42.09324
82.99600,6.91627,894.04592,-0.05512,24.07061,42.07156
83.19601,6.93301,893.91377,-0.05514,24.13757,42.06534
83.39600,6.94963,894.47768,-0.05513,24.20406,42.09188
83.59600,6.96631,893.71977,-0.05513,24.27078,42.05621
83.79601,6.98305,894.08727,-0.05512,24.33775,42.07351
83.99600,6.99962,894.47955,-0.05513,24.40400,42.09197
84.19601,7.01630,894.11028,-0.05512,24.47072,42.07459
84.39600,7.03310,893.64685,-0.05511,24.53792,42.05278
84.59600,7.04972,892.85439,-0.05510,24.60441,42.01549
84.79601,7.06634,893.67693,-0.05511,24.67090,42.05420
84.99600,7.08302,893.29826,-0.05512,24.73762,42.03638
85.19601,7.09970,893.02557,-0.05513,24.80434,42.02354
85.39600,7.11632,893.21891,-0.05514,24.87083,42.03264
85.59600,7.13295,893.15698,-0.05513,24.93732,42.02973
85.79601,7.14975,893.18873,-0.05514,25.00452,42.03122
85.99600,7.16631,893.42948,-0.05514,25.07077,42.04255
86.19601,7.18293,893.97384,-0.05515,25.13725,42.06817
86.39600,7.19967,893.59153,-0.05517,25.20422,42.05018
86.59600,7.21629,893.17448,-0.05515,25.27070,42.03055
86.79601,7.23297,892.89853,-0.05518,25.33743,42.01757
86.99600,7.24966,892.85634,-0.05518,25.40416,42.01558
87.19601,7.26634,892.81248,-0.05517,25.47088,42.01352
87.39600,7.28296,892.68181,-0.05514,25.53737,42.00737
87.59600,7.29964,892.08782,-0.05515,25.60409,41.97942
87.79601,7.31638,892.29085,-0.05517,25.67106,41.98897
87.99600,7.33300,892.81425,-0.05517,25.73754,42.01360
88.19601,7.34968,892.89760,-0.05519,25.80427,42.01752
88.39600,7.36636,892.38146,-0.05519,25.87099,41.99324
88.59600,7.38299,892.09964,-0.05519,25.93748,41.97997
88.79601,7.39973,892.11361,-0.05518,26.00444,41.98063
88.99600,7.41629,892.22109,-0.05519,26.07069,41.98569
89.19601,7.43297,891.72646,-0.05516,26.13741,41.96241
89.39600,7.44971,891.66705,-0.05515,26.20438,41.95962
89.59600,7.46627,891.86896,-0.05516,26.27062,41.96912
89.79601,7.48301,892.23720,-0.05516,26.33759,41.98645
89.99600,7.49970,891.80954,-0.05517,26.40431,41.96632
90.19601,7.51632,892.00530,-0.05519,26.47080,41.97554
90.39600,7.53306,891.77117,-0.05515,26.53776,41.96452
90.59600,7.54968,891.41903,-0.05517,26.60425,41.94795
90.79601,7.56630,891.71296,-0.05517,26.67074,41.96178
90.99600,7.58298,891.66965,-0.05516,26.73746,41.95974
91.19601,7.59972,891.88796,-0.05516,26.80442,41.97001
91.39600,7.61628,891.35896,-0.05517,26.87067,41.94512
91.59600,7.63291,890.71132,-0.05518,26.93716,41.91464
91.79601,7.64971,891.31519,-0.05516,27.00436,41.94306
91.99600,7.66633,890.85475,-0.05515,27.07085,41.92139
92.19601,7.68301,890.53251,-0.05516,27.13757,41.90623
92.39600,7.69975,890.71468,-0.05516,27.20454,41.91480
92.59600,7.71631,890.53465,-0.05517,27.27078,41.90633
92.79601,7.73305,890.45549,-0.05517,27.33774,41.90260
92.99600,7.74973,890.51006,-0.05518,27.40447,41.90517
93.19601,7.76636,890.45484,-0.05516,27.47096,41.90257
93.39600,7.78304,890.38759,-0.05516,27.53768,41.89941
93.59600,7.79960,890.53763,-0.05518,27.60393,41.90647
93.79601,7.81628,889.91830,-0.05517,27.67065,41.87733
93.99600,7.83296,890.64352,-0.05516,27.73738,41.91145
94.19601,7.84964,889.88943,-0.05515,27.80410,41.87597
94.39600,7.86632,889.74172,-0.05517,27.87083,41.86901
94.59601,7.88295,889.95928,-0.05518,27.93731,41.87925
94.79601,7.89963,889.78512,-0.05518,28.00404,41.87106
94.99600,7.91631,889.70847,-0.05517,28.07077,41.86745
95.19601,7.93299,889.17697,-0.05518,28.13749,41.84244
95.39600,7.94973,889.55266,-0.05517,28.20446,41.86012
95.59601,7.96635,889.22065,-0.05517,28.27094,41.84450
95.79601,7.98303,888.87131,-0.05518,28.33766,41.82806
95.99600,7.99965,888.68337,-0.05519,28.40415,41.81921
96.19601,8.01628,888.45119,-0.05518,28.47064,41.80829
96.39600,8.03302,888.63662,-0.05519,28.53760,41.81701
96.59601,8.04964,888.12588,-0.05519,28.60408,41.79298
96.79601,8.06626,888.46497,-0.05518,28.67057,41.80894
96.99600,8.08294,887.68853,-0.05520,28.73730,41.77240
97.19601,8.09962,887.74376,-0.05518,28.80402,41.77500
97.39600,8.11636,887.51335,-0.05518,28.87099,41.76416
97.59601,8.13304,887.53169,-0.05519,28.93771,41.76502
97.79601,8.14967,887.59251,-0.05521,29.00420,41.76788
97.99600,8.16629,887.67465,-0.05521,29.07068,41.77174
98.19601,8.18297,887.37924,-0.05520,29.13741,41.75784
98.39600,8.19971,886.72666,-0.05520,29.20437,41.72713
98.59601,8.21633,886.80638,-0.05519,29.27086,41.73089
98.79601,8.23295,886.94431,-0.05518,29.33735,41.73738
98.99600,8.24969,886.75506,-0.05520,29.40431,41.72847
99.19601,8.26632,886.70934,-0.05520,29.47080,41.72632
99.39600,8.28294,886.48219,-0.05521,29.53728,41.71563
99.59601,8.29974,886.52214,-0.05520,29.60449,41.71751
99.79601,8.31642,886.31911,-0.05519,29.67121,41.70796
99.99600,8.33298,886.11078,-0.05519,29.73746,41.69815
100.19601,8.34966,886.44493,-0.05519,29.80418,41.71388
100.39600,8.36634,886.08759,-0.05519,29.87091,41.69706
100.59601,8.38296,885.46528,-0.05520,29.93739,41.66778
100.79601,8.39965,885.45084,-0.05520,30.00412,41.66710
100.99600,8.41633,886.22728,-0.05519,30.07084,41.70364
101.19601,8.43295,885.33163,-0.05520,30.13733,41.66149
101.39600,8.44963,885.58169,-0.05520,30.20405,41.67326
101.59601,8.46637,885.25796,-0.05520,30.27102,41.65802
101.79601,8.48305,885.05559,-0.05522,30.33774,41.64850
101.99600,8.49961,884.44566,-0.05521,30.40399,41.61980
102.19601,8.51629,884.73493,-0.05519,30.47071,41.63341
102.39600,8.53298,884.93098,-0.05520,30.53744,41.64264
102.59601,8.54966,884.95398,-0.05520,30.60416,41.64372
102.79601,8.56634,883.83481,-0.05520,30.67089,41.59105
102.99600,8.58302,883.57441,-0.05520,30.73761,41.57880
103.19601,8.59964,883.92301,-0.05520,30.80410,41.59520
103.39600,8.61626,883.51145,-0.05520,30.87058,41.57584
103.59601,8.63306,883.35546,-0.05519,30.93779,41.56850
103.79601,8.64969,882.98935,-0.05520,31.00428,41.55127
103.99600,8.66631,882.87415,-0.05520,31.07076,41.54585
104.19601,8.68305,882.50060,-0.05521,31.13773,41.52827
104.39600,8.69961,883.20374,-0.05519,31.20397,41.56136
104.59601,8.71617,882.78204,-0.05520,31.27022,41.54151
104.79601,8.73303,882.33603,-0.05522,31.33766,41.52052
104.99600,8.74977,882.70223,-0.05521,31.40463,41.53775
105.19601,8.76628,881.49933,-0.05520,31.47063,41.48115
105.39600,8.78296,881.98865,-0.05519,31.53736,41.50418
105.59601,8.79976,881.94450,-0.05520,31.60456,41.50210
105.79601,8.81626,881.40760,-0.05519,31.67057,41.47683
105.99600,8.83300,881.46972,-0.05520,31.73753,41.47976
106.19601,8.84980,881.15456,-0.05520,31.80474,41.46493
106.39600,8.86630,881.56294,-0.05519,31.87074,41.48414
106.59601,8.88293,880.82505,-0.05521,31.93723,41.44942
106.79601,8.89972,880.99595,-0.05522,32.00443,41.45746
106.99600,8.91641,880.67651,-0.05520,32.07116,41.44243
107.19601,8.93297,880.61988,-0.05522,32.13741,41.43977
107.39600,8.94965,880.30333,-0.05521,32.20413,41.42487
107.59601,8.96633,880.09713,-0.05523,32.27086,41.41516
107.79601,8.98295,880.26710,-0.05522,32.33734,41.42316
107.99600,8.99963,880.01098,-0.05524,32.40407,41.41111
108.19601,9.01643,879.08395,-0.05522,32.47127,41.36749
108.39600,9.03288,879.34891,-0.05522,32.53704,41.37996
108.59601,9.04968,879.23622,-0.05522,32.60424,41.37465
108.79601,9.06636,879.10360,-0.05523,32.67097,41.36841
108.99600,9.08304,878.31914,-0.05522,32.73769,41.33150
109.19601,9.09966,878.73023,-0.05522,32.80418,41.35084
109.39600,9.11634,878.10978,-0.05525,32.87091,41.32165
109.59601,9.13302,878.96055,-0.05525,32.93763,41.36168
109.79601,9.14965,877.70820,-0.05526,33.00411,41.30275
109.99600,9.16627,878.35258,-0.05525,33.07060,41.33307
110.19601,9.18301,877.12221,-0.05525,33.13757,41.27517
110.39600,9.19963,877.01101,-0.05525,33.20405,41.26994
110.59601,9.21637,877.36519,-0.05524,33.27102,41.28661
110.79601,9.23305,876.77855,-0.05524,33.33774,41.25900
110.99600,9.24967,876.79056,-0.05523,33.40423,41.25957
111.19601,9.26641,876.87876,-0.05523,33.47119,41.26372
111.39600,9.28310,876.16090,-0.05525,33.53792,41.22994
111.59601,9.29966,876.09598,-0.05524,33.60416,41.22688
111.79601,9.31622,876.31829,-0.05524,33.67041,41.23734
111.99600,9.33296,875.89473,-0.05523,33.73738,41.21741
112.19601,9.34970,875.70148,-0.05522,33.80434,41.20832
112.39600,9.36632,874.90361,-0.05522,33.87082,41.17077
112.59601,9.38294,874.82771,-0.05522,33.93731,41.16720
112.79601,9.39975,874.81244,-0.05523,34.00451,41.16648
112.99600,9.41631,874.84047,-0.05522,34.07076,41.16780
113.19601,9.43299,874.71697,-0.05522,34.13749,41.16199
113.39600,9.44973,874.15930,-0.05523,34.20445,41.13575
113.59601,9.46641,873.94500,-0.05524,34.27118,41.12566
113.79601,9.48297,873.67697,-0.05524,34.33743,41.11305
113.99600,9.49965,873.11501,-0.05527,34.40415,41.08661
114.19601,9.51639,873.44572,-0.05528,34.47111,41.10217
114.39600,9.53296,873.27650,-0.05526,34.53736,41.09420
114.59601,9.54970,872.48674,-0.05527,34.60432,41.05704
114.79601,9.56644,872.29237,-0.05526,34.67129,41.04789
114.99600,9.58294,872.69964,-0.05525,34.73729,41.06706
115.19601,9.59962,871.76468,-0.05525,34.80402,41.02306
115.39600,9.61630,872.00534,-0.05524,34.87074,41.03439
115.59601,9.63298,871.65274,-0.05526,34.93747,41.01780
115.79601,9.64967,871.38200,-0.05525,35.00420,41.00505
115.99600,9.66629,870.95005,-0.05524,35.07068,40.98473
116.19601,9.68303,870.84910,-0.05526,35.13764,40.97998
116.39600,9.69965,870.68304,-0.05526,35.20413,40.97216
116.59601,9.71639,870.32160,-0.05523,35.27110,40.95515
116.79601,9.73307,869.80341,-0.05524,35.33782,40.93077
116.99600,9.74969,869.17942,-0.05525,35.40431,40.90141
117.19601,9.76625,869.30078,-0.05527,35.47055,40.90712
117.39600,9.78293,869.28373,-0.05527,35.53727,40.90631
117.59601,9.79962,868.75558,-0.05526,35.60400,40.88146
117.79601,9.81630,868.67381,-0.05523,35.67073,40.87761
117.99600,9.83298,868.38584,-0.05523,35.73745,40.86406
118.19601,9.84972,867.83366,-0.05523,35.80441,40.83808
118.39600,9.86628,868.02011,-0.05523,35.87066,40.84685
118.59601,9.88296,867.38402,-0.05524,35.93739,40.81692
118.79601,9.89970,867.00413,-0.05523,36.00435,40.79904
118.99600,9.91633,866.49368,-0.05524,36.07084,40.77502
119.19601,9.93301,866.54071,-0.05524,36.13757,40.77723
119.39600,9.94975,866.12264,-0.05525,36.20453,40.75756
119.59601,9.96631,866.21391,-0.05525,36.27077,40.76186
119.79601,9.98299,865.62792,-0.05525,36.33750,40.73428
119.99600,9.99973,865.58219,-0.05525,36.40446,40.73213
120.19601,10.01635,865.57595,-0.05524,36.47095,40.73183
120.39600,10.03298,864.86721,-0.05525,36.53743,40.69849
120.59601,10.04966,864.68300,-0.05528,36.60416,40.68982
120.79601,10.06634,864.11303,-0.05528,36.67088,40.66299
120.99600,10.08302,864.16854,-0.05527,36.73761,40.66561
121.19601,10.09964,863.32187,-0.05526,36.80409,40.62576
121.39600,10.11632,863.56131,-0.05525,36.87082,40.63703
121.59601,10.13294,862.89980,-0.05524,36.93731,40.60590
121.79601,10.14962,862.61481,-0.05524,37.00403,40.59249
121.99600,10.16636,862.33737,-0.05525,37.07099,40.57944
122.19601,10.18305,862.30030,-0.05526,37.13772,40.57769
122.39600,10.19967,861.47105,-0.05526,37.20421,40.53867
122.59601,10.21635,861.12544,-0.05528,37.27093,40.52241
122.79601,10.23297,861.27315,-0.05525,37.33742,40.52936
122.99600,10.24959,860.29237,-0.05526,37.40390,40.48320
123.19601,10.26633,860.06299,-0.05524,37.47087,40.47241
123.39600,10.28295,859.35593,-0.05525,37.53735,40.43914
123.59601,10.29964,859.88492,-0.05524,37.60408,40.46403
123.79601,10.31632,859.19555,-0.05526,37.67080,40.43159
123.99600,10.33300,859.30359,-0.05526,37.73753,40.43667
124.19601,10.34962,858.49380,-0.05525,37.80402,40.39857
124.39600,10.36642,858.22949,-0.05526,37.87122,40.38613
124.59601,10.38298,857.28513,-0.05526,37.93746,40.34169
124.79601,10.39961,857.33058,-0.05526,38.00395,40.34383
124.99600,10.41635,857.19414,-0.05526,38.07092,40.33741
125.19601,10.43297,856.78175,-0.05529,38.13740,40.31800
125.39600,10.44971,856.58235,-0.05528,38.20437,40.30862
125.59601,10.46633,855.70095,-0.05529,38.27085,40.26714
125.79601,10.48295,855.87408,-0.05528,38.33733,40.27529
125.99600,10.49963,855.26919,-0.05526,38.40407,40.24683
126.19601,10.51631,854.10131,-0.05527,38.47079,40.19187
126.39600,10.53299,853.83728,-0.05526,38.53751,40.17944
126.59601,10.54974,853.30717,-0.05528,38.60448,40.15450
126.79601,10.56630,853.19243,-0.05529,38.67072,40.14910
126.99601,10.58298,852.41990,-0.05526,38.73745,40.11274
127.19601,10.59960,852.23336,-0.05526,38.80394,40.10397
127.39600,10.61640,851.48914,-0.05527,38.87114,40.06895
127.59601,10.63302,851.17230,-0.05528,38.93763,40.05404
127.79601,10.64964,850.53928,-0.05529,39.00411,40.02425
127.99601,10.66639,850.27982,-0.05530,39.07107,40.01204
128.19600,10.68295,849.11799,-0.05528,39.13732,39.95737
128.39601,10.69969,848.78840,-0.05526,39.20428,39.94186
128.59601,10.71637,847.99230,-0.05527,39.27101,39.90439
128.79601,10.73299,846.60584,-0.05529,39.33750,39.83915
128.99600,10.74961,846.07387,-0.05528,39.40398,39.81412
129.19600,10.76629,844.44275,-0.05526,39.47071,39.73736
129.39601,10.78304,843.75925,-0.05525,39.53767,39.70520
129.59601,10.79972,842.85904,-0.05526,39.60440,39.66283
129.79601,10.81634,840.44561,-0.05528,39.67088,39.54926
129.99600,10.83302,838.78553,-0.05527,39.73761,39.47115
130.19600,10.84958,836.57922,-0.05527,39.80385,39.36732
130.39601,10.86632,833.37594,-0.05526,39.87082,39.21658
130.59601,10.88306,830.29261,-0.05527,39.93779,39.07149
130.79601,10.89968,826.03293,-0.05526,40.00427,38.87104
130.99600,10.91619,819.99879,-0.05527,40.07028,38.58709
131.19600,10.93299,809.85427,-0.05526,40.13748,38.10971
131.39602,10.94973,787.62947,-0.05527,40.20445,37.06387
131.46000,10.95511,1.72787,-0.05528,40.22597,0.08131