File: Manufatura Aditiva/Dados/Ensaios AMR/Ensaios/Ensaios SLS/Tracao_OLABI_21_12_2018_SLS_45.is_metal_RawData/Specimen_RawData_3.csv
Time,Extension,Load,Strain 1,Tensile strain,Tensile stress
(sec),(mm),(N),(mm/mm),(%),(MPa)
0.00000,0.00006,11.92697,0.00045,0.04517,0.59675
0.20000,0.01369,18.75270,0.00064,0.06399,0.93827
0.40000,0.03259,29.71720,0.00097,0.09746,1.48687
0.60000,0.04986,38.82339,0.00127,0.12745,1.94249
0.80000,0.06667,48.06996,0.00156,0.15580,2.40513
1.00000,0.08341,56.76552,0.00185,0.18507,2.84021
1.20000,0.10003,65.53103,0.00213,0.21319,3.27878
1.40000,0.11671,74.07339,0.00241,0.24134,3.70619
1.60000,0.13333,82.75138,0.00270,0.27006,4.14038
1.80000,0.14995,91.55233,0.00298,0.29846,4.58073
2.00000,0.16669,99.85591,0.00327,0.32660,4.99619
2.20000,0.18331,108.35262,0.00355,0.35491,5.42132
2.40000,0.19994,117.07856,0.00384,0.38357,5.85791
2.60000,0.21668,125.01419,0.00412,0.41227,6.25496
2.80000,0.23330,133.50882,0.00440,0.44045,6.67998
3.00000,0.25004,141.68181,0.00468,0.46843,7.08891
3.20000,0.26672,149.06110,0.00496,0.49628,7.45813
3.40000,0.28334,156.70343,0.00522,0.52152,7.84050
3.60000,0.29996,163.82878,0.00550,0.54969,8.19701
3.80000,0.31659,171.88641,0.00578,0.57770,8.60017
4.00000,0.33339,180.17462,0.00606,0.60647,9.01486
4.20000,0.35001,187.55787,0.00635,0.63507,9.38427
4.40000,0.36669,196.13944,0.00663,0.66321,9.81365
4.60000,0.38337,203.95634,0.00693,0.69281,10.20476
4.80000,0.39993,211.50403,0.00721,0.72096,10.58240
5.00000,0.41667,219.03242,0.00750,0.74979,10.95907
5.20000,0.43341,227.37628,0.00778,0.77778,11.37655
5.40000,0.45004,235.16812,0.00807,0.80670,11.76641
5.60000,0.46666,242.08494,0.00835,0.83546,12.11248
5.80000,0.48328,250.14041,0.00864,0.86353,12.51553
6.00000,0.50002,257.63523,0.00892,0.89155,12.89053
6.20000,0.51658,266.10566,0.00921,0.92065,13.31434
6.40000,0.53332,272.99789,0.00949,0.94919,13.65918
6.60000,0.55012,280.97059,0.00978,0.97826,14.05809
6.80000,0.56668,288.50529,0.01008,1.00767,14.43508
7.00000,0.58325,295.54276,0.01036,1.03642,14.78719
7.20000,0.59999,302.61201,0.01064,1.06420,15.14090
7.40000,0.61667,310.11403,0.01093,1.09316,15.51625
7.60000,0.63329,315.90369,0.01118,1.11808,15.80593
7.80000,0.64991,322.99503,0.01147,1.14664,16.16074
8.00000,0.66665,330.06633,0.01175,1.17526,16.51455
8.20000,0.68333,337.00785,0.01204,1.20358,16.86186
8.40000,0.70002,343.91049,0.01233,1.23270,17.20723
8.60000,0.71676,350.98689,0.01261,1.26120,17.56129
8.80000,0.73332,357.01548,0.01288,1.28842,17.86292
9.00000,0.75000,363.50742,0.01318,1.31796,18.18774
9.20000,0.76668,370.98699,0.01347,1.34695,18.56197
9.40000,0.78330,376.24957,0.01376,1.37606,18.82528
9.60000,0.80004,383.88430,0.01405,1.40482,19.20728
9.80000,0.81660,390.35950,0.01435,1.43455,19.53126
10.00000,0.83329,396.32898,0.01464,1.46403,19.82993
10.20000,0.84991,403.14430,0.01493,1.49285,20.17093
10.40000,0.86665,408.88246,0.01522,1.52209,20.45803
10.60000,0.88345,415.60601,0.01552,1.55158,20.79444
10.80000,0.90001,421.79758,0.01581,1.58088,21.10423
11.00000,0.91663,428.73700,0.01611,1.61058,21.45144
11.20000,0.93337,434.53709,0.01640,1.64027,21.74164
11.40000,0.95000,441.10934,0.01671,1.67063,22.07047
11.60000,0.96662,446.21178,0.01696,1.69584,22.32577
11.80000,0.98330,451.87655,0.01725,1.72527,22.60920
12.00000,0.99998,457.52982,0.01756,1.75584,22.89206
12.20000,1.01660,463.55911,0.01786,1.78587,23.19373
12.40000,1.03328,469.54192,0.01816,1.81606,23.49307
12.60000,1.05008,475.23542,0.01847,1.84689,23.77794
12.80000,1.06664,480.40356,0.01877,1.87703,24.03652
13.00000,1.08333,486.44473,0.01907,1.90739,24.33879
13.20000,1.10001,492.27118,0.01938,1.93816,24.63031
13.40000,1.11663,496.66287,0.01969,1.96905,24.85004
13.60000,1.13331,502.73361,0.02000,1.99965,25.15379
13.80000,1.14999,507.09383,0.02031,2.03098,25.37194
14.00000,1.16679,512.55627,0.02063,2.06256,25.64525
14.20000,1.18329,517.03667,0.02094,2.09406,25.86942
14.40000,1.20003,522.21692,0.02125,2.12532,26.12861
14.60000,1.21672,527.08238,0.02157,2.15697,26.37205
14.80000,1.23328,531.43837,0.02189,2.18917,26.59000
15.00000,1.24996,536.74500,0.02220,2.22027,26.85551
15.20000,1.26664,540.44239,0.02252,2.25227,27.04051
15.40000,1.28326,544.76489,0.02284,2.28407,27.25678
15.60000,1.29994,549.41862,0.02316,2.31638,27.48962
15.80000,1.31668,553.81497,0.02348,2.34834,27.70959
16.00000,1.33337,558.06548,0.02381,2.38063,27.92226
16.20000,1.35005,560.73638,0.02407,2.40749,28.05590
16.40000,1.36673,564.77115,0.02440,2.43983,28.25777
16.60000,1.38341,568.88144,0.02473,2.47294,28.46343
16.80000,1.39997,573.30285,0.02506,2.50629,28.68465
17.00000,1.41665,576.58316,0.02539,2.53872,28.84878
17.20000,1.43333,581.22491,0.02572,2.57237,29.08102
17.40000,1.44995,584.64669,0.02605,2.60538,29.25223
17.60000,1.46664,588.41147,0.02638,2.63839,29.44059
17.80000,1.48338,591.81419,0.02672,2.67185,29.61085
18.00000,1.50000,595.53422,0.02706,2.70589,29.79697
18.20000,1.51668,598.91911,0.02739,2.73914,29.96633
18.40000,1.53330,602.12184,0.02773,2.77295,30.12658
18.60000,1.54998,605.72890,0.02807,2.80690,30.30705
18.80000,1.56666,609.30187,0.02841,2.84134,30.48582
19.00000,1.58335,612.20145,0.02876,2.87564,30.63090
19.20000,1.60003,615.30364,0.02910,2.90995,30.78612
19.40000,1.61671,618.42850,0.02944,2.94397,30.94247
19.60000,1.63333,621.41549,0.02979,2.97913,31.09192
19.80000,1.65001,624.50501,0.03014,3.01397,31.24650
20.00000,1.66663,627.26405,0.03048,3.04840,31.38454
20.20000,1.68331,631.02846,0.03083,3.08342,31.57289
20.40000,1.70005,633.40063,0.03119,3.15039,31.69158
20.57800,1.71482,636.06240,0.03150,3.20946,31.82476
20.77800,1.73144,638.96058,0.03185,3.27594,31.96977
20.97800,1.74819,641.68288,0.03220,3.34291,32.10598
21.17800,1.76481,644.92412,0.03255,3.40939,32.26815
21.37800,1.78155,647.15953,0.03291,3.47636,32.37999
21.57800,1.79817,649.89747,0.03279,3.54284,32.51699
21.77800,1.81485,652.32581,0.03359,3.60957,32.63848
21.97800,1.83153,654.94101,0.01686,3.67629,32.76933
22.17800,1.84821,656.13533,0.00775,3.74302,32.82909
22.37800,1.86489,658.78490,0.00824,3.80974,32.96166
22.57800,1.88152,661.28331,0.00717,3.87623,33.08667
22.77800,1.89814,663.64203,0.00803,3.94272,33.20468
22.97800,1.91476,665.72735,0.00799,4.00920,33.30902
23.17800,1.93144,667.42161,0.00986,4.07593,33.39379
23.37800,1.94824,669.45921,0.00978,4.14313,33.49574
23.57800,1.96480,671.15892,0.00542,4.20938,33.58078
23.77800,1.98154,673.71433,-0.00580,4.27634,33.70864
23.97800,1.99816,675.97982,-0.03626,4.34283,33.82199
24.17800,2.01479,677.75561,-0.09190,4.40931,33.91084
24.37800,2.03159,680.17333,-0.12071,4.47652,34.03181
24.57800,2.04821,682.63416,0.03862,4.54300,34.15493
24.77800,2.06489,684.56298,-0.04756,4.60973,34.25144
24.97800,2.08145,686.26800,-0.04753,4.67597,34.33675
25.17800,2.09819,688.72715,-0.03614,4.74294,34.45979
25.37800,2.11481,691.22729,-0.05040,4.80942,34.58488
25.57800,2.13144,692.91014,-0.05621,4.87591,34.66908
25.77800,2.14812,694.97339,-0.06001,4.94263,34.77232
25.97800,2.16480,696.36772,-0.05929,5.00936,34.84208
26.17800,2.18148,698.59759,-0.05909,5.07608,34.95365
26.37800,2.19822,700.53139,-0.05852,5.14305,35.05040
26.57800,2.21484,702.34407,-0.05871,5.20953,35.14110
26.77800,2.23152,704.20476,-0.05898,5.27626,35.23420
26.97800,2.24820,705.95434,-0.05884,5.34299,35.32174
27.17800,2.26489,707.73074,-0.05881,5.40971,35.41062
27.37800,2.28157,709.54794,-0.05889,5.47643,35.50154
27.57800,2.29819,711.27643,-0.05896,5.54292,35.58802
27.77800,2.31487,712.75905,-0.05894,5.60965,35.66220
27.97800,2.33155,714.55534,-0.05893,5.67637,35.75208
28.17800,2.34811,716.07064,-0.05895,5.74262,35.82790
28.37800,2.36485,717.00490,-0.05895,5.80958,35.87464
28.57800,2.38148,718.84668,-0.05894,5.87607,35.96679
28.77800,2.39810,720.46095,-0.05892,5.94255,36.04756
28.97800,2.41484,721.98408,-0.05897,6.00952,36.12377
29.17800,2.43152,723.67783,-0.05894,6.07624,36.20851
29.37800,2.44814,725.39840,-0.05898,6.14273,36.29460
29.57800,2.46482,726.74365,-0.05899,6.20945,36.36191
29.77800,2.48150,728.42222,-0.05896,6.27618,36.44589
29.97800,2.49818,729.87620,-0.05897,6.34291,36.51864
30.17800,2.51487,730.80743,-0.05896,6.40963,36.56524
30.37800,2.53149,732.62863,-0.05900,6.47612,36.65636
30.57800,2.54817,734.38706,-0.05900,6.54284,36.74434
30.77800,2.56479,735.49910,-0.05900,6.60933,36.79998
30.97800,2.58153,736.61990,-0.05899,6.67629,36.85606
31.17800,2.59809,738.42076,-0.05900,6.74254,36.94616
31.37800,2.61477,739.81020,-0.05898,6.80926,37.01568
31.57800,2.63146,741.01724,-0.05900,6.87599,37.07607
31.77800,2.64820,742.80822,-0.05902,6.94295,37.16568
31.97800,2.66494,743.57372,-0.05902,7.00992,37.20398
32.17800,2.68150,745.02393,-0.05903,7.07616,37.27654
32.37800,2.69818,746.38836,-0.05904,7.14289,37.34481
32.57800,2.71480,748.23452,-0.05903,7.20937,37.43718
32.77800,2.73142,749.16114,-0.05902,7.27586,37.48355
32.97800,2.74816,749.85069,-0.05902,7.34282,37.51805
33.17800,2.76491,751.19110,-0.05903,7.40979,37.58511
33.37800,2.78153,752.85211,-0.05902,7.47627,37.66822
33.57800,2.79821,754.13319,-0.05903,7.54300,37.73232
33.77800,2.81477,755.05781,-0.05903,7.60925,37.77858
33.97800,2.83139,756.39733,-0.05902,7.67573,37.84560
34.17800,2.84819,757.42817,-0.05903,7.74294,37.89718
34.37800,2.86487,758.56633,-0.05903,7.80966,37.95412
34.57800,2.88143,759.81277,-0.05905,7.87591,38.01649
34.77800,2.89812,760.61278,-0.05906,7.94263,38.05652
34.97800,2.91486,762.95026,-0.05907,8.00960,38.17347
35.17800,2.93154,763.52279,-0.05905,8.07632,38.20212
35.37800,2.94822,762.26625,-0.05906,8.14305,38.13925
35.57800,2.96490,764.41602,-0.05905,8.20977,38.24681
35.77800,2.98146,764.88261,-0.05904,8.27602,38.27015
35.97800,2.99808,766.29799,-0.05906,8.34250,38.34097
36.17800,3.01489,767.61530,-0.05907,8.40971,38.40688
36.37800,3.03145,769.01778,-0.05905,8.47595,38.47705
36.57800,3.04819,770.13252,-0.05906,8.54292,38.53283
36.77800,3.06481,771.11800,-0.05907,8.60940,38.58213
36.97800,3.08149,772.16001,-0.05907,8.67613,38.63427
37.17800,3.09811,773.48449,-0.05906,8.74262,38.70054
37.37800,3.11479,774.09372,-0.05907,8.80934,38.73102
37.57800,3.13153,775.30402,-0.05907,8.87631,38.79158
37.77800,3.14822,776.85844,-0.05907,8.94303,38.86935
37.97800,3.16478,776.94943,-0.05906,9.00928,38.87391
38.17800,3.18152,778.25850,-0.05907,9.07624,38.93940
38.37800,3.19814,779.08663,-0.05907,9.14273,38.98084
38.57800,3.21482,780.18149,-0.05907,9.20945,39.03562
38.77800,3.23144,780.45228,-0.05906,9.27594,39.04917
38.97800,3.24812,782.12144,-0.05906,9.34266,39.13268
39.17800,3.26481,783.13947,-0.05908,9.40939,39.18362
39.37800,3.28149,783.52103,-0.05909,9.47611,39.20271
39.57800,3.29823,785.13706,-0.05908,9.54308,39.28357
39.77800,3.31485,785.23075,-0.05908,9.60956,39.28825
39.97800,3.33147,786.06522,-0.05909,9.67605,39.33001
40.17800,3.34815,787.40157,-0.05908,9.74277,39.39687
40.37800,3.36477,788.45425,-0.05908,9.80926,39.44954
40.57800,3.38151,789.78399,-0.05909,9.87623,39.51607
40.77800,3.39832,789.31181,-0.05910,9.94343,39.49245
40.97800,3.41488,790.83294,-0.05909,10.00968,39.56855
41.17800,3.43138,791.82861,-0.05907,10.07568,39.61837
41.37800,3.44818,792.05241,-0.05908,10.14289,39.62957
41.57800,3.46492,792.90243,-0.05909,10.20985,39.67210
41.77800,3.48148,793.61992,-0.05909,10.27610,39.70800
41.97800,3.49810,794.51418,-0.05908,10.34258,39.75274
42.17800,3.51490,795.69621,-0.05908,10.40979,39.81188
42.37800,3.53147,796.29952,-0.05907,10.47603,39.84207
42.57800,3.54815,796.68993,-0.05908,10.54276,39.86160
42.77800,3.56495,798.30084,-0.05909,10.60996,39.94220
42.97800,3.58151,798.55053,-0.05909,10.67621,39.95470
43.17800,3.59813,798.99831,-0.05910,10.74269,39.97710
43.37800,3.61481,800.21285,-0.05909,10.80942,40.03787
43.57800,3.63149,800.34351,-0.05910,10.87614,40.04441
43.77800,3.64812,800.99953,-0.05911,10.94263,40.07723
43.97800,3.66480,801.83884,-0.05913,11.00935,40.11922
44.17800,3.68148,802.50492,-0.05915,11.07608,40.15255
44.37800,3.69810,803.03140,-0.05914,11.14257,40.17889
44.57800,3.71484,803.19392,-0.05913,11.20953,40.18702
44.77800,3.73152,804.30638,-0.05914,11.27626,40.24268
44.97800,3.74814,805.21675,-0.05911,11.34274,40.28823
45.17800,3.76488,805.59934,-0.05911,11.40971,40.30738
45.37800,3.78145,806.41722,-0.05910,11.47595,40.34830
45.57800,3.79813,807.26119,-0.05909,11.54268,40.39053
45.77800,3.81481,807.95754,-0.05910,11.60940,40.42537
45.97800,3.83143,807.73029,-0.05910,11.67589,40.41400
46.17800,3.84817,808.70567,-0.05910,11.74285,40.46280
46.37800,3.86479,809.19061,-0.05909,11.80934,40.48706
46.57800,3.88141,810.37199,-0.05909,11.87582,40.54617
46.77800,3.89822,810.55975,-0.05910,11.94303,40.55556
46.97800,3.91484,811.44208,-0.05910,12.00951,40.59971
47.17800,3.93152,811.73014,-0.05910,12.07624,40.61412
47.37800,3.94820,812.61545,-0.05909,12.14296,40.65842
47.57800,3.96482,813.46612,-0.05910,12.20945,40.70098
47.77800,3.98138,814.46078,-0.05912,12.27570,40.75075
47.97800,3.99818,813.60517,-0.05912,12.34290,40.70794
48.17800,4.01498,815.25650,-0.05912,12.41010,40.79056
48.37800,4.03149,815.80002,-0.05911,12.47611,40.81776
48.57800,4.04811,815.89650,-0.05911,12.54260,40.82259
48.77800,4.06485,816.49758,-0.05911,12.60956,40.85266
48.97800,4.08147,817.01856,-0.05911,12.67605,40.87873
49.17800,4.09815,817.51999,-0.05912,12.74277,40.90381
49.37800,4.11489,817.81046,-0.05911,12.80974,40.91835
49.57800,4.13145,817.99347,-0.05911,12.87598,40.92751
49.77800,4.14813,818.80670,-0.05910,12.94271,40.96819
49.97800,4.16482,820.22715,-0.05911,13.00943,41.03926
50.17800,4.18156,819.41364,-0.05911,13.07640,40.99856
50.37800,4.19818,820.94651,-0.05911,13.14288,41.07526
50.57800,4.21480,821.02139,-0.05911,13.20937,41.07900
50.77800,4.23148,821.53697,-0.05911,13.27609,41.10480
50.97800,4.24816,821.79587,-0.05910,13.34282,41.11775
51.17800,4.26478,822.34973,-0.05910,13.40931,41.14547
51.37800,4.28153,822.62047,-0.05912,13.47627,41.15901
51.57800,4.29815,823.43370,-0.05912,13.54275,41.19970
51.77800,4.31477,823.57852,-0.05912,13.60924,41.20695
51.97800,4.33145,824.58640,-0.05915,13.67597,41.25737
52.17800,4.34813,824.70374,-0.05917,13.74269,41.26324
52.37800,4.36481,825.03008,-0.05920,13.80942,41.27958
52.57800,4.38149,825.44079,-0.05916,13.87614,41.30013
52.77800,4.39817,826.50315,-0.05912,13.94287,41.35328
52.97800,4.41480,826.63214,-0.05911,14.00935,41.35973
53.17800,4.43148,827.47042,-0.05912,14.07608,41.40167
53.37800,4.44816,827.09901,-0.05913,14.14280,41.38309
53.57800,4.46490,827.10171,-0.05912,14.20977,41.38322
53.77800,4.48152,828.19331,-0.05911,14.27625,41.43784
53.97800,4.49820,828.09571,-0.05911,14.34298,41.43296
54.17800,4.51482,828.56668,-0.05911,14.40946,41.45652
54.37800,4.53151,829.06662,-0.05913,14.47619,41.48154
54.57800,4.54819,829.91514,-0.05912,14.54291,41.52399
54.77800,4.56487,829.62196,-0.05910,14.60964,41.50932
54.97800,4.58143,830.32101,-0.05911,14.67589,41.54430
55.17800,4.59811,830.72232,-0.05911,14.74261,41.56438
55.37800,4.61491,831.73579,-0.05911,14.80981,41.61509
55.57800,4.63153,831.23902,-0.05912,14.87630,41.59023
55.77800,4.64815,831.70654,-0.05912,14.94279,41.61362
55.97800,4.66490,832.14417,-0.05913,15.00975,41.63552
56.17800,4.68152,832.46352,-0.05912,15.07624,41.65150
56.37800,4.69814,833.48416,-0.05914,15.14272,41.70256
56.57800,4.71482,833.09654,-0.05913,15.20945,41.68317
56.77800,4.73156,833.59331,-0.05914,15.27641,41.70803
56.97800,4.74818,834.06111,-0.05915,15.34290,41.73143
57.17800,4.76474,834.70894,-0.05915,15.40914,41.76385
57.37800,4.78149,834.35271,-0.05915,15.47611,41.74602
57.57800,4.79811,834.82796,-0.05913,15.54260,41.76980
57.77800,4.81485,835.32101,-0.05914,15.60956,41.79447
57.97800,4.83153,835.49786,-0.05915,15.67628,41.80332
58.17800,4.84815,835.85074,-0.05916,15.74277,41.82098
58.37800,4.86483,836.43692,-0.05916,15.80950,41.85030
58.57800,4.88151,836.80982,-0.05917,15.87622,41.86896
58.77800,4.89819,837.13159,-0.05915,15.94294,41.88506
58.97800,4.91482,837.20600,-0.05916,16.00943,41.88879
59.17800,4.93138,837.82952,-0.05913,16.07568,41.91998
59.37800,4.94818,837.60181,-0.05913,16.14288,41.90859
59.57800,4.96480,837.63348,-0.05913,16.20937,41.91017
59.77800,4.98142,838.72834,-0.05913,16.27585,41.96495
59.97800,4.99816,838.56499,-0.05912,16.34282,41.95678
60.17800,5.01478,838.84588,-0.05914,16.40930,41.97083
60.37800,5.03146,839.20648,-0.05914,16.47603,41.98888
60.57800,5.04815,839.70511,-0.05915,16.54275,42.01382
60.77800,5.06483,839.43177,-0.05913,16.60948,42.00015
60.97800,5.08151,839.86437,-0.05912,16.67620,42.02179
61.17800,5.09819,840.67183,-0.05913,16.74293,42.06219
61.37800,5.11487,840.67183,-0.05912,16.80965,42.06219
61.57800,5.13149,840.36309,-0.05912,16.87614,42.04675
61.77800,5.14811,841.04948,-0.05913,16.94262,42.08109
61.97800,5.16486,840.64044,-0.05912,17.00959,42.06062
62.17800,5.18148,841.20585,-0.05913,17.07607,42.08891
62.37800,5.19816,841.74611,-0.05913,17.14280,42.11594
62.57800,5.21484,841.23565,-0.05912,17.20952,42.09040
62.77800,5.23146,842.05195,-0.05911,17.27601,42.13125
62.97800,5.24814,842.18066,-0.05911,17.34274,42.13769
63.17800,5.26488,842.34364,-0.05912,17.40970,42.14584
63.37800,5.28156,842.06695,-0.05912,17.47642,42.13200
63.57800,5.29819,842.22686,-0.05913,17.54291,42.14000
63.77800,5.31487,842.79571,-0.05912,17.60964,42.16846
63.97800,5.33161,842.71152,-0.05912,17.67660,42.16425
64.17800,5.34817,843.10733,-0.05912,17.74285,42.18405
64.37801,5.36485,843.19869,-0.05912,17.80957,42.18862
64.57800,5.38153,843.53965,-0.05913,17.87630,42.20568
64.77800,5.39809,843.76698,-0.05912,17.94254,42.21706
64.97800,5.41484,844.00857,-0.05912,18.00951,42.22915
65.17800,5.43146,844.04889,-0.05912,18.07600,42.23116
65.37801,5.44814,843.80796,-0.05913,18.14272,42.21911
65.57800,5.46482,844.32894,-0.05916,18.20944,42.24517
65.77800,5.48144,844.54445,-0.05915,18.27593,42.25595
65.97801,5.49818,844.71880,-0.05916,18.34290,42.26468
66.17800,5.51480,844.49565,-0.05914,18.40938,42.25351
66.37801,5.53154,845.40080,-0.05914,18.47635,42.29880
66.57800,5.54823,845.08862,-0.05914,18.54307,42.28318
66.77800,5.56479,845.05891,-0.05916,18.60932,42.28170
66.97801,5.58147,845.44159,-0.05915,18.67604,42.30085
67.17800,5.59809,845.21808,-0.05914,18.74253,42.28966
67.37801,5.61489,845.64593,-0.05913,18.80973,42.31107
67.57800,5.63157,845.86330,-0.05913,18.87646,42.32195
67.77800,5.64819,845.75685,-0.05914,18.94294,42.31662
67.97801,5.66487,846.00644,-0.05914,19.00967,42.32911
68.17800,5.68144,846.03252,-0.05913,19.07591,42.33041
68.37801,5.69812,846.16542,-0.05913,19.14264,42.33706
68.57800,5.71486,846.23834,-0.05914,19.20960,42.34071
68.77800,5.73142,846.25818,-0.05913,19.27585,42.34170
68.97801,5.74810,846.97139,-0.05916,19.34258,42.37738
69.17800,5.76490,846.45972,-0.05918,19.40978,42.35178
69.37801,5.78152,846.51317,-0.05914,19.47626,42.35446
69.57800,5.79815,846.79080,-0.05917,19.54275,42.36835
69.77800,5.81489,846.98778,-0.05916,19.60971,42.37820
69.97801,5.83151,847.52673,-0.05915,19.67620,42.40517
70.17800,5.84807,847.57945,-0.05914,19.74245,42.40781
70.37801,5.86481,847.37809,-0.05913,19.80941,42.39774
70.57800,5.88161,847.01944,-0.05915,19.87661,42.37979
70.77800,5.89817,847.22163,-0.05913,19.94286,42.38991
70.97801,5.91485,847.04030,-0.05915,20.00959,42.38083
71.17800,5.93154,847.33646,-0.05915,20.07631,42.39565
71.37801,5.94816,847.68338,-0.05914,20.14280,42.41301
71.57800,5.96478,847.67072,-0.05915,20.20928,42.41238
71.77800,5.98158,847.76785,-0.05915,20.27649,42.41724
71.97801,5.99820,847.92040,-0.05914,20.34297,42.42487
72.17800,6.01482,847.84245,-0.05915,20.40946,42.42097
72.37801,6.03144,848.30774,-0.05914,20.47594,42.44425
72.57800,6.04819,847.61064,-0.05915,20.54291,42.40937
72.77800,6.06487,848.19142,-0.05915,20.60963,42.43843
72.97801,6.08149,848.11002,-0.05915,20.67612,42.43436
73.17800,6.09817,848.18369,-0.05916,20.74284,42.43804
73.37801,6.11473,848.59747,-0.05916,20.80909,42.45874
73.57800,6.13147,848.75291,-0.05915,20.87605,42.46652
73.77800,6.14821,848.38988,-0.05916,20.94302,42.44836
73.97801,6.16495,848.64832,-0.05916,21.00998,42.46129
74.17800,6.18140,848.43300,-0.05922,21.07575,42.45052
74.37801,6.19808,848.36809,-0.05918,21.14248,42.44727
74.57800,6.21482,848.86327,-0.05916,21.20944,42.47205
74.77800,6.23150,848.53144,-0.05918,21.27617,42.45544
74.97801,6.24824,848.27365,-0.05916,21.34313,42.44254
75.17800,6.26492,848.85471,-0.05917,21.40986,42.47161
75.37801,6.28142,848.00720,-0.05917,21.47586,42.42921
75.57800,6.29805,848.84809,-0.05916,21.54235,42.47129
75.77800,6.31485,848.79268,-0.05914,21.60955,42.46851
75.97801,6.33147,849.15981,-0.05915,21.67604,42.48688
76.17800,6.34815,848.48907,-0.05916,21.74276,42.45332
76.37801,6.36489,848.13330,-0.05915,21.80973,42.43552
76.57800,6.38157,849.31385,-0.05914,21.87645,42.49459
76.77800,6.39813,848.87864,-0.05914,21.94270,42.47281
76.97801,6.41487,848.95846,-0.05914,22.00966,42.47681
77.17800,6.43162,849.18160,-0.05914,22.07663,42.48797
77.37801,6.44818,848.79166,-0.05915,22.14288,42.46846
77.57800,6.46474,848.85675,-0.05914,22.20912,42.47172
77.77801,6.48160,848.86383,-0.05915,22.27657,42.47207
77.97801,6.49816,849.30826,-0.05914,22.34281,42.49431
78.17800,6.51478,848.99403,-0.05916,22.40930,42.47859
78.37801,6.53152,849.02151,-0.05915,22.47626,42.47996
78.57800,6.54809,849.19808,-0.05914,22.54251,42.48880
78.77801,6.56477,849.22817,-0.05915,22.60923,42.49030
78.97801,6.58151,848.58583,-0.05915,22.67620,42.45816
79.17800,6.59825,849.28032,-0.05915,22.74316,42.49291
79.37801,6.61487,849.06090,-0.05915,22.80965,42.48193
79.57800,6.63149,848.60213,-0.05916,22.87613,42.45898
79.77801,6.64817,849.00418,-0.05915,22.94286,42.47910
79.97801,6.66473,848.59459,-0.05915,23.00911,42.45860
80.17800,6.68148,849.01499,-0.05914,23.07607,42.47964
80.37801,6.69822,849.37895,-0.05914,23.14303,42.49784
80.57800,6.71478,848.59822,-0.05914,23.20928,42.45878
80.77801,6.73146,849.07161,-0.05915,23.27601,42.48247
80.97801,6.74808,848.68325,-0.05915,23.34249,42.46304
81.17800,6.76482,849.24838,-0.05916,23.40946,42.49131
81.37801,6.78150,849.21662,-0.05916,23.47618,42.48972
81.57800,6.79813,848.94141,-0.05915,23.54267,42.47596
81.77801,6.81481,848.50648,-0.05916,23.60939,42.45419
81.97801,6.83143,848.67580,-0.05917,23.67588,42.46267
82.17800,6.84817,848.94234,-0.05915,23.74284,42.47600
82.37801,6.86491,848.77769,-0.05916,23.80981,42.46776
82.57800,6.88153,849.22863,-0.05915,23.87629,42.49033
82.77801,6.89809,848.51515,-0.05917,23.94254,42.45463
82.97801,6.91477,848.56665,-0.05916,24.00927,42.45720
83.17800,6.93146,848.89242,-0.05917,24.07599,42.47350
83.37801,6.94814,848.56283,-0.05917,24.14271,42.45701
83.57800,6.96488,848.70514,-0.05917,24.20968,42.46413
83.77801,6.98156,849.15739,-0.05917,24.27641,42.48676
83.97801,6.99812,848.55948,-0.05915,24.34265,42.45684
84.17800,7.01480,848.67608,-0.05914,24.40938,42.46268
84.37801,7.03160,848.80032,-0.05915,24.47658,42.46889
84.57800,7.04816,848.73382,-0.05914,24.54283,42.46557
84.77801,7.06485,848.67440,-0.05914,24.60955,42.46259
84.97801,7.08153,848.45396,-0.05915,24.67628,42.45156
85.17800,7.09821,848.24637,-0.05917,24.74300,42.44118
85.37801,7.11483,848.21060,-0.05917,24.80949,42.43939
85.57800,7.13145,848.45135,-0.05917,24.87597,42.45144
85.77801,7.14819,847.95943,-0.05917,24.94294,42.42682
85.97801,7.16475,847.92236,-0.05916,25.00919,42.42497
86.17800,7.18144,848.07863,-0.05915,25.07591,42.43279
86.37801,7.19818,848.02024,-0.05915,25.14287,42.42986
86.57800,7.21480,847.65730,-0.05916,25.20936,42.41171
86.77801,7.23148,847.80138,-0.05914,25.27609,42.41891
86.97801,7.24816,847.97973,-0.05914,25.34281,42.42784
87.17800,7.26484,848.34322,-0.05915,25.40953,42.44603
87.37801,7.28146,847.03881,-0.05915,25.47602,42.38076
87.57800,7.29814,846.70465,-0.05915,25.54274,42.36404
87.77801,7.31489,847.47737,-0.05915,25.60971,42.40270
87.97801,7.33151,847.48697,-0.05915,25.67620,42.40318
88.17800,7.34819,847.24352,-0.05916,25.74292,42.39100
88.37801,7.36487,847.75779,-0.05916,25.80965,42.41673
88.57800,7.38149,847.47542,-0.05916,25.87613,42.40260
88.77801,7.39823,847.51491,-0.05917,25.94310,42.40458
88.97801,7.41479,847.78555,-0.05917,26.00934,42.41812
89.17800,7.43148,846.65185,-0.05916,26.07607,42.36140
89.37801,7.44816,846.92203,-0.05916,26.14279,42.37492
89.57800,7.46478,846.45711,-0.05916,26.20928,42.35165
89.77801,7.48152,846.46875,-0.05915,26.27624,42.35224
89.97801,7.49820,846.37236,-0.05916,26.34297,42.34742
90.17800,7.51482,846.47452,-0.05915,26.40945,42.35253
90.37801,7.53150,847.05576,-0.05915,26.47618,42.38161
90.57800,7.54818,846.36426,-0.05916,26.54290,42.34701
90.77801,7.56481,846.60063,-0.05918,26.60939,42.35884
90.97801,7.58155,845.99173,-0.05921,26.67635,42.32837
91.17800,7.59817,846.37003,-0.05918,26.74284,42.34730
91.37801,7.61479,846.55872,-0.05918,26.80933,42.35674
91.57800,7.63147,845.66223,-0.05917,26.87605,42.31188
91.77801,7.64815,846.53972,-0.05916,26.94277,42.35579
91.97801,7.66483,845.74809,-0.05916,27.00950,42.31618
92.17800,7.68157,846.48347,-0.05914,27.07646,42.35297
92.37801,7.69826,845.98642,-0.05916,27.14319,42.32811
92.57800,7.71482,845.45193,-0.05916,27.20944,42.30136
92.77801,7.73156,845.65356,-0.05919,27.27640,42.31145
92.97801,7.74818,845.90474,-0.05918,27.34289,42.32402
93.17800,7.76480,845.89291,-0.05917,27.40937,42.32343
93.37801,7.78154,845.76923,-0.05916,27.47634,42.31724
93.57800,7.79816,845.44457,-0.05916,27.54282,42.30099
93.77801,7.81485,845.28998,-0.05919,27.60955,42.29326
93.97801,7.83147,845.59591,-0.05917,27.67603,42.30857
94.17800,7.84809,845.06581,-0.05918,27.74252,42.28204
94.37801,7.86483,845.57086,-0.05919,27.80949,42.30731
94.57800,7.88145,844.19651,-0.05916,27.87597,42.23855
94.77801,7.89813,845.14907,-0.05916,27.94269,42.28621
94.97801,7.91481,844.84927,-0.05915,28.00942,42.27121
95.17800,7.93149,844.41900,-0.05916,28.07615,42.24968
95.37801,7.94824,844.08848,-0.05916,28.14311,42.23314
95.57800,7.96486,844.81463,-0.05915,28.20959,42.26947
95.77801,7.98154,844.03753,-0.05915,28.27632,42.23059
95.97801,7.99816,844.37160,-0.05916,28.34280,42.24731
96.17800,8.01478,843.94440,-0.05915,28.40929,42.22593
96.37801,8.03146,843.64424,-0.05917,28.47602,42.21091
96.57800,8.04814,843.92903,-0.05914,28.54274,42.22517
96.77801,8.06477,843.73122,-0.05917,28.60923,42.21527
96.97801,8.08145,843.89932,-0.05919,28.67595,42.22368
97.17800,8.09813,844.03064,-0.05920,28.74268,42.23025
97.37801,8.11487,843.99637,-0.05919,28.80964,42.22853
97.57800,8.13155,843.70794,-0.05917,28.87637,42.21410
97.77801,8.14817,843.19720,-0.05918,28.94285,42.18855
97.97801,8.16479,843.48423,-0.05918,29.00934,42.20291
98.17800,8.18147,842.96837,-0.05919,29.07607,42.17710
98.37801,8.19822,842.93913,-0.05917,29.14303,42.17564
98.57800,8.21484,842.68302,-0.05917,29.20952,42.16282
98.77801,8.23146,842.91054,-0.05916,29.27600,42.17421
98.97801,8.24820,842.63086,-0.05916,29.34296,42.16021
99.17800,8.26482,842.65228,-0.05917,29.40945,42.16129
99.37801,8.28144,842.19240,-0.05917,29.47594,42.13828
99.57800,8.29824,842.99333,-0.05916,29.54314,42.17835
99.77801,8.31486,842.12879,-0.05918,29.60963,42.13509
99.97801,8.33149,842.28069,-0.05916,29.67611,42.14269
100.17800,8.34823,842.30313,-0.05916,29.74308,42.14381
100.37801,8.36479,842.19296,-0.05917,29.80933,42.13830
100.57800,8.38147,842.44851,-0.05921,29.87605,42.15109
100.77801,8.39815,841.75682,-0.05918,29.94277,42.11648
100.97801,8.41483,841.20426,-0.05921,30.00950,42.08883
101.17800,8.43145,841.33372,-0.05920,30.07599,42.09531
101.37801,8.44814,841.17725,-0.05919,30.14271,42.08748
101.57800,8.46488,841.12193,-0.05920,30.20967,42.08471
101.77801,8.48156,841.09604,-0.05919,30.27640,42.08342
101.97801,8.49818,841.51151,-0.05918,30.34288,42.10421
102.17800,8.51480,840.62545,-0.05919,30.40937,42.05987
102.37801,8.53142,840.49813,-0.05919,30.47586,42.05350
102.57800,8.54816,840.30535,-0.05915,30.54282,42.04386
102.77801,8.56484,840.09487,-0.05916,30.60955,42.03333
102.97801,8.58153,839.82246,-0.05914,30.67627,42.01970
103.17800,8.59821,839.98255,-0.05916,30.74299,42.02771
103.37801,8.61483,839.85412,-0.05916,30.80948,42.02128
103.57800,8.63157,839.12518,-0.05915,30.87645,41.98481
103.77801,8.64813,839.39461,-0.05916,30.94269,41.99829
103.97801,8.66481,839.13924,-0.05917,31.00942,41.98551
104.17800,8.68161,839.09305,-0.05917,31.07662,41.98320
104.37801,8.69812,838.83554,-0.05915,31.14263,41.97032
104.57800,8.71468,839.80700,-0.05917,31.20888,42.01892
104.77801,8.73154,839.14716,-0.05915,31.27632,41.98591
104.97801,8.74822,838.47549,-0.05916,31.34304,41.95230
105.17800,8.76478,838.63372,-0.05915,31.40929,41.96022
105.37801,8.78146,838.87111,-0.05916,31.47601,41.97210
105.57800,8.79820,838.33439,-0.05917,31.54298,41.94524
105.77801,8.81476,838.13276,-0.05917,31.60923,41.93515
105.97801,8.83151,838.49803,-0.05916,31.67619,41.95343
106.17800,8.84831,838.11097,-0.05916,31.74340,41.93406
106.37801,8.86475,838.29574,-0.05917,31.80916,41.94331
106.57800,8.88143,837.32596,-0.05916,31.87589,41.89479
106.77801,8.89823,837.25443,-0.05918,31.94309,41.89121
106.97801,8.91485,837.25182,-0.05920,32.00958,41.89108
107.17800,8.93147,836.59384,-0.05919,32.07606,41.85815
107.37801,8.94815,836.66071,-0.05919,32.14279,41.86150
107.57800,8.96484,836.51626,-0.05919,32.20951,41.85427
107.77801,8.98140,837.32195,-0.05919,32.27576,41.89458
107.97801,8.99820,836.25494,-0.05917,32.34296,41.84120
108.17800,9.01494,836.65680,-0.05917,32.40993,41.86131
108.37801,9.03138,835.80799,-0.05916,32.47569,41.81884
108.57800,9.04812,835.16100,-0.05916,32.54266,41.78646
108.77801,9.06486,835.63058,-0.05917,32.60963,41.80996
108.97801,9.08149,835.08259,-0.05917,32.67611,41.78254
109.17800,9.09817,835.48678,-0.05917,32.74283,41.80276
109.37801,9.11485,835.40576,-0.05917,32.80956,41.79871
109.57800,9.13153,834.72878,-0.05918,32.87629,41.76484
109.77801,9.14809,834.06670,-0.05917,32.94253,41.73171
109.97801,9.16477,834.56486,-0.05917,33.00926,41.75664
110.17801,9.18151,834.79099,-0.05916,33.07622,41.76795
110.37801,9.19813,833.59648,-0.05919,33.14271,41.70819
110.57800,9.21488,833.26492,-0.05917,33.20967,41.69160
110.77801,9.23156,833.63345,-0.05917,33.27640,41.71003
110.97801,9.24818,833.29026,-0.05916,33.34288,41.69286
111.17801,9.26492,833.10679,-0.05917,33.40985,41.68369
111.37801,9.28160,832.78250,-0.05917,33.47657,41.66746
111.57800,9.29816,832.55507,-0.05917,33.54282,41.65608
111.77801,9.31466,832.93784,-0.05916,33.60883,41.67523
111.97801,9.33147,832.38157,-0.05917,33.67603,41.64740
112.17801,9.34821,831.83413,-0.05917,33.74299,41.62001
112.37801,9.36483,832.21616,-0.05919,33.80948,41.63912
112.57800,9.38145,831.54244,-0.05917,33.87597,41.60542
112.77801,9.39825,831.89951,-0.05918,33.94317,41.62328
112.97801,9.41475,831.29453,-0.05916,34.00918,41.59301
113.17801,9.43149,831.38086,-0.05916,34.07614,41.59733
113.37801,9.44823,831.03692,-0.05916,34.14311,41.58012
113.57800,9.46492,830.50365,-0.05917,34.20983,41.55344
113.77801,9.48148,830.19761,-0.05917,34.27608,41.53813
113.97801,9.49816,830.39161,-0.05916,34.34280,41.54783
114.17801,9.51484,829.76688,-0.05918,34.40953,41.51657
114.37801,9.53146,829.60166,-0.05917,34.47601,41.50831
114.57800,9.54820,829.34611,-0.05917,34.54298,41.49552
114.77801,9.56488,829.05265,-0.05917,34.60971,41.48084
114.97801,9.58145,829.48022,-0.05917,34.67595,41.50223
115.17801,9.59813,829.26154,-0.05917,34.74267,41.49129
115.37801,9.61481,828.66019,-0.05917,34.80940,41.46120
115.57800,9.63149,828.11778,-0.05917,34.87613,41.43406
115.77801,9.64817,828.23783,-0.05917,34.94285,41.44007
115.97801,9.66479,827.58060,-0.05916,35.00934,41.40719
116.17801,9.68147,827.77264,-0.05916,35.07606,41.41679
116.37801,9.69815,826.93100,-0.05917,35.14279,41.37468
116.57800,9.71490,826.77472,-0.05917,35.20975,41.36687
116.77801,9.73158,826.49942,-0.05917,35.27648,41.35309
116.97801,9.74820,826.22990,-0.05918,35.34296,41.33961
117.17801,9.76476,826.30012,-0.05918,35.40921,41.34312
117.37801,9.78144,825.80764,-0.05918,35.47593,41.31848
117.57800,9.79812,825.51893,-0.05918,35.54266,41.30403
117.77801,9.81480,825.58002,-0.05919,35.60938,41.30709
117.97801,9.83148,825.55199,-0.05917,35.67611,41.30569
118.17801,9.84817,824.72349,-0.05918,35.74283,41.26423
118.37801,9.86485,824.91050,-0.05918,35.80956,41.27359
118.57800,9.88153,824.10611,-0.05917,35.87629,41.23335
118.77801,9.89821,823.97489,-0.05918,35.94300,41.22678
118.97801,9.91477,823.35826,-0.05917,36.00926,41.19593
119.17801,9.93145,823.60953,-0.05916,36.07598,41.20850
119.37801,9.94825,822.75802,-0.05917,36.14318,41.16589
119.57800,9.96482,823.01209,-0.05917,36.20943,41.17860
119.77801,9.98150,822.55965,-0.05917,36.27616,41.15597
119.97801,9.99824,821.90894,-0.05917,36.34312,41.12341
120.17801,10.01480,821.77203,-0.05917,36.40936,41.11656
120.37801,10.03148,821.70023,-0.05917,36.47609,41.11297
120.57800,10.04816,821.80724,-0.05919,36.54281,41.11832
120.77801,10.06484,821.52262,-0.05919,36.60954,41.10408
120.97801,10.08152,820.93515,-0.05919,36.67627,41.07469
121.17801,10.09815,820.62772,-0.05920,36.74275,41.05931
121.37801,10.11489,819.36726,-0.05921,36.80971,40.99624
121.57800,10.13139,819.59749,-0.05930,36.87572,41.00776
121.77801,10.14813,819.77267,-0.05923,36.94269,41.01653
121.97801,10.16493,818.98542,-0.05921,37.00989,40.97713
122.17801,10.18155,818.51482,-0.05911,37.07638,40.95359
122.37801,10.19817,817.72245,-0.05920,37.14286,40.91394
122.57800,10.21479,817.14531,-0.05921,37.20935,40.88507
122.77801,10.23148,817.39537,-0.05919,37.27607,40.89758
122.97801,10.24810,817.59952,-0.05920,37.34256,40.90779
123.17801,10.26484,816.70703,-0.05917,37.40952,40.86314
123.37801,10.28152,816.60161,-0.05917,37.47625,40.85786
123.57800,10.29814,815.18488,-0.05917,37.54274,40.78698
123.77801,10.31482,815.42274,-0.05916,37.60946,40.79888
123.97801,10.33150,815.13636,-0.05916,37.67619,40.78455
124.17801,10.34819,814.80937,-0.05916,37.74291,40.76819
124.37801,10.36493,814.69426,-0.05916,37.80987,40.76243
124.57800,10.38149,813.82412,-0.05917,37.87612,40.71889
124.77801,10.39811,813.72829,-0.05917,37.94261,40.71410
124.97801,10.41485,813.31497,-0.05916,38.00957,40.69342
125.17801,10.43147,812.37908,-0.05917,38.07606,40.64660
125.37801,10.44821,812.68791,-0.05917,38.14302,40.66204
125.57800,10.46484,811.90793,-0.05917,38.20951,40.62302
125.77801,10.48140,811.80092,-0.05917,38.27575,40.61766
125.97801,10.49814,811.19845,-0.05919,38.34272,40.58752
126.17801,10.51482,810.00086,-0.05918,38.40944,40.52760
126.37801,10.53150,809.99760,-0.05917,38.47617,40.52744
126.57800,10.54818,808.99484,-0.05918,38.54289,40.47727
126.77801,10.56486,808.45142,-0.05920,38.60962,40.45008
126.97801,10.58154,808.26301,-0.05920,38.67634,40.44065
127.17801,10.59817,807.77416,-0.05919,38.74283,40.41619
127.37801,10.61485,807.64228,-0.05917,38.80956,40.40959
127.57800,10.63147,806.59455,-0.05918,38.87604,40.35717
127.77801,10.64821,806.33499,-0.05917,38.94300,40.34418
127.97801,10.66489,805.14513,-0.05917,39.00973,40.28465
128.17801,10.68145,804.67751,-0.05917,39.07597,40.26125
128.37801,10.69813,804.71393,-0.05917,39.14270,40.26308
128.57800,10.71493,803.71946,-0.05918,39.20990,40.21332
128.77800,10.73144,803.16113,-0.05918,39.27591,40.18538
128.97802,10.74812,802.50651,-0.05918,39.34264,40.15263
129.17801,10.76480,801.39609,-0.05918,39.40936,40.09707
129.37801,10.78148,800.65932,-0.05918,39.47609,40.06021
129.57800,10.79822,800.07715,-0.05918,39.54305,40.03108
129.77800,10.81484,799.39058,-0.05918,39.60954,39.99673
129.97802,10.83158,798.75346,-0.05919,39.67651,39.96485
130.17801,10.84808,798.12743,-0.05918,39.74251,39.93353
130.37801,10.86477,797.23764,-0.05918,39.80924,39.88901
130.57800,10.88151,795.92131,-0.05919,39.87620,39.82315
130.77800,10.89813,795.43516,-0.05920,39.94268,39.79882
130.97802,10.91475,795.19777,-0.05918,40.00917,39.78694
131.17802,10.93149,793.98835,-0.05918,40.07613,39.72643
131.37800,10.94817,792.90932,-0.05919,40.14286,39.67244
131.57800,10.96485,792.08696,-0.05919,40.20959,39.63130
131.77800,10.98154,791.09641,-0.05920,40.27631,39.58174
131.97802,10.99822,789.89323,-0.05921,40.34304,39.52154
132.17802,11.01478,788.41224,-0.05922,40.40928,39.44744
132.37800,11.03152,787.50560,-0.05921,40.47624,39.40207
132.57800,11.04820,785.98429,-0.05920,40.54298,39.32595
132.77800,11.06482,784.47582,-0.05921,40.60946,39.25048
132.97802,11.08150,782.82151,-0.05921,40.67618,39.16771
133.17802,11.09819,780.81982,-0.05921,40.74291,39.06756
133.37800,11.11481,778.56928,-0.05920,40.80939,38.95495
133.57800,11.13143,775.92102,-0.05921,40.87588,38.82245
133.77800,11.14817,773.62768,-0.05919,40.94285,38.70771
133.97802,11.16491,769.60437,-0.05920,41.00981,38.50640
134.17802,11.18147,764.23944,-0.05917,41.07606,38.23797
134.37800,11.19815,756.59105,-0.05919,41.14278,37.85529
134.57800,11.21495,132.91317,-0.05920,41.20998,6.65018
134.59202,11.21615,8.44093,-0.05919,41.21476,0.42233