File: Manufatura Aditiva/Classificação Orientação/Ensaios/Ensaios FDM/Tracao_OLABI_23_05_2018_FDM_XZ3.is_metal_RawData/Specimen_RawData_4.csv
Time,Extension,Load,Strain 1,Tensile strain,Tensile stress
(sec),(mm),(N),(mm/mm),(%),(MPa)
0.00000,0.00006,19.89435,0.00091,0.09135,0.96250
0.20000,0.01387,25.53218,0.00110,0.11018,1.23526
0.40000,0.03265,33.62702,0.00140,0.14049,1.62689
0.60000,0.04986,42.21471,0.00169,0.16908,2.04237
0.80000,0.06667,49.34010,0.00197,0.19682,2.38710
1.00000,0.08329,56.25365,0.00224,0.22430,2.72158
1.20000,0.10009,63.86847,0.00252,0.25158,3.08999
1.40000,0.11671,71.81240,0.00280,0.28018,3.47432
1.60000,0.13339,78.63497,0.00308,0.30814,3.80440
1.80000,0.15001,85.95953,0.00336,0.33554,4.15876
2.00000,0.16663,92.87643,0.00363,0.36349,4.49340
2.20000,0.18331,100.73219,0.00391,0.39110,4.87347
2.40000,0.19994,107.49745,0.00419,0.41947,5.20078
2.60000,0.21668,114.72575,0.00447,0.44696,5.55049
2.80000,0.23330,121.56168,0.00475,0.47453,5.88121
3.00000,0.24998,128.28467,0.00502,0.50218,6.20647
3.20000,0.26672,135.34715,0.00530,0.53033,6.54816
3.40000,0.28340,143.43353,0.00558,0.55812,6.93938
3.60000,0.30002,149.80014,0.00586,0.58571,7.24740
3.80000,0.31670,156.59600,0.00613,0.61293,7.57619
4.00000,0.33333,163.19781,0.00640,0.64019,7.89559
4.20000,0.35001,170.60053,0.00668,0.66754,8.25373
4.40000,0.36663,177.82423,0.00695,0.69545,8.60322
4.60000,0.38331,185.12250,0.00723,0.72299,8.95631
4.80000,0.40005,191.77236,0.00751,0.75094,9.27804
5.00000,0.41661,198.69434,0.00778,0.77794,9.61292
5.20000,0.43329,205.02403,0.00806,0.80558,9.91916
5.40000,0.45004,212.62432,0.00834,0.83365,10.28686
5.60000,0.46666,219.60132,0.00861,0.86086,10.62441
5.80000,0.48328,225.63343,0.00888,0.88824,10.91625
6.00000,0.50002,233.70250,0.00916,0.91593,11.30664
6.20000,0.51670,239.62473,0.00943,0.94286,11.59316
6.40000,0.53332,246.26972,0.00970,0.97003,11.91464
6.60000,0.54994,253.44621,0.00997,0.99736,12.26185
6.80000,0.56674,260.07188,0.01025,1.02505,12.58240
7.00000,0.58331,267.11186,0.01052,1.05214,12.92300
7.20000,0.59993,273.38336,0.01079,1.07935,13.22641
7.40000,0.61673,280.26670,0.01107,1.10733,13.55943
7.60000,0.63329,287.60682,0.01135,1.13496,13.91455
7.80000,0.64991,293.57495,0.01162,1.16193,14.20329
8.00000,0.66671,300.47498,0.01189,1.18936,14.53712
8.20000,0.68327,307.60213,0.01216,1.21638,14.88193
8.40000,0.69996,313.51438,0.01244,1.24396,15.16797
8.60000,0.71664,320.04940,0.01270,1.26975,15.48414
8.80000,0.73338,325.88767,0.01296,1.29640,15.76660
9.00000,0.75000,333.06801,0.01324,1.32367,16.11399
9.20000,0.76662,338.93688,0.01351,1.35139,16.39792
9.40000,0.78336,345.46964,0.01378,1.37850,16.71398
9.60000,0.79992,351.50661,0.01406,1.40605,17.00605
9.80000,0.81666,358.17227,0.01433,1.43319,17.32854
10.00000,0.83341,364.77789,0.01461,1.46061,17.64812
10.20000,0.85003,371.03028,0.01488,1.48750,17.95062
10.40000,0.86665,376.60932,0.01515,1.51489,18.22053
10.60000,0.88333,383.49335,0.01542,1.54201,18.55359
10.80000,0.89995,390.10614,0.01569,1.56936,18.87352
11.00000,0.91663,396.10271,0.01597,1.59674,19.16363
11.20000,0.93331,402.06453,0.01624,1.62416,19.45207
11.40000,0.95011,408.63897,0.01651,1.65149,19.77014
11.60000,0.96656,414.94453,0.01679,1.67896,20.07521
11.80000,0.98324,420.52655,0.01706,1.70622,20.34527
12.00000,1.00010,427.50547,0.01734,1.73416,20.68291
12.20000,1.01666,433.06826,0.01759,1.75889,20.95204
12.40000,1.03328,438.54117,0.01784,1.78444,21.21683
12.60000,1.05002,444.84083,0.01811,1.81119,21.52161
12.80000,1.06670,449.76054,0.01838,1.83840,21.75962
13.00000,1.08327,457.46202,0.01866,1.86593,22.13223
13.20000,1.10001,463.13461,0.01894,1.89372,22.40667
13.40000,1.11675,469.71878,0.01921,1.92108,22.72521
13.60000,1.13325,474.92296,0.01948,1.94811,22.97699
13.80000,1.14993,481.59440,0.01976,1.97573,23.29976
14.00000,1.16679,486.81879,0.02003,2.00337,23.55252
14.20000,1.18329,493.64138,0.02031,2.03070,23.88260
14.40000,1.19998,499.72637,0.02058,2.05801,24.17699
14.60000,1.21672,505.16268,0.02086,2.08635,24.44000
14.80000,1.23334,510.98401,0.02113,2.11341,24.72164
15.00000,1.24996,517.59249,0.02141,2.14090,25.04136
15.20000,1.26664,522.98293,0.02169,2.16883,25.30216
15.40000,1.28332,528.60449,0.02196,2.19600,25.57413
15.60000,1.30000,533.22492,0.02219,2.21913,25.79767
15.80000,1.31656,538.89947,0.02247,2.24693,26.07221
16.00000,1.33337,544.90711,0.02275,2.27499,26.36286
16.20000,1.34993,550.07963,0.02302,2.30233,26.61311
16.40000,1.36667,556.06691,0.02330,2.33001,26.90277
16.60000,1.38341,561.35412,0.02358,2.35758,27.15857
16.80000,1.40003,566.47295,0.02386,2.38552,27.40622
17.00000,1.41677,571.90699,0.02413,2.41347,27.66912
17.20000,1.43327,577.95462,0.02441,2.44133,27.96171
17.40000,1.45001,583.34349,0.02469,2.46901,28.22243
17.60000,1.46670,588.82581,0.02497,2.49684,28.48767
17.80000,1.48338,594.36318,0.02525,2.52490,28.75557
18.00000,1.50000,599.62380,0.02553,2.55288,29.01008
18.20000,1.51656,604.86980,0.02580,2.58033,29.26388
18.40000,1.53324,611.08042,0.02609,2.60871,29.56435
18.60000,1.55004,615.20063,0.02635,2.63523,29.76369
18.80000,1.56666,618.99931,0.02657,2.65745,29.94747
19.00000,1.58329,625.18604,0.02686,2.68556,30.24679
19.20000,1.60003,629.93653,0.02714,2.71378,30.47662
19.40000,1.61665,634.96451,0.02742,2.74218,30.71988
19.60000,1.63333,640.42667,0.02770,2.76996,30.98414
19.80000,1.65007,646.03770,0.02799,2.79869,31.25560
20.00000,1.66675,650.90242,0.02827,2.82664,31.49096
20.20000,1.68331,655.99810,0.02855,2.85532,31.73749
20.40000,1.69999,661.02315,0.02884,2.88361,31.98061
20.60000,1.71668,665.85983,0.02912,2.91225,32.21461
20.80000,1.73330,671.29377,0.02941,2.94071,32.47750
21.00000,1.74998,675.50209,0.02969,2.96891,32.68111
21.20000,1.76666,680.63363,0.02998,2.99774,32.92937
21.40000,1.78334,686.22059,0.03026,3.02630,33.19967
21.60000,1.79996,690.69681,0.03055,3.07414,33.41623
21.78400,1.81539,695.18522,0.03082,3.13584,33.63338
21.98400,1.83207,700.06093,0.03110,3.20257,33.86927
22.18400,1.84869,704.07558,0.03133,3.26905,34.06350
22.38400,1.86537,708.41955,0.03162,3.33578,34.27367
22.58400,1.88199,713.34145,0.03191,3.40226,34.51179
22.78400,1.89862,717.32467,0.03220,3.46875,34.70450
22.98400,1.91530,721.69960,0.03249,3.53547,34.91616
23.18400,1.93198,725.94215,0.03278,3.60220,35.12142
23.38400,1.94860,731.14871,0.03307,3.66868,35.37331
23.58400,1.96528,735.85669,0.03336,3.73541,35.60109
23.78400,1.98196,740.23646,0.03366,3.80213,35.81298
23.98400,1.99864,744.05316,0.03132,3.86886,35.99764
24.18400,2.01538,748.47769,0.03441,3.93582,36.21170
24.38400,2.03201,755.11453,0.02072,4.00231,36.53279
24.58400,2.04869,757.16688,0.00784,4.06904,36.63208
24.78400,2.06537,761.49758,0.00795,4.13576,36.84161
24.98400,2.08199,764.66789,0.00553,4.20225,36.99499
25.18400,2.09873,769.03692,0.00505,4.26921,37.20636
25.38400,2.11535,773.17348,0.00761,4.33570,37.40649
25.58400,2.13197,777.19362,0.00653,4.40218,37.60099
25.78400,2.14866,779.70293,0.00613,4.46891,37.72239
25.98400,2.16534,783.91051,0.00635,4.53563,37.92595
26.18400,2.18202,788.02919,0.01329,4.60236,38.12522
26.38400,2.19864,791.85776,-0.13619,4.66884,38.31045
26.58400,2.21532,795.81626,-0.13570,4.73557,38.50196
26.78400,2.23200,799.84069,-0.13570,4.80229,38.69666
26.98400,2.24862,803.10153,-0.13571,4.86878,38.85442
27.18400,2.26542,806.70742,-0.13571,4.93598,39.02888
27.38400,2.28199,810.05646,-0.13571,5.00223,39.19091
27.58400,2.29867,814.29845,-0.13572,5.06896,39.39614
27.78400,2.31541,817.82658,-0.13572,5.13592,39.56683
27.98400,2.33203,821.19480,-0.13572,5.20241,39.72979
28.18400,2.34865,825.15944,-0.13572,5.26889,39.92160
28.38400,2.36539,828.04011,-0.13573,5.33586,40.06097
28.58400,2.38201,831.49765,-0.13573,5.40234,40.22824
28.78400,2.39863,834.67551,-0.13572,5.46883,40.38199
28.98400,2.41526,838.35702,-0.13573,5.53531,40.56010
29.18400,2.43200,841.58005,-0.13573,5.60228,40.71603
29.38400,2.44862,843.50388,-0.13573,5.66876,40.80911
29.58400,2.46530,846.60016,-0.13573,5.73549,40.95891
29.78400,2.48204,849.26803,-0.13573,5.80245,41.08798
29.98400,2.49860,852.56267,-0.13573,5.86870,41.24738
30.18400,2.51534,855.42034,-0.13573,5.93566,41.38563
30.38400,2.53197,858.29422,-0.13573,6.00215,41.52467
30.58400,2.54871,861.41936,-0.13574,6.06911,41.67587
30.78400,2.56539,863.46520,-0.13573,6.13584,41.77485
30.98400,2.58195,866.22126,-0.13573,6.20208,41.90819
31.18400,2.59863,869.07912,-0.13573,6.26881,42.04645
31.38400,2.61537,871.39048,-0.13573,6.33577,42.15828
31.58400,2.63199,873.76311,-0.13574,6.40226,42.27306
31.78400,2.64867,876.23242,-0.13574,6.46899,42.39253
31.98400,2.66524,879.31799,-0.13574,6.53523,42.54181
32.18400,2.68198,881.01886,-0.13574,6.60220,42.62410
32.38400,2.69872,883.07243,-0.13574,6.66916,42.72345
32.58400,2.71540,884.84772,-0.13574,6.73589,42.80934
32.78400,2.73208,887.31786,-0.13574,6.80261,42.92885
32.98400,2.74864,889.38149,-0.13574,6.86886,43.02869
33.18400,2.76532,891.76241,-0.13574,6.93558,43.14388
33.38400,2.78189,892.89658,-0.13574,7.00183,43.19875
33.58400,2.79869,895.71765,-0.13574,7.06903,43.33524
33.78400,2.81549,896.92771,-0.13574,7.13624,43.39378
33.98400,2.83193,898.38468,-0.13574,7.20200,43.46427
34.18400,2.84861,899.57817,-0.13574,7.26873,43.52201
34.38400,2.86535,899.88979,-0.13574,7.33569,43.53709
34.58400,2.88197,901.42898,-0.13574,7.40218,43.61155
34.78400,2.89871,903.09158,-0.13574,7.46914,43.69199
34.98400,2.91546,904.12712,-0.13574,7.53611,43.74209
35.18400,2.93202,905.88182,-0.13574,7.60235,43.82698
35.38400,2.94864,906.78679,-0.13574,7.66884,43.87077
35.58400,2.96538,907.79336,-0.13574,7.73581,43.91946
35.78400,2.98212,909.13139,-0.13575,7.80277,43.98420
35.98400,2.99862,910.13638,-0.13574,7.86878,44.03282
36.18400,3.01518,911.06528,-0.13575,7.93502,44.07776
36.38400,3.03198,911.35530,-0.13574,8.00223,44.09179
36.58400,3.04855,912.99582,-0.13574,8.06847,44.17116
36.78400,3.06529,913.42870,-0.13575,8.13544,44.19210
36.98400,3.08197,913.69106,-0.13574,8.20216,44.20480
37.18400,3.09865,914.18577,-0.13574,8.26889,44.22873
37.38400,3.11533,914.83062,-0.13575,8.33561,44.25993
37.58400,3.13195,915.28660,-0.13575,8.40210,44.28199
37.78400,3.14869,915.75654,-0.13575,8.46906,44.30473
37.98400,3.16532,915.98118,-0.13574,8.53555,44.31559
38.18400,3.18206,915.05162,-0.13575,8.60251,44.27062
38.38400,3.19874,915.55864,-0.13575,8.66924,44.29515
38.58400,3.21530,915.35896,-0.13575,8.73548,44.28549
38.78400,3.23198,915.59775,-0.13575,8.80221,44.29704
38.98400,3.24872,915.97531,-0.13575,8.86917,44.31531
39.18400,3.26534,915.52380,-0.13575,8.93566,44.29346
39.38400,3.28196,914.54582,-0.13575,9.00215,44.24615
39.58400,3.29865,914.85009,-0.13575,9.06887,44.26087
39.78400,3.31533,914.34699,-0.13575,9.13560,44.23653
39.98400,3.33195,914.00500,-0.13575,9.20208,44.21999
40.18400,3.34869,913.31834,-0.13575,9.26905,44.18676
40.38400,3.36537,912.68998,-0.13575,9.33577,44.15636
40.58400,3.38193,912.04671,-0.13575,9.40202,44.12524
40.78400,3.39861,911.29914,-0.13575,9.46874,44.08908
40.98400,3.41547,910.68782,-0.13575,9.53619,44.05950
41.18400,3.43204,910.13601,-0.13575,9.60243,44.03280
41.38400,3.44860,908.81623,-0.13575,9.66868,43.96895
41.58400,3.46534,907.91676,-0.13575,9.73564,43.92543
41.78400,3.48196,907.20458,-0.13575,9.80213,43.89098
41.98400,3.49858,906.51913,-0.13575,9.86862,43.85781
42.18400,3.51538,905.19935,-0.13575,9.93582,43.79396
42.38400,3.53206,904.14919,-0.13575,10.00254,43.74316
42.58400,3.54857,902.82932,-0.13575,10.06855,43.67930
42.78400,3.56531,902.23746,-0.13575,10.13552,43.65067
42.98400,3.58211,901.06698,-0.13576,10.20272,43.59404
43.18400,3.59861,899.56168,-0.13575,10.26873,43.52121
43.38400,3.61523,898.57122,-0.13575,10.33521,43.47329
43.58400,3.63209,897.54565,-0.13575,10.40266,43.42368
43.78400,3.64865,896.12082,-0.13575,10.46890,43.35474
43.98400,3.66528,894.63750,-0.13575,10.53539,43.28298
44.18400,3.68208,893.75330,-0.13575,10.60259,43.24020
44.38400,3.69870,892.94044,-0.13575,10.66908,43.20087
44.58400,3.71532,890.62266,-0.13575,10.73556,43.08874
44.78400,3.73194,889.47536,-0.13576,10.80205,43.03323
44.98400,3.74868,888.26614,-0.13575,10.86901,42.97473
45.18400,3.76530,887.06529,-0.13576,10.93550,42.91663
45.38400,3.78192,885.48213,-0.13575,11.00199,42.84004
45.58400,3.79873,884.48199,-0.13575,11.06919,42.79165
45.78400,3.81529,882.54437,-0.13576,11.13544,42.69791
45.98400,3.83197,881.33188,-0.13575,11.20216,42.63924
46.18400,3.84865,880.66533,-0.13575,11.26889,42.60700
46.38400,3.86533,878.77782,-0.13575,11.33561,42.51568
46.58400,3.88195,878.37474,-0.13576,11.40210,42.49618
46.78400,3.89863,877.25595,-0.13575,11.46882,42.44205
46.98400,3.91537,875.12964,-0.13575,11.53579,42.33918
47.18400,3.93194,874.12186,-0.13576,11.60203,42.29042
47.38400,3.94862,873.08623,-0.13575,11.66876,42.24032
47.58400,3.96536,871.89749,-0.13576,11.73572,42.18280
47.78400,3.98198,870.53105,-0.13576,11.80221,42.11670
47.98400,3.99860,869.10054,-0.13576,11.86869,42.04749
48.18400,4.01534,867.85825,-0.13576,11.93566,41.98738
48.38400,4.03196,867.06514,-0.13575,12.00214,41.94901
48.58400,4.04871,865.12221,-0.13576,12.06911,41.85501
48.78400,4.06539,864.62470,-0.13575,12.13583,41.83094
48.98400,4.08207,863.05551,-0.13576,12.20256,41.75503
49.18400,4.09863,862.58892,-0.13576,12.26880,41.73245
49.38400,4.11531,860.87659,-0.13575,12.33553,41.64961
49.58400,4.13205,860.13814,-0.13576,12.40249,41.61388
49.78400,4.14861,858.66125,-0.13576,12.46874,41.54243
49.98400,4.16529,857.63521,-0.13576,12.53547,41.49279
50.18400,4.18204,857.20457,-0.13576,12.60243,41.47195
50.38400,4.19866,855.77630,-0.13575,12.66892,41.40285
50.58400,4.21534,855.21722,-0.13576,12.73564,41.37580
50.78400,4.23202,854.22108,-0.13576,12.80237,41.32761
50.98400,4.24876,853.21097,-0.13576,12.86933,41.27874
51.18400,4.26532,851.91019,-0.13576,12.93558,41.21581
51.38400,4.28200,850.79521,-0.13576,13.00230,41.16187
51.58400,4.29874,849.12060,-0.13576,13.06927,41.08085
51.78400,4.31537,848.91338,-0.13576,13.13575,41.07082
51.98400,4.33199,847.46545,-0.13576,13.20224,41.00077
52.18400,4.34861,847.25777,-0.13576,13.26872,40.99072
52.38400,4.36529,846.01007,-0.13575,13.33545,40.93036
52.58400,4.38197,845.08322,-0.13576,13.40218,40.88552
52.78400,4.39859,844.23674,-0.13576,13.46866,40.84457
52.98400,4.41533,843.46626,-0.13576,13.53562,40.80729
53.18400,4.43202,842.58765,-0.13576,13.60235,40.76478
53.38400,4.44864,841.37050,-0.13576,13.66884,40.70589
53.58400,4.46538,840.59862,-0.13576,13.73580,40.66855
53.78400,4.48200,839.49883,-0.13576,13.80229,40.61534
53.98400,4.49868,838.82408,-0.13576,13.86901,40.58270
54.18400,4.51542,837.99297,-0.13576,13.93598,40.54249
54.38400,4.53204,837.08307,-0.13576,14.00246,40.49847
54.58400,4.54861,836.87203,-0.13576,14.06871,40.48826
54.78400,4.56529,835.54797,-0.13576,14.13543,40.42420
54.98400,4.58203,834.94661,-0.13576,14.20240,40.39510
55.18400,4.59871,833.95410,-0.13576,14.26912,40.34709
55.38400,4.61533,833.13752,-0.13576,14.33561,40.30758
55.58400,4.63201,832.65714,-0.13576,14.40233,40.28434
55.78400,4.64869,831.56750,-0.13576,14.46906,40.23162
55.98400,4.66537,831.12670,-0.13576,14.53578,40.21030
56.18400,4.68211,829.96115,-0.13576,14.60275,40.15390
56.38400,4.69868,829.10573,-0.13576,14.66899,40.11252
56.58400,4.71536,828.13790,-0.13576,14.73572,40.06570
56.78400,4.73198,827.06232,-0.13576,14.80221,40.01366
56.98400,4.74860,826.88788,-0.13576,14.86869,40.00522
57.18400,4.76534,825.70789,-0.13576,14.93566,39.94813
57.38400,4.78196,825.50673,-0.13576,15.00214,39.93840
57.58400,4.79870,823.87989,-0.13576,15.06911,39.85969
57.78400,4.81527,823.52581,-0.13576,15.13535,39.84256
57.98400,4.83195,822.36091,-0.13576,15.20208,39.78620
58.18400,4.84869,822.18023,-0.13576,15.26904,39.77746
58.38400,4.86537,821.14264,-0.13576,15.33577,39.72726
58.58400,4.88199,820.12676,-0.13576,15.40225,39.67811
58.78400,4.89861,819.42985,-0.13576,15.46874,39.64440
58.98400,4.91529,819.06794,-0.13576,15.53546,39.62689
59.18400,4.93192,818.42337,-0.13576,15.60195,39.59570
59.38400,4.94872,817.54439,-0.13576,15.66915,39.55318
59.58400,4.96534,816.91639,-0.13576,15.73564,39.52279
59.78400,4.98196,816.32165,-0.13576,15.80213,39.49402
59.98400,4.99864,814.68634,-0.13576,15.86885,39.41490
60.18400,5.01532,815.00299,-0.13576,15.93557,39.43022
60.38400,5.03200,813.82561,-0.13576,16.00230,39.37326
60.58400,5.04868,813.14947,-0.13576,16.06902,39.34055
60.78400,5.06531,812.20828,-0.13576,16.13551,39.29501
60.98400,5.08199,812.17447,-0.13576,16.20224,39.29338
61.18400,5.09867,810.79472,-0.13576,16.26896,39.22662
61.38400,5.11535,810.02973,-0.13576,16.33569,39.18961
61.58400,5.13203,809.97515,-0.13576,16.40241,39.18697
61.78400,5.14871,808.97035,-0.13576,16.46914,39.13836
61.98400,5.16533,808.19828,-0.13576,16.53562,39.10101
62.18400,5.18202,807.93286,-0.13576,16.60235,39.08817
62.38400,5.19864,807.40256,-0.13576,16.66883,39.06251
62.58400,5.21532,805.84465,-0.13576,16.73556,38.98714
62.78400,5.23206,805.30243,-0.13576,16.80252,38.96091
62.98400,5.24862,805.10378,-0.13576,16.86877,38.95129
63.18400,5.26524,804.58438,-0.13576,16.93526,38.92617
63.38400,5.28198,803.74600,-0.13576,17.00222,38.88560
63.58400,5.29866,802.65859,-0.13576,17.06894,38.83300
63.78400,5.31535,802.37044,-0.13576,17.13567,38.81905
63.98400,5.33203,801.60117,-0.13576,17.20240,38.78184
64.18400,5.34865,801.17770,-0.13576,17.26888,38.76135
64.38400,5.36527,800.55548,-0.13576,17.33537,38.73125
64.58400,5.38201,799.79599,-0.13576,17.40233,38.69450
64.78400,5.39875,799.15505,-0.13576,17.46929,38.66349
64.98400,5.41537,798.55034,-0.13576,17.53578,38.63424
65.18400,5.43193,797.94955,-0.13576,17.60203,38.60517
65.38400,5.44868,797.76831,-0.13576,17.66899,38.59640
65.58400,5.46530,796.78409,-0.13576,17.73548,38.54878
65.78401,5.48204,795.67032,-0.13576,17.80244,38.49490
65.98400,5.49866,795.84895,-0.13576,17.86893,38.50354
66.18401,5.51528,794.66123,-0.13576,17.93541,38.44608
66.38400,5.53196,793.84847,-0.13576,18.00214,38.40676
66.58400,5.54864,793.16683,-0.13576,18.06886,38.37378
66.78401,5.56539,792.74708,-0.13576,18.13583,38.35347
66.98400,5.58207,791.48458,-0.13576,18.20255,38.29239
67.18401,5.59863,791.20332,-0.13576,18.26880,38.27879
67.38400,5.61531,791.02153,-0.13576,18.33553,38.26999
67.58400,5.63193,790.01812,-0.13576,18.40201,38.22144
67.78401,5.64867,789.24084,-0.13576,18.46898,38.18384
67.98400,5.66535,788.43180,-0.13576,18.53570,38.14470
68.18401,5.68197,787.88148,-0.13576,18.60219,38.11807
68.38400,5.69860,786.90564,-0.13576,18.66867,38.07086
68.58400,5.71528,786.53302,-0.13576,18.73540,38.05283
68.78401,5.73202,785.87756,-0.13576,18.80236,38.02112
68.98400,5.74870,785.10242,-0.13576,18.86909,37.98362
69.18401,5.76532,784.82525,-0.13576,18.93557,37.97021
69.38400,5.78206,783.75675,-0.13576,19.00254,37.91851
69.58400,5.79862,782.74356,-0.13576,19.06878,37.86950
69.78401,5.81537,782.21289,-0.13576,19.13575,37.84382
69.98400,5.83211,782.45914,-0.13577,19.20271,37.85574
70.18401,5.84867,781.10052,-0.13576,19.26896,37.79000
70.38400,5.86529,780.32413,-0.13576,19.33544,37.75244
70.58400,5.88197,780.11472,-0.13577,19.40217,37.74231
70.78401,5.89865,778.83727,-0.13577,19.46890,37.68051
70.98400,5.91527,778.09989,-0.13576,19.53538,37.64483
71.18401,5.93201,777.63791,-0.13576,19.60234,37.62248
71.38400,5.94876,777.14017,-0.13576,19.66931,37.59840
71.58400,5.96526,776.15962,-0.13576,19.73532,37.55096
71.78401,5.98194,775.07044,-0.13576,19.80204,37.49827
71.98400,5.99874,774.89996,-0.13576,19.86925,37.49002
72.18401,6.01536,774.30201,-0.13576,19.93573,37.46109
72.38400,6.03198,773.28105,-0.13576,20.00222,37.41170
72.58400,6.04866,772.87662,-0.13576,20.06894,37.39213
72.78401,6.06534,772.12937,-0.13576,20.13567,37.35598
72.98400,6.08191,771.52648,-0.13576,20.20191,37.32681
73.18401,6.09865,770.54692,-0.13576,20.26888,37.27942
73.38400,6.11545,769.87096,-0.13576,20.33608,37.24672
73.58401,6.13189,768.92292,-0.13576,20.40185,37.20085
73.78401,6.14857,768.28678,-0.13576,20.46857,37.17007
73.98400,6.16531,767.06293,-0.13577,20.53554,37.11086
74.18401,6.18193,766.71592,-0.13577,20.60202,37.09407
74.38400,6.19874,765.92788,-0.13576,20.66923,37.05595
74.58401,6.21542,765.51368,-0.13576,20.73595,37.03591
74.78401,6.23198,764.78808,-0.13576,20.80220,37.00080
74.98400,6.24860,763.52009,-0.13576,20.86869,36.93946
75.18401,6.26534,762.36576,-0.13577,20.93565,36.88361
75.38400,6.28202,762.29088,-0.13576,21.00238,36.87999
75.58401,6.29864,761.50293,-0.13576,21.06886,36.84187
75.78401,6.31527,760.73543,-0.13576,21.13535,36.80473
75.98400,6.33201,760.21063,-0.13576,21.20231,36.77934
76.18401,6.34863,759.06455,-0.13576,21.26880,36.72390
76.38400,6.36525,758.07278,-0.13576,21.33528,36.67591
76.58401,6.38211,757.72852,-0.13576,21.40273,36.65926
76.78401,6.39867,756.68483,-0.13576,21.46897,36.60876
76.98400,6.41529,756.43794,-0.13576,21.53546,36.59682
77.18401,6.43209,755.13972,-0.13576,21.60266,36.53401
77.38400,6.44871,754.55867,-0.13576,21.66915,36.50590
77.58401,6.46528,753.45770,-0.13576,21.73540,36.45263
77.78401,6.48202,752.44647,-0.13577,21.80236,36.40371
77.98400,6.49876,752.25295,-0.13576,21.86932,36.39435
78.18401,6.51526,751.47641,-0.13576,21.93533,36.35678
78.38400,6.53200,750.16222,-0.13576,22.00230,36.29320
78.58401,6.54880,749.47653,-0.13576,22.06950,36.26002
78.78401,6.56530,748.94107,-0.13576,22.13551,36.23412
78.98400,6.58187,747.92719,-0.13576,22.20175,36.18506
79.18401,6.59867,747.14031,-0.13576,22.26896,36.14700
79.38400,6.61535,746.79758,-0.13576,22.33568,36.13041
79.58401,6.63191,745.21452,-0.13576,22.40193,36.05383
79.78401,6.64865,744.12487,-0.13577,22.46889,36.00111
79.98400,6.66527,743.87402,-0.13576,22.53538,35.98897
80.18401,6.68195,742.46880,-0.13576,22.60210,35.92099
80.38400,6.69864,742.38139,-0.13576,22.66883,35.91676
80.58401,6.71538,740.82548,-0.13577,22.73579,35.84148
80.78401,6.73200,739.94263,-0.13576,22.80228,35.79877
80.98400,6.74868,739.08833,-0.13577,22.86900,35.75743
81.18401,6.76530,738.47207,-0.13576,22.93549,35.72762
81.38400,6.78198,738.18350,-0.13577,23.00221,35.71366
81.58401,6.79860,737.35481,-0.13576,23.06870,35.67357
81.78401,6.81528,735.81291,-0.13577,23.13543,35.59897
81.98400,6.83203,734.81216,-0.13577,23.20239,35.55055
82.18401,6.84865,733.76670,-0.13576,23.26888,35.49997
82.38400,6.86533,733.18379,-0.13576,23.33560,35.47177
82.58401,6.88201,731.60995,-0.13577,23.40233,35.39563
82.78401,6.89869,731.66890,-0.13577,23.46905,35.39848
82.98400,6.91537,730.74764,-0.13576,23.53578,35.35391
83.18401,6.93205,729.73757,-0.13577,23.60250,35.30504
83.38400,6.94862,728.67498,-0.13576,23.66875,35.25364
83.58401,6.96530,727.85667,-0.13576,23.73547,35.21404
83.78401,6.98198,726.15617,-0.13577,23.80220,35.13177
83.98400,6.99866,725.90024,-0.13577,23.86892,35.11939
84.18401,7.01534,724.91099,-0.13576,23.93565,35.07153
84.38400,7.03202,724.19280,-0.13576,24.00237,35.03679
84.58401,7.04870,723.46688,-0.13577,24.06910,35.00166
84.78401,7.06526,722.21295,-0.13576,24.13535,34.94100
84.98400,7.08195,720.59585,-0.13576,24.20207,34.86276
85.18401,7.09881,720.48781,-0.13577,24.26951,34.85754
85.38400,7.11531,719.14145,-0.13576,24.33552,34.79240
85.58401,7.13193,718.09669,-0.13577,24.40201,34.74185
85.78401,7.14873,716.70059,-0.13576,24.46921,34.67431
85.98400,7.16535,716.65309,-0.13577,24.53570,34.67201
86.18401,7.18197,716.16448,-0.13576,24.60218,34.64837
86.38400,7.19865,714.45587,-0.13576,24.66891,34.56571
86.58401,7.21534,713.56362,-0.13577,24.73563,34.52254
86.78401,7.23190,712.23071,-0.13577,24.80188,34.45805
86.98400,7.24864,711.77725,-0.13576,24.86884,34.43612
87.18401,7.26538,710.04736,-0.13577,24.93581,34.35242
87.38400,7.28200,709.09234,-0.13577,25.00229,34.30622
87.58401,7.29868,708.42896,-0.13577,25.06902,34.27412
87.78401,7.31536,706.95849,-0.13577,25.13574,34.20298
87.98400,7.33199,705.72500,-0.13576,25.20223,34.14330
88.18401,7.34873,704.60956,-0.13577,25.26919,34.08934
88.38400,7.36535,703.30361,-0.13577,25.33568,34.02615
88.58401,7.38203,702.67199,-0.13577,25.40241,33.99560
88.78401,7.39865,701.60963,-0.13577,25.46889,33.94420
88.98400,7.41533,699.94959,-0.13576,25.53562,33.86389
89.18401,7.43201,699.26353,-0.13576,25.60234,33.83069
89.38400,7.44869,698.06203,-0.13577,25.66907,33.77256
89.58401,7.46532,697.27907,-0.13577,25.73555,33.73468
89.78401,7.48200,695.75203,-0.13576,25.80228,33.66080
89.98400,7.49868,694.55914,-0.13577,25.86900,33.60309
90.18401,7.51530,693.84733,-0.13576,25.93549,33.56866
90.38400,7.53198,691.94930,-0.13576,26.00221,33.47683
90.58401,7.54872,691.37751,-0.13577,26.06918,33.44917
90.78401,7.56534,689.72046,-0.13577,26.13566,33.36900
90.98400,7.58197,688.55369,-0.13577,26.20215,33.31255
91.18401,7.59865,687.75187,-0.13576,26.26888,33.27375
91.38400,7.61527,686.24825,-0.13577,26.33536,33.20101
91.58401,7.63201,685.21984,-0.13576,26.40232,33.15125
91.78401,7.64875,683.43910,-0.13576,26.46929,33.06510
91.98400,7.66525,682.19812,-0.13577,26.53530,33.00506
92.18401,7.68193,681.22097,-0.13576,26.60202,32.95779
92.38400,7.69873,679.91354,-0.13577,26.66922,32.89453
92.58401,7.71542,679.15041,-0.13576,26.73595,32.85761
92.78401,7.73204,677.96861,-0.13577,26.80244,32.80043
92.98400,7.74866,676.85009,-0.13577,26.86892,32.74632
93.18401,7.76540,676.79090,-0.13576,26.93589,32.74346
93.38400,7.78202,675.16160,-0.13576,27.00237,32.66463
93.58401,7.79864,673.12759,-0.13577,27.06886,32.56623
93.78401,7.81538,672.55963,-0.13577,27.13582,32.53875
93.98400,7.83200,671.30742,-0.13577,27.20231,32.47816
94.18401,7.84869,670.19947,-0.13577,27.26903,32.42456
94.38400,7.86531,669.35057,-0.13576,27.33552,32.38349
94.58401,7.88199,668.40672,-0.13577,27.40224,32.33783
94.78401,7.89867,667.25640,-0.13576,27.46897,32.28217
94.98400,7.91529,665.99478,-0.13577,27.53545,32.22114
95.18401,7.93197,664.91566,-0.13576,27.60218,32.16893
95.38400,7.94859,664.17861,-0.13577,27.66866,32.13327
95.58401,7.96533,663.81176,-0.13577,27.73563,32.11552
95.78401,7.98202,662.07093,-0.13577,27.80235,32.03130
95.98400,7.99870,661.50315,-0.13577,27.86908,32.00383
96.18401,8.01538,660.79274,-0.13577,27.93581,31.96946
96.38400,8.03200,659.67496,-0.13576,28.00229,31.91538
96.58401,8.04868,659.22146,-0.13577,28.06901,31.89344
96.78401,8.06536,658.05633,-0.13577,28.13574,31.83707
96.98400,8.08204,657.13930,-0.13577,28.20247,31.79270
97.18401,8.09873,656.18153,-0.13577,28.26919,31.74637
97.38400,8.11529,656.01966,-0.13576,28.33544,31.73853
97.58401,8.13191,655.44071,-0.13577,28.40192,31.71053
97.78401,8.14871,654.91842,-0.13576,28.46912,31.68526
97.98400,8.16533,654.36871,-0.13577,28.53561,31.65866
98.18401,8.18201,653.38472,-0.13577,28.60234,31.61106
98.38400,8.19869,652.86080,-0.13577,28.66906,31.58571
98.58401,8.21526,652.04287,-0.13577,28.73531,31.54614
98.78401,8.23194,651.70866,-0.13577,28.80203,31.52997
98.98400,8.24874,651.05651,-0.13577,28.86924,31.49841
99.18401,8.26542,651.09595,-0.13577,28.93596,31.50032
99.38400,8.28198,650.52523,-0.13577,29.00221,31.47271
99.58401,8.29866,650.14297,-0.13577,29.06893,31.45422
99.78401,8.31540,649.32597,-0.13577,29.13590,31.41469
99.98400,8.33197,649.50492,-0.13577,29.20215,31.42335
100.18401,8.34865,648.77905,-0.13577,29.26887,31.38823
100.38400,8.36539,648.62887,-0.13577,29.33584,31.38097
100.58401,8.38201,648.10840,-0.13577,29.40232,31.35579
100.78401,8.39857,647.92787,-0.13577,29.46857,31.34705
100.98400,8.41543,647.79399,-0.13577,29.53601,31.34057
101.18401,8.43205,647.09196,-0.13577,29.60249,31.30661
101.38400,8.44867,648.24470,-0.13577,29.66898,31.36238
101.58401,8.46529,646.79524,-0.13577,29.73547,31.29225
101.78401,8.48198,646.91207,-0.13577,29.80219,31.29791
101.98400,8.49866,647.21280,-0.13577,29.86892,31.31246
102.18401,8.51528,647.18965,-0.13577,29.93540,31.31134
102.38400,8.53202,646.63421,-0.13577,30.00237,31.28446
102.58401,8.54852,646.64991,-0.13576,30.06837,31.28522
102.78401,8.56526,646.66676,-0.13577,30.13534,31.28604
102.98400,8.58200,646.17209,-0.13576,30.20231,31.26211
103.18401,8.59869,645.87290,-0.13577,30.26903,31.24763
103.38400,8.61537,646.34588,-0.13577,30.33575,31.27051
103.58401,8.63205,645.85027,-0.13577,30.40248,31.24654
103.78401,8.64867,646.48800,-0.13577,30.46896,31.27739
103.98400,8.66529,646.36311,-0.13577,30.53545,31.27135
104.18401,8.68203,646.30797,-0.13576,30.60242,31.26868
104.38400,8.69871,645.89623,-0.13577,30.66914,31.24876
104.58401,8.71527,646.03738,-0.13577,30.73539,31.25559
104.78401,8.73190,645.77470,-0.13577,30.80187,31.24288
104.98401,8.74870,646.30941,-0.13577,30.86908,31.26875
105.18401,8.76526,646.58904,-0.13577,30.93532,31.28228
105.38400,8.78200,646.06736,-0.13576,31.00229,31.25704
105.58401,8.79874,646.11970,-0.13577,31.06925,31.25957
105.78401,8.81530,645.78396,-0.13577,31.13550,31.24333
105.98401,8.83192,646.34425,-0.13576,31.20198,31.27044
106.18401,8.84867,646.31901,-0.13577,31.26895,31.26921
106.38400,8.86541,646.68120,-0.13577,31.33591,31.28674
106.58401,8.88203,646.28748,-0.13577,31.40240,31.26769
106.78401,8.89865,646.40339,-0.13577,31.46889,31.27330
106.98401,8.91539,646.81871,-0.13577,31.53585,31.29339
107.18401,8.93195,646.93652,-0.13577,31.60209,31.29909
107.38400,8.94863,646.76688,-0.13577,31.66882,31.29088
107.58401,8.96543,647.17089,-0.13577,31.73603,31.31043
107.78401,8.98200,647.17177,-0.13577,31.80227,31.31047
107.98401,8.99856,646.49316,-0.13576,31.86851,31.27764
108.18401,9.01536,647.09540,-0.13577,31.93572,31.30678
108.38400,9.03204,647.25685,-0.13577,32.00245,31.31459
108.58401,9.04872,647.01820,-0.13577,32.06917,31.30304
108.78401,9.06534,647.10858,-0.13577,32.13566,31.30741
108.98401,9.08202,647.27264,-0.13577,32.20238,31.31535
109.18401,9.09859,646.91543,-0.13577,32.26863,31.29807
109.38400,9.11533,647.23869,-0.13577,32.33559,31.31371
109.58401,9.13201,647.70398,-0.13577,32.40232,31.33622
109.78401,9.14863,647.03799,-0.13577,32.46880,31.30400
109.98401,9.16531,647.17452,-0.13577,32.53553,31.31060
110.18401,9.18193,647.41760,-0.13576,32.60202,31.32236
110.38400,9.19861,648.02412,-0.13577,32.66874,31.35171
110.58401,9.21529,646.86062,-0.13577,32.73546,31.29542
110.78401,9.23198,647.43357,-0.13577,32.80219,31.32314
110.98401,9.24878,647.33461,-0.13577,32.86939,31.31835
111.18401,9.26534,647.29797,-0.13577,32.93564,31.31658
111.38400,9.28202,647.75324,-0.13576,33.00237,31.33860
111.58401,9.29870,647.32763,-0.13577,33.06909,31.31801
111.78401,9.31538,647.75255,-0.13577,33.13581,31.33857
111.98401,9.33206,647.91795,-0.13577,33.20254,31.34657
112.18401,9.34869,647.15701,-0.13577,33.26903,31.30976
112.38400,9.36531,647.51711,-0.13577,33.33551,31.32718
112.58401,9.38199,647.70565,-0.13577,33.40224,31.33630
112.78401,9.39867,648.04964,-0.13577,33.46896,31.35294
112.98401,9.41535,647.62593,-0.13577,33.53569,31.33244
113.18401,9.43197,648.66911,-0.13577,33.60217,31.38291
113.38400,9.44865,647.93364,-0.13577,33.66890,31.34733
113.58401,9.46539,648.04633,-0.13577,33.73586,31.35278
113.78401,9.48196,648.39921,-0.13577,33.80211,31.36985
113.98401,9.49870,648.03432,-0.13577,33.86908,31.35220
114.18401,9.51538,648.75814,-0.13577,33.93580,31.38722
114.38400,9.53200,648.24480,-0.13577,34.00228,31.36238
114.58401,9.54862,647.78510,-0.13577,34.06878,31.34014
114.78401,9.56530,648.90450,-0.13577,34.13550,31.39430
114.98401,9.58204,648.11395,-0.13577,34.20246,31.35605
115.18401,9.59867,648.33066,-0.13577,34.26895,31.36654
115.38400,9.61529,648.36359,-0.13577,34.33543,31.36813
115.58401,9.63197,648.32401,-0.13577,34.40216,31.36622
115.78401,9.64859,648.33211,-0.13576,34.46864,31.36661
115.98401,9.66527,649.10026,-0.13577,34.53537,31.40377
116.18401,9.68201,648.87414,-0.13577,34.60233,31.39283
116.38400,9.69863,649.54427,-0.13576,34.66882,31.42525
116.58401,9.71531,649.00820,-0.13577,34.73555,31.39932
116.78401,9.73199,648.62049,-0.13577,34.80227,31.38056
116.98401,9.74868,648.79218,-0.13576,34.86899,31.38887
117.18401,9.76536,648.72173,-0.13577,34.93572,31.38546
117.38400,9.78204,649.00513,-0.13577,35.00244,31.39917
117.58401,9.79872,648.89994,-0.13577,35.06917,31.39408
117.78401,9.81528,649.06627,-0.13577,35.13542,31.40213
117.98401,9.83196,649.01491,-0.13577,35.20214,31.39964
118.18401,9.84864,648.49453,-0.13577,35.26886,31.37447
118.38400,9.86527,649.58697,-0.13577,35.33535,31.42732
118.58401,9.88201,649.42124,-0.13577,35.40231,31.41930
118.78401,9.89863,649.74013,-0.13577,35.46880,31.43473
118.98401,9.91531,649.33663,-0.13577,35.53553,31.41521
119.18401,9.93199,649.67670,-0.13577,35.60225,31.43166
119.38400,9.94867,649.46711,-0.13577,35.66898,31.42152
119.58401,9.96535,649.83391,-0.13577,35.73570,31.43927
119.78401,9.98203,649.53398,-0.13577,35.80242,31.42476
119.98401,9.99866,650.05310,-0.13577,35.86892,31.44987
120.18401,10.01540,649.96318,-0.13577,35.93588,31.44552
120.38400,10.03202,649.89235,-0.13577,36.00236,31.44209
120.58401,10.04870,649.86758,-0.13577,36.06909,31.44090
120.78401,10.06532,650.33613,-0.13577,36.13557,31.46356
120.98401,10.08194,650.03070,-0.13577,36.20206,31.44879
121.18401,10.09856,649.80178,-0.13577,36.26855,31.43771
121.38400,10.11531,649.94371,-0.13577,36.33551,31.44458
121.58401,10.13211,650.03838,-0.13577,36.40271,31.44916
121.78401,10.14867,649.67885,-0.13577,36.46896,31.43176
121.98401,10.16535,650.14069,-0.13576,36.53569,31.45411
122.18401,10.18203,650.47015,-0.13577,36.60241,31.47005
122.38400,10.19865,649.85626,-0.13577,36.66890,31.44035
122.58401,10.21533,650.65310,-0.13577,36.73562,31.47890
122.78401,10.23207,650.23908,-0.13577,36.80258,31.45887
122.98401,10.24864,650.27415,-0.13577,36.86883,31.46057
123.18401,10.26532,649.86269,-0.13577,36.93556,31.44066
123.38400,10.28200,650.07671,-0.13577,37.00228,31.45101
123.58401,10.29868,649.99945,-0.13577,37.06901,31.44728
123.78401,10.31530,650.05869,-0.13577,37.13550,31.45014
123.98401,10.33198,650.08886,-0.13577,37.20222,31.45160
124.18401,10.34860,649.73119,-0.13577,37.26870,31.43430
124.38400,10.36529,650.38200,-0.13577,37.33543,31.46578
124.58401,10.38197,650.14414,-0.13577,37.40215,31.45428
124.78401,10.39871,650.49273,-0.13577,37.46912,31.47114
124.98401,10.41539,650.23056,-0.13577,37.53584,31.45846
125.18401,10.43195,650.72631,-0.13576,37.60209,31.48244
125.38400,10.44857,650.05585,-0.13577,37.66858,31.45000
125.58401,10.46525,649.75829,-0.13577,37.73530,31.43561
125.78401,10.48199,649.80797,-0.13577,37.80227,31.43801
125.98401,10.49868,650.26758,-0.13577,37.86899,31.46025
126.18401,10.51536,649.74749,-0.13577,37.93572,31.43509
126.38400,10.53192,650.13450,-0.13576,38.00196,31.45381
126.58401,10.54860,649.73757,-0.13577,38.06868,31.43460
126.78401,10.56540,650.17119,-0.13577,38.13589,31.45558
126.98401,10.58202,649.38646,-0.13577,38.20238,31.41762
127.18401,10.59864,649.26152,-0.13577,38.26886,31.41157
127.38400,10.61538,649.48178,-0.13577,38.33583,31.42223
127.58401,10.63195,649.60369,-0.13577,38.40207,31.42813
127.78401,10.64863,649.32806,-0.13577,38.46880,31.41479
127.98401,10.66537,648.61178,-0.13577,38.53576,31.38014
128.18401,10.68205,649.25598,-0.13577,38.60249,31.41131
128.38400,10.69861,649.25207,-0.13578,38.66873,31.41112
128.58400,10.71523,648.75591,-0.13578,38.73522,31.38711
128.78402,10.73203,647.82547,-0.13579,38.80242,31.34210
128.98401,10.74872,648.37020,-0.13578,38.86915,31.36845
129.18401,10.76528,648.32722,-0.13578,38.93540,31.36637
129.38400,10.78202,648.33327,-0.13578,39.00236,31.36666
129.58400,10.79858,648.36750,-0.13578,39.06860,31.36832
129.78402,10.81532,647.58160,-0.13578,39.13557,31.33030
129.98401,10.83206,648.52680,-0.13577,39.20254,31.37603
130.18401,10.84874,647.35832,-0.13579,39.26926,31.31950
130.38400,10.86536,647.11669,-0.13578,39.33575,31.30781
130.58400,10.88199,647.38048,-0.13578,39.40223,31.32057
130.78402,10.89867,647.83078,-0.13578,39.46896,31.34235
130.98401,10.91529,647.16074,-0.13578,39.53544,31.30994
131.18400,10.93203,647.38421,-0.13578,39.60241,31.32075
131.38400,10.94865,646.10234,-0.13578,39.66889,31.25873
131.58400,10.96521,646.75538,-0.13579,39.73514,31.29033
131.78402,10.98195,646.91398,-0.13577,39.80210,31.29800
131.98402,10.99869,646.97498,-0.13577,39.86907,31.30095
132.18400,11.01538,646.58448,-0.13577,39.93580,31.28206
132.38400,11.03206,646.44683,-0.13577,40.00252,31.27540
132.58400,11.04862,645.53814,-0.13577,40.06877,31.23143
132.78402,11.06530,645.94196,-0.13577,40.13549,31.25097
132.98402,11.08198,645.73134,-0.13577,40.20222,31.24078
133.18400,11.09866,645.50363,-0.13577,40.26894,31.22976
133.38400,11.11546,645.55900,-0.13577,40.33614,31.23244
133.58400,11.13197,644.84691,-0.13577,40.40215,31.19799
133.78402,11.14859,645.05278,-0.13577,40.46864,31.20795
133.98402,11.16533,644.71522,-0.13578,40.53560,31.19162
134.18400,11.18195,644.14707,-0.13577,40.60209,31.16413
134.38400,11.19863,644.45892,-0.13577,40.66881,31.17922
134.58400,11.21537,644.45473,-0.13577,40.73578,31.17902
134.78402,11.23205,643.46660,-0.13577,40.80250,31.13121
134.98402,11.24862,644.27899,-0.13577,40.86875,31.17052
135.18400,11.26530,642.94757,-0.13577,40.93548,31.10610
135.38400,11.28216,642.85127,-0.13577,41.00291,31.10144
135.58400,11.29866,642.87474,-0.13577,41.06892,31.10258
135.78402,11.31528,642.50454,-0.13577,41.13541,31.08467
135.98402,11.33202,642.27600,-0.13577,41.20238,31.07361
136.18400,11.34864,642.03502,-0.13577,41.26886,31.06195
136.38400,11.36533,641.78579,-0.13577,41.33559,31.04989
136.58400,11.38207,641.29406,-0.13577,41.40255,31.02610
136.78402,11.39863,640.92563,-0.13577,41.46880,31.00828
136.98402,11.41525,640.83585,-0.13577,41.53528,31.00393
137.18400,11.43199,639.95929,-0.13577,41.60225,30.96153
137.38400,11.44873,639.78699,-0.13577,41.66921,30.95319
137.58400,11.46535,638.97390,-0.13577,41.73570,30.91385
137.78402,11.48197,638.51397,-0.13577,41.80219,30.89160
137.98402,11.49872,637.61706,-0.13577,41.86915,30.84821
138.18400,11.51534,637.32080,-0.13577,41.93563,30.83388
138.38400,11.53190,636.63595,-0.13577,42.00188,30.80074
138.58400,11.54864,635.29150,-0.13577,42.06884,30.73570
138.78402,11.56532,634.79454,-0.13577,42.13557,30.71165
138.98402,11.58194,633.84869,-0.13577,42.20206,30.66589
139.18400,11.59856,633.25400,-0.13577,42.26854,30.63712
139.38400,11.61536,631.45990,-0.13577,42.33575,30.55032
139.58400,11.63199,631.01188,-0.13577,42.40223,30.52865
139.78402,11.64867,629.82845,-0.13577,42.46896,30.47139
139.98402,11.66541,628.61536,-0.13577,42.53592,30.41270
140.18400,11.68197,627.17106,-0.13577,42.60217,30.34283
140.38400,11.69865,626.28887,-0.13577,42.66889,30.30015
140.58400,11.71539,624.13807,-0.13577,42.73585,30.19609
140.78402,11.73207,622.73275,-0.13577,42.80258,30.12810
140.98402,11.74863,620.29017,-0.13577,42.86883,30.00993
141.18400,11.76532,618.22520,-0.13577,42.93555,29.91002
141.38400,11.78206,615.62778,-0.13577,43.00252,29.78436
141.58400,11.79856,612.79936,-0.13577,43.06852,29.64752
141.78402,11.81530,609.63756,-0.13577,43.13549,29.49455
141.98402,11.83210,607.00304,-0.13577,43.20269,29.36709
142.18400,11.84860,603.15593,-0.13577,43.26870,29.18096
142.38400,11.86522,600.16504,-0.13577,43.33518,29.03626
142.58400,11.88208,595.24216,-0.13577,43.40263,28.79809
142.78402,11.89871,589.44239,-0.13577,43.46911,28.51750
142.98402,11.91527,582.59950,-0.13577,43.53536,28.18643
143.18400,11.93201,572.75770,-0.13577,43.60233,27.71028
143.38400,11.94875,534.37981,-0.13577,43.66929,25.85354
143.58400,11.96531,371.75838,-0.13577,43.73553,17.98584
143.65202,11.97111,9.45112,-0.13577,43.75874,0.45725