File: Manufatura Aditiva/Classificação Direção/Ensaios/Ensaios SLS/Tracao_OLABI_07_06_2018_SLS_YX5.is_metal_RawData/Specimen_RawData_5.csv
Time,Extension,Load,Strain 1,Tensile strain,Tensile stress
(sec),(mm),(N),(mm/mm),(%),(MPa)
0.00000,0.00006,29.77737,0.00134,0.13367,1.49008
0.20000,0.01381,35.71464,0.00152,0.15195,1.78718
0.40000,0.03270,45.45448,0.00183,0.18304,2.27457
0.60000,0.04986,54.57543,0.00211,0.21060,2.73098
0.80000,0.06673,62.15476,0.00238,0.23799,3.11026
1.00000,0.08335,70.12399,0.00265,0.26537,3.50904
1.20000,0.10003,78.28440,0.00293,0.29276,3.91739
1.40000,0.11683,86.21528,0.00320,0.32027,4.31426
1.60000,0.13339,93.44575,0.00347,0.34706,4.67607
1.80000,0.14995,101.16610,0.00374,0.37434,5.06241
2.00000,0.16657,108.87637,0.00402,0.40206,5.44823
2.20000,0.18331,115.76207,0.00429,0.42931,5.79280
2.40000,0.19994,123.28383,0.00457,0.45653,6.16919
2.60000,0.21668,130.79752,0.00485,0.48473,6.54518
2.80000,0.23336,137.19340,0.00511,0.51150,6.86523
3.00000,0.24998,145.02590,0.00539,0.53913,7.25717
3.20000,0.26672,151.82717,0.00567,0.56652,7.59751
3.40000,0.28340,159.38889,0.00595,0.59469,7.97590
3.60000,0.30002,165.87581,0.00622,0.62167,8.30051
3.80000,0.31665,172.85132,0.00649,0.64892,8.64957
4.00000,0.33327,179.41502,0.00677,0.67696,8.97802
4.20000,0.34995,186.71749,0.00704,0.70440,9.34344
4.40000,0.36657,193.59317,0.00732,0.73162,9.68751
4.60000,0.38331,200.64393,0.00759,0.75948,10.04033
4.80000,0.39999,206.40190,0.00786,0.78625,10.32846
5.00000,0.41661,212.44786,0.00809,0.80913,10.63100
5.20000,0.43335,218.61291,0.00836,0.83614,10.93951
5.40000,0.45010,225.64221,0.00864,0.86414,11.29126
5.60000,0.46666,231.74309,0.00892,0.89202,11.59655
5.80000,0.48334,238.66470,0.00920,0.91952,11.94291
6.00000,0.50002,245.13411,0.00948,0.94751,12.26664
6.20000,0.51664,251.75933,0.00975,0.97497,12.59817
6.40000,0.53326,258.72488,0.01003,1.00294,12.94673
6.60000,0.55000,264.87391,0.01031,1.03070,13.25443
6.80000,0.56674,271.34484,0.01058,1.05828,13.57824
7.00000,0.58331,277.22917,0.01086,1.08633,13.87269
7.20000,0.59993,283.88761,0.01114,1.11362,14.20589
7.40000,0.61673,289.64677,0.01141,1.14126,14.49408
7.60000,0.63329,296.30389,0.01169,1.16920,14.82720
7.80000,0.64997,302.12207,0.01198,1.19762,15.11835
8.00000,0.66671,308.29816,0.01226,1.22611,15.42740
8.20000,0.68333,314.04078,0.01254,1.25354,15.71477
8.40000,0.70002,320.37315,0.01282,1.28199,16.03164
8.60000,0.71664,326.32526,0.01310,1.31033,16.32949
8.80000,0.73344,331.16045,0.01337,1.33684,16.57145
9.00000,0.75000,336.77099,0.01364,1.36446,16.85220
9.20000,0.76662,342.56584,0.01393,1.39332,17.14218
9.40000,0.78342,348.24186,0.01422,1.42194,17.42621
9.60000,0.79992,354.00607,0.01450,1.45011,17.71465
9.80000,0.81666,357.97514,0.01473,1.47338,17.91327
10.00000,0.83341,363.04742,0.01501,1.50089,18.16709
10.20000,0.84991,367.83561,0.01529,1.52912,18.40669
10.40000,0.86665,373.60261,0.01558,1.55777,18.69527
10.60000,0.88333,379.15735,0.01587,1.58671,18.97324
10.80000,0.90007,383.91496,0.01616,1.61570,19.21131
11.00000,0.91669,388.75656,0.01645,1.64475,19.45358
11.20000,0.93331,393.96756,0.01674,1.67354,19.71435
11.40000,0.95000,398.94879,0.01703,1.70319,19.96361
11.60000,0.96656,404.37910,0.01733,1.73274,20.23535
11.80000,0.98330,408.77084,0.01762,1.76197,20.45511
12.00000,1.00010,414.16553,0.01791,1.79135,20.72506
12.20000,1.01666,418.81450,0.01821,1.82119,20.95770
12.40000,1.03328,423.04480,0.01851,1.85091,21.16939
12.60000,1.04996,428.16475,0.01881,1.88082,21.42559
12.80000,1.06664,432.51845,0.01910,1.91019,21.64345
13.00000,1.08333,436.39671,0.01941,1.94067,21.83752
13.20000,1.10001,441.58371,0.01970,1.97036,22.09708
13.40000,1.11675,446.03031,0.02001,2.00099,22.31960
13.60000,1.13319,450.54480,0.02032,2.03165,22.54550
13.80000,1.14993,454.57832,0.02061,2.06134,22.74734
14.00000,1.16673,458.83846,0.02093,2.09258,22.96052
14.20000,1.18329,462.23039,0.02124,2.12362,23.13025
14.40000,1.19998,466.88505,0.02155,2.15515,23.36318
14.60000,1.21672,471.15874,0.02186,2.18599,23.57703
14.80000,1.23334,473.35606,0.02210,2.20972,23.68699
15.00000,1.24990,477.26752,0.02242,2.24156,23.88272
15.20000,1.26670,481.05959,0.02273,2.27273,24.07248
15.40000,1.28344,484.55843,0.02304,2.30375,24.24756
15.60000,1.29988,488.92288,0.02335,2.33524,24.46596
15.80000,1.31656,492.88771,0.02367,2.36702,24.66436
16.00000,1.33343,496.16168,0.02399,2.39910,24.82820
16.20000,1.34993,499.83687,0.02431,2.43068,25.01210
16.40000,1.36667,503.40723,0.02463,2.46275,25.19077
16.60000,1.38341,506.50323,0.02494,2.49358,25.34569
16.80000,1.39997,510.43038,0.02526,2.52616,25.54221
17.00000,1.41659,513.50361,0.02558,2.55831,25.69599
17.20000,1.43333,516.51895,0.02591,2.59102,25.84688
17.40000,1.45001,519.51809,0.02623,2.62330,25.99696
17.60000,1.46664,523.17139,0.02656,2.65615,26.17978
17.80000,1.48320,526.56238,0.02689,2.68865,26.34946
18.00000,1.50006,529.22079,0.02721,2.72147,26.48249
18.20000,1.51656,532.53663,0.02755,2.75491,26.64842
18.40000,1.53336,535.08831,0.02788,2.78791,26.77610
18.60000,1.55004,538.65435,0.02821,2.82107,26.95455
18.80000,1.56666,541.41278,0.02855,2.85455,27.09258
19.00000,1.58335,544.35185,0.02888,2.88820,27.23966
19.20000,1.60003,546.66959,0.02922,2.92173,27.35564
19.40000,1.61671,549.71217,0.02955,2.95536,27.50789
19.60000,1.63333,552.22781,0.02989,2.98930,27.63377
19.80000,1.65001,555.23678,0.03023,3.02286,27.78434
20.00000,1.66663,558.57669,0.03057,3.05713,27.95148
20.20000,1.68325,560.15174,0.03091,3.10698,28.03029
20.40000,1.69993,563.02832,0.03124,3.17371,28.17424
20.53200,1.71100,564.92048,0.03147,3.21795,28.26892
20.73200,1.72762,567.43133,0.03181,3.28444,28.39457
20.93200,1.74436,569.91414,0.03215,3.35140,28.51881
21.13200,1.76098,572.23192,0.03249,3.41789,28.63479
21.33200,1.77760,573.16488,0.03277,3.48437,28.68148
21.53200,1.79434,575.41206,0.03311,3.55134,28.79393
21.73200,1.81114,578.30727,0.03345,3.61854,28.93880
21.93200,1.82770,580.07985,0.03380,3.68479,29.02751
22.13200,1.84433,582.45659,0.03415,3.75127,29.14644
22.33200,1.86101,585.11132,0.03442,3.81800,29.27928
22.53200,1.87763,587.37053,0.03347,3.88448,29.39233
22.73200,1.89425,590.11881,0.02769,3.95097,29.52986
22.93200,1.91105,591.50499,0.00364,4.01817,29.59922
23.13200,1.92767,594.14711,0.00200,4.08466,29.73144
23.33200,1.94423,596.52640,-0.00049,4.15091,29.85050
23.53200,1.96104,598.12074,0.00005,4.21811,29.93028
23.73200,1.97772,600.11088,0.00427,4.28483,30.02987
23.93200,1.99434,602.22931,0.00530,4.35132,30.13588
24.13200,2.01096,604.45801,0.00482,4.41781,30.24740
24.33200,2.02770,606.55666,0.00022,4.48477,30.35242
24.53200,2.04438,608.48622,-0.01137,4.55150,30.44897
24.73200,2.06100,610.05331,-0.13660,4.61798,30.52739
24.93200,2.07768,612.41114,-0.13634,4.68471,30.64538
25.13200,2.09431,614.12076,-0.13638,4.75119,30.73093
25.33200,2.11093,616.13135,-0.13636,4.81768,30.83154
25.53200,2.12761,618.37835,-0.13636,4.88440,30.94398
25.73200,2.14429,620.00314,-0.13636,4.95113,31.02529
25.93200,2.16103,621.73340,-0.13637,5.01809,31.11187
26.13200,2.17771,623.45224,-0.13637,5.08482,31.19788
26.33200,2.19439,625.48383,-0.13637,5.15154,31.29954
26.53200,2.21102,627.40822,-0.13637,5.21803,31.39584
26.73200,2.22764,628.70472,-0.13637,5.28451,31.46072
26.93200,2.24438,631.25016,-0.13637,5.35148,31.58809
27.13200,2.26100,633.06801,-0.13637,5.41796,31.67906
27.33200,2.27774,634.38113,-0.13637,5.48493,31.74477
27.53200,2.29436,635.86445,-0.13637,5.55141,31.81900
27.73200,2.31098,637.52108,-0.13637,5.61790,31.90190
27.93200,2.32766,639.29958,-0.13637,5.68463,31.99089
28.13200,2.34429,640.84940,-0.13638,5.75111,32.06845
28.33200,2.36097,641.97360,-0.13638,5.81784,32.12470
28.53200,2.37759,643.61673,-0.13638,5.88432,32.20692
28.73200,2.39427,646.39538,-0.13638,5.95105,32.34597
28.93200,2.41101,647.57662,-0.13639,6.01801,32.40508
29.13200,2.42769,648.99125,-0.13638,6.08474,32.47587
29.33200,2.44437,650.61133,-0.13638,6.15146,32.55694
29.53200,2.46106,652.61703,-0.13638,6.21819,32.65730
29.73200,2.47768,653.85806,-0.13638,6.28467,32.71941
29.93200,2.49430,655.21561,-0.13638,6.35116,32.78734
30.13200,2.51098,657.00840,-0.13639,6.41788,32.87705
30.33200,2.52772,658.94006,-0.13639,6.48485,32.97371
30.53200,2.54434,658.24073,-0.13639,6.55133,32.93872
30.73200,2.56084,659.71902,-0.13639,6.61734,33.01269
30.93200,2.57764,661.79535,-0.13639,6.68454,33.11659
31.13200,2.59433,662.68113,-0.13639,6.75127,33.16092
31.33200,2.61095,665.33266,-0.13639,6.81776,33.29360
31.53200,2.62769,666.24554,-0.13639,6.88472,33.33928
31.73200,2.64431,667.88425,-0.13639,6.95121,33.42128
31.93200,2.66099,669.76692,-0.13639,7.01793,33.51549
32.13200,2.67761,670.74061,-0.13639,7.08442,33.56422
32.33200,2.69441,672.72293,-0.13639,7.15162,33.66341
32.53200,2.71103,674.18609,-0.13639,7.21811,33.73663
32.73200,2.72766,675.21208,-0.13639,7.28459,33.78797
32.93200,2.74428,676.32091,-0.13639,7.35108,33.84346
33.13200,2.76096,677.83687,-0.13639,7.41780,33.91932
33.33200,2.77764,678.56694,-0.13639,7.48453,33.95585
33.53200,2.79444,680.20346,-0.13639,7.55173,34.03774
33.73200,2.81100,681.65073,-0.13639,7.61798,34.11016
33.93200,2.82762,683.59901,-0.13639,7.68447,34.20766
34.13200,2.84431,684.46011,-0.13639,7.75119,34.25075
34.33200,2.86099,686.23731,-0.13639,7.81792,34.33968
34.53200,2.87773,687.42000,-0.13639,7.88488,34.39886
34.73200,2.89435,688.62070,-0.13639,7.95136,34.45895
34.93200,2.91103,689.93187,-0.13639,8.01809,34.52456
35.13200,2.92759,690.77015,-0.13639,8.08434,34.56651
35.33200,2.94427,692.53319,-0.13639,8.15106,34.65473
35.53200,2.96107,693.58530,-0.13639,8.21827,34.70738
35.73200,2.97770,694.70797,-0.13639,8.28475,34.76356
35.93200,2.99432,695.42988,-0.13639,8.35124,34.79968
36.13200,3.01106,697.30957,-0.13639,8.41820,34.89374
36.33200,3.02762,698.15111,-0.13639,8.48445,34.93585
36.53200,3.04430,699.64663,-0.13639,8.55117,35.01069
36.73200,3.06104,700.66638,-0.13639,8.61814,35.06172
36.93200,3.07778,701.93047,-0.13639,8.68510,35.12497
37.13200,3.09423,702.88931,-0.13639,8.75087,35.17295
37.33200,3.11097,704.58492,-0.13639,8.81783,35.25780
37.53200,3.12777,705.06944,-0.13639,8.88504,35.28205
37.73200,3.14433,705.90666,-0.13639,8.95128,35.32394
37.93200,3.16101,707.16240,-0.13639,9.01801,35.38678
38.13200,3.17769,708.86607,-0.13639,9.08473,35.47203
38.33200,3.19431,709.62626,-0.13639,9.15122,35.51007
38.53200,3.21088,710.01835,-0.13639,9.21747,35.52970
38.73200,3.22768,711.66139,-0.13639,9.28467,35.61192
38.93200,3.24436,713.10233,-0.13639,9.35140,35.68402
39.13200,3.26098,713.33926,-0.13639,9.41788,35.69588
39.33200,3.27766,713.98560,-0.13639,9.48461,35.72822
39.53200,3.29440,715.60661,-0.13639,9.55157,35.80934
39.73200,3.31096,716.81836,-0.13639,9.61782,35.86997
39.93200,3.32764,717.36472,-0.13639,9.68454,35.89731
40.13200,3.34444,718.29571,-0.13640,9.75175,35.94390
40.33200,3.36101,718.48412,-0.13639,9.81799,35.95333
40.53200,3.37763,720.59757,-0.13639,9.88448,36.05909
40.73200,3.39437,721.11315,-0.13639,9.95144,36.08488
40.93200,3.41105,722.13146,-0.13639,10.01817,36.13584
41.13200,3.42767,722.75167,-0.13639,10.08465,36.16688
41.33200,3.44429,723.69557,-0.13639,10.15114,36.21411
41.53200,3.46097,724.79895,-0.13639,10.21786,36.26933
41.73200,3.47760,725.43593,-0.13639,10.28435,36.30120
41.93200,3.49434,726.53252,-0.13639,10.35132,36.35608
42.13200,3.51114,727.43208,-0.13639,10.41852,36.40109
42.33200,3.52770,728.58366,-0.13639,10.48477,36.45871
42.53200,3.54426,729.37035,-0.13639,10.55101,36.49808
42.73200,3.56100,730.10158,-0.13639,10.61798,36.53467
42.93200,3.57768,731.60022,-0.13639,10.68470,36.60966
43.13200,3.59425,731.82033,-0.13639,10.75095,36.62068
43.33200,3.61105,733.06449,-0.13639,10.81815,36.68294
43.53200,3.62773,733.64517,-0.13640,10.88488,36.71199
43.73200,3.64423,734.27013,-0.13640,10.95088,36.74327
43.93200,3.66103,733.42505,-0.13639,11.01809,36.70098
44.13200,3.67783,734.57323,-0.13639,11.08529,36.75843
44.33200,3.69433,734.47647,-0.13640,11.15130,36.75359
44.53200,3.71095,736.57744,-0.13639,11.21778,36.85873
44.73200,3.72776,737.33618,-0.13640,11.28499,36.89669
44.93200,3.74438,738.17628,-0.13640,11.35147,36.93874
45.13200,3.76088,738.99841,-0.13639,11.41748,36.97987
45.33200,3.77774,739.46719,-0.13640,11.48492,37.00333
45.53200,3.79436,740.35982,-0.13640,11.55141,37.04800
45.73200,3.81092,741.91643,-0.13639,11.61766,37.12589
45.93200,3.82766,741.93212,-0.13640,11.68462,37.12668
46.13200,3.84440,743.09865,-0.13639,11.75158,37.18505
46.33200,3.86097,743.71635,-0.13639,11.81783,37.21596
46.53200,3.87765,744.66476,-0.13640,11.88456,37.26342
46.73200,3.89433,744.94667,-0.13639,11.95128,37.27753
46.93200,3.91095,745.92712,-0.13639,12.01777,37.32659
47.13200,3.92763,747.19717,-0.13639,12.08449,37.39014
47.33200,3.94437,747.60206,-0.13639,12.15146,37.41040
47.53200,3.96099,747.89491,-0.13640,12.21794,37.42506
47.73200,3.97762,748.39615,-0.13640,12.28443,37.45014
47.93200,3.99430,749.36491,-0.13640,12.35115,37.49862
48.13200,4.01104,749.83831,-0.13639,12.41812,37.52231
48.33200,4.02766,750.61605,-0.13640,12.48460,37.56123
48.53200,4.04428,751.52791,-0.13640,12.55109,37.60686
48.73200,4.06108,752.50333,-0.13639,12.61829,37.65567
48.93200,4.07764,751.93620,-0.13640,12.68454,37.62729
49.13200,4.09426,753.54706,-0.13639,12.75102,37.70790
49.33200,4.11101,753.84220,-0.13639,12.81799,37.72266
49.53200,4.12769,754.64565,-0.13640,12.88471,37.76287
49.73200,4.14431,754.67341,-0.13639,12.95120,37.76426
49.93200,4.16099,756.45163,-0.13639,13.01793,37.85324
50.13200,4.17767,755.88091,-0.13639,13.08465,37.82468
50.33200,4.19423,757.15617,-0.13639,13.15090,37.88850
50.53200,4.21097,757.33513,-0.13639,13.21786,37.89745
50.73200,4.22777,758.18198,-0.13640,13.28507,37.93983
50.93200,4.24428,759.21719,-0.13639,13.35107,37.99163
51.13200,4.26096,759.40466,-0.13640,13.41780,38.00101
51.33200,4.27776,759.49188,-0.13639,13.48500,38.00538
51.53200,4.29432,760.44286,-0.13640,13.55125,38.05297
51.73200,4.31094,760.52109,-0.13640,13.61773,38.05688
51.93200,4.32768,761.34093,-0.13640,13.68470,38.09790
52.13200,4.34436,761.67714,-0.13640,13.75142,38.11473
52.33200,4.36099,761.99444,-0.13640,13.81791,38.13061
52.53200,4.37761,762.99547,-0.13639,13.88440,38.18070
52.73200,4.39441,762.99845,-0.13639,13.95160,38.18085
52.93200,4.41103,764.23716,-0.13640,14.01809,38.24284
53.13200,4.42765,764.33984,-0.13639,14.08457,38.24797
53.33200,4.44433,765.13742,-0.13639,14.15130,38.28788
53.53200,4.46095,765.47964,-0.13640,14.21778,38.30501
53.73200,4.47764,766.17477,-0.13639,14.28451,38.33979
53.93200,4.49432,765.84769,-0.13640,14.35123,38.32343
54.13200,4.51100,766.94335,-0.13639,14.41796,38.37825
54.33200,4.52762,767.36156,-0.13640,14.48444,38.39918
54.53200,4.54430,767.61828,-0.13639,14.55117,38.41203
54.73200,4.56098,768.19616,-0.13640,14.61789,38.44094
54.93200,4.57766,768.55565,-0.13640,14.68462,38.45893
55.13200,4.59440,769.18192,-0.13640,14.75158,38.49027
55.33200,4.61103,769.85601,-0.13640,14.81807,38.52401
55.53200,4.62765,770.26864,-0.13640,14.88456,38.54465
55.73200,4.64433,771.11726,-0.13640,14.95128,38.58712
55.93200,4.66101,771.29561,-0.13640,15.01800,38.59604
56.13200,4.67781,771.65389,-0.13640,15.08521,38.61397
56.33200,4.69437,771.45770,-0.13640,15.15145,38.60415
56.53200,4.71093,772.20257,-0.13640,15.21770,38.64143
56.73200,4.72767,772.99285,-0.13639,15.28467,38.68097
56.93200,4.74424,772.39992,-0.13640,15.35091,38.65130
57.13200,4.76098,773.51718,-0.13640,15.41788,38.70721
57.33200,4.77772,774.21055,-0.13640,15.48484,38.74191
57.53200,4.79428,774.44278,-0.13640,15.55109,38.75353
57.73200,4.81096,774.85377,-0.13639,15.61781,38.77409
57.93200,4.82770,775.34835,-0.13640,15.68478,38.79884
58.13200,4.84438,775.49885,-0.13640,15.75150,38.80638
58.33200,4.86101,775.77159,-0.13640,15.81799,38.82002
58.53200,4.87769,776.14379,-0.13640,15.88471,38.83865
58.73200,4.89437,776.86170,-0.13640,15.95144,38.87457
58.93200,4.91093,777.46869,-0.13640,16.01769,38.90495
59.13200,4.92767,776.84000,-0.13640,16.08465,38.87349
59.33200,4.94441,777.58501,-0.13640,16.15161,38.91077
59.53200,4.96097,777.81496,-0.13640,16.21786,38.92228
59.73200,4.97759,778.78372,-0.13640,16.28435,38.97075
59.93200,4.99434,778.75704,-0.13640,16.35131,38.96942
60.13200,5.01096,778.81371,-0.13640,16.41780,38.97225
60.33200,5.02776,779.34372,-0.13640,16.48500,38.99878
60.53200,5.04432,779.40412,-0.13640,16.55125,39.00180
60.73200,5.06100,780.70164,-0.13640,16.61797,39.06673
60.93200,5.07762,780.32333,-0.13640,16.68446,39.04779
61.13200,5.09424,780.18066,-0.13640,16.75094,39.04066
61.33200,5.11104,780.39290,-0.13640,16.81815,39.05128
61.53200,5.12767,780.93917,-0.13640,16.88463,39.07861
61.73200,5.14429,781.40181,-0.13640,16.95112,39.10176
61.93200,5.16097,781.40330,-0.13640,17.01784,39.10184
62.13200,5.17765,781.94411,-0.13640,17.08457,39.12890
62.33200,5.19427,782.31925,-0.13640,17.15105,39.14767
62.53200,5.21101,783.23120,-0.13640,17.21802,39.19331
62.73200,5.22763,782.90310,-0.13640,17.28450,39.17689
62.93200,5.24426,783.03730,-0.13640,17.35099,39.18361
63.13200,5.26094,783.33672,-0.13640,17.41772,39.19859
63.33200,5.27768,783.61006,-0.13640,17.48468,39.21227
63.53200,5.29436,783.48285,-0.13640,17.55140,39.20590
63.73200,5.31104,784.50376,-0.13640,17.61813,39.25698
63.93200,5.32766,784.37524,-0.13640,17.68462,39.25055
64.13200,5.34428,784.86232,-0.13640,17.75110,39.27493
64.33200,5.36097,785.09208,-0.13640,17.81783,39.28643
64.53200,5.37777,785.03974,-0.13640,17.88503,39.28381
64.73200,5.39433,785.37324,-0.13640,17.95128,39.30050
64.93201,5.41095,785.61008,-0.13640,18.01776,39.31235
65.13200,5.42763,786.17521,-0.13639,18.08449,39.34063
65.33200,5.44431,786.69814,-0.13640,18.15121,39.36679
65.53200,5.46099,786.10694,-0.13640,18.21794,39.33721
65.73200,5.47773,785.81115,-0.13640,18.28490,39.32241
65.93201,5.49435,786.69107,-0.13640,18.35139,39.36644
66.13200,5.51092,786.62885,-0.13640,18.41763,39.36333
66.33200,5.52766,787.41685,-0.13640,18.48460,39.40276
66.53201,5.54446,787.62621,-0.13640,18.55180,39.41323
66.73200,5.56102,787.32958,-0.13640,18.61805,39.39839
66.93201,5.57764,787.78053,-0.13640,18.68453,39.42096
67.13200,5.59438,787.52441,-0.13640,18.75150,39.40814
67.33200,5.61094,788.14551,-0.13639,18.81774,39.43922
67.53201,5.62763,788.28279,-0.13640,18.88447,39.44609
67.73200,5.64431,788.72805,-0.13640,18.95120,39.46837
67.93201,5.66099,788.54794,-0.13639,19.01792,39.45936
68.13200,5.67761,788.78049,-0.13640,19.08441,39.47100
68.33200,5.69429,788.87707,-0.13640,19.15113,39.47583
68.53201,5.71103,788.67236,-0.13640,19.21810,39.46558
68.73200,5.72759,789.17937,-0.13640,19.28434,39.49096
68.93201,5.74439,789.55507,-0.13640,19.35155,39.50976
69.13200,5.76108,789.71386,-0.13639,19.41827,39.51770
69.33200,5.77764,789.75577,-0.13640,19.48452,39.51980
69.53201,5.79432,790.32946,-0.13640,19.55124,39.54851
69.73200,5.81094,789.53970,-0.13640,19.61773,39.50899
69.93201,5.82768,790.03694,-0.13639,19.68469,39.53387
70.13200,5.84436,790.04457,-0.13639,19.75142,39.53425
70.33200,5.86092,789.77933,-0.13640,19.81767,39.52098
70.53201,5.87767,790.36457,-0.13640,19.88463,39.55027
70.73200,5.89429,790.63550,-0.13640,19.95112,39.56382
70.93201,5.91103,790.77389,-0.13640,20.01808,39.57075
71.13200,5.92777,790.63633,-0.13640,20.08504,39.56386
71.33200,5.94427,791.39359,-0.13640,20.15105,39.60176
71.53201,5.96095,790.83499,-0.13639,20.21778,39.57380
71.73200,5.97769,791.25902,-0.13640,20.28474,39.59502
71.93201,5.99437,790.83191,-0.13640,20.35147,39.57365
72.13200,6.01100,791.16533,-0.13640,20.41795,39.59034
72.33200,6.02768,791.32048,-0.13640,20.48468,39.59810
72.53201,6.04436,791.90480,-0.13640,20.55140,39.62734
72.73200,6.06092,792.11220,-0.13639,20.61765,39.63772
72.93201,6.07760,791.89083,-0.13640,20.68437,39.62664
73.13200,6.09446,792.19909,-0.13640,20.75182,39.64206
73.33200,6.11102,792.59118,-0.13640,20.81807,39.66169
73.53201,6.12765,791.95229,-0.13640,20.88455,39.62971
73.73200,6.14439,792.33106,-0.13640,20.95151,39.64867
73.93201,6.16101,792.54061,-0.13640,21.01800,39.65915
74.13200,6.17763,792.05418,-0.13640,21.08449,39.63481
74.33200,6.19437,792.34028,-0.13640,21.15145,39.64913
74.53201,6.21099,792.76487,-0.13640,21.21793,39.67038
74.73200,6.22755,792.50643,-0.13640,21.28418,39.65744
74.93201,6.24429,792.44571,-0.13640,21.35115,39.65440
75.13200,6.26110,792.33944,-0.13640,21.41835,39.64909
75.33200,6.27766,792.95924,-0.13640,21.48460,39.68010
75.53201,6.29428,792.58392,-0.13640,21.55108,39.66132
75.73200,6.31096,793.15854,-0.13640,21.61781,39.69007
75.93201,6.32764,793.12846,-0.13639,21.68453,39.68857
76.13200,6.34432,793.56302,-0.13640,21.75126,39.71032
76.33200,6.36100,793.21051,-0.13640,21.81798,39.69268
76.53201,6.37780,793.22197,-0.13640,21.88519,39.69325
76.73200,6.39419,793.52139,-0.13640,21.95072,39.70823
76.93201,6.41093,793.50937,-0.13640,22.01768,39.70763
77.13200,6.42773,793.79380,-0.13640,22.08488,39.72186
77.33200,6.44429,793.66891,-0.13640,22.15113,39.71561
77.53201,6.46103,793.12734,-0.13640,22.21809,39.68851
77.73200,6.47771,794.10868,-0.13640,22.28482,39.73762
77.93201,6.49427,793.21917,-0.13640,22.35107,39.69311
78.13200,6.51090,793.28483,-0.13640,22.41755,39.69640
78.33200,6.52764,793.82611,-0.13640,22.48452,39.72348
78.53201,6.54438,793.70616,-0.13640,22.55148,39.71748
78.73200,6.56094,793.24069,-0.13640,22.61773,39.69419
78.93201,6.57768,793.64832,-0.13640,22.68469,39.71458
79.13200,6.59442,793.98248,-0.13640,22.75166,39.73131
79.33200,6.61092,793.80618,-0.13640,22.81766,39.72248
79.53201,6.62767,793.81838,-0.13640,22.88463,39.72309
79.73200,6.64441,794.16130,-0.13640,22.95159,39.74025
79.93201,6.66097,793.77852,-0.13640,23.01784,39.72110
80.13200,6.67759,793.28483,-0.13640,23.08432,39.69640
80.33200,6.69439,793.84893,-0.13640,23.15153,39.72462
80.53201,6.71107,793.42751,-0.13640,23.21825,39.70354
80.73200,6.72763,793.69461,-0.13640,23.28450,39.71690
80.93201,6.74431,793.45433,-0.13640,23.35123,39.70488
81.13200,6.76100,794.46705,-0.13640,23.41795,39.75555
81.33200,6.77762,794.44824,-0.13640,23.48444,39.75461
81.53201,6.79436,793.57224,-0.13640,23.55140,39.71078
81.73200,6.81110,793.49559,-0.13640,23.61837,39.70694
81.93201,6.82760,793.95501,-0.13640,23.68437,39.72993
82.13200,6.84428,792.94108,-0.13640,23.75110,39.67920
82.33200,6.86102,793.51626,-0.13640,23.81806,39.70798
82.53201,6.87764,793.94635,-0.13640,23.88455,39.72950
82.73200,6.89433,794.11538,-0.13640,23.95127,39.73796
82.93201,6.91101,793.51394,-0.13640,24.01800,39.70786
83.13200,6.92763,793.76735,-0.13640,24.08448,39.72054
83.33200,6.94425,793.86290,-0.13640,24.15097,39.72532
83.53201,6.96093,793.41354,-0.13640,24.21769,39.70284
83.73200,6.97767,793.46197,-0.13640,24.28466,39.70526
83.93201,6.99435,793.83655,-0.13640,24.35138,39.72400
84.13200,7.01104,793.35216,-0.13640,24.41811,39.69976
84.33200,7.02766,793.04716,-0.13640,24.48460,39.68450
84.53201,7.04428,793.21656,-0.13640,24.55108,39.69298
84.73200,7.06096,793.91226,-0.13640,24.61780,39.72779
84.93201,7.07776,793.61573,-0.13640,24.68501,39.71296
85.13200,7.09438,793.33009,-0.13640,24.75150,39.69866
85.33200,7.11094,794.07999,-0.13640,24.81774,39.73619
85.53201,7.12768,793.26425,-0.13640,24.88471,39.69537
85.73200,7.14437,793.49605,-0.13640,24.95143,39.70697
85.93201,7.16093,793.50891,-0.13640,25.01768,39.70761
86.13200,7.17767,793.29582,-0.13640,25.08464,39.69695
86.33200,7.19441,793.42257,-0.13640,25.15161,39.70329
86.53201,7.21097,793.73401,-0.13640,25.21785,39.71887
86.73200,7.22753,793.49913,-0.13640,25.28410,39.70712
86.93201,7.24439,792.87095,-0.13640,25.35154,39.67569
87.13200,7.26108,793.05144,-0.13640,25.41827,39.68472
87.33200,7.27764,793.38048,-0.13640,25.48451,39.70118
87.53201,7.29432,793.41400,-0.13640,25.55124,39.70286
87.73200,7.31106,792.74690,-0.13640,25.61820,39.66948
87.93201,7.32762,793.49279,-0.13640,25.68445,39.70680
88.13200,7.34424,793.01326,-0.13640,25.75094,39.68280
88.33200,7.36110,792.62266,-0.13640,25.81838,39.66326
88.53201,7.37760,793.31370,-0.13640,25.88438,39.69784
88.73200,7.39429,792.97610,-0.13640,25.95111,39.68095
88.93201,7.41103,792.60040,-0.13640,26.01808,39.66215
89.13200,7.42765,792.78592,-0.13640,26.08456,39.67143
89.33200,7.44433,792.61521,-0.13640,26.15128,39.66289
89.53201,7.46101,792.66243,-0.13640,26.21801,39.66525
89.73200,7.47769,792.16985,-0.13640,26.28474,39.64060
89.93201,7.49437,792.87579,-0.13640,26.35146,39.67593
90.13200,7.51100,792.49628,-0.13640,26.41795,39.65694
90.33200,7.52780,791.70959,-0.13640,26.48515,39.61757
90.53201,7.54436,792.19751,-0.13640,26.55140,39.64199
90.73200,7.56098,791.55620,-0.13640,26.61788,39.60989
90.93201,7.57766,791.95015,-0.13640,26.68461,39.62961
91.13200,7.59428,791.48831,-0.13640,26.75110,39.60649
91.33200,7.61102,791.29934,-0.13640,26.81806,39.59704
91.53201,7.62764,791.01995,-0.13640,26.88454,39.58306
91.73200,7.64427,791.31499,-0.13640,26.95103,39.59782
91.93201,7.66101,791.38987,-0.13640,27.01800,39.60157
92.13200,7.67763,790.83443,-0.13640,27.08448,39.57378
92.33200,7.69437,791.14614,-0.13640,27.15144,39.58937
92.53201,7.71105,790.58278,-0.13640,27.21817,39.56118
92.73200,7.72761,790.38320,-0.13640,27.28442,39.55120
92.93201,7.74441,790.78618,-0.13640,27.35162,39.57136
93.13200,7.76098,790.35331,-0.13640,27.41787,39.54970
93.33200,7.77760,790.89217,-0.13640,27.48435,39.57666
93.53201,7.79434,789.81593,-0.13640,27.55132,39.52281
93.73200,7.81102,790.01822,-0.13640,27.61804,39.53293
93.93201,7.82758,790.39326,-0.13640,27.68429,39.55170
94.13200,7.84426,790.53659,-0.13640,27.75101,39.55887
94.33200,7.86106,789.91698,-0.13640,27.81821,39.52787
94.53201,7.87768,789.79507,-0.13640,27.88470,39.52177
94.73200,7.89437,789.69598,-0.13640,27.95143,39.51681
94.93201,7.91111,789.67232,-0.13640,28.01839,39.51562
95.13200,7.92761,789.00475,-0.13640,28.08440,39.48222
95.33200,7.94435,788.87055,-0.13640,28.15136,39.47550
95.53201,7.96103,789.44564,-0.13640,28.21809,39.50428
95.73200,7.97765,789.27185,-0.13640,28.28457,39.49558
95.93201,7.99439,788.71576,-0.13640,28.35154,39.46776
96.13200,8.01095,788.81839,-0.13640,28.41778,39.47289
96.33201,8.02764,788.70980,-0.13640,28.48451,39.46746
96.53201,8.04432,788.36065,-0.13640,28.55124,39.44999
96.73200,8.06094,788.05685,-0.13640,28.61772,39.43478
96.93201,8.07768,788.04493,-0.13640,28.68468,39.43419
97.13200,8.09424,788.18211,-0.13640,28.75093,39.44105
97.33201,8.11092,787.86425,-0.13640,28.81766,39.42515
97.53201,8.12766,787.36600,-0.13640,28.88462,39.40022
97.73200,8.14435,787.08744,-0.13640,28.95135,39.38628
97.93201,8.16109,787.10942,-0.13640,29.01831,39.38737
98.13200,8.17765,787.16241,-0.13640,29.08456,39.39003
98.33201,8.19433,786.26946,-0.13640,29.15128,39.34534
98.53201,8.21095,786.72860,-0.13640,29.21777,39.36832
98.73200,8.22763,786.41530,-0.13640,29.28449,39.35264
98.93201,8.24437,786.51058,-0.13640,29.35146,39.35741
99.13200,8.26093,786.35477,-0.13640,29.41771,39.34961
99.33201,8.27762,785.95281,-0.13640,29.48443,39.32950
99.53201,8.29430,786.19095,-0.13640,29.55116,39.34142
99.73200,8.31098,785.72966,-0.13640,29.61788,39.31833
99.93201,8.32772,785.07820,-0.13640,29.68484,39.28573
100.13200,8.34434,785.00602,-0.13640,29.75133,39.28212
100.33201,8.36102,784.71340,-0.13640,29.81806,39.26748
100.53201,8.37758,784.52071,-0.13640,29.88430,39.25784
100.73200,8.39433,784.65678,-0.13640,29.95127,39.26464
100.93201,8.41107,784.42814,-0.13640,30.01823,39.25320
101.13200,8.42763,784.55182,-0.13640,30.08448,39.25939
101.33201,8.44431,784.15200,-0.13640,30.15120,39.23938
101.53201,8.46105,783.20522,-0.13640,30.21817,39.19201
101.73200,8.47767,783.82753,-0.13640,30.28465,39.22315
101.93201,8.49429,783.34529,-0.13640,30.35114,39.19902
102.13200,8.51103,783.45882,-0.13640,30.41810,39.20470
102.33201,8.52772,783.32555,-0.13640,30.48483,39.19803
102.53201,8.54428,783.25681,-0.13640,30.55107,39.19459
102.73200,8.56102,782.66235,-0.13640,30.61804,39.16484
102.93201,8.57776,782.73760,-0.13640,30.68500,39.16861
103.13200,8.59432,782.24437,-0.13640,30.75125,39.14392
103.33201,8.61100,782.23227,-0.13640,30.81798,39.14332
103.53201,8.62774,781.81308,-0.13640,30.88494,39.12234
103.73200,8.64430,781.41699,-0.13640,30.95118,39.10252
103.93201,8.66093,781.36139,-0.13640,31.01767,39.09974
104.13200,8.67773,780.84646,-0.13640,31.08487,39.07397
104.33201,8.69435,780.96297,-0.13640,31.15136,39.07980
104.53201,8.71091,780.58327,-0.13640,31.21761,39.06080
104.73200,8.72759,781.22746,-0.13640,31.28433,39.09304
104.93201,8.74433,779.91863,-0.13640,31.35130,39.02754
105.13200,8.76101,779.42600,-0.13640,31.41802,39.00289
105.33201,8.77769,779.18782,-0.13640,31.48475,38.99097
105.53201,8.79444,779.40123,-0.13640,31.55171,39.00165
105.73200,8.81094,778.73962,-0.13640,31.61772,38.96854
105.93201,8.82762,778.09673,-0.13640,31.68445,38.93637
106.13200,8.84442,778.02050,-0.13640,31.75165,38.93256
106.33201,8.86098,777.82837,-0.13640,31.81790,38.92295
106.53201,8.87760,777.46972,-0.13640,31.88438,38.90500
106.73200,8.89434,777.45705,-0.13640,31.95135,38.90437
106.93201,8.91097,777.22883,-0.13640,32.01783,38.89294
107.13200,8.92753,776.75446,-0.13640,32.08408,38.86921
107.33201,8.94439,776.83092,-0.13640,32.15152,38.87303
107.53201,8.96107,776.58100,-0.13640,32.21824,38.86053
107.73200,8.97757,776.79018,-0.13640,32.28425,38.87099
107.93201,8.99431,775.55142,-0.13640,32.35122,38.80901
108.13200,9.01111,775.32078,-0.13640,32.41842,38.79747
108.33201,9.02762,775.16749,-0.13640,32.48443,38.78979
108.53201,9.04430,774.52739,-0.13640,32.55115,38.75776
108.73200,9.06116,774.68790,-0.13640,32.61859,38.76580
108.93201,9.07760,774.29586,-0.13640,32.68436,38.74618
109.13200,9.09428,774.02010,-0.13640,32.75109,38.73238
109.33201,9.11102,773.30200,-0.13640,32.81805,38.69645
109.53201,9.12770,772.69985,-0.13640,32.88478,38.66631
109.73200,9.14426,772.63056,-0.13640,32.95102,38.66285
109.93201,9.16095,772.13557,-0.13640,33.01775,38.63808
110.13200,9.17775,772.37221,-0.13640,33.08495,38.64992
110.33201,9.19431,772.52281,-0.13640,33.15120,38.65745
110.53201,9.21099,771.28666,-0.13640,33.21792,38.59560
110.73200,9.22779,770.70626,-0.13640,33.28513,38.56655
110.93201,9.24423,770.40233,-0.13640,33.35090,38.55134
111.13200,9.26097,770.57695,-0.13640,33.41786,38.56008
111.33201,9.27766,770.11683,-0.13640,33.48459,38.53706
111.53201,9.29434,769.14593,-0.13640,33.55131,38.48847
111.73200,9.31096,769.54253,-0.13640,33.61780,38.50832
111.93201,9.32764,768.18899,-0.13640,33.68452,38.44059
112.13200,9.34438,768.15053,-0.13640,33.75149,38.43866
112.33201,9.36094,768.01130,-0.13640,33.81774,38.43169
112.53201,9.37762,767.38084,-0.13640,33.88446,38.40015
112.73200,9.39436,766.96402,-0.13640,33.95142,38.37929
112.93201,9.41099,766.25175,-0.13640,34.01791,38.34365
113.13200,9.42767,765.57212,-0.13640,34.08463,38.30964
113.33201,9.44441,765.41537,-0.13640,34.15160,38.30179
113.53201,9.46103,764.74734,-0.13640,34.21808,38.26836
113.73200,9.47771,764.63539,-0.13640,34.28481,38.26276
113.93201,9.49439,763.92740,-0.13640,34.35154,38.22733
114.13200,9.51101,764.61090,-0.13640,34.41802,38.26154
114.33201,9.52758,763.03231,-0.13640,34.48427,38.18254
114.53201,9.54432,762.37167,-0.13640,34.55123,38.14949
114.73200,9.56112,762.36664,-0.13640,34.61843,38.14923
114.93201,9.57762,761.93027,-0.13640,34.68444,38.12740
115.13200,9.59430,761.13539,-0.13640,34.75117,38.08762
115.33201,9.61110,760.15727,-0.13640,34.81837,38.03867
115.53201,9.62760,760.26474,-0.13640,34.88438,38.04405
115.73200,9.64428,759.16117,-0.13640,34.95110,37.98883
115.93201,9.66103,758.38915,-0.13640,35.01807,37.95020
116.13200,9.67777,757.93182,-0.13640,35.08503,37.92731
116.33201,9.69427,757.29638,-0.13640,35.15104,37.89552
116.53201,9.71095,756.96707,-0.13640,35.21776,37.87904
116.73200,9.72781,755.79667,-0.13640,35.28521,37.82047
116.93201,9.74425,755.40389,-0.13640,35.35098,37.80081
117.13200,9.76099,754.40658,-0.13640,35.41794,37.75091
117.33201,9.77773,754.03056,-0.13640,35.48490,37.73209
117.53201,9.79424,753.13696,-0.13640,35.55091,37.68737
117.73200,9.81092,752.43539,-0.13640,35.61763,37.65227
117.93201,9.82766,751.75897,-0.13640,35.68460,37.61842
118.13200,9.84434,751.46267,-0.13640,35.75132,37.60359
118.33201,9.86102,750.13698,-0.13640,35.81805,37.53725
118.53201,9.87758,750.06466,-0.13640,35.88430,37.53363
118.73200,9.89438,748.94708,-0.13640,35.95150,37.47771
118.93201,9.91095,748.03508,-0.13640,36.01775,37.43208
119.13200,9.92769,747.15051,-0.13640,36.08471,37.38781
119.33201,9.94443,745.77103,-0.13640,36.15168,37.31878
119.53201,9.96105,744.43091,-0.13640,36.21816,37.25172
119.73200,9.97761,743.76808,-0.13640,36.28441,37.21855
119.93201,9.99429,742.53744,-0.13640,36.35113,37.15697
120.13200,10.01091,741.37822,-0.13640,36.41762,37.09896
120.33201,10.02765,739.64475,-0.13640,36.48458,37.01222
120.53201,10.04433,738.49382,-0.13640,36.55131,36.95462
120.73200,10.06102,736.72454,-0.13640,36.61804,36.86609
120.93201,10.07758,734.98148,-0.13640,36.68428,36.77887
121.13200,10.09432,732.30453,-0.13640,36.75124,36.64491
121.33201,10.11106,729.30502,-0.13640,36.81821,36.49481
121.53201,10.12768,724.33366,-0.13640,36.88470,36.24604
121.73200,10.14430,715.33970,-0.13640,36.95118,35.79598
121.91401,10.15973,1.12050,-0.13639,37.01288,0.05607