File: Manufatura Aditiva/Classificação Direção/Ensaios/Ensaios SLS/Tracao_OLABI_07_06_2018_SLS_YX5.is_metal_RawData/Specimen_RawData_3.csv
Time,Extension,Load,Strain 1,Tensile strain,Tensile stress
(sec),(mm),(N),(mm/mm),(%),(MPa)
0.00000,0.00006,19.95674,0.00114,0.11407,0.91263
0.20000,0.01375,26.37793,0.00132,0.13172,1.20628
0.40000,0.03270,37.61550,0.00163,0.16264,1.72018
0.60000,0.04986,46.92135,0.00191,0.19091,2.14574
0.80000,0.06673,55.68454,0.00217,0.21735,2.54649
1.00000,0.08335,64.42837,0.00244,0.24423,2.94635
1.20000,0.10003,72.91113,0.00272,0.27184,3.33427
1.40000,0.11683,82.21233,0.00299,0.29919,3.75962
1.60000,0.13339,89.46519,0.00326,0.32632,4.09130
1.80000,0.14995,98.23961,0.00352,0.35250,4.49256
2.00000,0.16657,106.94560,0.00380,0.37984,4.89069
2.20000,0.18331,114.44082,0.00407,0.40670,5.23345
2.40000,0.19994,123.01584,0.00434,0.43370,5.62559
2.60000,0.21668,131.00210,0.00461,0.46135,5.99080
2.80000,0.23336,139.07118,0.00488,0.48789,6.35981
3.00000,0.24992,146.94635,0.00514,0.51448,6.71994
3.20000,0.26672,151.44938,0.00532,0.53172,6.92587
3.40000,0.28340,159.37437,0.00560,0.56001,7.28828
3.60000,0.30002,167.37242,0.00587,0.58706,7.65404
3.80000,0.31665,175.14551,0.00613,0.61320,8.00951
4.00000,0.33327,182.94788,0.00640,0.64017,8.36631
4.20000,0.34995,190.53152,0.00667,0.66715,8.71312
4.40000,0.36657,198.18342,0.00694,0.69435,9.06305
4.60000,0.38331,204.83548,0.00722,0.72151,9.36725
4.80000,0.39999,212.78867,0.00748,0.74801,9.73095
5.00000,0.41661,220.01995,0.00775,0.77462,10.06164
5.20000,0.43335,227.40832,0.00801,0.80127,10.39952
5.40000,0.45010,235.27269,0.00829,0.82860,10.75916
5.60000,0.46666,242.32361,0.00855,0.85485,11.08160
5.80000,0.48334,249.10355,0.00882,0.88177,11.39165
6.00000,0.50002,254.65572,0.00902,0.90203,11.64556
6.20000,0.51664,261.79927,0.00929,0.92872,11.97224
6.40000,0.53326,268.90645,0.00956,0.95577,12.29725
6.60000,0.55000,276.25083,0.00983,0.98331,12.63311
6.80000,0.56674,283.26472,0.01010,1.01019,12.95386
7.00000,0.58331,290.47222,0.01036,1.03625,13.28347
7.20000,0.59993,297.08750,0.01064,1.06380,13.58599
7.40000,0.61673,304.54376,0.01091,1.09079,13.92697
7.60000,0.63329,310.65452,0.01119,1.11861,14.20642
7.80000,0.64997,317.49608,0.01145,1.14500,14.51928
8.00000,0.66671,324.15111,0.01172,1.17200,14.82362
8.20000,0.68333,331.15505,0.01199,1.19926,15.14392
8.40000,0.70002,335.05161,0.01220,1.21971,15.32211
8.60000,0.71664,341.93513,0.01247,1.24710,15.63690
8.80000,0.73344,348.50778,0.01274,1.27430,15.93747
9.00000,0.75000,354.82238,0.01301,1.30126,16.22624
9.20000,0.76662,361.78171,0.01329,1.32946,16.54449
9.40000,0.78342,367.44368,0.01356,1.35649,16.80342
9.60000,0.79992,373.91523,0.01384,1.38437,17.09937
9.80000,0.81660,380.37256,0.01412,1.41214,17.39466
10.00000,0.83341,386.14031,0.01439,1.43949,17.65842
10.20000,0.84997,392.36536,0.01467,1.46676,17.94310
10.40000,0.86671,398.58534,0.01495,1.49517,18.22754
10.60000,0.88333,401.35225,0.01516,1.51561,18.35408
10.80000,0.90007,407.89023,0.01543,1.54346,18.65306
11.00000,0.91669,413.42070,0.01571,1.57089,18.90597
11.20000,0.93331,419.57176,0.01599,1.59923,19.18727
11.40000,0.95000,425.54759,0.01628,1.62767,19.46054
11.60000,0.96656,430.87779,0.01656,1.65589,19.70430
11.80000,0.98330,435.93384,0.01684,1.68403,19.93551
12.00000,1.00010,441.42110,0.01712,1.71211,20.18645
12.20000,1.01666,447.07693,0.01741,1.74057,20.44509
12.40000,1.03328,450.56045,0.01762,1.76158,20.60440
12.60000,1.05002,455.85469,0.01790,1.78981,20.84650
12.80000,1.06664,461.00914,0.01819,1.81877,21.08222
13.00000,1.08333,466.59964,0.01848,1.84751,21.33788
13.20000,1.10001,471.58110,0.01876,1.87590,21.56568
13.40000,1.11675,476.56433,0.01906,1.90563,21.79357
13.60000,1.13325,482.23790,0.01935,1.93457,22.05302
13.80000,1.14999,486.86797,0.01964,1.96394,22.26476
14.00000,1.16673,492.19052,0.01993,1.99307,22.50816
14.20000,1.18329,494.27226,0.02015,2.01503,22.60336
14.40000,1.19998,499.37991,0.02045,2.04544,22.83694
14.60000,1.21672,504.76883,0.02075,2.07500,23.08338
14.80000,1.23334,509.25743,0.02104,2.10428,23.28864
15.00000,1.24990,513.95162,0.02135,2.13459,23.50331
15.20000,1.26664,518.19086,0.02165,2.16463,23.69717
15.40000,1.28344,522.93492,0.02195,2.19455,23.91412
15.60000,1.29994,526.59814,0.02225,2.22453,24.08164
15.80000,1.31662,530.93350,0.02255,2.25531,24.27990
16.00000,1.33343,533.43652,0.02279,2.27855,24.39437
16.20000,1.34993,538.00251,0.02309,2.30930,24.60317
16.40000,1.36667,541.81577,0.02340,2.34025,24.77756
16.60000,1.38341,545.36392,0.02371,2.37135,24.93982
16.80000,1.39997,549.55031,0.02402,2.40217,25.13126
17.00000,1.41659,553.68668,0.02433,2.43327,25.32042
17.20000,1.43333,557.55908,0.02464,2.46445,25.49751
17.40000,1.45001,560.96632,0.02495,2.49520,25.65332
17.60000,1.46664,564.35894,0.02527,2.52675,25.80847
17.80000,1.48320,567.05950,0.02551,2.55135,25.93197
18.00000,1.50006,570.64798,0.02582,2.58247,26.09607
18.20000,1.51656,573.78658,0.02614,2.61376,26.23960
18.40000,1.53330,577.91155,0.02646,2.64611,26.42824
18.60000,1.55004,581.58804,0.02678,2.67842,26.59636
18.80000,1.56666,584.54783,0.02710,2.71006,26.73172
19.00000,1.58335,587.65006,0.02742,2.74232,26.87358
19.20000,1.60003,590.81423,0.02775,2.77488,27.01828
19.40000,1.61671,594.62539,0.02807,2.80671,27.19257
19.60000,1.63333,597.44231,0.02839,2.83949,27.32139
19.80000,1.65001,598.72922,0.02864,2.86425,27.38024
20.00000,1.66663,601.86717,0.02896,2.89627,27.52374
20.20000,1.68325,605.06375,0.02930,2.92960,27.66992
20.40000,1.69993,607.86800,0.02962,2.96214,27.79816
20.60000,1.71674,610.65583,0.02995,2.99499,27.92565
20.80000,1.73330,613.29892,0.03028,3.02762,28.04652
21.00000,1.74992,616.60204,0.03061,3.06080,28.19758
21.20000,1.76672,619.66521,0.03094,3.11154,28.33766
21.37600,1.78131,621.69288,0.03123,3.16989,28.43038
21.57600,1.79793,624.59623,0.03157,3.23638,28.56316
21.77600,1.81485,627.23039,0.03191,3.30406,28.68362
21.97600,1.83135,628.32632,0.03216,3.37007,28.73373
22.17600,1.84791,629.75273,0.03245,3.43631,28.79897
22.37600,1.86465,632.66600,0.03278,3.50328,28.93219
22.57600,1.88140,635.38142,0.03312,3.57024,29.05637
22.77600,1.89796,638.14158,0.03346,3.63649,29.18259
22.97600,1.91464,641.39464,0.03379,3.70321,29.33136
23.17600,1.93138,643.58115,0.03413,3.77018,29.43135
23.37600,1.94794,646.55636,0.03448,3.83642,29.56741
23.57600,1.96468,648.76690,0.03521,3.90339,29.66849
23.77600,1.98148,650.39936,0.03601,3.97059,29.74315
23.97600,1.99805,653.52018,-0.00066,4.03684,29.88586
24.17600,2.01467,655.41524,-0.00056,4.10332,29.97253
24.37600,2.03135,655.51992,-0.00160,4.17005,29.97731
24.57600,2.04803,658.40124,-0.00452,4.23677,30.10908
24.77600,2.06465,661.11274,-0.00303,4.30326,30.23308
24.97600,2.08127,662.92314,-0.00164,4.36975,30.31587
25.17600,2.09795,665.08055,-0.00294,4.43647,30.41453
25.37600,2.11457,667.54268,-0.00341,4.50296,30.52712
25.57600,2.13126,670.39481,-0.01396,4.56968,30.65755
25.77600,2.14800,672.38733,-0.03865,4.63665,30.74867
25.97600,2.16468,674.03102,-0.14001,4.70337,30.82384
26.17600,2.18142,677.12828,-0.13998,4.77034,30.96548
26.37600,2.19798,679.01309,-0.13998,4.83658,31.05167
26.57600,2.21466,680.71433,-0.13999,4.90331,31.12947
26.77600,2.23140,682.98629,-0.13999,4.97027,31.23337
26.97600,2.24803,684.79721,-0.13999,5.03676,31.31618
27.17600,2.26471,684.89127,-0.13999,5.10348,31.32048
27.37600,2.28133,686.75666,-0.14000,5.16997,31.40579
27.57600,2.29801,689.33605,-0.14000,5.23669,31.52375
27.77600,2.31469,691.54999,-0.14000,5.30342,31.62499
27.97600,2.33131,692.82996,-0.14000,5.36991,31.68352
28.17600,2.34799,695.11160,-0.14000,5.43663,31.78786
28.37600,2.36461,696.94584,-0.14000,5.50312,31.87175
28.57600,2.38130,699.43974,-0.14000,5.56984,31.98579
28.77600,2.39798,701.18969,-0.14000,5.63657,32.06582
28.97600,2.41466,703.05662,-0.14000,5.70329,32.15120
29.17600,2.43140,704.66353,-0.14000,5.77026,32.22468
29.37600,2.44796,706.28463,-0.14001,5.83650,32.29881
29.57600,2.46464,708.35114,-0.14000,5.90323,32.39332
29.77600,2.48138,710.42217,-0.14001,5.97019,32.48803
29.97600,2.49795,712.41320,-0.14000,6.03644,32.57908
30.17600,2.51463,711.97413,-0.14001,6.10316,32.55900
30.37600,2.53137,713.08482,-0.14001,6.17013,32.60979
30.57600,2.54799,715.14514,-0.14001,6.23661,32.70401
30.77600,2.56461,717.54567,-0.14001,6.30310,32.81379
30.97600,2.58129,718.64477,-0.14001,6.36982,32.86405
31.17600,2.59803,720.53433,-0.14001,6.43679,32.95046
31.37600,2.61459,721.91013,-0.14001,6.50304,33.01338
31.57600,2.63134,723.40551,-0.14001,6.57000,33.08176
31.77600,2.64802,725.47239,-0.14001,6.63673,33.17628
31.97600,2.66458,727.46449,-0.14001,6.70297,33.26738
32.17600,2.68132,728.97305,-0.14001,6.76994,33.33637
32.37600,2.69800,729.74549,-0.14001,6.83666,33.37169
32.57600,2.71468,731.59025,-0.14001,6.90339,33.45605
32.77600,2.73136,733.53718,-0.14001,6.97011,33.54509
32.97600,2.74798,735.22069,-0.14001,7.03660,33.62208
33.17600,2.76473,736.49408,-0.14001,7.10356,33.68031
33.37600,2.78135,738.25992,-0.14001,7.17005,33.76106
33.57600,2.79797,739.21136,-0.14001,7.23653,33.80457
33.77600,2.81465,740.19502,-0.14001,7.30326,33.84956
33.97600,2.83127,742.48589,-0.14002,7.36974,33.95432
34.17600,2.84795,741.22204,-0.14001,7.43647,33.89652
34.37600,2.86469,742.61082,-0.14001,7.50343,33.96003
34.57600,2.88137,744.70108,-0.14002,7.57016,34.05562
34.77600,2.89800,746.12335,-0.14001,7.63664,34.12066
34.97600,2.91474,747.62926,-0.14002,7.70361,34.18953
35.17600,2.93136,749.48482,-0.14001,7.77009,34.27438
35.37600,2.94792,750.13791,-0.14001,7.83634,34.30425
35.57600,2.96472,752.24703,-0.14002,7.90354,34.40070
35.77600,2.98146,753.66171,-0.14002,7.97051,34.46540
35.97600,2.99790,754.96081,-0.14002,8.03628,34.52480
36.17600,3.01465,756.65182,-0.14002,8.10324,34.60213
36.37600,3.03139,757.43245,-0.14002,8.17021,34.63783
36.57600,3.04795,759.13388,-0.14002,8.23645,34.71564
36.77600,3.06469,760.35261,-0.14002,8.30342,34.77137
36.97600,3.08149,762.06140,-0.14002,8.37062,34.84952
37.17600,3.09793,763.04218,-0.14002,8.43639,34.89437
37.37600,3.11461,764.54594,-0.14002,8.50311,34.96314
37.57600,3.13141,765.79768,-0.14002,8.57032,35.02038
37.77600,3.14804,766.20379,-0.14002,8.63680,35.03895
37.97600,3.16460,767.97414,-0.14002,8.70305,35.11991
38.17600,3.18134,768.79188,-0.14002,8.77001,35.15731
38.37600,3.19802,770.44237,-0.14002,8.83674,35.23278
38.57600,3.21458,771.39321,-0.14002,8.90299,35.27627
38.77600,3.23126,772.61874,-0.14002,8.96971,35.33231
38.97600,3.24806,774.16953,-0.14002,9.03692,35.40323
39.17600,3.26469,771.76495,-0.14002,9.10340,35.29327
39.37600,3.28131,773.29632,-0.14002,9.16989,35.36330
39.57600,3.29799,774.28427,-0.14002,9.23661,35.40848
39.77600,3.31461,776.18510,-0.14002,9.30310,35.49540
39.97600,3.33135,777.52550,-0.14002,9.37006,35.55670
40.17600,3.34803,779.05506,-0.14002,9.43679,35.62665
40.37600,3.36471,779.53399,-0.14002,9.50351,35.64855
40.57600,3.38127,780.56776,-0.14002,9.56976,35.69583
40.77600,3.39796,781.98919,-0.14002,9.63648,35.76083
40.97600,3.41476,783.44783,-0.14002,9.70369,35.82753
41.17600,3.43132,784.24904,-0.14002,9.76993,35.86417
41.37600,3.44794,785.15802,-0.14002,9.83642,35.90574
41.57600,3.46468,786.45963,-0.14002,9.90338,35.96526
41.77600,3.48130,788.17215,-0.14002,9.96987,36.04358
41.97600,3.49798,788.91087,-0.14002,10.03659,36.07736
42.17600,3.51473,789.43484,-0.14002,10.10356,36.10132
42.37600,3.53141,790.33226,-0.14002,10.17028,36.14236
42.57600,3.54797,791.64496,-0.14002,10.23653,36.20239
42.77600,3.56459,792.85270,-0.14002,10.30302,36.25762
42.97600,3.58145,793.51813,-0.14002,10.37046,36.28806
43.17600,3.59789,794.15403,-0.14002,10.43623,36.31713
43.37600,3.61463,795.45602,-0.14002,10.50319,36.37667
43.57600,3.63143,796.52369,-0.14002,10.57039,36.42550
43.77600,3.64794,797.21455,-0.14002,10.63640,36.45709
43.97600,3.66462,798.45116,-0.14002,10.70313,36.51365
44.17600,3.68142,799.30257,-0.14002,10.77033,36.55258
44.37600,3.69804,799.54620,-0.14002,10.83682,36.56372
44.57600,3.71460,800.52055,-0.14003,10.90306,36.60828
44.77600,3.73134,801.40475,-0.14002,10.97003,36.64871
44.97600,3.74814,803.12965,-0.14003,11.03723,36.72760
45.17600,3.76459,803.85264,-0.14002,11.10300,36.76066
45.37600,3.78133,804.44878,-0.14002,11.16996,36.78792
45.57600,3.79807,805.09828,-0.14002,11.23693,36.81762
45.77600,3.81463,806.43147,-0.14002,11.30318,36.87859
45.97600,3.83125,807.28810,-0.14002,11.36966,36.91776
46.17600,3.84805,807.60680,-0.14003,11.43686,36.93234
46.37600,3.86467,805.47510,-0.14002,11.50335,36.83485
46.57600,3.88135,805.94057,-0.14003,11.57008,36.85614
46.77600,3.89792,807.61332,-0.14003,11.63632,36.93264
46.97600,3.91466,808.24997,-0.14003,11.70329,36.96175
47.17600,3.93128,808.91838,-0.14003,11.76977,36.99232
47.37600,3.94796,810.94308,-0.14003,11.83650,37.08491
47.57600,3.96476,811.45205,-0.14003,11.90370,37.10818
47.77600,3.98126,812.28251,-0.14003,11.96971,37.14616
47.97600,3.99794,813.75195,-0.14002,12.03643,37.21336
48.17600,4.01468,814.02045,-0.14002,12.10340,37.22564
48.37600,4.03131,814.80416,-0.14003,12.16988,37.26147
48.57600,4.04799,816.12039,-0.14002,12.23661,37.32167
48.77600,4.06467,816.40957,-0.14003,12.30333,37.33489
48.97600,4.08129,817.90797,-0.14003,12.36982,37.40342
49.17600,4.09791,818.47301,-0.14002,12.43631,37.42926
49.37600,4.11459,819.33457,-0.14002,12.50303,37.46865
49.57600,4.13145,819.92056,-0.14003,12.57047,37.49545
49.77600,4.14796,820.95256,-0.14003,12.63648,37.54265
49.97600,4.16464,821.62442,-0.14003,12.70321,37.57337
50.17600,4.18138,821.58642,-0.14003,12.77017,37.57163
50.37600,4.19794,822.48403,-0.14003,12.83642,37.61268
50.57600,4.21468,823.83947,-0.14003,12.90338,37.67467
50.77600,4.23142,824.22001,-0.14003,12.97034,37.69207
50.97600,4.24798,824.90509,-0.14003,13.03659,37.72340
51.17600,4.26460,825.57304,-0.14003,13.10308,37.75394
51.37600,4.28135,825.90198,-0.14003,13.17004,37.76899
51.57600,4.29809,826.46366,-0.14003,13.23701,37.79467
51.77600,4.31459,827.34963,-0.14003,13.30301,37.83519
51.97600,4.33127,828.27499,-0.14003,13.36974,37.87751
52.17600,4.34807,828.71132,-0.14003,13.43694,37.89746
52.37600,4.36463,829.34778,-0.14003,13.50319,37.92656
52.57600,4.38131,830.05847,-0.14003,13.56991,37.95906
52.77600,4.39800,830.31580,-0.14003,13.63664,37.97083
52.97600,4.41474,831.29779,-0.14003,13.70360,38.01574
53.17600,4.43130,831.54840,-0.14003,13.76985,38.02720
53.37600,4.44798,832.11046,-0.14003,13.83658,38.05290
53.57600,4.46466,832.45430,-0.14003,13.90330,38.06863
53.77600,4.48134,833.82903,-0.14003,13.97002,38.13150
53.97600,4.49802,833.63475,-0.14003,14.03675,38.12261
54.17600,4.51464,834.24775,-0.14003,14.10324,38.15064
54.37600,4.53127,835.43807,-0.14003,14.16972,38.20508
54.57600,4.54795,834.76892,-0.14003,14.23645,38.17448
54.77600,4.56463,836.03989,-0.14003,14.30317,38.23260
54.97600,4.58137,836.40348,-0.14003,14.37014,38.24923
55.17600,4.59805,837.06081,-0.14003,14.43686,38.27929
55.37600,4.61467,837.30919,-0.14003,14.50335,38.29065
55.57600,4.63135,837.74049,-0.14003,14.57007,38.31037
55.77600,4.64804,838.39064,-0.14003,14.63680,38.34010
55.97600,4.66472,839.37999,-0.14003,14.70352,38.38535
56.17600,4.68146,839.49277,-0.14003,14.77049,38.39050
56.37600,4.69802,839.78083,-0.14003,14.83673,38.40368
56.57600,4.71458,840.19126,-0.14003,14.90298,38.42244
56.77600,4.73132,840.26838,-0.14003,14.96994,38.42597
56.97600,4.74800,841.20156,-0.14003,15.03667,38.46865
57.17600,4.76462,841.25502,-0.14003,15.10316,38.47109
57.37600,4.78131,842.11277,-0.14003,15.16988,38.51031
57.57600,4.79799,839.23936,-0.14003,15.23661,38.37891
57.77600,4.81467,840.06973,-0.14003,15.30333,38.41689
57.97600,4.83141,841.42806,-0.14003,15.37030,38.47900
58.17600,4.84809,841.84399,-0.14003,15.43702,38.49802
58.37600,4.86465,842.15105,-0.14003,15.50327,38.51207
58.57600,4.88133,842.64232,-0.14003,15.56999,38.53453
58.77600,4.89801,842.99929,-0.14003,15.63672,38.55086
58.97600,4.91464,844.36713,-0.14003,15.70320,38.61341
59.17600,4.93132,844.65537,-0.14003,15.76993,38.62659
59.37600,4.94806,844.90729,-0.14003,15.83689,38.63811
59.57600,4.96462,845.31847,-0.14003,15.90314,38.65691
59.77600,4.98130,846.01110,-0.14003,15.96986,38.68859
59.97600,4.99798,846.68435,-0.14003,16.03659,38.71938
60.17600,5.01466,846.90396,-0.14003,16.10331,38.72942
60.37600,5.03135,847.34019,-0.14003,16.17004,38.74937
60.57600,5.04797,848.10685,-0.14003,16.23652,38.78443
60.77600,5.06471,848.00543,-0.14003,16.30349,38.77979
60.97600,5.08133,849.00530,-0.14003,16.36997,38.82552
61.17600,5.09795,849.56996,-0.14003,16.43646,38.85134
61.37600,5.11469,849.26570,-0.14003,16.50343,38.83742
61.57600,5.13131,850.39875,-0.14003,16.56991,38.88924
61.77600,5.14794,850.27851,-0.14003,16.63640,38.88374
61.97600,5.16468,850.70776,-0.14003,16.70336,38.90337
62.17600,5.18136,850.97747,-0.14003,16.77009,38.91570
62.37600,5.19798,851.16262,-0.14003,16.83657,38.92417
62.57600,5.21466,851.34422,-0.14003,16.90330,38.93248
62.77600,5.23134,852.23839,-0.14003,16.97002,38.97337
62.97600,5.24796,852.74428,-0.14003,17.03651,38.99650
63.17600,5.26464,852.88398,-0.14003,17.10323,39.00289
63.37600,5.28138,852.75611,-0.14003,17.17020,38.99704
63.57600,5.29801,853.27029,-0.14003,17.23668,39.02056
63.77600,5.31469,853.35393,-0.14003,17.30341,39.02438
63.97600,5.33131,853.48627,-0.14003,17.36990,39.03043
64.17600,5.34799,854.56409,-0.14003,17.43662,39.07972
64.37600,5.36467,854.67715,-0.14003,17.50335,39.08489
64.57600,5.38135,854.45102,-0.14003,17.57007,39.07455
64.77600,5.39803,854.80260,-0.14003,17.63680,39.09063
64.97600,5.41460,855.09354,-0.14003,17.70304,39.10394
65.17600,5.43128,855.19347,-0.14003,17.76977,39.10851
65.37600,5.44802,855.53760,-0.14003,17.83673,39.12424
65.57601,5.46464,855.84391,-0.14003,17.90322,39.13825
65.77600,5.48138,856.93272,-0.14003,17.97018,39.18804
65.97601,5.49806,856.33453,-0.14003,18.03691,39.16069
66.17600,5.51462,857.11172,-0.14003,18.10315,39.19623
66.37600,5.53131,857.34939,-0.14003,18.16988,39.20710
66.57601,5.54805,857.46208,-0.14003,18.23684,39.21225
66.77600,5.56473,857.18622,-0.14003,18.30357,39.19963
66.97601,5.58135,858.10181,-0.14003,18.37005,39.24150
67.17600,5.59803,858.24551,-0.14003,18.43678,39.24807
67.37600,5.61471,857.78385,-0.14003,18.50350,39.22696
67.57601,5.63127,858.13832,-0.14003,18.56975,39.24317
67.77600,5.64795,858.43019,-0.14003,18.63648,39.25652
67.97601,5.66470,858.42125,-0.14003,18.70344,39.25611
68.17600,5.68126,858.62624,-0.14003,18.76968,39.26549
68.37600,5.69800,859.65330,-0.14003,18.83665,39.31245
68.57601,5.71462,859.53660,-0.14003,18.90314,39.30712
68.77600,5.73130,859.99751,-0.14003,18.96986,39.32819
68.97601,5.74804,859.53968,-0.14003,19.03683,39.30726
69.17600,5.76466,860.40255,-0.14003,19.10331,39.34672
69.37601,5.78140,860.59142,-0.14003,19.17028,39.35535
69.57601,5.79791,859.94890,-0.14003,19.23628,39.32597
69.77600,5.81465,860.40758,-0.14003,19.30325,39.34695
69.97601,5.83139,860.01093,-0.14003,19.37021,39.32881
70.17600,5.84795,860.62877,-0.14003,19.43646,39.35706
70.37601,5.86463,860.89009,-0.14003,19.50318,39.36901
70.57601,5.88131,861.21066,-0.14003,19.56991,39.38367
70.77600,5.89799,861.20991,-0.14003,19.63663,39.38364
70.97601,5.91468,861.09312,-0.14003,19.70336,39.37830
71.17600,5.93130,861.31049,-0.14003,19.76984,39.38824
71.37601,5.94804,861.36432,-0.14003,19.83681,39.39070
71.57601,5.96466,861.47040,-0.14003,19.90330,39.39555
71.77600,5.98134,862.43115,-0.14003,19.97002,39.43949
71.97601,5.99808,862.02295,-0.14004,20.03698,39.42082
72.17600,6.01464,862.46487,-0.14003,20.10323,39.44103
72.37601,6.03132,862.07483,-0.14003,20.16996,39.42319
72.57601,6.04801,862.88815,-0.14003,20.23668,39.46038
72.77600,6.06463,862.91069,-0.14003,20.30317,39.46142
72.97601,6.08125,862.81030,-0.14003,20.36965,39.45683
73.17600,6.09805,863.06510,-0.14004,20.43686,39.46848
73.37601,6.11479,863.07125,-0.14003,20.50382,39.46876
73.57601,6.13129,863.29998,-0.14003,20.56983,39.47922
73.77600,6.14797,863.01817,-0.14004,20.63655,39.46633
73.97601,6.16472,863.18152,-0.14003,20.70352,39.47380
74.17600,6.18134,863.31116,-0.14003,20.77001,39.47973
74.37601,6.19796,863.13160,-0.14003,20.83649,39.47152
74.57601,6.21470,863.65100,-0.14004,20.90345,39.49527
74.77600,6.23126,863.46976,-0.14004,20.96970,39.48698
74.97601,6.24794,863.94381,-0.14004,21.03643,39.50866
75.17600,6.26468,863.54185,-0.14003,21.10339,39.49028
75.37601,6.28136,863.56960,-0.14003,21.17012,39.49155
75.57601,6.29793,864.15606,-0.14003,21.23636,39.51837
75.77600,6.31461,864.02847,-0.14003,21.30308,39.51253
75.97601,6.33135,864.01766,-0.14004,21.37005,39.51204
76.17600,6.34797,864.90847,-0.14003,21.43654,39.55278
76.37601,6.36471,864.50111,-0.14003,21.50350,39.53415
76.57601,6.38145,864.30386,-0.14003,21.57046,39.52513
76.77600,6.39789,864.54917,-0.14003,21.63623,39.53635
76.97601,6.41458,864.10213,-0.14004,21.70296,39.51590
77.17600,6.43138,864.40509,-0.14003,21.77016,39.52975
77.37601,6.44800,864.29697,-0.14004,21.83665,39.52481
77.57601,6.46468,864.48817,-0.14004,21.90337,39.53355
77.77600,6.48136,864.55792,-0.14003,21.97010,39.53675
77.97601,6.49798,865.03467,-0.14004,22.03659,39.55855
78.17600,6.51454,864.71504,-0.14003,22.10283,39.54393
78.37601,6.53128,864.93790,-0.14004,22.16979,39.55412
78.57601,6.54815,864.68868,-0.14003,22.23724,39.54272
78.77600,6.56471,865.17837,-0.14004,22.30348,39.56512
78.97601,6.58127,864.46563,-0.14004,22.36973,39.53252
79.17600,6.59807,864.44719,-0.14004,22.43693,39.53168
79.37601,6.61463,865.05301,-0.14003,22.50318,39.55939
79.57601,6.63125,864.97515,-0.14003,22.56967,39.55582
79.77600,6.64811,864.94237,-0.14003,22.63711,39.55433
79.97601,6.66473,864.66847,-0.14004,22.70360,39.54180
80.17600,6.68124,865.40123,-0.14004,22.76960,39.57531
80.37601,6.69792,865.14084,-0.14004,22.83633,39.56340
80.57601,6.71478,864.84086,-0.14003,22.90377,39.54968
80.77600,6.73128,864.92207,-0.14003,22.96978,39.55340
80.97601,6.74790,865.38279,-0.14004,23.03627,39.57447
81.17600,6.76470,865.02600,-0.14003,23.10347,39.55815
81.37601,6.78126,865.43867,-0.14004,23.16972,39.57702
81.57601,6.79795,865.08337,-0.14004,23.23644,39.56078
81.77600,6.81481,865.12184,-0.14004,23.30388,39.56253
81.97601,6.83131,864.91769,-0.14003,23.36989,39.55320
82.17600,6.84793,865.07071,-0.14004,23.43637,39.56020
82.37601,6.86461,865.25772,-0.14004,23.50310,39.56875
82.57601,6.88135,865.43811,-0.14004,23.57006,39.57700
82.77600,6.89803,865.34629,-0.14003,23.63679,39.57280
82.97601,6.91465,865.21795,-0.14004,23.70328,39.56693
83.17600,6.93134,865.17874,-0.14004,23.77000,39.56514
83.37601,6.94796,865.38652,-0.14004,23.83649,39.57464
83.57601,6.96458,865.30084,-0.14003,23.90298,39.57072
83.77600,6.98132,864.73152,-0.14004,23.96994,39.54469
83.97601,6.99800,864.52775,-0.14003,24.03666,39.53537
84.17600,7.01468,865.00701,-0.14004,24.10339,39.55728
84.37601,7.03130,864.81059,-0.14004,24.16987,39.54830
84.57601,7.04799,864.51424,-0.14004,24.23660,39.53475
84.77600,7.06467,864.87252,-0.14004,24.30332,39.55113
84.97601,7.08135,864.71559,-0.14004,24.37005,39.54396
85.17600,7.09809,865.59551,-0.14004,24.43701,39.58419
85.37601,7.11459,865.15713,-0.14004,24.50302,39.56415
85.57601,7.13133,863.82590,-0.14004,24.56999,39.50327
85.77600,7.14801,864.16956,-0.14004,24.63671,39.51899
85.97601,7.16463,864.63206,-0.14004,24.70319,39.54013
86.17600,7.18126,864.42716,-0.14004,24.76968,39.53077
86.37601,7.19800,864.49981,-0.14003,24.83665,39.53409
86.57601,7.21468,864.23559,-0.14004,24.90337,39.52201
86.77600,7.23124,864.37566,-0.14003,24.96962,39.52841
86.97601,7.24798,864.44244,-0.14004,25.03658,39.53146
87.17600,7.26478,864.32947,-0.14004,25.10378,39.52630
87.37601,7.28128,863.91922,-0.14004,25.16980,39.50754
87.57601,7.29796,863.68704,-0.14003,25.23652,39.49692
87.77600,7.31477,864.21920,-0.14004,25.30372,39.52126
87.97601,7.33133,863.49575,-0.14004,25.36997,39.48817
88.17600,7.34795,863.32392,-0.14004,25.43645,39.48031
88.37601,7.36463,863.65556,-0.14004,25.50318,39.49548
88.57601,7.38131,863.60732,-0.14003,25.56990,39.49327
88.77600,7.39793,863.67056,-0.14004,25.63639,39.49617
88.97601,7.41467,863.50143,-0.14004,25.70335,39.48843
89.17600,7.43142,863.22706,-0.14004,25.77032,39.47588
89.37601,7.44798,863.35661,-0.14004,25.83657,39.48181
89.57601,7.46466,863.05933,-0.14004,25.90329,39.46822
89.77600,7.48134,863.33696,-0.14003,25.97002,39.48091
89.97601,7.49802,863.00755,-0.14004,26.03674,39.46585
90.17600,7.51476,862.72852,-0.14003,26.10371,39.45309
90.37601,7.53138,863.13374,-0.14004,26.17019,39.47162
90.57601,7.54801,862.84773,-0.14004,26.23668,39.45854
90.77600,7.56469,862.80471,-0.14003,26.30340,39.45657
90.97601,7.58131,863.17742,-0.14004,26.36989,39.47361
91.17600,7.59799,861.48949,-0.14004,26.43661,39.39642
91.37601,7.61467,862.07753,-0.14004,26.50334,39.42332
91.57601,7.63123,862.21574,-0.14004,26.56958,39.42964
91.77600,7.64797,862.03441,-0.14004,26.63655,39.42134
91.97601,7.66465,861.51483,-0.14004,26.70327,39.39758
92.17600,7.68134,862.14030,-0.14004,26.77000,39.42619
92.37601,7.69802,862.00759,-0.14004,26.83672,39.42012
92.57601,7.71470,861.83706,-0.14004,26.90345,39.41232
92.77600,7.73132,861.11380,-0.14004,26.96994,39.37924
92.97601,7.74800,861.33005,-0.14004,27.03666,39.38913
93.17600,7.76468,861.58188,-0.14004,27.10339,39.40065
93.37601,7.78124,861.46016,-0.14004,27.16963,39.39508
93.57601,7.79798,861.10383,-0.14004,27.23660,39.37879
93.77600,7.81472,861.02476,-0.14004,27.30356,39.37517
93.97601,7.83129,860.69815,-0.14004,27.36980,39.36024
94.17600,7.84797,860.65577,-0.14004,27.43653,39.35830
94.37601,7.86471,860.22643,-0.14004,27.50349,39.33867
94.57601,7.88139,860.61908,-0.14004,27.57022,39.35662
94.77600,7.89801,860.20296,-0.14004,27.63671,39.33759
94.97601,7.91469,860.03579,-0.14004,27.70343,39.32994
95.17600,7.93132,859.88548,-0.14004,27.76992,39.32307
95.37601,7.94800,859.66634,-0.14004,27.83664,39.31305
95.57601,7.96462,859.90541,-0.14004,27.90313,39.32398
95.77600,7.98136,859.68040,-0.14004,27.97010,39.31369
95.97601,7.99798,858.96393,-0.14004,28.03658,39.28093
96.17600,8.01466,859.35658,-0.14004,28.10330,39.29889
96.37601,8.03134,859.41721,-0.14004,28.17003,39.30166
96.57601,8.04796,858.25091,-0.14004,28.23652,39.24832
96.77600,8.06465,858.63126,-0.14004,28.30324,39.26572
96.97601,8.08127,858.41166,-0.14004,28.36972,39.25567
97.17600,8.09801,858.19894,-0.14004,28.43669,39.24594
97.37601,8.11457,857.81356,-0.14004,28.50294,39.22832
97.57601,8.13131,858.33101,-0.14004,28.56990,39.25198
97.77600,8.14799,858.02181,-0.14004,28.63663,39.23785
97.97601,8.16473,857.35135,-0.14004,28.70359,39.20718
98.17600,8.18136,857.14385,-0.14004,28.77008,39.19770
98.37601,8.19804,857.36876,-0.14004,28.83680,39.20798
98.57601,8.21466,856.95377,-0.14004,28.90329,39.18900
98.77600,8.23128,856.07450,-0.14004,28.96977,39.14879
98.97601,8.24802,856.25937,-0.14004,29.03674,39.15725
99.17600,8.26470,856.11586,-0.14004,29.10346,39.15068
99.37601,8.28132,856.29662,-0.14004,29.16995,39.15895
99.57601,8.29788,855.69741,-0.14004,29.23619,39.13155
99.77600,8.31468,855.44335,-0.14003,29.30340,39.11993
99.97601,8.33137,855.61462,-0.14004,29.37012,39.12776
100.17600,8.34799,855.67227,-0.14004,29.43661,39.13040
100.37601,8.36473,854.90514,-0.14004,29.50357,39.09532
100.57601,8.38129,854.41172,-0.14004,29.56982,39.07275
100.77600,8.39791,854.57563,-0.14004,29.63631,39.08025
100.97601,8.41477,854.43864,-0.14004,29.70375,39.07399
101.17600,8.43133,854.12338,-0.14004,29.77000,39.05957
101.37601,8.44796,853.80124,-0.14004,29.83648,39.04484
101.57601,8.46470,853.53507,-0.14004,29.90345,39.03267
101.77601,8.48138,853.57325,-0.14004,29.97017,39.03441
101.97601,8.49788,853.35048,-0.14004,30.03618,39.02422
102.17600,8.51462,852.60570,-0.14004,30.10314,38.99016
102.37601,8.53136,852.59462,-0.14004,30.17011,38.98966
102.57601,8.54798,852.46023,-0.14004,30.23659,38.98351
102.77601,8.56461,851.92490,-0.14004,30.30308,38.95903
102.97601,8.58141,851.39731,-0.14004,30.37028,38.93490
103.17600,8.59803,851.56197,-0.14004,30.43677,38.94243
103.37601,8.61471,851.47796,-0.14004,30.50349,38.93859
103.57601,8.63139,850.81104,-0.14004,30.57022,38.90809
103.77601,8.64801,850.62347,-0.14004,30.63670,38.89951
103.97601,8.66463,850.38133,-0.14004,30.70319,38.88844
104.17600,8.68125,850.59786,-0.14004,30.76968,38.89834
104.37601,8.69806,849.37317,-0.14004,30.83688,38.84234
104.57601,8.71456,849.01415,-0.14004,30.90289,38.82592
104.77601,8.73124,849.68107,-0.14004,30.96961,38.85642
104.97601,8.74804,848.91077,-0.14004,31.03682,38.82119
105.17600,8.76466,848.58201,-0.14004,31.10330,38.80616
105.37601,8.78134,847.82345,-0.14004,31.17003,38.77147
105.57601,8.79808,848.03021,-0.14004,31.23699,38.78092
105.77601,8.81465,847.77949,-0.14004,31.30324,38.76946
105.97601,8.83127,846.87946,-0.14004,31.36972,38.72830
106.17600,8.84795,847.32054,-0.14004,31.43645,38.74847
106.37601,8.86475,846.91197,-0.14004,31.50365,38.72979
106.57601,8.88131,845.37053,-0.14004,31.56990,38.65929
106.77601,8.89793,845.41440,-0.14004,31.63638,38.66130
106.97601,8.91467,844.83968,-0.14004,31.70335,38.63502
107.17600,8.93123,844.94995,-0.14004,31.76959,38.64006
107.37601,8.94798,844.38231,-0.14004,31.83656,38.61410
107.57601,8.96484,844.18543,-0.14004,31.90400,38.60510
107.77601,8.98128,843.58519,-0.14004,31.96977,38.57765
107.97601,8.99790,842.96195,-0.14004,32.03626,38.54915
108.17600,9.01470,842.69345,-0.14004,32.10346,38.53687
108.37601,9.03138,842.07682,-0.14004,32.17018,38.50867
108.57601,9.04800,842.02150,-0.14004,32.23667,38.50614
108.77601,9.06468,841.22075,-0.14004,32.30340,38.46952
108.97601,9.08137,841.17902,-0.14004,32.37012,38.46761
109.17600,9.09793,839.82190,-0.14004,32.43637,38.40555
109.37601,9.11467,839.61682,-0.14004,32.50333,38.39618
109.57601,9.13147,840.01943,-0.14004,32.57054,38.41459
109.77601,9.14797,838.88117,-0.14004,32.63654,38.36253
109.97601,9.16453,838.52168,-0.14004,32.70279,38.34609
110.17600,9.18139,838.14505,-0.14004,32.77023,38.32887
110.37601,9.19802,836.99999,-0.14004,32.83672,38.27650
110.57601,9.21464,837.23944,-0.14004,32.90321,38.28746
110.77601,9.23138,837.19911,-0.14004,32.97017,38.28561
110.97601,9.24800,836.22281,-0.14004,33.03666,38.24096
111.17600,9.26462,835.14880,-0.14004,33.10314,38.19185
111.37601,9.28130,834.63583,-0.14004,33.16987,38.16839
111.57601,9.29804,834.54531,-0.14004,33.23683,38.16425
111.77601,9.31461,833.68830,-0.14004,33.30308,38.12506
111.97601,9.33135,833.12085,-0.14004,33.37004,38.09911
112.17600,9.34803,832.50217,-0.14004,33.43677,38.07082
112.37601,9.36459,831.85649,-0.14004,33.50301,38.04129
112.57601,9.38133,831.42556,-0.14004,33.56998,38.02158
112.77601,9.39801,830.73247,-0.14004,33.63670,37.98989
112.97601,9.41475,830.05307,-0.14004,33.70367,37.95882
113.17600,9.43131,828.59611,-0.14004,33.76991,37.89219
113.37601,9.44800,828.72668,-0.14004,33.83664,37.89816
113.57601,9.46474,828.34847,-0.14004,33.90360,37.88087
113.77601,9.48130,827.44500,-0.14004,33.96985,37.83955
113.97601,9.49804,826.16238,-0.14004,34.03682,37.78090
114.17600,9.51466,825.77672,-0.14004,34.10330,37.76326
114.37601,9.53128,825.63823,-0.14004,34.16979,37.75692
114.57601,9.54790,824.81103,-0.14004,34.23627,37.71910
114.77601,9.56476,823.30871,-0.14004,34.30371,37.65039
114.97601,9.58139,823.20292,-0.14004,34.37020,37.64556
115.17600,9.59795,822.33325,-0.14004,34.43644,37.60579
115.37601,9.61463,821.15224,-0.14004,34.50317,37.55178
115.57601,9.63137,820.78837,-0.14004,34.57014,37.53514
115.77601,9.64793,819.68606,-0.14004,34.63638,37.48473
115.97601,9.66473,818.30481,-0.14004,34.70359,37.42156
116.17600,9.68141,817.70932,-0.14004,34.77031,37.39433
116.37601,9.69797,816.66159,-0.14004,34.83656,37.34642
116.57601,9.71460,815.89092,-0.14004,34.90305,37.31118
116.77601,9.73140,814.73999,-0.14004,34.97024,37.25854
116.97601,9.74802,814.37333,-0.14004,35.03674,37.24178
117.17600,9.76464,813.14771,-0.14004,35.10322,37.18573
117.37601,9.78132,812.29461,-0.14004,35.16994,37.14671
117.57601,9.79794,811.19761,-0.14004,35.23643,37.09655
117.77601,9.81462,810.34396,-0.14004,35.30315,37.05751
117.97601,9.83131,809.79625,-0.14004,35.36988,37.03246
118.17600,9.84799,808.42543,-0.14004,35.43660,36.96977
118.37601,9.86467,806.68619,-0.14004,35.50333,36.89024
118.57601,9.88129,806.20414,-0.14004,35.56982,36.86819
118.77601,9.89803,804.41292,-0.14004,35.63678,36.78628
118.97601,9.91471,803.63201,-0.14004,35.70351,36.75057
119.17600,9.93139,801.94930,-0.14004,35.77023,36.67361
119.37601,9.94807,801.22650,-0.14004,35.83696,36.64056
119.57601,9.96470,799.65806,-0.14004,35.90344,36.56884
119.77601,9.98132,798.28342,-0.14004,35.96992,36.50597
119.97601,9.99794,796.60621,-0.14004,36.03641,36.42927
120.17600,10.01468,795.25737,-0.14004,36.10338,36.36759
120.37601,10.03124,794.07347,-0.14004,36.16962,36.31345
120.57601,10.04798,791.62046,-0.14004,36.23659,36.20127
120.77601,10.06466,789.79377,-0.14004,36.30331,36.11774
120.97601,10.08134,787.78844,-0.14004,36.37004,36.02603
121.17600,10.09797,785.33869,-0.14004,36.43652,35.91400
121.37601,10.11471,782.99697,-0.14004,36.50349,35.80692
121.57601,10.13133,779.57665,-0.14004,36.56997,35.65050
121.77601,10.14801,777.17905,-0.14004,36.63670,35.54086
121.97601,10.16463,774.77656,-0.14004,36.70319,35.43099
122.17600,10.18137,771.76611,-0.14004,36.77015,35.29332
122.37601,10.19799,768.14252,-0.14004,36.83663,35.12761
122.57601,10.21462,765.17621,-0.14004,36.90312,34.99196
122.77601,10.23136,760.41091,-0.14004,36.97009,34.77404
122.97601,10.24792,756.04334,-0.14004,37.03633,34.57431
123.17600,10.26460,750.94104,-0.14004,37.10306,34.34098
123.37601,10.28140,744.47948,-0.14004,37.17026,34.04549
123.57601,10.29802,731.35104,-0.14004,37.23674,33.44511
123.72201,10.31022,3.07399,-0.14004,37.28554,0.14058