File: Manufatura Aditiva/Classificação Orientação/Ensaios/Ensaios FDM/Tracao_OLABI_23_05_2018_FDM_YX2.is_metal_RawData/Specimen_RawData_3.csv
Time,Extension,Load,Strain 1,Tensile strain,Tensile stress
(sec),(mm),(N),(mm/mm),(%),(MPa)
0.00000,0.00006,18.32835,0.00053,0.05320,0.92504
0.10000,0.00430,19.57399,0.00056,0.05648,0.98791
0.20000,0.01393,23.67470,0.00070,0.07046,1.19488
0.30000,0.02356,28.22711,0.00085,0.08548,1.42464
0.40000,0.03265,32.48936,0.00100,0.10004,1.63976
0.50000,0.04143,36.13491,0.00114,0.11415,1.82375
0.60000,0.04986,40.03209,0.00128,0.12783,2.02045
0.70000,0.05829,42.94634,0.00141,0.14112,2.16753
0.80000,0.06667,46.95925,0.00154,0.15433,2.37006
0.90000,0.07498,50.93439,0.00168,0.16789,2.57069
1.00000,0.08329,54.89382,0.00181,0.18124,2.77053
1.10000,0.09172,57.90037,0.00195,0.19495,2.92227
1.20000,0.10003,61.57713,0.00209,0.20851,3.10784
1.30000,0.10834,64.72346,0.00222,0.22217,3.26663
1.40000,0.11671,68.62016,0.00236,0.23622,3.46330
1.50000,0.12508,72.31977,0.00250,0.24955,3.65003
1.60000,0.13339,75.61820,0.00264,0.26421,3.81650
1.70000,0.14164,80.03646,0.00278,0.27793,4.03949
1.80000,0.14995,82.75155,0.00291,0.29110,4.17652
1.90000,0.15832,86.65103,0.00305,0.30549,4.37333
2.00000,0.16657,90.25598,0.00319,0.31926,4.55528
2.10000,0.17494,93.53720,0.00334,0.33400,4.72088
2.20000,0.18331,96.84918,0.00348,0.34761,4.88804
2.30000,0.19157,100.53876,0.00362,0.36178,5.07426
2.40000,0.19994,103.32618,0.00376,0.37625,5.21494
2.50000,0.20837,108.47586,0.00390,0.39049,5.47485
2.60000,0.21668,110.63638,0.00405,0.40450,5.58389
2.70000,0.22499,114.40916,0.00419,0.41873,5.77430
2.80000,0.23330,117.52588,0.00433,0.43326,5.93161
2.90000,0.24161,121.42460,0.00448,0.44787,6.12838
3.00000,0.24998,125.05041,0.00462,0.46235,6.31137
3.10000,0.25841,127.55877,0.00477,0.47708,6.43797
3.20000,0.26672,131.69775,0.00492,0.49157,6.64687
3.30000,0.27503,135.28845,0.00506,0.50596,6.82809
3.40000,0.28340,138.61627,0.00521,0.52062,6.99605
3.50000,0.29165,141.47675,0.00535,0.53475,7.14042
3.60000,0.30002,145.41594,0.00550,0.54965,7.33924
3.70000,0.30839,148.73928,0.00564,0.56412,7.50697
3.80000,0.31670,152.12942,0.00579,0.57887,7.67807
3.90000,0.32502,155.38939,0.00593,0.59327,7.84260
4.00000,0.33333,158.97858,0.00608,0.60811,8.02375
4.10000,0.34164,162.32233,0.00623,0.62277,8.19251
4.20000,0.35001,165.67977,0.00638,0.63793,8.36196
4.30000,0.35826,169.08965,0.00653,0.65254,8.53406
4.40000,0.36663,172.57767,0.00667,0.66710,8.71010
4.50000,0.37500,175.56993,0.00682,0.68225,8.86113
4.60000,0.38331,179.21583,0.00697,0.69711,9.04514
4.70000,0.39162,182.96088,0.00712,0.71166,9.23415
4.80000,0.40005,186.03003,0.00727,0.72711,9.38905
4.90000,0.40836,189.94268,0.00742,0.74206,9.58653
5.00000,0.41661,192.77192,0.00757,0.75712,9.72932
5.10000,0.42510,196.41586,0.00772,0.77224,9.91323
5.20000,0.43329,199.48746,0.00787,0.78719,10.06826
5.30000,0.44161,202.85682,0.00802,0.80177,10.23831
5.40000,0.45004,205.05621,0.00811,0.81086,10.34932
5.50000,0.45829,208.61675,0.00826,0.82581,10.52902
5.60000,0.46666,211.33197,0.00841,0.84097,10.66606
5.70000,0.47509,215.57268,0.00857,0.85654,10.88009
5.80000,0.48328,217.95284,0.00871,0.87086,11.00022
5.90000,0.49165,221.63612,0.00886,0.88624,11.18612
6.00000,0.50002,225.00104,0.00901,0.90130,11.35595
6.10000,0.50827,228.88542,0.00916,0.91636,11.55199
6.20000,0.51670,231.64025,0.00931,0.93110,11.69103
6.30000,0.52501,235.13210,0.00947,0.94690,11.86727
6.40000,0.53332,238.32368,0.00962,0.96166,12.02835
6.50000,0.54169,242.21528,0.00977,0.97687,12.22476
6.60000,0.55000,245.43386,0.00993,0.99254,12.38720
6.70000,0.55825,249.26292,0.01007,1.00707,12.58046
6.80000,0.56680,252.07615,0.01023,1.02308,12.72244
6.90000,0.57506,255.64362,0.01038,1.03837,12.90250
7.00000,0.58331,258.73634,0.01053,1.05345,13.05859
7.10000,0.59180,262.24789,0.01069,1.06899,13.23582
7.20000,0.59993,265.37124,0.01084,1.08376,13.39346
7.30000,0.60824,269.42568,0.01099,1.09905,13.59809
7.40000,0.61673,272.09278,0.01115,1.11465,13.73270
7.50000,0.62492,275.48254,0.01130,1.12985,13.90378
7.60000,0.63329,278.51607,0.01145,1.14540,14.05688
7.70000,0.64166,282.34289,0.01161,1.16077,14.25003
7.80000,0.64997,285.28727,0.01176,1.17611,14.39863
7.90000,0.65834,288.88239,0.01191,1.19130,14.58008
8.00000,0.66671,292.14704,0.01207,1.20683,14.74485
8.10000,0.67496,295.28190,0.01222,1.22161,14.90307
8.20000,0.68327,298.88027,0.01237,1.23685,15.08468
8.30000,0.69164,301.71964,0.01253,1.25255,15.22798
8.40000,0.69996,305.42857,0.01268,1.26802,15.41517
8.50000,0.70833,307.97545,0.01283,1.28332,15.54372
8.60000,0.71664,311.61145,0.01299,1.29873,15.72723
8.70000,0.72495,314.63064,0.01314,1.31425,15.87961
8.80000,0.73338,317.72547,0.01329,1.32917,16.03581
8.90000,0.74169,320.46973,0.01345,1.34481,16.17431
9.00000,0.75000,324.02889,0.01360,1.36033,16.35394
9.10000,0.75843,327.78773,0.01376,1.37600,16.54366
9.20000,0.76662,330.67984,0.01391,1.39101,16.68962
9.30000,0.77493,333.73472,0.01407,1.40670,16.84381
9.40000,0.78336,337.17954,0.01422,1.42228,17.01767
9.50000,0.79167,338.94579,0.01432,1.43170,17.10681
9.60000,0.79992,342.08831,0.01448,1.44782,17.26542
9.70000,0.80835,345.39765,0.01463,1.46303,17.43244
9.80000,0.81666,348.26330,0.01479,1.47879,17.57707
9.90000,0.82498,351.57821,0.01494,1.49359,17.74438
10.00000,0.83341,354.44237,0.01510,1.50975,17.88893
10.10000,0.84172,357.44773,0.01526,1.52562,18.04062
10.20000,0.85003,360.64831,0.01541,1.54068,18.20215
10.30000,0.85840,364.14042,0.01557,1.55659,18.37840
10.40000,0.86665,367.55665,0.01572,1.57195,18.55082
10.50000,0.87496,369.75725,0.01587,1.58743,18.66188
10.60000,0.88333,373.38776,0.01603,1.60309,18.84512
10.70000,0.89158,375.66177,0.01616,1.61604,18.95989
10.80000,0.89995,378.65809,0.01631,1.63146,19.11112
10.90000,0.90832,381.70246,0.01647,1.64724,19.26477
11.00000,0.91663,384.69611,0.01663,1.66273,19.41586
11.10000,0.92506,387.61564,0.01679,1.67870,19.56321
11.20000,0.93331,390.57482,0.01694,1.69410,19.71256
11.30000,0.94168,393.77399,0.01710,1.70983,19.87403
11.40000,0.95011,397.32330,0.01726,1.72560,20.05316
11.50000,0.95825,400.03611,0.01741,1.74108,20.19008
11.60000,0.96656,402.69946,0.01757,1.75696,20.32450
11.70000,0.97505,406.34256,0.01773,1.77274,20.50837
11.80000,0.98324,409.58035,0.01789,1.78867,20.67178
11.90000,0.99161,412.37739,0.01804,1.80440,20.81295
12.00000,1.00010,415.53150,0.01820,1.82018,20.97214
12.10000,1.00829,418.10325,0.01836,1.83597,21.10194
12.20000,1.01666,421.03999,0.01851,1.85127,21.25016
12.30000,1.02509,424.56225,0.01867,1.86738,21.42793
12.40000,1.03328,427.59320,0.01883,1.88307,21.58090
12.50000,1.04165,430.46633,0.01899,1.89898,21.72591
12.60000,1.05002,433.66197,0.01915,1.91494,21.88720
12.70000,1.05827,436.28491,0.01931,1.93096,22.01958
12.80000,1.06670,439.41783,0.01947,1.94677,22.17770
12.90000,1.07502,442.56784,0.01963,1.96257,22.33668
13.00000,1.08327,444.08152,0.01973,1.97257,22.41308
13.10000,1.09170,447.06305,0.01989,1.98865,22.56356
13.20000,1.10001,449.92901,0.02005,2.00460,22.70820
13.30000,1.10832,453.82194,0.02020,2.02025,22.90468
13.40000,1.11675,456.15202,0.02036,2.03649,23.02228
13.50000,1.12506,459.22468,0.02052,2.05203,23.17736
13.60000,1.13325,462.28757,0.02068,2.06774,23.33195
13.70000,1.14174,465.45668,0.02084,2.08412,23.49190
13.80000,1.14993,468.10922,0.02100,2.09984,23.62577
13.90000,1.15824,471.26277,0.02116,2.11594,23.78493
14.00000,1.16679,474.12184,0.02132,2.13205,23.92923
14.10000,1.17492,476.53476,0.02148,2.14795,24.05101
14.20000,1.18329,480.08449,0.02164,2.16357,24.23017
14.30000,1.19172,482.80009,0.02180,2.17980,24.36723
14.40000,1.19998,485.80565,0.02196,2.19604,24.51892
14.50000,1.20841,488.25233,0.02212,2.21206,24.64241
14.60000,1.21672,491.15354,0.02228,2.22836,24.78883
14.70000,1.22497,494.50477,0.02244,2.24414,24.95797
14.80000,1.23334,497.42102,0.02260,2.25987,25.10516
14.90000,1.24165,500.53140,0.02276,2.27616,25.26214
15.00000,1.24996,503.23089,0.02292,2.29203,25.39838
15.10000,1.25833,506.49145,0.02308,2.30816,25.56295
15.20000,1.26664,508.37738,0.02324,2.32416,25.65813
15.30000,1.27495,511.35239,0.02341,2.34051,25.80828
15.40000,1.28338,514.44611,0.02357,2.35650,25.96442
15.50000,1.29169,517.43118,0.02373,2.37283,26.11508
15.60000,1.30000,519.64852,0.02388,2.38847,26.22699
15.70000,1.30831,522.20272,0.02405,2.40457,26.35591
15.80000,1.31656,525.31254,0.02421,2.42064,26.51286
15.90000,1.32488,528.25976,0.02437,2.43655,26.66161
16.00000,1.33337,531.33294,0.02453,2.45273,26.81671
16.10000,1.34156,534.17748,0.02469,2.46873,26.96028
16.20000,1.34993,535.32636,0.02479,2.47909,27.01826
16.30000,1.35842,537.72680,0.02495,2.49535,27.13942
16.40000,1.36667,540.73329,0.02511,2.51125,27.29115
16.50000,1.37504,543.28092,0.02528,2.52755,27.41973
16.60000,1.38341,546.31447,0.02544,2.54402,27.57284
16.70000,1.39166,548.61340,0.02560,2.56029,27.68887
16.80000,1.40003,551.15251,0.02577,2.57662,27.81702
16.90000,1.40840,553.85320,0.02593,2.59289,27.95333
17.00000,1.41671,556.65546,0.02609,2.60904,28.09476
17.10000,1.42502,558.84467,0.02626,2.62561,28.20525
17.20000,1.43333,561.95087,0.02642,2.64185,28.36202
17.30000,1.44164,564.71867,0.02657,2.65684,28.50171
17.40000,1.45001,567.14858,0.02673,2.67265,28.62435
17.50000,1.45839,569.81049,0.02689,2.68910,28.75870
17.60000,1.46670,573.05400,0.02706,2.70556,28.92240
17.70000,1.47507,575.24922,0.02722,2.72224,29.03320
17.80000,1.48338,577.66819,0.02739,2.73859,29.15528
17.90000,1.49163,580.23366,0.02755,2.75486,29.28476
18.00000,1.49994,583.24765,0.02771,2.77143,29.43688
18.10000,1.50825,585.36734,0.02788,2.78789,29.54386
18.20000,1.51656,588.19028,0.02804,2.80380,29.68634
18.30000,1.52505,589.72565,0.02821,2.82070,29.76383
18.40000,1.53324,593.13383,0.02837,2.83667,29.93584
18.50000,1.54167,595.21147,0.02853,2.85317,30.04070
18.60000,1.55004,597.84362,0.02870,2.87011,30.17355
18.70000,1.55829,601.17943,0.02887,2.88679,30.34191
18.80000,1.56666,603.08226,0.02903,2.90257,30.43795
18.90000,1.57497,605.86273,0.02920,2.91956,30.57828
19.00000,1.58329,608.59635,0.02936,2.93586,30.71625
19.10000,1.59160,610.87548,0.02953,2.95289,30.83128
19.20000,1.60003,612.78371,0.02963,2.96286,30.92759
19.30000,1.60834,614.44347,0.02980,2.97966,31.01135
19.40000,1.61665,617.17662,0.02997,2.99656,31.14930
19.50000,1.62502,619.54763,0.03013,3.01313,31.26896
19.60000,1.63333,621.74047,0.03030,3.02998,31.37964
19.70000,1.64176,624.51293,0.03047,3.04653,31.51957
19.80000,1.65007,627.60049,0.03063,3.06316,31.67540
19.90000,1.65838,629.29085,0.03080,3.08020,31.76071
20.00000,1.66675,632.53087,0.03097,3.11368,31.92424
20.10000,1.67500,634.32083,0.03114,3.14668,32.01458
20.19800,1.68313,636.53751,0.03130,3.17921,32.12645
20.29800,1.69156,638.81590,0.03147,3.21293,32.24145
20.39800,1.69982,641.95204,0.03164,3.24593,32.39973
20.49800,1.70813,643.74702,0.03181,3.27917,32.49032
20.59800,1.71656,645.93838,0.03198,3.31290,32.60092
20.69800,1.72481,648.66352,0.03215,3.34590,32.73846
20.79800,1.73312,650.97446,0.03232,3.37914,32.85509
20.89800,1.74155,653.57615,0.03249,3.41286,32.98640
20.99800,1.74986,655.57975,0.03266,3.44611,33.08753
21.09800,1.75811,658.56902,0.03282,3.47911,33.23840
21.19800,1.76654,660.42901,0.03300,3.51283,33.33228
21.29800,1.77479,662.98647,0.03317,3.54584,33.46135
21.39800,1.78316,665.67603,0.03334,3.57932,33.59710
21.49800,1.79153,667.09900,0.03351,3.61280,33.66891
21.59800,1.79984,669.58941,0.03368,3.64604,33.79461
21.69800,1.80815,672.23413,0.03385,3.67929,33.92809
21.79800,1.81652,674.69785,0.03403,3.71277,34.05243
21.89800,1.82489,676.90825,0.03419,3.74625,34.16399
21.99800,1.83327,678.97891,0.03433,3.77973,34.26850
22.09800,1.84152,680.60313,0.03448,3.81274,34.35048
22.19800,1.84983,682.02470,0.03465,3.84598,34.42222
22.29800,1.85820,684.16339,0.03481,3.87946,34.53016
22.39800,1.86651,687.12020,0.03499,3.91270,34.67939
22.49800,1.87482,689.24129,0.03516,3.94595,34.78645
22.59800,1.88319,691.70571,0.03534,3.97943,34.91083
22.69800,1.89150,693.86349,0.03551,4.01267,35.01973
22.79800,1.89975,696.38751,0.03568,4.04568,35.14712
22.89800,1.90818,698.85617,0.03604,4.07940,35.27172
22.99800,1.91643,700.15937,0.03535,4.11240,35.33749
23.09800,1.92480,702.00916,0.03544,4.14588,35.43085
23.19800,1.93311,704.13556,0.02913,4.17913,35.53817
23.29800,1.94142,706.65986,-0.00849,4.21237,35.66557
23.39800,1.94980,708.96139,-0.05559,4.24585,35.78173
23.49800,1.95811,710.37188,-0.04766,4.27909,35.85292
23.59800,1.96642,713.07127,-0.04388,4.31234,35.98916
23.69800,1.97479,714.65652,-0.09016,4.34582,36.06917
23.79800,1.98310,716.52108,-0.18805,4.37906,36.16328
23.89800,1.99153,718.57739,-0.17452,4.41278,36.26706
23.99800,1.99990,720.72265,-0.15601,4.44627,36.37533
24.09800,2.00815,722.84192,-0.17753,4.47927,36.48229
24.19800,2.01652,724.96566,-0.15379,4.51275,36.58948
24.29800,2.02483,726.53689,-0.15403,4.54599,36.66878
24.39800,2.03320,728.93212,-0.15909,4.57948,36.78967
24.49800,2.04151,731.25460,-0.20452,4.61272,36.90689
24.59800,2.04982,733.13229,-0.32195,4.64596,37.00166
24.69800,2.05819,734.56625,-0.31852,4.67944,37.07403
24.79800,2.06650,736.42018,-0.31868,4.71269,37.16760
24.89800,2.07487,738.27873,-0.31864,4.74617,37.26140
24.99800,2.08319,739.58528,-0.31864,4.77941,37.32734
25.09800,2.09150,742.20248,-0.31865,4.81266,37.45943
25.19800,2.09993,743.01600,-0.31865,4.84638,37.50049
25.29800,2.10818,745.58617,-0.31865,4.87938,37.63021
25.39800,2.11655,746.52531,-0.31865,4.91286,37.67761
25.49800,2.12486,749.42787,-0.31865,4.94611,37.82410
25.59800,2.13317,751.10751,-0.31865,4.97935,37.90887
25.69800,2.14148,753.52807,-0.31865,5.01259,38.03104
25.79800,2.14979,754.80430,-0.31865,5.04583,38.09546
25.89800,2.15816,756.90090,-0.31865,5.07932,38.20127
25.99800,2.16647,758.21974,-0.31865,5.11256,38.26783
26.09800,2.17484,760.04062,-0.31866,5.14604,38.35973
26.19800,2.18321,762.90015,-0.31866,5.17952,38.50406
26.29800,2.19146,764.03837,-0.31866,5.21253,38.56150
26.39800,2.19983,765.82306,-0.31866,5.24601,38.65158
26.49800,2.20815,767.48682,-0.31866,5.27925,38.73555
26.59800,2.21646,769.31478,-0.31866,5.31250,38.82781
26.69800,2.22483,770.78519,-0.31866,5.34598,38.90202
26.79800,2.23314,772.85273,-0.31866,5.37922,39.00637
26.89800,2.24151,774.13581,-0.31866,5.41270,39.07113
26.99800,2.24976,776.40731,-0.31866,5.44571,39.18577
27.09800,2.25813,778.19065,-0.31866,5.47919,39.27578
27.19800,2.26656,779.53669,-0.31867,5.51291,39.34372
27.29800,2.27487,781.97168,-0.31866,5.54615,39.46661
27.39800,2.28318,782.88158,-0.31867,5.57940,39.51254
27.49800,2.29155,784.52975,-0.31866,5.61288,39.59572
27.59800,2.29980,786.27598,-0.31867,5.64588,39.68385
27.69800,2.30817,787.39570,-0.31867,5.67936,39.74036
27.79800,2.31654,789.46622,-0.31866,5.71285,39.84486
27.89800,2.32485,789.98720,-0.31866,5.74609,39.87116
27.99800,2.33317,791.94391,-0.31867,5.77933,39.96991
28.09800,2.34154,792.86024,-0.31867,5.81281,40.01616
28.19800,2.34985,794.75166,-0.31867,5.84606,40.11163
28.29800,2.35822,796.46818,-0.31867,5.87954,40.19826
28.39800,2.36659,797.42186,-0.31867,5.91302,40.24639
28.49800,2.37484,799.44590,-0.31867,5.94603,40.34855
28.59800,2.38321,800.61080,-0.31867,5.97951,40.40734
28.69800,2.39146,802.50688,-0.31867,6.01251,40.50304
28.79800,2.39977,804.21828,-0.31867,6.04575,40.58941
28.89800,2.40820,806.19361,-0.31867,6.07948,40.68911
28.99800,2.41639,806.40623,-0.31867,6.11224,40.69984
29.09800,2.42476,808.43270,-0.31867,6.14572,40.80212
29.19800,2.43313,810.31332,-0.31867,6.17920,40.89703
29.29800,2.44138,811.31980,-0.31867,6.21221,40.94783
29.39800,2.44981,812.64628,-0.31867,6.24593,41.01478
29.49800,2.45819,814.61603,-0.31868,6.27941,41.11419
29.59800,2.46650,816.09040,-0.31868,6.31265,41.18860
29.69800,2.47481,816.47830,-0.31868,6.34590,41.20818
29.79800,2.48318,818.64763,-0.31868,6.37938,41.31767
29.89800,2.49143,820.33435,-0.31868,6.41238,41.40280
29.99800,2.49974,821.22646,-0.31868,6.44563,41.44782
30.09800,2.50811,822.64999,-0.31868,6.47911,41.51967
30.19800,2.51654,824.72842,-0.31868,6.51283,41.62457
30.29800,2.52485,825.28898,-0.31868,6.54607,41.65286
30.39800,2.53316,826.32126,-0.31868,6.57931,41.70496
30.49800,2.54153,827.66851,-0.31868,6.61280,41.77296
30.59800,2.54990,829.45731,-0.31868,6.64628,41.86324
30.69800,2.55821,830.06248,-0.31868,6.67952,41.89378
30.79800,2.56652,831.55809,-0.31868,6.71277,41.96927
30.89800,2.57477,833.20215,-0.31868,6.74577,42.05225
30.99800,2.58309,833.93650,-0.31868,6.77901,42.08931
31.09800,2.59146,834.89995,-0.31868,6.81249,42.13794
31.19800,2.59983,836.55054,-0.31868,6.84598,42.22124
31.29800,2.60814,837.45541,-0.31868,6.87922,42.26691
31.39800,2.61651,838.52140,-0.31868,6.91270,42.32071
31.49800,2.62488,839.72309,-0.31868,6.94618,42.38136
31.59800,2.63313,841.43355,-0.31868,6.97919,42.46769
31.69800,2.64150,842.31319,-0.31868,7.01267,42.51208
31.79800,2.64981,841.97307,-0.31868,7.04591,42.49492
31.89800,2.65812,842.95133,-0.31869,7.07916,42.54429
31.99800,2.66643,844.39674,-0.31868,7.11240,42.61724
32.09800,2.67480,845.18585,-0.31868,7.14588,42.65707
32.19800,2.68311,846.27839,-0.31869,7.17912,42.71221
32.29800,2.69148,847.38042,-0.31868,7.21261,42.76783
32.39800,2.69991,848.58080,-0.31869,7.24633,42.82841
32.49800,2.70822,849.79385,-0.31869,7.27957,42.88964
32.59800,2.71654,850.60373,-0.31868,7.31281,42.93052
32.69800,2.72485,851.59997,-0.31868,7.34606,42.98079
32.79800,2.73322,852.67024,-0.31868,7.37954,43.03481
32.89800,2.74153,854.32585,-0.31869,7.41278,43.11837
32.99800,2.74984,854.29139,-0.31869,7.44602,43.11663
33.09800,2.75815,855.19310,-0.31869,7.47927,43.16214
33.19800,2.76652,856.16708,-0.31869,7.51275,43.21130
33.29800,2.77477,856.54808,-0.31869,7.54575,43.23053
33.39800,2.78308,858.38726,-0.31868,7.57900,43.32335
33.49800,2.79151,858.60221,-0.31869,7.61272,43.33420
33.59800,2.79988,859.82131,-0.31869,7.64620,43.39573
33.69800,2.80819,860.36734,-0.31869,7.67944,43.42329
33.79800,2.81662,861.79972,-0.31869,7.71316,43.49558
33.89800,2.82481,862.47437,-0.31869,7.74593,43.52963
33.99800,2.83313,863.39517,-0.31869,7.77917,43.57611
34.09800,2.84156,864.11964,-0.31869,7.81289,43.61267
34.19800,2.84975,864.83303,-0.31868,7.84566,43.64867
34.29800,2.85812,866.28906,-0.31869,7.87914,43.72216
34.39800,2.86655,865.93060,-0.31869,7.91286,43.70407
34.49800,2.87474,867.15994,-0.31869,7.94562,43.76612
34.59800,2.88311,867.35664,-0.31869,7.97911,43.77604
34.69800,2.89154,868.23320,-0.31869,8.01283,43.82029
34.79800,2.89985,868.77886,-0.31869,8.04607,43.84782
34.89800,2.90822,870.03438,-0.31869,8.07955,43.91119
34.99800,2.91653,870.88561,-0.31869,8.11280,43.95415
35.09800,2.92478,871.24407,-0.31869,8.14580,43.97224
35.19800,2.93321,871.92394,-0.31869,8.17952,44.00656
35.29800,2.94152,873.15114,-0.31869,8.21276,44.06850
35.39800,2.94983,872.71119,-0.31869,8.24601,44.04629
35.49800,2.95826,874.08591,-0.31869,8.27973,44.11567
35.59800,2.96652,874.28708,-0.31869,8.31273,44.12583
35.69800,2.97483,874.79716,-0.31869,8.34597,44.15157
35.79800,2.98332,875.40392,-0.31869,8.37994,44.18219
35.89800,2.99151,876.17356,-0.31869,8.41270,44.22104
35.99800,2.99976,877.29124,-0.31869,8.44570,44.27745
36.09800,3.00819,877.10517,-0.31869,8.47942,44.26806
36.19800,3.01638,877.59281,-0.31869,8.51219,44.29267
36.29800,3.02475,878.17507,-0.31869,8.54567,44.32206
36.39800,3.03318,878.37139,-0.31869,8.57939,44.33197
36.49800,3.04143,879.19999,-0.31869,8.61240,44.37378
36.59800,3.04974,879.51357,-0.31869,8.64564,44.38961
36.69800,3.05817,880.33862,-0.31869,8.67936,44.43125
36.79800,3.06642,881.04829,-0.31869,8.71237,44.46707
36.89800,3.07479,881.35647,-0.31869,8.74585,44.48262
36.99800,3.08316,881.26529,-0.31869,8.77933,44.47802
37.09800,3.09148,881.73365,-0.31869,8.81257,44.50166
37.19800,3.09985,881.24974,-0.31869,8.84605,44.47724
37.29800,3.10816,881.96890,-0.31869,8.87930,44.51353
37.39800,3.11647,882.37878,-0.31869,8.91254,44.53422
37.49800,3.12484,882.62940,-0.31869,8.94602,44.54687
37.59800,3.13315,883.51872,-0.31870,8.97927,44.59175
37.69800,3.14146,883.57152,-0.31870,9.01251,44.59442
37.79800,3.14989,883.97684,-0.31869,9.04623,44.61488
37.89800,3.15808,884.36240,-0.31869,9.07900,44.63433
37.99800,3.16645,883.80873,-0.31869,9.11248,44.60639
38.09800,3.17488,884.50760,-0.31870,9.14620,44.64166
38.19800,3.18319,884.55332,-0.31869,9.17944,44.64397
38.29800,3.19150,884.92166,-0.31870,9.21268,44.66256
38.39800,3.19987,885.07123,-0.31869,9.24617,44.67011
38.49800,3.20812,885.93913,-0.31870,9.27917,44.71391
38.59800,3.21650,885.86416,-0.31869,9.31265,44.71013
38.69800,3.22487,885.73098,-0.31870,9.34613,44.70341
38.79800,3.23318,886.73616,-0.31869,9.37938,44.75414
38.89800,3.24149,886.44102,-0.31870,9.41262,44.73925
38.99800,3.24986,886.67134,-0.31869,9.44610,44.75087
39.09800,3.25817,886.75292,-0.31870,9.47935,44.75499
39.19800,3.26648,887.36117,-0.31870,9.51259,44.78569
39.29800,3.27485,887.00848,-0.31870,9.54607,44.76788
39.39800,3.28310,887.37728,-0.31870,9.57907,44.78650
39.49800,3.29147,886.82193,-0.31869,9.61256,44.75847
39.59800,3.29984,886.68978,-0.31870,9.64604,44.75180
39.69800,3.30809,887.66897,-0.31870,9.67904,44.80122
39.79800,3.31652,887.09667,-0.31870,9.71276,44.77234
39.89800,3.32483,888.00061,-0.31870,9.74601,44.81796
39.99800,3.33314,887.53607,-0.31870,9.77925,44.79451
40.09800,3.34157,887.32289,-0.31870,9.81297,44.78375
40.19800,3.34983,887.63721,-0.31870,9.84597,44.79962
40.29800,3.35820,887.99857,-0.31870,9.87946,44.81786
40.39800,3.36657,887.40224,-0.31870,9.91294,44.78776
40.49800,3.37482,887.18813,-0.31870,9.94594,44.77695
40.59800,3.38307,887.69449,-0.31870,9.97895,44.80251
40.69800,3.39156,887.55880,-0.31870,10.01291,44.79566
40.79800,3.39975,887.76369,-0.31870,10.04567,44.80600
40.89800,3.40812,887.94697,-0.31870,10.07915,44.81525
40.99800,3.41661,887.78241,-0.31870,10.11311,44.80695
41.09800,3.42486,887.24596,-0.31869,10.14612,44.77987
41.19800,3.43317,887.52853,-0.31870,10.17936,44.79413
41.29800,3.44166,887.13933,-0.31870,10.21332,44.77449
41.39800,3.44973,887.04024,-0.31870,10.24561,44.76949
41.49800,3.45816,887.77477,-0.31869,10.27933,44.80656
41.59800,3.46654,886.80508,-0.31870,10.31281,44.75762
41.69800,3.47467,886.97448,-0.31870,10.34534,44.76617
41.79800,3.48322,886.54514,-0.31870,10.37954,44.74450
41.89800,3.49153,886.82575,-0.31870,10.41278,44.75866
41.99800,3.49978,886.76736,-0.31870,10.44578,44.75571
42.09800,3.50827,885.77298,-0.31870,10.47974,44.70553
42.19800,3.51652,886.04577,-0.31870,10.51275,44.71930
42.29800,3.52477,886.23846,-0.31870,10.54575,44.72902
42.39800,3.53332,885.49629,-0.31870,10.57995,44.69156
42.49800,3.54145,885.67305,-0.31870,10.61248,44.70049
42.59800,3.54976,885.79794,-0.31870,10.64572,44.70679
42.69800,3.55825,885.06667,-0.31870,10.67968,44.66988
42.79800,3.56650,885.25033,-0.31870,10.71268,44.67915
42.89800,3.57481,885.04637,-0.31870,10.74593,44.66885
42.99800,3.58324,884.80599,-0.31870,10.77965,44.65672
43.09800,3.59144,884.57474,-0.31870,10.81241,44.64505
43.19800,3.59981,884.12268,-0.31870,10.84589,44.62224
43.29800,3.60830,883.41171,-0.31870,10.87985,44.58635
43.39800,3.61643,883.63849,-0.31870,10.91238,44.59780
43.49800,3.62480,883.89125,-0.31870,10.94586,44.61056
43.59800,3.63329,882.90796,-0.31870,10.97982,44.56093
43.69800,3.64148,883.78731,-0.31870,11.01259,44.60531
43.79800,3.64991,882.44164,-0.31870,11.04631,44.53739
43.89800,3.65822,882.33873,-0.31870,11.07955,44.53220
43.99800,3.66641,882.31303,-0.31870,11.11232,44.53090
44.09800,3.67484,881.57225,-0.31870,11.14604,44.49352
44.19800,3.68321,881.91722,-0.31870,11.17952,44.51093
44.29800,3.69146,881.20075,-0.31870,11.21252,44.47477
44.39800,3.69989,880.33350,-0.31870,11.24624,44.43100
44.49800,3.70814,880.80047,-0.31870,11.27925,44.45456
44.59800,3.71645,879.75701,-0.31870,11.31249,44.40190
44.69800,3.72489,880.17303,-0.31870,11.34621,44.42289
44.79800,3.73308,879.51347,-0.31870,11.37898,44.38961
44.89800,3.74139,879.36781,-0.31870,11.41222,44.38226
44.99800,3.74988,878.80241,-0.31870,11.44618,44.35372
45.09800,3.75813,878.39253,-0.31870,11.47918,44.33303
45.19800,3.76644,878.57526,-0.31870,11.51243,44.34225
45.29800,3.77487,877.52230,-0.31870,11.54615,44.28911
45.39800,3.78312,877.63332,-0.31870,11.57915,44.29472
45.49800,3.79149,877.39369,-0.31870,11.61264,44.28262
45.59800,3.79986,876.21640,-0.31870,11.64612,44.22320
45.69800,3.80817,876.82307,-0.31870,11.67936,44.25382
45.79800,3.81642,876.31531,-0.31870,11.71236,44.22820
45.89800,3.82479,875.29719,-0.31870,11.74585,44.17681
45.99800,3.83310,874.99581,-0.31870,11.77909,44.16160
46.09800,3.84147,874.68456,-0.31870,11.81257,44.14589
46.19800,3.84985,874.26128,-0.31870,11.84605,44.12453
46.29800,3.85816,874.13779,-0.31870,11.87930,44.11829
46.39800,3.86653,873.14285,-0.31870,11.91278,44.06808
46.49800,3.87478,873.14295,-0.31870,11.94578,44.06808
46.59800,3.88315,872.77638,-0.31870,11.97926,44.04958
46.69800,3.89158,871.90280,-0.31870,12.01299,44.00549
46.79800,3.89983,871.47895,-0.31870,12.04599,43.98410
46.89800,3.90814,871.23448,-0.31870,12.07923,43.97176
46.99800,3.91657,870.71517,-0.31870,12.11295,43.94555
47.09800,3.92476,870.87695,-0.31870,12.14572,43.95372
47.19800,3.93313,870.50572,-0.31870,12.17920,43.93498
47.29800,3.94156,869.80220,-0.31870,12.21292,43.89947
47.39800,3.94975,869.64350,-0.31870,12.24568,43.89146
47.49800,3.95818,869.51759,-0.31870,12.27941,43.88511
47.59800,3.96655,868.08242,-0.31870,12.31289,43.81268
47.69800,3.97481,868.94874,-0.31870,12.34589,43.85640
47.79800,3.98318,867.91264,-0.31871,12.37937,43.80410
47.89800,3.99155,867.65764,-0.31870,12.41286,43.79124
47.99800,3.99980,867.32442,-0.31870,12.44586,43.77442
48.09800,4.00817,866.63691,-0.31870,12.47934,43.73972
48.19800,4.01654,866.11453,-0.31870,12.51282,43.71335
48.29800,4.02473,865.79304,-0.31870,12.54559,43.69713
48.39800,4.03316,865.01595,-0.31870,12.57931,43.65791
48.49800,4.04153,865.16645,-0.31870,12.61279,43.66550
48.59800,4.04984,864.28961,-0.31870,12.64603,43.62125
48.69800,4.05833,863.58013,-0.31870,12.68000,43.58544
48.79800,4.06652,864.14320,-0.31870,12.71276,43.61386
48.89800,4.07477,863.36518,-0.31870,12.74576,43.57459
48.99800,4.08320,862.56145,-0.31870,12.77949,43.53403
49.09800,4.09145,862.27180,-0.31870,12.81249,43.51941
49.19800,4.09982,861.90198,-0.31870,12.84597,43.50074
49.29800,4.10820,861.51324,-0.31871,12.87945,43.48112
49.39800,4.11651,860.59840,-0.31871,12.91270,43.43495
49.49800,4.12482,861.06621,-0.31870,12.94594,43.45856
49.59800,4.13325,859.83751,-0.31870,12.97966,43.39655
49.69800,4.14150,859.21912,-0.31871,13.01266,43.36534
49.79800,4.14981,859.59928,-0.31871,13.04591,43.38453
49.89800,4.15824,859.31662,-0.31871,13.07963,43.37026
49.99800,4.16643,858.48831,-0.31870,13.11239,43.32845
50.09800,4.17480,858.28416,-0.31870,13.14587,43.31815
50.19800,4.18317,857.99331,-0.31870,13.17936,43.30347
50.29800,4.19142,856.93430,-0.31870,13.21236,43.25002
50.39800,4.19979,856.64773,-0.31870,13.24584,43.23556
50.49800,4.20816,856.05998,-0.31871,13.27933,43.20589
50.59800,4.21647,855.58416,-0.31870,13.31257,43.18188
50.69800,4.22490,854.90532,-0.31871,13.34629,43.14762
50.79800,4.23316,854.31822,-0.31871,13.37930,43.11798
50.89800,4.24147,854.51948,-0.31871,13.41254,43.12814
50.99800,4.24996,854.35146,-0.31871,13.44650,43.11966
51.09800,4.25815,853.70168,-0.31871,13.47926,43.08687
51.19800,4.26652,853.35616,-0.31870,13.51274,43.06943
51.29800,4.27483,853.02247,-0.31870,13.54599,43.05259
51.39800,4.28314,852.47373,-0.31871,13.57923,43.02489
51.49800,4.29151,851.77459,-0.31870,13.61271,42.98961
51.59800,4.29988,851.66777,-0.31871,13.64620,42.98421
51.69800,4.30813,850.50026,-0.31871,13.67920,42.92529
51.79800,4.31650,850.85873,-0.31871,13.71268,42.94338
51.89800,4.32487,849.34998,-0.31871,13.74616,42.86724
51.99800,4.33312,849.10281,-0.31871,13.77916,42.85476
52.09800,4.34143,849.16055,-0.31870,13.81241,42.85767
52.19800,4.34975,848.78420,-0.31871,13.84565,42.83868
52.29800,4.35806,848.44334,-0.31871,13.87890,42.82148
52.39800,4.36643,847.75658,-0.31871,13.91238,42.78682
52.49800,4.37480,847.41795,-0.31871,13.94586,42.76973
52.59800,4.38311,847.46089,-0.31871,13.97910,42.77189
52.69800,4.39148,846.72673,-0.31871,14.01258,42.73484
52.79800,4.39979,845.58828,-0.31871,14.04583,42.67738
52.89800,4.40816,845.53622,-0.31870,14.07931,42.67475
52.99800,4.41653,845.04858,-0.31871,14.11279,42.65014
53.09800,4.42484,844.83111,-0.31871,14.14603,42.63916
53.19800,4.43321,844.67502,-0.31871,14.17952,42.63129
53.29800,4.44152,844.12834,-0.31871,14.21276,42.60369
53.39800,4.44977,843.33969,-0.31871,14.24576,42.56389
53.49800,4.45814,843.14812,-0.31871,14.27924,42.55423
53.59800,4.46651,842.76879,-0.31871,14.31273,42.53508
53.69800,4.47482,842.34783,-0.31870,14.34597,42.51383
53.79800,4.48314,841.90238,-0.31871,14.37921,42.49135
53.89800,4.49157,841.93610,-0.31870,14.41294,42.49305
53.99800,4.49988,840.50540,-0.31871,14.44618,42.42085
54.09800,4.50825,840.70256,-0.31871,14.47966,42.43079
54.19800,4.51662,840.90298,-0.31871,14.51314,42.44091
54.29800,4.52487,839.56486,-0.31871,14.54615,42.37337
54.39800,4.53318,839.16476,-0.31871,14.57939,42.35318
54.49800,4.54149,839.08793,-0.31870,14.61263,42.34930
54.59800,4.54980,838.77547,-0.31871,14.64587,42.33353
54.69800,4.55817,838.49328,-0.31871,14.67936,42.31929
54.79800,4.56642,837.50701,-0.31870,14.71236,42.26951
54.89800,4.57485,837.27622,-0.31871,14.74608,42.25787
54.99800,4.58316,836.69545,-0.31871,14.77932,42.22855
55.09800,4.59153,836.70709,-0.31871,14.81281,42.22914
55.19800,4.59990,836.22262,-0.31870,14.84629,42.20469
55.29800,4.60822,835.34028,-0.31871,14.87953,42.16016
55.39800,4.61647,835.33674,-0.31871,14.91254,42.15998
55.49800,4.62478,835.00016,-0.31871,14.94578,42.14299
55.59800,4.63321,834.47844,-0.31871,14.97950,42.11666
55.69800,4.64146,834.03112,-0.31871,15.01250,42.09408
55.79800,4.64983,833.68924,-0.31871,15.04599,42.07683
55.89800,4.65826,832.94045,-0.31871,15.07971,42.03904
55.99800,4.66651,833.04802,-0.31871,15.11271,42.04446
56.09800,4.67488,831.89951,-0.31871,15.14619,41.98650
56.19800,4.68325,832.01230,-0.31871,15.17967,41.99219
56.29800,4.69144,831.37928,-0.31870,15.21244,41.96024
56.39800,4.69981,830.87990,-0.31871,15.24592,41.93504
56.49800,4.70824,830.41033,-0.31871,15.27964,41.91134
56.59800,4.71649,829.86578,-0.31871,15.31265,41.88386
56.69800,4.72480,829.97084,-0.31871,15.34589,41.88916
56.79800,4.73312,829.52902,-0.31871,15.37913,41.86686
56.89800,4.74143,829.44129,-0.31871,15.41238,41.86243
56.99800,4.74980,828.33534,-0.31871,15.44586,41.80661
57.09800,4.75817,828.28822,-0.31871,15.47934,41.80423
57.19800,4.76648,827.91355,-0.31871,15.51258,41.78532
57.29800,4.77491,827.27605,-0.31871,15.54631,41.75315
57.39800,4.78310,827.29859,-0.31871,15.57907,41.75429
57.49800,4.79147,826.87922,-0.31871,15.61255,41.73312
57.59800,4.79984,826.03786,-0.31871,15.64603,41.69066
57.69800,4.80809,826.11060,-0.31871,15.67904,41.69433
57.79800,4.81640,825.15376,-0.31871,15.71228,41.64604
57.89800,4.82483,824.80870,-0.31871,15.74600,41.62862
57.99800,4.83308,824.50500,-0.31871,15.77900,41.61329
58.09800,4.84145,823.45884,-0.31871,15.81249,41.56049
58.19800,4.84988,823.13102,-0.31871,15.84621,41.54395
58.29800,4.85820,823.17237,-0.31871,15.87945,41.54604
58.39800,4.86657,822.89027,-0.31871,15.91293,41.53180
58.49800,4.87488,822.11494,-0.31871,15.94618,41.49267
58.59800,4.88319,822.28528,-0.31871,15.97942,41.50126
58.69800,4.89150,821.93539,-0.31871,16.01266,41.48360
58.79800,4.89981,820.77859,-0.31871,16.04591,41.42522
58.89800,4.90812,820.50795,-0.31871,16.07915,41.41156
58.99800,4.91649,819.91330,-0.31871,16.11263,41.38155
59.09800,4.92480,819.77462,-0.31871,16.14587,41.37455
59.19800,4.93311,819.33178,-0.31871,16.17912,41.35220
59.29800,4.94154,818.92395,-0.31871,16.21284,41.33162
59.39800,4.94985,818.31552,-0.31871,16.24608,41.30091
59.49800,4.95816,818.15375,-0.31871,16.27932,41.29274
59.59800,4.96653,817.12957,-0.31871,16.31281,41.24105
59.69800,4.97472,817.31910,-0.31871,16.34557,41.25062
59.79800,4.98310,817.16301,-0.31871,16.37905,41.24274
59.89800,4.99153,816.27052,-0.31871,16.41277,41.19769
59.99800,4.99984,815.76407,-0.31871,16.44602,41.17213
60.09800,5.00815,815.67485,-0.31871,16.47926,41.16763
60.19800,5.01652,815.34842,-0.31871,16.51274,41.15116
60.29800,5.02477,814.23931,-0.31871,16.54574,41.09518
60.39800,5.03320,814.13630,-0.31871,16.57946,41.08998
60.49800,5.04151,814.03079,-0.31871,16.61271,41.08465
60.59800,5.04982,813.21290,-0.31871,16.64595,41.04337
60.69800,5.05813,812.97895,-0.31871,16.67919,41.03157
60.79800,5.06644,812.79045,-0.31871,16.71244,41.02205
60.89800,5.07475,812.62635,-0.31871,16.74568,41.01377
60.99800,5.08312,811.37605,-0.31871,16.77916,40.95067
61.09800,5.09149,810.80617,-0.31871,16.81265,40.92191
61.19800,5.09980,810.88608,-0.31871,16.84589,40.92594
61.29800,5.10817,810.54233,-0.31871,16.87937,40.90859
61.39800,5.11655,809.45836,-0.31871,16.91285,40.85388
61.49800,5.12486,809.19852,-0.31871,16.94610,40.84077
61.59800,5.13323,808.68928,-0.31871,16.97958,40.81506
61.69800,5.14154,808.65752,-0.31871,17.01282,40.81346
61.79800,5.14985,807.89020,-0.31871,17.04606,40.77473
61.89800,5.15822,807.53658,-0.31871,17.07955,40.75689
61.99800,5.16647,806.67399,-0.31871,17.11255,40.71335
62.09800,5.17478,806.57955,-0.31871,17.14579,40.70858
62.19800,5.18315,805.98341,-0.31871,17.17927,40.67850
62.29800,5.19146,805.50201,-0.31871,17.21252,40.65420
62.39800,5.19977,804.72166,-0.31871,17.24576,40.61481
62.49800,5.20820,804.57618,-0.31871,17.27948,40.60748
62.59800,5.21645,804.49823,-0.31871,17.31248,40.60354
62.69800,5.22476,803.45478,-0.31871,17.34573,40.55088
62.79800,5.23319,803.12844,-0.31871,17.37945,40.53440
62.89800,5.24145,802.82791,-0.31871,17.41245,40.51924
62.99800,5.24976,802.10604,-0.31871,17.44570,40.48280
63.09800,5.25819,801.00270,-0.31871,17.47942,40.42712
63.19800,5.26638,801.59502,-0.31871,17.51218,40.45701
63.29800,5.27475,800.92438,-0.31871,17.54566,40.42316
63.39800,5.28318,799.93559,-0.31871,17.57939,40.37326
63.49800,5.29149,799.02867,-0.31871,17.61263,40.32749
63.59800,5.29992,799.45335,-0.31871,17.64635,40.34892
63.69800,5.30823,798.49921,-0.31871,17.67959,40.30077
63.79800,5.31648,798.03569,-0.31871,17.71260,40.27737
63.89800,5.32485,798.34396,-0.31871,17.74608,40.29293
63.99800,5.33316,797.25450,-0.31871,17.77932,40.23795
64.09800,5.34147,796.34069,-0.31871,17.81256,40.19182
64.19800,5.34984,796.12872,-0.31871,17.84605,40.18113
64.29800,5.35809,795.16200,-0.31871,17.87905,40.13234
64.39800,5.36647,794.93504,-0.31871,17.91253,40.12088
64.49800,5.37490,795.19507,-0.31871,17.94626,40.13400
64.59800,5.38321,793.85890,-0.31871,17.97950,40.06657
64.69800,5.39152,793.41596,-0.31871,18.01274,40.04421
64.79800,5.39995,792.50531,-0.31871,18.04646,39.99825
64.89800,5.40820,792.22852,-0.31871,18.07946,39.98428
64.99800,5.41645,791.03177,-0.31871,18.11247,39.92388
65.09800,5.42488,790.54143,-0.31871,18.14619,39.89913
65.19800,5.43313,789.71833,-0.31871,18.17919,39.85759
65.29800,5.44144,789.70836,-0.31871,18.21244,39.85709
65.39800,5.44987,789.52871,-0.31871,18.24616,39.84802
65.49800,5.45812,787.98309,-0.31871,18.27916,39.77001
65.59800,5.46649,787.83277,-0.31871,18.31264,39.76242
65.69801,5.47480,786.51337,-0.31871,18.34588,39.69583
65.79801,5.48317,785.54805,-0.31871,18.37937,39.64711
65.89800,5.49149,785.97460,-0.31871,18.41261,39.66864
65.99800,5.49980,785.08826,-0.31871,18.44585,39.62391
66.09800,5.50811,784.29505,-0.31871,18.47910,39.58387
66.19801,5.51648,783.50287,-0.31871,18.51258,39.54389
66.29801,5.52479,783.08508,-0.31871,18.54582,39.52280
66.39800,5.53310,782.54016,-0.31872,18.57907,39.49530
66.49800,5.54153,781.81690,-0.31871,18.61279,39.45880
66.59800,5.54984,780.62904,-0.31871,18.64603,39.39885
66.69801,5.55809,779.52724,-0.31871,18.67903,39.34324
66.79801,5.56652,779.26349,-0.31871,18.71275,39.32993
66.89800,5.57489,778.45980,-0.31871,18.74624,39.28936
66.99800,5.58320,777.79815,-0.31871,18.77948,39.25597
67.09800,5.59157,776.80973,-0.31871,18.81296,39.20609
67.19801,5.59982,775.68586,-0.31871,18.84597,39.14936
67.29801,5.60813,775.40199,-0.31871,18.87921,39.13503
67.39800,5.61650,774.94504,-0.31871,18.91269,39.11197
67.49800,5.62482,774.30797,-0.31871,18.94593,39.07982
67.59800,5.63313,773.25660,-0.31871,18.97918,39.02676
67.69801,5.64150,771.96728,-0.31871,19.01266,38.96168
67.79801,5.64987,771.26855,-0.31871,19.04614,38.92641
67.89800,5.65818,770.19930,-0.31871,19.07939,38.87245
67.99800,5.66655,769.23836,-0.31871,19.11287,38.82395
68.09800,5.67486,768.44445,-0.31871,19.14611,38.78388
68.19801,5.68317,767.92655,-0.31871,19.17935,38.75774
68.29801,5.69148,766.77813,-0.31871,19.21259,38.69978
68.39800,5.69973,765.74222,-0.31871,19.24560,38.64750
68.49800,5.70816,764.81565,-0.31871,19.27932,38.60073
68.59800,5.71647,763.54523,-0.31871,19.31256,38.53662
68.69801,5.72472,762.83193,-0.31871,19.34557,38.50061
68.79801,5.73321,761.92454,-0.31871,19.37953,38.45482
68.89800,5.74153,761.12743,-0.31871,19.41277,38.41459
68.99800,5.74984,760.14926,-0.31871,19.44602,38.36522
69.09800,5.75827,759.01588,-0.31871,19.47974,38.30802
69.19801,5.76646,757.66942,-0.31871,19.51250,38.24006
69.29801,5.77477,756.53163,-0.31871,19.54574,38.18264
69.39800,5.78320,755.92264,-0.31871,19.57946,38.15190
69.49800,5.79145,754.81790,-0.31871,19.61247,38.09614
69.59800,5.79982,753.80467,-0.31871,19.64595,38.04500
69.69801,5.80825,752.61751,-0.31871,19.67967,37.98509
69.79801,5.81650,751.41937,-0.31871,19.71268,37.92461
69.89800,5.82487,750.24772,-0.31871,19.74616,37.86548
69.99800,5.83330,749.15993,-0.31871,19.77988,37.81058
70.09800,5.84149,747.78371,-0.31871,19.81264,37.74112
70.19801,5.84986,746.43674,-0.31871,19.84612,37.67314
70.29801,5.85823,745.40395,-0.31872,19.87961,37.62101
70.39800,5.86643,744.19738,-0.31871,19.91237,37.56012
70.49800,5.87486,743.16664,-0.31871,19.94609,37.50809
70.59800,5.88317,741.66046,-0.31871,19.97934,37.43208
70.69801,5.89142,741.07316,-0.31871,20.01234,37.40244
70.79801,5.89985,739.68987,-0.31871,20.04606,37.33262
70.89800,5.90816,737.99682,-0.31871,20.07930,37.24717
70.99800,5.91641,737.04948,-0.31871,20.11231,37.19936
71.09800,5.92496,735.59559,-0.31871,20.14651,37.12598
71.19801,5.93315,734.74115,-0.31871,20.17927,37.08286
71.29801,5.94146,733.10486,-0.31871,20.21251,37.00027
71.39800,5.94995,732.12320,-0.31871,20.24647,36.95073
71.49800,5.95814,730.69306,-0.31871,20.27924,36.87854
71.59801,5.96645,729.68537,-0.31871,20.31248,36.82769
71.69801,5.97488,728.70930,-0.31871,20.34620,36.77842
71.79801,5.98313,727.18095,-0.31871,20.37921,36.70129
71.89800,5.99150,726.62481,-0.31871,20.41269,36.67322
71.99800,5.99988,725.20948,-0.31872,20.44617,36.60178
72.09801,6.00807,722.99815,-0.31871,20.47894,36.49018
72.19801,6.01656,722.20592,-0.31871,20.51290,36.45020
72.29801,6.02493,720.90649,-0.31872,20.54638,36.38461
72.39800,6.03312,719.84767,-0.31871,20.57914,36.33117
72.49800,6.04155,718.26852,-0.31871,20.61286,36.25147
72.59801,6.04986,717.36337,-0.31871,20.64611,36.20579
72.69801,6.05811,716.17514,-0.31871,20.67911,36.14582
72.79801,6.06648,715.33374,-0.31871,20.71259,36.10335
72.89800,6.07479,713.14643,-0.31871,20.74584,35.99295
72.99800,6.08310,712.16752,-0.31871,20.77908,35.94355
73.09801,6.09153,711.37995,-0.31871,20.81280,35.90380
73.19801,6.09984,710.01565,-0.31871,20.84604,35.83494
73.29801,6.10815,708.52642,-0.31871,20.87929,35.75978
73.39800,6.11658,707.69484,-0.31872,20.91301,35.71781
73.49800,6.12478,706.83048,-0.31871,20.94577,35.67419
73.59801,6.13309,705.75564,-0.31871,20.97902,35.61994
73.69801,6.14152,704.38622,-0.31872,21.01274,35.55082
73.79801,6.14977,703.73290,-0.31871,21.04574,35.51785
73.89800,6.15808,701.96632,-0.31871,21.07898,35.42869
73.99800,6.16657,701.35701,-0.31871,21.11294,35.39794
74.09801,6.17476,700.26889,-0.31871,21.14571,35.34302
74.19801,6.18313,698.90902,-0.31871,21.17919,35.27438
74.29801,6.19156,698.45938,-0.31871,21.21291,35.25169
74.39800,6.19987,697.07329,-0.31871,21.24616,35.18174
74.49800,6.20830,696.66682,-0.31871,21.27988,35.16122
74.59801,6.21649,695.14378,-0.31871,21.31264,35.08435
74.69801,6.22474,694.27527,-0.31871,21.34565,35.04052
74.79801,6.23311,693.78088,-0.31871,21.37913,35.01556
74.89800,6.24148,692.76541,-0.31871,21.41261,34.96431
74.99800,6.24980,691.54166,-0.31872,21.44585,34.90255
75.09801,6.25817,690.95199,-0.31871,21.47934,34.87279
75.19801,6.26648,689.93196,-0.31872,21.51258,34.82131
75.29801,6.27479,688.91090,-0.31871,21.54582,34.76977
75.39800,6.28322,688.02503,-0.31872,21.57954,34.72506
75.49800,6.29153,687.25869,-0.31871,21.61279,34.68639
75.59801,6.29984,686.22474,-0.31871,21.64603,34.63420
75.69801,6.30827,686.31563,-0.31871,21.67975,34.63879
75.79801,6.31646,684.55720,-0.31871,21.71251,34.55004
75.89800,6.32477,684.53681,-0.31871,21.74576,34.54901
75.99800,6.33320,683.07887,-0.31872,21.77948,34.47543
76.09801,6.34139,682.80129,-0.31871,21.81224,34.46142
76.19801,6.34976,682.93498,-0.31871,21.84573,34.46817
76.29801,6.35819,681.56477,-0.31871,21.87945,34.39901
76.39800,6.36638,681.67588,-0.31871,21.91221,34.40462
76.49800,6.37488,680.91610,-0.31871,21.94617,34.36627
76.59801,6.38331,680.48327,-0.31871,21.97989,34.34443
76.69801,6.39150,679.38175,-0.31871,22.01266,34.28883
76.79801,6.39987,678.94245,-0.31871,22.04614,34.26666
76.89800,6.40824,678.08367,-0.31872,22.07962,34.22332
76.99800,6.41643,677.72288,-0.31871,22.11238,34.20510
77.09801,6.42486,677.05363,-0.31871,22.14611,34.17133
77.19801,6.43317,676.31360,-0.31871,22.17935,34.13398
77.29801,6.44142,677.12925,-0.31871,22.21235,34.17514
77.39800,6.44991,675.80733,-0.31872,22.24632,34.10843
77.49800,6.45816,675.18568,-0.31871,22.27932,34.07705
77.59801,6.46647,675.16984,-0.31872,22.31256,34.07625
77.69801,6.47496,674.68216,-0.31871,22.34652,34.05164
77.79801,6.48321,673.76452,-0.31871,22.37953,34.00533
77.89800,6.49147,673.16680,-0.31871,22.41253,33.97516
77.99800,6.49995,673.32345,-0.31871,22.44649,33.98306
78.09801,6.50809,672.89686,-0.31871,22.47902,33.96153
78.19801,6.51646,672.60833,-0.31871,22.51250,33.94697
78.29801,6.52495,671.50365,-0.31871,22.54646,33.89122
78.39800,6.53314,670.93843,-0.31871,22.57922,33.86269
78.49800,6.54151,671.18751,-0.31871,22.61270,33.87526
78.59801,6.54994,670.66196,-0.31871,22.64643,33.84874
78.69801,6.55813,670.22108,-0.31871,22.67919,33.82648
78.79801,6.56650,670.08343,-0.31871,22.71267,33.81954
78.89800,6.57487,669.61497,-0.31872,22.74615,33.79589
78.99800,6.58300,669.46303,-0.31871,22.77868,33.78823
79.09801,6.59143,669.54913,-0.31871,22.81240,33.79257
79.19801,6.59986,668.68467,-0.31871,22.84612,33.74894
79.29801,6.60805,669.11755,-0.31871,22.87889,33.77079
79.39800,6.61654,668.49105,-0.31871,22.91285,33.73917
79.49800,6.62485,667.79903,-0.31871,22.94609,33.70424
79.59801,6.63311,667.99517,-0.31871,22.97909,33.71414
79.69801,6.64154,667.36680,-0.31871,23.01282,33.68243
79.79801,6.64985,667.68145,-0.31872,23.04606,33.69831
79.89800,6.65810,666.85053,-0.31871,23.07906,33.65637
79.99800,6.66647,666.72009,-0.31872,23.11255,33.64979
80.09801,6.67478,666.23800,-0.31872,23.14579,33.62546
80.19801,6.68309,666.42524,-0.31871,23.17903,33.63491
80.29801,6.69152,666.43306,-0.31872,23.21275,33.63530
80.39800,6.69977,665.73732,-0.31872,23.24576,33.60019
80.49800,6.70808,665.68237,-0.31871,23.27900,33.59742
80.59801,6.71651,665.49606,-0.31871,23.31272,33.58801
80.69801,6.72482,665.24213,-0.31871,23.34596,33.57520
80.79801,6.73319,664.70592,-0.31871,23.37945,33.54813
80.89800,6.74156,664.83128,-0.31872,23.41293,33.55446
80.99800,6.74982,664.25144,-0.31872,23.44593,33.52520
81.09801,6.75813,664.09623,-0.31872,23.47917,33.51736
81.19801,6.76650,663.88608,-0.31871,23.51266,33.50676
81.29801,6.77481,663.37190,-0.31871,23.54590,33.48080
81.39800,6.78318,663.01725,-0.31871,23.57938,33.46291
81.49800,6.79143,663.21627,-0.31871,23.61238,33.47295
81.59801,6.79974,662.90782,-0.31871,23.64563,33.45738
81.69801,6.80817,663.23462,-0.31871,23.67935,33.47387
81.79801,6.81648,662.96672,-0.31871,23.71259,33.46035
81.89800,6.82485,662.35238,-0.31872,23.74607,33.42935
81.99800,6.83322,662.28206,-0.31871,23.77956,33.42580
82.09801,6.84153,662.42879,-0.31871,23.81280,33.43320
82.19801,6.84978,661.99829,-0.31871,23.84580,33.41148
82.29801,6.85815,661.41402,-0.31872,23.87929,33.38199
82.39800,6.86646,660.87730,-0.31872,23.91253,33.35490
82.49800,6.87478,661.17500,-0.31871,23.94577,33.36992
82.59801,6.88321,661.07004,-0.31872,23.97949,33.36463
82.69801,6.89152,661.08066,-0.31871,24.01274,33.36516
82.79801,6.89983,661.02888,-0.31871,24.04598,33.36255
82.89800,6.90826,661.04182,-0.31872,24.07970,33.36320
82.99800,6.91651,660.60727,-0.31871,24.11270,33.34127
83.09801,6.92488,660.36661,-0.31871,24.14619,33.32912
83.19801,6.93325,660.04158,-0.31872,24.17967,33.31272
83.29801,6.94144,660.50193,-0.31872,24.21243,33.33595
83.39800,6.94981,659.70756,-0.31871,24.24591,33.29586
83.49800,6.95812,658.96348,-0.31871,24.27916,33.25831
83.59801,6.96643,658.60902,-0.31872,24.31240,33.24042
83.69801,6.97486,658.78225,-0.31872,24.34612,33.24916
83.79801,6.98311,658.84273,-0.31872,24.37913,33.25221
83.89800,6.99148,658.73545,-0.31871,24.41261,33.24680
83.99800,6.99985,657.92375,-0.31872,24.44609,33.20583
84.09801,7.00823,658.30271,-0.31871,24.47957,33.22496
84.19801,7.01648,657.29669,-0.31871,24.51258,33.17418
84.29801,7.02491,657.58820,-0.31871,24.54630,33.18890
84.39800,7.03316,657.21525,-0.31872,24.57930,33.17007
84.49800,7.04141,657.03290,-0.31872,24.61231,33.16087
84.59801,7.04990,656.61799,-0.31872,24.64626,33.13993
84.69801,7.05815,656.11838,-0.31872,24.67927,33.11472
84.79801,7.06640,656.00676,-0.31872,24.71227,33.10908
84.89800,7.07495,655.23922,-0.31871,24.74647,33.07034
84.99800,7.08314,654.98701,-0.31872,24.77924,33.05761
85.09801,7.09151,654.73625,-0.31872,24.81272,33.04496
85.19801,7.09994,654.58445,-0.31872,24.84644,33.03730
85.29801,7.10813,653.95357,-0.31871,24.87920,33.00546
85.39800,7.11650,654.17495,-0.31872,24.91269,33.01663
85.49800,7.12482,653.02909,-0.31871,24.94593,32.95879
85.59801,7.13307,653.06081,-0.31872,24.97893,32.96040
85.69801,7.14156,653.00716,-0.31872,25.01290,32.95769
85.79801,7.14987,652.01791,-0.31872,25.04614,32.90776
85.89800,7.15818,651.98722,-0.31872,25.07938,32.90621
85.99800,7.16655,651.64114,-0.31872,25.11286,32.88874
86.09801,7.17480,651.40133,-0.31871,25.14587,32.87664
86.19801,7.18311,650.89678,-0.31872,25.17911,32.85118
86.29801,7.19154,651.15881,-0.31872,25.21283,32.86440
86.39800,7.19979,650.66288,-0.31872,25.24584,32.83937
86.49800,7.20810,650.12169,-0.31872,25.27908,32.81206
86.59801,7.21647,649.60402,-0.31871,25.31256,32.78593
86.69801,7.22472,649.39726,-0.31872,25.34556,32.77549
86.79801,7.23309,648.95465,-0.31872,25.37904,32.75315
86.89800,7.24152,648.51162,-0.31872,25.41277,32.73080
86.99800,7.24983,647.98594,-0.31872,25.44601,32.70427
87.09801,7.25809,647.76777,-0.31872,25.47901,32.69325
87.19801,7.26652,647.75832,-0.31871,25.51274,32.69278
87.29801,7.27483,647.06188,-0.31871,25.54598,32.65763
87.39800,7.28320,646.47016,-0.31872,25.57946,32.62776
87.49800,7.29151,645.76301,-0.31872,25.61270,32.59207
87.59801,7.29982,646.00981,-0.31872,25.64594,32.60453
87.69801,7.30819,645.25246,-0.31872,25.67943,32.56630
87.79801,7.31650,645.51891,-0.31872,25.71267,32.57975
87.89800,7.32481,644.89897,-0.31871,25.74591,32.54846
87.99800,7.33318,644.33175,-0.31872,25.77940,32.51984
88.09801,7.34149,643.51019,-0.31872,25.81264,32.47837
88.19801,7.34992,643.21491,-0.31872,25.84636,32.46347
88.29801,7.35823,643.60169,-0.31872,25.87960,32.48299
88.39800,7.36654,643.10515,-0.31872,25.91285,32.45793
88.49800,7.37485,642.82552,-0.31871,25.94609,32.44381
88.59801,7.38317,642.53183,-0.31872,25.97933,32.42899
88.69801,7.39154,642.03516,-0.31871,26.01281,32.40392
88.79801,7.39985,641.27524,-0.31872,26.04606,32.36557
88.89800,7.40822,641.39026,-0.31872,26.07954,32.37138
88.99800,7.41647,640.44120,-0.31872,26.11254,32.32347
89.09801,7.42484,640.79058,-0.31872,26.14603,32.34111
89.19801,7.43321,640.26555,-0.31872,26.17951,32.31461
89.29801,7.44152,639.52040,-0.31871,26.21275,32.27700
89.39800,7.44989,639.69605,-0.31872,26.24623,32.28587
89.49800,7.45814,639.40105,-0.31872,26.27923,32.27098
89.59801,7.46651,638.70763,-0.31872,26.31272,32.23598
89.69801,7.47482,638.53282,-0.31871,26.34596,32.22716
89.79801,7.48313,638.22218,-0.31872,26.37920,32.21148
89.89800,7.49150,638.40365,-0.31872,26.41268,32.22064
89.99800,7.49987,637.49687,-0.31872,26.44617,32.17487
90.09801,7.50813,636.70129,-0.31872,26.47917,32.13472
90.19801,7.51650,636.27288,-0.31872,26.51265,32.11310
90.29801,7.52487,636.20578,-0.31872,26.54614,32.10971
90.39800,7.53318,635.61117,-0.31872,26.57938,32.07970
90.49800,7.54155,635.75567,-0.31871,26.61286,32.08699
90.59801,7.54992,635.29839,-0.31872,26.64634,32.06392
90.69801,7.55811,634.23696,-0.31872,26.67911,32.01035
90.79801,7.56648,633.66257,-0.31872,26.71259,31.98135
90.89800,7.57485,633.49912,-0.31871,26.74607,31.97310
90.99800,7.58310,632.53730,-0.31872,26.77908,31.92456
91.09801,7.59147,630.81239,-0.31872,26.81256,31.83751
91.19801,7.59984,629.49997,-0.31872,26.84604,31.77127
91.29801,7.60809,628.39035,-0.31872,26.87904,31.71526
91.39800,7.61646,625.61897,-0.31872,26.91253,31.57539
91.49800,7.62489,620.69916,-0.31872,26.94625,31.32708
91.59801,7.63315,610.17573,-0.31871,26.97925,30.79596
91.69801,7.64152,579.47664,-0.31872,27.01273,29.24656
91.79801,7.64989,541.93437,-0.31872,27.04622,27.35177
91.89800,7.65808,481.03924,-0.31872,27.07898,24.27836
91.98000,7.66501,3.82319,-0.31872,27.10672,0.19296