File: IA-QUS-MEC/Ensaio Mecânico/Dados/Specimen_RawData_2[1].csv
Time,Extension,Load,Strain 1,Tensile strain,Tensile stress
(sec),(mm),(N),,(%),(MPa)
0.00000,-0.00006,26.74156,0.00000,-0.00024,0.63159
0.10000,0.00054,28.18536,0.00000,0.00215,0.66569
0.20000,0.00275,31.28084,0.00000,0.01100,0.73880
0.30000,0.00741,43.92011,0.00000,0.02966,1.03732
0.40000,0.01190,55.74825,0.00000,0.04759,1.31668
0.50000,0.01608,65.87530,0.00000,0.06433,1.55586
0.60000,0.01973,75.62941,0.00000,0.07892,1.78624
0.70000,0.02314,83.92906,0.00000,0.09255,1.98226
0.80000,0.02655,92.75959,0.00000,0.10619,2.19083
0.90000,0.02989,101.76254,0.00000,0.11958,2.40346
1.00000,0.03324,110.32531,0.00000,0.13297,2.60570
1.10000,0.03671,119.03681,0.00000,0.14684,2.81145
1.20000,0.04000,128.10651,0.00000,0.16000,3.02566
1.30000,0.04335,137.92168,0.00000,0.17339,3.25748
1.40000,0.04676,146.73073,0.00000,0.18702,3.46553
1.50000,0.04992,155.28093,0.00000,0.19970,3.66748
1.60000,0.05327,163.64764,0.00000,0.21309,3.86508
1.70000,0.05668,172.83428,0.00000,0.22672,4.08206
1.80000,0.05997,180.64772,0.00000,0.23988,4.26660
1.90000,0.06326,189.10599,0.00000,0.25303,4.46637
2.00000,0.06673,196.80683,0.00000,0.26690,4.64825
2.10000,0.06995,205.40764,0.00000,0.27981,4.85139
2.20000,0.07318,212.65347,0.00000,0.29273,5.02252
2.30000,0.07659,221.31354,0.00000,0.30636,5.22706
2.40000,0.07994,229.74752,0.00000,0.31975,5.42625
2.50000,0.08329,237.80949,0.00000,0.33315,5.61666
2.60000,0.08663,246.61792,0.00000,0.34654,5.82470
2.70000,0.09004,255.61480,0.00000,0.36017,6.03719
2.80000,0.09333,263.85833,0.00000,0.37333,6.23189
2.90000,0.09656,271.44379,0.00000,0.38624,6.41105
3.00000,0.09997,280.61860,0.00000,0.39987,6.62774
3.10000,0.10332,289.43680,0.00000,0.41326,6.83601
3.20000,0.10660,298.56558,0.00000,0.42642,7.05162
3.30000,0.11001,307.64802,0.00000,0.44005,7.26613
3.40000,0.11336,315.76734,0.00000,0.45344,7.45790
3.50000,0.11665,325.02264,0.00000,0.46660,7.67649
3.60000,0.11994,334.21232,0.00000,0.47975,7.89354
3.70000,0.12323,343.45414,0.00000,0.49290,8.11181
3.80000,0.12657,353.56029,0.00000,0.50630,8.35050
3.90000,0.12998,362.25689,0.00000,0.51993,8.55590
4.00000,0.13333,372.29285,0.00000,0.53332,8.79293
4.10000,0.13668,382.03008,0.00000,0.54672,9.02291
4.20000,0.14003,391.86156,0.00000,0.56011,9.25511
4.30000,0.14326,400.45348,0.00000,0.57302,9.45804
4.40000,0.14654,409.59911,0.00000,0.58618,9.67405
4.50000,0.14989,418.72701,0.00000,0.59957,9.88963
4.60000,0.15324,428.04345,0.00000,0.61296,10.10967
4.70000,0.15665,437.20803,0.00000,0.62659,10.32612
4.80000,0.16000,446.53961,0.00000,0.63999,10.54652
4.90000,0.16334,456.48497,0.00000,0.65338,10.78141
5.00000,0.16663,464.77909,0.00000,0.66653,10.97731
5.10000,0.16986,473.92952,0.00000,0.67945,11.19342
5.20000,0.17327,483.82343,0.00000,0.69308,11.42710
5.30000,0.17662,493.54667,0.00000,0.70647,11.65675
5.40000,0.17991,502.38483,0.00000,0.71963,11.86549
5.50000,0.18331,511.88245,0.00000,0.73326,12.08981
5.60000,0.18672,521.86209,0.00000,0.74689,12.32551
5.70000,0.18989,532.29760,0.00000,0.75957,12.57198
5.80000,0.19324,542.05772,0.00000,0.77296,12.80250
5.90000,0.19659,551.32410,0.00000,0.78635,13.02135
6.00000,0.19994,560.56967,0.00000,0.79974,13.23972
6.10000,0.20334,570.08890,0.00000,0.81338,13.46455
6.20000,0.20669,579.58043,0.00000,0.82677,13.68872
6.30000,0.21004,589.40030,0.00000,0.84016,13.92065
6.40000,0.21333,598.81103,0.00000,0.85332,14.14292
6.50000,0.21656,607.59787,0.00000,0.86623,14.35045
6.60000,0.21985,616.86700,0.00000,0.87938,14.56937
6.70000,0.22325,626.70801,0.00000,0.89302,14.80180
6.80000,0.22660,635.90123,0.00000,0.90641,15.01892
6.90000,0.22995,644.84561,0.00000,0.91980,15.23018
7.00000,0.23336,654.34291,0.00000,0.93343,15.45448
7.10000,0.23665,663.19457,0.00000,0.94659,15.66355
7.20000,0.23994,672.85611,0.00000,0.95974,15.89174
7.30000,0.24322,681.57073,0.00000,0.97289,16.09756
7.40000,0.24663,691.14710,0.00000,0.98653,16.32374
7.50000,0.24998,701.99636,0.00000,0.99992,16.57998
7.60000,0.25333,712.97963,0.00000,1.01331,16.83939
7.70000,0.25680,725.38527,0.00000,1.02718,17.13239
7.80000,0.26008,735.93133,0.00000,1.04034,17.38147
7.90000,0.26325,747.33440,0.00000,1.05301,17.65079
8.00000,0.26666,758.40778,0.00000,1.06664,17.91232
8.10000,0.26989,768.69503,0.00000,1.07956,18.15529
8.20000,0.27324,780.84134,0.00000,1.09295,18.44217
8.30000,0.27671,792.78005,0.00000,1.10682,18.72414
8.40000,0.28005,804.26810,0.00000,1.12022,18.99547
8.50000,0.28328,814.90781,0.00000,1.13313,19.24676
8.60000,0.28663,825.21150,0.00000,1.14652,19.49012
8.70000,0.28986,836.58807,0.00000,1.15944,19.75881
8.80000,0.29321,847.91547,0.00000,1.17283,20.02635
8.90000,0.29662,859.74121,0.00000,1.18646,20.30565
9.00000,0.29996,870.48486,0.00000,1.19986,20.55940
9.10000,0.30331,881.52671,0.00000,1.21325,20.82019
9.20000,0.30672,893.23698,0.00000,1.22688,21.09676
9.30000,0.30995,904.14966,0.00000,1.23979,21.35450
9.40000,0.31318,914.22517,0.00000,1.25271,21.59247
9.50000,0.31659,926.27294,0.00000,1.26634,21.87702
9.60000,0.31999,938.06405,0.00000,1.27997,22.15550
9.70000,0.32334,949.67363,0.00000,1.29337,22.42970
9.80000,0.32669,961.04769,0.00000,1.30676,22.69834
9.90000,0.33010,972.05676,0.00000,1.32039,22.95835
10.00000,0.33339,982.37069,0.00000,1.33354,23.20195
10.10000,0.33661,992.64048,0.00000,1.34646,23.44451
10.20000,0.33996,1004.74395,0.00000,1.35985,23.73037
10.30000,0.34331,1015.19777,0.00000,1.37325,23.97727
10.40000,0.34666,1025.85293,0.00000,1.38664,24.22893
10.50000,0.35013,1037.25847,0.00000,1.40051,24.49831
10.60000,0.35342,1048.00137,0.00000,1.41366,24.75204
10.70000,0.35664,1057.79339,0.00000,1.42658,24.98331
10.80000,0.35993,1068.25819,0.00000,1.43973,25.23047
10.90000,0.36316,1079.43695,0.00000,1.45265,25.49450
11.00000,0.36651,1090.12704,0.00000,1.46604,25.74698
11.10000,0.36992,1100.73397,0.00000,1.47967,25.99750
11.20000,0.37327,1111.03877,0.00000,1.49306,26.24088
11.30000,0.37667,1122.09674,0.00000,1.50670,26.50205
11.40000,0.38002,1132.59898,0.00000,1.52009,26.75009
11.50000,0.38319,1142.80321,0.00000,1.53276,26.99110
11.60000,0.38654,1154.23547,0.00000,1.54616,27.26111
11.70000,0.38995,1164.58125,0.00000,1.55979,27.50546
11.80000,0.39324,1175.25607,0.00000,1.57294,27.75758
11.90000,0.39664,1186.12200,0.00000,1.58657,28.01422
12.00000,0.39999,1196.04152,0.00000,1.59997,28.24850
12.10000,0.40334,1207.14633,0.00000,1.61336,28.51078
12.20000,0.40663,1217.31320,0.00000,1.62651,28.75090
12.30000,0.40992,1227.91864,0.00000,1.63967,29.00138
12.40000,0.41326,1238.25083,0.00000,1.65306,29.24541
12.50000,0.41667,1248.34450,0.00000,1.66669,29.48381
12.60000,0.41996,1257.67328,0.00000,1.67985,29.70414
12.70000,0.42331,1268.39550,0.00000,1.69324,29.95738
12.80000,0.42666,1279.30259,0.00000,1.70663,30.21499
12.90000,0.42995,1289.18001,0.00000,1.71978,30.44828
13.00000,0.43329,1298.86800,0.00000,1.73318,30.67709
13.10000,0.43664,1308.98012,0.00000,1.74657,30.91592
13.20000,0.43993,1318.52310,0.00000,1.75972,31.14131
13.30000,0.44334,1328.90753,0.00000,1.77336,31.38657
13.40000,0.44669,1339.64932,0.00000,1.78675,31.64028
13.50000,0.44998,1348.88440,0.00000,1.79990,31.85839
13.60000,0.45332,1358.31665,0.00000,1.81330,32.08117
13.70000,0.45655,1367.71621,0.00000,1.82621,32.30317
13.80000,0.45990,1377.97687,0.00000,1.83960,32.54551
13.90000,0.46331,1387.55413,0.00000,1.85324,32.77171
14.00000,0.46660,1396.90666,0.00000,1.86639,32.99260
14.10000,0.46995,1406.38817,0.00000,1.87978,33.21654
14.20000,0.47329,1416.21660,0.00000,1.89317,33.44867
14.30000,0.47664,1424.82379,0.00000,1.90657,33.65195
14.40000,0.47987,1434.67607,0.00000,1.91948,33.88465
14.50000,0.48328,1444.56541,0.00000,1.93311,34.11822
14.60000,0.48669,1453.53451,0.00000,1.94675,34.33006
14.70000,0.48997,1461.62361,0.00000,1.95990,34.52111
14.80000,0.49326,1470.91262,0.00000,1.97305,34.74050
14.90000,0.49667,1480.84471,0.00000,1.98669,34.97507
15.00000,0.49996,1489.84455,0.00000,1.99984,35.18764
15.10000,0.50319,1498.03432,0.00000,2.01275,35.38107
15.20000,0.50666,1507.14796,0.00000,2.02662,35.59631
15.30000,0.51000,1516.41518,0.00000,2.04002,35.81519
15.40000,0.51329,1524.92849,0.00000,2.05317,36.01626
15.50000,0.51670,1534.52372,0.00000,2.06680,36.24289
15.60000,0.51999,1543.30842,0.00000,2.07996,36.45036
15.70000,0.52328,1551.59142,0.00000,2.09311,36.64600
15.80000,0.52669,1561.14725,0.00000,2.10674,36.87169
15.90000,0.52997,1570.95212,0.00000,2.11990,37.10326
16.00000,0.53326,1579.11796,0.00000,2.13305,37.29613
16.10000,0.53661,1588.84507,0.00000,2.14644,37.52586
16.20000,0.53990,1597.26273,0.00000,2.15960,37.72467
16.30000,0.54325,1606.41279,0.00000,2.17299,37.94078
16.40000,0.54660,1614.99381,0.00000,2.18638,38.14345
16.50000,0.54994,1624.17516,0.00000,2.19977,38.36030
16.60000,0.55323,1633.01677,0.00000,2.21293,38.56913
16.70000,0.55658,1641.94070,0.00000,2.22632,38.77989
16.80000,0.55999,1650.81061,0.00000,2.23995,38.98939
16.90000,0.56328,1660.01003,0.00000,2.25311,39.20666
17.00000,0.56657,1668.50928,0.00000,2.26626,39.40740
17.10000,0.57003,1677.57981,0.00000,2.28013,39.62163
17.20000,0.57332,1685.49921,0.00000,2.29329,39.80867
17.30000,0.57661,1694.54031,0.00000,2.30644,40.02221
17.40000,0.58002,1703.86452,0.00000,2.32007,40.24243
17.50000,0.58331,1710.80548,0.00000,2.33322,40.40636
17.60000,0.58683,232.07080,0.00000,2.34734,5.48112
17.70000,0.59018,269.72862,0.00000,2.36073,6.37054
17.80000,0.59341,281.88643,0.00000,2.37364,6.65769
17.90000,0.59664,292.46400,0.00000,2.38656,6.90751
18.00000,0.59999,303.31369,0.00000,2.39995,7.16376
18.10000,0.60328,313.20420,0.00000,2.41310,7.39736
18.20000,0.60662,323.10514,0.00000,2.42650,7.63120
18.30000,0.60997,331.86774,0.00000,2.43989,7.83816
18.40000,0.61320,340.44848,0.00000,2.45280,8.04082
18.50000,0.61661,349.41817,0.00000,2.46644,8.25267
18.60000,0.61996,358.08010,0.00000,2.47983,8.45725
18.70000,0.62325,367.02002,0.00000,2.49298,8.66840
18.80000,0.62659,375.17871,0.00000,2.50638,8.86109
18.90000,0.62994,383.22459,0.00000,2.51977,9.05112
19.00000,0.63323,391.01262,0.00000,2.53292,9.23506
19.10000,0.63658,400.05404,0.00000,2.54631,9.44861
19.20000,0.63993,408.09778,0.00000,2.55971,9.63859
19.30000,0.64328,416.27884,0.00000,2.57310,9.83181
19.40000,0.64656,424.11359,0.00000,2.58625,10.01685
19.50000,0.64991,432.17465,0.00000,2.59965,10.20724
19.60000,0.65332,440.57681,0.00000,2.61328,10.40569
19.70000,0.65661,449.31606,0.00000,2.62643,10.61209
19.80000,0.65996,457.32134,0.00000,2.63983,10.80117
19.90000,0.66336,465.01076,0.00000,2.65346,10.98278
20.00000,0.66665,473.24710,0.00000,2.66661,11.17731
20.10000,0.66988,480.52901,0.00000,2.67953,11.34929
20.20000,0.67335,489.02421,0.00000,2.69340,11.54993
20.30000,0.67664,496.40937,0.00000,2.70655,11.72436
20.40000,0.67999,505.47170,0.00000,2.71994,11.93840
20.50000,0.68333,513.22980,0.00000,2.73334,12.12163
20.60000,0.68662,521.63424,0.00000,2.74649,12.32013
20.70000,0.68997,529.76883,0.00000,2.75988,12.51225
20.80000,0.69332,537.98915,0.00000,2.77328,12.70640
20.90000,0.69661,545.50860,0.00000,2.78643,12.88400
21.00000,0.69996,553.38568,0.00000,2.79982,13.07004
21.10000,0.70330,560.73940,0.00000,2.81321,13.24373
21.20000,0.70671,568.11571,0.00000,2.82685,13.41794
21.30000,0.71000,575.75507,0.00000,2.84000,13.59837
21.40000,0.71329,582.98078,0.00000,2.85315,13.76903
21.50000,0.71664,590.59239,0.00000,2.86655,13.94880
21.60000,0.71993,598.16893,0.00000,2.87970,14.12775
21.70000,0.72321,605.33863,0.00000,2.89285,14.29709
21.80000,0.72662,612.92411,0.00000,2.90649,14.47624
21.90000,0.72997,620.32412,0.00000,2.91988,14.65102
22.00000,0.73332,627.69563,0.00000,2.93327,14.82512
22.10000,0.73673,635.65550,0.00000,2.94690,15.01312
22.20000,0.74001,642.90287,0.00000,2.96006,15.18429
22.30000,0.74324,650.34148,0.00000,2.97297,15.35998
22.40000,0.74665,657.51974,0.00000,2.98660,15.52952
22.50000,0.75000,664.57796,0.00000,3.00000,15.69622
22.60000,0.75329,671.00963,0.00000,3.01315,15.84813
22.70000,0.75670,679.01248,0.00000,3.02678,16.03714
22.80000,0.75998,684.87790,0.00000,3.03994,16.17567
22.90000,0.76327,691.03483,0.00000,3.05309,16.32109
23.00000,0.76656,696.72470,0.00000,3.06624,16.45547
23.10000,0.76991,703.76894,0.00000,3.07964,16.62185
23.20000,0.77326,710.11628,0.00000,3.09303,16.77176
23.30000,0.77655,717.44821,0.00000,3.10618,16.94493
23.40000,0.77995,724.66661,0.00000,3.11982,17.11541
23.50000,0.78336,732.18821,0.00000,3.13345,17.29306
23.60000,0.78665,739.25420,0.00000,3.14660,17.45995
23.70000,0.79000,747.00471,0.00000,3.15999,17.64300
23.80000,0.79329,754.22809,0.00000,3.17315,17.81361
23.90000,0.79658,762.08320,0.00000,3.18630,17.99913
24.00000,0.79998,768.74597,0.00000,3.19993,18.15649
24.10000,0.80339,776.75600,0.00000,3.21357,18.34568
24.20000,0.80668,784.67941,0.00000,3.22672,18.53282
24.30000,0.81009,792.04850,0.00000,3.24035,18.70686
24.40000,0.81332,799.68702,0.00000,3.25327,18.88727
24.50000,0.81655,807.40880,0.00000,3.26618,19.06964
24.60000,0.81995,814.87307,0.00000,3.27981,19.24594
24.70000,0.82324,822.75569,0.00000,3.29297,19.43211
24.80000,0.82659,830.24101,0.00000,3.30636,19.60890
24.90000,0.83006,838.57412,0.00000,3.32023,19.80572
25.00000,0.83329,845.77268,0.00000,3.33314,19.97574
25.10000,0.83657,853.60939,0.00000,3.34630,20.16083
25.20000,0.83986,860.54904,0.00000,3.35945,20.32473
25.30000,0.84321,868.25220,0.00000,3.37285,20.50666
25.40000,0.84656,876.49729,0.00000,3.38624,20.70140
25.50000,0.84997,883.73683,0.00000,3.39987,20.87239
25.60000,0.85332,890.42736,0.00000,3.41326,21.03041
25.70000,0.85666,897.21410,0.00000,3.42666,21.19070
25.80000,0.86001,904.44339,0.00000,3.44005,21.36144
25.90000,0.86324,911.00074,0.00000,3.45296,21.51631
26.00000,0.86665,917.12084,0.00000,3.46659,21.66086
26.10000,0.87000,923.32764,0.00000,3.47999,21.80746
26.20000,0.87335,932.03187,0.00000,3.49338,22.01303
26.30000,0.87669,939.44091,0.00000,3.50677,22.18802
26.40000,0.88004,946.92232,0.00000,3.52017,22.36472
26.50000,0.88333,953.64572,0.00000,3.53332,22.52352
26.60000,0.88662,961.00699,0.00000,3.54647,22.69738
26.70000,0.88991,968.49781,0.00000,3.55963,22.87430
26.80000,0.89331,976.42755,0.00000,3.57326,23.06159
26.90000,0.89666,983.42830,0.00000,3.58665,23.22693
27.00000,0.90001,991.66818,0.00000,3.60004,23.42155
27.10000,0.90342,998.52029,0.00000,3.61368,23.58338
27.20000,0.90665,1005.01254,0.00000,3.62659,23.73672
27.30000,0.90988,1011.15732,0.00000,3.63951,23.88185
27.40000,0.91334,1019.21139,0.00000,3.65338,24.07207
27.50000,0.91657,1025.66900,0.00000,3.66629,24.22459
27.60000,0.91992,1032.22271,0.00000,3.67968,24.37937
27.70000,0.92333,1040.09835,0.00000,3.69332,24.56538
27.80000,0.92668,1045.81853,0.00000,3.70671,24.70049
27.90000,0.92991,1038.42719,0.00000,3.71962,24.52591
28.00000,0.93325,1037.15705,0.00000,3.73302,24.49591
28.10000,0.93654,1045.37765,0.00000,3.74617,24.69007
28.20000,0.93995,1054.08700,0.00000,3.75980,24.89577
28.30000,0.94330,1061.67039,0.00000,3.77320,25.07488
28.40000,0.94665,1067.71253,0.00000,3.78659,25.21758
28.50000,0.95000,1070.44037,0.00000,3.79998,25.28201
28.60000,0.95334,1075.81057,0.00000,3.81337,25.40885
28.70000,0.95663,1083.31889,0.00000,3.82653,25.58618
28.80000,0.95992,1089.18101,0.00000,3.83968,25.72463
28.90000,0.96327,1095.08196,0.00000,3.85307,25.86400
29.00000,0.96668,1101.94031,0.00000,3.86671,26.02599
29.10000,0.97002,1107.46669,0.00000,3.88010,26.15651
29.20000,0.97331,1113.02780,0.00000,3.89325,26.28786
29.30000,0.97672,1119.94389,0.00000,3.90688,26.45120
29.40000,0.98001,1124.46966,0.00000,3.92004,26.55809
29.50000,0.98324,1130.14262,0.00000,3.93295,26.69208
29.60000,0.98665,1136.84721,0.00000,3.94658,26.85043
29.70000,0.98999,1142.92176,0.00000,3.95998,26.99390
29.80000,0.99328,1148.59687,0.00000,3.97313,27.12794
29.90000,0.99663,1154.76865,0.00000,3.98652,27.27370
30.00000,0.99998,1159.57484,0.00000,3.99992,27.38722
30.10000,1.00327,1164.56021,0.00000,4.01307,27.50496
30.20000,1.00662,1169.88970,0.00000,4.02646,27.63084
30.30000,1.00996,1175.31950,0.00000,4.03986,27.75908
30.40000,1.01325,1180.04652,0.00000,4.05301,27.87073
30.50000,1.01660,1184.09293,0.00000,4.06640,27.96630
30.60000,1.01995,1190.39658,0.00000,4.07980,28.11518
30.70000,1.02330,1195.87714,0.00000,4.09319,28.24462
30.80000,1.02659,1199.75973,0.00000,4.10634,28.33632
30.90000,1.02987,1205.44620,0.00000,4.11950,28.47062
31.00000,1.03322,1210.06006,0.00000,4.13289,28.57960
31.10000,1.03657,1215.62276,0.00000,4.14628,28.71098
31.20000,1.03998,1220.13353,0.00000,4.15991,28.81751
31.30000,1.04333,1226.07835,0.00000,4.17331,28.95792
31.40000,1.04667,1230.54031,0.00000,4.18670,29.06330
31.50000,1.05002,1236.06417,0.00000,4.20009,29.19377
31.60000,1.05331,1240.23361,0.00000,4.21325,29.29224
31.70000,1.05666,1245.05246,0.00000,4.22664,29.40606
31.80000,1.06007,1250.85516,0.00000,4.24027,29.54311
31.90000,1.06336,1254.38636,0.00000,4.25342,29.62651
32.00000,1.06664,1259.28242,0.00000,4.26658,29.74215
32.10000,1.06999,1264.46187,0.00000,4.27997,29.86448
32.20000,1.07328,1269.10536,0.00000,4.29312,29.97415
32.30000,1.07657,1274.38810,0.00000,4.30628,30.09892
32.40000,1.07992,1279.59242,0.00000,4.31967,30.22183
32.50000,1.08327,1285.32760,0.00000,4.33306,30.35729
32.60000,1.08661,1290.91917,0.00000,4.34646,30.48935
32.70000,1.08996,1295.46234,0.00000,4.35985,30.59665
32.80000,1.09325,1301.49387,0.00000,4.37300,30.73911
32.90000,1.09660,1306.92990,0.00000,4.38640,30.86750
33.00000,1.09995,1311.77120,0.00000,4.39979,30.98184
33.10000,1.10324,1317.19857,0.00000,4.41294,31.11003
33.20000,1.10658,1322.47889,0.00000,4.42634,31.23474
33.30000,1.10993,1327.56997,0.00000,4.43973,31.35498
33.40000,1.11328,1333.57244,0.00000,4.45312,31.49675
33.50000,1.11663,1338.08870,0.00000,4.46651,31.60342
33.60000,1.11998,1342.37576,0.00000,4.47991,31.70467
33.70000,1.12332,1347.45566,0.00000,4.49330,31.82465
33.80000,1.12661,1352.22115,0.00000,4.50645,31.93720
33.90000,1.12996,1356.96651,0.00000,4.51985,32.04928
34.00000,1.13337,1361.35034,0.00000,4.53348,32.15282
34.10000,1.13660,1365.95117,0.00000,4.54639,32.26148
34.20000,1.13995,1371.85138,0.00000,4.55979,32.40084
34.30000,1.14335,1375.86165,0.00000,4.57342,32.49555
34.40000,1.14664,1379.31136,0.00000,4.58657,32.57703
34.50000,1.14993,1382.93114,0.00000,4.59973,32.66252
34.60000,1.15334,1388.11162,0.00000,4.61336,32.78487
34.70000,1.15663,1391.03131,0.00000,4.62651,32.85383
34.80000,1.15992,1394.33956,0.00000,4.63966,32.93197
34.90000,1.16326,1397.72817,0.00000,4.65306,33.01200
35.00000,1.16655,1400.89979,0.00000,4.66621,33.08691
35.10000,1.16990,1402.18213,0.00000,4.67960,33.11720
35.20000,1.17325,1402.68411,0.00000,4.69300,33.12906
35.30000,1.17654,1406.71413,0.00000,4.70615,33.22424
35.40000,1.17995,1410.08375,0.00000,4.71978,33.30382
35.50000,1.18329,1412.75395,0.00000,4.73318,33.36689
35.60000,1.18664,1416.37092,0.00000,4.74657,33.45231
35.70000,1.18993,1419.62012,0.00000,4.75972,33.52905
35.80000,1.19328,1422.34992,0.00000,4.77311,33.59352
35.90000,1.19669,1427.91718,0.00000,4.78675,33.72502
36.00000,1.20003,1432.51289,0.00000,4.80014,33.83356
36.10000,1.20326,1437.03138,0.00000,4.81305,33.94028
36.20000,1.20667,1441.95510,0.00000,4.82669,34.05657
36.30000,1.21002,1446.10936,0.00000,4.84008,34.15469
36.40000,1.21331,1445.38945,0.00000,4.85323,34.13768
36.50000,1.21666,1450.10659,0.00000,4.86663,34.24909
36.60000,1.22000,1454.50253,0.00000,4.88002,34.35292
36.70000,1.22329,1460.03189,0.00000,4.89317,34.48351
36.80000,1.22670,1464.62843,0.00000,4.90680,34.59208
36.90000,1.22999,1469.06050,0.00000,4.91996,34.69675
37.00000,1.23328,1475.19391,0.00000,4.93311,34.84161
37.10000,1.23663,1479.68531,0.00000,4.94650,34.94769
37.20000,1.23991,1484.33363,0.00000,4.95966,35.05748
37.30000,1.24326,1488.28505,0.00000,4.97305,35.15080
37.40000,1.24661,1493.24210,0.00000,4.98644,35.26788
37.50000,1.24996,1497.17629,0.00000,4.99984,35.36080
37.60000,1.25331,1500.53892,0.00000,5.01323,35.44022
37.70000,1.25660,1504.89360,0.00000,5.02638,35.54307
37.80000,1.25994,1508.97941,0.00000,5.03978,35.63957
37.90000,1.26329,1514.31384,0.00000,5.05317,35.76556
38.00000,1.26658,1517.82837,0.00000,5.06632,35.84857
38.10000,1.26987,1522.45685,0.00000,5.07948,35.95789
38.20000,1.27328,1527.22308,0.00000,5.09311,36.07045
38.30000,1.27663,1531.74959,0.00000,5.10650,36.17736
38.40000,1.28003,1535.91484,0.00000,5.12013,36.27574
38.50000,1.28338,1541.37127,0.00000,5.13353,36.40461
38.60000,1.28661,1545.69345,0.00000,5.14644,36.50669
38.70000,1.29002,1550.94722,0.00000,5.16007,36.63078
38.80000,1.29331,1553.94115,0.00000,5.17323,36.70149
38.90000,1.29665,1559.57378,0.00000,5.18662,36.83453
39.00000,1.30000,1563.81540,0.00000,5.20001,36.93470
39.10000,1.30329,1567.30339,0.00000,5.21316,37.01709
39.20000,1.30658,1571.17750,0.00000,5.22632,37.10859
39.30000,1.30999,1574.20728,0.00000,5.23995,37.18015
39.40000,1.31328,1575.84026,0.00000,5.25310,37.21871
39.50000,1.31656,1576.93457,0.00000,5.26626,37.24456
39.60000,1.31997,1579.82558,0.00000,5.27989,37.31284
39.70000,1.32332,1582.49345,0.00000,5.29328,37.37585
39.80000,1.32667,1586.50707,0.00000,5.30668,37.47065
39.90000,1.33002,1591.43638,0.00000,5.32007,37.58707
40.00000,1.33331,1595.98812,0.00000,5.33322,37.69457
40.10000,1.33671,1601.05694,0.00000,5.34685,37.81429
40.20000,1.34000,1605.19499,0.00000,5.36001,37.91202
40.30000,1.34335,1610.14833,0.00000,5.37340,38.02901
40.40000,1.34664,1614.53243,0.00000,5.38655,38.13256
40.50000,1.34993,1617.43071,0.00000,5.39971,38.20101
40.60000,1.35334,1623.08458,0.00000,5.41334,38.33455
40.70000,1.35662,1595.47515,0.00000,5.42649,37.68246
40.80000,1.35997,1600.53987,0.00000,5.43989,37.80207
40.90000,1.36338,1608.78263,0.00000,5.45352,37.99676
41.00000,1.36655,1616.92109,0.00000,5.46619,38.18897
41.10000,1.36990,1624.64809,0.00000,5.47959,38.37147
41.20000,1.37330,1631.98132,0.00000,5.49322,38.54467
41.30000,1.37665,1638.76954,0.00000,5.50661,38.70500
41.40000,1.37994,1645.68666,0.00000,5.51977,38.86837
41.50000,1.38335,1651.57095,0.00000,5.53340,39.00734
41.60000,1.38664,1656.14337,0.00000,5.54655,39.11534
41.70000,1.38993,1660.28589,0.00000,5.55971,39.21318
41.80000,1.39327,1664.49025,0.00000,5.57310,39.31248
41.90000,1.39656,1667.63030,0.00000,5.58625,39.38664
42.00000,1.39991,1668.64563,0.00000,5.59964,39.41062
42.10000,1.40332,1670.05621,0.00000,5.61328,39.44394
42.20000,1.40667,1670.79847,0.00000,5.62667,39.46147
42.30000,1.41002,1671.27419,0.00000,5.64006,39.47270
42.40000,1.41324,1673.17316,0.00000,5.65298,39.51755
42.50000,1.41659,1675.60335,0.00000,5.66637,39.57495
42.60000,1.41994,1677.74912,0.00000,5.67976,39.62563
42.70000,1.42323,1680.78318,0.00000,5.69292,39.69729
42.80000,1.42670,1684.75546,0.00000,5.70679,39.79111
42.90000,1.43005,1687.99758,0.00000,5.72018,39.86768
43.00000,1.43333,1690.95807,0.00000,5.73333,39.93760
43.10000,1.43668,1694.68056,0.00000,5.74673,40.02552
43.20000,1.43997,1698.97173,0.00000,5.75988,40.12687
43.30000,1.44320,1702.85013,0.00000,5.77279,40.21847
43.40000,1.44667,1706.44224,0.00000,5.78667,40.30331
43.50000,1.45001,1709.29711,0.00000,5.80006,40.37074
43.60000,1.45330,1712.42803,0.00000,5.81321,40.44469
43.70000,1.45671,1715.75695,0.00000,5.82684,40.52331
43.80000,1.45994,1717.33182,0.00000,5.83976,40.56050
43.90000,1.46317,1720.14330,0.00000,5.85267,40.62691
44.00000,1.46658,1724.38193,0.00000,5.86631,40.72702
44.10000,1.46992,1726.86949,0.00000,5.87970,40.78577
44.20000,1.47327,1730.50202,0.00000,5.89309,40.87156
44.30000,1.47668,1733.46512,0.00000,5.90672,40.94155
44.40000,1.47997,1736.23543,0.00000,5.91988,41.00698
44.50000,1.48326,1739.14470,0.00000,5.93303,41.07569
44.60000,1.48661,1742.82230,0.00000,5.94642,41.16255
44.70000,1.48989,1745.06661,0.00000,5.95958,41.21555
44.80000,1.49324,1748.31580,0.00000,5.97297,41.29230
44.90000,1.49665,1751.65143,0.00000,5.98660,41.37108
45.00000,1.50000,1754.39510,0.00000,6.00000,41.43588
45.10000,1.50341,1758.17218,0.00000,6.01363,41.52509
45.20000,1.50664,1760.30062,0.00000,6.02654,41.57536
45.30000,1.50992,1763.64928,0.00000,6.03970,41.65445
45.40000,1.51327,1767.02216,0.00000,6.05309,41.73411
45.50000,1.51662,1769.91653,0.00000,6.06648,41.80247
45.60000,1.52003,1773.77332,0.00000,6.08011,41.89356
45.70000,1.52338,1776.69991,0.00000,6.09351,41.96268
45.80000,1.52666,1779.64009,0.00000,6.10666,42.03212
45.90000,1.53001,1782.38861,0.00000,6.12005,42.09704
46.00000,1.53324,1784.67818,0.00000,6.13297,42.15112
46.10000,1.53659,1787.64723,0.00000,6.14636,42.22124
46.20000,1.54000,1790.48106,0.00000,6.15999,42.28817
46.30000,1.54329,1793.47415,0.00000,6.17315,42.35886
46.40000,1.54663,1796.65815,0.00000,6.18654,42.43406
46.50000,1.55004,1799.19619,0.00000,6.20017,42.49401
46.60000,1.55327,1801.59006,0.00000,6.21308,42.55054
46.70000,1.55656,1803.52330,0.00000,6.22624,42.59620
46.80000,1.55991,1806.88985,0.00000,6.23963,42.67572
46.90000,1.56326,1810.06920,0.00000,6.25302,42.75081
47.00000,1.56660,1810.69113,0.00000,6.26642,42.76550
47.10000,1.57001,1814.85601,0.00000,6.28005,42.86386
47.20000,1.57330,1818.92533,0.00000,6.29320,42.95998
47.30000,1.57665,1822.07655,0.00000,6.30660,43.03440
47.40000,1.57994,1825.47923,0.00000,6.31975,43.11477
47.50000,1.58329,1829.44499,0.00000,6.33314,43.20843
47.60000,1.58663,1832.03313,0.00000,6.34653,43.26956
47.70000,1.58998,1835.90334,0.00000,6.35993,43.36097
47.80000,1.59333,1839.05326,0.00000,6.37332,43.43536
47.90000,1.59674,1841.75745,0.00000,6.38695,43.49923
48.00000,1.60003,1844.45940,0.00000,6.40011,43.56305
48.10000,1.60337,1847.41430,0.00000,6.41350,43.63284
48.20000,1.60666,1850.73130,0.00000,6.42665,43.71118
48.30000,1.60995,1853.13746,0.00000,6.43981,43.76801
48.40000,1.61336,1856.57740,0.00000,6.45344,43.84925
48.50000,1.61665,1859.30785,0.00000,6.46659,43.91374
48.60000,1.61994,1861.71699,0.00000,6.47975,43.97064
48.70000,1.62334,1866.40415,0.00000,6.49338,44.08134
48.80000,1.62657,1868.64212,0.00000,6.50629,44.13420
48.90000,1.62986,1871.29509,0.00000,6.51945,44.19686
49.00000,1.63327,1874.19727,0.00000,6.53308,44.26540
49.10000,1.63656,1877.77504,0.00000,6.54623,44.34991
49.20000,1.63991,1880.99183,0.00000,6.55962,44.42588
49.30000,1.64325,1884.71172,0.00000,6.57302,44.51374
49.40000,1.64660,1888.46029,0.00000,6.58641,44.60228
49.50000,1.64995,1890.65114,0.00000,6.59980,44.65402
49.60000,1.65324,1893.85712,0.00000,6.61296,44.72974
49.70000,1.65659,1897.91303,0.00000,6.62635,44.82553
49.80000,1.66000,1901.30100,0.00000,6.63998,44.90555
49.90000,1.66328,1904.95811,0.00000,6.65314,44.99192
50.00000,1.66669,1908.33807,0.00000,6.66677,45.07175
50.10000,1.66998,1910.26498,0.00000,6.67992,45.11726
50.20000,1.67327,1913.11538,0.00000,6.69307,45.18459
50.30000,1.67668,1918.29950,0.00000,6.70671,45.30703
50.40000,1.68003,1920.24335,0.00000,6.72010,45.35294
50.50000,1.68331,1923.38936,0.00000,6.73325,45.42724
50.60000,1.68672,1927.20182,0.00000,6.74689,45.51728
50.70000,1.69001,1930.06769,0.00000,6.76004,45.58497
50.80000,1.69330,1933.53482,0.00000,6.77319,45.66686
50.90000,1.69671,1936.24049,0.00000,6.78682,45.73076
51.00000,1.69993,1938.70347,0.00000,6.79974,45.78893
51.10000,1.70322,1942.30508,0.00000,6.81289,45.87400
51.20000,1.70663,1945.80890,0.00000,6.82652,45.95675
51.30000,1.70986,1947.69278,0.00000,6.83944,46.00125
51.40000,1.71327,1951.97035,0.00000,6.85307,46.10228
51.50000,1.71662,1954.78611,0.00000,6.86646,46.16878
51.60000,1.71990,1957.18575,0.00000,6.87962,46.22546
51.70000,1.72325,1960.45768,0.00000,6.89301,46.30273
51.80000,1.72660,1963.56922,0.00000,6.90640,46.37622
51.90000,1.72989,1966.86089,0.00000,6.91956,46.45396
52.00000,1.73324,1969.51795,0.00000,6.93295,46.51672
52.10000,1.73659,1973.10876,0.00000,6.94634,46.60153
52.20000,1.73993,1976.89496,0.00000,6.95974,46.69095
52.30000,1.74334,1980.34160,0.00000,6.97337,46.77236
52.40000,1.74657,1981.93118,0.00000,6.98628,46.80990
52.50000,1.74992,1985.65628,0.00000,6.99968,46.89788
52.60000,1.75327,1988.93622,0.00000,7.01307,46.97535
52.70000,1.75662,1991.27849,0.00000,7.02646,47.03067
52.80000,1.76002,1995.70414,0.00000,7.04009,47.13519
52.90000,1.76337,1998.57242,0.00000,7.05349,47.20294
53.00000,1.76666,2001.48318,0.00000,7.06664,47.27169
53.10000,1.77007,2004.50122,0.00000,7.08027,47.34297
53.20000,1.77330,2007.08415,0.00000,7.09319,47.40397
53.30000,1.77664,2009.69633,0.00000,7.10658,47.46567
53.40000,1.77999,2012.47968,0.00000,7.11997,47.53141
53.50000,1.78328,2015.49679,0.00000,7.13313,47.60266
53.60000,1.78663,2018.52359,0.00000,7.14652,47.67415
53.70000,1.79004,2020.72691,0.00000,7.16015,47.72619
53.80000,1.79327,2022.78588,0.00000,7.17307,47.77482
53.90000,1.79655,2024.74929,0.00000,7.18622,47.82119
54.00000,1.79996,2028.02252,0.00000,7.19985,47.89850
54.10000,1.80325,2031.34120,0.00000,7.21300,47.97688
54.20000,1.80660,2034.38029,0.00000,7.22640,48.04866
54.30000,1.80995,2037.36238,0.00000,7.23979,48.11909
54.40000,1.81330,2040.55775,0.00000,7.25318,48.19456
54.50000,1.81664,2042.77672,0.00000,7.26658,48.24697
54.60000,1.81987,2045.65991,0.00000,7.27949,48.31507
54.70000,1.82334,2048.76643,0.00000,7.29336,48.38844
54.80000,1.82663,2051.61776,0.00000,7.30651,48.45578
54.90000,1.82998,2053.24590,0.00000,7.31991,48.49424
55.00000,1.83339,2056.51280,0.00000,7.33354,48.57139
55.10000,1.83667,2057.88705,0.00000,7.34669,48.60385
55.20000,1.83996,2059.79571,0.00000,7.35985,48.64893
55.30000,1.84337,2061.94241,0.00000,7.37348,48.69963
55.40000,1.84666,2062.57999,0.00000,7.38663,48.71469
55.50000,1.84995,2063.04528,0.00000,7.39979,48.72568
55.60000,1.85335,2063.94419,0.00000,7.41342,48.74691
55.70000,1.85664,2064.32436,0.00000,7.42657,48.75589
55.80000,1.85999,2066.45373,0.00000,7.43997,48.80618
55.90000,1.86334,2068.61794,0.00000,7.45336,48.85730
56.00000,1.86657,2072.62002,0.00000,7.46627,48.95182
56.10000,1.86992,2076.70312,0.00000,7.47967,49.04826
56.20000,1.87326,2079.43078,0.00000,7.49306,49.11268
56.30000,1.87655,2082.56338,0.00000,7.50621,49.18666
56.40000,1.87996,2086.53100,0.00000,7.51984,49.28037
56.50000,1.88331,2089.12306,0.00000,7.53324,49.34159
56.60000,1.88666,2091.34165,0.00000,7.54663,49.39399
56.70000,1.88995,2094.18777,0.00000,7.55978,49.46121
56.80000,1.89317,2096.22122,0.00000,7.57270,49.50924
56.90000,1.89664,2100.95756,0.00000,7.58657,49.62111
57.00000,1.89999,2103.08041,0.00000,7.59996,49.67124
57.10000,1.90328,2105.92821,0.00000,7.61312,49.73850
57.20000,1.90669,2110.31660,0.00000,7.62675,49.84215
57.30000,1.91004,2112.62889,0.00000,7.64014,49.89676
57.40000,1.91320,2115.22505,0.00000,7.65282,49.95808
57.50000,1.91661,2118.36044,0.00000,7.66645,50.03213
57.60000,1.91996,2122.12000,0.00000,7.67984,50.12093
57.70000,1.92325,2124.65059,0.00000,7.69299,50.18069
57.80000,1.92666,2128.16559,0.00000,7.70663,50.26371
57.90000,1.93000,2129.90250,0.00000,7.72002,50.30474
58.00000,1.93335,2132.85964,0.00000,7.73341,50.37458
58.10000,1.93670,2135.43363,0.00000,7.74680,50.43537
58.20000,1.93993,2137.63490,0.00000,7.75972,50.48736
58.30000,1.94328,2141.35088,0.00000,7.77311,50.57513
58.40000,1.94669,2143.21930,0.00000,7.78674,50.61926
58.50000,1.94997,2145.43566,0.00000,7.79990,50.67160
58.60000,1.95338,2147.65910,0.00000,7.81353,50.72412
58.70000,1.95673,2149.95611,0.00000,7.82692,50.77837
58.80000,1.95990,2151.19943,0.00000,7.83960,50.80773
58.90000,1.96325,2155.25795,0.00000,7.85299,50.90359
59.00000,1.96654,2157.41489,0.00000,7.86614,50.95453
59.10000,1.96988,2159.41444,0.00000,7.87954,51.00176
59.20000,1.97329,2161.50414,0.00000,7.89317,51.05111
59.30000,1.97664,2163.91180,0.00000,7.90656,51.10798
59.40000,1.97999,2166.51540,0.00000,7.91996,51.16947
59.50000,1.98334,2167.68552,0.00000,7.93335,51.19711
59.60000,1.98651,2169.13018,0.00000,7.94602,51.23123
59.70000,1.98991,2171.99754,0.00000,7.95966,51.29895
59.80000,1.99332,2173.67876,0.00000,7.97329,51.33866
59.90000,1.99661,2175.61405,0.00000,7.98644,51.38437
60.00000,2.00008,2178.12713,0.00000,8.00031,51.44372
60.10000,2.00337,2178.88355,0.00000,8.01347,51.46159
60.20000,2.00665,2180.98965,0.00000,8.02662,51.51133
60.30000,2.01000,2183.11362,0.00000,8.04001,51.56149
60.40000,2.01323,2185.22064,0.00000,8.05293,51.61126
60.50000,2.01658,2187.37032,0.00000,8.06632,51.66203
60.60000,2.01999,2190.35428,0.00000,8.07995,51.73251
60.70000,2.02334,2191.79038,0.00000,8.09334,51.76642
60.80000,2.02668,2193.92218,0.00000,8.10674,51.81677
60.90000,2.03003,2195.97016,0.00000,8.12013,51.86514
61.00000,2.03326,2196.59712,0.00000,8.13304,51.87995
61.10000,2.03655,2198.04328,0.00000,8.14620,51.91411
61.20000,2.03990,2200.19929,0.00000,8.15959,51.96503
61.30000,2.04331,2202.44732,0.00000,8.17322,52.01812
61.40000,2.04665,2203.59899,0.00000,8.18662,52.04532
61.50000,2.05006,2205.19919,0.00000,8.20025,52.08312
61.60000,2.05341,2205.32790,0.00000,8.21364,52.08616
61.70000,2.05664,2206.08730,0.00000,8.22656,52.10409
61.80000,2.05987,2206.76512,0.00000,8.23947,52.12010
61.90000,2.06328,2208.60690,0.00000,8.25310,52.16360
62.00000,2.06662,2209.54120,0.00000,8.26650,52.18567
62.10000,2.06991,2209.65408,0.00000,8.27965,52.18834
62.20000,2.07338,2211.83971,0.00000,8.29352,52.23996
62.30000,2.07673,2211.24645,0.00000,8.30691,52.22594
62.40000,2.07990,2212.54136,0.00000,8.31959,52.25653
62.50000,2.08325,2213.37751,0.00000,8.33298,52.27628
62.60000,2.08659,2215.97813,0.00000,8.34637,52.33770
62.70000,2.08988,2216.90368,0.00000,8.35953,52.35956
62.80000,2.09335,2218.81922,0.00000,8.37340,52.40480
62.90000,2.09670,2220.49169,0.00000,8.38679,52.44430
63.00000,2.09999,2221.51447,0.00000,8.39994,52.46846
63.10000,2.10333,2222.83900,0.00000,8.41334,52.49974
63.20000,2.10656,2222.94275,0.00000,8.42625,52.50219
63.30000,2.10991,2224.68060,0.00000,8.43965,52.54324
63.40000,2.11326,2225.03338,0.00000,8.45304,52.55157
63.50000,2.11661,2227.02455,0.00000,8.46643,52.59859
63.60000,2.12002,2228.07582,0.00000,8.48006,52.62342
63.70000,2.12336,2228.51131,0.00000,8.49346,52.63371
63.80000,2.12665,2230.00459,0.00000,8.50661,52.66898
63.90000,2.12988,2231.40959,0.00000,8.51952,52.70216
64.00000,2.13323,2232.92746,0.00000,8.53292,52.73801
64.10001,2.13658,2209.33277,0.00000,8.54631,52.18074
64.20000,2.13999,2213.42519,0.00000,8.55994,52.27740
64.30000,2.14333,2219.43930,0.00000,8.57333,52.41945
64.40000,2.14668,2225.81234,0.00000,8.58673,52.56997
64.50000,2.15003,2229.67230,0.00000,8.60012,52.66113
64.60001,2.15326,2232.62254,0.00000,8.61304,52.73081
64.70000,2.15661,2236.32529,0.00000,8.62643,52.81826
64.80000,2.15996,2238.85700,0.00000,8.63982,52.87806
64.90000,2.16324,2240.84593,0.00000,8.65297,52.92503
65.00000,2.16665,2244.08023,0.00000,8.66661,53.00142
65.10001,2.17006,2245.30566,0.00000,8.68024,53.03036
65.20000,2.17335,2247.10535,0.00000,8.69339,53.07287
65.30000,2.17664,2248.74988,0.00000,8.70655,53.11171
65.40000,2.17987,2250.90291,0.00000,8.71946,53.16256
65.50000,2.18321,2254.17875,0.00000,8.73285,53.23993
65.60001,2.18662,2256.02929,0.00000,8.74649,53.28364
65.70001,2.18997,2258.48984,0.00000,8.75988,53.34175
65.80000,2.19332,2260.94890,0.00000,8.77327,53.39983
65.90000,2.19673,2262.40885,0.00000,8.78690,53.43431
66.00000,2.19995,2263.38916,0.00000,8.79982,53.45747
66.10001,2.20318,2264.84928,0.00000,8.81273,53.49195
66.20001,2.20659,2266.96748,0.00000,8.82636,53.54198
66.30000,2.20994,2269.60275,0.00000,8.83976,53.60422
66.40000,2.21335,2271.71518,0.00000,8.85339,53.65411
66.50000,2.21670,2273.60558,0.00000,8.86678,53.69876
66.60001,2.22004,2275.38776,0.00000,8.88017,53.74085
66.70001,2.22333,2276.70502,0.00000,8.89333,53.77197
66.80000,2.22656,2277.69315,0.00000,8.90624,53.79530
66.90000,2.22997,2280.25503,0.00000,8.91987,53.85581
67.00000,2.23326,2281.58217,0.00000,8.93303,53.88716
67.10001,2.23661,2283.75122,0.00000,8.94642,53.93839
67.20001,2.24007,2286.72419,0.00000,8.96029,54.00860
67.30000,2.24336,2287.78683,0.00000,8.97345,54.03370
67.40000,2.24659,2288.75596,0.00000,8.98636,54.05659
67.50000,2.24994,2290.43104,0.00000,8.99975,54.09615
67.60001,2.25323,2292.12046,0.00000,9.01291,54.13605
67.70001,2.25658,2293.87954,0.00000,9.02630,54.17760
67.80000,2.25998,2294.94516,0.00000,9.03993,54.20277
67.90000,2.26333,2296.42186,0.00000,9.05332,54.23764
68.00000,2.26662,2297.98853,0.00000,9.06648,54.27465
68.10001,2.27003,2299.48945,0.00000,9.08011,54.31010
68.20001,2.27320,2301.03619,0.00000,9.09279,54.34663
68.30000,2.27648,2302.69190,0.00000,9.10594,54.38573
68.40000,2.27995,2304.35058,0.00000,9.11981,54.42491
68.50000,2.28330,2305.98543,0.00000,9.13320,54.46352
68.60001,2.28665,2307.60016,0.00000,9.14660,54.50166
68.70001,2.29000,2309.71705,0.00000,9.15999,54.55165
68.80000,2.29335,2311.89709,0.00000,9.17338,54.60314
68.90000,2.29663,2312.05113,0.00000,9.18654,54.60678
69.00000,2.29992,2314.17697,0.00000,9.19969,54.65699
69.10001,2.30333,2316.42295,0.00000,9.21332,54.71004
69.20001,2.30668,2317.90505,0.00000,9.22671,54.74504
69.30000,2.31003,2318.92988,0.00000,9.24011,54.76925
69.40000,2.31338,2321.63109,0.00000,9.25350,54.83305
69.50000,2.31672,2321.91458,0.00000,9.26689,54.83974
69.60001,2.31995,2322.72185,0.00000,9.27981,54.85881
69.70001,2.32330,2324.01155,0.00000,9.29320,54.88927
69.80000,2.32659,2326.02712,0.00000,9.30635,54.93687
69.90000,2.32988,2327.14042,0.00000,9.31951,54.96317
70.00000,2.33328,2329.64028,0.00000,9.33314,55.02221
70.10001,2.33663,2331.82404,0.00000,9.34653,55.07378
70.20001,2.33998,2333.73344,0.00000,9.35993,55.11888
70.30000,2.34333,2333.77349,0.00000,9.37332,55.11983
70.40000,2.34656,2336.13160,0.00000,9.38623,55.17552
70.50000,2.34991,2338.02162,0.00000,9.39963,55.22016
70.60001,2.35331,2338.36621,0.00000,9.41326,55.22830
70.70001,2.35660,2340.81317,0.00000,9.42641,55.28609
70.80000,2.35995,2342.70710,0.00000,9.43980,55.33083
70.90000,2.36330,2344.01114,0.00000,9.45320,55.36162
71.00000,2.36659,2345.08403,0.00000,9.46635,55.38696
71.10001,2.36988,2346.10625,0.00000,9.47950,55.41111
71.20001,2.37322,2348.02272,0.00000,9.49290,55.45637
71.30000,2.37663,2350.19960,0.00000,9.50653,55.50779
71.40000,2.37998,2351.29446,0.00000,9.51992,55.53364
71.50000,2.38333,2353.05801,0.00000,9.53332,55.57529
71.60001,2.38668,2353.70379,0.00000,9.54671,55.59055
71.70001,2.39003,2355.09127,0.00000,9.56010,55.62332
71.80000,2.39325,2355.97119,0.00000,9.57302,55.64410
71.90000,2.39660,2357.56245,0.00000,9.58641,55.68168
72.00000,2.39995,2359.29526,0.00000,9.59980,55.72261
72.10001,2.40330,2359.72833,0.00000,9.61319,55.73284
72.20001,2.40665,2361.82585,0.00000,9.62659,55.78238
72.30000,2.40999,2362.58153,0.00000,9.63998,55.80022
72.40000,2.41334,2363.88221,0.00000,9.65337,55.83094
72.50000,2.41663,2365.28702,0.00000,9.66653,55.86412
72.60001,2.41992,2366.67152,0.00000,9.67968,55.89682
72.70001,2.42321,2366.59087,0.00000,9.69283,55.89492
72.80000,2.42662,2369.58675,0.00000,9.70647,55.96568
72.90000,2.42990,2370.73880,0.00000,9.71962,55.99289
73.00000,2.43331,2372.96242,0.00000,9.73325,56.04540
73.10001,2.43672,2373.87829,0.00000,9.74688,56.06704
73.20001,2.43995,2375.31550,0.00000,9.75980,56.10098
73.30000,2.44324,2376.16487,0.00000,9.77295,56.12104
73.40000,2.44659,2377.37931,0.00000,9.78634,56.14972
73.50000,2.44999,2379.72550,0.00000,9.79998,56.20514
73.60001,2.45328,2381.07666,0.00000,9.81313,56.23705
73.70001,2.45669,2382.71505,0.00000,9.82676,56.27575
73.80000,2.46004,2383.64879,0.00000,9.84015,56.29780
73.90000,2.46333,2384.84107,0.00000,9.85331,56.32596
74.00000,2.46656,2385.88918,0.00000,9.86622,56.35071
74.10001,2.46996,2387.87327,0.00000,9.87985,56.39758
74.20001,2.47331,2388.24822,0.00000,9.89325,56.40643
74.30000,2.47666,2390.57858,0.00000,9.90664,56.46147
74.40000,2.48013,2392.69696,0.00000,9.92051,56.51150
74.50000,2.48342,2393.31312,0.00000,9.93366,56.52605
74.60001,2.48664,2392.48164,0.00000,9.94658,56.50642
74.70001,2.48993,2395.44939,0.00000,9.95973,56.57651
74.80000,2.49322,2395.67086,0.00000,9.97289,56.58174
74.90000,2.49657,2397.19655,0.00000,9.98628,56.61777
75.00000,2.49998,2398.73845,0.00000,9.99991,56.65419
75.10001,2.50333,2400.58303,0.00000,10.01330,56.69776
75.20001,2.50661,2402.02341,0.00000,10.02646,56.73178
75.30000,2.50996,2402.68875,0.00000,10.03985,56.74749
75.40000,2.51319,2404.47540,0.00000,10.05277,56.78969
75.50000,2.51648,2405.32905,0.00000,10.06592,56.80985
75.60001,2.51989,2406.63402,0.00000,10.07955,56.84067
75.70001,2.52330,2409.67926,0.00000,10.09318,56.91259
75.80000,2.52670,2411.38004,0.00000,10.10682,56.95276
75.90000,2.53005,2412.05320,0.00000,10.12021,56.96866
76.00000,2.53334,2412.75709,0.00000,10.13336,56.98529
76.10001,2.53663,2412.96031,0.00000,10.14652,56.99009
76.20001,2.53986,2413.92050,0.00000,10.15943,57.01276
76.30000,2.54333,2416.37733,0.00000,10.17330,57.07079
76.40000,2.54667,2416.63624,0.00000,10.18669,57.07691
76.50000,2.55002,2418.42121,0.00000,10.20009,57.11906
76.60001,2.55349,2420.24530,0.00000,10.21396,57.16215
76.70001,2.55678,2420.24139,0.00000,10.22711,57.16206
76.80000,2.55989,2420.52618,0.00000,10.23955,57.16878
76.90000,2.56324,2421.16749,0.00000,10.25294,57.18393
77.00000,2.56658,2422.96886,0.00000,10.26633,57.22647
77.10001,2.56993,2423.74446,0.00000,10.27973,57.24479
77.20001,2.57340,2425.88483,0.00000,10.29360,57.29534
77.30000,2.57675,2427.07487,0.00000,10.30699,57.32345
77.40000,2.58004,2427.80335,0.00000,10.32014,57.34066
77.50000,2.58326,2427.99968,0.00000,10.33306,57.34529
77.60001,2.58649,2429.76937,0.00000,10.34597,57.38709
77.70001,2.58984,2431.02983,0.00000,10.35937,57.41686
77.80000,2.59325,2431.32692,0.00000,10.37300,57.42388
77.90000,2.59660,2432.95096,0.00000,10.38639,57.46223
78.00000,2.60001,2433.82789,0.00000,10.40002,57.48294
78.10001,2.60335,2434.49137,0.00000,10.41342,57.49862
78.20001,2.60658,2434.82310,0.00000,10.42633,57.50645
78.30000,2.60987,2436.66805,0.00000,10.43948,57.55003
78.40000,2.61316,2437.14545,0.00000,10.45264,57.56130
78.50000,2.61657,2438.34201,0.00000,10.46627,57.58956
78.60001,2.61998,2439.69616,0.00000,10.47990,57.62154
78.70001,2.62338,2441.45617,0.00000,10.49353,57.66311
78.80000,2.62679,2442.45976,0.00000,10.50717,57.68682
78.90000,2.63002,2442.64081,0.00000,10.52008,57.69109
79.00000,2.63325,2443.32533,0.00000,10.53299,57.70726
79.10001,2.63660,2445.07901,0.00000,10.54639,57.74868
79.20001,2.63995,2446.10272,0.00000,10.55978,57.77286
79.30000,2.64329,2447.43489,0.00000,10.57317,57.80432
79.40000,2.64676,2450.11281,0.00000,10.58704,57.86757
79.50000,2.65005,2450.37116,0.00000,10.60020,57.87367
79.60001,2.65334,2450.15230,0.00000,10.61335,57.86850
79.70001,2.65663,2451.06593,0.00000,10.62651,57.89008
79.80000,2.65986,2451.34551,0.00000,10.63942,57.89668
79.90000,2.66320,2453.16587,0.00000,10.65281,57.93967
80.00000,2.66667,2454.30935,0.00000,10.66668,57.96668
80.10001,2.67002,2455.13096,0.00000,10.68008,57.98609
80.20001,2.67337,2456.18578,0.00000,10.69347,58.01100
80.30000,2.67666,2455.69944,0.00000,10.70662,57.99952
80.40000,2.67988,2455.64766,0.00000,10.71954,57.99829
80.50001,2.68317,2457.37303,0.00000,10.73269,58.03904
80.60001,2.68658,2457.80256,0.00000,10.74632,58.04919
80.70001,2.68999,2460.10311,0.00000,10.75996,58.10352
80.80000,2.69340,2461.21939,0.00000,10.77359,58.12989
80.90000,2.69675,2462.37312,0.00000,10.78698,58.15714
81.00001,2.70009,2462.84250,0.00000,10.80037,58.16822
81.10001,2.70326,2461.81283,0.00000,10.81305,58.14390
81.20001,2.70655,2462.78569,0.00000,10.82620,58.16688
81.30000,2.70996,2464.76140,0.00000,10.83983,58.21354
81.40000,2.71331,2465.77784,0.00000,10.85323,58.23755
81.50001,2.71666,2466.81478,0.00000,10.86662,58.26204
81.60001,2.72012,2468.50718,0.00000,10.88049,58.30201
81.70001,2.72341,2468.18475,0.00000,10.89365,58.29440
81.80000,2.72652,2468.48390,0.00000,10.90608,58.30146
81.90000,2.72993,2470.50542,0.00000,10.91971,58.34921
82.00001,2.73322,2471.79009,0.00000,10.93287,58.37955
82.10001,2.73656,2472.55508,0.00000,10.94626,58.39762
82.20001,2.73997,2473.29734,0.00000,10.95989,58.41515
82.30000,2.74338,2475.57405,0.00000,10.97352,58.46892
82.40000,2.74667,2476.29713,0.00000,10.98668,58.48600
82.50001,2.74996,2477.18506,0.00000,10.99983,58.50697
82.60001,2.75319,2478.30637,0.00000,11.01275,58.53345
82.70001,2.75659,2480.46946,0.00000,11.02638,58.58454
82.80000,2.75994,2480.48641,0.00000,11.03977,58.58494
82.90000,2.76335,2482.24940,0.00000,11.05340,58.62658
83.00001,2.76670,2483.29341,0.00000,11.06680,58.65124
83.10001,2.76999,2483.53872,0.00000,11.07995,58.65703
83.20001,2.77334,2484.98935,0.00000,11.09334,58.69129
83.30000,2.77662,2485.51369,0.00000,11.10650,58.70368
83.40000,2.77991,2486.27011,0.00000,11.11965,58.72154
83.50001,2.78332,2487.90048,0.00000,11.13328,58.76005
83.60001,2.78667,2488.50323,0.00000,11.14668,58.77428
83.70001,2.78996,2488.78673,0.00000,11.15983,58.78098
83.80000,2.79342,2490.55438,0.00000,11.17370,58.82273
83.90000,2.79671,2490.12429,0.00000,11.18685,58.81257
84.00001,2.79988,2490.07251,0.00000,11.19953,58.81135
84.10001,2.80323,2492.35369,0.00000,11.21292,58.86523
84.20001,2.80658,2492.78694,0.00000,11.22631,58.87546
84.30000,2.80993,2493.19077,0.00000,11.23971,58.88500
84.40000,2.81333,2494.83082,0.00000,11.25334,58.92373
84.50001,2.81668,2495.46729,0.00000,11.26673,58.93876
84.60001,2.81997,2495.86720,0.00000,11.27989,58.94821
84.70001,2.82326,2496.03670,0.00000,11.29304,58.95221
84.80000,2.82655,2497.02800,0.00000,11.30619,58.97562
84.90000,2.82996,2497.88407,0.00000,11.31983,58.99585
85.00001,2.83330,2499.44162,0.00000,11.33322,59.03263
85.10001,2.83659,2499.38369,0.00000,11.34637,59.03126
85.20001,2.84006,2501.35977,0.00000,11.36024,59.07793
85.30000,2.84335,2501.79768,0.00000,11.37340,59.08828
85.40000,2.84658,2502.54273,0.00000,11.38631,59.10587
85.50001,2.84987,2503.18777,0.00000,11.39946,59.12111
85.60001,2.85327,2503.97548,0.00000,11.41310,59.13971
85.70001,2.85662,2505.11412,0.00000,11.42649,59.16661
85.80000,2.85997,2504.91258,0.00000,11.43988,59.16185
85.90000,2.86332,2506.27361,0.00000,11.45328,59.19399
86.00001,2.86667,2507.21369,0.00000,11.46667,59.21619
86.10001,2.86996,2506.22109,0.00000,11.47982,59.19275
86.20001,2.87324,2507.89840,0.00000,11.49297,59.23236
86.30000,2.87665,2508.40560,0.00000,11.50661,59.24435
86.40000,2.87994,2509.47885,0.00000,11.51976,59.26970
86.50001,2.88329,2511.06173,0.00000,11.53315,59.30708
86.60001,2.88670,2511.40557,0.00000,11.54679,59.31520
86.70001,2.88999,2511.17721,0.00000,11.55994,59.30981
86.80000,2.89333,2511.99175,0.00000,11.57333,59.32904
86.90000,2.89662,2512.44586,0.00000,11.58649,59.33977
87.00001,2.89991,2513.41499,0.00000,11.59964,59.36266
87.10001,2.90326,2513.96839,0.00000,11.61303,59.37573
87.20001,2.90661,2515.37468,0.00000,11.62642,59.40894
87.30000,2.90995,2515.89753,0.00000,11.63982,59.42129
87.40000,2.91330,2515.64160,0.00000,11.65321,59.41525
87.50001,2.91665,2516.22535,0.00000,11.66660,59.42904
87.60001,2.91994,2517.22354,0.00000,11.67976,59.45261
87.70001,2.92329,2516.97302,0.00000,11.69315,59.44669
87.80000,2.92664,2517.96525,0.00000,11.70654,59.47013
87.90000,2.92998,2518.85299,0.00000,11.71994,59.49110
88.00001,2.93333,2519.36223,0.00000,11.73333,59.50312
88.10001,2.93668,2519.61630,0.00000,11.74672,59.50912
88.20001,2.94009,2520.88718,0.00000,11.76035,59.53914
88.30000,2.94332,2519.98138,0.00000,11.77327,59.51775
88.40000,2.94655,2520.70688,0.00000,11.78618,59.53488
88.50001,2.95001,2522.54456,0.00000,11.80005,59.57829
88.60001,2.95330,2521.80900,0.00000,11.81321,59.56091
88.70001,2.95665,2522.83067,0.00000,11.82660,59.58504
88.80000,2.96006,2523.55468,0.00000,11.84023,59.60214
88.90000,2.96329,2523.42802,0.00000,11.85315,59.59915
89.00001,2.96658,2523.62192,0.00000,11.86630,59.60373
89.10001,2.97034,481.74402,0.00000,11.88137,11.37799
89.11601,2.97094,1.81407,0.00000,11.88376,0.04285