File: Ensaio Mecânico/Dados/Specimen_RawData_1.csv
Time,Extension,Load,Strain 1,Tensile strain,Tensile stress
(sec),(mm),(N),,(%),(MPa)
0.00000,0.00000,-0.38219,0.00000,0.00000,-0.00782
0.10000,0.00060,0.84913,0.00000,0.00239,0.01736
0.20000,0.00383,2.00683,0.00000,0.01531,0.04104
0.30000,0.00981,4.27740,0.00000,0.03922,0.08747
0.40000,0.01525,8.44453,0.00000,0.06099,0.17269
0.50000,0.02009,11.44284,0.00000,0.08036,0.23400
0.60000,0.02469,13.67366,0.00000,0.09877,0.27963
0.70000,0.02912,17.61603,0.00000,0.11647,0.36025
0.80000,0.03342,19.82003,0.00000,0.13369,0.40532
0.90000,0.03743,24.48113,0.00000,0.14971,0.50064
1.00000,0.04155,28.03833,0.00000,0.16621,0.57338
1.10000,0.04574,33.18646,0.00000,0.18296,0.67866
1.20000,0.04998,37.92172,0.00000,0.19994,0.77550
1.30000,0.05417,44.00455,0.00000,0.21668,0.89989
1.40000,0.05829,48.97824,0.00000,0.23318,1.00160
1.50000,0.06242,54.66855,0.00000,0.24968,1.11797
1.60000,0.06655,60.72407,0.00000,0.26618,1.24180
1.70000,0.07073,67.80225,0.00000,0.28292,1.38655
1.80000,0.07498,74.31973,0.00000,0.29990,1.51983
1.90000,0.07922,81.23750,0.00000,0.31688,1.66130
2.00000,0.08335,88.16658,0.00000,0.33339,1.80300
2.10000,0.08735,95.61352,0.00000,0.34941,1.95529
2.20000,0.09154,102.79693,0.00000,0.36615,2.10219
2.30000,0.09578,109.84637,0.00000,0.38313,2.24635
2.40000,0.10003,118.44636,0.00000,0.40011,2.42222
2.50000,0.10427,125.52557,0.00000,0.41709,2.56698
2.60000,0.10834,133.02929,0.00000,0.43335,2.72044
2.70000,0.11240,140.31969,0.00000,0.44962,2.86952
2.80000,0.11665,147.25656,0.00000,0.46660,3.01138
2.90000,0.12083,155.07594,0.00000,0.48334,3.17129
3.00000,0.12508,163.29064,0.00000,0.50032,3.33928
3.10000,0.12926,171.49384,0.00000,0.51706,3.50703
3.20000,0.13327,179.18263,0.00000,0.53308,3.66427
3.30000,0.13740,187.06261,0.00000,0.54958,3.82541
3.40000,0.14158,194.75877,0.00000,0.56633,3.98280
3.50000,0.14583,202.56985,0.00000,0.58331,4.14253
3.60000,0.15007,210.47536,0.00000,0.60029,4.30420
3.70000,0.15414,219.49622,0.00000,0.61655,4.48868
3.80000,0.15832,226.46398,0.00000,0.63329,4.63117
3.90000,0.16239,235.59658,0.00000,0.64955,4.81793
4.00000,0.16663,242.46376,0.00000,0.66653,4.95836
4.10000,0.17082,251.90862,0.00000,0.68327,5.15151
4.20000,0.17506,259.49448,0.00000,0.70025,5.30664
4.30000,0.17919,267.78583,0.00000,0.71676,5.47619
4.40000,0.18320,275.66573,0.00000,0.73278,5.63734
4.50000,0.18744,283.40211,0.00000,0.74976,5.79554
4.60000,0.19163,290.61874,0.00000,0.76650,5.94312
4.70000,0.19581,299.32689,0.00000,0.78324,6.12120
4.80000,0.20012,307.53384,0.00000,0.80046,6.28904
4.90000,0.20412,315.75067,0.00000,0.81649,6.45707
5.00000,0.20825,324.49700,0.00000,0.83299,6.63593
5.10000,0.21249,332.90957,0.00000,0.84997,6.80797
5.20000,0.21668,340.27796,0.00000,0.86671,6.95865
5.30000,0.22092,348.81313,0.00000,0.88369,7.13319
5.40000,0.22505,357.75080,0.00000,0.90019,7.31597
5.50000,0.22911,365.02283,0.00000,0.91645,7.46468
5.60000,0.23324,374.19063,0.00000,0.93296,7.65216
5.70000,0.23742,382.84704,0.00000,0.94970,7.82918
5.80000,0.24167,392.46916,0.00000,0.96668,8.02595
5.90000,0.24591,400.41604,0.00000,0.98366,8.18847
6.00000,0.24998,409.32172,0.00000,0.99992,8.37059
6.10000,0.25411,418.38894,0.00000,1.01642,8.55601
6.20000,0.25823,427.37792,0.00000,1.03292,8.73983
6.30000,0.26248,437.11322,0.00000,1.04990,8.93892
6.40000,0.26666,446.35762,0.00000,1.06664,9.12797
6.50000,0.27091,456.05134,0.00000,1.08362,9.32620
6.60000,0.27491,465.07702,0.00000,1.09965,9.51078
6.70000,0.27904,474.62182,0.00000,1.11615,9.70597
6.80000,0.28328,484.63000,0.00000,1.13313,9.91063
6.90000,0.28747,494.20465,0.00000,1.14987,10.10643
7.00000,0.29171,503.36979,0.00000,1.16685,10.29386
7.10000,0.29584,512.83431,0.00000,1.18335,10.48741
7.20000,0.29996,521.71596,0.00000,1.19986,10.66904
7.30000,0.30409,532.26491,0.00000,1.21636,10.88476
7.40000,0.30827,541.80571,0.00000,1.23310,11.07987
7.50000,0.31246,551.38492,0.00000,1.24984,11.27577
7.60000,0.31670,561.13410,0.00000,1.26682,11.47513
7.70000,0.32089,570.40271,0.00000,1.28356,11.66468
7.80000,0.32496,580.34863,0.00000,1.29982,11.86807
7.90000,0.32908,589.98549,0.00000,1.31633,12.06514
8.00000,0.33327,599.40908,0.00000,1.33307,12.25785
8.10000,0.33745,609.77638,0.00000,1.34981,12.46986
8.20000,0.34176,619.87927,0.00000,1.36703,12.67647
8.30000,0.34594,629.52833,0.00000,1.38377,12.87379
8.40000,0.34995,638.70130,0.00000,1.39979,13.06138
8.50000,0.35407,649.53542,0.00000,1.41629,13.28293
8.60000,0.35826,659.61597,0.00000,1.43303,13.48908
8.70000,0.36250,670.48008,0.00000,1.45001,13.71125
8.80000,0.36681,681.44635,0.00000,1.46723,13.93551
8.90000,0.37081,690.41373,0.00000,1.48326,14.11889
9.00000,0.37488,701.20851,0.00000,1.49952,14.33964
9.10000,0.37907,711.27745,0.00000,1.51626,14.54555
9.20000,0.38331,722.13220,0.00000,1.53324,14.76753
9.30000,0.38762,732.41028,0.00000,1.55046,14.97772
9.40000,0.39180,742.60863,0.00000,1.56720,15.18627
9.50000,0.39581,753.11307,0.00000,1.58323,15.40108
9.60000,0.39987,763.25689,0.00000,1.59949,15.60853
9.70000,0.40406,773.79402,0.00000,1.61623,15.82401
9.80000,0.40836,784.74497,0.00000,1.63345,16.04795
9.90000,0.41261,795.98390,0.00000,1.65043,16.27779
10.00000,0.41667,806.82179,0.00000,1.66669,16.49942
10.10000,0.42074,817.26182,0.00000,1.68295,16.71292
10.20000,0.42480,828.27564,0.00000,1.69922,16.93815
10.30000,0.42905,839.23433,0.00000,1.71620,17.16226
10.40000,0.43335,851.86902,0.00000,1.73342,17.42064
10.50000,0.43754,863.49435,0.00000,1.75016,17.65837
10.60000,0.44166,875.36527,0.00000,1.76666,17.90113
10.70000,0.44573,887.34683,0.00000,1.78292,18.14615
10.80000,0.44998,899.05271,0.00000,1.79990,18.38554
10.90000,0.45416,910.25550,0.00000,1.81664,18.61463
11.00000,0.45835,923.38109,0.00000,1.83339,18.88305
11.10000,0.46259,935.80764,0.00000,1.85037,19.13717
11.20000,0.46666,946.99562,0.00000,1.86663,19.36596
11.30000,0.47072,958.92372,0.00000,1.88289,19.60989
11.40000,0.47491,971.04106,0.00000,1.89963,19.85769
11.50000,0.47909,983.54332,0.00000,1.91637,20.11336
11.60000,0.48340,996.76112,0.00000,1.93359,20.38366
11.70000,0.48758,1009.53942,0.00000,1.95033,20.64498
11.80000,0.49171,1021.46864,0.00000,1.96683,20.88893
11.90000,0.49571,1035.33436,0.00000,1.98286,21.17248
12.00000,0.49990,1047.75634,0.00000,1.99960,21.42651
12.10000,0.50414,1062.17070,0.00000,2.01658,21.72128
12.20000,0.50839,1075.33308,0.00000,2.03356,21.99045
12.30000,0.51258,1087.85443,0.00000,2.05030,22.24651
12.40000,0.51658,1100.44917,0.00000,2.06632,22.50407
12.50000,0.52065,1113.79968,0.00000,2.08259,22.77709
12.60000,0.52483,1126.46399,0.00000,2.09933,23.03607
12.70000,0.52914,1140.00877,0.00000,2.11655,23.31306
12.80000,0.53350,1152.77097,0.00000,2.13401,23.57405
12.90000,0.53757,1165.22545,0.00000,2.15027,23.82874
13.00000,0.54157,1178.41335,0.00000,2.16629,24.09843
13.10000,0.54570,1192.09550,0.00000,2.18279,24.37823
13.20000,0.54994,1204.40638,0.00000,2.19977,24.62999
13.30000,0.55431,1218.72118,0.00000,2.21723,24.92272
13.40000,0.55849,1232.15578,0.00000,2.23397,25.19746
13.50000,0.56250,1245.25875,0.00000,2.25000,25.46541
13.60000,0.56657,1258.58104,0.00000,2.26626,25.73785
13.70000,0.57069,1271.81308,0.00000,2.28276,26.00845
13.80000,0.57500,1285.80714,0.00000,2.29998,26.29462
13.90000,0.57924,1299.98373,0.00000,2.31696,26.58453
14.00000,0.58343,1313.06415,0.00000,2.33370,26.85203
14.10000,0.58743,1325.87906,0.00000,2.34973,27.11409
14.20000,0.59150,1338.65606,0.00000,2.36599,27.37538
14.30000,0.59574,1352.03693,0.00000,2.38297,27.64902
14.40000,0.59999,1365.34115,0.00000,2.39995,27.92109
14.50000,0.60423,1378.20616,0.00000,2.41693,28.18418
14.60000,0.60836,1390.69716,0.00000,2.43343,28.43962
14.70000,0.61242,1401.90320,0.00000,2.44970,28.66878
14.80000,0.61655,1415.70494,0.00000,2.46620,28.95102
14.90000,0.62079,1428.61241,0.00000,2.48318,29.21498
15.00000,0.62498,1442.27883,0.00000,2.49992,29.49446
15.10000,0.62928,1455.78114,0.00000,2.51714,29.77058
15.20000,0.63329,1467.87465,0.00000,2.53316,30.01789
15.30000,0.63742,1480.85421,0.00000,2.54966,30.28332
15.40000,0.64154,1493.93147,0.00000,2.56617,30.55075
15.50000,0.64573,1507.19341,0.00000,2.58291,30.82195
15.60000,0.65003,1522.15119,0.00000,2.60013,31.12784
15.70000,0.65428,1534.92009,0.00000,2.61711,31.38896
15.80000,0.65834,1547.41379,0.00000,2.63337,31.64445
15.90000,0.66241,1560.31707,0.00000,2.64963,31.90833
16.00000,0.66653,1573.44211,0.00000,2.66613,32.17673
16.10000,0.67084,1588.64483,0.00000,2.68335,32.48763
16.20000,0.67502,1602.65006,0.00000,2.70009,32.77403
16.30000,0.67921,1616.65455,0.00000,2.71683,33.06042
16.40000,0.68327,1629.69269,0.00000,2.73310,33.32705
16.50000,0.68734,1644.13750,0.00000,2.74936,33.62244
16.60000,0.69159,1658.98036,0.00000,2.76634,33.92598
16.70000,0.69577,1672.84217,0.00000,2.78308,34.20945
16.80000,0.70008,1688.14287,0.00000,2.80030,34.52235
16.90000,0.70420,1701.79289,0.00000,2.81680,34.80149
17.00000,0.70821,1716.78215,0.00000,2.83283,35.10802
17.10000,0.71233,1732.22777,0.00000,2.84933,35.42388
17.20000,0.71658,1746.83779,0.00000,2.86631,35.72265
17.30000,0.72082,1761.54412,0.00000,2.88329,36.02340
17.40000,0.72507,1775.60840,0.00000,2.90027,36.31101
17.50000,0.72919,1789.31467,0.00000,2.91677,36.59130
17.60000,0.73326,1804.12475,0.00000,2.93303,36.89417
17.70000,0.73744,1818.61613,0.00000,2.94977,37.19051
17.80000,0.74163,1831.74610,0.00000,2.96652,37.45902
17.90000,0.74587,1846.83166,0.00000,2.98350,37.76752
18.00000,0.75006,1861.14758,0.00000,3.00024,38.06028
18.10000,0.75412,1874.52156,0.00000,3.01650,38.33377
18.20000,0.75819,1888.06113,0.00000,3.03276,38.61066
18.30000,0.76250,1903.34711,0.00000,3.04998,38.92325
18.40000,0.76668,1916.95280,0.00000,3.06672,39.20149
18.50000,0.77081,1931.92940,0.00000,3.08322,39.50776
18.60000,0.77499,1946.62269,0.00000,3.09997,39.80824
18.70000,0.77906,1959.68989,0.00000,3.11623,40.07546
18.80000,0.78324,1974.78570,0.00000,3.13297,40.38417
18.90000,0.78743,1989.38400,0.00000,3.14971,40.68270
19.00000,0.79161,2004.81769,0.00000,3.16645,40.99832
19.10000,0.79592,2020.03848,0.00000,3.18367,41.30958
19.20000,0.79998,2032.77692,0.00000,3.19993,41.57008
19.30000,0.80411,2047.00548,0.00000,3.21644,41.86105
19.40000,0.80823,2060.97215,0.00000,3.23294,42.14667
19.50000,0.81242,2075.44547,0.00000,3.24968,42.44265
19.60000,0.81666,2090.61317,0.00000,3.26666,42.75283
19.70000,0.82085,2104.69849,0.00000,3.28340,43.04087
19.80000,0.82504,2118.75029,0.00000,3.30014,43.32823
19.90000,0.82916,2133.37336,0.00000,3.31664,43.62727
20.00000,0.83329,2147.45104,0.00000,3.33314,43.91515
20.10000,0.83747,2161.89884,0.00000,3.34989,44.21061
20.20000,0.84166,2176.74877,0.00000,3.36663,44.51429
20.30000,0.84590,2190.92499,0.00000,3.38361,44.80419
20.40000,0.84997,2204.42750,0.00000,3.39987,45.08032
20.50000,0.85403,2218.46662,0.00000,3.41613,45.36742
20.60000,0.85834,2233.64178,0.00000,3.43335,45.67775
20.70000,0.86246,2247.89251,0.00000,3.44985,45.96917
20.80000,0.86665,2261.70942,0.00000,3.46659,46.25173
20.90000,0.87083,2275.21937,0.00000,3.48334,46.52800
21.00000,0.87490,2289.16556,0.00000,3.49960,46.81320
21.10000,0.87914,2305.18561,0.00000,3.51658,47.14081
21.20000,0.88327,2318.32713,0.00000,3.53308,47.40955
21.30000,0.88746,2332.44449,0.00000,3.54982,47.69825
21.40000,0.89170,2347.63958,0.00000,3.56680,48.00899
21.50000,0.89583,2361.23204,0.00000,3.58330,48.28695
21.60000,0.89995,2375.99667,0.00000,3.59981,48.58889
21.70000,0.90408,2389.24082,0.00000,3.61631,48.85973
21.80000,0.90826,2403.62454,0.00000,3.63305,49.15388
21.90000,0.91245,2418.43089,0.00000,3.64979,49.45667
22.00000,0.91663,2432.74625,0.00000,3.66653,49.74941
22.10000,0.92082,2447.61575,0.00000,3.68327,50.05349
22.20000,0.92494,2461.87337,0.00000,3.69977,50.34506
22.30000,0.92913,2476.01029,0.00000,3.71652,50.63416
22.40000,0.93325,2489.24997,0.00000,3.73302,50.90491
22.50000,0.93750,2505.75617,0.00000,3.75000,51.24246
22.60000,0.94174,2520.98497,0.00000,3.76698,51.55389
22.70000,0.94581,2535.01628,0.00000,3.78324,51.84082
22.80000,0.94988,2549.57732,0.00000,3.79950,52.13860
22.90000,0.95400,2564.84412,0.00000,3.81600,52.45080
23.00000,0.95825,2579.70560,0.00000,3.83299,52.75471
23.10000,0.96249,2594.84034,0.00000,3.84996,53.06422
23.20000,0.96668,2609.22294,0.00000,3.86671,53.35834
23.30000,0.97074,2623.72512,0.00000,3.88297,53.65491
23.40000,0.97487,2638.52309,0.00000,3.89947,53.95753
23.50000,0.97905,2652.72651,0.00000,3.91621,54.24799
23.60000,0.98336,2669.44673,0.00000,3.93343,54.58991
23.70000,0.98754,2683.72595,0.00000,3.95017,54.88192
23.80000,0.99173,2697.76005,0.00000,3.96691,55.16892
23.90000,0.99573,2712.38033,0.00000,3.98294,55.46790
24.00000,0.99992,2727.11832,0.00000,3.99968,55.76929
24.10000,1.00416,2742.32812,0.00000,4.01666,56.08033
24.20000,1.00835,2757.86705,0.00000,4.03340,56.39810
24.30000,1.01259,2773.25176,0.00000,4.05038,56.71272
24.40000,1.01666,2786.34913,0.00000,4.06664,56.98056
24.50000,1.02079,2801.12214,0.00000,4.08314,57.28266
24.60000,1.02497,2816.53404,0.00000,4.09989,57.59783
24.70000,1.02910,2830.48488,0.00000,4.11639,57.88313
24.80000,1.03334,2845.45589,0.00000,4.13337,58.18928
24.90000,1.03753,2860.72604,0.00000,4.15011,58.50156
25.00000,1.04159,2874.65081,0.00000,4.16637,58.78632
25.10000,1.04578,2888.36919,0.00000,4.18311,59.06686
25.20000,1.04990,2902.84604,0.00000,4.19961,59.36290
25.30000,1.05415,2917.85821,0.00000,4.21659,59.66990
25.40000,1.05833,2932.40063,0.00000,4.23334,59.96729
25.50000,1.06252,2945.87687,0.00000,4.25008,60.24288
25.60000,1.06664,2961.18185,0.00000,4.26658,60.55587
25.70000,1.07077,2975.61698,0.00000,4.28308,60.85106
25.80000,1.07490,2989.58775,0.00000,4.29958,61.13676
25.90000,1.07920,3005.77898,0.00000,4.31680,61.46787
26.00000,1.08339,3019.67636,0.00000,4.33354,61.75207
26.10000,1.08757,3033.63651,0.00000,4.35028,62.03756
26.20000,1.09164,3047.54097,0.00000,4.36655,62.32190
26.30000,1.09570,3061.56650,0.00000,4.38281,62.60872
26.40000,1.09995,3075.96102,0.00000,4.39979,62.90309
26.50000,1.10419,3090.04653,0.00000,4.41677,63.19114
26.60000,1.10850,3104.36413,0.00000,4.43399,63.48393
26.70000,1.11250,3117.50229,0.00000,4.45001,63.75260
26.80000,1.11651,3130.67287,0.00000,4.46604,64.02194
26.90000,1.12069,3145.84263,0.00000,4.48278,64.33216
27.00000,1.12494,3159.07076,0.00000,4.49976,64.60268
27.10000,1.12924,3174.73672,0.00000,4.51698,64.92304
27.20000,1.13343,3188.50689,0.00000,4.53372,65.20464
27.30000,1.13744,3201.40235,0.00000,4.54974,65.46835
27.40000,1.14150,3215.43813,0.00000,4.56600,65.75538
27.50000,1.14575,3229.75479,0.00000,4.58298,66.04816
27.60000,1.15005,3244.34638,0.00000,4.60020,66.34655
27.70000,1.15424,3258.57438,0.00000,4.61694,66.63751
27.80000,1.15836,3271.97164,0.00000,4.63345,66.91148
27.90000,1.16243,3284.87828,0.00000,4.64971,67.17542
28.00000,1.16655,3298.32211,0.00000,4.66621,67.45035
28.10000,1.17080,3311.57483,0.00000,4.68319,67.72137
28.20000,1.17498,3326.21187,0.00000,4.69993,68.02069
28.30000,1.17929,3340.36201,0.00000,4.71715,68.31006
28.40000,1.18329,3352.37011,0.00000,4.73318,68.55563
28.50000,1.18742,3365.71112,0.00000,4.74968,68.82845
28.60000,1.19160,3378.86028,0.00000,4.76642,69.09734
28.70000,1.19579,3392.67440,0.00000,4.78316,69.37984
28.80000,1.20003,3407.27456,0.00000,4.80014,69.67841
28.90000,1.20428,3421.03988,0.00000,4.81712,69.95992
29.00000,1.20829,3432.53054,0.00000,4.83314,70.19490
29.10000,1.21247,3445.87564,0.00000,4.84988,70.46780
29.20000,1.21660,3459.68790,0.00000,4.86639,70.75027
29.30000,1.22078,3472.94509,0.00000,4.88313,71.02137
29.40000,1.22503,3487.21258,0.00000,4.90011,71.31314
29.50000,1.22921,3499.59061,0.00000,4.91685,71.56627
29.60000,1.23334,3511.76336,0.00000,4.93335,71.81520
29.70000,1.23740,3524.07731,0.00000,4.94961,72.06702
29.80000,1.24159,3537.69958,0.00000,4.96635,72.34560
29.90000,1.24583,3551.24362,0.00000,4.98333,72.62257
30.00000,1.25002,3564.11226,0.00000,5.00008,72.88573
30.10000,1.25426,3577.22864,0.00000,5.01706,73.15396
30.20000,1.25827,3588.33782,0.00000,5.03308,73.38114
30.30000,1.26240,3601.73918,0.00000,5.04958,73.65520
30.40000,1.26658,3614.94869,0.00000,5.06632,73.92533
30.50000,1.27083,3627.76406,0.00000,5.08330,74.18740
30.60000,1.27513,3641.25967,0.00000,5.10052,74.46339
30.70000,1.27920,3653.04388,0.00000,5.11678,74.70438
30.80000,1.28326,3665.13021,0.00000,5.13305,74.95154
30.90000,1.28745,3678.97190,0.00000,5.14979,75.23460
31.00000,1.29163,3690.74419,0.00000,5.16653,75.47534
31.10000,1.29594,3704.98076,0.00000,5.18375,75.76648
31.20000,1.30006,3716.82718,0.00000,5.20025,76.00874
31.30000,1.30413,3728.03509,0.00000,5.21651,76.23794
31.40000,1.30825,3741.07659,0.00000,5.23302,76.50463
31.50000,1.31238,3753.49149,0.00000,5.24952,76.75851
31.60000,1.31662,3766.90216,0.00000,5.26650,77.03276
31.70000,1.32087,3779.61248,0.00000,5.28348,77.29269
31.80000,1.32499,3791.81542,0.00000,5.29998,77.54224
31.90000,1.32912,3803.93937,0.00000,5.31648,77.79017
32.00000,1.33325,3816.30808,0.00000,5.33298,78.04311
32.10000,1.33749,3827.94440,0.00000,5.34996,78.28107
32.20000,1.34168,3840.46957,0.00000,5.36670,78.53721
32.30000,1.34580,3853.43246,0.00000,5.38321,78.80230
32.40000,1.34999,3865.77025,0.00000,5.39995,79.05460
32.50000,1.35411,3877.43190,0.00000,5.41645,79.29308
32.60000,1.35836,3890.23349,0.00000,5.43343,79.55488
32.70000,1.36248,3901.74277,0.00000,5.44993,79.79024
32.80000,1.36661,3913.83320,0.00000,5.46643,80.03749
32.90000,1.37079,3925.88079,0.00000,5.48317,80.28386
33.00000,1.37498,3937.16656,0.00000,5.49992,80.51466
33.10000,1.37910,3948.84981,0.00000,5.51642,80.75358
33.20000,1.38329,3961.55305,0.00000,5.53316,81.01335
33.30000,1.38747,3973.38346,0.00000,5.54990,81.25529
33.40000,1.39160,3985.82704,0.00000,5.56640,81.50976
33.50000,1.39579,3998.10448,0.00000,5.58314,81.76083
33.60000,1.39997,4010.39645,0.00000,5.59988,82.01220
33.70000,1.40410,4021.94411,0.00000,5.61639,82.24834
33.80000,1.40822,4034.32064,0.00000,5.63289,82.50144
33.90000,1.41241,4046.16296,0.00000,5.64963,82.74362
34.00000,1.41659,4058.74401,0.00000,5.66637,83.00090
34.10000,1.42084,4070.98122,0.00000,5.68335,83.25115
34.20000,1.42490,4081.96859,0.00000,5.69961,83.47584
34.30000,1.42909,4093.17985,0.00000,5.71635,83.70511
34.40000,1.43327,4104.86422,0.00000,5.73309,83.94405
34.50000,1.43746,4116.39996,0.00000,5.74984,84.17995
34.60000,1.44170,4128.87186,0.00000,5.76682,84.43501
34.70000,1.44583,4139.38276,0.00000,5.78332,84.64996
34.80000,1.44995,4151.49294,0.00000,5.79982,84.89761
34.90000,1.45414,4162.86252,0.00000,5.81656,85.13011
35.00000,1.45833,4174.10880,0.00000,5.83330,85.36010
35.10000,1.46257,4186.33334,0.00000,5.85028,85.61009
35.20000,1.46670,4197.43843,0.00000,5.86678,85.83719
35.30000,1.47082,4208.03092,0.00000,5.88329,86.05380
35.40000,1.47495,4220.81128,0.00000,5.89979,86.31516
35.50000,1.47913,4231.54794,0.00000,5.91653,86.53472
35.60000,1.48332,4242.88698,0.00000,5.93327,86.76660
35.70000,1.48750,4255.14691,0.00000,5.95001,87.01732
35.80000,1.49169,4266.91808,0.00000,5.96675,87.25804
35.90000,1.49581,4277.67262,0.00000,5.98325,87.47797
36.00000,1.49994,4289.22921,0.00000,5.99976,87.71430
36.10000,1.50418,4299.40745,0.00000,6.01674,87.92244
36.20000,1.50837,4310.34490,0.00000,6.03348,88.14611
36.30000,1.51243,4322.18723,0.00000,6.04974,88.38829
36.40000,1.51662,4332.60798,0.00000,6.06648,88.60139
36.50000,1.52075,4342.68303,0.00000,6.08298,88.80743
36.60000,1.52493,4353.35748,0.00000,6.09972,89.02572
36.70000,1.52918,4364.72148,0.00000,6.11670,89.25811
36.80000,1.53330,4375.37469,0.00000,6.13321,89.47597
36.90000,1.53749,4387.39732,0.00000,6.14995,89.72182
37.00000,1.54167,4397.20117,0.00000,6.16669,89.92232
37.10000,1.54586,4407.27584,0.00000,6.18343,90.12834
37.20000,1.55004,4418.28966,0.00000,6.20017,90.35357
37.30000,1.55411,4428.72457,0.00000,6.21643,90.56696
37.40000,1.55835,4440.84816,0.00000,6.23341,90.81489
37.50000,1.56248,4451.25699,0.00000,6.24992,91.02775
37.60000,1.56660,4461.16328,0.00000,6.26642,91.23033
37.70000,1.57073,4471.54380,0.00000,6.28292,91.44261
37.80000,1.57491,4482.77444,0.00000,6.29966,91.67228
37.90000,1.57910,4493.74057,0.00000,6.31640,91.89654
38.00000,1.58329,4504.51113,0.00000,6.33314,92.11679
38.10000,1.58753,4515.48360,0.00000,6.35012,92.34118
38.20000,1.59160,4524.98347,0.00000,6.36638,92.53545
38.30000,1.59578,4535.88851,0.00000,6.38313,92.75845
38.40000,1.59997,4546.33310,0.00000,6.39987,92.97205
38.50000,1.60409,4556.46776,0.00000,6.41637,93.17930
38.60000,1.60834,4567.40409,0.00000,6.43335,93.40295
38.70000,1.61252,4576.86372,0.00000,6.45009,93.59640
38.80000,1.61659,4586.83409,0.00000,6.46635,93.80029
38.90000,1.62071,4596.77540,0.00000,6.48286,94.00359
39.00000,1.62490,4607.25911,0.00000,6.49960,94.21798
39.10000,1.62914,4617.95069,0.00000,6.51658,94.43662
39.20000,1.63333,4628.09950,0.00000,6.53332,94.64417
39.30000,1.63745,4637.74949,0.00000,6.54982,94.84150
39.40000,1.64164,4647.89197,0.00000,6.56656,95.04891
39.50000,1.64577,4658.06760,0.00000,6.58306,95.25700
39.60000,1.65001,4667.88448,0.00000,6.60004,95.45776
39.70000,1.65420,4678.15921,0.00000,6.61678,95.66788
39.80000,1.65838,4687.92245,0.00000,6.63352,95.86754
39.90000,1.66251,4697.88872,0.00000,6.65003,96.07134
40.00000,1.66651,4707.01605,0.00000,6.66605,96.25800
40.10000,1.67076,4716.88733,0.00000,6.68303,96.45986
40.20000,1.67494,4726.72395,0.00000,6.69977,96.66102
40.30000,1.67919,4737.44795,0.00000,6.71675,96.88033
40.40000,1.68337,4747.98568,0.00000,6.73349,97.09583
40.50000,1.68744,4756.27035,0.00000,6.74976,97.26524
40.60000,1.69162,4765.64392,0.00000,6.76650,97.45693
40.70000,1.69581,4775.28796,0.00000,6.78324,97.65415
40.80000,1.69999,4785.21287,0.00000,6.79998,97.85712
40.90000,1.70424,4794.86175,0.00000,6.81696,98.05444
41.00000,1.70837,4804.60338,0.00000,6.83346,98.25365
41.10000,1.71243,4813.13057,0.00000,6.84972,98.42802
41.20000,1.71656,4822.02284,0.00000,6.86622,98.60987
41.30000,1.72074,4831.13714,0.00000,6.88297,98.79626
41.40000,1.72505,4841.62681,0.00000,6.90019,99.01077
41.50000,1.72923,4850.93035,0.00000,6.91693,99.20103
41.60000,1.73336,4859.41544,0.00000,6.93343,99.37455
41.70000,1.73748,4868.42766,0.00000,6.94993,99.55885
41.80000,1.74161,4876.79243,0.00000,6.96643,99.72990
41.90000,1.74585,4888.02753,0.00000,6.98341,99.95966
42.00000,1.75004,4896.07006,0.00000,7.00015,100.12413
42.10000,1.75422,4905.37025,0.00000,7.01689,100.31432
42.20000,1.75829,4912.89459,0.00000,7.03316,100.46819
42.30000,1.76236,4921.60805,0.00000,7.04942,100.64638
42.40000,1.76666,4931.12914,0.00000,7.06664,100.84109
42.50000,1.77079,4939.82174,0.00000,7.08314,101.01885
42.60000,1.77497,4948.21481,0.00000,7.09988,101.19049
42.70000,1.77916,4956.69805,0.00000,7.11662,101.36397
42.80000,1.78322,4963.50974,0.00000,7.13289,101.50327
42.90000,1.78741,4973.41566,0.00000,7.14963,101.70584
43.00000,1.79159,4981.51667,0.00000,7.16637,101.87151
43.10000,1.79584,4990.14743,0.00000,7.18335,102.04800
43.20000,1.80008,4999.35076,0.00000,7.20033,102.23621
43.30000,1.80421,5006.35244,0.00000,7.21683,102.37939
43.40000,1.80827,5014.49108,0.00000,7.23309,102.54583
43.50000,1.81246,5022.45426,0.00000,7.24983,102.70868
43.60000,1.81664,5031.23701,0.00000,7.26658,102.88828
43.70000,1.82089,5039.39800,0.00000,7.28356,103.05518
43.80000,1.82507,5048.23364,0.00000,7.30030,103.23586
43.90000,1.82914,5055.51957,0.00000,7.31656,103.38486
44.00000,1.83327,5063.01373,0.00000,7.33306,103.53812
44.10000,1.83745,5071.27196,0.00000,7.34980,103.70699
44.20000,1.84164,5079.24706,0.00000,7.36654,103.87009
44.30000,1.84582,5088.35614,0.00000,7.38328,104.05637
44.40000,1.85001,5096.02949,0.00000,7.40003,104.21328
44.50000,1.85413,5103.94089,0.00000,7.41653,104.37507
44.60000,1.85826,5111.58817,0.00000,7.43303,104.53146
44.70000,1.86244,5119.70147,0.00000,7.44977,104.69737
44.80000,1.86657,5127.28915,0.00000,7.46627,104.85254
44.90000,1.87087,5136.68284,0.00000,7.48349,105.04464
45.00000,1.87500,5143.56792,0.00000,7.49999,105.18544
45.10000,1.87912,5151.63243,0.00000,7.51650,105.35036
45.20000,1.88331,5159.31845,0.00000,7.53324,105.50754
45.30000,1.88749,5166.96498,0.00000,7.54998,105.66390
45.40000,1.89168,5175.58418,0.00000,7.56672,105.84016
45.50000,1.89586,5183.47956,0.00000,7.58346,106.00163
45.60000,1.90005,5191.59995,0.00000,7.60020,106.16769
45.70000,1.90412,5198.66012,0.00000,7.61646,106.31207
45.80000,1.90830,5206.88780,0.00000,7.63320,106.48032
45.90000,1.91249,5215.32372,0.00000,7.64995,106.65284
46.00000,1.91667,5223.13230,0.00000,7.66669,106.81252
46.10000,1.92086,5231.92324,0.00000,7.68343,106.99229
46.20000,1.92498,5239.31943,0.00000,7.69993,107.14355
46.30000,1.92911,5247.21369,0.00000,7.71643,107.30499
46.40000,1.93335,5255.75243,0.00000,7.73341,107.47960
46.50000,1.93748,5263.61093,0.00000,7.74991,107.64030
46.60000,1.94166,5271.55139,0.00000,7.76666,107.80269
46.70000,1.94579,5280.04356,0.00000,7.78316,107.97635
46.80000,1.94985,5287.73218,0.00000,7.79942,108.13358
46.90000,1.95416,5295.88833,0.00000,7.81664,108.30038
47.00000,1.95829,5304.16034,0.00000,7.83314,108.46954
47.10000,1.96247,5312.18089,0.00000,7.84988,108.63355
47.20000,1.96666,5319.49960,0.00000,7.86662,108.78323
47.30000,1.97084,5326.56722,0.00000,7.88336,108.92776
47.40000,1.97497,5334.38846,0.00000,7.89987,109.08770
47.50000,1.97915,5342.19220,0.00000,7.91661,109.24728
47.60000,1.98328,5349.44125,0.00000,7.93311,109.39552
47.70000,1.98746,5358.38269,0.00000,7.94985,109.57838
47.80000,1.99165,5366.29260,0.00000,7.96659,109.74014
47.90000,1.99589,5373.22648,0.00000,7.98357,109.88194
48.00000,1.99996,5380.16707,0.00000,7.99983,110.02386
48.10000,2.00414,5387.94063,0.00000,8.01658,110.18284
48.20000,2.00827,5394.70874,0.00000,8.03308,110.32124
48.30000,2.01245,5402.89022,0.00000,8.04982,110.48856
48.40000,2.01670,5410.41791,0.00000,8.06680,110.64249
48.50000,2.02082,5416.99678,0.00000,8.08330,110.77703
48.60000,2.02495,5425.21738,0.00000,8.09980,110.94514
48.70000,2.02908,5432.20155,0.00000,8.11630,111.08797
48.80000,2.03326,5438.71410,0.00000,8.13304,111.22115
48.90000,2.03745,5446.80022,0.00000,8.14979,111.38651
49.00000,2.04163,5454.03473,0.00000,8.16653,111.53445
49.10000,2.04576,5461.23907,0.00000,8.18303,111.68178
49.20000,2.04988,5468.32532,0.00000,8.19953,111.82669
49.30000,2.05413,5474.99955,0.00000,8.21651,111.96318
49.40000,2.05831,5482.80925,0.00000,8.23325,112.12289
49.50000,2.06250,5490.95534,0.00000,8.24999,112.28947
49.60000,2.06662,5496.47622,0.00000,8.26650,112.40237
49.70000,2.07081,5504.89724,0.00000,8.28324,112.57458
49.80000,2.07499,5511.51223,0.00000,8.29998,112.70986
49.90000,2.07918,5518.65920,0.00000,8.31672,112.85602
50.00000,2.08336,5525.53684,0.00000,8.33346,112.99667
50.10000,2.08755,5533.08651,0.00000,8.35020,113.15105
50.20000,2.09168,5539.87473,0.00000,8.36670,113.28987
50.30000,2.09580,5545.69736,0.00000,8.38320,113.40894
50.40000,2.10005,5553.06748,0.00000,8.40018,113.55966
50.50000,2.10411,5558.95045,0.00000,8.41645,113.67997
50.60000,2.10836,5566.80113,0.00000,8.43343,113.84052
50.70000,2.11248,5573.14605,0.00000,8.44993,113.97027
50.80000,2.11661,5579.16313,0.00000,8.46643,114.09332
50.90000,2.12127,4077.00129,0.00000,8.48509,83.37426
50.93800,2.12342,7.47733,0.00000,8.49369,0.15291