File: Manufatura Aditiva/Classificação Orientação/Ensaios/Ensaios SLS/Tracao_OLABI_07_06_2018_SLS_YX5.is_metal_RawData/Specimen_RawData_2.csv
Time,Extension,Load,Strain 1,Tensile strain,Tensile stress
(sec),(mm),(N),(mm/mm),(%),(MPa)
0.00000,0.00006,21.68446,0.00085,0.08502,1.02535
0.20000,0.01381,28.71486,0.00104,0.10395,1.35778
0.40000,0.03270,38.63574,0.00136,0.13608,1.82689
0.60000,0.04986,47.43241,0.00166,0.16564,2.24284
0.80000,0.06673,55.93292,0.00194,0.19406,2.64478
1.00000,0.08335,63.59147,0.00222,0.22232,3.00692
1.20000,0.10003,72.23811,0.00251,0.25051,3.41577
1.40000,0.11683,80.48069,0.00280,0.27978,3.80552
1.60000,0.13333,88.19248,0.00308,0.30756,4.17017
1.80000,0.14995,96.36543,0.00336,0.33559,4.55663
2.00000,0.16663,103.98543,0.00364,0.36405,4.91694
2.20000,0.18331,111.82734,0.00393,0.39315,5.28774
2.40000,0.19994,119.12631,0.00421,0.42074,5.63288
2.60000,0.21668,127.20287,0.00449,0.44910,6.01477
2.80000,0.23336,134.55222,0.00478,0.47783,6.36229
3.00000,0.24998,142.01906,0.00506,0.50589,6.71536
3.20000,0.26672,149.29716,0.00534,0.53417,7.05950
3.40000,0.28340,157.03868,0.00562,0.56240,7.42556
3.60000,0.30002,164.18290,0.00591,0.59147,7.76337
3.80000,0.31665,171.29177,0.00619,0.61936,8.09951
4.00000,0.33327,178.21785,0.00648,0.64759,8.42701
4.20000,0.34995,185.52082,0.00676,0.67593,8.77233
4.40000,0.36663,193.24012,0.00705,0.70474,9.13734
4.60000,0.38331,200.15028,0.00733,0.73335,9.46409
4.80000,0.39999,207.22630,0.00761,0.76137,9.79868
5.00000,0.41661,214.24817,0.00790,0.78971,10.13070
5.20000,0.43335,221.68697,0.00818,0.81804,10.48245
5.40000,0.45010,229.19769,0.00846,0.84622,10.83759
5.60000,0.46666,235.87677,0.00875,0.87467,11.15341
5.80000,0.48334,242.63589,0.00903,0.90295,11.47301
6.00000,0.50002,249.38914,0.00932,0.93178,11.79234
6.20000,0.51664,256.08588,0.00959,0.95931,12.10900
6.40000,0.53332,263.96026,0.00988,0.98795,12.48133
6.60000,0.55000,270.22571,0.01018,1.01767,12.77760
6.80000,0.56674,276.81594,0.01046,1.04591,13.08921
7.00000,0.58331,283.47727,0.01074,1.07380,13.40419
7.20000,0.59993,289.49049,0.01102,1.10167,13.68853
7.40000,0.61673,296.60210,0.01131,1.13091,14.02480
7.60000,0.63329,302.81190,0.01159,1.15950,14.31843
7.80000,0.64997,308.80505,0.01188,1.18781,14.60182
8.00000,0.66671,315.68212,0.01217,1.21666,14.92700
8.20000,0.68333,321.88669,0.01244,1.24431,15.22038
8.40000,0.70002,327.55523,0.01273,1.27319,15.48842
8.60000,0.71664,333.70897,0.01303,1.30254,15.77940
8.80000,0.73344,340.33793,0.01331,1.33122,16.09285
9.00000,0.75000,346.14454,0.01359,1.35932,16.36741
9.20000,0.76662,351.78484,0.01388,1.38809,16.63411
9.40000,0.78342,357.83565,0.01418,1.41765,16.92022
9.60000,0.79992,364.21812,0.01447,1.44692,17.22202
9.80000,0.81660,369.10081,0.01476,1.47580,17.45290
10.00000,0.83341,374.98767,0.01505,1.50542,17.73125
10.20000,0.84991,380.69484,0.01535,1.53495,18.00112
10.40000,0.86665,383.73442,0.01556,1.55640,18.14484
10.60000,0.88333,390.18928,0.01586,1.58570,18.45006
10.80000,0.90007,395.52245,0.01615,1.61512,18.70224
11.00000,0.91663,400.47546,0.01645,1.64518,18.93644
11.20000,0.93331,406.02922,0.01675,1.67495,19.19905
11.40000,0.95000,412.08072,0.01705,1.70460,19.48520
11.60000,0.96656,416.86157,0.01734,1.73434,19.71126
11.80000,0.98330,421.79618,0.01765,1.76459,19.94459
12.00000,1.00010,427.30714,0.01795,1.79465,20.20518
12.20000,1.01666,431.95467,0.01825,1.82484,20.42493
12.40000,1.03328,437.37530,0.01856,1.85559,20.68125
12.60000,1.04996,441.76094,0.01885,1.88541,20.88862
12.80000,1.06664,446.91516,0.01916,1.91600,21.13234
13.00000,1.08333,451.96572,0.01947,1.94685,21.37115
13.20000,1.10001,456.50871,0.01978,1.97754,21.58597
13.40000,1.11675,461.11792,0.02009,2.00877,21.80392
13.60000,1.13325,466.26856,0.02039,2.03934,22.04746
13.80000,1.14993,470.12484,0.02070,2.07029,22.22981
14.00000,1.16673,474.43858,0.02099,2.09943,22.43378
14.20000,1.18329,478.25584,0.02131,2.13089,22.61428
14.40000,1.19998,482.84545,0.02162,2.16239,22.83130
14.60000,1.21672,487.50276,0.02194,2.19421,23.05152
14.80000,1.23334,492.02512,0.02226,2.22554,23.26536
15.00000,1.24990,495.65560,0.02257,2.25736,23.43703
15.20000,1.26664,500.21638,0.02290,2.28952,23.65268
15.40000,1.28344,503.93147,0.02322,2.32152,23.82835
15.60000,1.29994,508.02650,0.02353,2.35344,24.02198
15.80000,1.31662,512.01191,0.02386,2.38577,24.21043
16.00000,1.33343,515.83257,0.02419,2.41852,24.39109
16.20000,1.34993,519.48521,0.02451,2.45135,24.56381
16.40000,1.36667,523.21488,0.02485,2.48452,24.74016
16.60000,1.38341,526.34366,0.02517,2.51674,24.88811
16.80000,1.39997,529.76189,0.02549,2.54941,25.04974
17.00000,1.41659,534.17203,0.02583,2.58275,25.25827
17.20000,1.43333,537.36111,0.02616,2.61605,25.40907
17.40000,1.45001,538.76014,0.02641,2.64091,25.47522
17.60000,1.46664,541.73488,0.02674,2.67431,25.61588
17.80000,1.48320,545.31852,0.02708,2.70778,25.78533
18.00000,1.50006,548.85852,0.02742,2.74151,25.95272
18.20000,1.51662,552.07112,0.02775,2.77466,26.10463
18.40000,1.53330,555.37205,0.02808,2.80835,26.26071
18.60000,1.55004,558.31354,0.02842,2.84200,26.39980
18.80000,1.56666,561.05461,0.02876,2.87633,26.52941
19.00000,1.58341,565.13911,0.02910,2.91012,26.72255
19.20000,1.60003,567.74644,0.02944,2.94434,26.84583
19.40000,1.61671,570.34008,0.02978,2.97822,26.96847
19.60000,1.63333,573.30481,0.03012,3.01219,27.10866
19.80000,1.65001,576.30693,0.03046,3.04616,27.25062
20.00000,1.66663,579.06020,0.03081,3.11265,27.38080
20.14400,1.67865,581.13872,0.03106,3.16072,27.47909
20.34400,1.69533,583.82135,0.03141,3.22745,27.60593
20.54400,1.71195,586.58081,0.03175,3.29393,27.73642
20.74400,1.72863,589.05212,0.03210,3.36066,27.85327
20.94400,1.74532,590.92152,0.03245,3.42738,27.94167
21.14400,1.76200,593.53854,0.03280,3.49411,28.06541
21.34400,1.77862,596.57888,0.03315,3.56059,28.20917
21.54400,1.79530,598.47953,0.03341,3.62732,28.29905
21.74400,1.81216,600.27684,0.03148,3.69476,28.38403
21.94400,1.82872,602.33669,0.00678,3.76101,28.48143
22.14400,1.84534,604.24581,0.00657,3.82749,28.57170
22.34400,1.86202,608.59499,0.00616,3.89422,28.77735
22.54400,1.87865,610.26565,0.00479,3.96070,28.85635
22.74400,1.89527,612.16275,0.00548,4.02719,28.94605
22.94400,1.91201,615.10275,0.00578,4.09415,29.08507
23.14400,1.92869,616.64553,0.00547,4.16088,29.15802
23.34400,1.94525,618.91489,0.00509,4.22713,29.26533
23.54400,1.96199,621.11174,0.00491,4.29409,29.36921
23.74400,1.97873,624.24322,0.00455,4.36105,29.51728
23.94400,1.99535,625.86009,0.00196,4.42754,29.59373
24.14400,2.01204,628.22634,-0.00671,4.49427,29.70562
24.34400,2.02866,629.78901,-0.06076,4.56075,29.77951
24.54400,2.04534,631.83163,-0.03449,4.62748,29.87610
24.74400,2.06196,633.98257,-0.07743,4.69396,29.97780
24.94400,2.07870,636.19292,-0.05714,4.76093,30.08232
25.14400,2.09532,638.19098,-0.05859,4.82741,30.17680
25.34400,2.11194,640.64763,-0.06968,4.89390,30.29296
25.54400,2.12857,641.63823,-0.05662,4.96038,30.33980
25.74400,2.14531,643.54409,-0.06295,5.02735,30.42992
25.94400,2.16205,645.61991,-0.06556,5.09431,30.52807
26.14400,2.17873,647.60656,-0.05840,5.16104,30.62201
26.34400,2.19535,649.52178,-0.06363,5.22752,30.71257
26.54400,2.21203,651.69754,-0.06382,5.29425,30.81545
26.74400,2.22865,652.88567,-0.05969,5.36073,30.87163
26.94400,2.24533,655.62264,-0.06342,5.42746,31.00105
27.14400,2.26208,656.79103,-0.06310,5.49442,31.05630
27.34400,2.27870,658.82117,-0.06046,5.56091,31.15229
27.54400,2.29532,659.43282,-0.06313,5.62740,31.18122
27.74400,2.31200,660.26798,-0.06281,5.69412,31.22071
27.94400,2.32868,662.83438,-0.06097,5.76085,31.34206
28.14400,2.34530,664.01511,-0.06286,5.82733,31.39789
28.34400,2.36198,665.79566,-0.06262,5.89406,31.48208
28.54400,2.37861,667.74008,-0.06131,5.96054,31.57402
28.74400,2.39529,669.89744,-0.06269,6.02727,31.67603
28.94400,2.41203,671.24316,-0.06253,6.09423,31.73967
29.14400,2.42865,673.13747,-0.06156,6.16072,31.82924
29.34400,2.44533,674.45715,-0.06254,6.22744,31.89164
29.54400,2.46201,676.80785,-0.06249,6.29417,32.00279
29.74400,2.47869,678.34184,-0.06170,6.36089,32.07533
29.94400,2.49531,680.52015,-0.06243,6.42738,32.17833
30.14400,2.51194,681.44402,-0.06244,6.49386,32.22201
30.34400,2.52874,683.01549,-0.06183,6.56107,32.29632
30.54400,2.54536,684.21303,-0.06237,6.62755,32.35295
30.74400,2.56192,686.23307,-0.06236,6.69380,32.44846
30.94400,2.57866,687.06032,-0.06183,6.76077,32.48758
31.14400,2.59534,689.23370,-0.06225,6.82749,32.59035
31.34400,2.61196,690.43245,-0.06244,6.89398,32.64703
31.54400,2.62870,691.82236,-0.06203,6.96094,32.71275
31.74400,2.64533,693.51131,-0.06223,7.02743,32.79261
31.94400,2.66195,695.85759,-0.06237,7.09391,32.90356
32.14400,2.67863,696.83348,-0.06209,7.16064,32.94970
32.34400,2.69537,698.06818,-0.06219,7.22760,33.00808
32.54400,2.71205,699.23601,-0.06238,7.29433,33.06330
32.74400,2.72867,700.58410,-0.06214,7.36081,33.12705
32.94400,2.74529,702.38546,-0.06218,7.42730,33.21223
33.14400,2.76198,703.46161,-0.06234,7.49402,33.26311
33.34400,2.77872,704.38515,-0.06216,7.56099,33.30678
33.54400,2.79540,706.14587,-0.06220,7.62771,33.39004
33.74400,2.81196,707.11304,-0.06233,7.69396,33.43577
33.94400,2.82864,708.09922,-0.06220,7.76068,33.48240
34.14400,2.84526,709.53779,-0.06221,7.82717,33.55042
34.34400,2.86194,711.56221,-0.06232,7.89390,33.64615
34.54400,2.87874,712.27178,-0.06222,7.96110,33.67970
34.74400,2.89531,714.48577,-0.06220,8.02735,33.78439
34.94400,2.91205,715.16144,-0.06232,8.09431,33.81634
35.14400,2.92861,716.70455,-0.06222,8.16056,33.88931
35.34400,2.94529,717.57515,-0.06221,8.22728,33.93047
35.54400,2.96209,719.12883,-0.06229,8.29449,34.00394
35.74400,2.97871,719.68809,-0.06222,8.36097,34.03038
35.94400,2.99527,720.51934,-0.06220,8.42722,34.06969
36.14400,3.01202,722.93244,-0.06226,8.49418,34.18379
36.34400,3.02864,723.77226,-0.06224,8.56067,34.22350
36.54400,3.04532,724.84510,-0.06223,8.62739,34.27423
36.74400,3.06206,725.76320,-0.06227,8.69436,34.31764
36.94400,3.07880,725.90089,-0.06225,8.76132,34.32415
37.14400,3.09524,728.30305,-0.06223,8.82709,34.43774
37.34400,3.11198,728.41253,-0.06226,8.89405,34.44291
37.54400,3.12878,729.81408,-0.06225,8.96126,34.50919
37.74400,3.14535,730.46573,-0.06223,9.02750,34.54000
37.94400,3.16197,731.88357,-0.06225,9.09399,34.60704
38.14400,3.17865,732.33531,-0.06226,9.16072,34.62840
38.34400,3.19533,734.53519,-0.06220,9.22744,34.73242
38.54400,3.21195,735.67405,-0.06221,9.29393,34.78627
38.74400,3.22863,736.86563,-0.06224,9.36065,34.84262
38.94400,3.24531,737.72441,-0.06220,9.42738,34.88322
39.14400,3.26194,738.38541,-0.06224,9.49386,34.91448
39.34400,3.27862,739.15236,-0.06227,9.56059,34.95074
39.54400,3.29542,740.35451,-0.06223,9.62779,35.00759
39.74400,3.31198,742.01939,-0.06224,9.69404,35.08631
39.94400,3.32866,742.15704,-0.06227,9.76076,35.09282
40.14400,3.34540,743.32445,-0.06224,9.82773,35.14802
40.34400,3.36202,744.52152,-0.06223,9.89421,35.20463
40.54400,3.37864,745.55781,-0.06226,9.96070,35.25363
40.74400,3.39533,746.72550,-0.06225,10.02742,35.30884
40.94400,3.41207,747.14837,-0.06225,10.09439,35.32884
41.14400,3.42863,748.40379,-0.06226,10.16063,35.38820
41.34400,3.44525,749.46699,-0.06224,10.22712,35.43847
41.54400,3.46199,750.02597,-0.06223,10.29408,35.46490
41.74400,3.47861,751.39846,-0.06226,10.36057,35.52980
41.94400,3.49529,752.32037,-0.06224,10.42730,35.57339
42.14400,3.51209,753.05356,-0.06227,10.49450,35.60806
42.34400,3.52872,753.64215,-0.06228,10.56099,35.63589
42.54400,3.54528,754.71741,-0.06225,10.62723,35.68674
42.74400,3.56196,755.60906,-0.06225,10.69396,35.72890
42.94400,3.57870,756.11486,-0.06227,10.76092,35.75282
43.14400,3.59526,757.18062,-0.06224,10.82717,35.80321
43.34400,3.61200,758.06677,-0.06225,10.89413,35.84511
43.54400,3.62868,758.93071,-0.06227,10.96086,35.88596
43.74400,3.64525,760.58162,-0.06225,11.02710,35.96403
43.94400,3.66205,760.82079,-0.06223,11.09431,35.97533
44.14400,3.67879,761.39644,-0.06225,11.16127,36.00256
44.34400,3.69535,762.10233,-0.06223,11.22752,36.03593
44.54400,3.71197,763.29322,-0.06222,11.29401,36.09224
44.74400,3.72871,764.55818,-0.06223,11.36097,36.15206
44.94400,3.74539,765.15595,-0.06222,11.42769,36.18032
45.14400,3.76190,766.30535,-0.06225,11.49370,36.23467
45.34400,3.77876,763.79413,-0.06226,11.56114,36.11593
45.54400,3.79538,765.58171,-0.06225,11.62763,36.20045
45.74400,3.81194,766.60062,-0.06228,11.69388,36.24863
45.94400,3.82868,767.72082,-0.06228,11.76084,36.30160
46.14400,3.84542,768.29265,-0.06227,11.82781,36.32864
46.34400,3.86198,768.90960,-0.06227,11.89405,36.35781
46.54400,3.87866,769.21512,-0.06226,11.96078,36.37226
46.74400,3.89535,770.49541,-0.06226,12.02750,36.43280
46.94400,3.91197,772.25650,-0.06227,12.09399,36.51607
47.14400,3.92865,772.14534,-0.06227,12.16071,36.51081
47.34400,3.94533,773.33082,-0.06225,12.22744,36.56687
47.54400,3.96201,774.16473,-0.06226,12.29416,36.60630
47.74400,3.97863,774.23188,-0.06227,12.36065,36.60948
47.94400,3.99531,775.12250,-0.06226,12.42737,36.65159
48.14400,4.01199,776.31404,-0.06225,12.49410,36.70793
48.34400,4.02862,776.66147,-0.06225,12.56059,36.72436
48.54400,4.04530,777.37835,-0.06224,12.62731,36.75826
48.74400,4.06210,777.91009,-0.06225,12.69451,36.78340
48.94400,4.07866,778.94572,-0.06226,12.76076,36.83237
49.14400,4.09522,779.51904,-0.06226,12.82701,36.85948
49.34400,4.11196,779.96696,-0.06226,12.89397,36.88066
49.54400,4.12870,780.36864,-0.06226,12.96093,36.89965
49.74400,4.14527,781.00599,-0.06225,13.02718,36.92979
49.94400,4.16201,781.83170,-0.06225,13.09415,36.96883
50.14400,4.17869,782.47730,-0.06223,13.16087,36.99936
50.34400,4.19519,782.98263,-0.06219,13.22688,37.02325
50.54400,4.21199,783.57821,-0.06219,13.29408,37.05142
50.74400,4.22879,783.95344,-0.06224,13.36129,37.06916
50.94400,4.24529,784.92258,-0.06222,13.42729,37.11499
51.14400,4.26197,785.01012,-0.06224,13.49402,37.11913
51.34400,4.27878,786.13143,-0.06228,13.56122,37.17215
51.54400,4.29534,786.58592,-0.06227,13.62747,37.19364
51.74400,4.31196,787.02690,-0.06229,13.69396,37.21449
51.94400,4.32864,787.63710,-0.06229,13.76068,37.24334
52.14400,4.34538,788.09820,-0.06226,13.82765,37.26514
52.34400,4.36194,788.74342,-0.06227,13.89389,37.29565
52.54400,4.37862,788.98463,-0.06228,13.96061,37.30706
52.74400,4.39536,789.85738,-0.06224,14.02758,37.34833
52.94400,4.41199,790.32406,-0.06224,14.09407,37.37040
53.14400,4.42867,790.83182,-0.06223,14.16079,37.39441
53.34400,4.44535,791.06856,-0.06222,14.22752,37.40560
53.54400,4.46197,792.24128,-0.06222,14.29400,37.46105
53.74400,4.47865,791.92566,-0.06221,14.36073,37.44613
53.94400,4.49533,793.00450,-0.06219,14.42745,37.49714
54.14400,4.51201,793.51878,-0.06224,14.49418,37.52146
54.34400,4.52864,793.95482,-0.06223,14.56066,37.54208
54.54400,4.54526,794.14696,-0.06221,14.62715,37.55116
54.74400,4.56200,794.67334,-0.06225,14.69411,37.57605
54.94400,4.57868,795.01439,-0.06225,14.76084,37.59218
55.14400,4.59536,795.47204,-0.06221,14.82756,37.61382
55.34400,4.61204,795.92187,-0.06225,14.89429,37.63509
55.54400,4.62866,796.35289,-0.06225,14.96078,37.65547
55.74400,4.64534,796.63908,-0.06224,15.02750,37.66900
55.94400,4.66203,797.26651,-0.06226,15.09423,37.69867
56.14400,4.67877,797.98577,-0.06224,15.16119,37.73268
56.34400,4.69539,797.97404,-0.06223,15.22768,37.73212
56.54400,4.71195,798.55584,-0.06225,15.29392,37.75963
56.74400,4.72869,799.08688,-0.06225,15.36089,37.78474
56.94400,4.74525,799.43035,-0.06225,15.42713,37.80098
57.14400,4.76199,799.30238,-0.06226,15.49410,37.79493
57.34400,4.77873,800.53722,-0.06227,15.56106,37.85332
57.54400,4.79530,800.55073,-0.06225,15.62731,37.85396
57.74400,4.81198,800.97765,-0.06225,15.69403,37.87415
57.94400,4.82872,801.26822,-0.06227,15.76100,37.88789
58.14400,4.84540,801.20843,-0.06225,15.82772,37.88506
58.34400,4.86196,801.78259,-0.06225,15.89397,37.91221
58.54400,4.87864,802.90642,-0.06225,15.96069,37.96535
58.74400,4.89538,802.67293,-0.06223,16.02766,37.95431
58.94400,4.91195,803.15210,-0.06222,16.09390,37.97697
59.14400,4.92869,803.39964,-0.06221,16.16087,37.98867
59.34400,4.94543,803.82563,-0.06220,16.22783,38.00882
59.54400,4.96199,804.13939,-0.06221,16.29408,38.02365
59.74400,4.97861,805.23631,-0.06225,16.36057,38.07552
59.94400,4.99535,805.01093,-0.06222,16.42753,38.06486
60.14400,5.01197,805.18713,-0.06221,16.49402,38.07319
60.34400,5.02877,805.89000,-0.06224,16.56122,38.10643
60.54400,5.04534,805.58863,-0.06227,16.62747,38.09218
60.74400,5.06202,806.59045,-0.06223,16.69419,38.13955
60.94400,5.07864,806.60144,-0.06226,16.76068,38.14007
61.14400,5.09526,806.57350,-0.06226,16.82716,38.13875
61.34400,5.11206,807.24889,-0.06223,16.89437,38.17068
61.54400,5.12862,808.28695,-0.06222,16.96061,38.21977
61.74400,5.14524,808.15498,-0.06226,17.02710,38.21353
61.94400,5.16199,808.38194,-0.06225,17.09407,38.22426
62.14400,5.17867,808.54092,-0.06224,17.16079,38.23178
62.34400,5.19529,808.85505,-0.06225,17.22727,38.24663
62.54400,5.21203,808.76919,-0.06222,17.29424,38.24257
62.74400,5.22865,809.38675,-0.06225,17.36072,38.27177
62.94400,5.24527,809.61641,-0.06224,17.42721,38.28263
63.14400,5.26195,809.71690,-0.06225,17.49393,38.28738
63.34400,5.27869,810.30075,-0.06222,17.56090,38.31499
63.54400,5.29538,809.71150,-0.06224,17.62762,38.28713
63.74400,5.31200,810.88720,-0.06225,17.69411,38.34272
63.94400,5.32868,810.52221,-0.06222,17.76084,38.32546
64.14400,5.34530,811.66280,-0.06224,17.82732,38.37939
64.34400,5.36198,811.55309,-0.06228,17.89404,38.37421
64.54401,5.37872,811.93000,-0.06226,17.96101,38.39203
64.74400,5.39534,812.21154,-0.06227,18.02750,38.40534
64.94400,5.41196,812.04232,-0.06225,18.09398,38.39734
65.14400,5.42865,812.80777,-0.06223,18.16071,38.43354
65.34400,5.44527,812.78104,-0.06223,18.22719,38.43227
65.54401,5.46195,813.02300,-0.06226,18.29392,38.44371
65.74400,5.47869,813.73146,-0.06224,18.36088,38.47721
65.94400,5.49537,813.80820,-0.06221,18.42761,38.48084
66.14401,5.51193,813.65341,-0.06217,18.49385,38.47352
66.34400,5.52861,813.52647,-0.06221,18.56058,38.46752
66.54401,5.54542,814.40788,-0.06220,18.62778,38.50920
66.74400,5.56204,814.20392,-0.06220,18.69427,38.49955
66.94400,5.57866,814.19144,-0.06223,18.76075,38.49896
67.14401,5.59534,814.57049,-0.06223,18.82748,38.51688
67.34400,5.61202,814.95401,-0.06226,18.89421,38.53502
67.54401,5.62864,815.01296,-0.06221,18.96069,38.53781
67.74400,5.64532,814.71307,-0.06224,19.02742,38.52363
67.94400,5.66200,814.95112,-0.06228,19.09414,38.53488
68.14401,5.67863,815.40002,-0.06222,19.16063,38.55611
68.34400,5.69525,816.20393,-0.06224,19.22711,38.59412
68.54401,5.71199,816.18726,-0.06228,19.29408,38.59333
68.74400,5.72867,815.68751,-0.06225,19.36080,38.56970
68.94400,5.74535,815.77152,-0.06226,19.42753,38.57368
69.14401,5.76203,816.47169,-0.06228,19.49425,38.60678
69.34400,5.77865,816.42726,-0.06224,19.56074,38.60468
69.54401,5.79534,816.67798,-0.06221,19.62747,38.61654
69.74400,5.81202,816.73143,-0.06223,19.69419,38.61906
69.94400,5.82876,817.69479,-0.06224,19.76115,38.66462
70.14401,5.84532,816.95979,-0.06219,19.82740,38.62986
70.34400,5.86194,816.99183,-0.06223,19.89389,38.63138
70.54401,5.87868,817.16729,-0.06224,19.96085,38.63968
70.74400,5.89530,818.30285,-0.06222,20.02733,38.69337
70.94400,5.91198,817.92129,-0.06223,20.09406,38.67533
71.14401,5.92873,818.24893,-0.06226,20.16102,38.69082
71.34400,5.94529,818.25387,-0.06219,20.22727,38.69105
71.54401,5.96197,818.15524,-0.06221,20.29400,38.68639
71.74400,5.97871,817.86681,-0.06223,20.36096,38.67275
71.94400,5.99539,818.98933,-0.06222,20.42769,38.72583
72.14401,6.01201,818.41238,-0.06226,20.49417,38.69855
72.34400,6.02863,818.74141,-0.06224,20.56066,38.71411
72.54401,6.04543,818.68470,-0.06222,20.62786,38.71143
72.74400,6.06194,819.42007,-0.06224,20.69387,38.74620
72.94400,6.07862,818.43967,-0.06225,20.76060,38.69984
73.14401,6.09536,819.27916,-0.06222,20.82756,38.73953
73.34400,6.11204,819.23846,-0.06225,20.89428,38.73761
73.54401,6.12860,819.26342,-0.06225,20.96053,38.73879
73.74400,6.14534,819.61565,-0.06223,21.02750,38.75544
73.94400,6.16202,819.33392,-0.06226,21.09422,38.74212
74.14401,6.17865,819.28466,-0.06226,21.16071,38.73980
74.34400,6.19533,819.40116,-0.06224,21.22743,38.74530
74.54401,6.21201,819.73672,-0.06225,21.29415,38.76117
74.74400,6.22857,820.10785,-0.06226,21.36040,38.77872
74.94400,6.24531,820.19409,-0.06225,21.42737,38.78279
75.14401,6.26205,819.60056,-0.06226,21.49433,38.75473
75.34400,6.27867,819.79102,-0.06227,21.56082,38.76374
75.54401,6.29530,820.31200,-0.06222,21.62730,38.78837
75.74400,6.31198,819.33169,-0.06222,21.69403,38.74202
75.94400,6.32866,820.80541,-0.06223,21.76075,38.81170
76.14401,6.34528,820.10292,-0.06221,21.82724,38.77848
76.34400,6.36202,820.11782,-0.06223,21.89420,38.77919
76.54401,6.37882,820.46231,-0.06225,21.96141,38.79548
76.74400,6.39520,820.31302,-0.06218,22.02694,38.78842
76.94400,6.41194,820.73491,-0.06227,22.09390,38.80837
77.14401,6.42875,820.88960,-0.06226,22.16110,38.81569
77.34400,6.44531,820.70651,-0.06221,22.22735,38.80703
77.54401,6.46205,821.01533,-0.06226,22.29431,38.82163
77.74400,6.47873,820.56141,-0.06222,22.36104,38.80016
77.94400,6.49529,820.75084,-0.06222,22.42729,38.80912
78.14401,6.51191,821.11191,-0.06221,22.49377,38.82619
78.34400,6.52865,821.10744,-0.06227,22.56074,38.82598
78.54401,6.54540,820.98469,-0.06223,22.62770,38.82018
78.74400,6.56196,821.05808,-0.06224,22.69395,38.82365
78.94400,6.57864,821.33878,-0.06227,22.76067,38.83692
79.14401,6.59544,820.50879,-0.06225,22.82788,38.79768
79.34400,6.61194,820.98320,-0.06225,22.89388,38.82011
79.54401,6.62868,821.25589,-0.06227,22.96085,38.83300
79.74400,6.64542,821.12271,-0.06226,23.02781,38.82671
79.94400,6.66204,821.29594,-0.06225,23.09430,38.83490
80.14401,6.67861,821.29594,-0.06227,23.16054,38.83490
80.34400,6.69535,821.37780,-0.06227,23.22751,38.83877
80.54401,6.71203,821.37976,-0.06226,23.29423,38.83886
80.74400,6.72865,820.96737,-0.06227,23.36072,38.81936
80.94400,6.74527,820.83670,-0.06227,23.42721,38.81318
81.14401,6.76207,821.17850,-0.06226,23.49441,38.82935
81.34400,6.77857,821.60709,-0.06227,23.56042,38.84961
81.54401,6.79531,820.90655,-0.06226,23.62738,38.81649
81.74400,6.81212,821.15941,-0.06225,23.69459,38.82844
81.94400,6.82862,821.09394,-0.06226,23.76059,38.82534
82.14401,6.84530,821.16509,-0.06223,23.82732,38.82871
82.34400,6.86198,821.12597,-0.06219,23.89404,38.82686
82.54401,6.87866,820.93915,-0.06224,23.96077,38.81803
82.74400,6.89534,820.78753,-0.06216,24.02749,38.81086
82.94400,6.91202,821.15047,-0.06222,24.09422,38.82802
83.14401,6.92865,820.84499,-0.06229,24.16070,38.81358
83.34400,6.94527,820.81417,-0.06223,24.22719,38.81211
83.54401,6.96189,820.66040,-0.06220,24.29367,38.80485
83.74400,6.97869,820.97985,-0.06228,24.36088,38.81995
83.94400,6.99537,820.78399,-0.06224,24.42760,38.81069
84.14401,7.01205,820.38259,-0.06222,24.49433,38.79171
84.34400,7.02867,821.06786,-0.06228,24.56081,38.82411
84.54401,7.04529,821.38767,-0.06225,24.62730,38.83923
84.74400,7.06198,820.28760,-0.06221,24.69403,38.78722
84.94400,7.07872,820.18860,-0.06229,24.76099,38.78254
85.14401,7.09540,821.08807,-0.06227,24.82771,38.82507
85.34400,7.11196,820.34860,-0.06223,24.89396,38.79010
85.54401,7.12864,820.40764,-0.06228,24.96069,38.79289
85.74400,7.14538,820.48792,-0.06228,25.02765,38.79669
85.94401,7.16194,820.48364,-0.06223,25.09390,38.79649
86.14401,7.17863,820.72439,-0.06226,25.16062,38.80787
86.34400,7.19537,820.26124,-0.06223,25.22759,38.78597
86.54401,7.21199,820.71153,-0.06224,25.29407,38.80726
86.74400,7.22855,821.09096,-0.06221,25.36032,38.82520
86.94401,7.24541,820.54203,-0.06218,25.42776,38.79925
87.14401,7.26209,820.18776,-0.06214,25.49449,38.78250
87.34400,7.27865,820.81789,-0.06226,25.56073,38.81229
87.54401,7.29533,820.36201,-0.06218,25.62746,38.79074
87.74400,7.31208,820.59847,-0.06219,25.69442,38.80192
87.94401,7.32864,820.36899,-0.06228,25.76067,38.79107
88.14401,7.34526,819.92652,-0.06225,25.82715,38.77015
88.34400,7.36206,820.15675,-0.06222,25.89436,38.78103
88.54401,7.37862,820.22883,-0.06230,25.96061,38.78444
88.74400,7.39530,820.22129,-0.06227,26.02733,38.78408
88.94401,7.41198,820.32038,-0.06224,26.09406,38.78877
89.14401,7.42866,819.65681,-0.06228,26.16078,38.75739
89.34400,7.44535,819.98361,-0.06228,26.22751,38.77284
89.54401,7.46203,819.17141,-0.06225,26.29423,38.73444
89.74400,7.47865,819.37406,-0.06231,26.36072,38.74402
89.94401,7.49533,819.46477,-0.06231,26.42744,38.74831
90.14401,7.51201,819.40508,-0.06220,26.49417,38.74549
90.34400,7.52875,819.33774,-0.06225,26.56113,38.74231
90.54401,7.54531,819.38142,-0.06228,26.62738,38.74437
90.74400,7.56200,819.11692,-0.06224,26.69410,38.73186
90.94401,7.57862,819.51227,-0.06226,26.76059,38.75056
91.14401,7.59530,819.13797,-0.06225,26.82732,38.73286
91.34400,7.61204,818.84004,-0.06223,26.89428,38.71877
91.54401,7.62860,818.44982,-0.06225,26.96052,38.70032
91.74400,7.64528,819.30794,-0.06221,27.02725,38.74089
91.94401,7.66202,818.67799,-0.06219,27.09422,38.71111
92.14401,7.67859,818.38099,-0.06223,27.16046,38.69706
92.34400,7.69539,818.70519,-0.06225,27.22766,38.71239
92.54401,7.71207,818.22136,-0.06225,27.29439,38.68952
92.74400,7.72863,817.97754,-0.06223,27.36064,38.67799
92.94401,7.74537,818.47990,-0.06225,27.42760,38.70174
93.14401,7.76199,817.98537,-0.06223,27.49409,38.67836
93.34400,7.77861,817.92912,-0.06224,27.56057,38.67570
93.54401,7.79535,817.97596,-0.06226,27.62754,38.67791
93.74400,7.81204,817.78858,-0.06225,27.69426,38.66905
93.94401,7.82860,818.05224,-0.06223,27.76051,38.68152
94.14401,7.84528,817.49661,-0.06227,27.82723,38.65525
94.34400,7.86202,817.67039,-0.06226,27.89420,38.66346
94.54401,7.87870,817.50434,-0.06222,27.96092,38.65561
94.74400,7.89532,817.75216,-0.06224,28.02741,38.66733
94.94401,7.91206,817.40096,-0.06221,28.09438,38.65072
95.14401,7.92862,816.78517,-0.06220,28.16062,38.62160
95.34400,7.94537,817.38327,-0.06225,28.22758,38.64989
95.54401,7.96205,817.06531,-0.06225,28.29431,38.63485
95.74400,7.97867,816.47672,-0.06221,28.36080,38.60702
95.94401,7.99535,816.56659,-0.06223,28.42752,38.61127
96.14401,8.01197,816.80221,-0.06226,28.49400,38.62241
96.34400,8.02865,816.11462,-0.06226,28.56073,38.58990
96.54401,8.04533,816.24752,-0.06220,28.62746,38.59618
96.74400,8.06195,816.44785,-0.06217,28.69394,38.60566
96.94401,8.07864,816.20449,-0.06223,28.76067,38.59415
97.14401,8.09526,816.32398,-0.06221,28.82715,38.59980
97.34400,8.11194,816.03937,-0.06223,28.89388,38.58634
97.54401,8.12868,814.92150,-0.06224,28.96084,38.53348
97.74400,8.14536,815.20323,-0.06227,29.02757,38.54680
97.94401,8.16210,815.01100,-0.06228,29.09453,38.53772
98.14401,8.17866,815.11727,-0.06229,29.16078,38.54274
98.34400,8.19535,815.19987,-0.06228,29.22750,38.54665
98.54401,8.21197,814.64536,-0.06224,29.29399,38.52042
98.74400,8.22865,814.54311,-0.06222,29.36072,38.51559
98.94401,8.24539,814.76849,-0.06224,29.42768,38.52625
99.14401,8.26195,814.09039,-0.06224,29.49392,38.49418
99.34400,8.27863,814.15819,-0.06226,29.56065,38.49739
99.54401,8.29531,814.27395,-0.06228,29.62738,38.50286
99.74400,8.31199,813.44079,-0.06226,29.69410,38.46347
99.94401,8.32874,813.99716,-0.06225,29.76106,38.48978
100.14401,8.34536,813.55451,-0.06227,29.82755,38.46885
100.34400,8.36204,813.36256,-0.06226,29.89427,38.45977
100.54401,8.37860,813.25322,-0.06225,29.96052,38.45460
100.74400,8.39534,813.31413,-0.06226,30.02749,38.45748
100.94401,8.41214,813.36647,-0.06225,30.09469,38.45995
101.14401,8.42864,813.01667,-0.06224,30.16070,38.44341
101.34400,8.44527,812.54570,-0.06223,30.22718,38.42114
101.54401,8.46207,812.58286,-0.06225,30.29439,38.42290
101.74400,8.47869,812.45266,-0.06225,30.36087,38.41674
101.94401,8.49525,812.78495,-0.06224,30.42712,38.43246
102.14401,8.51205,812.34695,-0.06224,30.49432,38.41175
102.34400,8.52867,811.76702,-0.06223,30.56081,38.38432
102.54401,8.54529,811.13074,-0.06222,30.62730,38.35424
102.74400,8.56197,811.21298,-0.06226,30.69402,38.35812
102.94401,8.57878,811.63328,-0.06225,30.76122,38.37800
103.14401,8.59528,811.25656,-0.06225,30.82723,38.36019
103.34400,8.61202,810.75625,-0.06226,30.89420,38.33653
103.54401,8.62876,811.01339,-0.06225,30.96116,38.34869
103.74400,8.64532,810.53292,-0.06225,31.02741,38.32597
103.94401,8.66200,810.62028,-0.06226,31.09413,38.33010
104.14401,8.67862,810.20305,-0.06225,31.16062,38.31037
104.34400,8.69531,809.61566,-0.06224,31.22734,38.28260
104.54401,8.71193,808.96514,-0.06225,31.29383,38.25183
104.74400,8.72861,809.44626,-0.06225,31.36055,38.27459
104.94401,8.74535,809.50046,-0.06224,31.42752,38.27715
105.14401,8.76197,808.82637,-0.06225,31.49400,38.24527
105.34400,8.77865,808.80234,-0.06226,31.56073,38.24414
105.54401,8.79539,808.54595,-0.06226,31.62769,38.23201
105.74400,8.81195,807.93919,-0.06225,31.69394,38.20332
105.94401,8.82864,808.17752,-0.06226,31.76066,38.21459
106.14401,8.84538,808.07712,-0.06226,31.82763,38.20985
106.34400,8.86200,807.32461,-0.06226,31.89411,38.17426
106.54401,8.87862,806.84163,-0.06226,31.96060,38.15143
106.74400,8.89536,807.18650,-0.06226,32.02757,38.16773
106.94401,8.91198,807.05080,-0.06226,32.09405,38.16132
107.14401,8.92854,807.03543,-0.06226,32.16030,38.16059
107.34400,8.94535,806.72391,-0.06225,32.22750,38.14586
107.54401,8.96209,806.68079,-0.06225,32.29446,38.14382
107.74400,8.97859,806.15897,-0.06225,32.36047,38.11915
107.94401,8.99533,805.92679,-0.06225,32.42744,38.10817
108.14401,9.01207,805.61051,-0.06226,32.49440,38.09321
108.34400,9.02863,805.91179,-0.06226,32.56065,38.10746
108.54401,9.04531,804.88222,-0.06227,32.62737,38.05878
108.74400,9.06211,804.33488,-0.06226,32.69458,38.03289
108.94401,9.07862,804.82233,-0.06226,32.76058,38.05594
109.14401,9.09530,804.52645,-0.06225,32.82731,38.04195
109.34400,9.11204,804.30759,-0.06224,32.89427,38.03160
109.54401,9.12878,803.71816,-0.06224,32.96124,38.00373
109.74400,9.14528,803.48607,-0.06225,33.02725,37.99276
109.94401,9.16196,803.31154,-0.06224,33.09397,37.98451
110.14401,9.17870,803.23033,-0.06226,33.16094,37.98067
110.34400,9.19532,802.30003,-0.06227,33.22742,37.93668
110.54401,9.21201,801.86902,-0.06225,33.29415,37.91630
110.74400,9.22881,802.23214,-0.06226,33.36135,37.93347
110.94401,9.24525,801.85467,-0.06226,33.42712,37.91562
111.14401,9.26193,801.72038,-0.06225,33.49384,37.90927
111.34400,9.27867,801.46939,-0.06226,33.56080,37.89740
111.54401,9.29535,800.90351,-0.06227,33.62753,37.87064
111.74400,9.31197,800.24488,-0.06226,33.69402,37.83950
111.94401,9.32865,799.93866,-0.06227,33.76074,37.82502
112.14401,9.34540,799.73442,-0.06227,33.82771,37.81536
112.34400,9.36196,799.12366,-0.06226,33.89395,37.78648
112.54401,9.37864,798.99020,-0.06226,33.96068,37.78017
112.74400,9.39538,799.01721,-0.06227,34.02764,37.78145
112.94401,9.41200,798.29404,-0.06226,34.09413,37.74725
113.14401,9.42868,798.08803,-0.06226,34.16085,37.73751
113.34400,9.44542,797.97264,-0.06227,34.22782,37.73206
113.54401,9.46199,797.74642,-0.06226,34.29407,37.72136
113.74400,9.47867,797.10949,-0.06226,34.36079,37.69124
113.94401,9.49541,796.58190,-0.06226,34.42775,37.66630
114.14401,9.51203,795.92653,-0.06226,34.49424,37.63531
114.34400,9.52859,796.52742,-0.06225,34.56049,37.66372
114.54401,9.54527,796.08066,-0.06225,34.62721,37.64259
114.74400,9.56207,795.71884,-0.06224,34.69442,37.62549
114.94401,9.57864,795.36280,-0.06220,34.76066,37.60865
115.14401,9.59526,794.63283,-0.06222,34.82715,37.57413
115.34400,9.61206,794.37727,-0.06221,34.89435,37.56205
115.54401,9.62862,793.54066,-0.06219,34.96060,37.52249
115.74400,9.64524,793.85368,-0.06223,35.02708,37.53729
115.94401,9.66204,793.15444,-0.06226,35.09429,37.50423
116.14401,9.67878,792.75286,-0.06223,35.16125,37.48524
116.34400,9.69528,792.09208,-0.06225,35.22726,37.45399
116.54401,9.71197,791.90116,-0.06226,35.29399,37.44497
116.74400,9.72877,791.30614,-0.06225,35.36119,37.41683
116.94401,9.74527,791.24048,-0.06226,35.42719,37.41373
117.14401,9.76201,790.39335,-0.06227,35.49416,37.37367
117.34400,9.77875,789.90990,-0.06226,35.56112,37.35081
117.54401,9.79525,790.56658,-0.06225,35.62713,37.38186
117.74400,9.81193,788.92661,-0.06225,35.69386,37.30432
117.94401,9.82862,789.31982,-0.06225,35.76058,37.32291
118.14401,9.84536,788.59990,-0.06225,35.82755,37.28887
118.34401,9.86204,788.35441,-0.06227,35.89427,37.27726
118.54401,9.87854,788.04856,-0.06225,35.96028,37.26280
118.74400,9.89534,787.55701,-0.06226,36.02749,37.23956
118.94401,9.91196,786.91859,-0.06226,36.09397,37.20937
119.14401,9.92870,786.55928,-0.06225,36.16093,37.19238
119.34401,9.94544,785.96454,-0.06225,36.22790,37.16426
119.54401,9.96200,785.32659,-0.06228,36.29414,37.13409
119.74400,9.97863,785.68729,-0.06222,36.36063,37.15115
119.94401,9.99525,784.31778,-0.06227,36.42712,37.08639
120.14401,10.01193,784.41771,-0.06227,36.49384,37.09111
120.34401,10.02867,784.02497,-0.06224,36.56080,37.07254
120.54401,10.04529,783.00955,-0.06225,36.62729,37.02453
120.74400,10.06203,782.56670,-0.06225,36.69426,37.00359
120.94401,10.07859,782.81090,-0.06223,36.76050,37.01514
121.14401,10.09534,781.69564,-0.06220,36.82747,36.96240
121.34401,10.11208,780.12547,-0.06223,36.89443,36.88816
121.54401,10.12864,780.80990,-0.06225,36.96067,36.92052
121.74400,10.14532,780.00054,-0.06223,37.02740,36.88225
121.94401,10.16206,779.57767,-0.06225,37.09437,36.86225
122.14401,10.17862,778.95252,-0.06225,37.16061,36.83269
122.34401,10.19530,778.27112,-0.06222,37.22734,36.80047
122.54401,10.21205,777.88965,-0.06224,37.29430,36.78244
122.74400,10.22873,776.80140,-0.06228,37.36103,36.73098
122.94401,10.24529,776.61360,-0.06226,37.42727,36.72210
123.14401,10.26191,776.03539,-0.06225,37.49376,36.69476
123.34401,10.27871,775.25568,-0.06226,37.56096,36.65789
123.54401,10.29533,775.38770,-0.06226,37.62745,36.66413
123.74400,10.31195,774.47309,-0.06225,37.69394,36.62088
123.94401,10.32869,774.18014,-0.06226,37.76090,36.60703
124.14401,10.34532,773.58484,-0.06226,37.82738,36.57888
124.34401,10.36200,772.50740,-0.06225,37.89411,36.52794
124.54401,10.37874,771.96117,-0.06226,37.96107,36.50211
124.74400,10.39542,771.38585,-0.06226,38.02780,36.47490
124.94401,10.41192,770.43199,-0.06224,38.09381,36.42980
125.14401,10.42860,769.84270,-0.06223,38.16053,36.40194
125.34401,10.44534,769.90663,-0.06223,38.22749,36.40496
125.54401,10.46197,768.68283,-0.06224,38.29398,36.34709
125.74400,10.47871,768.42611,-0.06224,38.36095,36.33495
125.94401,10.49533,767.74750,-0.06229,38.42743,36.30286
126.14401,10.51195,766.68328,-0.06226,38.49392,36.25254
126.34401,10.52863,767.12938,-0.06224,38.56064,36.27364
126.54401,10.54531,766.35624,-0.06223,38.62737,36.23708
126.74400,10.56199,765.31987,-0.06223,38.69409,36.18808
126.94401,10.57867,764.54887,-0.06225,38.76082,36.15162
127.14401,10.59529,763.96917,-0.06218,38.82730,36.12421
127.34401,10.61198,763.50127,-0.06224,38.89403,36.10208
127.54401,10.62866,762.74923,-0.06223,38.96075,36.06652
127.74400,10.64534,761.89893,-0.06225,39.02748,36.02631
127.94401,10.66202,761.12645,-0.06223,39.09420,35.98979
128.14402,10.67864,760.87001,-0.06227,39.16069,35.97766
128.34401,10.69526,760.06893,-0.06227,39.22717,35.93979
128.54401,10.71200,758.82622,-0.06225,39.29414,35.88102
128.74400,10.72869,758.96163,-0.06223,39.36087,35.88742
128.94400,10.74531,757.93127,-0.06220,39.42735,35.83870
129.14402,10.76205,757.71157,-0.06219,39.49431,35.82832
129.34401,10.77861,756.82579,-0.06223,39.56057,35.78643
129.54401,10.79529,755.77945,-0.06220,39.62729,35.73696
129.74400,10.81197,754.76943,-0.06218,39.69401,35.68920
129.94400,10.82877,754.07773,-0.06227,39.76121,35.65649
130.14402,10.84534,753.54138,-0.06227,39.82746,35.63113
130.34401,10.86196,752.82422,-0.06222,39.89395,35.59722
130.54401,10.87876,752.18724,-0.06226,39.96115,35.56710
130.74400,10.89532,751.32484,-0.06226,40.02740,35.52632
130.94400,10.91194,750.64278,-0.06222,40.09388,35.49407
131.14402,10.92868,750.20916,-0.06220,40.16085,35.47356
131.34402,10.94530,749.15849,-0.06222,40.22734,35.42389
131.54400,10.96192,748.78442,-0.06224,40.29382,35.40620
131.74400,10.97867,747.75140,-0.06219,40.36078,35.35735
131.94400,10.99541,747.17803,-0.06218,40.42775,35.33024
132.14402,11.01203,745.96596,-0.06222,40.49424,35.27293
132.34402,11.02865,745.51376,-0.06225,40.56072,35.25154
132.54400,11.04539,744.16841,-0.06224,40.62768,35.18793
132.74400,11.06195,743.96469,-0.06225,40.69393,35.17830
132.94400,11.07863,742.74298,-0.06226,40.76066,35.12053
133.14402,11.09537,742.57711,-0.06225,40.82762,35.11269
133.34402,11.11206,741.47126,-0.06225,40.89435,35.06039
133.54400,11.12856,740.58264,-0.06226,40.96036,35.01838
133.74400,11.14530,739.89425,-0.06227,41.02732,34.98582
133.94400,11.16204,739.27986,-0.06225,41.09429,34.95678
134.14402,11.17872,738.53731,-0.06227,41.16101,34.92167
134.34402,11.19534,737.61446,-0.06227,41.22749,34.87803
134.54400,11.21208,737.43495,-0.06225,41.29446,34.86954
134.74400,11.22865,736.33580,-0.06226,41.36070,34.81757
134.94400,11.24533,736.36333,-0.06227,41.42743,34.81887
135.14402,11.26207,734.93365,-0.06227,41.49439,34.75127
135.34402,11.27875,734.46576,-0.06227,41.56112,34.72914
135.54400,11.29531,733.80512,-0.06228,41.62737,34.69790
135.74400,11.31193,732.17675,-0.06228,41.69385,34.62091
135.94400,11.32867,732.59086,-0.06227,41.76082,34.64049
136.14402,11.34529,731.31276,-0.06227,41.82730,34.58005
136.34402,11.36198,730.78163,-0.06226,41.89402,34.55494
136.54400,11.37872,729.53869,-0.06226,41.96099,34.49617
136.74400,11.39528,729.24476,-0.06226,42.02724,34.48227
136.94400,11.41190,728.24969,-0.06226,42.09372,34.43521
137.14402,11.42876,727.48200,-0.06225,42.16117,34.39891
137.34402,11.44532,726.77410,-0.06226,42.22741,34.36544
137.54400,11.46200,726.32707,-0.06226,42.29414,34.34430
137.74400,11.47869,725.89736,-0.06225,42.36087,34.32399
137.94400,11.49543,724.26456,-0.06226,42.42783,34.24678
138.14402,11.51193,725.13507,-0.06226,42.49384,34.28794
138.34402,11.52867,723.47787,-0.06224,42.56080,34.20958
138.54400,11.54541,722.74455,-0.06223,42.62776,34.17490
138.74400,11.56197,722.41710,-0.06224,42.69401,34.15942
138.94400,11.57853,721.99595,-0.06223,42.76026,34.13951
139.14402,11.59539,720.89694,-0.06226,42.82770,34.08754
139.34402,11.61196,720.57326,-0.06224,42.89394,34.07224
139.54400,11.62870,720.19738,-0.06222,42.96091,34.05446
139.74400,11.64532,719.51854,-0.06224,43.02740,34.02236
139.94400,11.66200,718.84594,-0.06225,43.09412,33.99056
140.14402,11.67862,718.57031,-0.06225,43.16061,33.97753
140.34402,11.69530,717.78684,-0.06227,43.22734,33.94048
140.54400,11.71204,717.61962,-0.06226,43.29430,33.93257
140.74400,11.72861,716.36806,-0.06226,43.36055,33.87339
140.94400,11.74529,715.65919,-0.06226,43.42727,33.83987
141.14402,11.76197,714.74612,-0.06226,43.49399,33.79670
141.34402,11.77859,714.17345,-0.06226,43.56048,33.76962
141.54400,11.79533,713.43235,-0.06227,43.62744,33.73458
141.74400,11.81201,713.02308,-0.06226,43.69417,33.71523
141.94400,11.82869,711.68998,-0.06225,43.76089,33.65219
142.14402,11.84531,710.76765,-0.06226,43.82738,33.60858
142.34402,11.86199,710.52634,-0.06226,43.89410,33.59717
142.54400,11.87874,709.27027,-0.06225,43.96107,33.53777
142.74400,11.89530,708.35752,-0.06225,44.02732,33.49461
142.94400,11.91198,707.61377,-0.06226,44.09404,33.45945
143.14402,11.92872,706.70154,-0.06225,44.16100,33.41631
143.34402,11.94528,706.15001,-0.06225,44.22725,33.39023
143.54400,11.96190,705.06688,-0.06226,44.29374,33.33902
143.74400,11.97876,703.78818,-0.06225,44.36118,33.27855
143.94400,11.99539,702.93196,-0.06225,44.42767,33.23807
144.14402,12.01195,702.78416,-0.06223,44.49391,33.23108
144.34402,12.02863,701.64381,-0.06224,44.56064,33.17716
144.54400,12.04543,700.16417,-0.06224,44.62784,33.10719
144.74400,12.06199,699.69571,-0.06227,44.69409,33.08504
144.94400,12.07867,699.44086,-0.06226,44.76081,33.07299
145.14402,12.09541,698.14273,-0.06225,44.82777,33.01161
145.34402,12.11198,696.86598,-0.06227,44.89402,32.95124
145.54400,12.12866,695.99939,-0.06228,44.96075,32.91026
145.74400,12.14540,694.35867,-0.06225,45.02771,32.83268
145.94400,12.16202,693.33105,-0.06227,45.09420,32.78409
146.14402,12.17864,691.79493,-0.06226,45.16069,32.71146
146.34402,12.19532,690.13061,-0.06223,45.22741,32.63276
146.54400,12.21200,688.25250,-0.06225,45.29414,32.54395
146.74400,12.22863,686.46898,-0.06227,45.36062,32.45962
146.94400,12.24525,683.58369,-0.06225,45.42711,32.32319
147.14402,12.26211,678.83790,-0.06226,45.49455,32.09878
147.34402,12.27867,673.66306,-0.06227,45.56080,31.85409
147.54400,12.29529,667.71111,-0.06226,45.62728,31.57265
147.74400,12.31197,659.23980,-0.06226,45.69401,31.17209
147.94400,12.32865,647.43157,-0.06227,45.76073,30.61374
148.12800,12.34408,6.61458,-0.06227,45.82244,0.31277