File: Manufatura Aditiva/Classificação Orientação/Ensaios/Ensaios SLS/Tracao_OLABI_07_06_2018_SLS_YX5.is_metal_RawData/Specimen_RawData_4.csv
Time,Extension,Load,Strain 1,Tensile strain,Tensile stress
(sec),(mm),(N),(mm/mm),(%),(MPa)
0.00000,0.00006,22.61309,0.00090,0.09030,1.09403
0.20000,0.01381,28.33957,0.00109,0.10928,1.37108
0.40000,0.03270,38.94212,0.00142,0.14185,1.88404
0.60000,0.04986,48.30032,0.00171,0.17090,2.33679
0.80000,0.06673,56.47167,0.00199,0.19913,2.73213
1.00000,0.08329,64.94563,0.00227,0.22652,3.14210
1.20000,0.10003,73.07961,0.00256,0.25555,3.53563
1.40000,0.11683,81.87760,0.00284,0.28396,3.96128
1.60000,0.13339,89.73710,0.00312,0.31157,4.34152
1.80000,0.14995,97.49004,0.00340,0.33987,4.71661
2.00000,0.16663,105.40870,0.00368,0.36788,5.09972
2.20000,0.18331,112.94590,0.00396,0.39605,5.46438
2.40000,0.19994,121.05886,0.00425,0.42456,5.85688
2.60000,0.21668,128.40341,0.00453,0.45303,6.21222
2.80000,0.23336,135.71624,0.00481,0.48114,6.56601
3.00000,0.24992,143.40669,0.00509,0.50938,6.93808
3.20000,0.26672,151.14858,0.00537,0.53739,7.31264
3.40000,0.28340,158.64078,0.00566,0.56629,7.67511
3.60000,0.30002,166.34433,0.00594,0.59398,8.04782
3.80000,0.31665,173.29472,0.00622,0.62216,8.38408
4.00000,0.33327,180.82253,0.00651,0.65101,8.74828
4.20000,0.34995,187.98474,0.00679,0.67921,9.09479
4.40000,0.36663,195.33732,0.00707,0.70716,9.45051
4.60000,0.38331,202.26361,0.00735,0.73518,9.78561
4.80000,0.39999,209.80781,0.00763,0.76327,10.15060
5.00000,0.41661,216.86761,0.00792,0.79182,10.49216
5.20000,0.43335,223.60233,0.00819,0.81931,10.81798
5.40000,0.45010,230.78367,0.00848,0.84815,11.16542
5.60000,0.46666,237.99608,0.00877,0.87659,11.51436
5.80000,0.48334,245.02808,0.00905,0.90465,11.85457
6.00000,0.50002,252.32830,0.00933,0.93343,12.20776
6.20000,0.51664,258.86663,0.00962,0.96150,12.52409
6.40000,0.53326,265.99872,0.00990,0.99012,12.86914
6.60000,0.55000,273.08261,0.01018,1.01843,13.21186
6.80000,0.56674,279.25845,0.01047,1.04673,13.51065
7.00000,0.58331,286.38125,0.01075,1.07523,13.85526
7.20000,0.59993,292.93129,0.01104,1.10390,14.17215
7.40000,0.61673,298.50793,0.01131,1.13072,14.44195
7.60000,0.63329,305.76969,0.01159,1.15928,14.79328
7.80000,0.64997,312.29146,0.01188,1.18846,15.10881
8.00000,0.66671,318.60257,0.01217,1.21704,15.41414
8.20000,0.68333,325.37107,0.01245,1.24520,15.74160
8.40000,0.70002,330.86953,0.01274,1.27402,16.00762
8.60000,0.71664,337.26611,0.01303,1.30324,16.31709
8.80000,0.73344,343.81524,0.01332,1.33220,16.63394
9.00000,0.75000,349.34329,0.01361,1.36052,16.90139
9.20000,0.76662,355.55763,0.01389,1.38934,17.20204
9.40000,0.78336,361.53209,0.01418,1.41826,17.49109
9.60000,0.79992,367.23968,0.01447,1.44742,17.76723
9.80000,0.81660,373.36883,0.01477,1.47670,18.06376
10.00000,0.83341,378.61348,0.01506,1.50630,18.31750
10.20000,0.84991,384.68093,0.01535,1.53499,18.61104
10.40000,0.86665,389.42748,0.01564,1.56445,18.84068
10.60000,0.88333,395.65251,0.01594,1.59411,19.14185
10.80000,0.90007,398.79363,0.01614,1.61352,19.29382
11.00000,0.91669,404.40746,0.01643,1.64328,19.56542
11.20000,0.93331,410.29486,0.01673,1.67272,19.85026
11.40000,0.95000,415.44065,0.01703,1.70288,20.09921
11.60000,0.96656,420.64292,0.01733,1.73277,20.35090
11.80000,0.98336,425.86066,0.01763,1.76268,20.60334
12.00000,1.00010,431.33972,0.01793,1.79278,20.86842
12.20000,1.01666,435.62176,0.01823,1.82332,21.07558
12.40000,1.03328,441.28429,0.01854,1.85362,21.34954
12.60000,1.04996,445.98784,0.01884,1.88400,21.57710
12.80000,1.06664,450.93433,0.01914,1.91446,21.81641
13.00000,1.08333,455.32864,0.01945,1.94489,22.02901
13.20000,1.10001,460.13598,0.01972,1.97228,22.26159
13.40000,1.11675,464.21955,0.02004,2.00405,22.45916
13.60000,1.13325,469.48902,0.02035,2.03452,22.71410
13.80000,1.14993,473.49902,0.02065,2.06530,22.90810
14.00000,1.16673,478.63428,0.02097,2.09678,23.15655
14.20000,1.18329,483.06873,0.02128,2.12848,23.37109
14.40000,1.19998,487.13046,0.02160,2.15971,23.56760
14.60000,1.21672,492.18736,0.02192,2.19194,23.81225
14.80000,1.23334,496.24061,0.02224,2.22406,24.00835
15.00000,1.24996,500.39878,0.02256,2.25573,24.20953
15.20000,1.26670,504.44887,0.02288,2.28752,24.40547
15.40000,1.28344,508.53356,0.02320,2.31983,24.60309
15.60000,1.29994,512.62416,0.02352,2.35216,24.80099
15.80000,1.31662,516.13376,0.02385,2.38462,24.97079
16.00000,1.33343,520.53267,0.02417,2.41748,25.18361
16.20000,1.34993,523.79281,0.02450,2.45025,25.34134
16.40000,1.36667,527.70041,0.02483,2.48293,25.53039
16.60000,1.38341,531.33611,0.02517,2.51655,25.70629
16.80000,1.39997,535.00971,0.02549,2.54905,25.88402
17.00000,1.41659,538.23781,0.02582,2.58195,26.04020
17.20000,1.43333,542.50029,0.02615,2.61533,26.24642
17.40000,1.45001,545.27726,0.02649,2.64939,26.38077
17.60000,1.46664,547.95868,0.02682,2.68225,26.51049
17.80000,1.48320,551.97449,0.02715,2.71544,26.70478
18.00000,1.50006,553.34857,0.02741,2.74087,26.77126
18.20000,1.51656,556.13359,0.02774,2.77418,26.90600
18.40000,1.53336,559.25655,0.02808,2.80760,27.05709
18.60000,1.55004,562.41211,0.02842,2.84181,27.20976
18.80000,1.56666,565.71783,0.02875,2.87543,27.36969
19.00000,1.58335,568.96321,0.02910,2.90999,27.52670
19.20000,1.60003,571.99942,0.02944,2.94392,27.67360
19.40000,1.61665,575.49169,0.02978,2.97823,27.84256
19.60000,1.63333,577.47299,0.03013,3.01260,27.93841
19.80000,1.65001,580.96568,0.03047,3.04715,28.10739
20.00000,1.66663,583.74959,0.03081,3.08139,28.24208
20.20000,1.68325,585.51379,0.03116,3.14788,28.32743
20.34800,1.69569,588.42083,0.03142,3.19763,28.46807
20.54800,1.71231,590.97791,0.03177,3.26411,28.59179
20.74800,1.72899,593.75353,0.03211,3.33084,28.72607
20.94800,1.74561,596.30498,0.03246,3.39732,28.84951
21.14800,1.76236,599.06617,0.03281,3.46429,28.98310
21.34800,1.77892,601.79783,0.03317,3.53053,29.11526
21.54800,1.79566,603.28878,0.03352,3.59750,29.18739
21.74800,1.81246,606.15065,0.03387,3.66470,29.32585
21.94800,1.82902,608.92426,0.03426,3.73095,29.46004
22.14800,1.84564,610.88474,0.03495,3.79743,29.55489
22.34800,1.86238,614.27765,0.02421,3.86440,29.71904
22.54800,1.87900,614.81586,0.00404,3.93088,29.74508
22.74800,1.89563,618.07213,0.00588,3.99737,29.90262
22.94800,1.91237,620.51155,0.00346,4.06433,30.02064
23.14800,1.92905,622.56148,0.00174,4.13106,30.11981
23.34800,1.94561,624.84494,0.00248,4.19731,30.23029
23.54800,1.96235,626.36877,0.00332,4.26427,30.30401
23.74800,1.97909,629.25671,0.00523,4.33123,30.44373
23.94800,1.99571,630.86809,0.00801,4.39772,30.52169
24.14800,2.01233,633.38503,-0.01975,4.46420,30.64346
24.34800,2.02902,635.07147,-0.13479,4.53093,30.72505
24.54800,2.04570,637.77789,-0.13476,4.59766,30.85599
24.74800,2.06232,639.75020,-0.13476,4.66414,30.95141
24.94800,2.07900,641.76391,-0.13476,4.73087,31.04884
25.14800,2.09562,643.54781,-0.13477,4.79735,31.13514
25.34800,2.11224,645.98047,-0.13477,4.86384,31.25283
25.54800,2.12886,647.07529,-0.13477,4.93032,31.30580
25.74800,2.14567,649.51736,-0.13477,4.99753,31.42395
25.94800,2.16235,651.40077,-0.13477,5.06425,31.51507
26.14800,2.17903,653.06867,-0.13477,5.13098,31.59577
26.34800,2.19565,655.36667,-0.13477,5.19746,31.70694
26.54800,2.21233,657.07802,-0.13477,5.26419,31.78974
26.74800,2.22901,658.84613,-0.13477,5.33091,31.87528
26.94800,2.24569,660.76685,-0.13477,5.39764,31.96821
27.14800,2.26237,662.89799,-0.13478,5.46436,32.07131
27.34800,2.27906,664.24441,-0.13478,5.53109,32.13645
27.54800,2.29562,663.94787,-0.13478,5.59734,32.12210
27.74800,2.31230,666.76005,-0.13477,5.66406,32.25816
27.94800,2.32898,668.57622,-0.13478,5.73079,32.34603
28.14800,2.34566,670.00883,-0.13478,5.79751,32.41534
28.34800,2.36234,671.32576,-0.13478,5.86424,32.47905
28.54800,2.37896,673.72774,-0.13478,5.93072,32.59526
28.74800,2.39559,675.88179,-0.13478,5.99721,32.69947
28.94800,2.41233,676.65596,-0.13478,6.06417,32.73693
29.14800,2.42901,679.14319,-0.13478,6.13090,32.85726
29.34800,2.44569,679.90222,-0.13478,6.19762,32.89399
29.54800,2.46237,682.25218,-0.13478,6.26435,33.00768
29.74800,2.47905,683.67142,-0.13476,6.33107,33.07634
29.94800,2.49567,685.27870,-0.13477,6.39756,33.15410
30.14800,2.51229,687.36323,-0.13476,6.46404,33.25495
30.34800,2.52910,688.54378,-0.13476,6.53125,33.31207
30.54800,2.54566,690.46244,-0.13477,6.59749,33.40489
30.74800,2.56222,692.33654,-0.13477,6.66374,33.49556
30.94800,2.57896,693.10544,-0.13477,6.73071,33.53276
31.14800,2.59564,695.13996,-0.13477,6.79743,33.63120
31.34800,2.61232,696.91273,-0.13476,6.86416,33.71696
31.54800,2.62900,698.17393,-0.13477,6.93088,33.77798
31.74800,2.64563,699.51992,-0.13477,6.99737,33.84310
31.94800,2.66225,700.75234,-0.13477,7.06385,33.90273
32.14800,2.67899,702.10942,-0.13476,7.13082,33.96838
32.34800,2.69573,703.73621,-0.13476,7.19778,34.04708
32.54800,2.71241,705.24989,-0.13477,7.26451,34.12032
32.74800,2.72903,705.58647,-0.13477,7.33099,34.13660
32.94800,2.74565,707.66681,-0.13477,7.39748,34.23725
33.14800,2.76233,708.96107,-0.13477,7.46420,34.29987
33.34800,2.77902,710.51344,-0.13477,7.53093,34.37497
33.54800,2.79570,711.95383,-0.13477,7.59765,34.44466
33.74800,2.81232,713.02843,-0.13477,7.66414,34.49665
33.94800,2.82894,714.56493,-0.13477,7.73062,34.57098
34.14800,2.84562,715.56866,-0.13477,7.79735,34.61954
34.34800,2.86230,716.93761,-0.13477,7.86408,34.68578
34.54800,2.87910,717.92095,-0.13477,7.93128,34.73335
34.74800,2.89566,719.48464,-0.13477,7.99753,34.80900
34.94800,2.91241,720.63399,-0.13477,8.06449,34.86460
35.14800,2.92897,721.99283,-0.13477,8.13074,34.93035
35.34800,2.94559,723.55825,-0.13477,8.19722,35.00608
35.54800,2.96245,724.43229,-0.13477,8.26467,35.04837
35.74800,2.97907,725.61200,-0.13477,8.33115,35.10545
35.94800,2.99557,726.39044,-0.13477,8.39716,35.14311
36.14800,3.01231,728.52727,-0.13477,8.46412,35.24649
36.34800,3.02900,729.29584,-0.13477,8.53085,35.28367
36.54800,3.04562,730.52268,-0.13477,8.59733,35.34303
36.74800,3.06236,730.81870,-0.13478,8.66430,35.35735
36.94800,3.07916,733.09247,-0.13477,8.73150,35.46735
37.14800,3.09554,733.86133,-0.13477,8.79703,35.50455
37.34800,3.11234,735.20103,-0.13477,8.86423,35.56937
37.54800,3.12908,735.91536,-0.13477,8.93120,35.60393
37.74800,3.14564,736.81525,-0.13477,8.99744,35.64746
37.94800,3.16227,738.44767,-0.13477,9.06393,35.72644
38.14800,3.17901,739.66538,-0.13477,9.13090,35.78535
38.34800,3.19569,740.47712,-0.13477,9.19762,35.82463
38.54800,3.21225,741.59363,-0.13477,9.26387,35.87864
38.74800,3.22899,742.01454,-0.13477,9.33083,35.89901
38.94800,3.24567,742.62959,-0.13477,9.39756,35.92876
39.14800,3.26229,743.72650,-0.13478,9.46404,35.98183
39.34800,3.27898,745.15524,-0.13477,9.53077,36.05096
39.54800,3.29572,745.90254,-0.13477,9.59773,36.08711
39.74800,3.31228,747.36774,-0.13477,9.66398,36.15800
39.94800,3.32902,748.47699,-0.13478,9.73094,36.21166
40.14800,3.34570,749.11863,-0.13478,9.79767,36.24271
40.34800,3.36238,750.17801,-0.13477,9.86439,36.29396
40.54800,3.37894,750.84618,-0.13477,9.93064,36.32629
40.74800,3.39562,752.36363,-0.13477,9.99736,36.39970
40.94800,3.41237,753.09239,-0.13478,10.06433,36.43496
41.14800,3.42899,754.26130,-0.13477,10.13081,36.49151
41.34800,3.44561,752.96946,-0.13478,10.19730,36.42901
41.54800,3.46235,754.02679,-0.13478,10.26426,36.48017
41.74800,3.47897,755.65185,-0.13478,10.33075,36.55879
41.94800,3.49565,757.01713,-0.13477,10.39748,36.62484
42.14800,3.51239,757.55361,-0.13477,10.46444,36.65079
42.34800,3.52901,758.79605,-0.13478,10.53093,36.71090
42.54800,3.54564,759.76900,-0.13478,10.59741,36.75798
42.74800,3.56232,760.49371,-0.13478,10.66414,36.79304
42.94800,3.57906,761.60505,-0.13478,10.73110,36.84681
43.14800,3.59556,762.39267,-0.13477,10.79711,36.88491
43.34800,3.61236,763.10965,-0.13478,10.86431,36.91960
43.54800,3.62904,764.59209,-0.13478,10.93104,36.99132
43.74800,3.64554,765.80262,-0.13478,10.99705,37.04988
43.94800,3.66235,765.67684,-0.13477,11.06425,37.04380
44.14800,3.67915,766.61571,-0.13478,11.13145,37.08922
44.34800,3.69565,766.75583,-0.13478,11.19746,37.09600
44.54800,3.71227,768.41097,-0.13478,11.26395,37.17608
44.74800,3.72907,769.44199,-0.13478,11.33115,37.22596
44.94800,3.74575,769.54085,-0.13478,11.39787,37.23074
45.14800,3.76225,771.18329,-0.13477,11.46388,37.31020
45.34800,3.77905,772.23857,-0.13478,11.53108,37.36126
45.54800,3.79568,772.05384,-0.13478,11.59757,37.35232
45.74800,3.81230,773.13227,-0.13478,11.66406,37.40450
45.94800,3.82898,773.34153,-0.13477,11.73078,37.41462
46.14800,3.84572,773.97521,-0.13478,11.79775,37.44528
46.34800,3.86228,775.13517,-0.13478,11.86399,37.50140
46.54800,3.87902,775.86886,-0.13478,11.93096,37.53690
46.74800,3.89564,776.60792,-0.13478,11.99744,37.57265
46.94800,3.91233,777.25872,-0.13477,12.06417,37.60414
47.14800,3.92895,777.99880,-0.13478,12.13065,37.63994
47.34800,3.94569,778.71713,-0.13478,12.19762,37.67470
47.54800,3.96237,779.39588,-0.13478,12.26434,37.70753
47.74800,3.97893,780.42848,-0.13478,12.33059,37.75749
47.94800,3.99561,780.93475,-0.13478,12.39731,37.78199
48.14800,4.01235,781.53098,-0.13478,12.46428,37.81083
48.34800,4.02897,782.10272,-0.13478,12.53076,37.83849
48.54800,4.04560,783.29509,-0.13478,12.59725,37.89618
48.74800,4.06240,783.80201,-0.13478,12.66445,37.92070
48.94800,4.07902,784.09081,-0.13478,12.73094,37.93468
49.14800,4.09558,785.21706,-0.13478,12.79719,37.98917
49.34800,4.11232,784.54576,-0.13478,12.86415,37.95669
49.54800,4.12900,785.60729,-0.13478,12.93088,38.00805
49.74800,4.14562,786.43728,-0.13478,12.99736,38.04820
49.94800,4.16230,786.75561,-0.13478,13.06409,38.06360
50.14800,4.17905,788.01410,-0.13478,13.13105,38.12449
50.34800,4.19555,788.62766,-0.13478,13.19706,38.15417
50.54800,4.21235,788.85360,-0.13478,13.26426,38.16510
50.74800,4.22915,790.00443,-0.13478,13.33147,38.22078
50.94800,4.24565,790.25403,-0.13478,13.39747,38.23286
51.14800,4.26227,790.70684,-0.13478,13.46396,38.25476
51.34800,4.27907,791.64989,-0.13478,13.53116,38.30039
51.54800,4.29570,791.92910,-0.13478,13.59765,38.31390
51.74800,4.31232,792.65647,-0.13478,13.66413,38.34909
51.94800,4.32900,792.72864,-0.13478,13.73086,38.35258
52.14800,4.34568,793.48059,-0.13478,13.79759,38.38896
52.34800,4.36230,793.80274,-0.13478,13.86407,38.40454
52.54800,4.37898,794.67492,-0.13478,13.93080,38.44674
52.74800,4.39572,794.98924,-0.13478,13.99776,38.46195
52.94800,4.41234,795.67600,-0.13478,14.06424,38.49517
53.14800,4.42897,795.94022,-0.13478,14.13073,38.50796
53.34800,4.44571,796.67810,-0.13477,14.19770,38.54366
53.54800,4.46233,797.04178,-0.13478,14.26418,38.56125
53.74800,4.47901,797.19108,-0.13478,14.33091,38.56847
53.94800,4.49563,797.93343,-0.13478,14.39739,38.60439
54.14800,4.51231,798.85172,-0.13478,14.46412,38.64882
54.34800,4.52893,798.48096,-0.13478,14.53060,38.63088
54.54800,4.54562,799.03686,-0.13478,14.59733,38.65778
54.74800,4.56230,799.68544,-0.13478,14.66405,38.68915
54.94800,4.57904,799.91249,-0.13478,14.73102,38.70014
55.14800,4.59572,800.39809,-0.13478,14.79774,38.72363
55.34800,4.61234,801.49155,-0.13478,14.86423,38.77653
55.54800,4.62896,801.12331,-0.13478,14.93072,38.75872
55.74800,4.64570,802.52225,-0.13478,14.99768,38.82640
55.94800,4.66232,802.25049,-0.13478,15.06416,38.81325
56.14800,4.67913,802.82642,-0.13478,15.13137,38.84111
56.34800,4.69569,803.54642,-0.13478,15.19762,38.87595
56.54800,4.71225,803.49278,-0.13478,15.26386,38.87335
56.74800,4.72905,804.30983,-0.13478,15.33106,38.91288
56.94800,4.74561,804.14386,-0.13478,15.39731,38.90485
57.14800,4.76229,805.15509,-0.13478,15.46404,38.95378
57.34800,4.77903,804.93595,-0.13478,15.53100,38.94318
57.54800,4.79560,805.51598,-0.13478,15.59725,38.97124
57.74800,4.81228,806.37699,-0.13478,15.66397,39.01289
57.94800,4.82902,806.57834,-0.13478,15.73094,39.02263
58.14800,4.84576,806.89704,-0.13478,15.79790,39.03805
58.34800,4.86232,806.99809,-0.13478,15.86415,39.04294
58.54800,4.87900,807.07669,-0.13478,15.93087,39.04675
58.74800,4.89568,807.79102,-0.13478,15.99760,39.08130
58.94800,4.91224,808.10999,-0.13478,16.06385,39.09674
59.14800,4.92899,808.67996,-0.13478,16.13081,39.12431
59.34800,4.94573,808.51186,-0.13478,16.19777,39.11618
59.54800,4.96229,809.46777,-0.13478,16.26402,39.16243
59.74800,4.97891,809.60449,-0.13478,16.33051,39.16904
59.94800,4.99565,810.04957,-0.13478,16.39747,39.19057
60.14800,5.01233,810.42340,-0.13478,16.46419,39.20866
60.34800,5.02907,810.35867,-0.13478,16.53116,39.20553
60.54800,5.04564,810.41595,-0.13478,16.59741,39.20830
60.74800,5.06238,811.41843,-0.13478,16.66437,39.25680
60.94800,5.07900,811.16613,-0.13478,16.73086,39.24459
61.14800,5.09562,812.25047,-0.13478,16.79734,39.29705
61.34800,5.11236,811.34085,-0.13478,16.86431,39.25305
61.54800,5.12892,812.44679,-0.13478,16.93055,39.30655
61.74800,5.14560,812.84009,-0.13478,16.99728,39.32558
61.94800,5.16234,812.54505,-0.13478,17.06424,39.31131
62.14800,5.17903,813.02654,-0.13478,17.13097,39.33460
62.34800,5.19565,813.31823,-0.13478,17.19745,39.34871
62.54800,5.21233,813.47758,-0.13478,17.26418,39.35642
62.74800,5.22895,813.92135,-0.13478,17.33066,39.37789
62.94800,5.24563,814.30878,-0.13478,17.39739,39.39664
63.14800,5.26231,814.17440,-0.13478,17.46412,39.39014
63.34800,5.27905,814.62124,-0.13478,17.53108,39.41175
63.54800,5.29567,815.71974,-0.13478,17.59757,39.46490
63.74800,5.31236,814.66017,-0.13478,17.66429,39.41364
63.94800,5.32898,815.54409,-0.13478,17.73077,39.45640
64.14800,5.34560,815.82600,-0.13478,17.79726,39.47004
64.34800,5.36234,816.19257,-0.13478,17.86423,39.48777
64.54800,5.37908,816.33339,-0.13478,17.93119,39.49459
64.74800,5.39564,816.34177,-0.13478,17.99744,39.49500
64.94800,5.41232,817.00636,-0.13478,18.06416,39.52715
65.14800,5.42895,816.97507,-0.13478,18.13065,39.52563
65.34800,5.44563,817.04929,-0.13478,18.19737,39.52922
65.54801,5.46231,817.33642,-0.13478,18.26410,39.54311
65.74800,5.47905,817.51728,-0.13478,18.33106,39.55186
65.94801,5.49573,817.57950,-0.13478,18.39779,39.55487
66.14800,5.51223,817.40422,-0.13478,18.46379,39.54639
66.34800,5.52897,817.69805,-0.13478,18.53076,39.56061
66.54801,5.54577,818.48381,-0.13478,18.59796,39.59863
66.74800,5.56240,818.47245,-0.13478,18.66445,39.59808
66.94801,5.57896,818.94277,-0.13478,18.73070,39.62083
67.14800,5.59570,818.70835,-0.13478,18.79766,39.60949
67.34800,5.61232,819.46021,-0.13478,18.86415,39.64587
67.54801,5.62900,819.38254,-0.13478,18.93087,39.64211
67.74800,5.64562,819.44466,-0.13478,18.99736,39.64511
67.94801,5.66236,819.35255,-0.13478,19.06432,39.64066
68.14800,5.67893,819.81448,-0.13478,19.13057,39.66301
68.34800,5.69561,820.26441,-0.13478,19.19729,39.68477
68.54801,5.71235,820.33090,-0.13478,19.26426,39.68799
68.74800,5.72897,820.39256,-0.13478,19.33074,39.69097
68.94801,5.74571,820.81668,-0.13478,19.39771,39.71149
69.14800,5.76239,820.49454,-0.13478,19.46443,39.69591
69.34800,5.77901,820.83689,-0.13478,19.53092,39.71247
69.54801,5.79563,820.70595,-0.13478,19.59741,39.70613
69.74800,5.81232,820.50869,-0.13478,19.66413,39.69659
69.94801,5.82906,820.67475,-0.13478,19.73110,39.70462
70.14800,5.84562,821.25748,-0.13478,19.79734,39.73282
70.34800,5.86224,821.56081,-0.13478,19.86383,39.74749
70.54801,5.87904,820.93440,-0.13478,19.93103,39.71719
70.74800,5.89566,821.64304,-0.13478,19.99752,39.75147
70.94801,5.91234,821.58800,-0.13478,20.06424,39.74881
71.14800,5.92902,821.74400,-0.13478,20.13097,39.75636
71.34801,5.94565,822.28892,-0.13478,20.19745,39.78272
71.54801,5.96233,822.31835,-0.13478,20.26417,39.78414
71.74800,5.97907,822.77292,-0.13478,20.33114,39.80614
71.94801,5.99575,822.67644,-0.13478,20.39787,39.80147
72.14800,6.01231,821.71643,-0.13478,20.46411,39.75502
72.34801,6.02899,822.34992,-0.13478,20.53084,39.78567
72.54801,6.04573,822.54484,-0.13478,20.59780,39.79510
72.74800,6.06230,822.80627,-0.13478,20.66405,39.80775
72.94801,6.07892,822.39285,-0.13478,20.73053,39.78775
73.14800,6.09572,822.50098,-0.13478,20.79774,39.79298
73.34801,6.11234,822.87053,-0.13478,20.86422,39.81086
73.54801,6.12896,823.25935,-0.13478,20.93071,39.82967
73.74800,6.14570,823.28059,-0.13478,20.99767,39.83070
73.94801,6.16238,823.03453,-0.13479,21.06440,39.81879
74.14800,6.17900,823.37279,-0.13478,21.13088,39.83516
74.34801,6.19569,823.56315,-0.13478,21.19761,39.84437
74.54801,6.21237,823.10876,-0.13478,21.26434,39.82238
74.74800,6.22893,823.71198,-0.13478,21.33058,39.85157
74.94801,6.24561,822.77805,-0.13478,21.39731,39.80639
75.14800,6.26235,823.13335,-0.13478,21.46427,39.82357
75.34801,6.27903,822.89176,-0.13478,21.53100,39.81189
75.54801,6.29559,821.69222,-0.13478,21.59724,39.75385
75.74800,6.31234,822.76929,-0.13478,21.66421,39.80596
75.94801,6.32896,822.60938,-0.13478,21.73069,39.79823
76.14800,6.34564,822.71323,-0.13478,21.79742,39.80325
76.34801,6.36238,822.74796,-0.13478,21.86438,39.80493
76.54801,6.37912,823.27407,-0.13478,21.93135,39.83038
76.74800,6.39556,822.95267,-0.13478,21.99712,39.81483
76.94801,6.41230,823.06154,-0.13478,22.06408,39.82010
77.14800,6.42910,823.17619,-0.13478,22.13128,39.82565
77.34801,6.44561,822.96105,-0.13478,22.19729,39.81524
77.54801,6.46235,823.70210,-0.13478,22.26426,39.85109
77.74800,6.47903,823.48166,-0.13479,22.33098,39.84042
77.94801,6.49565,823.29735,-0.13478,22.39746,39.83151
78.14800,6.51227,823.76292,-0.13478,22.46395,39.85403
78.34801,6.52895,823.34885,-0.13478,22.53068,39.83400
78.54801,6.54575,823.91808,-0.13478,22.59788,39.86154
78.74800,6.56232,823.73833,-0.13479,22.66413,39.85284
78.94801,6.57900,823.57069,-0.13478,22.73085,39.84473
79.14800,6.59580,824.13545,-0.13478,22.79805,39.87206
79.34801,6.61224,824.24646,-0.13478,22.86382,39.87743
79.54801,6.62898,823.70918,-0.13478,22.93079,39.85143
79.74800,6.64578,824.05107,-0.13478,22.99799,39.86797
79.94801,6.66234,824.01773,-0.13478,23.06424,39.86636
80.14800,6.67890,824.18993,-0.13478,23.13049,39.87469
80.34801,6.69571,823.56120,-0.13479,23.19769,39.84427
80.54801,6.71239,824.31119,-0.13478,23.26441,39.88056
80.74800,6.72895,823.91240,-0.13478,23.33066,39.86126
80.94801,6.74563,823.40520,-0.13478,23.39739,39.83673
81.14800,6.76237,824.16628,-0.13478,23.46435,39.87355
81.34801,6.77887,824.11217,-0.13478,23.53036,39.87093
81.54801,6.79567,823.75444,-0.13478,23.59756,39.85362
81.74800,6.81247,823.96222,-0.13479,23.66476,39.86367
81.94801,6.82898,824.61648,-0.13478,23.73077,39.89533
82.14800,6.84560,823.83063,-0.13478,23.79726,39.85731
82.34801,6.86234,823.67482,-0.13478,23.86422,39.84977
82.54801,6.87902,823.27565,-0.13478,23.93095,39.83046
82.74800,6.89564,823.72865,-0.13478,23.99743,39.85238
82.94801,6.91238,823.14592,-0.13478,24.06440,39.82418
83.14800,6.92900,824.07864,-0.13478,24.13088,39.86931
83.34801,6.94557,823.54285,-0.13478,24.19713,39.84338
83.54801,6.96225,823.28031,-0.13478,24.26385,39.83068
83.74800,6.97899,823.82355,-0.13479,24.33082,39.85696
83.94801,6.99567,823.96297,-0.13478,24.39754,39.86371
84.14800,7.01241,823.57852,-0.13478,24.46451,39.84511
84.34801,7.02897,823.09190,-0.13478,24.53075,39.82157
84.54801,7.04565,823.31020,-0.13478,24.59748,39.83213
84.74800,7.06233,823.51370,-0.13478,24.66421,39.84198
84.94801,7.07908,822.71062,-0.13478,24.73117,39.80312
85.14800,7.09576,823.18243,-0.13478,24.79790,39.82595
85.34801,7.11226,823.22136,-0.13478,24.86390,39.82783
85.54801,7.12894,822.13506,-0.13478,24.93063,39.77528
85.74800,7.14568,822.96543,-0.13479,24.99759,39.81545
85.94801,7.16230,822.98182,-0.13478,25.06408,39.81624
86.14800,7.17898,822.68789,-0.13478,25.13080,39.80202
86.34801,7.19567,822.89819,-0.13478,25.19753,39.81219
86.54801,7.21229,822.56561,-0.13478,25.26402,39.79610
86.74800,7.22891,822.94578,-0.13479,25.33050,39.81450
86.94801,7.24571,822.03289,-0.13478,25.39770,39.77033
87.14800,7.26245,822.25157,-0.13478,25.46467,39.78091
87.34801,7.27895,821.94023,-0.13478,25.53067,39.76585
87.54801,7.29563,822.21478,-0.13478,25.59740,39.77913
87.74800,7.31237,821.83313,-0.13479,25.66437,39.76067
87.94801,7.32900,821.64304,-0.13478,25.73085,39.75147
88.14800,7.34562,822.45283,-0.13478,25.79734,39.79065
88.34801,7.36236,822.45972,-0.13478,25.86430,39.79098
88.54801,7.37892,821.65264,-0.13478,25.93054,39.75193
88.74800,7.39560,822.00179,-0.13478,25.99727,39.76883
88.94801,7.41228,821.66828,-0.13478,26.06400,39.75269
89.14800,7.42902,821.31410,-0.13478,26.13096,39.73556
89.34801,7.44571,820.74925,-0.13478,26.19769,39.70823
89.54801,7.46239,820.31852,-0.13478,26.26441,39.68739
89.74800,7.47901,821.16323,-0.13479,26.33090,39.72826
89.94801,7.49569,820.46660,-0.13478,26.39762,39.69455
90.14800,7.51237,820.92537,-0.13478,26.46435,39.71675
90.34801,7.52911,820.99745,-0.13479,26.53131,39.72024
90.54801,7.54567,820.64588,-0.13478,26.59756,39.70323
90.74800,7.56235,820.54082,-0.13478,26.66428,39.69815
90.94801,7.57898,820.34580,-0.13478,26.73077,39.68871
91.14800,7.59566,819.76419,-0.13478,26.79749,39.66057
91.34801,7.61240,820.24587,-0.13479,26.86446,39.68388
91.54801,7.62896,820.15889,-0.13478,26.93070,39.67967
91.74800,7.64564,819.17802,-0.13478,26.99743,39.63221
91.94801,7.66232,819.29173,-0.13478,27.06416,39.63771
92.14800,7.67894,819.58761,-0.13478,27.13064,39.65203
92.34801,7.69574,819.20829,-0.13479,27.19784,39.63368
92.54801,7.71237,819.18472,-0.13478,27.26433,39.63254
92.74800,7.72899,818.86016,-0.13478,27.33082,39.61683
92.94801,7.74573,819.05806,-0.13479,27.39778,39.62641
93.14800,7.76229,818.36870,-0.13478,27.46403,39.59306
93.34801,7.77897,818.55906,-0.13478,27.53075,39.60227
93.54801,7.79565,818.30621,-0.13478,27.59748,39.59003
93.74800,7.81233,818.39133,-0.13478,27.66420,39.59415
93.94801,7.82889,818.56539,-0.13478,27.73045,39.60257
94.14800,7.84564,818.03994,-0.13478,27.79741,39.57715
94.34801,7.86238,817.61405,-0.13478,27.86438,39.55655
94.54801,7.87900,817.76204,-0.13478,27.93086,39.56371
94.74800,7.89568,817.99915,-0.13478,27.99759,39.57518
94.94801,7.91242,817.25419,-0.13478,28.06455,39.53913
95.14800,7.92892,816.53688,-0.13478,28.13056,39.50443
95.34801,7.94566,816.68971,-0.13478,28.19752,39.51183
95.54801,7.96241,816.45753,-0.13478,28.26449,39.50060
95.74800,7.97903,816.36244,-0.13478,28.33097,39.49599
95.94801,7.99571,816.22200,-0.13478,28.39770,39.48920
96.14800,8.01227,816.03145,-0.13478,28.46394,39.47998
96.34801,8.02901,815.91606,-0.13479,28.53091,39.47440
96.54801,8.04563,816.14992,-0.13478,28.59740,39.48571
96.74800,8.06225,816.04347,-0.13479,28.66388,39.48056
96.94801,8.07900,815.89753,-0.13479,28.73085,39.47350
97.14800,8.09562,815.67895,-0.13478,28.79733,39.46292
97.34801,8.11224,815.10590,-0.13479,28.86382,39.43520
97.54801,8.12904,814.53109,-0.13478,28.93102,39.40739
97.74800,8.14566,814.79903,-0.13479,28.99751,39.42036
97.94801,8.16240,814.46040,-0.13478,29.06447,39.40397
98.14800,8.17896,813.89314,-0.13478,29.13072,39.37653
98.34801,8.19570,813.94603,-0.13478,29.19768,39.37909
98.54801,8.21233,813.94315,-0.13479,29.26417,39.37895
98.74800,8.22901,813.34272,-0.13478,29.33089,39.34990
98.94801,8.24569,813.25928,-0.13478,29.39762,39.34586
99.14800,8.26231,812.67701,-0.13479,29.46410,39.31769
99.34801,8.27893,812.37601,-0.13478,29.53059,39.30313
99.54801,8.29561,811.73740,-0.13478,29.59732,39.27223
99.74800,8.31229,812.10462,-0.13478,29.66404,39.29000
99.94801,8.32903,811.63216,-0.13478,29.73101,39.26714
100.14800,8.34566,811.38192,-0.13478,29.79749,39.25504
100.34801,8.36234,810.98834,-0.13478,29.86422,39.23599
100.54801,8.37896,810.97642,-0.13478,29.93070,39.23542
100.74800,8.39564,811.41591,-0.13478,29.99743,39.25668
100.94801,8.41250,810.97325,-0.13479,30.06487,39.23526
101.14800,8.42894,809.72407,-0.13478,30.13064,39.17483
101.34801,8.44562,810.17520,-0.13479,30.19736,39.19665
101.54801,8.46243,809.97115,-0.13478,30.26457,39.18678
101.74800,8.47899,809.73646,-0.13478,30.33082,39.17543
101.94801,8.49561,809.37222,-0.13478,30.39730,39.15780
102.14800,8.51235,809.27145,-0.13478,30.46426,39.15293
102.34801,8.52903,808.19661,-0.13478,30.53099,39.10093
102.54801,8.54565,808.13086,-0.13478,30.59748,39.09774
102.74800,8.56233,808.35167,-0.13478,30.66420,39.10843
102.94801,8.57907,807.85546,-0.13478,30.73117,39.08442
103.14800,8.59564,807.86217,-0.13478,30.79741,39.08475
103.34801,8.61238,807.43041,-0.13478,30.86437,39.06386
103.54801,8.62906,807.28242,-0.13479,30.93110,39.05670
103.74801,8.64562,806.62146,-0.13478,30.99735,39.02472
103.94801,8.66236,806.70584,-0.13478,31.06431,39.02880
104.14800,8.67898,805.83021,-0.13478,31.13080,38.98644
104.34801,8.69566,805.72134,-0.13478,31.19752,38.98117
104.54801,8.71229,805.83189,-0.13478,31.26401,38.98652
104.74801,8.72891,805.19281,-0.13478,31.33049,38.95560
104.94801,8.74571,804.62862,-0.13479,31.39770,38.92831
105.14800,8.76233,804.28552,-0.13479,31.46418,38.91171
105.34801,8.77901,803.98982,-0.13479,31.53091,38.89740
105.54801,8.79575,804.00733,-0.13478,31.59787,38.89825
105.74801,8.81231,803.18535,-0.13479,31.66412,38.85848
105.94801,8.82893,802.99387,-0.13478,31.73060,38.84922
106.14800,8.84568,802.82297,-0.13479,31.79757,38.84095
106.34801,8.86236,802.44681,-0.13479,31.86429,38.82275
106.54801,8.87898,802.03116,-0.13478,31.93078,38.80264
106.74801,8.89566,801.87088,-0.13478,31.99750,38.79488
106.94801,8.91234,801.50682,-0.13479,32.06423,38.77727
107.14800,8.92884,800.45722,-0.13478,32.13024,38.72649
107.34801,8.94564,800.82696,-0.13479,32.19744,38.74438
107.54801,8.96244,799.60749,-0.13478,32.26465,38.68538
107.74801,8.97895,799.62509,-0.13478,32.33065,38.68623
107.94801,8.99563,799.13521,-0.13478,32.39738,38.66253
108.14800,9.01243,799.36991,-0.13478,32.46458,38.67389
108.34801,9.02893,798.86029,-0.13478,32.53059,38.64923
108.54801,9.04567,797.98223,-0.13478,32.59755,38.60675
108.74801,9.06247,798.03932,-0.13478,32.66476,38.60951
108.94801,9.07897,797.06879,-0.13479,32.73076,38.56256
109.14800,9.09560,796.98423,-0.13478,32.79725,38.55847
109.34801,9.11234,796.25286,-0.13479,32.86421,38.52308
109.54801,9.12908,795.70552,-0.13479,32.93118,38.49660
109.74801,9.14558,795.55325,-0.13479,32.99719,38.48923
109.94801,9.16226,795.32927,-0.13479,33.06391,38.47840
110.14800,9.17906,795.01988,-0.13479,33.13112,38.46343
110.34801,9.19562,794.04227,-0.13479,33.19736,38.41613
110.54801,9.21230,793.34676,-0.13479,33.26409,38.38248
110.74801,9.22911,793.58108,-0.13479,33.33129,38.39382
110.94801,9.24561,792.35854,-0.13478,33.39730,38.33467
111.14800,9.26229,792.19509,-0.13478,33.46402,38.32677
111.34801,9.27897,791.76584,-0.13478,33.53074,38.30600
111.54801,9.29565,791.81213,-0.13479,33.59747,38.30824
111.74801,9.31227,790.89515,-0.13478,33.66396,38.26387
111.94801,9.32895,790.23065,-0.13478,33.73068,38.23172
112.14800,9.34570,789.88094,-0.13478,33.79765,38.21481
112.34801,9.36226,788.94524,-0.13478,33.86389,38.16954
112.54801,9.37894,788.22719,-0.13478,33.93062,38.13480
112.74801,9.39568,788.26956,-0.13478,33.99759,38.13685
112.94801,9.41236,787.20944,-0.13479,34.06431,38.08556
113.14800,9.42898,787.04068,-0.13479,34.13079,38.07739
113.34801,9.44572,786.38922,-0.13478,34.19776,38.04588
113.54801,9.46234,785.51387,-0.13478,34.26424,38.00352
113.74801,9.47897,785.09543,-0.13479,34.33073,37.98328
113.94801,9.49571,785.01431,-0.13479,34.39769,37.97935
114.14800,9.51239,784.30390,-0.13478,34.46442,37.94499
114.34801,9.52889,783.71279,-0.13478,34.53043,37.91639
114.54801,9.54563,782.65416,-0.13478,34.59739,37.86517
114.74801,9.56237,782.33555,-0.13479,34.66436,37.84976
114.94801,9.57899,782.20535,-0.13479,34.73084,37.84346
115.14800,9.59562,781.00320,-0.13478,34.79733,37.78530
115.34801,9.61236,780.71607,-0.13478,34.86429,37.77140
115.54801,9.62898,779.98419,-0.13479,34.93078,37.73600
115.74801,9.64560,779.08086,-0.13478,34.99727,37.69230
115.94801,9.66234,778.50264,-0.13479,35.06423,37.66432
116.14800,9.67908,778.02944,-0.13478,35.13119,37.64143
116.34801,9.69558,777.51060,-0.13478,35.19720,37.61633
116.54801,9.71226,776.43748,-0.13478,35.26393,37.56441
116.74801,9.72907,775.51049,-0.13479,35.33113,37.51956
116.94801,9.74563,775.13806,-0.13478,35.39738,37.50154
117.14800,9.76237,774.58830,-0.13479,35.46434,37.47494
117.34801,9.77905,774.11798,-0.13479,35.53106,37.45219
117.54801,9.79561,773.59020,-0.13479,35.59731,37.42665
117.74801,9.81223,772.19200,-0.13479,35.66380,37.35901
117.94801,9.82897,772.13803,-0.13478,35.73076,37.35640
118.14800,9.84572,770.47194,-0.13479,35.79773,37.27579
118.34801,9.86234,769.96405,-0.13479,35.86421,37.25122
118.54801,9.87890,768.95612,-0.13478,35.93046,37.20245
118.74801,9.89570,768.01963,-0.13478,35.99766,37.15715
118.94801,9.91232,767.22028,-0.13479,36.06414,37.11847
119.14800,9.92906,766.80100,-0.13479,36.13111,37.09819
119.34801,9.94574,766.15452,-0.13479,36.19784,37.06691
119.54801,9.96236,765.18552,-0.13479,36.26432,37.02003
119.74801,9.97899,763.96121,-0.13479,36.33081,36.96080
119.94801,9.99561,763.61308,-0.13478,36.39729,36.94395
120.14800,10.01229,762.51756,-0.13478,36.46402,36.89095
120.34801,10.02897,761.58359,-0.13478,36.53074,36.84577
120.54801,10.04565,761.00617,-0.13479,36.59747,36.81783
120.74801,10.06233,760.00146,-0.13478,36.66419,36.76922
120.94801,10.07895,759.07796,-0.13478,36.73068,36.72454
121.14800,10.09564,758.49518,-0.13479,36.79741,36.69635
121.34801,10.11244,757.09494,-0.13479,36.86461,36.62860
121.54801,10.12900,756.32581,-0.13479,36.93085,36.59139
121.74801,10.14568,755.34512,-0.13478,36.99758,36.54395
121.94801,10.16236,754.33599,-0.13479,37.06431,36.49512
122.14800,10.17898,754.28686,-0.13479,37.13079,36.49275
122.34801,10.19560,753.03605,-0.13478,37.19728,36.43223
122.54801,10.21234,751.92200,-0.13478,37.26424,36.37833
122.74801,10.22902,750.71328,-0.13479,37.33096,36.31986
122.94801,10.24559,749.86294,-0.13479,37.39721,36.27872
123.14800,10.26227,748.74577,-0.13479,37.46394,36.22467
123.34801,10.27907,748.21040,-0.13478,37.53114,36.19876
123.54801,10.29569,746.71851,-0.13479,37.59763,36.12659
123.74801,10.31231,745.80056,-0.13478,37.66412,36.08218
123.94801,10.32899,744.31133,-0.13478,37.73084,36.01013
124.14800,10.34561,744.03184,-0.13479,37.79732,35.99660
124.34801,10.36236,742.24984,-0.13479,37.86429,35.91039
124.54801,10.37904,741.22441,-0.13478,37.93101,35.86078
124.74801,10.39572,738.98961,-0.13478,37.99774,35.75266
124.94801,10.41228,738.10485,-0.13479,38.06399,35.70985
125.14800,10.42890,736.27522,-0.13479,38.13047,35.62134
125.34801,10.44564,734.27130,-0.13479,38.19743,35.52439
125.54801,10.46232,731.98387,-0.13478,38.26416,35.41372
125.74801,10.47906,728.04317,-0.13478,38.33112,35.22306
125.94801,10.49569,722.27982,-0.13479,38.39761,34.94423
126.14800,10.51231,709.91316,-0.13479,38.46410,34.34593
126.25601,10.52140,3.90653,-0.13478,38.50045,0.18900