File: Manufatura Aditiva/Classificação Orientação/Ensaios/Ensaios SLS/Tracao_OLABI_07_06_2018_SLS_XZ2.is_metal_RawData/Specimen_RawData_5.csv
Time,Extension,Load,Strain 1,Tensile strain,Tensile stress
(sec),(mm),(N),(mm/mm),(%),(MPa)
0.00000,0.00006,13.25304,0.00059,0.05926,0.65459
0.20000,0.01381,19.20892,0.00079,0.07861,0.94876
0.40000,0.03270,29.28919,0.00111,0.11139,1.44664
0.60000,0.04986,38.12377,0.00141,0.14097,1.88299
0.80000,0.06673,46.50621,0.00169,0.16919,2.29701
1.00000,0.08335,54.11331,0.00197,0.19715,2.67274
1.20000,0.10003,63.28254,0.00226,0.22573,3.12562
1.40000,0.11683,70.63058,0.00254,0.25444,3.48855
1.60000,0.13339,78.46273,0.00282,0.28187,3.87539
1.80000,0.14995,86.31330,0.00310,0.31004,4.26314
2.00000,0.16657,93.91402,0.00338,0.33837,4.63855
2.20000,0.18331,101.75894,0.00367,0.36657,5.02603
2.40000,0.19994,109.52204,0.00395,0.39501,5.40946
2.60000,0.21668,116.13305,0.00422,0.42191,5.73599
2.80000,0.23336,121.55243,0.00444,0.44404,6.00366
3.00000,0.24998,129.23853,0.00472,0.47161,6.38328
3.20000,0.26672,137.06739,0.00500,0.50039,6.76996
3.40000,0.28340,144.83158,0.00529,0.52865,7.15345
3.60000,0.30002,151.56229,0.00556,0.55588,7.48589
3.80000,0.31665,158.18798,0.00583,0.58345,7.81314
4.00000,0.33327,165.70231,0.00612,0.61174,8.18429
4.20000,0.34995,172.42135,0.00640,0.63987,8.51615
4.40000,0.36663,179.79419,0.00668,0.66762,8.88030
4.60000,0.38331,186.04799,0.00695,0.69549,9.18919
4.80000,0.39999,193.44265,0.00723,0.72346,9.55442
5.00000,0.41661,200.60309,0.00751,0.75119,9.90809
5.20000,0.43335,207.22030,0.00779,0.77908,10.23492
5.40000,0.45010,215.24541,0.00807,0.80741,10.63129
5.60000,0.46672,221.53934,0.00835,0.83452,10.94216
5.80000,0.48334,225.84724,0.00856,0.85575,11.15493
6.00000,0.50002,232.64952,0.00884,0.88433,11.49091
6.20000,0.51664,239.87272,0.00912,0.91224,11.84767
6.40000,0.53326,246.54595,0.00940,0.94015,12.17727
6.60000,0.55000,252.50581,0.00968,0.96763,12.47164
6.80000,0.56674,259.74002,0.00995,0.99547,12.82895
7.00000,0.58331,266.01092,0.01024,1.02382,13.13868
7.20000,0.59993,272.33283,0.01052,1.05167,13.45093
7.40000,0.61673,279.56262,0.01079,1.07919,13.80802
7.60000,0.63329,284.94329,0.01107,1.10708,14.07378
7.80000,0.64997,291.63349,0.01135,1.13531,14.40421
8.00000,0.66671,297.64234,0.01164,1.16356,14.70100
8.20000,0.68333,301.95275,0.01185,1.18542,14.91390
8.40000,0.70002,308.22014,0.01213,1.21333,15.22345
8.60000,0.71664,315.17490,0.01242,1.24152,15.56696
8.80000,0.73338,320.34332,0.01269,1.26947,15.82224
9.00000,0.75000,326.11908,0.01297,1.29733,16.10751
9.20000,0.76662,332.45683,0.01326,1.32577,16.42054
9.40000,0.78336,338.63750,0.01354,1.35389,16.72581
9.60000,0.79992,343.81843,0.01382,1.38152,16.98171
9.80000,0.81660,349.49628,0.01409,1.40930,17.26214
10.00000,0.83341,354.16253,0.01437,1.43736,17.49262
10.20000,0.84991,358.52666,0.01460,1.45989,17.70817
10.40000,0.86671,364.31756,0.01488,1.48816,17.99419
10.60000,0.88333,369.50503,0.01516,1.51592,18.25041
10.80000,0.90007,374.78670,0.01545,1.54487,18.51128
11.00000,0.91669,379.98743,0.01573,1.57304,18.76815
11.20000,0.93331,385.01271,0.01601,1.60130,19.01635
11.40000,0.95000,389.86600,0.01629,1.62923,19.25607
11.60000,0.96656,396.00348,0.01658,1.65822,19.55920
11.80000,0.98330,398.64220,0.01681,1.68142,19.68954
12.00000,1.00010,403.76438,0.01710,1.70979,19.94253
12.20000,1.01666,408.55482,0.01738,1.73826,20.17913
12.40000,1.03328,413.44315,0.01767,1.76701,20.42058
12.60000,1.04996,418.32207,0.01796,1.79561,20.66155
12.80000,1.06664,423.29468,0.01824,1.82440,20.90716
13.00000,1.08339,427.70458,0.01853,1.85346,21.12497
13.20000,1.10001,430.75392,0.01878,1.87779,21.27558
13.40000,1.11675,435.23889,0.01906,1.90640,21.49710
13.60000,1.13325,440.28829,0.01936,1.93567,21.74650
13.80000,1.14993,444.54155,0.01965,1.96539,21.95657
14.00000,1.16673,448.63778,0.01995,1.99483,22.15889
14.20000,1.18329,453.23740,0.02024,2.02379,22.38607
14.40000,1.19998,456.03770,0.02050,2.05038,22.52439
14.60000,1.21672,460.40611,0.02079,2.07913,22.74015
14.80000,1.23334,464.41248,0.02109,2.10868,22.93803
15.00000,1.24996,468.20156,0.02138,2.13843,23.12518
15.20000,1.26664,472.46339,0.02169,2.16851,23.33567
15.40000,1.28344,476.71772,0.02198,2.19842,23.54580
15.60000,1.29994,480.36221,0.02228,2.22836,23.72581
15.80000,1.31656,483.61714,0.02253,2.25327,23.88657
16.00000,1.33343,486.92594,0.02284,2.28417,24.05000
16.20000,1.34993,491.46195,0.02314,2.31422,24.27404
16.40000,1.36667,494.57517,0.02345,2.34502,24.42781
16.60000,1.38341,498.43718,0.02376,2.37635,24.61856
16.80000,1.39997,501.92750,0.02407,2.40664,24.79095
17.00000,1.41659,503.89520,0.02431,2.43108,24.88814
17.20000,1.43333,507.75805,0.02463,2.46331,25.07893
17.40000,1.45001,510.59839,0.02494,2.49445,25.21922
17.60000,1.46664,514.52345,0.02525,2.52457,25.41308
17.80000,1.48320,518.23156,0.02556,2.55618,25.59623
18.00000,1.50000,520.76373,0.02587,2.58743,25.72130
18.20000,1.51656,524.31752,0.02619,2.61880,25.89683
18.40000,1.53330,526.24964,0.02644,2.64387,25.99226
18.60000,1.55004,528.84133,0.02676,2.67570,26.12026
18.80000,1.56666,532.09965,0.02707,2.70746,26.28120
19.00000,1.58335,534.69292,0.02739,2.73909,26.40928
19.20000,1.60003,538.28279,0.02771,2.77095,26.58659
19.40000,1.61671,540.59899,0.02803,2.80274,26.70099
19.60000,1.63339,542.99422,0.02829,2.82921,26.81930
19.80000,1.65007,545.48350,0.02861,2.86074,26.94225
20.00000,1.66663,548.10829,0.02893,2.89308,27.07189
20.20000,1.68325,551.13472,0.02925,2.92515,27.22137
20.40000,1.69993,554.51123,0.02957,2.95733,27.38814
20.60000,1.71674,557.22161,0.02990,2.98970,27.52201
20.80000,1.73330,560.05302,0.03022,3.02174,27.66186
21.00000,1.74992,560.51440,0.03048,3.04781,27.68464
21.20000,1.76672,563.37006,0.03081,3.11501,27.82569
21.37000,1.78077,565.72668,0.03109,3.17121,27.94209
21.57000,1.79745,568.52051,0.03142,3.23794,28.08008
21.77000,1.81437,571.28873,0.03174,3.30562,28.21680
21.97000,1.83081,574.03669,0.03207,3.37139,28.35253
22.17000,1.84744,576.11400,0.03240,3.43787,28.45513
22.37000,1.86418,577.18856,0.03266,3.50484,28.50821
22.57000,1.88086,579.95580,0.03300,3.57156,28.64489
22.77000,1.89748,581.10026,0.03328,3.63805,28.70141
22.97000,1.91410,583.37022,0.03361,3.70453,28.81353
23.17000,1.93084,586.32288,0.03415,3.77150,28.95936
23.37000,1.94740,588.47885,0.03423,3.83775,29.06585
23.57000,1.96414,591.10285,0.03143,3.90471,29.19545
23.77000,1.98095,590.70908,0.00745,3.97191,29.17601
23.97000,1.99751,593.93770,0.00957,4.03816,29.33547
24.17000,2.01419,596.30834,0.01073,4.10488,29.45256
24.37000,2.03087,598.51734,0.00944,4.17161,29.56167
24.57000,2.04755,601.19894,0.00793,4.23834,29.69412
24.77000,2.06417,602.95053,0.00801,4.30482,29.78063
24.97000,2.08079,605.24284,0.00768,4.37131,29.89385
25.17000,2.09748,605.92825,0.00725,4.43803,29.92770
25.37000,2.11410,608.42177,0.00354,4.50452,30.05086
25.57000,2.13078,610.38029,-0.00025,4.57124,30.14760
25.77000,2.14752,612.30697,-0.01338,4.63821,30.24276
25.97000,2.16420,614.24854,-0.13660,4.70493,30.33866
26.17000,2.18088,616.23314,-0.13659,4.77166,30.43668
26.37000,2.19750,618.63316,-0.13659,4.83814,30.55522
26.57000,2.21418,620.03951,-0.13660,4.90487,30.62468
26.77000,2.23087,620.45874,-0.13660,4.97159,30.64539
26.97000,2.24749,623.12549,-0.13660,5.03808,30.77710
27.17000,2.26423,624.77500,-0.13660,5.10504,30.85857
27.37000,2.28085,627.26582,-0.13660,5.17153,30.98160
27.57000,2.29747,628.76539,-0.13661,5.23802,31.05566
27.77000,2.31415,630.90432,-0.13661,5.30474,31.16131
27.97000,2.33077,632.80347,-0.13660,5.37123,31.25511
28.17000,2.34751,632.76365,-0.13661,5.43819,31.25314
28.37000,2.36414,634.57228,-0.13661,5.50468,31.34247
28.57000,2.38076,636.94958,-0.13661,5.57116,31.45989
28.77000,2.39750,638.29217,-0.13661,5.63813,31.52621
28.97000,2.41412,641.44428,-0.13661,5.70461,31.68189
29.17000,2.43086,642.36466,-0.13661,5.77158,31.72735
29.37000,2.44748,644.93814,-0.13661,5.83806,31.85446
29.57000,2.46416,644.03061,-0.13661,5.90479,31.80964
29.77000,2.48091,647.36814,-0.13661,5.97175,31.97448
29.97000,2.49747,648.80000,-0.13662,6.03800,32.04520
30.17000,2.51415,649.92341,-0.13662,6.10472,32.10069
30.37000,2.53089,652.36320,-0.13661,6.17169,32.22120
30.57000,2.54751,653.65238,-0.13661,6.23817,32.28487
30.77000,2.56407,655.85435,-0.13661,6.30442,32.39363
30.97000,2.58081,655.42473,-0.13662,6.37138,32.37241
31.17000,2.59749,657.28924,-0.13662,6.43811,32.46450
31.37000,2.61412,658.70285,-0.13662,6.50460,32.53432
31.57000,2.63080,660.81542,-0.13662,6.57132,32.63866
31.77000,2.64754,663.19890,-0.13662,6.63829,32.75639
31.97000,2.66410,663.89991,-0.13662,6.70453,32.79101
32.17000,2.68084,665.51589,-0.13662,6.77150,32.87083
32.37000,2.69752,667.20932,-0.13662,6.83822,32.95447
32.57000,2.71420,667.06985,-0.13662,6.90495,32.94758
32.77000,2.73083,668.58395,-0.13662,6.97143,33.02236
32.97000,2.74751,670.62699,-0.13662,7.03816,33.12327
33.17000,2.76419,672.02351,-0.13662,7.10488,33.19225
33.37000,2.78087,673.74664,-0.13662,7.17161,33.27736
33.57000,2.79749,675.55946,-0.13662,7.23809,33.36689
33.77000,2.81417,676.86415,-0.13662,7.30482,33.43134
33.97000,2.83079,678.13136,-0.13663,7.37130,33.49392
34.17000,2.84741,678.02225,-0.13662,7.43779,33.48853
34.37000,2.86416,679.22929,-0.13662,7.50476,33.54815
34.57000,2.88090,681.59080,-0.13662,7.57172,33.66479
34.77000,2.89752,683.44828,-0.13663,7.63820,33.75653
34.97000,2.91426,684.29341,-0.13662,7.70517,33.79827
35.17000,2.93082,685.90869,-0.13662,7.77142,33.87806
35.37000,2.94738,688.02778,-0.13662,7.83766,33.98272
35.57000,2.96424,689.40646,-0.13662,7.90510,34.05082
35.77000,2.98092,691.07465,-0.13662,7.97183,34.13321
35.97000,2.99743,690.58281,-0.13662,8.03784,34.10892
36.17000,3.01417,691.88150,-0.13663,8.10480,34.17306
36.37000,3.03085,693.57036,-0.13662,8.17153,34.25648
36.57000,3.04741,694.86550,-0.13662,8.23777,34.32045
36.77000,3.06415,696.70640,-0.13663,8.30474,34.41137
36.97000,3.08095,697.43549,-0.13663,8.37194,34.44738
37.17000,3.09745,699.08719,-0.13663,8.43795,34.52896
37.37000,3.11414,700.50242,-0.13663,8.50467,34.59886
37.57000,3.13094,702.05848,-0.13663,8.57188,34.67572
37.77000,3.14756,702.82756,-0.13663,8.63836,34.71371
37.97000,3.16412,701.83459,-0.13662,8.70461,34.66466
38.17000,3.18086,703.80918,-0.13663,8.77157,34.76219
38.37000,3.19748,705.05925,-0.13663,8.83806,34.82393
38.57000,3.21410,706.59984,-0.13663,8.90455,34.90002
38.77000,3.23078,707.88772,-0.13663,8.97127,34.96363
38.97000,3.24753,708.85839,-0.13663,9.03823,35.01158
39.17000,3.26415,710.76355,-0.13663,9.10472,35.10567
39.37000,3.28077,710.98940,-0.13663,9.17121,35.11683
39.57000,3.29751,712.60878,-0.13663,9.23817,35.19682
39.77000,3.31413,714.27184,-0.13663,9.30466,35.27895
39.97000,3.33087,714.81508,-0.13663,9.37162,35.30579
40.17000,3.34755,715.98757,-0.13663,9.43835,35.36370
40.37000,3.36424,716.77561,-0.13663,9.50507,35.40262
40.57000,3.38080,716.68923,-0.13663,9.57132,35.39835
40.77000,3.39748,718.29958,-0.13663,9.63804,35.47789
40.97000,3.41428,719.75342,-0.13663,9.70525,35.54970
41.17000,3.43078,719.85228,-0.13663,9.77125,35.55458
41.37000,3.44746,721.56587,-0.13663,9.83798,35.63922
41.57000,3.46420,722.47931,-0.13663,9.90494,35.68433
41.77000,3.48082,723.94335,-0.13663,9.97143,35.75665
41.97000,3.49751,725.08198,-0.13663,10.03816,35.81289
42.17000,3.51425,725.90760,-0.13663,10.10512,35.85366
42.37000,3.53087,726.83985,-0.13663,10.17161,35.89971
42.57000,3.54749,728.00568,-0.13663,10.23809,35.95729
42.77000,3.56411,729.46385,-0.13663,10.30458,36.02931
42.97000,3.58091,730.06279,-0.13663,10.37178,36.05890
43.17000,3.59741,729.23666,-0.13663,10.43779,36.01809
43.37000,3.61416,730.06060,-0.13663,10.50475,36.05878
43.57000,3.63090,731.78387,-0.13663,10.57172,36.14390
43.77000,3.64740,733.21001,-0.13663,10.63772,36.21434
43.97000,3.66414,733.91544,-0.13663,10.70469,36.24918
44.17000,3.68094,735.23093,-0.13663,10.77189,36.31416
44.37000,3.69756,735.95252,-0.13663,10.83838,36.34980
44.57000,3.71412,737.31705,-0.13663,10.90462,36.41719
44.77000,3.73086,737.68101,-0.13663,10.97159,36.43517
44.97000,3.74761,738.87496,-0.13663,11.03855,36.49414
45.17000,3.76405,739.79222,-0.13663,11.10432,36.53944
45.37000,3.78085,740.00480,-0.13663,11.17152,36.54995
45.57000,3.79759,741.29184,-0.13663,11.23849,36.61351
45.77000,3.81409,742.28342,-0.13663,11.30450,36.66249
45.97000,3.83077,741.75992,-0.13663,11.37122,36.63663
46.17000,3.84757,742.93348,-0.13663,11.43842,36.69460
46.37000,3.86419,743.31947,-0.13663,11.50491,36.71366
46.57000,3.88088,744.80670,-0.13663,11.57164,36.78712
46.77000,3.89744,745.63790,-0.13663,11.63788,36.82817
46.97000,3.91412,746.97374,-0.13663,11.70461,36.89415
47.17000,3.93080,747.93985,-0.13663,11.77133,36.94187
47.37000,3.94748,748.69432,-0.13663,11.83806,36.97913
47.57000,3.96428,749.28352,-0.13664,11.90526,37.00824
47.77000,3.98078,749.93162,-0.13664,11.97127,37.04025
47.97000,3.99747,750.84968,-0.13663,12.03799,37.08559
48.17000,4.01415,751.80661,-0.13663,12.10472,37.13285
48.37000,4.03083,752.59358,-0.13663,12.17144,37.17172
48.57000,4.04751,753.30003,-0.13663,12.23817,37.20662
48.77000,4.06419,752.14133,-0.13663,12.30489,37.14939
48.97000,4.08081,753.47065,-0.13663,12.37138,37.21504
49.17000,4.09743,754.70670,-0.13663,12.43787,37.27609
49.37000,4.11411,755.20501,-0.13663,12.50459,37.30070
49.57000,4.13092,756.35426,-0.13664,12.57180,37.35747
49.77000,4.14742,757.45843,-0.13663,12.63780,37.41201
49.97000,4.16410,757.64470,-0.13664,12.70453,37.42121
50.17000,4.18090,758.35236,-0.13664,12.77173,37.45616
50.37000,4.19740,759.34962,-0.13663,12.83774,37.50541
50.57000,4.21414,760.61171,-0.13664,12.90470,37.56775
50.77000,4.23094,760.44290,-0.13664,12.97190,37.55941
50.97000,4.24751,761.38992,-0.13663,13.03815,37.60619
51.17000,4.26407,762.24315,-0.13664,13.10440,37.64833
51.37000,4.28087,762.71463,-0.13664,13.17160,37.67162
51.57000,4.29755,762.68511,-0.13664,13.23833,37.67016
51.77000,4.31411,763.70109,-0.13664,13.30457,37.72034
51.97000,4.33079,763.83376,-0.13663,13.37130,37.72689
52.17000,4.34753,764.87488,-0.13664,13.43826,37.77832
52.37000,4.36415,765.03470,-0.13664,13.50475,37.78621
52.57000,4.38078,766.69939,-0.13663,13.57124,37.86843
52.77000,4.39752,767.39551,-0.13663,13.63820,37.90281
52.97000,4.41420,767.87919,-0.13664,13.70493,37.92670
53.17000,4.43082,768.36543,-0.13664,13.77141,37.95072
53.37000,4.44750,768.85493,-0.13664,13.83814,37.97490
53.57000,4.46418,769.29918,-0.13663,13.90486,37.99684
53.77000,4.48086,769.64828,-0.13664,13.97159,38.01408
53.97000,4.49749,770.35842,-0.13664,14.03807,38.04916
54.17000,4.51411,771.56899,-0.13663,14.10456,38.10895
54.37000,4.53073,771.66073,-0.13664,14.17104,38.11348
54.57000,4.54747,772.19335,-0.13663,14.23801,38.13979
54.77000,4.56415,771.99526,-0.13664,14.30473,38.13000
54.97000,4.58089,772.80365,-0.13664,14.37170,38.16993
55.17000,4.59757,773.10330,-0.13663,14.43842,38.18473
55.37000,4.61413,773.82610,-0.13664,14.50467,38.22043
55.57000,4.63082,774.67761,-0.13663,14.57139,38.26249
55.77000,4.64756,775.41331,-0.13664,14.63836,38.29882
55.97000,4.66424,775.62435,-0.13664,14.70508,38.30925
56.17000,4.68092,775.85652,-0.13664,14.77181,38.32072
56.37000,4.69748,776.89420,-0.13664,14.83805,38.37197
56.57000,4.71410,777.34408,-0.13664,14.90454,38.39419
56.77000,4.73084,777.90637,-0.13664,14.97151,38.42196
56.97000,4.74746,778.68816,-0.13664,15.03799,38.46058
57.17000,4.76415,778.66898,-0.13664,15.10472,38.45963
57.37000,4.78083,779.63914,-0.13664,15.17144,38.50755
57.57000,4.79745,779.81469,-0.13664,15.23793,38.51622
57.77000,4.81413,780.54261,-0.13664,15.30465,38.55217
57.97000,4.83087,779.80557,-0.13664,15.37162,38.51576
58.17000,4.84761,780.50382,-0.13663,15.43858,38.55025
58.37000,4.86417,781.09754,-0.13664,15.50483,38.57958
58.57000,4.88080,781.59608,-0.13664,15.57131,38.60420
58.77000,4.89754,782.47720,-0.13664,15.63828,38.64772
58.97000,4.91410,782.91688,-0.13664,15.70453,38.66944
59.17000,4.93084,783.68559,-0.13664,15.77149,38.70741
59.37000,4.94758,784.31703,-0.13664,15.83845,38.73859
59.57000,4.96414,784.02255,-0.13664,15.90470,38.72405
59.77000,4.98082,785.04067,-0.13664,15.97142,38.77433
59.97000,4.99750,785.38051,-0.13664,16.03815,38.79112
60.17000,5.01419,785.39923,-0.13664,16.10487,38.79204
60.37000,5.03087,785.97777,-0.13664,16.17160,38.82062
60.57000,5.04749,786.34350,-0.13664,16.23808,38.83868
60.77000,5.06417,786.95640,-0.13664,16.30481,38.86895
60.97000,5.08079,787.39533,-0.13664,16.37130,38.89063
61.17000,5.09747,787.41387,-0.13664,16.43802,38.89155
61.37000,5.11421,787.59082,-0.13664,16.50499,38.90029
61.57000,5.13078,787.71245,-0.13664,16.57123,38.90630
61.77000,5.14746,787.29019,-0.13664,16.63796,38.88544
61.97000,5.16414,788.17056,-0.13664,16.70468,38.92892
62.17000,5.18082,788.34379,-0.13664,16.77141,38.93748
62.37000,5.19750,789.30324,-0.13664,16.83813,38.98487
62.57000,5.21412,789.84238,-0.13664,16.90462,39.01150
62.77000,5.23080,790.01859,-0.13664,16.97134,39.02020
62.97000,5.24748,790.19386,-0.13664,17.03807,39.02886
63.17000,5.26411,790.87447,-0.13664,17.10455,39.06247
63.37000,5.28091,791.41650,-0.13664,17.17176,39.08924
63.57000,5.29753,791.63946,-0.13664,17.23824,39.10026
63.77000,5.31421,791.67401,-0.13664,17.30497,39.10196
63.97000,5.33083,791.89008,-0.13664,17.37145,39.11264
64.17000,5.34745,793.04446,-0.13664,17.43794,39.16965
64.37000,5.36419,793.43831,-0.13664,17.50491,39.18911
64.57000,5.38081,793.71668,-0.13664,17.57139,39.20285
64.77000,5.39750,793.52437,-0.13664,17.63812,39.19336
64.97000,5.41412,793.76474,-0.13664,17.70460,39.20523
65.17000,5.43074,794.06276,-0.13664,17.77109,39.21995
65.37000,5.44754,794.43445,-0.13664,17.83829,39.23831
65.57000,5.46410,795.09057,-0.13664,17.90454,39.27071
65.77001,5.48084,794.98999,-0.13664,17.97150,39.26575
65.97000,5.49758,794.42514,-0.13664,18.03847,39.23785
66.17001,5.51415,794.80493,-0.13664,18.10471,39.25661
66.37000,5.53083,795.04801,-0.13664,18.17144,39.26861
66.57000,5.54751,796.17295,-0.13664,18.23816,39.32417
66.77001,5.56425,795.50017,-0.13664,18.30513,39.29094
66.97000,5.58081,795.63009,-0.13664,18.37137,39.29736
67.17001,5.59749,796.95703,-0.13664,18.43810,39.36290
67.37000,5.61423,797.05436,-0.13664,18.50506,39.36771
67.57000,5.63079,797.53986,-0.13664,18.57131,39.39169
67.77001,5.64748,797.97516,-0.13664,18.63804,39.41319
67.97000,5.66416,798.05916,-0.13664,18.70476,39.41734
68.17001,5.68078,798.48589,-0.13664,18.77125,39.43841
68.37000,5.69746,798.47984,-0.13664,18.83797,39.43811
68.57000,5.71414,798.32068,-0.13664,18.90470,39.43025
68.77001,5.73082,799.33424,-0.13664,18.97142,39.48032
68.97000,5.74750,799.82989,-0.13664,19.03815,39.50480
69.17001,5.76419,799.82514,-0.13664,19.10487,39.50456
69.37000,5.78087,799.97359,-0.13664,19.17160,39.51189
69.57000,5.79743,800.27236,-0.13664,19.23784,39.52665
69.77001,5.81417,800.35524,-0.13664,19.30481,39.53074
69.97000,5.83091,800.89262,-0.13664,19.37177,39.55729
70.17001,5.84747,800.71362,-0.13664,19.43802,39.54844
70.37000,5.86409,801.23441,-0.13664,19.50451,39.57417
70.57000,5.88083,800.98286,-0.13664,19.57147,39.56174
70.77001,5.89752,801.83493,-0.13664,19.63819,39.60383
70.97000,5.91420,801.11390,-0.13664,19.70492,39.56821
71.17001,5.93082,800.20018,-0.13664,19.77140,39.52308
71.37000,5.94756,801.51763,-0.13664,19.83837,39.58815
71.57000,5.96412,801.82757,-0.13664,19.90461,39.60346
71.77001,5.98086,802.62069,-0.13664,19.97158,39.64264
71.97000,5.99760,802.38981,-0.13664,20.03855,39.63123
72.17001,6.01417,802.08890,-0.13664,20.10479,39.61637
72.37000,6.03079,802.55782,-0.13664,20.17128,39.63953
72.57000,6.04753,803.37664,-0.13664,20.23824,39.67997
72.77001,6.06415,803.30987,-0.13664,20.30473,39.67668
72.97000,6.08077,803.82610,-0.13664,20.37121,39.70218
73.17001,6.09751,804.44720,-0.13664,20.43818,39.73285
73.37000,6.11425,803.99867,-0.13664,20.50514,39.71070
73.57000,6.13075,803.92128,-0.13664,20.57115,39.70687
73.77001,6.14750,804.16603,-0.13664,20.63811,39.71896
73.97000,6.16418,805.06420,-0.13664,20.70484,39.76332
74.17001,6.18086,804.69651,-0.13664,20.77156,39.74517
74.37000,6.19748,805.02192,-0.13664,20.83805,39.76124
74.57001,6.21422,805.43878,-0.13664,20.90501,39.78183
74.77001,6.23078,805.43561,-0.13664,20.97126,39.78167
74.97000,6.24740,805.60995,-0.13664,21.03775,39.79028
75.17001,6.26420,805.50779,-0.13664,21.10495,39.78524
75.37000,6.28089,805.39668,-0.13664,21.17168,39.77975
75.57001,6.29745,805.63379,-0.13664,21.23792,39.79146
75.77001,6.31413,805.99654,-0.13664,21.30465,39.80938
75.97000,6.33081,805.90481,-0.13664,21.37137,39.80484
76.17001,6.34743,805.93936,-0.13664,21.43786,39.80655
76.37000,6.36423,806.24521,-0.13664,21.50506,39.82166
76.57001,6.38091,806.28544,-0.13664,21.57179,39.82365
76.77001,6.39742,806.93280,-0.13664,21.63779,39.85562
76.97000,6.41410,806.75110,-0.13664,21.70452,39.84665
77.17001,6.43090,807.16154,-0.13664,21.77172,39.86692
77.37000,6.44746,806.61178,-0.13664,21.83797,39.83976
77.57001,6.46420,806.84107,-0.13664,21.90493,39.85109
77.77001,6.48082,807.02370,-0.13664,21.97142,39.86011
77.97000,6.49750,807.44065,-0.13664,22.03815,39.88070
78.17001,6.51407,807.45434,-0.13664,22.10439,39.88138
78.37000,6.53075,807.89234,-0.13664,22.17111,39.90301
78.57001,6.54761,805.53405,-0.13664,22.23856,39.78653
78.77001,6.56417,805.83273,-0.13664,22.30481,39.80128
78.97000,6.58079,806.05643,-0.13664,22.37129,39.81233
79.17001,6.59759,806.70901,-0.13665,22.43849,39.84457
79.37000,6.61409,807.05611,-0.13664,22.50450,39.86171
79.57001,6.63077,806.71823,-0.13664,22.57123,39.84502
79.77001,6.64764,807.46114,-0.13664,22.63867,39.88171
79.97000,6.66426,807.70254,-0.13664,22.70516,39.89364
80.17001,6.68076,808.05235,-0.13664,22.77116,39.91092
80.37000,6.69744,807.94720,-0.13664,22.83789,39.90572
80.57001,6.71430,808.12173,-0.13664,22.90533,39.91434
80.77001,6.73080,808.55470,-0.13664,22.97134,39.93573
80.97000,6.74742,808.27409,-0.13664,23.03782,39.92187
81.17001,6.76422,809.03703,-0.13665,23.10503,39.95955
81.37000,6.78079,809.01673,-0.13664,23.17128,39.95855
81.57001,6.79747,808.76602,-0.13664,23.23800,39.94616
81.77001,6.81427,809.12914,-0.13665,23.30520,39.96410
81.97000,6.83083,809.11061,-0.13664,23.37145,39.96318
82.17001,6.84745,809.75471,-0.13664,23.43794,39.99500
82.37000,6.86413,809.21175,-0.13664,23.50466,39.96818
82.57001,6.88087,809.39149,-0.13664,23.57163,39.97706
82.77001,6.89749,809.33254,-0.13665,23.63811,39.97414
82.97000,6.91418,810.03895,-0.13664,23.70484,40.00904
83.17001,6.93086,809.90186,-0.13665,23.77156,40.00227
83.37000,6.94742,809.77324,-0.13664,23.83781,39.99591
83.57001,6.96410,809.83946,-0.13664,23.90453,39.99918
83.77001,6.98084,809.62153,-0.13664,23.97150,39.98842
83.97000,6.99752,809.58707,-0.13664,24.03822,39.98672
84.17001,7.01420,810.50135,-0.13665,24.10495,40.03188
84.37000,7.03077,809.82978,-0.13664,24.17120,39.99870
84.57001,7.04751,810.11746,-0.13664,24.23816,40.01291
84.77001,7.06419,810.35029,-0.13664,24.30488,40.02441
84.97000,7.08087,810.02666,-0.13665,24.37161,40.00843
85.17001,7.09761,809.85213,-0.13665,24.43857,39.99981
85.37000,7.11411,810.23807,-0.13664,24.50458,40.01887
85.57001,7.13079,810.18573,-0.13664,24.57131,40.01628
85.77001,7.14754,810.33548,-0.13664,24.63827,40.02368
85.97000,7.16416,810.54913,-0.13664,24.70476,40.03423
86.17001,7.18078,810.67141,-0.13664,24.77124,40.04028
86.37000,7.19746,810.27988,-0.13664,24.83797,40.02094
86.57001,7.21414,810.64431,-0.13665,24.90469,40.03894
86.77001,7.23076,811.16725,-0.13664,24.97118,40.06477
86.97000,7.24750,810.78345,-0.13664,25.03814,40.04581
87.17001,7.26430,810.97987,-0.13665,25.10535,40.05551
87.37000,7.28081,810.13963,-0.13664,25.17135,40.01401
87.57001,7.29749,810.22382,-0.13665,25.23808,40.01817
87.77001,7.31423,810.46494,-0.13665,25.30504,40.03008
87.97000,7.33085,810.82694,-0.13665,25.37153,40.04795
88.17001,7.34747,810.77442,-0.13664,25.43801,40.04536
88.37000,7.36415,810.29506,-0.13664,25.50474,40.02169
88.57001,7.38077,810.70140,-0.13664,25.57122,40.04176
88.77001,7.39746,810.74620,-0.13664,25.63795,40.04397
88.97000,7.41414,810.09949,-0.13664,25.70468,40.01203
89.17001,7.43088,810.50694,-0.13665,25.77164,40.03215
89.37000,7.44750,810.56431,-0.13664,25.83812,40.03498
89.57001,7.46418,810.66154,-0.13664,25.90485,40.03979
89.77001,7.48086,810.66005,-0.13665,25.97158,40.03971
89.97000,7.49748,810.99989,-0.13665,26.03806,40.05650
90.17001,7.51428,810.86932,-0.13665,26.10527,40.05005
90.37000,7.53090,809.93855,-0.13665,26.17175,40.00408
90.57001,7.54747,810.46773,-0.13665,26.23800,40.03022
90.77001,7.56421,810.55323,-0.13664,26.30496,40.03444
90.97000,7.58077,810.35942,-0.13665,26.37121,40.02486
91.17001,7.59751,810.42610,-0.13665,26.43817,40.02816
91.37000,7.61419,811.03686,-0.13664,26.50490,40.05832
91.57001,7.63075,811.01302,-0.13664,26.57115,40.05715
91.77001,7.64749,810.58601,-0.13664,26.63811,40.03606
91.97000,7.66418,810.73036,-0.13664,26.70484,40.04319
92.17001,7.68080,810.73223,-0.13664,26.77132,40.04328
92.37000,7.69754,810.94997,-0.13664,26.83828,40.05403
92.57001,7.71422,810.93274,-0.13664,26.90501,40.05318
92.77001,7.73084,810.62419,-0.13665,26.97150,40.03794
92.97000,7.74746,810.66163,-0.13665,27.03798,40.03979
93.17001,7.76414,811.14685,-0.13664,27.10471,40.06376
93.37000,7.78077,810.85078,-0.13664,27.17119,40.04913
93.57001,7.79751,810.64217,-0.13665,27.23816,40.03883
93.77001,7.81419,810.80934,-0.13664,27.30488,40.04709
93.97000,7.83081,810.20920,-0.13664,27.37136,40.01744
94.17001,7.84749,810.83784,-0.13664,27.43809,40.04850
94.37000,7.86423,810.19942,-0.13664,27.50506,40.01696
94.57001,7.88085,810.48375,-0.13664,27.57154,40.03101
94.77001,7.89753,810.31462,-0.13664,27.63827,40.02265
94.97000,7.91422,808.54986,-0.13664,27.70499,39.93549
95.17001,7.93084,809.10912,-0.13664,27.77148,39.96311
95.37000,7.94752,809.01105,-0.13664,27.83820,39.95827
95.57001,7.96414,808.78744,-0.13664,27.90469,39.94722
95.77001,7.98088,809.36160,-0.13664,27.97165,39.97558
95.97000,7.99750,809.39569,-0.13664,28.03814,39.97726
96.17001,8.01412,809.28812,-0.13664,28.10462,39.97195
96.37000,8.03086,809.49739,-0.13664,28.17159,39.98229
96.57001,8.04749,809.05845,-0.13664,28.23807,39.96061
96.77001,8.06411,809.42400,-0.13664,28.30456,39.97866
96.97000,8.08079,809.73739,-0.13664,28.37129,39.99414
97.17001,8.09747,809.91266,-0.13664,28.43801,40.00280
97.37000,8.11409,809.59946,-0.13664,28.50450,39.98733
97.57001,8.13083,809.82614,-0.13664,28.57146,39.99852
97.77001,8.14751,809.42018,-0.13664,28.63819,39.97847
97.97000,8.16420,809.68551,-0.13664,28.70491,39.99158
98.17001,8.18082,809.45892,-0.13664,28.77140,39.98039
98.37000,8.19750,809.57524,-0.13664,28.83812,39.98613
98.57001,8.21418,810.04947,-0.13664,28.90485,40.00956
98.77001,8.23080,809.99723,-0.13664,28.97134,40.00698
98.97000,8.24748,809.61790,-0.13664,29.03806,39.98824
99.17001,8.26416,809.22814,-0.13664,29.10478,39.96899
99.37000,8.28084,809.64640,-0.13664,29.17151,39.98965
99.57001,8.29741,809.33888,-0.13664,29.23776,39.97446
99.77001,8.31415,809.92021,-0.13664,29.30472,40.00317
99.97000,8.33089,809.64584,-0.13664,29.37168,39.98962
100.17001,8.34751,809.72183,-0.13664,29.43817,39.99337
100.37000,8.36419,810.24133,-0.13664,29.50490,40.01903
100.57001,8.38075,809.65348,-0.13664,29.57114,39.99000
100.77001,8.39743,809.31773,-0.13664,29.63787,39.97342
100.97000,8.41424,809.16565,-0.13664,29.70507,39.96590
101.17001,8.43080,809.05277,-0.13664,29.77132,39.96033
101.37000,8.44748,809.03629,-0.13664,29.83804,39.95951
101.57001,8.46422,809.21892,-0.13664,29.90501,39.96853
101.77001,8.48084,809.12802,-0.13664,29.97149,39.96404
101.97000,8.49740,809.64835,-0.13664,30.03774,39.98974
102.17001,8.51414,809.20653,-0.13664,30.10470,39.96792
102.37000,8.53088,808.76257,-0.13664,30.17167,39.94600
102.57001,8.54751,809.01487,-0.13664,30.23815,39.95845
102.77001,8.56407,809.04970,-0.13664,30.30440,39.96017
102.97000,8.58093,809.11107,-0.13664,30.37184,39.96321
103.17001,8.59749,808.77235,-0.13664,30.43809,39.94648
103.37000,8.61423,808.92062,-0.13664,30.50506,39.95380
103.57001,8.63091,809.31801,-0.13664,30.57178,39.97343
103.77001,8.64747,808.81650,-0.13664,30.63803,39.94866
103.97000,8.66415,808.16131,-0.13664,30.70475,39.91630
104.17001,8.68078,808.82227,-0.13664,30.77124,39.94894
104.37000,8.69752,808.51745,-0.13664,30.83820,39.93389
104.57001,8.71408,808.45729,-0.13664,30.90445,39.93092
104.77001,8.73076,808.48467,-0.13664,30.97117,39.93227
104.97000,8.74756,808.69347,-0.13664,31.03837,39.94258
105.17001,8.76412,807.67488,-0.13664,31.10462,39.89227
105.37000,8.78086,808.11111,-0.13664,31.17159,39.91382
105.57001,8.79760,808.90860,-0.13664,31.23855,39.95321
105.77001,8.81417,807.79055,-0.13664,31.30480,39.89798
105.97000,8.83085,807.56834,-0.13664,31.37152,39.88701
106.17001,8.84747,808.25556,-0.13664,31.43801,39.92095
106.37000,8.86421,807.35199,-0.13664,31.50497,39.87632
106.57001,8.88083,807.23623,-0.13664,31.57146,39.87061
106.77001,8.89745,807.70785,-0.13664,31.63795,39.89390
106.97001,8.91413,807.34780,-0.13664,31.70467,39.87612
107.17001,8.93070,807.18342,-0.13664,31.77091,39.86800
107.37000,8.94750,807.23464,-0.13664,31.83812,39.87053
107.57001,8.96430,807.28615,-0.13665,31.90532,39.87307
107.77001,8.98080,807.57150,-0.13664,31.97133,39.88717
107.97001,8.99748,806.95674,-0.13664,32.03806,39.85680
108.17001,9.01422,807.27804,-0.13664,32.10502,39.87267
108.37000,9.03084,806.65974,-0.13664,32.17151,39.84213
108.57001,9.04747,807.15986,-0.13664,32.23799,39.86683
108.77001,9.06421,806.45140,-0.13664,32.30495,39.83184
108.97001,9.08083,806.40744,-0.13664,32.37144,39.82967
109.17001,9.09739,806.30258,-0.13664,32.43769,39.82449
109.37000,9.11413,806.54062,-0.13664,32.50465,39.83625
109.57001,9.13093,806.29820,-0.13664,32.57186,39.82428
109.77001,9.14743,805.92576,-0.13664,32.63786,39.80588
109.97001,9.16406,806.45243,-0.13664,32.70435,39.83189
110.17001,9.18086,806.47022,-0.13664,32.77156,39.83277
110.37000,9.19748,805.69508,-0.13664,32.83804,39.79449
110.57001,9.21416,806.37746,-0.13664,32.90476,39.82819
110.77001,9.23090,805.77247,-0.13664,32.97173,39.79831
110.97001,9.24752,806.05680,-0.13664,33.03821,39.81235
111.17001,9.26408,805.54336,-0.13664,33.10446,39.78699
111.37000,9.28082,805.32003,-0.13664,33.17143,39.77596
111.57001,9.29751,805.84371,-0.13664,33.23815,39.80183
111.77001,9.31413,805.77377,-0.13664,33.30463,39.79837
111.97001,9.33087,805.25614,-0.13664,33.37160,39.77281
112.17001,9.34755,805.24087,-0.13664,33.43833,39.77205
112.37000,9.36411,805.20343,-0.13664,33.50457,39.77020
112.57001,9.38079,804.39756,-0.13664,33.57130,39.73040
112.77001,9.39753,804.84571,-0.13664,33.63826,39.75253
112.97001,9.41427,805.00953,-0.13665,33.70523,39.76062
113.17001,9.43084,804.47458,-0.13664,33.77148,39.73420
113.37000,9.44752,804.31178,-0.13664,33.83820,39.72616
113.57001,9.46420,804.07578,-0.13664,33.90492,39.71451
113.77001,9.48082,804.89954,-0.13664,33.97141,39.75519
113.97001,9.49756,804.17749,-0.13664,34.03837,39.71953
114.17001,9.51418,804.87952,-0.13664,34.10486,39.75420
114.37000,9.53074,804.29958,-0.13664,34.17111,39.72556
114.57001,9.54743,804.20431,-0.13664,34.23783,39.72086
114.77001,9.56423,804.02335,-0.13665,34.30504,39.71192
114.97001,9.58091,803.73203,-0.13664,34.37176,39.69753
115.17001,9.59741,803.03578,-0.13665,34.43777,39.66314
115.37000,9.61415,803.87415,-0.13664,34.50473,39.70455
115.57001,9.63089,803.89678,-0.13664,34.57170,39.70567
115.77001,9.64745,803.43643,-0.13665,34.63795,39.68293
115.97001,9.66419,802.97608,-0.13664,34.70491,39.66019
116.17001,9.68094,803.17631,-0.13664,34.77187,39.67008
116.37000,9.69744,804.00696,-0.13664,34.83788,39.71111
116.57001,9.71412,803.35401,-0.13665,34.90461,39.67886
116.77001,9.73092,802.50707,-0.13664,34.97181,39.63702
116.97001,9.74754,802.97394,-0.13665,35.03829,39.66008
117.17001,9.76416,802.34436,-0.13664,35.10478,39.62899
117.37000,9.78084,802.58781,-0.13664,35.17150,39.64101
117.57001,9.79746,802.80434,-0.13665,35.23799,39.65171
117.77001,9.81409,803.23471,-0.13665,35.30448,39.67297
117.97001,9.83077,802.01933,-0.13664,35.37120,39.61293
118.17001,9.84751,802.31465,-0.13665,35.43816,39.62752
118.37000,9.86413,802.57384,-0.13664,35.50465,39.64032
118.57001,9.88075,802.28169,-0.13664,35.57114,39.62589
118.77001,9.89749,801.81211,-0.13665,35.63810,39.60270
118.97001,9.91417,801.82608,-0.13664,35.70482,39.60339
119.17001,9.93085,801.89295,-0.13665,35.77155,39.60669
119.37000,9.94760,801.70715,-0.13665,35.83851,39.59752
119.57001,9.96416,802.20606,-0.13664,35.90476,39.62216
119.77001,9.98084,801.76974,-0.13665,35.97149,39.60061
119.97001,9.99746,801.29756,-0.13664,36.03797,39.57729
120.17001,10.01414,801.01201,-0.13664,36.10470,39.56318
120.37000,10.03076,800.87846,-0.13665,36.17118,39.55659
120.57001,10.04744,800.85276,-0.13664,36.23791,39.55532
120.77001,10.06418,801.32401,-0.13664,36.30487,39.57859
120.97001,10.08081,800.44437,-0.13665,36.37136,39.53514
121.17001,10.09749,801.09704,-0.13664,36.43809,39.56738
121.37000,10.11423,800.30086,-0.13664,36.50505,39.52806
121.57001,10.13085,800.84335,-0.13665,36.57153,39.55485
121.77001,10.14753,800.33550,-0.13664,36.63826,39.52977
121.97001,10.16415,800.43981,-0.13664,36.70474,39.53492
122.17001,10.18083,800.53722,-0.13664,36.77147,39.53973
122.37000,10.19752,800.30160,-0.13665,36.83820,39.52810
122.57001,10.21414,799.97024,-0.13664,36.90468,39.51173
122.77001,10.23082,800.63688,-0.13664,36.97141,39.54465
122.97001,10.24744,800.15846,-0.13664,37.03789,39.52102
123.17001,10.26412,800.69937,-0.13664,37.10462,39.54774
123.37000,10.28092,799.67715,-0.13665,37.17182,39.49725
123.57001,10.29754,799.45549,-0.13665,37.23831,39.48631
123.77001,10.31411,799.71580,-0.13665,37.30455,39.49916
123.97001,10.33085,799.46490,-0.13665,37.37151,39.48677
124.17001,10.34753,799.09507,-0.13664,37.43824,39.46850
124.37000,10.36421,799.54145,-0.13664,37.50497,39.49055
124.57001,10.38089,798.68808,-0.13664,37.57169,39.44840
124.77001,10.39757,798.63444,-0.13664,37.63842,39.44575
124.97001,10.41407,799.14713,-0.13664,37.70443,39.47107
125.17001,10.43081,798.97782,-0.13664,37.77139,39.46271
125.37000,10.44750,798.54541,-0.13665,37.83812,39.44135
125.57001,10.46412,798.60995,-0.13665,37.90460,39.44454
125.77001,10.48080,798.16543,-0.13664,37.97132,39.42258
125.97001,10.49748,798.47686,-0.13664,38.03805,39.43797
126.17001,10.51416,797.82382,-0.13665,38.10478,39.40571
126.37000,10.53084,798.87314,-0.13664,38.17150,39.45754
126.57001,10.54746,797.91080,-0.13665,38.23799,39.41001
126.77001,10.56421,797.73404,-0.13665,38.30495,39.40128
126.97001,10.58083,797.71411,-0.13664,38.37144,39.40030
127.17001,10.59745,798.03448,-0.13664,38.43792,39.41612
127.37000,10.61413,797.71159,-0.13664,38.50465,39.40017
127.57001,10.63075,797.71681,-0.13664,38.57113,39.40043
127.77001,10.64749,797.41813,-0.13664,38.63810,39.38567
127.97001,10.66417,797.81497,-0.13664,38.70482,39.40528
128.17002,10.68085,796.93450,-0.13665,38.77155,39.36179
128.37001,10.69747,796.83866,-0.13664,38.83803,39.35706
128.57001,10.71416,797.34400,-0.13665,38.90476,39.38202
128.77001,10.73090,796.01584,-0.13665,38.97172,39.31641
128.97000,10.74752,796.64197,-0.13665,39.03821,39.34734
129.17002,10.76414,796.86791,-0.13665,39.10470,39.35850
129.37001,10.78088,796.65715,-0.13665,39.17166,39.34809
129.57001,10.79744,796.42637,-0.13664,39.23790,39.33669
129.77001,10.81413,796.69422,-0.13664,39.30463,39.34992
129.97000,10.83093,796.36043,-0.13665,39.37183,39.33344
130.17002,10.84755,796.31042,-0.13665,39.43833,39.33096
130.37001,10.86417,795.96518,-0.13665,39.50481,39.31391
130.57001,10.88085,795.80471,-0.13664,39.57153,39.30598
130.77001,10.89753,795.96145,-0.13664,39.63826,39.31373
130.97000,10.91415,795.46236,-0.13665,39.70474,39.28908
131.17002,10.93077,795.68438,-0.13665,39.77123,39.30004
131.37002,10.94752,795.73980,-0.13664,39.83820,39.30278
131.57000,10.96408,795.17178,-0.13665,39.90444,39.27472
131.77000,10.98082,795.03851,-0.13665,39.97141,39.26814
131.97000,10.99756,794.92461,-0.13665,40.03837,39.26252
132.17002,11.01418,794.93923,-0.13665,40.10485,39.26324
132.37002,11.03080,794.56745,-0.13664,40.17134,39.24488
132.57000,11.04754,795.13909,-0.13665,40.23831,39.27311
132.77000,11.06423,794.55068,-0.13664,40.30503,39.24405
132.97000,11.08079,794.80633,-0.13664,40.37128,39.25668
133.17002,11.09753,794.93355,-0.13665,40.43824,39.26296
133.37002,11.11421,794.06574,-0.13665,40.50497,39.22010
133.57000,11.13077,794.02886,-0.13664,40.57121,39.21827
133.77000,11.14745,794.14472,-0.13664,40.63794,39.22400
133.97000,11.16419,794.14649,-0.13664,40.70490,39.22408
134.17002,11.18087,793.65019,-0.13665,40.77162,39.19957
134.37002,11.19756,793.58695,-0.13665,40.83835,39.19645
134.57000,11.21418,793.17801,-0.13665,40.90484,39.17625
134.77000,11.23086,794.09033,-0.13665,40.97156,39.22131
134.97000,11.24748,793.17400,-0.13664,41.03805,39.17605
135.17002,11.26416,792.55057,-0.13665,41.10478,39.14526
135.37002,11.28090,793.15649,-0.13665,41.17174,39.17519
135.57000,11.29746,792.65367,-0.13665,41.23798,39.15035
135.77000,11.31415,792.85018,-0.13665,41.30471,39.16006
135.97000,11.33089,792.19788,-0.13665,41.37168,39.12784
136.17002,11.34745,792.47849,-0.13664,41.43792,39.14170
136.37002,11.36413,792.29558,-0.13665,41.50465,39.13266
136.57000,11.38087,792.04850,-0.13665,41.57161,39.12046
136.77000,11.39749,791.66051,-0.13665,41.63809,39.10130
136.97000,11.41405,791.77842,-0.13665,41.70434,39.10712
137.17002,11.43079,791.98275,-0.13665,41.77130,39.11721
137.37002,11.44759,791.76705,-0.13665,41.83851,39.10656
137.57000,11.46422,791.48104,-0.13665,41.90500,39.09243
137.77000,11.48084,791.46298,-0.13665,41.97148,39.09154
137.97000,11.49758,791.12686,-0.13665,42.03845,39.07494
138.17002,11.51414,790.90586,-0.13665,42.10470,39.06403
138.37002,11.53082,790.93566,-0.13665,42.17142,39.06549
138.57000,11.54756,790.79727,-0.13665,42.23838,39.05866
138.77000,11.56413,791.06316,-0.13665,42.30463,39.07179
138.97000,11.58069,790.92169,-0.13665,42.37088,39.06481
139.17002,11.59749,790.31158,-0.13665,42.43808,39.03467
139.37002,11.61417,790.41524,-0.13665,42.50481,39.03979
139.57000,11.63085,790.09691,-0.13665,42.57153,39.02407
139.77000,11.64753,790.04867,-0.13665,42.63825,39.02169
139.97000,11.66421,789.74674,-0.13665,42.70498,39.00677
140.17002,11.68077,789.63200,-0.13665,42.77123,39.00111
140.37002,11.69740,789.55833,-0.13665,42.83771,38.99747
140.57000,11.71420,789.63023,-0.13665,42.90492,39.00102
140.77000,11.73082,789.23376,-0.13664,42.97140,38.98144
140.97000,11.74744,789.81239,-0.13665,43.03789,39.01002
141.17002,11.76412,789.11418,-0.13665,43.10461,38.97553
141.37002,11.78080,789.55870,-0.13665,43.17134,38.99749
141.57000,11.79748,788.92540,-0.13665,43.23806,38.96621
141.77000,11.81422,788.49318,-0.13665,43.30503,38.94486
141.97000,11.83085,788.56917,-0.13665,43.37151,38.94861
142.17002,11.84747,788.68745,-0.13665,43.43800,38.95445
142.37002,11.86409,788.22915,-0.13665,43.50448,38.93182
142.57000,11.88089,787.78761,-0.13665,43.57169,38.91001
142.77000,11.89751,787.68600,-0.13665,43.63818,38.90499
142.97000,11.91413,787.20069,-0.13665,43.70466,38.88102
143.17002,11.93087,787.44302,-0.13665,43.77162,38.89299
143.37002,11.94749,787.79012,-0.13665,43.83811,38.91013
143.57000,11.96406,787.62574,-0.13665,43.90436,38.90202
143.77000,11.98086,787.77242,-0.13665,43.97156,38.90926
143.97000,11.99760,787.31012,-0.13665,44.03853,38.88643
144.17002,12.01410,787.30062,-0.13664,44.10453,38.88596
144.37002,12.03072,786.96534,-0.13665,44.17102,38.86940
144.57000,12.04764,786.94839,-0.13665,44.23870,38.86856
144.77000,12.06420,786.67030,-0.13665,44.30495,38.85482
144.97000,12.08077,787.19184,-0.13665,44.37120,38.88058
145.17002,12.09757,786.11616,-0.13665,44.43839,38.82745
145.37002,12.11419,786.37907,-0.13665,44.50488,38.84044
145.57000,12.13081,786.34638,-0.13665,44.57137,38.83883
145.77000,12.14749,786.28436,-0.13665,44.63809,38.83576
145.97000,12.16423,786.00580,-0.13665,44.70506,38.82200
146.17002,12.18079,785.82643,-0.13665,44.77130,38.81314
146.37002,12.19747,785.87690,-0.13665,44.83803,38.81564
146.57000,12.21416,785.41124,-0.13665,44.90475,38.79264
146.77000,12.23078,785.04588,-0.13665,44.97124,38.77459
146.97000,12.24746,785.66559,-0.13664,45.03797,38.80520
147.17002,12.26426,785.35918,-0.13665,45.10517,38.79007
147.37002,12.28082,785.31941,-0.13665,45.17142,38.78810
147.57000,12.29744,785.19713,-0.13665,45.23790,38.78206
147.77000,12.31412,784.37338,-0.13665,45.30463,38.74137
147.97000,12.33086,784.50255,-0.13665,45.37159,38.74776
148.17002,12.34761,784.30334,-0.13665,45.43855,38.73792
148.37002,12.36417,784.21701,-0.13665,45.50480,38.73365
148.57000,12.38085,784.02702,-0.13665,45.57153,38.72427
148.77000,12.39741,783.81784,-0.13665,45.63777,38.71394
148.97000,12.41409,783.76671,-0.13664,45.70450,38.71141
149.17002,12.43083,783.55772,-0.13665,45.77146,38.70109
149.37002,12.44751,782.72354,-0.13665,45.83819,38.65989
149.57000,12.46414,783.18920,-0.13665,45.90468,38.68289
149.77000,12.48082,783.06980,-0.13665,45.97140,38.67699
149.97000,12.49744,782.85616,-0.13665,46.03789,38.66644
150.17002,12.51412,782.55618,-0.13665,46.10461,38.65162
150.37002,12.53086,782.30845,-0.13665,46.17158,38.63939
150.57000,12.54754,782.16204,-0.13665,46.23830,38.63215
150.77000,12.56410,782.47376,-0.13665,46.30455,38.64755
150.97000,12.58085,782.15431,-0.13665,46.37151,38.63177
151.17002,12.59759,782.03129,-0.13665,46.43848,38.62569
151.37002,12.61415,781.94998,-0.13665,46.50472,38.62168
151.57000,12.63083,781.69024,-0.13665,46.57145,38.60885
151.77000,12.64751,781.66658,-0.13665,46.63817,38.60768
151.97000,12.66407,781.64265,-0.13665,46.70442,38.60650
152.17002,12.68081,781.41522,-0.13665,46.77139,38.59527
152.37002,12.69755,780.72874,-0.13665,46.83835,38.56136
152.57000,12.71417,780.01749,-0.13665,46.90483,38.52623
152.77000,12.73080,780.64352,-0.13665,46.97132,38.55715
152.97000,12.74748,780.44967,-0.13665,47.03804,38.54758
153.17002,12.76422,780.54504,-0.13665,47.10501,38.55229
153.37002,12.78084,779.82354,-0.13665,47.17150,38.51665
153.57000,12.79752,780.01260,-0.13665,47.23822,38.52599
153.77000,12.81420,780.12128,-0.13665,47.30494,38.53136
153.97000,12.83076,779.67476,-0.13665,47.37119,38.50930
154.17002,12.84739,779.98694,-0.13665,47.43768,38.52472
154.37002,12.86413,779.07024,-0.13665,47.50464,38.47945
154.57000,12.88081,779.48403,-0.13665,47.57137,38.49988
154.77000,12.89749,779.29730,-0.13665,47.63809,38.49066
154.97000,12.91411,778.77729,-0.13665,47.70457,38.46498
155.17002,12.93079,778.79857,-0.13665,47.77130,38.46603
155.37002,12.94741,778.82656,-0.13665,47.83779,38.46741
155.57000,12.96415,778.00411,-0.13665,47.90475,38.42679
155.77000,12.98090,778.26483,-0.13665,47.97172,38.43967
155.97000,12.99752,778.40039,-0.13665,48.03820,38.44636
156.17002,13.01414,778.03778,-0.13665,48.10469,38.42845
156.37002,13.03082,777.75419,-0.13665,48.17142,38.41444
156.57000,13.04750,777.78185,-0.13665,48.23814,38.41581
156.77000,13.06418,777.55479,-0.13665,48.30486,38.40459
156.97000,13.08081,777.60480,-0.13665,48.37135,38.40707
157.17002,13.09749,776.98245,-0.13665,48.43808,38.37633
157.37002,13.11411,777.88313,-0.13665,48.50456,38.42081
157.57000,13.13079,776.99176,-0.13665,48.57128,38.37679
157.77000,13.14759,776.58487,-0.13665,48.63849,38.35669
157.97000,13.16421,776.65914,-0.13665,48.70498,38.36036
158.17002,13.18083,776.76177,-0.13665,48.77146,38.36543
158.37002,13.19757,776.63832,-0.13665,48.83842,38.35933
158.57000,13.21419,776.40400,-0.13665,48.90491,38.34776
158.77000,13.23082,775.96731,-0.13665,48.97140,38.32619
158.97000,13.24756,775.69704,-0.13665,49.03836,38.31284
159.17002,13.26412,776.04200,-0.13665,49.10461,38.32988
159.37002,13.28080,775.56591,-0.13665,49.17133,38.30636
159.57000,13.29754,775.54509,-0.13665,49.23830,38.30533
159.77000,13.31422,775.19715,-0.13665,49.30502,38.28815
159.97000,13.33078,775.46001,-0.13665,49.37127,38.30113
160.17002,13.34747,774.88692,-0.13665,49.43800,38.27282
160.37002,13.36421,775.66979,-0.13665,49.50496,38.31149
160.57000,13.38083,774.95235,-0.13665,49.57145,38.27606
160.77000,13.39751,774.39304,-0.13665,49.63817,38.24843
160.97000,13.41419,774.18690,-0.13665,49.70489,38.23825
161.17002,13.43081,774.06541,-0.13665,49.77138,38.23225
161.37002,13.44749,774.30955,-0.13665,49.83810,38.24431
161.57000,13.46412,773.57539,-0.13665,49.90459,38.20805
161.77000,13.48080,773.31169,-0.13665,49.97132,38.19502
161.97000,13.49748,773.15820,-0.13665,50.03804,38.18744
162.17002,13.51416,773.07397,-0.13665,50.10477,38.18328
162.37002,13.53084,773.03289,-0.13665,50.17149,38.18125
162.57000,13.54746,772.86423,-0.13665,50.23798,38.17292
162.77000,13.56408,772.83671,-0.13665,50.30447,38.17156
162.97000,13.58082,772.60905,-0.13665,50.37143,38.16032
163.17002,13.59751,772.16942,-0.13665,50.43815,38.13860
163.37002,13.61419,771.86963,-0.13665,50.50488,38.12379
163.57000,13.63081,772.36970,-0.13665,50.57136,38.14849
163.77000,13.64749,771.72709,-0.13665,50.63809,38.11676
163.97000,13.66411,771.77794,-0.13665,50.70457,38.11927
164.17002,13.68085,771.98506,-0.13665,50.77154,38.12950
164.37002,13.69759,770.86100,-0.13665,50.83851,38.07398
164.57000,13.71410,771.78897,-0.13665,50.90451,38.11981
164.77000,13.73078,771.34827,-0.13665,50.97123,38.09805
164.97000,13.74758,771.04960,-0.13665,51.03844,38.08329
165.17002,13.76414,770.16400,-0.13665,51.10468,38.03955
165.37002,13.78082,770.19762,-0.13665,51.17141,38.04121
165.57000,13.79756,769.88284,-0.13665,51.23838,38.02567
165.77000,13.81412,770.38230,-0.13665,51.30462,38.05033
165.97000,13.83080,770.01280,-0.13665,51.37135,38.03209
166.17002,13.84749,769.77806,-0.13665,51.43808,38.02049
166.37002,13.86423,769.54849,-0.13665,51.50504,38.00915
166.57000,13.88079,769.33247,-0.13665,51.57129,37.99848
166.77000,13.89741,768.75561,-0.13665,51.63777,37.96999
166.97000,13.91421,768.96930,-0.13665,51.70497,37.98055
167.17002,13.93077,768.85209,-0.13665,51.77122,37.97475
167.37002,13.94745,768.35593,-0.13665,51.83795,37.95025
167.57000,13.96425,768.69270,-0.13665,51.90515,37.96688
167.77000,13.98076,768.17176,-0.13665,51.97116,37.94115
167.97000,13.99744,768.19109,-0.13665,52.03788,37.94211
168.17002,14.01412,767.38433,-0.13665,52.10460,37.90226
168.37002,14.03092,768.44920,-0.13665,52.17181,37.95486
168.57000,14.04754,768.05297,-0.13665,52.23830,37.93529
168.77000,14.06416,767.13860,-0.13665,52.30478,37.89013
168.97000,14.08084,767.35774,-0.13665,52.37150,37.90095
169.17002,14.09741,766.91089,-0.13665,52.43775,37.87888
169.37002,14.11421,766.38553,-0.13665,52.50496,37.85293
169.57000,14.13095,766.16919,-0.13665,52.57192,37.84224
169.77000,14.14751,766.11354,-0.13665,52.63817,37.83949
169.97000,14.16419,765.52406,-0.13665,52.70489,37.81038
170.17002,14.18081,765.76713,-0.13665,52.77138,37.82238
170.37002,14.19743,765.51642,-0.13665,52.83786,37.81000
170.57000,14.21412,765.32569,-0.13665,52.90459,37.80058
170.77000,14.23086,765.35568,-0.13665,52.97155,37.80206
170.97000,14.24760,764.87106,-0.13665,53.03851,37.77813
171.17002,14.26410,764.87362,-0.13665,53.10453,37.77825
171.37002,14.28078,764.49616,-0.13664,53.17125,37.75961
171.57000,14.29764,764.89537,-0.13664,53.23870,37.77933
171.77000,14.31420,764.48540,-0.13664,53.30494,37.75908
171.97000,14.33082,763.81024,-0.13664,53.37143,37.72573
172.17002,14.34751,763.42449,-0.13664,53.43815,37.70668
172.37002,14.36413,763.70602,-0.13664,53.50464,37.72058
172.57000,14.38069,763.30812,-0.13664,53.57088,37.70093
172.77000,14.39749,763.01945,-0.13664,53.63809,37.68667
172.97000,14.41429,763.15678,-0.13665,53.70529,37.69345
173.17002,14.43073,762.52231,-0.13664,53.77105,37.66212
173.37002,14.44747,761.43658,-0.13665,53.83803,37.60849
173.57000,14.46433,761.88897,-0.13664,53.90546,37.63084
173.77000,14.48084,761.52254,-0.13664,53.97148,37.61274
173.97000,14.49752,761.28659,-0.13664,54.03820,37.60109
174.17002,14.51426,760.94042,-0.13665,54.10516,37.58398
174.37002,14.53076,761.51029,-0.13664,54.17117,37.61213
174.57000,14.54738,760.82177,-0.13664,54.23765,37.57812
174.77000,14.56424,760.90316,-0.13664,54.30509,37.58215
174.97000,14.58092,759.56667,-0.13665,54.37183,37.51614
175.17002,14.59742,759.76858,-0.13665,54.43783,37.52611
175.37002,14.61411,759.78846,-0.13664,54.50456,37.52709
175.57000,14.63085,759.39391,-0.13664,54.57152,37.50760
175.77000,14.64741,759.27502,-0.13664,54.63777,37.50173
175.97000,14.66415,758.99833,-0.13664,54.70473,37.48806
176.17002,14.68089,758.42105,-0.13665,54.77169,37.45955
176.37002,14.69751,757.74151,-0.13665,54.83819,37.42599
176.57000,14.71407,757.49503,-0.13664,54.90443,37.41381
176.77000,14.73082,757.71362,-0.13664,54.97139,37.42461
176.97000,14.74756,756.81936,-0.13664,55.03836,37.38044
177.17002,14.76418,756.60315,-0.13664,55.10484,37.36976
177.37002,14.78086,755.63868,-0.13664,55.17157,37.32212
177.57000,14.79748,755.02694,-0.13664,55.23806,37.29191
177.77000,14.81410,755.24366,-0.13664,55.30454,37.30262
177.97000,14.83084,754.29883,-0.13665,55.37151,37.25595
178.17002,14.84758,753.42190,-0.13664,55.43847,37.21264
178.37002,14.86415,752.92150,-0.13665,55.50472,37.18792
178.57000,14.88077,752.35199,-0.13664,55.57120,37.15979
178.77000,14.89751,752.89053,-0.13664,55.63817,37.18639
178.97000,14.91413,751.70691,-0.13664,55.70465,37.12793
179.17002,14.93081,750.02629,-0.13664,55.77137,37.04492
179.37002,14.94755,749.40040,-0.13665,55.83834,37.01401
179.57000,14.96417,748.61008,-0.13664,55.90483,36.97497
179.77000,14.98074,747.49971,-0.13665,55.97107,36.92013
179.97000,14.99742,747.14054,-0.13664,56.03780,36.90239
180.17002,15.01422,745.96405,-0.13665,56.10501,36.84428
180.37002,15.03084,744.12101,-0.13664,56.17148,36.75325
180.57000,15.04746,742.03433,-0.13664,56.23797,36.65018
180.77000,15.06420,739.45750,-0.13664,56.30494,36.52291
180.97000,15.08082,735.82707,-0.13664,56.37142,36.34360
181.17002,15.09750,728.53812,-0.13664,56.43815,35.98359
181.37002,15.11430,156.77211,-0.13665,56.50535,7.74321
181.38600,15.11562,2.48411,-0.13663,56.51062,0.12269