File: Manufatura Aditiva/Classificação Orientação/Ensaios/Ensaios SLS/Tracao_OLABI_07_06_2018_SLS_XZ2.is_metal_RawData/Specimen_RawData_3.csv
Time,Extension,Load,Strain 1,Tensile strain,Tensile stress
(sec),(mm),(N),(mm/mm),(%),(MPa)
0.00000,0.00006,24.41640,0.00096,0.09564,1.17172
0.20000,0.01375,30.12005,0.00114,0.11430,1.44544
0.40000,0.03265,39.56844,0.00146,0.14608,1.89886
0.60000,0.04986,48.86147,0.00175,0.17503,2.34483
0.80000,0.06673,57.05813,0.00203,0.20322,2.73818
1.00000,0.08335,64.87842,0.00231,0.23077,3.11347
1.20000,0.10003,73.43537,0.00259,0.25869,3.52411
1.40000,0.11683,82.12797,0.00287,0.28701,3.94126
1.60000,0.13339,89.91031,0.00315,0.31469,4.31473
1.80000,0.14995,97.55151,0.00343,0.34289,4.68142
2.00000,0.16663,105.54682,0.00371,0.37101,5.06511
2.20000,0.18331,113.37206,0.00399,0.39857,5.44064
2.40000,0.19994,120.67958,0.00426,0.42648,5.79132
2.60000,0.21668,128.27320,0.00455,0.45509,6.15573
2.80000,0.23336,135.73037,0.00483,0.48318,6.51360
3.00000,0.24998,143.66196,0.00511,0.51081,6.89423
3.20000,0.26672,150.88655,0.00539,0.53898,7.24093
3.40000,0.28340,158.83774,0.00567,0.56747,7.62250
3.60000,0.30002,165.67759,0.00596,0.59575,7.95074
3.80000,0.31665,172.83224,0.00623,0.62334,8.29409
4.00000,0.33327,177.74247,0.00644,0.64430,8.52973
4.20000,0.34995,185.29792,0.00672,0.67240,8.89231
4.40000,0.36663,192.48256,0.00700,0.70007,9.23709
4.60000,0.38331,199.65777,0.00728,0.72819,9.58143
4.80000,0.39999,206.70604,0.00757,0.75654,9.91967
5.00000,0.41667,214.04556,0.00784,0.78431,10.27189
5.20000,0.43335,220.98671,0.00812,0.81154,10.60499
5.40000,0.45004,228.19007,0.00840,0.84041,10.95067
5.60000,0.46666,235.27413,0.00868,0.86839,11.29063
5.80000,0.48334,242.41589,0.00897,0.89692,11.63336
6.00000,0.50002,249.19410,0.00925,0.92492,11.95864
6.20000,0.51664,255.85224,0.00952,0.95247,12.27816
6.40000,0.53326,262.68137,0.00981,0.98134,12.60588
6.60000,0.55000,268.99257,0.01009,1.00948,12.90875
6.80000,0.56674,275.40987,0.01038,1.03760,13.21671
7.00000,0.58331,283.06092,0.01066,1.06555,13.58388
7.20000,0.59993,289.27634,0.01094,1.09375,13.88215
7.40000,0.61673,296.31583,0.01122,1.12217,14.21997
7.60000,0.63329,302.09178,0.01151,1.15104,14.49716
7.80000,0.64997,308.14710,0.01179,1.17880,14.78775
8.00000,0.66671,313.40718,0.01202,1.20203,15.04018
8.20000,0.68333,318.98390,0.01229,1.22852,15.30780
8.40000,0.70002,325.40197,0.01257,1.25744,15.61580
8.60000,0.71664,331.88718,0.01286,1.28636,15.92702
8.80000,0.73344,337.54748,0.01314,1.31412,16.19865
9.00000,0.75000,343.64101,0.01342,1.34245,16.49107
9.20000,0.76662,350.18278,0.01372,1.37224,16.80501
9.40000,0.78336,355.97847,0.01401,1.40137,17.08314
9.60000,0.79992,362.02746,0.01430,1.42959,17.37343
9.80000,0.81666,367.61612,0.01458,1.45840,17.64162
10.00000,0.83341,373.37034,0.01488,1.48789,17.91776
10.20000,0.84997,378.83054,0.01517,1.51681,18.17979
10.40000,0.86671,384.96365,0.01546,1.54598,18.47412
10.60000,0.88333,390.02453,0.01575,1.57463,18.71699
10.80000,0.90007,395.91286,0.01604,1.60446,18.99956
11.00000,0.91669,401.09376,0.01634,1.63387,19.24819
11.20000,0.93331,406.53981,0.01663,1.66304,19.50954
11.40000,0.95000,411.56965,0.01693,1.69282,19.75092
11.60000,0.96656,415.45872,0.01716,1.71561,19.93755
11.80000,0.98330,420.49866,0.01745,1.74467,20.17941
12.00000,1.00010,424.89804,0.01774,1.77436,20.39054
12.20000,1.01666,430.21399,0.01804,1.80447,20.64565
12.40000,1.03328,435.23004,0.01834,1.83421,20.88636
12.60000,1.04996,440.21825,0.01864,1.86377,21.12574
12.80000,1.06664,445.14881,0.01894,1.89437,21.36236
13.00000,1.08333,449.81837,0.01924,1.92375,21.58645
13.20000,1.10001,454.25491,0.01952,1.95179,21.79935
13.40000,1.11675,459.19190,0.01982,1.98209,22.03628
13.60000,1.13325,463.79943,0.02013,2.01261,22.25739
13.80000,1.14999,468.48906,0.02044,2.04377,22.48244
14.00000,1.16673,472.55224,0.02074,2.07429,22.67743
14.20000,1.18329,477.14035,0.02105,2.10509,22.89761
14.40000,1.19998,481.96604,0.02137,2.13654,23.12919
14.60000,1.21672,486.46000,0.02168,2.16759,23.34485
14.80000,1.23334,490.46497,0.02199,2.19916,23.53705
15.00000,1.24990,494.30574,0.02230,2.23024,23.72136
15.20000,1.26664,496.93426,0.02255,2.25472,23.84750
15.40000,1.28344,501.80024,0.02286,2.28614,24.08102
15.60000,1.29994,504.81269,0.02318,2.31789,24.22558
15.80000,1.31656,509.34087,0.02349,2.34930,24.44289
16.00000,1.33343,512.53508,0.02381,2.38113,24.59617
16.20000,1.34993,517.10377,0.02413,2.41329,24.81542
16.40000,1.36667,520.44922,0.02446,2.44575,24.97597
16.60000,1.38341,524.35785,0.02478,2.47788,25.16354
16.80000,1.39997,528.00030,0.02510,2.50999,25.33834
17.00000,1.41659,531.23576,0.02543,2.54277,25.49361
17.20000,1.43333,534.74600,0.02575,2.57522,25.66206
17.40000,1.45001,538.05993,0.02608,2.60768,25.82109
17.60000,1.46664,541.34494,0.02640,2.64027,25.97874
17.80000,1.48326,545.14278,0.02673,2.67346,26.16099
18.00000,1.50000,547.70699,0.02706,2.70639,26.28405
18.20000,1.51656,551.67824,0.02739,2.73945,26.47462
18.40000,1.53330,554.36105,0.02772,2.77229,26.60337
18.60000,1.55004,557.23018,0.02806,2.80564,26.74106
18.80000,1.56666,560.58359,0.02839,2.83946,26.90199
19.00000,1.58341,562.21089,0.02865,2.86517,26.98008
19.20000,1.60003,565.54261,0.02899,2.89902,27.13997
19.40000,1.61665,568.27022,0.02932,2.93235,27.27086
19.60000,1.63339,571.82591,0.02966,2.96578,27.44150
19.80000,1.65001,574.49206,0.02999,2.99934,27.56944
20.00000,1.66663,577.78331,0.03033,3.03265,27.72739
20.20000,1.68325,580.59236,0.03067,3.06726,27.86219
20.40000,1.69993,582.52229,0.03101,3.13399,27.95481
20.55000,1.71249,584.55127,0.03126,3.18421,28.05218
20.75000,1.72917,587.79065,0.03160,3.25093,28.20763
20.95000,1.74579,589.53445,0.03194,3.31742,28.29132
21.15000,1.76253,592.18826,0.03228,3.38438,28.41867
21.35000,1.77910,595.01515,0.03263,3.45063,28.55433
21.55000,1.79578,597.45144,0.03297,3.51736,28.67125
21.75000,1.81264,600.17849,0.03332,3.58480,28.80212
21.95000,1.82920,602.83588,0.03367,3.65105,28.92964
22.15000,1.84582,604.93210,0.03390,3.71753,29.03024
22.35000,1.86250,607.24402,0.03457,3.78426,29.14119
22.55000,1.87912,610.31417,0.01889,3.85074,29.28852
22.75000,1.89575,611.13783,0.00109,3.91723,29.32805
22.95000,1.91249,613.09156,0.00136,3.98419,29.42180
23.15000,1.92917,614.15806,0.00434,4.05092,29.47298
23.35000,1.94573,616.97802,0.00286,4.11716,29.60831
23.55000,1.96247,619.61510,0.00249,4.18413,29.73487
23.75000,1.97927,622.16846,0.00283,4.25133,29.85740
23.95000,1.99589,624.25244,0.00600,4.31782,29.95741
24.15000,2.01251,626.22833,0.00679,4.38430,30.05223
24.35000,2.02920,628.93564,0.00749,4.45103,30.18215
24.55000,2.04582,629.94170,0.02380,4.51751,30.23043
24.75000,2.06250,632.58875,-0.13782,4.58424,30.35746
24.95000,2.07918,634.58085,-0.13882,4.65096,30.45306
25.15000,2.09580,637.12504,-0.13884,4.71745,30.57515
25.35000,2.11242,638.94140,-0.13884,4.78394,30.66232
25.55000,2.12904,641.29191,-0.13884,4.85042,30.77512
25.75000,2.14578,642.79861,-0.13885,4.91739,30.84742
25.95000,2.16253,644.81813,-0.13885,4.98435,30.94434
26.15000,2.17921,646.62923,-0.13885,5.05108,31.03125
26.35000,2.19583,648.25872,-0.13885,5.11756,31.10945
26.55000,2.21251,650.19508,-0.13885,5.18429,31.20237
26.75000,2.22919,652.61074,-0.13885,5.25101,31.31830
26.95000,2.24587,654.51735,-0.13885,5.31774,31.40980
27.15000,2.26255,656.01249,-0.13885,5.38446,31.48155
27.35000,2.27924,657.80152,-0.13885,5.45119,31.56740
27.55000,2.29580,659.50556,-0.13885,5.51743,31.64918
27.75000,2.31248,661.49156,-0.13885,5.58416,31.74448
27.95000,2.32916,661.36974,-0.13885,5.65088,31.73864
28.15000,2.34584,663.97362,-0.13885,5.71761,31.86360
28.35000,2.36252,665.34057,-0.13885,5.78433,31.92920
28.55000,2.37914,667.63745,-0.13885,5.85082,32.03942
28.75000,2.39576,669.81437,-0.13885,5.91731,32.14389
28.95000,2.41251,671.63301,-0.13885,5.98427,32.23116
29.15000,2.42919,672.76591,-0.13885,6.05100,32.28553
29.35000,2.44587,674.20835,-0.13885,6.11772,32.35475
29.55000,2.46255,676.28594,-0.13885,6.18445,32.45446
29.75000,2.47923,678.15925,-0.13886,6.25117,32.54435
29.95000,2.49585,679.05858,-0.13886,6.31766,32.58751
30.15000,2.51247,680.15428,-0.13886,6.38414,32.64009
30.35000,2.52927,682.39067,-0.13885,6.45135,32.74742
30.55000,2.54584,684.69471,-0.13886,6.51759,32.85799
30.75000,2.56240,685.84788,-0.13885,6.58384,32.91333
30.95000,2.57914,687.80063,-0.13885,6.65080,33.00704
31.15000,2.59582,688.89176,-0.13886,6.71753,33.05940
31.35000,2.61244,690.42379,-0.13885,6.78401,33.13292
31.55000,2.62918,691.64690,-0.13886,6.85098,33.19162
31.75000,2.64580,693.16095,-0.13885,6.91746,33.26427
31.95000,2.66243,694.49595,-0.13886,6.98395,33.32834
32.15000,2.67911,696.68032,-0.13885,7.05068,33.43317
32.35000,2.69585,698.30772,-0.13886,7.11764,33.51126
32.55000,2.71259,699.55233,-0.13886,7.18460,33.57099
32.75000,2.72915,700.92496,-0.13886,7.25085,33.63686
32.95000,2.74583,700.28873,-0.13886,7.31758,33.60633
33.15000,2.76251,701.97880,-0.13886,7.38430,33.68744
33.35000,2.77919,703.47828,-0.13886,7.45103,33.75940
33.55000,2.79588,705.34572,-0.13886,7.51775,33.84901
33.75000,2.81250,706.92264,-0.13886,7.58424,33.92469
33.95000,2.82912,708.35464,-0.13886,7.65072,33.99341
34.15000,2.84574,709.33900,-0.13886,7.71721,34.04065
34.35000,2.86248,711.34614,-0.13886,7.78417,34.13697
34.55000,2.87922,712.18465,-0.13886,7.85114,34.17721
34.75000,2.89584,713.68455,-0.13886,7.91762,34.24919
34.95000,2.91253,715.22170,-0.13886,7.98435,34.32295
35.15000,2.92915,715.76936,-0.13886,8.05084,34.34924
35.35000,2.94577,717.68621,-0.13886,8.11732,34.44122
35.55000,2.96257,719.19509,-0.13886,8.18452,34.51363
35.75000,2.97919,720.29596,-0.13886,8.25101,34.56646
35.95000,2.99575,721.34146,-0.13886,8.31726,34.61663
36.15000,3.01249,722.37384,-0.13886,8.38422,34.66618
36.35000,3.02917,723.76649,-0.13886,8.45095,34.73301
36.55000,3.04580,724.53828,-0.13886,8.51743,34.77005
36.75000,3.06254,726.19356,-0.13886,8.58440,34.84948
36.95000,3.07928,727.42621,-0.13886,8.65136,34.90864
37.15000,3.09572,728.43819,-0.13886,8.71713,34.95720
37.35000,3.11252,729.57925,-0.13886,8.78433,35.01196
37.55000,3.12926,730.65194,-0.13886,8.85130,35.06344
37.75000,3.14582,731.67984,-0.13886,8.91754,35.11277
37.95000,3.16245,733.12656,-0.13886,8.98403,35.18219
38.15000,3.17919,734.40652,-0.13886,9.05099,35.24362
38.35000,3.19581,735.56863,-0.13886,9.11748,35.29939
38.55000,3.21243,736.88333,-0.13886,9.18397,35.36248
38.75000,3.22911,736.60514,-0.13886,9.25069,35.34913
38.95000,3.24579,737.10042,-0.13886,9.31741,35.37290
39.15000,3.26241,738.00585,-0.13886,9.38390,35.41635
39.35000,3.27915,739.36647,-0.13886,9.45086,35.48164
39.55000,3.29590,740.58720,-0.13886,9.51783,35.54023
39.75000,3.31246,741.76365,-0.13886,9.58408,35.59668
39.95000,3.32920,742.15075,-0.13886,9.65104,35.61526
40.15000,3.34588,743.06256,-0.13886,9.71777,35.65902
40.35000,3.36256,744.50788,-0.13886,9.78449,35.72837
40.55000,3.37912,746.23805,-0.13886,9.85074,35.81141
40.75000,3.39580,747.03796,-0.13886,9.91746,35.84979
40.95000,3.41255,748.10721,-0.13886,9.98443,35.90110
41.15000,3.42917,749.39253,-0.13886,10.05091,35.96278
41.35000,3.44579,749.55956,-0.13886,10.11740,35.97080
41.55000,3.46253,750.63757,-0.13886,10.18436,36.02253
41.75000,3.47909,752.65458,-0.13886,10.25061,36.11933
41.95000,3.49583,753.00722,-0.13886,10.31757,36.13625
42.15000,3.51257,754.42209,-0.13886,10.38454,36.20415
42.35000,3.52919,754.91904,-0.13886,10.45102,36.22800
42.55000,3.54582,755.59481,-0.13886,10.51751,36.26043
42.75000,3.56250,757.23217,-0.13886,10.58424,36.33900
42.95000,3.57924,757.57252,-0.13886,10.65120,36.35534
43.15000,3.59574,757.93052,-0.13886,10.71721,36.37252
43.35000,3.61248,759.04010,-0.13886,10.78417,36.42577
43.55000,3.62922,759.81906,-0.13886,10.85114,36.46315
43.75000,3.64572,760.62288,-0.13886,10.91714,36.50172
43.95000,3.66252,761.55509,-0.13886,10.98435,36.54646
44.15000,3.67927,761.83118,-0.13886,11.05131,36.55971
44.35000,3.69583,763.31091,-0.13886,11.11756,36.63072
44.55000,3.71245,764.37886,-0.13886,11.18404,36.68197
44.75000,3.72919,764.96820,-0.13886,11.25101,36.71025
44.95000,3.74593,765.87754,-0.13886,11.31797,36.75389
45.15000,3.76237,766.75564,-0.13885,11.38374,36.79603
45.35000,3.77923,767.55276,-0.13886,11.45118,36.83428
45.55000,3.79586,768.41842,-0.13886,11.51767,36.87582
45.75000,3.81248,769.09182,-0.13886,11.58415,36.90814
45.95000,3.82916,770.26542,-0.13886,11.65088,36.96446
46.15000,3.84590,771.47386,-0.13886,11.71784,37.02245
46.35000,3.86246,771.30939,-0.13886,11.78409,37.01456
46.55000,3.87920,770.44587,-0.13886,11.85105,36.97312
46.75000,3.89582,771.77309,-0.13886,11.91754,37.03681
46.95000,3.91244,773.44971,-0.13886,11.98403,37.11727
47.15000,3.92913,773.73134,-0.13886,12.05075,37.13079
47.35000,3.94581,774.08412,-0.13886,12.11748,37.14772
47.55000,3.96255,775.63939,-0.13886,12.18444,37.22235
47.75000,3.97911,775.97867,-0.13886,12.25069,37.23864
47.95000,3.99579,776.65686,-0.13886,12.31741,37.27118
48.15000,4.01247,777.76448,-0.13886,12.38414,37.32433
48.35000,4.02915,778.00625,-0.13886,12.45086,37.33594
48.55000,4.04578,778.63042,-0.13885,12.51735,37.36589
48.75000,4.06258,779.35793,-0.13885,12.58455,37.40080
48.95000,4.07914,780.33600,-0.13881,12.65080,37.44774
49.15000,4.09576,781.44874,-0.13881,12.71728,37.50114
49.35000,4.11244,781.74928,-0.13881,12.78401,37.51556
49.55000,4.12918,782.07264,-0.13881,12.85097,37.53108
49.75000,4.14580,782.85737,-0.13881,12.91746,37.56874
49.95000,4.16248,783.73011,-0.13881,12.98418,37.61062
50.15000,4.17917,784.66926,-0.13881,13.05091,37.65569
50.35000,4.19573,785.85865,-0.13881,13.11716,37.71277
50.55000,4.21253,786.12808,-0.13881,13.18436,37.72570
50.75000,4.22933,786.38401,-0.13881,13.25156,37.73798
50.95000,4.24583,786.59663,-0.13881,13.31757,37.74818
51.15000,4.26245,787.59547,-0.13881,13.38406,37.79612
51.35000,4.27925,788.19720,-0.13881,13.45126,37.82499
51.55000,4.29582,789.54892,-0.13881,13.51751,37.88986
51.75000,4.31250,789.28703,-0.13881,13.58423,37.87729
51.95000,4.32918,790.42837,-0.13881,13.65096,37.93206
52.15000,4.34586,789.92611,-0.13881,13.71768,37.90796
52.35000,4.36248,791.63155,-0.13881,13.78417,37.98980
52.55000,4.37910,791.57278,-0.13881,13.85065,37.98698
52.75000,4.39590,792.49684,-0.13881,13.91786,38.03133
52.95000,4.41252,792.95803,-0.13881,13.98434,38.05346
53.15000,4.42915,793.79659,-0.13881,14.05083,38.09370
53.35000,4.44583,794.37820,-0.13881,14.11756,38.12162
53.55000,4.46251,794.76293,-0.13882,14.18428,38.14008
53.75000,4.47913,794.82961,-0.13881,14.25077,38.14328
53.95000,4.49581,795.86646,-0.13881,14.31749,38.19304
54.15000,4.51249,796.34236,-0.13881,14.38422,38.21587
54.35000,4.52911,796.56178,-0.13881,14.45070,38.22640
54.55000,4.54579,796.88802,-0.13881,14.51743,38.24206
54.75000,4.56248,797.38740,-0.13881,14.58415,38.26602
54.95000,4.57922,797.98819,-0.13882,14.65112,38.29486
55.15000,4.59590,798.97689,-0.13882,14.71784,38.34230
55.35000,4.61252,798.80180,-0.13881,14.78433,38.33390
55.55000,4.62914,799.22257,-0.13881,14.85081,38.35409
55.75000,4.64588,800.03850,-0.13881,14.91778,38.39325
55.95000,4.66250,800.44558,-0.13881,14.98426,38.41278
56.15000,4.67931,800.36689,-0.13881,15.05147,38.40901
56.35000,4.69587,801.54520,-0.13881,15.11771,38.46555
56.55000,4.71243,801.50012,-0.13881,15.18396,38.46339
56.75000,4.72917,800.20158,-0.13881,15.25093,38.40107
56.95000,4.74573,801.08996,-0.13881,15.31717,38.44371
57.15000,4.76247,801.91391,-0.13881,15.38414,38.48325
57.35000,4.77921,802.27237,-0.13881,15.45110,38.50045
57.55000,4.79577,803.23527,-0.13881,15.51735,38.54666
57.75000,4.81246,803.12751,-0.13881,15.58407,38.54149
57.95000,4.82920,803.90479,-0.13881,15.65104,38.57879
58.15000,4.84594,803.94093,-0.13881,15.71800,38.58052
58.35000,4.86250,804.74988,-0.13881,15.78425,38.61934
58.55000,4.87912,805.34238,-0.13882,15.85073,38.64778
58.75000,4.89586,805.82136,-0.13881,15.91770,38.67076
58.95000,4.91242,806.50682,-0.13881,15.98395,38.70366
59.15000,4.92917,806.59939,-0.13881,16.05091,38.70810
59.35000,4.94591,807.47474,-0.13881,16.11787,38.75011
59.55000,4.96247,807.43087,-0.13881,16.18412,38.74800
59.75000,4.97909,808.59158,-0.13881,16.25060,38.80370
59.95000,4.99583,807.56415,-0.13881,16.31757,38.75440
60.15000,5.01251,808.68620,-0.13881,16.38429,38.80825
60.35000,5.02925,808.83736,-0.13881,16.45126,38.81550
60.55000,5.04581,809.09822,-0.13881,16.51750,38.82802
60.75000,5.06250,809.69948,-0.13881,16.58423,38.85687
60.95000,5.07918,810.01678,-0.13881,16.65096,38.87210
61.15000,5.09580,810.80897,-0.13881,16.71744,38.91011
61.35000,5.11254,810.64804,-0.13881,16.78441,38.90239
61.55000,5.12910,811.16697,-0.13882,16.85065,38.92730
61.75000,5.14578,811.61102,-0.13881,16.91738,38.94860
61.95000,5.16246,812.13852,-0.13881,16.98410,38.97392
62.15000,5.17920,812.56274,-0.13881,17.05107,38.99428
62.35000,5.19583,812.59450,-0.13881,17.11755,38.99580
62.55000,5.21251,812.25391,-0.13881,17.18428,38.97946
62.75000,5.22913,812.51329,-0.13882,17.25076,38.99191
62.95000,5.24581,813.35986,-0.13881,17.31749,39.03253
63.15000,5.26249,813.31320,-0.13881,17.38421,39.03029
63.35000,5.27923,814.22608,-0.13881,17.45118,39.07410
63.55000,5.29585,814.21267,-0.13881,17.51766,39.07346
63.75000,5.31254,814.71791,-0.13881,17.58439,39.09770
63.95000,5.32916,813.91567,-0.13881,17.65087,39.05920
64.15000,5.34578,814.97263,-0.13881,17.71736,39.10992
64.35001,5.36252,815.91075,-0.13882,17.78432,39.15495
64.55000,5.37920,815.81362,-0.13881,17.85105,39.15028
64.75000,5.39582,816.15038,-0.13881,17.91754,39.16645
64.95000,5.41250,816.35127,-0.13882,17.98426,39.17609
65.15000,5.42912,816.06861,-0.13882,18.05075,39.16252
65.35001,5.44581,816.68254,-0.13881,18.11747,39.19198
65.55000,5.46249,817.31658,-0.13881,18.18420,39.22241
65.75000,5.47923,817.25800,-0.13881,18.25116,39.21960
65.95001,5.49591,817.64916,-0.13881,18.31789,39.23837
66.15000,5.51241,817.60632,-0.13882,18.38389,39.23631
66.35001,5.52915,818.14211,-0.13882,18.45086,39.26203
66.55000,5.54589,818.11417,-0.13882,18.51782,39.26068
66.75000,5.56257,818.14686,-0.13882,18.58455,39.26225
66.95001,5.57914,818.90896,-0.13882,18.65079,39.29883
67.15000,5.59582,818.25899,-0.13882,18.71752,39.26764
67.35001,5.61250,818.93764,-0.13882,18.78425,39.30021
67.55000,5.62918,819.08889,-0.13881,18.85097,39.30746
67.75000,5.64586,819.57839,-0.13881,18.91769,39.33095
67.95001,5.66248,820.71237,-0.13882,18.98418,39.38537
68.15000,5.67910,820.23395,-0.13882,19.05067,39.36241
68.35001,5.69579,819.75237,-0.13881,19.11739,39.33930
68.55000,5.71253,820.47852,-0.13882,19.18436,39.37415
68.75000,5.72915,820.77449,-0.13881,19.25084,39.38835
68.95001,5.74589,820.63796,-0.13882,19.31780,39.38180
69.15000,5.76251,821.29650,-0.13881,19.38429,39.41340
69.35001,5.77919,820.79740,-0.13882,19.45102,39.38945
69.55000,5.79581,821.47606,-0.13881,19.51750,39.42202
69.75000,5.81250,822.04416,-0.13881,19.58423,39.44928
69.95001,5.82924,822.12416,-0.13881,19.65119,39.45312
70.15000,5.84580,822.86820,-0.13882,19.71744,39.48883
70.35001,5.86242,822.65651,-0.13882,19.78392,39.47867
70.55000,5.87916,822.66210,-0.13881,19.85089,39.47894
70.75000,5.89584,822.79472,-0.13881,19.91761,39.48530
70.95001,5.91252,822.24691,-0.13882,19.98434,39.45901
71.15000,5.92920,822.53693,-0.13882,20.05106,39.47293
71.35001,5.94583,823.44012,-0.13881,20.11755,39.51627
71.55000,5.96251,822.98806,-0.13882,20.18428,39.49458
71.75000,5.97919,823.58643,-0.13881,20.25100,39.52330
71.95001,5.99593,823.59351,-0.13882,20.31796,39.52364
72.15000,6.01249,824.01875,-0.13882,20.38421,39.54404
72.35001,6.02911,823.41172,-0.13882,20.45070,39.51491
72.55000,6.04591,823.36869,-0.13882,20.51790,39.51285
72.75000,6.06247,824.18704,-0.13882,20.58415,39.55212
72.95001,6.07910,824.67077,-0.13882,20.65063,39.57533
73.15000,6.09584,824.18639,-0.13882,20.71760,39.55209
73.35001,6.11252,824.36185,-0.13882,20.78432,39.56051
73.55000,6.12914,824.29834,-0.13882,20.85081,39.55746
73.75000,6.14582,825.14985,-0.13882,20.91753,39.59832
73.95001,6.16250,824.89653,-0.13882,20.98426,39.58617
74.15000,6.17918,824.57522,-0.13882,21.05098,39.57075
74.35001,6.19587,825.06239,-0.13882,21.11771,39.59413
74.55000,6.21255,825.28619,-0.13882,21.18443,39.60487
74.75000,6.22911,825.71441,-0.13882,21.25068,39.62542
74.95001,6.24579,825.15329,-0.13882,21.31740,39.59849
75.15000,6.26253,825.92694,-0.13882,21.38437,39.63562
75.35001,6.27915,825.65481,-0.13882,21.45085,39.62255
75.55000,6.29577,825.84964,-0.13882,21.51734,39.63190
75.75000,6.31245,825.77094,-0.13882,21.58407,39.62813
75.95001,6.32914,825.97844,-0.13881,21.65079,39.63809
76.15000,6.34582,826.10920,-0.13882,21.71752,39.64436
76.35001,6.36256,826.69510,-0.13882,21.78448,39.67248
76.55000,6.37930,826.93435,-0.13882,21.85144,39.68396
76.75000,6.39574,826.63763,-0.13882,21.91721,39.66972
76.95001,6.41242,827.05114,-0.13882,21.98394,39.68956
77.15000,6.42922,826.63065,-0.13882,22.05114,39.66938
77.35001,6.44579,826.79242,-0.13881,22.11739,39.67715
77.55000,6.46253,824.51561,-0.13882,22.18435,39.56789
77.75000,6.47921,825.22156,-0.13882,22.25108,39.60176
77.95001,6.49583,825.43278,-0.13882,22.31756,39.61190
78.15000,6.51245,825.73649,-0.13881,22.38405,39.62648
78.35001,6.52913,825.41658,-0.13882,22.45078,39.61112
78.55000,6.54593,826.52615,-0.13882,22.51798,39.66437
78.75000,6.56249,825.41509,-0.13882,22.58423,39.61105
78.95001,6.57918,826.29248,-0.13882,22.65095,39.65316
79.15000,6.59598,826.86003,-0.13882,22.71815,39.68039
79.35001,6.61242,827.19149,-0.13882,22.78392,39.69630
79.55000,6.62916,827.15759,-0.13882,22.85089,39.69467
79.75000,6.64590,827.19838,-0.13882,22.91785,39.69663
79.95001,6.66252,827.69636,-0.13882,22.98434,39.72053
80.15000,6.67908,827.24076,-0.13882,23.05058,39.69867
80.35001,6.69583,827.23591,-0.13882,23.11755,39.69843
80.55000,6.71257,827.33314,-0.13882,23.18451,39.70310
80.75001,6.72913,827.36751,-0.13882,23.25076,39.70475
80.95001,6.74581,828.31038,-0.13882,23.31748,39.75000
81.15000,6.76255,827.76006,-0.13882,23.38445,39.72358
81.35001,6.77905,827.91597,-0.13882,23.45046,39.73107
81.55000,6.79579,828.15597,-0.13882,23.51742,39.74258
81.75001,6.81259,828.02782,-0.13882,23.58463,39.73643
81.95001,6.82916,828.47988,-0.13882,23.65087,39.75813
82.15000,6.84578,828.72463,-0.13882,23.71736,39.76987
82.35001,6.86246,828.65115,-0.13882,23.78408,39.76635
82.55000,6.87920,828.05566,-0.13882,23.85105,39.73777
82.75001,6.89582,828.25003,-0.13882,23.91753,39.74710
82.95001,6.91250,828.52449,-0.13882,23.98425,39.76027
83.15000,6.92918,827.84863,-0.13882,24.05098,39.72784
83.35001,6.94575,828.50074,-0.13882,24.11723,39.75913
83.55000,6.96237,828.63830,-0.13882,24.18371,39.76573
83.75001,6.97917,828.24184,-0.13882,24.25092,39.74670
83.95001,6.99585,828.64547,-0.13882,24.31764,39.76608
84.15000,7.01253,828.34801,-0.13882,24.38437,39.75180
84.35001,7.02915,828.46871,-0.13882,24.45085,39.75759
84.55000,7.04577,829.32329,-0.13882,24.51734,39.79860
84.75001,7.06251,828.58289,-0.13882,24.58430,39.76307
84.95001,7.07926,828.88715,-0.13882,24.65127,39.77767
85.15000,7.09594,828.77334,-0.13882,24.71799,39.77221
85.35001,7.11244,829.14447,-0.13882,24.78400,39.79002
85.55000,7.12912,828.54563,-0.13882,24.85072,39.76128
85.75001,7.14586,828.69586,-0.13882,24.91769,39.76849
85.95001,7.16248,829.16152,-0.13882,24.98418,39.79084
86.15000,7.17916,828.89190,-0.13882,25.05090,39.77790
86.35001,7.19584,828.81954,-0.13882,25.11763,39.77443
86.55000,7.21247,829.41055,-0.13882,25.18411,39.80279
86.75001,7.22909,829.16366,-0.13882,25.25060,39.79094
86.95001,7.24589,828.65413,-0.13882,25.31780,39.76649
87.15000,7.26263,828.17813,-0.13882,25.38477,39.74365
87.35001,7.27913,829.04585,-0.13882,25.45077,39.78529
87.55000,7.29581,828.91285,-0.13882,25.51750,39.77891
87.75001,7.31255,829.25307,-0.13882,25.58446,39.79523
87.95001,7.32918,828.89274,-0.13882,25.65095,39.77794
88.15000,7.34580,828.62275,-0.13882,25.71743,39.76498
88.35001,7.36254,828.88231,-0.13882,25.78440,39.77744
88.55000,7.37910,828.96305,-0.13882,25.85064,39.78131
88.75001,7.39578,829.11057,-0.13882,25.91737,39.78839
88.95001,7.41246,828.92263,-0.13882,25.98410,39.77938
89.15000,7.42920,828.51890,-0.13882,26.05106,39.76000
89.35001,7.44582,828.65059,-0.13882,26.11755,39.76632
89.55000,7.46251,829.23546,-0.13882,26.18427,39.79439
89.75001,7.47919,828.65087,-0.13882,26.25100,39.76633
89.95001,7.49581,828.09804,-0.13882,26.31748,39.73980
90.15000,7.51255,827.98358,-0.13882,26.38445,39.73431
90.35001,7.52923,828.35108,-0.13882,26.45117,39.75195
90.55000,7.54585,829.18294,-0.13882,26.51766,39.79187
90.75001,7.56253,828.13036,-0.13882,26.58438,39.74136
90.95001,7.57910,828.60552,-0.13882,26.65063,39.76416
91.15000,7.59578,828.34503,-0.13882,26.71735,39.75166
91.35001,7.61258,828.46973,-0.13882,26.78456,39.75764
91.55000,7.62914,828.31774,-0.13882,26.85080,39.75035
91.75001,7.64576,828.56193,-0.13882,26.91729,39.76207
91.95001,7.66250,828.04039,-0.13882,26.98425,39.73704
92.15000,7.67912,828.76105,-0.13882,27.05074,39.77162
92.35001,7.69586,828.62852,-0.13882,27.11770,39.76526
92.55000,7.71255,828.64845,-0.13882,27.18443,39.76622
92.75001,7.72917,828.50726,-0.13882,27.25092,39.75944
92.95001,7.74585,828.05939,-0.13882,27.31764,39.73795
93.15000,7.76247,828.26549,-0.13882,27.38413,39.74784
93.35001,7.77915,828.66801,-0.13881,27.45085,39.76716
93.55000,7.79583,828.27387,-0.13882,27.51758,39.74824
93.75001,7.81251,828.53334,-0.13882,27.58430,39.76069
93.95001,7.82907,827.86269,-0.13882,27.65055,39.72851
94.15000,7.84576,828.10549,-0.13882,27.71727,39.74016
94.35001,7.86256,828.50503,-0.13882,27.78448,39.75933
94.55000,7.87918,828.14777,-0.13882,27.85096,39.74219
94.75001,7.89586,827.66069,-0.13882,27.91769,39.71881
94.95001,7.91254,827.68723,-0.13882,27.98441,39.72009
95.15000,7.92910,828.15997,-0.13882,28.05066,39.74277
95.35001,7.94584,828.44980,-0.13882,28.11762,39.75668
95.55000,7.96253,827.35894,-0.13882,28.18435,39.70433
95.75001,7.97915,827.69878,-0.13882,28.25083,39.72065
95.95001,7.99583,827.62595,-0.13882,28.31756,39.71715
96.15000,8.01245,827.91736,-0.13882,28.38404,39.73113
96.35001,8.02919,828.46070,-0.13882,28.45100,39.75721
96.55000,8.04581,827.64681,-0.13882,28.51750,39.71815
96.75001,8.06243,828.04756,-0.13882,28.58398,39.73738
96.95001,8.07911,827.36108,-0.13882,28.65070,39.70444
97.15000,8.09580,827.36975,-0.13882,28.71743,39.70485
97.35001,8.11242,827.37766,-0.13882,28.78392,39.70523
97.55000,8.12916,827.69468,-0.13882,28.85088,39.72045
97.75001,8.14584,827.47173,-0.13882,28.91761,39.70975
97.95001,8.16258,827.32793,-0.13882,28.98457,39.70285
98.15000,8.17914,826.72238,-0.13882,29.05082,39.67379
98.35001,8.19582,827.54502,-0.13882,29.11755,39.71326
98.55000,8.21250,826.52839,-0.13882,29.18427,39.66448
98.75001,8.22913,826.81915,-0.13882,29.25075,39.67843
98.95001,8.24587,826.57067,-0.13882,29.31772,39.66651
99.15000,8.26249,826.30776,-0.13882,29.38420,39.65389
99.35001,8.27911,827.09119,-0.13882,29.45069,39.69149
99.55000,8.29579,826.74036,-0.13882,29.51741,39.67465
99.75001,8.31247,826.52932,-0.13882,29.58414,39.66452
99.95001,8.32921,826.22198,-0.13882,29.65110,39.64977
100.15000,8.34584,826.80974,-0.13882,29.71759,39.67798
100.35001,8.36252,826.50203,-0.13882,29.78432,39.66321
100.55000,8.37914,826.75274,-0.13882,29.85080,39.67524
100.75001,8.39582,826.23763,-0.13882,29.91753,39.65052
100.95001,8.41262,826.54171,-0.13882,29.98473,39.66512
101.15000,8.42912,826.03656,-0.13882,30.05074,39.64088
101.35001,8.44580,826.28047,-0.13882,30.11746,39.65258
101.55000,8.46254,826.19023,-0.13882,30.18443,39.64825
101.75001,8.47917,826.52289,-0.13882,30.25091,39.66422
101.95001,8.49579,825.79544,-0.13882,30.31740,39.62930
102.15000,8.51253,826.08936,-0.13882,30.38436,39.64341
102.35001,8.52921,825.71916,-0.13882,30.45109,39.62564
102.55000,8.54577,825.49937,-0.13882,30.51733,39.61510
102.75001,8.56251,825.81621,-0.13882,30.58430,39.63030
102.95001,8.57925,825.95944,-0.13882,30.65127,39.63717
103.15000,8.59582,825.66924,-0.13882,30.71751,39.62325
103.35001,8.61256,825.28070,-0.13882,30.78447,39.60460
103.55000,8.62924,825.71218,-0.13882,30.85120,39.62531
103.75001,8.64580,825.57425,-0.13882,30.91744,39.61869
103.95001,8.66248,825.03203,-0.13882,30.98417,39.59267
104.15000,8.67910,825.22957,-0.13882,31.05066,39.60215
104.35001,8.69584,825.38268,-0.13882,31.11762,39.60950
104.55000,8.71241,824.96470,-0.13882,31.18387,39.58944
104.75001,8.72909,824.75748,-0.13882,31.25059,39.57949
104.95001,8.74589,825.03380,-0.13882,31.31780,39.59275
105.15000,8.76251,824.92922,-0.13882,31.38428,39.58773
105.35001,8.77919,824.92922,-0.13882,31.45100,39.58773
105.55000,8.79593,824.80703,-0.13882,31.51797,39.58187
105.75001,8.81249,823.76879,-0.13882,31.58422,39.53205
105.95001,8.82911,824.20362,-0.13882,31.65070,39.55291
106.15000,8.84586,823.97116,-0.13882,31.71767,39.54176
106.35001,8.86254,824.57885,-0.13882,31.78439,39.57092
106.55000,8.87916,824.07789,-0.13882,31.85088,39.54688
106.75001,8.89584,823.73880,-0.13882,31.91760,39.53061
106.95001,8.91252,824.23594,-0.13882,31.98433,39.55447
107.15000,8.92902,823.58690,-0.13882,32.05034,39.52332
107.35001,8.94582,824.19114,-0.13882,32.11754,39.55231
107.55000,8.96256,823.66336,-0.13882,32.18450,39.52699
107.75001,8.97913,823.31300,-0.13882,32.25075,39.51017
107.95001,8.99581,823.92963,-0.13882,32.31747,39.53976
108.15000,9.01261,823.21959,-0.13882,32.38468,39.50569
108.35001,9.02911,823.38341,-0.13882,32.45069,39.51355
108.55000,9.04585,823.59491,-0.13882,32.51765,39.52370
108.75001,9.06265,823.67789,-0.13882,32.58485,39.52768
108.95001,9.07915,823.20608,-0.13882,32.65086,39.50504
109.15000,9.09578,822.82005,-0.13882,32.71735,39.48652
109.35001,9.11252,822.61991,-0.13882,32.78431,39.47691
109.55000,9.12926,823.12906,-0.13882,32.85128,39.50135
109.75001,9.14576,823.34643,-0.13882,32.91728,39.51178
109.95001,9.16244,822.53842,-0.13882,32.98401,39.47300
110.15000,9.17918,822.11150,-0.13882,33.05097,39.45251
110.35001,9.19580,821.88910,-0.13882,33.11746,39.44184
110.55000,9.21248,822.64906,-0.13882,33.18419,39.47831
110.75001,9.22929,821.92821,-0.13882,33.25139,39.44372
110.95001,9.24579,822.01753,-0.13882,33.31740,39.44801
111.15000,9.26247,822.41567,-0.13882,33.38412,39.46711
111.35001,9.27915,821.60654,-0.13882,33.45084,39.42828
111.55000,9.29583,822.13841,-0.13882,33.51757,39.45381
111.75001,9.31245,821.51080,-0.13882,33.58406,39.42369
111.95001,9.32913,821.76914,-0.13882,33.65078,39.43608
112.15000,9.34587,821.73953,-0.13882,33.71775,39.43467
112.35001,9.36244,821.19992,-0.13882,33.78399,39.40877
112.55000,9.37912,821.19470,-0.13882,33.85072,39.40852
112.75001,9.39586,820.92285,-0.13882,33.91768,39.39547
112.95001,9.41254,821.16947,-0.13882,33.98441,39.40731
113.15001,9.42916,821.24481,-0.13882,34.05089,39.41092
113.35001,9.44590,821.35787,-0.13882,34.11786,39.41635
113.55000,9.46252,820.87535,-0.13882,34.18435,39.39319
113.75001,9.47915,820.38268,-0.13882,34.25083,39.36955
113.95001,9.49589,821.02381,-0.13882,34.31779,39.40032
114.15001,9.51257,820.85859,-0.13882,34.38452,39.39239
114.35001,9.52907,820.58199,-0.13882,34.45053,39.37912
114.55000,9.54575,820.39554,-0.13882,34.51725,39.37017
114.75001,9.56255,820.83251,-0.13882,34.58445,39.39114
114.95001,9.57917,820.24978,-0.13882,34.65094,39.36317
115.15001,9.59579,820.20862,-0.13882,34.71743,39.36120
115.35001,9.61254,819.79102,-0.13882,34.78439,39.34116
115.55000,9.62916,819.61425,-0.13882,34.85088,39.33267
115.75001,9.64578,820.23274,-0.13882,34.91736,39.36235
115.95001,9.66252,819.75926,-0.13882,34.98433,39.33963
116.15001,9.67926,819.69537,-0.13882,35.05129,39.33657
116.35001,9.69576,819.85518,-0.13882,35.11730,39.34423
116.55000,9.71244,819.60140,-0.13882,35.18402,39.33206
116.75001,9.72924,819.26109,-0.13882,35.25122,39.31573
116.95001,9.74581,819.54114,-0.13882,35.31747,39.32917
117.15001,9.76255,819.19068,-0.13882,35.38444,39.31235
117.35001,9.77923,819.02687,-0.13882,35.45116,39.30449
117.55000,9.79579,819.18174,-0.13882,35.51741,39.31192
117.75001,9.81241,818.56530,-0.13882,35.58389,39.28233
117.95001,9.82909,818.71673,-0.13882,35.65062,39.28960
118.15001,9.84583,818.24977,-0.13882,35.71758,39.26719
118.35001,9.86252,818.48325,-0.13882,35.78431,39.27840
118.55000,9.87908,818.42737,-0.13882,35.85056,39.27571
118.75001,9.89582,817.97391,-0.13882,35.91752,39.25396
118.95001,9.91250,817.96674,-0.13882,35.98425,39.25361
119.15001,9.92918,818.21503,-0.13882,36.05097,39.26553
119.35001,9.94592,818.10933,-0.13882,36.11794,39.26045
119.55000,9.96254,817.58900,-0.13882,36.18442,39.23548
119.75001,9.97916,817.51458,-0.13882,36.25090,39.23191
119.95001,9.99579,817.40711,-0.13882,36.31739,39.22675
120.15001,10.01247,817.14951,-0.13882,36.38412,39.21439
120.35001,10.02915,816.77800,-0.13882,36.45084,39.19656
120.55000,10.04577,817.23817,-0.13882,36.51733,39.21865
120.75001,10.06251,816.79150,-0.13882,36.58429,39.19721
120.95001,10.07913,817.07174,-0.13882,36.65078,39.21066
121.15001,10.09581,816.86163,-0.13882,36.71750,39.20058
121.35001,10.11261,817.17726,-0.13882,36.78471,39.21572
121.55000,10.12918,816.70191,-0.13882,36.85096,39.19291
121.75001,10.14586,816.01413,-0.13882,36.91767,39.15991
121.95001,10.16254,816.62759,-0.13882,36.98440,39.18935
122.15001,10.17916,815.52118,-0.13882,37.05089,39.13625
122.35001,10.19578,816.22181,-0.13882,37.11737,39.16987
122.55000,10.21252,815.63946,-0.13882,37.18434,39.14193
122.75001,10.22920,815.46139,-0.13882,37.25107,39.13338
122.95001,10.24577,815.67364,-0.13882,37.31731,39.14357
123.15001,10.26245,815.97418,-0.13882,37.38404,39.15799
123.35001,10.27925,815.65380,-0.13882,37.45124,39.14262
123.55000,10.29587,814.92970,-0.13882,37.51773,39.10786
123.75001,10.31249,814.77324,-0.13882,37.58421,39.10036
123.95001,10.32917,815.50609,-0.13882,37.65094,39.13552
124.15001,10.34579,814.65729,-0.13882,37.71742,39.09479
124.35001,10.36254,814.77277,-0.13882,37.78439,39.10033
124.55000,10.37922,814.92504,-0.13882,37.85111,39.10764
124.75001,10.39590,814.67386,-0.13882,37.91784,39.09559
124.95001,10.41246,814.45631,-0.13882,37.98408,39.08515
125.15001,10.42908,815.04853,-0.13882,38.05057,39.11357
125.35001,10.44582,814.35302,-0.13882,38.11754,39.08019
125.55000,10.46244,813.99195,-0.13882,38.18402,39.06286
125.75001,10.47918,813.93868,-0.13882,38.25099,39.06031
125.95001,10.49581,813.76554,-0.13882,38.31747,39.05200
126.15001,10.51249,813.72131,-0.13882,38.38419,39.04988
126.35001,10.52917,813.62724,-0.13882,38.45092,39.04536
126.55000,10.54579,813.80419,-0.13882,38.51741,39.05385
126.75001,10.56253,813.27604,-0.13882,38.58437,39.02851
126.95001,10.57921,812.53396,-0.13882,38.65110,38.99290
127.15001,10.59577,813.26002,-0.13882,38.71734,39.02774
127.35001,10.61245,812.75199,-0.13882,38.78407,39.00336
127.55000,10.62914,812.53229,-0.13882,38.85079,38.99282
127.75001,10.64582,812.69844,-0.13882,38.91752,39.00079
127.95001,10.66256,812.11692,-0.13882,38.98449,38.97288
128.15001,10.67912,812.44987,-0.13882,39.05073,38.98886
128.35001,10.69580,812.99553,-0.13882,39.11746,39.01505
128.55000,10.71248,812.32693,-0.13882,39.18418,38.98296
128.75000,10.72922,811.54564,-0.13882,39.25114,38.94547
128.95002,10.74585,811.92050,-0.13882,39.31763,38.96346
129.15001,10.76253,811.56660,-0.13882,39.38435,38.94647
129.35001,10.77915,811.34299,-0.13882,39.45084,38.93574
129.55000,10.79577,811.42569,-0.13882,39.51733,38.93971
129.75000,10.81245,811.54071,-0.13882,39.58405,38.94523
129.95002,10.82925,810.88021,-0.13882,39.65126,38.91353
130.15001,10.84587,811.22899,-0.13882,39.71774,38.93027
130.35001,10.86249,810.99868,-0.13882,39.78423,38.91922
130.55000,10.87924,810.78717,-0.13882,39.85119,38.90907
130.75000,10.89586,810.58126,-0.13882,39.91767,38.89919
130.95002,10.91248,810.22503,-0.13882,39.98416,38.88209
131.15002,10.92916,809.79811,-0.13882,40.05089,38.86160
131.35000,10.94578,810.63537,-0.13882,40.11737,38.90178
131.55000,10.96240,809.71587,-0.13882,40.18386,38.85766
131.75000,10.97914,809.73329,-0.13882,40.25082,38.85849
131.95002,10.99588,809.22898,-0.13882,40.31779,38.83429
132.15002,11.01251,809.55848,-0.13882,40.38427,38.85011
132.35000,11.02913,808.91233,-0.13882,40.45076,38.81910
132.55000,11.04587,808.87089,-0.13882,40.51772,38.81711
132.75000,11.06249,809.19713,-0.13882,40.58421,38.83276
132.95002,11.07911,808.42897,-0.13882,40.65070,38.79590
133.15002,11.09585,809.00779,-0.13882,40.71766,38.82368
133.35000,11.11253,808.71964,-0.13882,40.78438,38.80985
133.55000,11.12904,808.57845,-0.13882,40.85039,38.80307
133.75000,11.14578,808.31740,-0.13882,40.91736,38.79055
133.95002,11.16252,807.92587,-0.13882,40.98432,38.77176
134.15002,11.17920,808.05440,-0.13882,41.05105,38.77792
134.35000,11.19588,806.93141,-0.13882,41.11777,38.72403
134.55000,11.21256,807.76382,-0.13882,41.18449,38.76398
134.75000,11.22912,807.17532,-0.13882,41.25074,38.73574
134.95002,11.24581,807.36876,-0.13882,41.31747,38.74502
135.15002,11.26255,807.24508,-0.13882,41.38443,38.73909
135.35000,11.27923,807.26901,-0.13882,41.45116,38.74023
135.55000,11.29585,806.98384,-0.13882,41.51765,38.72655
135.75000,11.31247,806.50393,-0.13882,41.58413,38.70352
135.95002,11.32921,806.40120,-0.13882,41.65109,38.69859
136.15002,11.34583,806.20637,-0.13882,41.71758,38.68924
136.35000,11.36245,806.92032,-0.13882,41.78407,38.72350
136.55000,11.37920,805.78318,-0.13882,41.85103,38.66893
136.75000,11.39582,805.96274,-0.13882,41.91752,38.67755
136.95002,11.41238,805.77247,-0.13882,41.98376,38.66842
137.15002,11.42924,806.14174,-0.13882,42.05121,38.68614
137.35000,11.44586,805.43347,-0.13882,42.11769,38.65215
137.55000,11.46254,805.22792,-0.13882,42.18442,38.64228
137.75000,11.47916,805.36287,-0.13882,42.25090,38.64876
137.95002,11.49590,804.85055,-0.13882,42.31787,38.62418
138.15002,11.51247,804.50587,-0.13882,42.38411,38.60764
138.35000,11.52915,804.91090,-0.13882,42.45084,38.62707
138.55000,11.54589,804.60245,-0.13883,42.51780,38.61227
138.75000,11.56245,803.97548,-0.13882,42.58405,38.58218
138.95002,11.57907,804.49069,-0.13882,42.65054,38.60691
139.15002,11.59587,803.60817,-0.13882,42.71774,38.56455
139.35000,11.61243,803.86382,-0.13882,42.78398,38.57682
139.55000,11.62917,803.75196,-0.13882,42.85094,38.57145
139.75000,11.64586,803.19475,-0.13882,42.91767,38.54472
139.95002,11.66254,803.00253,-0.13882,42.98440,38.53549
140.15002,11.67916,802.60383,-0.13882,43.05088,38.51636
140.35000,11.69578,802.46162,-0.13882,43.11737,38.50953
140.55000,11.71252,802.86711,-0.13882,43.18434,38.52899
140.75000,11.72908,802.31475,-0.13882,43.25058,38.50248
140.95002,11.74583,801.95880,-0.13882,43.31755,38.48540
141.15002,11.76251,801.84834,-0.13882,43.38427,38.48010
141.35000,11.77913,802.38888,-0.13882,43.45075,38.50604
141.55000,11.79581,801.76862,-0.13882,43.51749,38.47628
141.75000,11.81255,800.89662,-0.13882,43.58445,38.43443
141.95002,11.82917,801.11735,-0.13882,43.65093,38.44502
142.15002,11.84579,801.11595,-0.13882,43.71742,38.44495
142.35000,11.86247,800.42910,-0.13882,43.78414,38.41199
142.55000,11.87922,800.94654,-0.13882,43.85111,38.43682
142.75000,11.89578,800.19971,-0.13882,43.91736,38.40099
142.95002,11.91252,800.52251,-0.13882,43.98432,38.41647
143.15002,11.92920,800.22411,-0.13882,44.05104,38.40216
143.35000,11.94576,799.65713,-0.13882,44.11729,38.37495
143.55000,11.96244,799.91603,-0.13882,44.18402,38.38737
143.75000,11.97924,799.71589,-0.13882,44.25122,38.37777
143.95002,11.99592,799.19081,-0.13882,44.31794,38.35257
144.15002,12.01243,798.76054,-0.13882,44.38396,38.33192
144.35000,12.02911,798.22587,-0.13882,44.45067,38.30626
144.55000,12.04591,798.37032,-0.13882,44.51788,38.31319
144.75000,12.06247,797.88649,-0.13882,44.58413,38.28997
144.95002,12.07915,798.25828,-0.13882,44.65085,38.30782
145.15002,12.09589,797.57357,-0.13882,44.71782,38.27496
145.35000,12.11251,797.22190,-0.13882,44.78430,38.25808
145.55000,12.12914,798.21702,-0.13883,44.85079,38.30584
145.75000,12.14588,796.57594,-0.13882,44.91775,38.22708
145.95002,12.16256,796.91038,-0.13882,44.98447,38.24313
146.15002,12.17912,796.67382,-0.13882,45.05073,38.23178
146.35000,12.19580,796.41668,-0.13882,45.11745,38.21944
146.55000,12.21248,796.35056,-0.13882,45.18417,38.21627
146.75000,12.22910,795.72620,-0.13882,45.25066,38.18630
146.95002,12.24572,795.61174,-0.13882,45.31714,38.18081
147.15002,12.26265,795.12931,-0.13882,45.38483,38.15766
147.35000,12.27915,795.32517,-0.13882,45.45084,38.16706
147.55000,12.29583,795.25476,-0.13882,45.51756,38.16368
147.75000,12.31245,794.49154,-0.13882,45.58405,38.12705
147.95002,12.32913,794.58244,-0.13882,45.65077,38.13142
148.15002,12.34587,794.24037,-0.13882,45.71774,38.11500
148.35000,12.36255,793.64255,-0.13882,45.78446,38.08631
148.55000,12.37917,793.94346,-0.13882,45.85094,38.10075
148.75000,12.39580,793.15668,-0.13883,45.91743,38.06300
148.95002,12.41242,793.11384,-0.13882,45.98392,38.06094
149.15002,12.42916,793.28120,-0.13882,46.05088,38.06897
149.35000,12.44584,792.69558,-0.13882,46.11761,38.04087
149.55000,12.46246,792.29055,-0.13882,46.18409,38.02143
149.75000,12.47920,791.99951,-0.13882,46.25106,38.00746
149.95002,12.49576,791.55238,-0.13882,46.31731,37.98600
150.15002,12.51239,792.24305,-0.13882,46.38379,38.01915
150.35000,12.52925,791.71686,-0.13882,46.45123,37.99390
150.55000,12.54587,790.84812,-0.13882,46.51772,37.95221
150.75000,12.56243,791.20174,-0.13882,46.58397,37.96918
150.95002,12.57917,790.43079,-0.13882,46.65093,37.93218
151.15002,12.59585,790.40127,-0.13882,46.71766,37.93076
151.35000,12.61253,789.53579,-0.13882,46.78438,37.88923
151.55000,12.62921,789.68070,-0.13882,46.85110,37.89619
151.75000,12.64584,788.92261,-0.13882,46.91759,37.85981
151.95002,12.66240,789.47395,-0.13882,46.98384,37.88626
152.15002,12.67914,789.09360,-0.13882,47.05080,37.86801
152.35000,12.69588,788.53145,-0.13882,47.11777,37.84103
152.55000,12.71250,788.23157,-0.13882,47.18426,37.82664
152.75000,12.72912,787.52004,-0.13882,47.25074,37.79250
152.95002,12.74580,787.27352,-0.13882,47.31746,37.78067
153.15002,12.76249,786.89950,-0.13882,47.38419,37.76272
153.35000,12.77923,786.65186,-0.13882,47.45115,37.75083
153.55000,12.79591,786.12352,-0.13882,47.51788,37.72548
153.75000,12.81253,786.08776,-0.13882,47.58436,37.72376
153.95002,12.82909,785.38191,-0.13882,47.65061,37.68989
154.15002,12.84577,785.57171,-0.13882,47.71734,37.69900
154.35000,12.86245,785.50158,-0.13882,47.78406,37.69563
154.55000,12.87913,784.26329,-0.13882,47.85078,37.63621
154.75000,12.89582,784.33733,-0.13882,47.91751,37.63976
154.95002,12.91244,783.92280,-0.13882,47.98400,37.61987
155.15002,12.92912,784.09007,-0.13882,48.05072,37.62790
155.35000,12.94580,783.03758,-0.13882,48.11744,37.57738
155.55000,12.96248,782.80959,-0.13882,48.18417,37.56644
155.75000,12.97922,782.25294,-0.13882,48.25114,37.53973
155.95002,12.99590,782.22826,-0.13882,48.31786,37.53855
156.15002,13.01253,781.71184,-0.13882,48.38435,37.51377
156.35000,13.02915,780.97014,-0.13882,48.45083,37.47817
156.55000,13.04583,781.06970,-0.13882,48.51755,37.48295
156.75000,13.06257,780.40301,-0.13882,48.58452,37.45095
156.95002,13.07919,780.07565,-0.13882,48.65101,37.43525
157.15002,13.09581,779.54284,-0.13882,48.71749,37.40968
157.35000,13.11243,780.11295,-0.13882,48.78398,37.43703
157.55000,13.12912,779.09585,-0.13882,48.85071,37.38823
157.75000,13.14586,778.30940,-0.13882,48.91767,37.35048
157.95002,13.16254,777.92611,-0.13882,48.98439,37.33209
158.15002,13.17916,776.95725,-0.13882,49.05088,37.28559
158.35000,13.19590,777.10473,-0.13882,49.11785,37.29268
158.55000,13.21252,776.77183,-0.13882,49.18433,37.27670
158.75000,13.22914,775.61196,-0.13882,49.25082,37.22104
158.95002,13.24594,775.59059,-0.13882,49.31802,37.22001
159.15002,13.26245,775.35780,-0.13882,49.38403,37.20884
159.35000,13.27907,774.51323,-0.13882,49.45052,37.16831
159.55000,13.29581,773.79839,-0.13882,49.51748,37.13401
159.75000,13.31255,773.67220,-0.13882,49.58444,37.12795
159.95002,13.32917,772.96547,-0.13882,49.65093,37.09403
160.15002,13.34579,772.49189,-0.13882,49.71741,37.07131
160.35000,13.36253,772.14339,-0.13882,49.78438,37.05458
160.55000,13.37909,771.65910,-0.13882,49.85063,37.03134
160.75002,13.39584,770.60675,-0.13882,49.91759,36.98084
160.95002,13.41258,769.75236,-0.13882,49.98456,36.93984
161.15002,13.42914,769.24963,-0.13882,50.05080,36.91571
161.35000,13.44582,768.98509,-0.13882,50.11752,36.90302
161.55000,13.46244,768.01958,-0.13882,50.18401,36.85669
161.75002,13.47912,767.60412,-0.13882,50.25074,36.83675
161.95002,13.49580,766.89175,-0.13882,50.31746,36.80256
162.15002,13.51248,766.27606,-0.13882,50.38419,36.77301
162.35000,13.52917,766.04709,-0.13882,50.45091,36.76202
162.55000,13.54579,765.02697,-0.13882,50.51740,36.71307
162.75002,13.56241,764.34985,-0.13882,50.58388,36.68058
162.95002,13.57921,763.60744,-0.13882,50.65109,36.64495
163.15002,13.59583,763.50481,-0.13882,50.71757,36.64002
163.35000,13.61251,762.18122,-0.13882,50.78430,36.57650
163.55000,13.62919,761.72212,-0.13882,50.85102,36.55447
163.75002,13.64582,760.94735,-0.13882,50.91751,36.51729
163.95002,13.66250,760.20905,-0.13882,50.98424,36.48186
164.15002,13.67918,759.74087,-0.13882,51.05096,36.45940
164.35000,13.69592,758.97123,-0.13882,51.11792,36.42246
164.55000,13.71242,757.73406,-0.13882,51.18393,36.36309
164.75002,13.72916,756.61479,-0.13882,51.25089,36.30938
164.95002,13.74590,756.70308,-0.13882,51.31785,36.31361
165.15002,13.76241,755.78913,-0.13882,51.38386,36.26975
165.35000,13.77915,754.63797,-0.13882,51.45083,36.21451
165.55000,13.79589,753.73277,-0.13882,51.51779,36.17107
165.75002,13.81245,752.91372,-0.13882,51.58404,36.13176
165.95002,13.82913,752.69360,-0.13882,51.65077,36.12120
166.15002,13.84587,750.73931,-0.13882,51.71773,36.02742
166.35000,13.86255,750.52935,-0.13882,51.78446,36.01734
166.55000,13.87911,749.03900,-0.13882,51.85070,35.94582
166.75002,13.89579,748.22805,-0.13882,51.91743,35.90690
166.95002,13.91254,746.90930,-0.13882,51.98439,35.84362
167.15002,13.92910,745.83674,-0.13882,52.05064,35.79214
167.35000,13.94584,743.68888,-0.13882,52.11760,35.68907
167.55000,13.96258,742.60375,-0.13882,52.18457,35.63700
167.75002,13.97908,739.86710,-0.13882,52.25058,35.50567
167.95002,13.99576,738.34490,-0.13882,52.31730,35.43262
168.15002,14.01250,735.54921,-0.13882,52.38427,35.29845
168.35000,14.02919,732.73750,-0.13882,52.45099,35.16352
168.55000,14.04587,730.75276,-0.13882,52.51772,35.06828
168.75002,14.06249,727.61020,-0.13882,52.58420,34.91747
168.95002,14.07917,724.71066,-0.13882,52.65093,34.77832
169.15002,14.09579,720.09275,-0.13882,52.71741,34.55671
169.35000,14.11253,710.56155,-0.13882,52.78438,34.09932
169.55000,14.12933,124.72771,-0.13882,52.85158,5.98559
169.56402,14.13053,9.40282,-0.13880,52.85636,0.45123