File: Manufatura Aditiva/Classificação Orientação/Ensaios/Ensaios SLS/Tracao_OLABI_07_06_2018_SLS_XZ2.is_metal_RawData/Specimen_RawData_2.csv
Time,Extension,Load,Strain 1,Tensile strain,Tensile stress
(sec),(mm),(N),(mm/mm),(%),(MPa)
0.00000,0.00006,24.47748,0.00114,0.11379,1.24518
0.20000,0.01375,30.74643,0.00132,0.13165,1.56408
0.40000,0.03270,40.42713,0.00162,0.16240,2.05654
0.60000,0.04986,48.57802,0.00191,0.19137,2.47118
0.80000,0.06673,57.01421,0.00218,0.21810,2.90034
1.00000,0.08335,64.70304,0.00245,0.24484,3.29147
1.20000,0.10003,72.41933,0.00272,0.27233,3.68400
1.40000,0.11683,81.30184,0.00300,0.30044,4.13586
1.60000,0.13339,89.08721,0.00327,0.32725,4.53190
1.80000,0.14995,96.70878,0.00354,0.35404,4.91961
2.00000,0.16663,103.41497,0.00382,0.38186,5.26076
2.20000,0.18331,111.92441,0.00409,0.40917,5.69364
2.40000,0.19994,117.98705,0.00437,0.43686,6.00205
2.60000,0.21668,125.88635,0.00465,0.46454,6.40389
2.80000,0.23336,133.13683,0.00493,0.49263,6.77272
3.00000,0.24998,140.58052,0.00520,0.52012,7.15139
3.20000,0.26672,147.88380,0.00548,0.54786,7.52291
3.40000,0.28340,155.77307,0.00576,0.57614,7.92424
3.60000,0.30008,162.37309,0.00604,0.60398,8.25998
3.80000,0.31665,169.49633,0.00631,0.63128,8.62234
4.00000,0.33327,175.91128,0.00659,0.65888,8.94868
4.20000,0.34995,183.67070,0.00687,0.68707,9.34340
4.40000,0.36663,190.49158,0.00715,0.71539,9.69038
4.60000,0.38331,197.37331,0.00743,0.74318,10.04046
4.80000,0.39999,203.65538,0.00770,0.77048,10.36003
5.00000,0.41667,211.49574,0.00799,0.79867,10.75887
5.20000,0.43335,218.03703,0.00827,0.82727,11.09163
5.40000,0.45010,224.30457,0.00855,0.85525,11.41046
5.60000,0.46666,230.89903,0.00883,0.88327,11.74592
5.80000,0.48334,237.80297,0.00911,0.91150,12.09713
6.00000,0.50002,244.25185,0.00940,0.93984,12.42519
6.20000,0.51664,251.80820,0.00968,0.96810,12.80958
6.40000,0.53332,258.22879,0.00996,0.99619,13.13620
6.60000,0.54994,264.09705,0.01025,1.02535,13.43472
6.80000,0.56674,270.69533,0.01053,1.05314,13.77038
7.00000,0.58331,277.18754,0.01081,1.08140,14.10064
7.20000,0.59993,284.16466,0.01110,1.11012,14.45557
7.40000,0.61673,289.89087,0.01139,1.13908,14.74686
7.60000,0.63329,295.85252,0.01167,1.16702,15.05013
7.80000,0.64997,302.69539,0.01195,1.19550,15.39823
8.00000,0.66671,308.88133,0.01225,1.22511,15.71291
8.20000,0.68333,314.94903,0.01254,1.25353,16.02158
8.40000,0.70002,320.63392,0.01282,1.28217,16.31077
8.60000,0.71664,327.24808,0.01311,1.31136,16.64724
8.80000,0.73344,332.50300,0.01341,1.34080,16.91456
9.00000,0.75000,338.61389,0.01370,1.36967,17.22542
9.20000,0.76662,344.31021,0.01399,1.39855,17.51520
9.40000,0.78336,349.28538,0.01428,1.42816,17.76828
9.60000,0.79992,356.19328,0.01458,1.45752,18.11969
9.80000,0.81666,360.99178,0.01486,1.48613,18.36379
10.00000,0.83341,366.50035,0.01515,1.51537,18.64402
10.20000,0.84997,371.79324,0.01545,1.54477,18.91327
10.40000,0.86671,377.66860,0.01575,1.57463,19.21215
10.60000,0.88333,382.72883,0.01604,1.60379,19.46957
10.80000,0.90007,387.71313,0.01634,1.63401,19.72312
11.00000,0.91669,393.21459,0.01664,1.66380,20.00298
11.20000,0.93331,398.12028,0.01694,1.69378,20.25253
11.40000,0.95000,403.14775,0.01724,1.72373,20.50828
11.60000,0.96656,408.86481,0.01754,1.75449,20.79911
11.80000,0.98330,412.96477,0.01785,1.78463,21.00768
12.00000,1.00004,418.18218,0.01813,1.81345,21.27309
12.20000,1.01666,422.25062,0.01842,1.84246,21.48005
12.40000,1.03328,426.97866,0.01873,1.87331,21.72057
12.60000,1.04996,431.67458,0.01904,1.90366,21.95946
12.80000,1.06664,436.68523,0.01934,1.93410,22.21435
13.00000,1.08333,440.81262,0.01965,1.96494,22.42431
13.20000,1.10001,445.35468,0.01996,1.99608,22.65537
13.40000,1.11675,449.96380,0.02027,2.02744,22.88984
13.60000,1.13325,454.10288,0.02059,2.05878,23.10039
13.80000,1.14999,457.78868,0.02090,2.09016,23.28789
14.00000,1.16673,462.60934,0.02122,2.12169,23.53312
14.20000,1.18329,466.48583,0.02154,2.15378,23.73032
14.40000,1.19998,470.50631,0.02186,2.18596,23.93484
14.60000,1.21672,474.96990,0.02218,2.21761,24.16191
14.80000,1.23334,478.93887,0.02250,2.24991,24.36381
15.00000,1.24990,482.73122,0.02282,2.28242,24.55673
15.20000,1.26664,486.37623,0.02313,2.31294,24.74215
15.40000,1.28344,489.51013,0.02342,2.34192,24.90157
15.60000,1.29994,493.43496,0.02374,2.37424,25.10123
15.80000,1.31656,496.96332,0.02407,2.40693,25.28072
16.00000,1.33343,501.08004,0.02440,2.44002,25.49014
16.20000,1.34993,503.63997,0.02472,2.47241,25.62036
16.40000,1.36667,508.01206,0.02506,2.50571,25.84277
16.60000,1.38341,510.60305,0.02539,2.53920,25.97458
16.80000,1.39997,514.86949,0.02572,2.57240,26.19161
17.00000,1.41659,517.82457,0.02605,2.60544,26.34194
17.20000,1.43333,520.28759,0.02639,2.63905,26.46723
17.40000,1.45001,524.40804,0.02673,2.67335,26.67684
17.60000,1.46664,527.28257,0.02706,2.70646,26.82307
17.80000,1.48326,531.11957,0.02740,2.74036,27.01826
18.00000,1.50000,533.44662,0.02774,2.77414,27.13664
18.20000,1.51656,536.21545,0.02808,2.80846,27.27749
18.40000,1.53330,538.58343,0.02842,2.84248,27.39795
18.60000,1.55004,541.78401,0.02877,2.87699,27.56076
18.80000,1.56666,544.34892,0.02911,2.91127,27.69124
19.00000,1.58341,547.39555,0.02946,2.94599,27.84623
19.20000,1.60003,550.06114,0.02981,2.98057,27.98183
19.40000,1.61665,552.56803,0.03015,3.01547,28.10935
19.60000,1.63339,555.54933,0.03050,3.05014,28.26101
19.80000,1.65001,558.30372,0.03085,3.08495,28.40113
20.00000,1.66663,561.08744,0.03120,3.15144,28.54274
20.13800,1.67811,562.62738,0.03144,3.19735,28.62108
20.33800,1.69485,565.04137,0.03179,3.26432,28.74388
20.53800,1.71147,567.56553,0.03214,3.33080,28.87228
20.73800,1.72816,570.01263,0.03249,3.39753,28.99677
20.93800,1.74484,572.38336,0.03284,3.46425,29.11737
21.13800,1.76152,575.36773,0.03320,3.53098,29.26918
21.33800,1.77814,577.52281,0.03355,3.59746,29.37881
21.53800,1.79482,579.28073,0.03389,3.66419,29.46824
21.73800,1.81162,581.83745,0.03447,3.73139,29.59830
21.93800,1.82818,584.64776,0.03440,3.79764,29.74126
22.13800,1.84480,586.58654,0.03009,3.86413,29.83989
22.33800,1.86149,588.82595,0.00804,3.93085,29.95381
22.53800,1.87811,590.40622,0.00561,3.99734,30.03420
22.73800,1.89479,592.08609,0.00793,4.06406,30.11965
22.93800,1.91153,593.90715,0.00860,4.13103,30.21229
23.13800,1.92821,596.46447,0.00900,4.19775,30.34238
23.33800,1.94477,598.68223,0.01051,4.26400,30.45520
23.53800,1.96151,600.59866,0.00934,4.33096,30.55269
23.73800,1.97825,602.90308,0.00841,4.39793,30.66992
23.93800,1.99488,604.98579,0.00881,4.46441,30.77587
24.13800,2.01150,606.31293,0.01080,4.53090,30.84338
24.33800,2.02818,607.97730,0.01107,4.59762,30.92804
24.53800,2.04486,610.46476,-0.07197,4.66435,31.05458
24.73800,2.06148,612.49333,-0.13372,4.73083,31.15778
24.93800,2.07816,614.41218,-0.13372,4.79756,31.25539
25.13800,2.09478,616.46551,-0.13373,4.86405,31.35984
25.33800,2.11147,617.56251,-0.13373,4.93077,31.41565
25.53800,2.12809,619.55466,-0.13374,4.99726,31.51699
25.73800,2.14477,621.59449,-0.13374,5.06398,31.62076
25.93800,2.16151,622.86761,-0.13374,5.13095,31.68552
26.13800,2.17819,625.07056,-0.13374,5.19767,31.79758
26.33800,2.19487,626.82438,-0.13375,5.26440,31.88680
26.53800,2.21155,628.21633,-0.13375,5.33112,31.95761
26.73800,2.22817,630.76559,-0.13375,5.39761,32.08729
26.93800,2.24486,631.83284,-0.13375,5.46433,32.14159
27.13800,2.26154,633.48757,-0.13375,5.53106,32.22576
27.33800,2.27822,635.04302,-0.13376,5.59778,32.30489
27.53800,2.29484,636.27171,-0.13376,5.66427,32.36739
27.73800,2.31146,638.25413,-0.13376,5.73075,32.46824
27.93800,2.32814,639.70638,-0.13376,5.79748,32.54211
28.13800,2.34482,641.50202,-0.13376,5.86420,32.63346
28.33800,2.36151,643.36830,-0.13376,5.93093,32.72840
28.53800,2.37813,644.76305,-0.13376,5.99742,32.79935
28.73800,2.39475,646.17437,-0.13377,6.06390,32.87114
28.93800,2.41149,647.66998,-0.13377,6.13087,32.94723
29.13800,2.42817,649.12550,-0.13377,6.19759,33.02127
29.33800,2.44485,651.20426,-0.13376,6.26432,33.12702
29.53800,2.46153,651.82871,-0.13377,6.33104,33.15878
29.73800,2.47821,653.73145,-0.13377,6.39777,33.25558
29.93800,2.49484,655.39591,-0.13377,6.46425,33.34025
30.13800,2.51146,656.60849,-0.13377,6.53074,33.40193
30.33800,2.52826,658.07672,-0.13377,6.59794,33.47662
30.53800,2.54488,659.23575,-0.13377,6.66443,33.53558
30.73800,2.56138,660.62454,-0.13377,6.73043,33.60623
30.93800,2.57812,661.27526,-0.13377,6.79740,33.63933
31.13800,2.59480,663.13092,-0.13377,6.86412,33.73373
31.33800,2.61149,664.39207,-0.13377,6.93085,33.79789
31.53800,2.62817,666.29970,-0.13377,6.99757,33.89493
31.73800,2.64479,667.30552,-0.13376,7.06406,33.94609
31.93800,2.66147,668.29827,-0.13376,7.13078,33.99659
32.13800,2.67815,669.93143,-0.13377,7.19751,34.07967
32.33800,2.69489,671.18318,-0.13376,7.26447,34.14335
32.53800,2.71157,672.31753,-0.13377,7.33120,34.20106
32.73800,2.72819,673.70194,-0.13377,7.39769,34.27148
32.93800,2.74482,675.09464,-0.13377,7.46417,34.34233
33.13800,2.76150,676.10131,-0.13377,7.53090,34.39354
33.33800,2.77824,678.22323,-0.13377,7.59786,34.50148
33.53800,2.79492,678.98687,-0.13377,7.66459,34.54033
33.73800,2.81148,680.18297,-0.13377,7.73083,34.60117
33.93800,2.82816,680.94973,-0.13377,7.79756,34.64018
34.13800,2.84478,682.29083,-0.13377,7.86404,34.70840
34.33800,2.86147,684.03152,-0.13377,7.93077,34.79695
34.53800,2.87827,684.44554,-0.13377,7.99797,34.81801
34.73800,2.89483,686.11996,-0.13377,8.06422,34.90319
34.93800,2.91151,687.18991,-0.13377,8.13094,34.95762
35.13800,2.92813,688.56305,-0.13377,8.19743,35.02747
35.33800,2.94481,689.95305,-0.13377,8.26415,35.09818
35.53800,2.96155,690.80614,-0.13377,8.33112,35.14158
35.73800,2.97817,691.71418,-0.13377,8.39760,35.18777
35.93800,2.99480,692.71647,-0.13377,8.46409,35.23876
36.13800,3.01154,693.76077,-0.13377,8.53105,35.29188
36.33800,3.02810,694.37590,-0.13377,8.59730,35.32317
36.53800,3.04478,695.71626,-0.13377,8.66403,35.39136
36.73800,3.06152,696.73671,-0.13377,8.73099,35.44327
36.93800,3.07826,697.59600,-0.13377,8.79796,35.48698
37.13800,3.09476,699.19717,-0.13377,8.86396,35.56844
37.33800,3.11150,699.63993,-0.13378,8.93093,35.59096
37.53800,3.12825,701.32222,-0.13377,8.99789,35.67654
37.73800,3.14481,701.91985,-0.13378,9.06414,35.70694
37.93800,3.16149,703.75018,-0.13377,9.13086,35.80005
38.13800,3.17817,704.34147,-0.13378,9.19759,35.83013
38.33800,3.19479,705.84514,-0.13377,9.26407,35.90662
38.53800,3.21141,706.35038,-0.13378,9.33056,35.93232
38.73800,3.22815,707.60148,-0.13378,9.39752,35.99596
38.93800,3.24484,708.96829,-0.13378,9.46425,36.06549
39.13800,3.26146,709.61425,-0.13378,9.53073,36.09835
39.33800,3.27814,710.73659,-0.13378,9.59746,36.15545
39.53800,3.29482,711.32854,-0.13378,9.66418,36.18556
39.73800,3.31144,712.59276,-0.13378,9.73067,36.24987
39.93800,3.32818,712.89293,-0.13378,9.79763,36.26514
40.13800,3.34492,713.53670,-0.13378,9.86460,36.29789
40.33800,3.36154,715.36996,-0.13378,9.93109,36.39115
40.53800,3.37811,715.80992,-0.13378,9.99733,36.41353
40.73800,3.39485,716.56890,-0.13378,10.06430,36.45214
40.93800,3.41159,717.50209,-0.13378,10.13126,36.49961
41.13800,3.42821,718.67104,-0.13378,10.19775,36.55908
41.33800,3.44477,719.77330,-0.13378,10.26399,36.61515
41.53800,3.46151,720.12870,-0.13378,10.33096,36.63323
41.73800,3.47813,720.68451,-0.13378,10.39744,36.66150
41.93800,3.49482,722.21323,-0.13378,10.46417,36.73927
42.13800,3.51162,722.39158,-0.13378,10.53137,36.74834
42.33800,3.52818,723.69850,-0.13378,10.59762,36.81483
42.53800,3.54480,724.31029,-0.13378,10.66410,36.84595
42.73800,3.56148,725.82555,-0.13378,10.73083,36.92303
42.93800,3.57822,726.51119,-0.13378,10.79779,36.95791
43.13800,3.59478,726.56483,-0.13378,10.86404,36.96064
43.33800,3.61146,727.97281,-0.13378,10.93077,37.03226
43.53800,3.62821,728.66622,-0.13379,10.99773,37.06754
43.73800,3.64477,729.66963,-0.13378,11.06398,37.11858
43.93800,3.66151,729.99736,-0.13379,11.13094,37.13525
44.13800,3.67831,730.24100,-0.13379,11.19815,37.14765
44.33800,3.69481,731.59756,-0.13378,11.26415,37.21666
44.53800,3.71143,731.84236,-0.13379,11.33064,37.22911
44.73800,3.72823,732.69084,-0.13379,11.39784,37.27227
44.93800,3.74491,733.28121,-0.13378,11.46457,37.30230
45.13800,3.76142,734.74040,-0.13378,11.53057,37.37653
45.33800,3.77822,735.09538,-0.13379,11.59778,37.39459
45.53800,3.79484,735.21743,-0.13378,11.66426,37.40080
45.73800,3.81146,736.54130,-0.13379,11.73075,37.46814
45.93800,3.82814,736.78647,-0.13378,11.79747,37.48062
46.13800,3.84488,737.45418,-0.13378,11.86444,37.51458
46.33800,3.86144,738.35379,-0.13378,11.93069,37.56035
46.53800,3.87819,738.72730,-0.13379,11.99765,37.57935
46.73800,3.89487,739.73001,-0.13379,12.06437,37.63036
46.93800,3.91149,740.46161,-0.13379,12.13086,37.66757
47.13800,3.92811,740.49546,-0.13378,12.19735,37.66930
47.33800,3.94485,740.98455,-0.13379,12.26431,37.69418
47.53800,3.96153,742.19629,-0.13379,12.33103,37.75582
47.73800,3.97815,742.07820,-0.13379,12.39752,37.74981
47.93800,3.99478,743.06550,-0.13379,12.46401,37.80003
48.13800,4.01152,743.78722,-0.13379,12.53097,37.83675
48.33800,4.02820,744.68101,-0.13379,12.59770,37.88221
48.53800,4.04482,745.49457,-0.13379,12.66418,37.92360
48.73800,4.06156,745.30016,-0.13379,12.73115,37.91371
48.93800,4.07812,746.15963,-0.13379,12.79739,37.95743
49.13800,4.09474,746.96862,-0.13378,12.86388,37.99859
49.33800,4.11148,747.02934,-0.13379,12.93084,38.00167
49.53800,4.12817,747.71470,-0.13379,12.99757,38.03654
49.73800,4.14479,748.37790,-0.13379,13.06406,38.07028
49.93800,4.16147,748.79089,-0.13379,13.13078,38.09129
50.13800,4.17821,750.09656,-0.13379,13.19775,38.15771
50.33800,4.19471,750.39547,-0.13378,13.26375,38.17291
50.53800,4.21145,750.63109,-0.13379,13.33072,38.18490
50.73800,4.22831,750.98015,-0.13379,13.39816,38.20266
50.93800,4.24481,752.09262,-0.13379,13.46417,38.25925
51.13800,4.26150,751.72503,-0.13379,13.53089,38.24055
51.33800,4.27824,752.53728,-0.13379,13.59786,38.28187
51.53800,4.29480,753.05691,-0.13379,13.66410,38.30830
51.73800,4.31148,753.95089,-0.13379,13.73083,38.35378
51.93800,4.32816,754.24458,-0.13379,13.79755,38.36872
52.13800,4.34484,754.71606,-0.13379,13.86428,38.39270
52.33800,4.36146,755.32915,-0.13379,13.93076,38.42389
52.53800,4.37815,755.93214,-0.13379,13.99749,38.45456
52.73800,4.39489,755.80925,-0.13379,14.06445,38.44831
52.93800,4.41151,756.44446,-0.13379,14.13094,38.48063
53.13800,4.42819,757.18244,-0.13379,14.19766,38.51817
53.33800,4.44487,757.89983,-0.13379,14.26439,38.55466
53.53800,4.46149,758.14277,-0.13379,14.33088,38.56702
53.73800,4.47811,758.32177,-0.13379,14.39736,38.57613
53.93800,4.49485,758.83842,-0.13379,14.46432,38.60241
54.13800,4.51148,759.11889,-0.13379,14.53081,38.61668
54.33800,4.52810,759.64457,-0.13379,14.59730,38.64342
54.53800,4.54478,760.24821,-0.13379,14.66402,38.67413
54.73800,4.56146,760.38991,-0.13379,14.73075,38.68133
54.93800,4.57814,760.49385,-0.13379,14.79747,38.68662
55.13800,4.59488,760.82838,-0.13379,14.86444,38.70364
55.33800,4.61150,761.81400,-0.13379,14.93092,38.75378
55.53800,4.62813,762.60539,-0.13379,14.99741,38.79404
55.73800,4.64487,762.46881,-0.13379,15.06437,38.78709
55.93800,4.66155,762.76450,-0.13379,15.13110,38.80213
56.13800,4.67829,762.87477,-0.13379,15.19806,38.80774
56.33800,4.69485,763.07952,-0.13379,15.26431,38.81815
56.53800,4.71141,764.34342,-0.13379,15.33055,38.88245
56.73800,4.72821,765.11223,-0.13379,15.39776,38.92156
56.93800,4.74477,765.27097,-0.13379,15.46400,38.92963
57.13800,4.76146,765.54767,-0.13379,15.53073,38.94371
57.33800,4.77820,766.09575,-0.13379,15.59769,38.97159
57.53800,4.79476,765.74781,-0.13379,15.66394,38.95389
57.73800,4.81144,766.20886,-0.13379,15.73067,38.97734
57.93800,4.82818,766.37804,-0.13379,15.79763,38.98595
58.13800,4.84492,767.01581,-0.13379,15.86459,39.01839
58.33800,4.86148,767.08631,-0.13379,15.93084,39.02198
58.53800,4.87816,767.79183,-0.13380,15.99757,39.05787
58.73800,4.89491,768.06131,-0.13379,16.06453,39.07158
58.93800,4.91147,768.27025,-0.13379,16.13078,39.08221
59.13800,4.92815,768.65167,-0.13379,16.19750,39.10161
59.33800,4.94489,768.84893,-0.13379,16.26447,39.11165
59.53800,4.96145,769.22514,-0.13380,16.33071,39.13078
59.73800,4.97807,769.70616,-0.13379,16.39720,39.15525
59.93800,4.99481,769.89238,-0.13379,16.46416,39.16473
60.13800,5.01150,769.54775,-0.13379,16.53089,39.14719
60.33800,5.02824,770.73998,-0.13379,16.59786,39.20784
60.53800,5.04480,771.09314,-0.13379,16.66410,39.22581
60.73800,5.06154,770.82124,-0.13379,16.73106,39.21198
60.93800,5.07816,771.57784,-0.13379,16.79755,39.25047
61.13800,5.09478,771.76606,-0.13379,16.86404,39.26004
61.33800,5.11152,772.04984,-0.13380,16.93100,39.27448
61.53800,5.12814,772.21282,-0.13380,16.99748,39.28277
61.73800,5.14477,772.39224,-0.13379,17.06397,39.29190
61.93800,5.16151,772.20048,-0.13380,17.13093,39.28214
62.13800,5.17813,773.12742,-0.13380,17.19742,39.32930
62.33800,5.19481,772.85012,-0.13380,17.26415,39.31519
62.53800,5.21149,773.83625,-0.13380,17.33087,39.36535
62.73800,5.22811,773.50116,-0.13380,17.39736,39.34831
62.93800,5.24479,773.63630,-0.13379,17.46408,39.35518
63.13800,5.26147,774.02694,-0.13380,17.53081,39.37505
63.33800,5.27816,774.30350,-0.13379,17.59753,39.38912
63.53800,5.29484,775.03822,-0.13380,17.66426,39.42650
63.73800,5.31152,774.75561,-0.13380,17.73098,39.41212
63.93800,5.32814,774.63398,-0.13380,17.79747,39.40593
64.13800,5.34476,775.12083,-0.13380,17.86395,39.43070
64.33800,5.36150,775.72367,-0.13380,17.93092,39.46137
64.53800,5.37824,775.80232,-0.13380,17.99788,39.46537
64.73801,5.39487,775.22066,-0.13379,18.06437,39.43578
64.93800,5.41149,776.55464,-0.13380,18.13086,39.50364
65.13800,5.42811,776.68661,-0.13380,18.19734,39.51035
65.33800,5.44479,776.96741,-0.13380,18.26407,39.52464
65.53800,5.46147,777.19102,-0.13380,18.33079,39.53601
65.73801,5.47821,777.42394,-0.13380,18.39776,39.54786
65.93800,5.49489,777.30375,-0.13380,18.46448,39.54175
66.13800,5.51146,776.98440,-0.13380,18.53073,39.52550
66.33801,5.52814,777.91051,-0.13380,18.59745,39.57261
66.53800,5.54494,777.68178,-0.13380,18.66466,39.56098
66.73801,5.56156,777.74380,-0.13380,18.73114,39.56413
66.93800,5.57818,778.24956,-0.13380,18.79763,39.58986
67.13800,5.59486,778.29622,-0.13380,18.86435,39.59224
67.33801,5.61148,778.42926,-0.13380,18.93084,39.59900
67.53800,5.62816,778.31871,-0.13380,18.99756,39.59338
67.73801,5.64485,779.45138,-0.13380,19.06429,39.65100
67.93800,5.66153,778.86269,-0.13380,19.13102,39.62105
68.13800,5.67809,779.20132,-0.13380,19.19726,39.63828
68.33801,5.69477,779.25473,-0.13380,19.26399,39.64100
68.53800,5.71151,778.97599,-0.13380,19.33095,39.62682
68.73801,5.72813,779.21827,-0.13380,19.39744,39.63914
68.93800,5.74487,780.03034,-0.13380,19.46440,39.68045
69.13800,5.76155,779.40174,-0.13380,19.53112,39.64847
69.33801,5.77818,780.17619,-0.13380,19.59761,39.68787
69.53800,5.79486,780.43374,-0.13380,19.66434,39.70097
69.73801,5.81148,779.90564,-0.13380,19.73082,39.67411
69.93800,5.82822,780.61838,-0.13380,19.79779,39.71036
70.13800,5.84484,780.88925,-0.13380,19.86427,39.72414
70.33801,5.86146,780.80189,-0.13380,19.93076,39.71970
70.53800,5.87814,780.77503,-0.13380,19.99748,39.71833
70.73801,5.89482,780.93023,-0.13380,20.06421,39.72623
70.93800,5.91151,780.89386,-0.13380,20.13093,39.72438
71.13800,5.92825,781.44930,-0.13380,20.19790,39.75263
71.33801,5.94481,781.80535,-0.13380,20.26414,39.77074
71.53800,5.96149,781.56469,-0.13380,20.33087,39.75850
71.73801,5.97817,781.71380,-0.13380,20.39759,39.76609
71.93800,5.99491,781.57354,-0.13380,20.46456,39.75895
72.13800,6.01153,781.59757,-0.13380,20.53104,39.76017
72.33801,6.02816,781.52353,-0.13380,20.59753,39.75641
72.53800,6.04490,781.47547,-0.13380,20.66450,39.75396
72.73801,6.06146,782.85150,-0.13380,20.73074,39.82396
72.93800,6.07814,782.15273,-0.13380,20.79746,39.78842
73.13800,6.09488,782.04814,-0.13380,20.86443,39.78310
73.33801,6.11150,782.60219,-0.13380,20.93092,39.81128
73.53800,6.12812,782.51353,-0.13380,20.99740,39.80677
73.73801,6.14486,782.68079,-0.13380,21.06437,39.81528
73.93800,6.16155,782.50226,-0.13380,21.13109,39.80620
74.13800,6.17817,782.62025,-0.13380,21.19758,39.81220
74.33801,6.19485,782.98487,-0.13380,21.26430,39.83075
74.53800,6.21153,782.44228,-0.13380,21.33103,39.80315
74.73801,6.22809,782.54659,-0.13380,21.39727,39.80845
74.93800,6.24477,783.04308,-0.13380,21.46400,39.83371
75.13800,6.26157,783.62999,-0.13380,21.53120,39.86356
75.33801,6.27820,783.43526,-0.13380,21.59769,39.85366
75.53800,6.29476,782.80335,-0.13380,21.66394,39.82151
75.73801,6.31144,782.97537,-0.13380,21.73066,39.83027
75.93800,6.32812,783.93631,-0.13380,21.79739,39.87915
76.13800,6.34480,783.43581,-0.13380,21.86411,39.85369
76.33801,6.36154,783.22375,-0.13380,21.93108,39.84290
76.53800,6.37828,783.65104,-0.13380,21.99804,39.86464
76.73801,6.39473,783.52541,-0.13380,22.06381,39.85825
76.93800,6.41147,783.98120,-0.13380,22.13077,39.88143
77.13800,6.42827,783.68383,-0.13380,22.19798,39.86630
77.33801,6.44477,783.80611,-0.13380,22.26398,39.87252
77.53800,6.46151,782.90207,-0.13380,22.33095,39.82653
77.73801,6.47819,784.10031,-0.13380,22.39767,39.88749
77.93800,6.49481,783.75591,-0.13380,22.46416,39.86997
78.13800,6.51143,784.01351,-0.13380,22.53065,39.88308
78.33801,6.52812,784.06949,-0.13381,22.59737,39.88592
78.53800,6.54492,784.02963,-0.13380,22.66457,39.88390
78.73801,6.56148,783.86674,-0.13380,22.73082,39.87561
78.93800,6.57816,784.18851,-0.13380,22.79755,39.89198
79.13800,6.59496,784.47331,-0.13380,22.86475,39.90646
79.33801,6.61140,784.69431,-0.13380,22.93052,39.91771
79.53800,6.62814,784.23675,-0.13380,22.99748,39.89443
79.73801,6.64494,784.22045,-0.13380,23.06469,39.89360
79.93800,6.66151,784.23014,-0.13380,23.13093,39.89410
80.13800,6.67807,783.96583,-0.13380,23.19718,39.88065
80.33801,6.69487,784.01230,-0.13380,23.26438,39.88301
80.53800,6.71155,784.92863,-0.13380,23.33111,39.92963
80.73801,6.72811,784.07507,-0.13380,23.39735,39.88621
80.93800,6.74479,783.59907,-0.13380,23.46408,39.86199
81.13800,6.76153,783.96220,-0.13380,23.53104,39.88047
81.33801,6.77810,784.67820,-0.13380,23.59729,39.91689
81.53800,6.79484,784.40001,-0.13380,23.66425,39.90274
81.73801,6.81158,784.54567,-0.13381,23.73122,39.91014
81.93800,6.82814,784.51093,-0.13380,23.79746,39.90838
82.13800,6.84476,784.45310,-0.13380,23.86395,39.90544
82.33801,6.86150,784.15005,-0.13380,23.93091,39.89002
82.53800,6.87818,784.48197,-0.13380,23.99764,39.90691
82.73801,6.89480,784.83801,-0.13380,24.06413,39.92502
82.93800,6.91155,784.49650,-0.13380,24.13109,39.90765
83.13800,6.92817,784.67345,-0.13380,24.19757,39.91665
83.33801,6.94479,783.88555,-0.13380,24.26406,39.87656
83.53800,6.96141,784.72747,-0.13380,24.33055,39.91940
83.73801,6.97815,784.06362,-0.13381,24.39751,39.88562
83.93800,6.99483,784.36816,-0.13380,24.46424,39.90112
84.13800,7.01151,784.69086,-0.13380,24.53096,39.91753
84.33801,7.02814,784.59959,-0.13380,24.59745,39.91289
84.53800,7.04482,784.13170,-0.13381,24.66417,39.88909
84.73801,7.06150,783.74753,-0.13381,24.73090,39.86954
84.93800,7.07824,784.55172,-0.13380,24.79786,39.91045
85.13800,7.09486,783.68485,-0.13381,24.86435,39.86636
85.33801,7.11148,783.71977,-0.13381,24.93083,39.86813
85.53800,7.12816,784.26581,-0.13381,24.99756,39.89591
85.73801,7.14484,783.85035,-0.13380,25.06428,39.87477
85.93800,7.16147,784.31591,-0.13380,25.13077,39.89846
86.13800,7.17815,784.42385,-0.13380,25.19750,39.90395
86.33801,7.19483,784.56476,-0.13380,25.26422,39.91112
86.53800,7.21145,784.13235,-0.13380,25.33070,39.88912
86.73801,7.22807,784.52248,-0.13381,25.39719,39.90897
86.93800,7.24487,784.48681,-0.13381,25.46440,39.90715
87.13800,7.26155,784.42590,-0.13381,25.53112,39.90405
87.33801,7.27817,784.44593,-0.13381,25.59761,39.90507
87.53800,7.29486,783.42436,-0.13381,25.66433,39.85310
87.73801,7.31154,783.87270,-0.13380,25.73106,39.87591
87.93800,7.32810,784.46548,-0.13381,25.79730,39.90607
88.13800,7.34478,783.81272,-0.13380,25.86403,39.87286
88.33801,7.36152,783.84457,-0.13381,25.93099,39.87448
88.53800,7.37814,784.09072,-0.13381,25.99748,39.88700
88.73801,7.39482,783.77957,-0.13380,26.06420,39.87117
88.93800,7.41145,783.73989,-0.13381,26.13069,39.86916
89.13800,7.42813,783.39046,-0.13381,26.19742,39.85138
89.33801,7.44487,784.03205,-0.13380,26.26438,39.88402
89.53800,7.46155,783.67880,-0.13381,26.33110,39.86605
89.73801,7.47817,783.01216,-0.13381,26.39759,39.83213
89.93800,7.49485,783.41682,-0.13380,26.46432,39.85272
90.13800,7.51153,783.31046,-0.13381,26.53104,39.84731
90.33801,7.52827,783.45630,-0.13381,26.59801,39.85473
90.53800,7.54484,783.20522,-0.13381,26.66425,39.84196
90.73801,7.56152,783.69444,-0.13381,26.73098,39.86684
90.93800,7.57814,783.34166,-0.13381,26.79746,39.84890
91.13801,7.59482,783.04075,-0.13381,26.86419,39.83359
91.33801,7.61156,783.71363,-0.13381,26.93115,39.86782
91.53800,7.62812,783.26100,-0.13381,26.99740,39.84480
91.73801,7.64474,783.38264,-0.13381,27.06389,39.85098
91.93800,7.66149,783.14804,-0.13381,27.13085,39.83905
92.13801,7.67811,783.67647,-0.13380,27.19733,39.86593
92.33801,7.69491,782.66757,-0.13381,27.26454,39.81461
92.53800,7.71153,782.28246,-0.13381,27.33102,39.79502
92.73801,7.72815,782.23767,-0.13381,27.39751,39.79274
92.93800,7.74489,782.71274,-0.13381,27.46448,39.81690
93.13801,7.76151,783.08238,-0.13380,27.53096,39.83571
93.33801,7.77807,782.56447,-0.13381,27.59721,39.80936
93.53800,7.79482,782.16922,-0.13381,27.66417,39.78925
93.73801,7.81150,782.37578,-0.13381,27.73090,39.79976
93.93800,7.82812,782.90589,-0.13381,27.79738,39.82673
94.13801,7.84480,782.67390,-0.13381,27.86410,39.81493
94.33801,7.86154,782.14193,-0.13381,27.93107,39.78787
94.53800,7.87822,782.00251,-0.13381,27.99779,39.78077
94.73801,7.89484,781.71864,-0.13381,28.06428,39.76633
94.93800,7.91158,782.67045,-0.13381,28.13125,39.81475
95.13801,7.92809,782.31217,-0.13381,28.19725,39.79653
95.33801,7.94483,782.88810,-0.13381,28.26422,39.82582
95.53800,7.96151,782.31618,-0.13381,28.33094,39.79673
95.73801,7.97819,781.99338,-0.13381,28.39767,39.78031
95.93800,7.99487,781.25224,-0.13381,28.46439,39.74261
96.13801,8.01143,781.80898,-0.13380,28.53064,39.77093
96.33801,8.02817,781.90928,-0.13381,28.59760,39.77603
96.53800,8.04480,781.67226,-0.13381,28.66409,39.76397
96.73801,8.06142,781.80563,-0.13381,28.73057,39.77076
96.93800,8.07816,781.41466,-0.13381,28.79754,39.75087
97.13801,8.09478,781.65494,-0.13381,28.86403,39.76309
97.33801,8.11146,781.45415,-0.13381,28.93075,39.75288
97.53800,8.12814,781.39389,-0.13381,28.99747,39.74981
97.73801,8.14482,780.52785,-0.13381,29.06420,39.70576
97.93800,8.16162,780.84571,-0.13381,29.13140,39.72193
98.13801,8.17813,781.16306,-0.13381,29.19741,39.73807
98.33801,8.19481,780.94350,-0.13381,29.26413,39.72690
98.53800,8.21149,780.47039,-0.13381,29.33086,39.70284
98.73801,8.22817,780.59081,-0.13381,29.39759,39.70896
98.93800,8.24485,780.24813,-0.13381,29.46431,39.69153
99.13801,8.26147,780.94373,-0.13381,29.53080,39.72691
99.33801,8.27809,779.91597,-0.13381,29.59729,39.67463
99.53800,8.29478,779.74596,-0.13381,29.66401,39.66598
99.73801,8.31152,780.33255,-0.13381,29.73098,39.69582
99.93800,8.32820,780.08734,-0.13381,29.79770,39.68335
100.13801,8.34488,779.81288,-0.13381,29.86442,39.66939
100.33801,8.36150,779.95933,-0.13381,29.93091,39.67684
100.53800,8.37812,780.11318,-0.13381,29.99740,39.68466
100.73801,8.39486,779.48971,-0.13381,30.06436,39.65295
100.93800,8.41160,779.96622,-0.13381,30.13133,39.67719
101.13801,8.42811,779.42787,-0.13381,30.19733,39.64980
101.33801,8.44479,779.54526,-0.13381,30.26406,39.65577
101.53800,8.46159,779.50656,-0.13381,30.33126,39.65380
101.73801,8.47815,779.05199,-0.13381,30.39751,39.63068
101.93800,8.49477,779.17534,-0.13381,30.46399,39.63696
102.13801,8.51151,779.17408,-0.13381,30.53096,39.63689
102.33801,8.52819,778.94344,-0.13381,30.59768,39.62516
102.53800,8.54476,778.45831,-0.13381,30.66393,39.60048
102.73801,8.56150,779.11802,-0.13381,30.73089,39.63404
102.93800,8.57824,778.51964,-0.13381,30.79785,39.60360
103.13801,8.59480,778.79550,-0.13380,30.86410,39.61763
103.33801,8.61154,778.10027,-0.13381,30.93107,39.58227
103.53800,8.62822,778.16932,-0.13381,30.99779,39.58578
103.73801,8.64478,777.97468,-0.13381,31.06404,39.57588
103.93800,8.66146,778.78172,-0.13381,31.13076,39.61693
104.13801,8.67821,777.92672,-0.13381,31.19773,39.57344
104.33801,8.69483,777.34375,-0.13381,31.26422,39.54378
104.53800,8.71145,777.21174,-0.13381,31.33070,39.53707
104.73801,8.72813,777.23134,-0.13381,31.39743,39.53806
104.93800,8.74487,777.28140,-0.13381,31.46439,39.54061
105.13801,8.76149,776.91982,-0.13381,31.53087,39.52222
105.33801,8.77817,776.43390,-0.13381,31.59760,39.49750
105.53800,8.79491,777.09723,-0.13382,31.66456,39.53124
105.73801,8.81148,776.79977,-0.13381,31.73081,39.51611
105.93800,8.82810,776.75707,-0.13381,31.79730,39.51394
106.13801,8.84490,776.49383,-0.13381,31.86450,39.50055
106.33801,8.86152,776.76182,-0.13381,31.93099,39.51418
106.53800,8.87814,776.45192,-0.13381,31.99747,39.49841
106.73801,8.89482,776.19422,-0.13381,32.06420,39.48531
106.93800,8.91144,776.36437,-0.13381,32.13068,39.49396
107.13801,8.92807,776.10989,-0.13381,32.19717,39.48101
107.33801,8.94487,775.92502,-0.13381,32.26437,39.47161
107.53800,8.96155,775.75734,-0.13381,32.33110,39.46308
107.73801,8.97811,775.91431,-0.13381,32.39734,39.47107
107.93800,8.99479,775.65392,-0.13381,32.46407,39.45782
108.13801,9.01159,775.28004,-0.13381,32.53128,39.43880
108.33801,9.02809,774.97088,-0.13381,32.59728,39.42307
108.53800,9.04483,774.68329,-0.13381,32.66425,39.40844
108.73801,9.06164,775.40311,-0.13381,32.73145,39.44506
108.93800,9.07814,774.70890,-0.13381,32.79746,39.40974
109.13801,9.09476,774.62047,-0.13381,32.86394,39.40525
109.33801,9.11156,774.71682,-0.13381,32.93115,39.41015
109.53800,9.12824,774.52268,-0.13381,32.99787,39.40027
109.73801,9.14474,773.53329,-0.13381,33.06388,39.34994
109.93800,9.16142,774.35286,-0.13381,33.13060,39.39163
110.13801,9.17823,773.85372,-0.13381,33.19781,39.36624
110.33801,9.19479,773.78908,-0.13381,33.26405,39.36295
110.53800,9.21153,773.46638,-0.13381,33.33102,39.34654
110.73801,9.22833,773.59215,-0.13381,33.39822,39.35294
110.93800,9.24477,773.33720,-0.13381,33.46399,39.33997
111.13801,9.26151,772.92244,-0.13381,33.53095,39.31887
111.33801,9.27819,772.43075,-0.13381,33.59768,39.29385
111.53800,9.29481,773.12137,-0.13381,33.66417,39.32899
111.73801,9.31150,772.47228,-0.13381,33.73089,39.29597
111.93800,9.32818,772.75420,-0.13381,33.79762,39.31031
112.13801,9.34486,772.45720,-0.13381,33.86434,39.29520
112.33801,9.36142,771.70921,-0.13381,33.93059,39.25715
112.53800,9.37810,772.40728,-0.13381,33.99731,39.29266
112.73801,9.39484,771.19074,-0.13381,34.06428,39.23077
112.93800,9.41152,771.86036,-0.13381,34.13100,39.26484
113.13801,9.42821,771.54418,-0.13381,34.19773,39.24876
113.33801,9.44489,771.36778,-0.13381,34.26445,39.23978
113.53800,9.46151,771.55023,-0.13381,34.33094,39.24906
113.73801,9.47819,771.13668,-0.13381,34.39766,39.22802
113.93800,9.49487,771.19153,-0.13381,34.46439,39.23082
114.13801,9.51155,770.63954,-0.13381,34.53111,39.20274
114.33801,9.52805,770.98734,-0.13381,34.59712,39.22043
114.53800,9.54479,770.12526,-0.13381,34.66409,39.17657
114.73801,9.56160,770.19166,-0.13381,34.73129,39.17995
114.93800,9.57816,770.35232,-0.13381,34.79754,39.18813
115.13801,9.59478,770.05583,-0.13381,34.86402,39.17304
115.33801,9.61158,770.11241,-0.13381,34.93122,39.17592
115.53800,9.62814,769.55277,-0.13381,34.99747,39.14745
115.73801,9.64476,769.49983,-0.13382,35.06396,39.14476
115.93800,9.66150,769.03128,-0.13381,35.13092,39.12092
116.13801,9.67830,769.13526,-0.13381,35.19813,39.12621
116.33801,9.69475,768.44054,-0.13381,35.26389,39.09087
116.53800,9.71149,768.53288,-0.13381,35.33086,39.09557
116.73801,9.72829,768.93899,-0.13382,35.39806,39.11623
116.93800,9.74479,768.85279,-0.13381,35.46407,39.11184
117.13801,9.76153,767.92175,-0.13381,35.53103,39.06448
117.33801,9.77827,768.36213,-0.13381,35.59800,39.08688
117.53800,9.79477,767.80892,-0.13382,35.66400,39.05874
117.73801,9.81146,767.71942,-0.13381,35.73073,39.05419
117.93800,9.82814,767.20947,-0.13381,35.79745,39.02825
118.13801,9.84482,767.53385,-0.13381,35.86418,39.04475
118.33801,9.86150,767.12370,-0.13381,35.93090,39.02388
118.53800,9.87806,767.33478,-0.13381,35.99715,39.03462
118.73801,9.89486,766.46092,-0.13381,36.06435,38.99017
118.93800,9.91148,766.19806,-0.13381,36.13084,38.97680
119.13801,9.92817,766.48686,-0.13381,36.19757,38.99149
119.33801,9.94491,766.19070,-0.13381,36.26453,38.97642
119.53800,9.96153,766.32509,-0.13381,36.33101,38.98326
119.73801,9.97815,765.53319,-0.13381,36.39750,38.94297
119.93800,9.99477,765.49533,-0.13381,36.46399,38.94105
120.13801,10.01145,764.84219,-0.13382,36.53071,38.90782
120.33801,10.02813,764.87521,-0.13381,36.59744,38.90950
120.53800,10.04481,764.88233,-0.13381,36.66416,38.90986
120.73801,10.06149,765.08322,-0.13381,36.73089,38.92008
120.93800,10.07812,764.20452,-0.13381,36.79737,38.87539
121.13801,10.09480,764.88508,-0.13381,36.86410,38.91000
121.33801,10.11154,764.26058,-0.13381,36.93106,38.87823
121.53800,10.12816,763.96898,-0.13381,36.99755,38.86340
121.73801,10.14484,763.52200,-0.13382,37.06428,38.84066
121.93800,10.16158,763.41718,-0.13382,37.13124,38.83533
122.13801,10.17814,763.63883,-0.13381,37.19748,38.84661
122.33801,10.19477,763.51720,-0.13381,37.26397,38.84042
122.53800,10.21157,762.65410,-0.13381,37.33117,38.79651
122.73801,10.22819,762.64609,-0.13382,37.39766,38.79610
122.93800,10.24481,763.01126,-0.13382,37.46415,38.81468
123.13801,10.26143,762.22313,-0.13381,37.53063,38.77459
123.33801,10.27817,762.75291,-0.13381,37.59759,38.80154
123.53801,10.29485,761.68324,-0.13381,37.66432,38.74712
123.73801,10.31147,761.85009,-0.13382,37.73080,38.75561
123.93800,10.32822,761.39001,-0.13382,37.79777,38.73221
124.13801,10.34478,760.82908,-0.13382,37.86402,38.70367
124.33801,10.36152,761.37572,-0.13381,37.93098,38.73148
124.53801,10.37820,760.73282,-0.13382,37.99771,38.69878
124.73801,10.39488,760.60565,-0.13382,38.06443,38.69231
124.93800,10.41144,760.14563,-0.13382,38.13068,38.66891
125.13801,10.42806,760.25603,-0.13381,38.19717,38.67452
125.33801,10.44481,760.24621,-0.13381,38.26413,38.67402
125.53801,10.46149,759.38306,-0.13381,38.33086,38.63012
125.73801,10.47817,759.18199,-0.13381,38.39757,38.61988
125.93800,10.49485,759.38636,-0.13381,38.46430,38.63028
126.13801,10.51147,758.56536,-0.13381,38.53079,38.58852
126.33801,10.52815,758.45821,-0.13381,38.59751,38.58307
126.53801,10.54483,758.62855,-0.13382,38.66424,38.59173
126.73801,10.56151,757.77764,-0.13381,38.73097,38.54845
126.93800,10.57826,758.00358,-0.13382,38.79793,38.55994
127.13801,10.59482,757.71958,-0.13381,38.86418,38.54549
127.33801,10.61150,757.54668,-0.13381,38.93090,38.53670
127.53801,10.62812,756.48171,-0.13382,38.99738,38.48252
127.73801,10.64480,756.95333,-0.13381,39.06412,38.50651
127.93800,10.66154,757.04129,-0.13381,39.13108,38.51099
128.13800,10.67816,756.29205,-0.13381,39.19756,38.47287
128.33802,10.69479,755.73581,-0.13382,39.26405,38.44458
128.53801,10.71153,755.55122,-0.13381,39.33101,38.43519
128.73801,10.72821,755.33977,-0.13381,39.39774,38.42443
128.93800,10.74483,754.81688,-0.13381,39.46422,38.39783
129.13800,10.76157,754.56910,-0.13382,39.53119,38.38523
129.33802,10.77813,754.64025,-0.13381,39.59744,38.38885
129.53801,10.79475,753.89729,-0.13382,39.66392,38.35105
129.73801,10.81144,753.64956,-0.13381,39.73065,38.33845
129.93800,10.82824,753.82511,-0.13382,39.79785,38.34738
130.13800,10.84486,753.42092,-0.13382,39.86433,38.32682
130.33802,10.86148,753.28886,-0.13381,39.93082,38.32010
130.53801,10.87822,752.18626,-0.13382,39.99778,38.26401
130.73801,10.89478,752.64797,-0.13382,40.06403,38.28750
130.93800,10.91146,751.68530,-0.13382,40.13076,38.23853
131.13800,10.92820,751.26234,-0.13381,40.19772,38.21701
131.33802,10.94476,751.49685,-0.13382,40.26397,38.22894
131.53802,10.96145,750.22336,-0.13382,40.33069,38.16416
131.73800,10.97813,749.58871,-0.13382,40.39742,38.13187
131.93800,10.99493,750.46783,-0.13381,40.46462,38.17659
132.13800,11.01155,749.43216,-0.13382,40.53110,38.12391
132.33802,11.02817,749.55132,-0.13382,40.59759,38.12997
132.53802,11.04485,748.96091,-0.13381,40.66432,38.09993
132.73800,11.06147,748.69604,-0.13382,40.73080,38.08646
132.93800,11.07816,748.37320,-0.13381,40.79753,38.07004
133.13800,11.09490,747.43042,-0.13381,40.86449,38.02208
133.33802,11.11152,747.58078,-0.13382,40.93098,38.02973
133.53802,11.12808,746.86226,-0.13382,40.99723,37.99318
133.73800,11.14482,746.83330,-0.13381,41.06419,37.99170
133.93800,11.16156,746.16913,-0.13381,41.13116,37.95792
134.13800,11.17818,745.35753,-0.13381,41.19764,37.91663
134.33802,11.19487,745.38384,-0.13382,41.26437,37.91797
134.53802,11.21155,744.84097,-0.13382,41.33109,37.89035
134.73800,11.22811,744.85014,-0.13381,41.39734,37.89082
134.93800,11.24485,744.40064,-0.13382,41.46430,37.86795
135.13800,11.26159,743.23788,-0.13382,41.53127,37.80880
135.33802,11.27821,743.42843,-0.13382,41.59775,37.81850
135.53802,11.29483,742.80878,-0.13382,41.66424,37.78697
135.73800,11.31145,742.58330,-0.13382,41.73072,37.77551
135.93800,11.32819,742.03745,-0.13382,41.79769,37.74774
136.13800,11.34482,742.17785,-0.13382,41.86417,37.75488
136.33802,11.36150,741.39591,-0.13382,41.93090,37.71510
136.53802,11.37824,740.88182,-0.13382,41.99786,37.68895
136.73800,11.39480,740.37639,-0.13382,42.06411,37.66324
136.93800,11.41142,739.89951,-0.13382,42.13060,37.63898
137.13800,11.42822,738.97978,-0.13382,42.19780,37.59219
137.33802,11.44485,738.66248,-0.13382,42.26429,37.57605
137.53802,11.46153,738.27901,-0.13382,42.33101,37.55654
137.73800,11.47821,738.25596,-0.13382,42.39774,37.55537
137.93800,11.49489,738.15435,-0.13382,42.46446,37.55020
138.13800,11.51145,737.47099,-0.13381,42.53071,37.51544
138.33802,11.52813,737.03048,-0.13381,42.59743,37.49303
138.53802,11.54493,736.64123,-0.13382,42.66464,37.47323
138.73800,11.56143,735.19638,-0.13381,42.73065,37.39973
138.93800,11.57806,735.24523,-0.13382,42.79713,37.40221
139.13800,11.59486,734.39674,-0.13381,42.86433,37.35905
139.33802,11.61148,733.63166,-0.13382,42.93082,37.32013
139.53802,11.62822,733.77322,-0.13382,42.99778,37.32733
139.73800,11.64484,732.79170,-0.13382,43.06427,37.27740
139.93800,11.66152,731.71775,-0.13382,43.13099,37.22277
140.13800,11.67814,730.81171,-0.13382,43.19748,37.17668
140.33802,11.69476,731.26038,-0.13381,43.26396,37.19950
140.53802,11.71157,730.06311,-0.13382,43.33117,37.13860
140.73800,11.72813,729.40961,-0.13382,43.39741,37.10535
140.93800,11.74481,728.99004,-0.13382,43.46414,37.08401
141.13800,11.76149,728.21248,-0.13382,43.53087,37.04446
141.33802,11.77811,727.54528,-0.13382,43.59735,37.01051
141.53802,11.79479,726.37945,-0.13382,43.66407,36.95121
141.73800,11.81153,726.40907,-0.13382,43.73104,36.95271
141.93800,11.82816,725.45228,-0.13382,43.79753,36.90404
142.13800,11.84484,724.84510,-0.13382,43.86425,36.87315
142.33802,11.86146,723.55638,-0.13382,43.93074,36.80760
142.53802,11.87820,722.82963,-0.13382,43.99770,36.77063
142.73800,11.89482,722.29356,-0.13382,44.06419,36.74335
142.93800,11.91150,720.61829,-0.13382,44.13091,36.65813
143.13800,11.92818,720.63566,-0.13382,44.19764,36.65902
143.33802,11.94480,718.65972,-0.13382,44.26412,36.55850
143.53802,11.96143,716.92918,-0.13382,44.33061,36.47047
143.73800,11.97823,715.65346,-0.13382,44.39781,36.40557
143.93800,11.99485,713.35607,-0.13382,44.46430,36.28870
144.13800,12.01141,711.06800,-0.13382,44.53054,36.17231
144.33802,12.02815,707.31398,-0.13382,44.59751,35.98134
144.53802,12.04489,701.21554,-0.13382,44.66448,35.67111
144.73800,12.06151,686.61296,-0.13382,44.73096,34.92827
144.93800,12.07819,219.00295,-0.13382,44.79769,11.14077
144.96000,12.08005,6.74294,-0.13382,44.80510,0.34302