File: Manufatura Aditiva/Dados/Ensaios AMR/Ensaios/Ensaios PP/Tracao_OLABI_21_05_2018_Polipropileno.is_metal_RawData/Specimen_RawData_1.csv
Time,Extension,Load,Strain 1,Tensile strain,Tensile stress
(sec),(mm),(N),(mm/mm),(%),(MPa)
0.00000,0.00000,23.12176,0.00085,0.08466,1.13342
3.50000,0.29171,133.29010,0.00459,0.45878,6.53383
7.00000,0.58337,213.59383,0.00826,0.82628,10.47029
10.50000,0.87496,271.98063,0.01226,1.22608,13.33238
14.00000,1.16661,316.28981,0.01678,1.67799,15.50440
17.50000,1.45845,350.15664,0.02151,2.15104,17.16454
21.00000,1.75010,377.99899,0.02650,2.64989,18.52936
24.41200,2.03434,402.13177,0.03155,3.26566,19.71234
27.91200,2.32605,422.70110,0.07202,4.43251,20.72064
31.41200,2.61764,440.59418,-0.13323,5.59889,21.59775
34.91200,2.90930,456.60646,-0.13323,6.76550,22.38267
38.41200,3.20095,468.74154,-0.13323,7.93211,22.97753
41.91200,3.49272,477.34780,-0.13323,9.09920,23.39940
45.41200,3.78444,483.31725,-0.13323,10.26605,23.69202
48.91200,4.07591,488.23454,-0.13323,11.43195,23.93307
52.41200,4.36762,490.68006,-0.13323,12.59880,24.05294
55.91200,4.65940,491.32421,-0.13323,13.76589,24.08452
59.41200,4.95105,490.89734,-0.13323,14.93250,24.06359
62.91200,5.24270,489.86650,-0.13323,16.09912,24.01306
66.41200,5.53435,488.70519,-0.13323,17.26573,23.95614
69.91200,5.82601,486.14652,-0.13323,18.43234,23.83071
73.41200,6.11754,483.23944,-0.13323,19.59848,23.68821
76.91200,6.40937,479.90344,-0.13323,20.76581,23.52468
80.41200,6.70103,477.91759,-0.13323,21.93242,23.42733
83.91200,6.99274,474.09204,-0.13323,23.09927,23.23981
87.41200,7.28433,471.48932,-0.13323,24.26564,23.11222
90.91200,7.57599,468.36287,-0.13323,25.43226,22.95896
94.41200,7.86770,464.86165,-0.13323,26.59911,22.78734
97.91200,8.15941,462.01916,-0.13323,27.76596,22.64800
101.41200,8.45101,458.78547,-0.13323,28.93233,22.48948
104.91200,8.74254,456.55603,-0.13323,30.09847,22.38020
108.41200,9.03437,453.91796,-0.13323,31.26580,22.25088
111.91200,9.32603,450.73996,-0.13323,32.43241,22.09510
115.41200,9.61768,448.43550,-0.13323,33.59902,21.98213
118.91200,9.90933,446.19557,-0.13323,34.76563,21.87233
122.41200,10.20098,442.75043,-0.13323,35.93225,21.70345
125.91200,10.49264,440.64927,-0.13323,37.09886,21.60045
129.41200,10.78429,438.71691,-0.13323,38.26547,21.50573
132.91200,11.07606,436.00718,-0.13323,39.43256,21.37290
136.41200,11.36772,434.36470,-0.13323,40.59918,21.29239
139.91200,11.65931,431.90708,-0.13323,41.76555,21.17192
143.41200,11.95096,430.63853,-0.13323,42.93216,21.10973
146.91200,12.24262,427.93718,-0.13323,44.09877,20.97731
150.41200,12.53445,426.28609,-0.13323,45.26610,20.89638
153.91200,12.82604,423.64737,-0.13323,46.43248,20.76703
157.41200,13.11758,421.64074,-0.13323,47.59862,20.66866
160.91200,13.40935,419.23951,-0.13323,48.76570,20.55096
164.41200,13.70100,417.58525,-0.13323,49.93231,20.46987
167.91200,13.99271,415.81793,-0.13323,51.09917,20.38323
171.41200,14.28443,414.29615,-0.13323,52.26602,20.30863
174.91200,14.57602,412.08663,-0.13323,53.43239,20.20033
178.41200,14.86761,410.93458,-0.13323,54.59877,20.14385
181.91200,15.15927,408.81978,-0.13322,55.76538,20.04019
185.41200,15.45104,406.89204,-0.13323,56.93247,19.94569
188.91200,15.74269,405.90013,-0.13322,58.09908,19.89707
192.41200,16.03435,404.64667,-0.13323,59.26570,19.83562
195.91200,16.32594,402.69052,-0.13323,60.43207,19.73973
199.41200,16.61759,401.58252,-0.13323,61.59868,19.68542
202.91200,16.90937,400.91001,-0.13323,62.76577,19.65245
206.41200,17.20108,399.31126,-0.13323,63.93262,19.57408
209.91200,17.49261,399.05771,-0.13322,65.09876,19.56165
213.41200,17.78432,398.30827,-0.13323,66.26561,19.52492
216.91202,18.07604,397.17751,-0.13323,67.43246,19.46949
220.41202,18.36763,395.93917,-0.13323,68.59883,19.40878
223.91202,18.65934,395.73372,-0.13323,69.76569,19.39871
227.41202,18.95100,394.94806,-0.13323,70.93230,19.36020
230.91202,19.24271,395.10448,-0.13323,72.09915,19.36787
234.41202,19.53424,394.38661,-0.13323,73.26528,19.33268
237.91202,19.82602,394.46517,-0.13323,74.43237,19.33653
241.41202,20.11773,393.44789,-0.13323,75.59922,19.28666
244.91202,20.40926,393.83606,-0.13323,76.76536,19.30569
248.41202,20.70091,393.39517,-0.13322,77.93197,19.28408
251.91202,20.99263,393.11084,-0.13323,79.09882,19.27014
255.41202,21.28434,392.68425,-0.13323,80.26568,19.24923
258.91202,21.57605,392.80467,-0.13323,81.43253,19.25513
262.41203,21.86765,392.26138,-0.13323,82.59890,19.22850
265.91203,22.15930,392.20243,-0.13323,83.76551,19.22561
269.41203,22.45101,391.96122,-0.13323,84.93237,19.21379
272.91203,22.74261,392.11856,-0.13323,86.09874,19.22150
276.41203,23.03438,392.68332,-0.13322,87.26583,19.24918
279.91203,23.32603,392.67298,-0.13323,88.43244,19.24868
283.41203,23.61769,392.67670,-0.13322,89.59906,19.24886
286.91203,23.90928,392.69980,-0.13323,90.76543,19.24999
290.41203,24.20099,392.24918,-0.13322,91.93228,19.22790
293.91203,24.49282,392.79712,-0.13323,93.09961,19.25476
297.41203,24.78430,392.96839,-0.13323,94.26550,19.26316
300.91203,25.07595,392.67153,-0.13323,95.43211,19.24860
304.41203,25.36766,392.86613,-0.13323,96.59897,19.25814
307.91203,25.65938,392.64378,-0.13323,97.76582,19.24724
311.41203,25.95103,392.52760,-0.13323,98.93243,19.24155
314.91203,26.24268,392.94353,-0.13322,100.09905,19.26194
318.41203,26.53428,393.33892,-0.13323,101.26542,19.28132
321.91203,26.82599,393.19331,-0.13322,102.43227,19.27418
325.41203,27.11758,393.26753,-0.13322,103.59864,19.27782
328.91203,27.40942,392.78721,-0.13323,104.76598,19.25427
332.41203,27.70107,393.87955,-0.13323,105.93259,19.30782
335.91203,27.99260,393.78405,-0.13322,107.09872,19.30314
339.41203,28.28432,393.97390,-0.13323,108.26558,19.31245
342.91203,28.57597,394.22819,-0.13323,109.43218,19.32491
346.41203,28.86774,394.38056,-0.13323,110.59927,19.33238
349.91203,29.15939,394.31397,-0.13323,111.76589,19.32912
353.41203,29.45093,394.61968,-0.13323,112.93203,19.34410
356.91203,29.74264,394.38610,-0.13323,114.09888,19.33265
360.41203,30.03430,393.77687,-0.13322,115.26550,19.30279
363.91203,30.32601,393.80537,-0.13322,116.43234,19.30419
367.41203,30.61772,394.45208,-0.13322,117.59919,19.33589
370.91203,30.90937,394.24677,-0.13323,118.76581,19.32582
374.41203,31.20103,394.76398,-0.13323,119.93241,19.35118
377.91203,31.49268,394.69469,-0.13322,121.09902,19.34778
381.41203,31.78433,395.31542,-0.13322,122.26564,19.37821
384.91203,32.07611,395.29558,-0.13323,123.43274,19.37723
388.41203,32.36764,395.48571,-0.13322,124.59886,19.38655
391.91203,32.65923,395.32068,-0.13322,125.76524,19.37847
395.41203,32.95101,395.30313,-0.13323,126.93233,19.37760
398.91203,33.24278,396.54267,-0.13323,128.09942,19.43837
402.41203,33.53437,395.81670,-0.13322,129.26580,19.40278
405.91203,33.82596,395.49521,-0.13323,130.43216,19.38702
409.41203,34.11768,395.06233,-0.13323,131.59902,19.36580
412.91203,34.40939,395.30410,-0.13323,132.76587,19.37765
416.41203,34.70098,395.82788,-0.13323,133.93224,19.40333
419.91203,34.99276,396.03901,-0.13322,135.09933,19.41368
423.41203,35.28441,395.98327,-0.13322,136.26595,19.41094
426.91203,35.57594,396.67636,-0.13322,137.43209,19.44492
430.41203,35.86760,396.82589,-0.13322,138.59869,19.45225
433.91203,36.15931,396.66630,-0.13322,139.76554,19.44443
437.41203,36.45114,396.70500,-0.13322,140.93288,19.44632
440.91203,36.74268,396.24888,-0.13322,142.09901,19.42397
444.41203,37.03433,396.28516,-0.13322,143.26563,19.42574
447.91203,37.32604,396.23324,-0.13322,144.43249,19.42320
451.41203,37.61770,396.01550,-0.13322,145.59909,19.41253
454.91203,37.90935,395.51551,-0.13322,146.76571,19.38802
458.41203,38.20106,396.23128,-0.13322,147.93255,19.42310
461.91203,38.49265,396.56586,-0.13322,149.09893,19.43950
465.41203,38.78425,396.42360,-0.13322,150.26530,19.43253
468.91203,39.07602,396.64563,-0.13322,151.43238,19.44341
472.41203,39.36773,396.57215,-0.13322,152.59924,19.43981
475.91203,39.65932,396.42630,-0.13322,153.76561,19.43266
479.41203,39.95098,396.33242,-0.13322,154.93222,19.42806
482.91203,40.24263,397.28945,-0.13322,156.09883,19.47497
486.41203,40.53428,396.83133,-0.13322,157.26545,19.45252
489.91203,40.82606,397.20545,-0.13322,158.43254,19.47086
493.41203,41.11777,397.04381,-0.13322,159.59939,19.46293
496.91203,41.40925,397.00759,-0.13322,160.76530,19.46116
500.41203,41.70096,397.48680,-0.13322,161.93215,19.48465
503.91203,41.99267,397.07352,-0.13323,163.09899,19.46439
507.41203,42.28438,396.89029,-0.13322,164.26584,19.45541
510.91203,42.57597,396.92861,-0.13322,165.43221,19.45728
514.41206,42.86775,397.00489,-0.13322,166.59931,19.46102
517.91206,43.15940,396.74458,-0.13322,167.76592,19.44826
521.41206,43.45093,397.40726,-0.13322,168.93204,19.48075
524.91206,43.74271,396.79608,-0.13322,170.09914,19.45079
528.41206,44.03436,396.68907,-0.13322,171.26576,19.44554
531.91206,44.32601,397.30361,-0.13322,172.43236,19.47567
535.41206,44.61761,397.47478,-0.13322,173.59873,19.48406
538.91206,44.90926,396.72200,-0.13322,174.76535,19.44716
542.41206,45.20109,396.32111,-0.13322,175.93268,19.42751
545.91206,45.49269,396.89518,-0.13322,177.09907,19.45565
549.41206,45.78428,396.38653,-0.13322,178.26544,19.43071
552.91206,46.07594,396.44348,-0.13322,179.43206,19.43350
556.41206,46.36765,396.74812,-0.13322,180.59891,19.44844
559.91206,46.65930,396.68120,-0.13322,181.76552,19.44516
563.41206,46.95107,396.34225,-0.13322,182.93260,19.42854
566.91206,47.24266,395.31039,-0.13322,184.09897,19.37796
570.41206,47.53438,395.74662,-0.13322,185.26583,19.39934
573.91206,47.82603,396.09871,-0.13322,186.43243,19.41660
577.41206,48.11768,395.72907,-0.13322,187.59905,19.39848
580.91206,48.40946,395.33023,-0.13322,188.76615,19.37893
584.41206,48.70105,395.49642,-0.13322,189.93251,19.38708
587.91206,48.99264,395.82369,-0.13322,191.09888,19.40312
591.41206,49.28424,395.38420,-0.13322,192.26525,19.38158
594.91206,49.57607,395.61903,-0.13322,193.43259,19.39309
598.41206,49.86772,395.88287,-0.13322,194.59920,19.40602
601.91206,50.15938,395.65908,-0.13322,195.76582,19.39505
605.41206,50.45097,395.07300,-0.13322,196.93221,19.36632
608.91206,50.74268,395.59281,-0.13323,198.09904,19.39180
612.41206,51.03434,395.72865,-0.13322,199.26565,19.39846
615.91206,51.32605,394.75425,-0.13322,200.43252,19.35070
619.41206,51.61776,395.34466,-0.13323,201.59936,19.37964
622.91206,51.90929,395.13786,-0.13322,202.76549,19.36950
626.41206,52.20101,395.56581,-0.13322,203.93233,19.39048
629.91206,52.49266,395.58108,-0.13322,205.09896,19.39123
633.41206,52.78437,395.34462,-0.13322,206.26581,19.37964
636.91206,53.07603,394.93726,-0.13322,207.43241,19.35967
640.41206,53.36762,395.53097,-0.13322,208.59878,19.38877
643.91206,53.65927,395.16999,-0.13322,209.76541,19.37108
647.41206,53.95099,394.99737,-0.13322,210.93225,19.36262
650.91206,54.24270,395.56236,-0.13322,212.09912,19.39031
654.41206,54.53430,395.34699,-0.13322,213.26549,19.37976
657.91206,54.82595,394.80561,-0.13322,214.43212,19.35322
661.41206,55.11766,395.34844,-0.13322,215.59896,19.37983
664.91206,55.40932,395.31877,-0.13322,216.76557,19.37837
668.41206,55.70097,395.07253,-0.13322,217.93218,19.36630
671.91206,55.99268,395.11090,-0.13322,219.09902,19.36818
675.41206,56.28433,395.43831,-0.13322,220.26563,19.38423
678.91206,56.57587,394.64678,-0.13322,221.43178,19.34543
682.41206,56.86758,394.90089,-0.13322,222.59862,19.35789
685.91206,57.15941,394.84981,-0.13322,223.76595,19.35538
689.41206,57.45106,394.62224,-0.13322,224.93258,19.34423
692.91206,57.74260,394.02717,-0.13322,226.09870,19.31506
696.41206,58.03425,394.27239,-0.13322,227.26531,19.32708
699.91206,58.32602,394.16663,-0.13322,228.43239,19.32189
703.41206,58.61768,393.76859,-0.13322,229.59902,19.30238
706.91206,58.90933,394.36989,-0.13322,230.76565,19.33186
710.41206,59.20105,393.13142,-0.13322,231.93250,19.27115
713.91206,59.49270,393.57976,-0.13322,233.09910,19.29313
717.41206,59.78429,393.70996,-0.13322,234.26547,19.29951
720.91206,60.07601,393.23904,-0.13322,235.43234,19.27642
724.41206,60.36784,393.21207,-0.13322,236.59966,19.27510
727.91206,60.65937,393.11373,-0.13322,237.76579,19.27028
731.41206,60.95096,392.97286,-0.13322,238.93218,19.26338
734.91206,61.24267,392.80099,-0.13322,240.09900,19.25495
738.41206,61.53433,393.13114,-0.13322,241.26561,19.27114
741.91206,61.82604,392.34525,-0.13322,242.43248,19.23261
745.41206,62.11758,392.72257,-0.13322,243.59863,19.25111
748.91206,62.40929,392.26683,-0.13322,244.76545,19.22877
752.41206,62.70093,392.30324,-0.13322,245.93205,19.23055
755.91206,62.99266,391.89979,-0.13322,247.09895,19.21077
759.41206,63.28437,391.84070,-0.13322,248.26579,19.20788
762.91206,63.57596,390.84051,-0.13322,249.43216,19.15885
766.41206,63.86773,390.83562,-0.13322,250.59924,19.15861
769.91206,64.15933,390.09477,-0.13322,251.76563,19.12229
773.41206,64.45098,390.28456,-0.13322,252.93224,19.13160
776.91206,64.74269,390.14483,-0.13322,254.09908,19.12475
780.41206,65.03446,389.67603,-0.13322,255.26617,19.10177
783.91206,65.32588,390.04288,-0.13322,256.43184,19.11975
787.41206,65.61759,389.78804,-0.13322,257.59869,19.10726
790.91206,65.90930,389.24625,-0.13322,258.76553,19.08070
794.41206,66.20102,389.56311,-0.13322,259.93237,19.09623
797.91206,66.49261,389.35223,-0.13322,261.09874,19.08589
801.41206,66.78438,389.11880,-0.13322,262.26585,19.07445
804.91206,67.07604,389.58946,-0.13322,263.43246,19.09752
808.41206,67.36769,388.72513,-0.13322,264.59906,19.05515
811.91206,67.65934,388.57157,-0.13322,265.76567,19.04763
815.41206,67.95106,388.25313,-0.13322,266.93254,19.03202
818.91206,68.24265,388.25949,-0.13322,268.09890,19.03233
822.41206,68.53430,388.48466,-0.13322,269.26551,19.04337
825.91206,68.82595,388.05529,-0.13322,270.43211,19.02232
829.41206,69.11767,387.48819,-0.13322,271.59898,18.99452
832.91206,69.40938,387.62053,-0.13322,272.76583,19.00101
836.41206,69.70091,387.40670,-0.13322,273.93196,18.99052
839.91206,69.99263,387.36898,-0.13321,275.09882,18.98868
843.41206,70.28428,386.95401,-0.13322,276.26543,18.96833
846.91206,70.57599,386.79850,-0.13322,277.43227,18.96071
850.41206,70.86770,386.52474,-0.13322,278.59912,18.94729
853.91206,71.15935,386.99389,-0.13321,279.76573,18.97029
857.41206,71.45101,386.26723,-0.13322,280.93233,18.93467
860.91206,71.74266,386.07344,-0.13322,282.09896,18.92517
864.41206,72.03432,386.37249,-0.13322,283.26559,18.93983
867.91206,72.32610,385.94273,-0.13322,284.43270,18.91876
871.41206,72.61769,385.68645,-0.13322,285.59906,18.90620
874.91206,72.90922,385.28962,-0.13322,286.76519,18.88675
878.41206,73.20093,385.27986,-0.13322,287.93204,18.88627
881.91206,73.49265,384.52018,-0.13322,289.09891,18.84903
885.41206,73.78436,384.58854,-0.13322,290.26575,18.85238
888.91206,74.07589,385.08638,-0.13322,291.43188,18.87678
892.41206,74.36767,384.63206,-0.13322,292.59899,18.85451
895.91206,74.65932,384.55473,-0.13322,293.76559,18.85072
899.41206,74.95097,384.29664,-0.13322,294.93220,18.83807
902.91206,75.24274,384.06875,-0.13322,296.09928,18.82690
906.41206,75.53434,383.86846,-0.13322,297.26565,18.81708
909.91206,75.82599,383.86851,-0.13322,298.43225,18.81708
913.41206,76.11764,383.47219,-0.13321,299.59888,18.79766
916.91206,76.40935,383.61570,-0.13322,300.76573,18.80469
920.41206,76.70101,383.25575,-0.13321,301.93233,18.78705
923.91206,76.99272,383.35123,-0.13322,303.09920,18.79173
927.41206,77.28425,382.98056,-0.13322,304.26533,18.77356
930.91206,77.57591,383.23966,-0.13322,305.43194,18.78626
934.41206,77.86762,382.70701,-0.13321,306.59878,18.76015
937.91206,78.15945,382.34249,-0.13322,307.76610,18.74228
941.41206,78.45098,382.64908,-0.13322,308.93223,18.75731
944.91206,78.74263,382.75565,-0.13322,310.09884,18.76253
948.41206,79.03435,382.89735,-0.13322,311.26573,18.76948
951.91206,79.32601,382.77190,-0.13322,312.43234,18.76333
955.41206,79.61766,381.91411,-0.13322,313.59894,18.72128
958.91206,79.90931,382.28952,-0.13322,314.76555,18.73968
962.41206,80.20096,382.38238,-0.13322,315.93218,18.74423
965.91206,80.49262,381.66454,-0.13322,317.09878,18.70905
969.41206,80.78434,382.08358,-0.13322,318.26565,18.72959
972.91206,81.07604,382.39458,-0.13322,319.43250,18.74483
976.41206,81.36782,381.80996,-0.13321,320.59958,18.71618
979.91206,81.65929,382.21015,-0.13322,321.76549,18.73579
983.41206,81.95088,383.02825,-0.13322,322.93184,18.77589
986.91206,82.24266,382.27455,-0.13322,324.09894,18.73895
990.41206,82.53437,381.89657,-0.13322,325.26581,18.72042
993.91206,82.82603,382.22647,-0.13322,326.43242,18.73659
997.41206,83.11762,382.18470,-0.13322,327.59876,18.73454
1000.91206,83.40933,382.33739,-0.13322,328.76565,18.74203
1004.41206,83.70099,382.20549,-0.13322,329.93226,18.73556
1007.91206,83.99264,382.10575,-0.13322,331.09887,18.73067
1011.41206,84.28447,382.49062,-0.13322,332.26619,18.74954
1014.91206,84.57600,382.47495,-0.13322,333.43232,18.74877
1018.41206,84.86765,382.44952,-0.13322,334.59892,18.74753
1021.91206,85.15931,382.77479,-0.13321,335.76553,18.76347
1025.41212,85.45102,382.25392,-0.13322,336.93237,18.73794
1028.91212,85.74273,382.61854,-0.13322,338.09924,18.75581
1032.41212,86.03432,383.01221,-0.13322,339.26561,18.77511
1035.91212,86.32598,383.59875,-0.13322,340.43221,18.80386
1039.41212,86.61763,382.87307,-0.13322,341.59882,18.76829
1042.91212,86.90940,382.71800,-0.13322,342.76593,18.76069
1046.41212,87.20106,383.15570,-0.13322,343.93253,18.78214
1049.91212,87.49265,382.68503,-0.13322,345.09892,18.75907
1053.41212,87.78436,383.42532,-0.13322,346.26575,18.79536
1056.91212,88.07596,383.29335,-0.13321,347.43214,18.78889
1060.41212,88.36761,383.44252,-0.13321,348.59877,18.79620
1063.91212,88.65932,382.99835,-0.13322,349.76559,18.77443
1067.41212,88.95109,383.86886,-0.13322,350.93269,18.81710
1070.91212,89.24263,384.12029,-0.13322,352.09882,18.82943
1074.41212,89.53428,384.78577,-0.13321,353.26543,18.86205
1077.91212,89.82600,384.22991,-0.13321,354.43230,18.83480
1081.41212,90.11777,384.34770,-0.13322,355.59940,18.84057
1084.91212,90.40930,384.54856,-0.13322,356.76553,18.85042
1088.41212,90.70096,384.76591,-0.13321,357.93214,18.86107
1091.91212,90.99267,384.79306,-0.13321,359.09901,18.86240
1095.41212,91.28433,384.76645,-0.13322,360.26561,18.86110
1098.91212,91.57598,384.95786,-0.13322,361.43224,18.87048
1102.41212,91.86769,385.06002,-0.13322,362.59906,18.87549
1105.91212,92.15934,385.04312,-0.13322,363.76567,18.87466
1109.41212,92.45087,385.68890,-0.13321,364.93180,18.90632
1112.91212,92.74259,385.93062,-0.13322,366.09869,18.91817
1116.41212,93.03437,385.78224,-0.13322,367.26577,18.91089
1119.91212,93.32608,386.13104,-0.13321,368.43262,18.92799
1123.41212,93.61767,385.87491,-0.13322,369.59901,18.91544
1126.91212,93.90932,386.06145,-0.13322,370.76557,18.92458
1130.41212,94.20097,385.27334,-0.13322,371.93220,18.88595
1133.91212,94.49274,385.80273,-0.13322,373.09928,18.91190
1137.41212,94.78440,385.81935,-0.13322,374.26589,18.91271
1140.91212,95.07599,386.31482,-0.13322,375.43228,18.93700
1144.41212,95.36770,386.96800,-0.13322,376.59912,18.96902
1147.91212,95.65935,386.96043,-0.13322,377.76573,18.96865
1151.41212,95.95101,387.32886,-0.13321,378.93233,18.98671
1154.91212,96.24273,387.42097,-0.13322,380.09923,18.99122
1158.41212,96.53431,387.27629,-0.13322,381.26557,18.98413
1161.91212,96.82591,387.38961,-0.13322,382.43196,18.98969
1165.41212,97.11756,387.65143,-0.13321,383.59857,19.00252
1168.91212,97.40939,387.44560,-0.13322,384.76589,18.99243
1172.41212,97.70105,389.00746,-0.13321,385.93249,19.06899
1175.91212,97.99258,388.64613,-0.13322,387.09862,19.05128
1179.41212,98.28435,389.07051,-0.13322,388.26573,19.07208
1182.91212,98.57601,389.59184,-0.13321,389.43233,19.09764
1186.41212,98.86760,388.88673,-0.13322,390.59873,19.06308
1189.91212,99.15944,389.16131,-0.13322,391.76607,19.07653
1193.41212,99.45097,388.83151,-0.13321,392.93220,19.06037
1196.91212,99.74263,388.83097,-0.13321,394.09881,19.06034
1200.41212,100.03440,389.43940,-0.13322,395.26591,19.09017
1203.91212,100.32599,390.13904,-0.13321,396.43226,19.12446
1207.41212,100.61771,390.25224,-0.13321,397.59915,19.13001
1210.91212,100.90936,390.40376,-0.13322,398.76575,19.13744
1214.41212,101.20101,389.87703,-0.13322,399.93236,19.11162
1217.91212,101.49260,390.19389,-0.13322,401.09873,19.12715
1221.41212,101.78432,390.44521,-0.13321,402.26560,19.13947
1224.91212,102.07608,391.05113,-0.13322,403.43266,19.16917
1228.41212,102.36762,390.93490,-0.13321,404.59881,19.16348
1231.91212,102.65933,390.84274,-0.13321,405.76563,19.15896
1235.41212,102.95099,391.18258,-0.13321,406.93226,19.17562
1238.91212,103.24270,392.24275,-0.13321,408.09908,19.22759
1242.41212,103.53435,391.89556,-0.13322,409.26571,19.21057
1245.91212,103.82600,391.53998,-0.13321,410.43234,19.19314
1249.41212,104.11760,391.62864,-0.13322,411.59868,19.19748
1252.91212,104.40937,392.09044,-0.13322,412.76579,19.22012
1256.41212,104.70096,392.21942,-0.13321,413.93213,19.22644
1259.91212,104.99273,392.32573,-0.13321,415.09924,19.23165
1263.41212,105.28439,392.40150,-0.13321,416.26587,19.23537
1266.91212,105.57598,392.11037,-0.13321,417.43226,19.22110
1270.41212,105.86757,392.34017,-0.13321,418.59860,19.23236
1273.91212,106.15929,392.62497,-0.13321,419.76547,19.24632
1277.41212,106.45112,392.17132,-0.13321,420.93277,19.22408
1280.91212,106.74272,392.54194,-0.13321,422.09916,19.24225
1284.41212,107.03425,393.19559,-0.13321,423.26531,19.27429
1287.91212,107.32602,393.49780,-0.13321,424.43242,19.28911
1291.41212,107.61761,393.85939,-0.13321,425.59876,19.30683
1294.91212,107.90933,393.34446,-0.13322,426.76563,19.28159
1298.41212,108.20110,393.92067,-0.13322,427.93274,19.30984
1301.91212,108.49264,394.63639,-0.13321,429.09884,19.34492
1305.41212,108.78441,394.81344,-0.13322,430.26595,19.35360
1308.91212,109.07601,394.62051,-0.13321,431.43234,19.34414
1312.41212,109.36772,394.63672,-0.13321,432.59916,19.34494
1315.91212,109.65943,394.39914,-0.13321,433.76603,19.33329
1319.41212,109.95102,395.37735,-0.13321,434.93237,19.38124
1322.91212,110.24262,395.06294,-0.13321,436.09877,19.36583
1326.41212,110.53427,395.37437,-0.13321,437.26540,19.38110
1329.91212,110.82605,395.36259,-0.13321,438.43250,19.38052
1333.41212,111.11775,396.16958,-0.13322,439.59932,19.42008
1336.91212,111.40929,395.94155,-0.13321,440.76548,19.40890
1340.41212,111.70094,396.36549,-0.13321,441.93206,19.42968
1343.91212,111.99266,396.14360,-0.13322,443.09893,19.41880
1347.41212,112.28437,395.96977,-0.13321,444.26579,19.41028
1350.91212,112.57602,396.38244,-0.13321,445.43238,19.43051
1354.41212,112.86767,396.69443,-0.13322,446.59901,19.44580
1357.91212,113.15932,397.07301,-0.13321,447.76559,19.46436
1361.41212,113.45092,397.29737,-0.13322,448.93198,19.47536
1364.91212,113.74263,397.95740,-0.13321,450.09885,19.50772
1368.41212,114.03446,397.72065,-0.13321,451.26615,19.49611
1371.91212,114.32606,397.37774,-0.13321,452.43254,19.47930
1375.41212,114.61765,397.90994,-0.13321,453.59888,19.50539
1378.91212,114.90936,397.86734,-0.13321,454.76575,19.50330
1382.41212,115.20102,398.13835,-0.13321,455.93238,19.51659
1385.91212,115.49267,398.59754,-0.13321,457.09901,19.53909
1389.41212,115.78432,398.46869,-0.13321,458.26559,19.53278
1392.91212,116.07598,397.56987,-0.13321,459.43222,19.48872
1396.41212,116.36763,399.11773,-0.13321,460.59880,19.56459
1399.91212,116.65928,399.14977,-0.13321,461.76543,19.56617
1403.41212,116.95106,399.29287,-0.13321,462.93254,19.57318
1406.91212,117.24271,399.14949,-0.13321,464.09917,19.56615
1410.41212,117.53436,399.21482,-0.13321,465.26575,19.56935
1413.91212,117.82596,399.59759,-0.13321,466.43214,19.58812
1417.41212,118.11761,399.50893,-0.13321,467.59877,19.58377
1420.91212,118.40939,399.14558,-0.13321,468.76583,19.56596
1424.41212,118.70109,399.69878,-0.13321,469.93270,19.59308
1427.91212,118.99263,400.33692,-0.13321,471.09880,19.62436
1431.41212,119.28434,400.61600,-0.13321,472.26567,19.63804
1434.91212,119.57605,400.47108,-0.13321,473.43254,19.63094
1438.41212,119.86765,400.27755,-0.13321,474.59893,19.62145
1441.91212,120.15936,400.17092,-0.13321,475.76575,19.61622
1445.41212,120.45096,400.63700,-0.13321,476.93214,19.63907
1448.91212,120.74267,400.73940,-0.13321,478.09896,19.64409
1452.41212,121.03426,400.51104,-0.13321,479.26536,19.63289
1455.91212,121.32609,400.79998,-0.13321,480.43270,19.64706
1459.41212,121.61775,401.19542,-0.13321,481.59928,19.66644
1462.91212,121.90934,401.74169,-0.13321,482.76567,19.69322
1466.41212,122.20100,401.46490,-0.13321,483.93230,19.67965
1469.91212,122.49265,401.41982,-0.13322,485.09889,19.67744
1473.41212,122.78436,401.95389,-0.13321,486.26575,19.70362
1476.91212,123.07607,402.07589,-0.13322,487.43258,19.70960
1480.41212,123.36761,402.07552,-0.13321,488.59873,19.70958
1483.91212,123.65926,402.42458,-0.13321,489.76536,19.72669
1487.41212,123.95103,402.33661,-0.13321,490.93242,19.72238
1490.91212,124.24262,403.06714,-0.13321,492.09881,19.75819
1494.41212,124.53433,402.12264,-0.13321,493.26563,19.71189
1497.91212,124.82598,403.13741,-0.13321,494.43226,19.76164
1501.41212,125.11769,403.00791,-0.13321,495.59908,19.75529
1504.91212,125.40929,402.90360,-0.13321,496.76547,19.75018
1508.41212,125.70101,403.15739,-0.13321,497.93234,19.76262
1511.91212,125.99272,403.40121,-0.13321,499.09916,19.77457
1515.41212,126.28431,403.64712,-0.13321,500.26555,19.78662
1518.91212,126.57590,404.04121,-0.13322,501.43194,19.80594
1522.41212,126.86762,404.23041,-0.13321,502.59881,19.81522
1525.91212,127.15933,404.62376,-0.13321,503.76563,19.83450
1529.41212,127.45105,404.01705,-0.13321,504.93250,19.80476
1532.91212,127.74264,403.83125,-0.13322,506.09884,19.79565
1536.41212,128.03423,404.46501,-0.13321,507.26523,19.82672
1539.91212,128.32594,404.84294,-0.13321,508.43205,19.84524
1543.41212,128.61760,405.10548,-0.13321,509.59873,19.85811
1546.91212,128.90937,404.70785,-0.13321,510.76579,19.83862
1550.41212,129.20109,405.03344,-0.13321,511.93266,19.85458
1553.91212,129.49261,404.65845,-0.13321,513.09876,19.83620
1557.41212,129.78427,405.34362,-0.13321,514.26539,19.86979
1560.91212,130.07598,405.24038,-0.13321,515.43221,19.86473
1564.41212,130.36770,405.34427,-0.13321,516.59908,19.86982
1567.91212,130.65929,405.85482,-0.13321,517.76547,19.89484
1571.41212,130.95095,405.67266,-0.13321,518.93210,19.88591
1574.91212,131.24259,405.68425,-0.13321,520.09869,19.88648
1578.41212,131.53431,405.56621,-0.13321,521.26555,19.88070
1581.91212,131.82602,405.61119,-0.13321,522.43237,19.88290
1585.41212,132.11774,406.54433,-0.13321,523.59924,19.92864
1588.91212,132.40926,405.94391,-0.13321,524.76535,19.89921
1592.41212,132.70098,406.64491,-0.13321,525.93222,19.93357
1595.91212,132.99263,406.36454,-0.13321,527.09885,19.91983
1599.41212,133.28435,406.79029,-0.13321,528.26571,19.94070
1602.91212,133.57599,406.81395,-0.13321,529.43230,19.94186
1606.41212,133.86765,406.62349,-0.13322,530.59893,19.93252
1609.91212,134.15930,406.17827,-0.13321,531.76551,19.91070
1613.41212,134.45090,407.49125,-0.13321,532.93190,19.97506
1616.91212,134.74268,407.47630,-0.13321,534.09901,19.97433
1620.41212,135.03444,407.72464,-0.13321,535.26607,19.98650
1623.91212,135.32599,407.50848,-0.13321,536.43227,19.97591
1627.41212,135.61763,407.96781,-0.13321,537.59885,19.99842
1630.91212,135.90929,408.43515,-0.13321,538.76548,20.02133
1634.41212,136.20106,408.14420,-0.13321,539.93254,20.00707
1637.91212,136.49265,408.79459,-0.13321,541.09893,20.03895
1641.41212,136.78431,408.47687,-0.13321,542.26551,20.02338
1644.91212,137.07596,408.68511,-0.13321,543.43214,20.03358
1648.41212,137.36761,408.87548,-0.13321,544.59877,20.04292
1651.91212,137.65933,408.47249,-0.13321,545.76564,20.02316
1655.41212,137.95109,409.73159,-0.13321,546.93270,20.08488
1658.91212,138.24269,409.14617,-0.13321,548.09909,20.05618
1662.41212,138.53434,409.47394,-0.13321,549.26567,20.07225
1665.91212,138.82600,409.40130,-0.13321,550.43230,20.06869
1669.41212,139.11771,409.59311,-0.13321,551.59912,20.07809
1672.91212,139.40937,410.48890,-0.13321,552.76580,20.12201
1676.41212,139.70095,409.95455,-0.13321,553.93209,20.09581
1679.91212,139.99261,409.74291,-0.13321,555.09877,20.08544
1683.41212,140.28425,410.78129,-0.13321,556.26531,20.13634
1686.91212,140.57598,410.35437,-0.13321,557.43222,20.11541
1690.41212,140.86768,410.84178,-0.13321,558.59904,20.13930
1693.91212,141.15934,411.10618,-0.13321,559.76567,20.15226
1697.41212,141.45105,410.78730,-0.13322,560.93249,20.13663
1700.91212,141.74265,410.70641,-0.13321,562.09888,20.13267
1704.41212,142.03429,410.89025,-0.13321,563.26547,20.14168
1707.91212,142.32608,411.13682,-0.13321,564.43262,20.15377
1711.41212,142.61772,411.06013,-0.13322,565.59920,20.15001
1714.91212,142.90926,412.22139,-0.13321,566.76536,20.20693
1718.41212,143.20097,411.63042,-0.13321,567.93218,20.17796
1721.91212,143.49262,412.39895,-0.13321,569.09881,20.21564
1725.41212,143.78441,412.52133,-0.13321,570.26591,20.22163
1728.91212,144.07599,412.77218,-0.13321,571.43230,20.23393
1732.41212,144.36766,412.67113,-0.13321,572.59893,20.22898
1735.91212,144.65930,412.96072,-0.13321,573.76552,20.24317
1739.41212,144.95102,413.11411,-0.13321,574.93238,20.25069
1742.91212,145.24278,413.16058,-0.13322,576.09944,20.25297
1746.41212,145.53432,413.18154,-0.13321,577.26560,20.25400
1749.91212,145.82597,414.26439,-0.13321,578.43218,20.30708
1753.41212,146.11769,413.88539,-0.13321,579.59905,20.28850
1756.91212,146.40922,414.17517,-0.13321,580.76520,20.30270
1760.41212,146.70099,414.14616,-0.13321,581.93226,20.30128
1763.91212,146.99276,413.87905,-0.13321,583.09932,20.28819
1767.41212,147.28424,414.47752,-0.13321,584.26528,20.31753
1770.91212,147.57595,414.49526,-0.13321,585.43210,20.31840
1774.41212,147.86767,414.75180,-0.13321,586.59897,20.33097
1777.91212,148.15937,415.46430,-0.13321,587.76579,20.36590
1781.41212,148.45103,415.50696,-0.13321,588.93242,20.36799
1784.91212,148.74262,415.49844,-0.13321,590.09876,20.36757
1788.41212,149.03434,415.85793,-0.13322,591.26568,20.38519
1791.91212,149.32598,415.80172,-0.13322,592.43221,20.38244
1795.41212,149.61764,416.12890,-0.13321,593.59889,20.39848
1798.91212,149.90941,416.24317,-0.13321,594.76595,20.40408
1802.41212,150.20101,415.79623,-0.13321,595.93234,20.38217
1805.91212,150.49266,415.60642,-0.13321,597.09892,20.37286
1809.41212,150.78425,416.32350,-0.13322,598.26531,20.40801
1812.91212,151.07602,416.14901,-0.13321,599.43237,20.39946
1816.41212,151.36774,416.35833,-0.13321,600.59924,20.40972
1819.91212,151.65927,416.90534,-0.13321,601.76539,20.43654
1823.41212,151.95093,416.91805,-0.13322,602.93202,20.43716
1826.91212,152.24271,417.17198,-0.13321,604.09913,20.44961
1830.41212,152.53435,417.44532,-0.13321,605.26571,20.46301
1833.91212,152.82601,417.53664,-0.13321,606.43234,20.46748
1837.41212,153.11765,418.22502,-0.13321,607.59892,20.50123
1840.91212,153.40932,418.34717,-0.13321,608.76560,20.50721
1844.41212,153.70090,418.58060,-0.13321,609.93195,20.51866
1847.91212,153.99262,418.35606,-0.13321,611.09881,20.50765
1851.41212,154.28433,418.48724,-0.13321,612.26563,20.51408
1854.91212,154.57599,419.07532,-0.13321,613.43226,20.54291
1858.41212,154.86764,419.16925,-0.13321,614.59885,20.54751
1861.91212,155.15930,419.27467,-0.13322,615.76552,20.55268
1865.41212,155.45100,418.64770,-0.13321,616.93230,20.52195
1868.91212,155.74278,419.30508,-0.13321,618.09945,20.55417
1872.41212,156.03443,419.67933,-0.13321,619.26603,20.57252
1875.91212,156.32596,419.67635,-0.13321,620.43214,20.57237
1879.41212,156.61767,419.87505,-0.13321,621.59896,20.58211
1882.91212,156.90940,419.72743,-0.13322,622.76587,20.57487
1886.41212,157.20103,420.57913,-0.13321,623.93241,20.61662
1889.91212,157.49276,419.87197,-0.13321,625.09933,20.58196
1893.41212,157.78434,420.64302,-0.13321,626.26567,20.61975
1896.91212,158.07601,420.72395,-0.13321,627.43235,20.62372
1900.41212,158.36764,421.22458,-0.13321,628.59888,20.64826
1903.91212,158.65937,421.54891,-0.13322,629.76580,20.66416
1907.41212,158.95113,421.36149,-0.13321,630.93286,20.65497
1910.91212,159.24267,421.31138,-0.13322,632.09901,20.65252
1914.41212,159.53420,421.40596,-0.13321,633.26511,20.65715
1917.91212,159.82598,421.85024,-0.13321,634.43222,20.67893
1921.41212,160.11775,421.55962,-0.13321,635.59928,20.66469
1924.91212,160.40929,422.50287,-0.13321,636.76548,20.71092
1928.41212,160.70100,422.12973,-0.13321,637.93230,20.69263
1931.91212,160.99259,422.49388,-0.13321,639.09869,20.71048
1935.41212,161.28423,422.72145,-0.13321,640.26523,20.72164
1938.91212,161.57595,423.21957,-0.13321,641.43214,20.74606
1942.41212,161.86774,423.26790,-0.13321,642.59925,20.74843
1945.91212,162.15926,422.86804,-0.13321,643.76535,20.72882
1949.41212,162.45099,423.07773,-0.13321,644.93227,20.73910
1952.91212,162.74262,423.52718,-0.13321,646.09880,20.76114
1956.41212,163.03429,423.90535,-0.13321,647.26548,20.77967
1959.91212,163.32606,423.92341,-0.13321,648.43254,20.78056
1963.41212,163.61766,424.17431,-0.13321,649.59893,20.79286
1966.91212,163.90923,424.06642,-0.13321,650.76523,20.78757
1970.41212,164.20091,423.91862,-0.13321,651.93195,20.78032
1973.91212,164.49267,424.73804,-0.13321,653.09901,20.82049
1977.41212,164.78438,423.65533,-0.13321,654.26583,20.76742
1980.91212,165.07598,424.36118,-0.13321,655.43222,20.80202
1984.41212,165.36769,424.60421,-0.13321,656.59904,20.81393
1987.91212,165.65934,425.04757,-0.13321,657.76567,20.83566
1991.41212,165.95094,425.14955,-0.13321,658.93207,20.84066
1994.91212,166.24276,425.09171,-0.13321,660.09932,20.83783
1998.41212,166.53430,425.32333,-0.13321,661.26552,20.84918
2001.91212,166.82589,425.96119,-0.13321,662.43191,20.88045
2005.41212,167.11766,426.11402,-0.13321,663.59897,20.88794
2008.91212,167.40937,425.71099,-0.13321,664.76579,20.86819
2012.41212,167.70110,426.36911,-0.13321,665.93270,20.90045
2015.91212,167.99267,426.33777,-0.13321,667.09900,20.89891
2019.41212,168.28435,426.74378,-0.13321,668.26568,20.91881
2022.91212,168.57598,426.88237,-0.13321,669.43221,20.92561
2026.41212,168.86771,426.56679,-0.13321,670.59913,20.91014
2029.91212,169.15942,426.52902,-0.13321,671.76600,20.90829
2033.41212,169.45101,427.63576,-0.13321,672.93239,20.96254
2036.91212,169.74259,427.55716,-0.13321,674.09868,20.95868
2040.41212,170.03432,427.72228,-0.13321,675.26560,20.96678
2043.91212,170.32590,428.26533,-0.13321,676.43189,20.99340
2047.41212,170.61768,428.22594,-0.13321,677.59905,20.99147
2050.91212,170.90941,428.59563,-0.13321,678.76596,21.00959
2054.41212,171.20099,428.19409,-0.13321,679.93226,20.98991
2057.91212,171.49264,428.18910,-0.13321,681.09889,20.98966
2061.41212,171.78435,428.47781,-0.13321,682.26571,21.00381
2064.91212,172.07613,428.85067,-0.13321,683.43282,21.02209
2068.41212,172.36771,428.52657,-0.13321,684.59916,21.00620
2071.91212,172.65933,428.39171,-0.13321,685.76560,20.99959
2075.41212,172.95090,429.38371,-0.13321,686.93194,21.04822
2078.91212,173.24269,429.07214,-0.13321,688.09905,21.03295
2082.41212,173.53440,429.50241,-0.13321,689.26592,21.05404
2085.91212,173.82599,429.56681,-0.13321,690.43231,21.05720
2089.41212,174.11763,430.22903,-0.13321,691.59884,21.08966
2092.91212,174.40936,430.02148,-0.13321,692.76571,21.07948
2096.41212,174.70088,430.31126,-0.13321,693.93182,21.09369
2099.91200,174.99272,430.35648,-0.13321,695.09916,21.09591
2103.41200,175.28443,431.37479,-0.13321,696.26603,21.14582
2106.91200,175.57597,430.80184,-0.13321,697.43218,21.11774
2110.41200,175.86762,431.06852,-0.13321,698.59881,21.13081
2113.91200,176.15927,431.16440,-0.13321,699.76540,21.13551
2117.41200,176.45104,431.17637,-0.13321,700.93246,21.13610
2120.91200,176.74269,431.22582,-0.13321,702.09908,21.13852
2124.41200,177.03423,431.49646,-0.13321,703.26524,21.15179
2127.91200,177.32594,431.73009,-0.13321,704.43206,21.16324
2131.41200,177.61759,431.99630,-0.13321,705.59869,21.17629
2134.91200,177.90930,432.03668,-0.13321,706.76551,21.17827
2138.41200,178.20101,432.29549,-0.13322,707.93238,21.19096
2141.91200,178.49268,432.18317,-0.13321,709.09905,21.18545
2145.41200,178.78432,432.87030,-0.13321,710.26559,21.21913
2148.91200,179.07592,432.71114,-0.13321,711.43198,21.21133
2152.41200,179.36764,433.18789,-0.13321,712.59890,21.23470
2155.91200,179.65941,432.99249,-0.13321,713.76595,21.22512
2159.41200,179.95100,432.99021,-0.13321,714.93235,21.22501
2162.91200,180.24260,433.34230,-0.13321,716.09874,21.24227
2166.41200,180.53431,434.03874,-0.13321,717.26556,21.27641
2169.91200,180.82602,434.10137,-0.13321,718.43238,21.27948
2173.41200,181.11775,434.24754,-0.13321,719.59929,21.28664
2176.91200,181.40927,434.15525,-0.13321,720.76540,21.28212
2180.41200,181.70092,434.55558,-0.13321,721.93198,21.30174
2183.91200,181.99269,434.55912,-0.13321,723.09904,21.30192
2187.41200,182.28428,434.83255,-0.13321,724.26543,21.31532
2190.91200,182.57599,435.43708,-0.13321,725.43230,21.34496
2194.41200,182.86772,435.30064,-0.13321,726.59922,21.33827
2197.91200,183.15936,435.93738,-0.13321,727.76575,21.36948
2201.41200,183.45090,436.02334,-0.13321,728.93190,21.37369
2204.91200,183.74261,435.85151,-0.13321,730.09872,21.36527
2208.41200,184.03444,435.86455,-0.13321,731.26607,21.36591
2211.91200,184.32597,436.62353,-0.13321,732.43217,21.40311
2215.41200,184.61758,437.04938,-0.13321,733.59866,21.42399
2218.91200,184.90927,436.47401,-0.13321,734.76539,21.39578
2222.41200,185.20094,436.89907,-0.13321,735.93211,21.41662
2225.91200,185.49271,437.05874,-0.13321,737.09917,21.42445
2229.41200,185.78449,437.01669,-0.13321,738.26628,21.42239
2232.91200,186.07596,437.48012,-0.13321,739.43214,21.44510
2236.41200,186.36767,438.27440,-0.13321,740.59896,21.48404
2239.91200,186.65932,437.99900,-0.13321,741.76559,21.47054
2243.41200,186.95097,438.14960,-0.13321,742.93222,21.47792
2246.91200,187.24268,439.25373,-0.13321,744.09904,21.53205
2250.41200,187.53428,438.81810,-0.13321,745.26544,21.51069
2253.91200,187.82593,438.96073,-0.13321,746.43207,21.51768
2257.41200,188.11759,439.77355,-0.13321,747.59865,21.55753
2260.91200,188.40943,439.68488,-0.13321,748.76599,21.55318
2264.41200,188.70108,439.70314,-0.13321,749.93262,21.55408
2267.91200,188.99262,440.11069,-0.13321,751.09878,21.57405
2271.41200,189.28425,440.79809,-0.13321,752.26531,21.60775
2274.91200,189.57598,441.02669,-0.13321,753.43223,21.61896
2278.41200,189.86762,440.74231,-0.13321,754.59876,21.60501
2281.91200,190.15940,440.98338,-0.13321,755.76591,21.61683
2285.41200,190.45092,441.45011,-0.13321,756.93202,21.63971
2288.91200,190.74271,442.07657,-0.13321,758.09913,21.67042
2292.41200,191.03430,441.67666,-0.13321,759.26552,21.65082
2295.91200,191.32607,442.05855,-0.13321,760.43258,21.66954
2299.41200,191.61772,442.68551,-0.13321,761.59921,21.70027
2302.91200,191.90937,442.49003,-0.13321,762.76579,21.69069
2306.41200,192.20097,442.69818,-0.13321,763.93218,21.70089
2309.91200,192.49262,443.45087,-0.13321,765.09881,21.73779
2313.41200,192.78433,442.93902,-0.13321,766.26563,21.71270
2316.91200,193.07612,443.48994,-0.13321,767.43279,21.73970
2320.41200,193.36764,443.70173,-0.13321,768.59884,21.75008
2323.91200,193.65923,443.68813,-0.13321,769.76523,21.74942
2327.41200,193.95100,444.43645,-0.13321,770.93229,21.78610
2330.91200,194.24267,443.48468,-0.13321,772.09902,21.73944
2334.41200,194.53431,444.62960,-0.13321,773.26555,21.79557
2337.91200,194.82598,444.05209,-0.13321,774.43223,21.76726
2341.41200,195.11774,444.54895,-0.13321,775.59929,21.79161
2344.91200,195.40934,444.54220,-0.13321,776.76568,21.79128
2348.41200,195.70097,444.65540,-0.13321,777.93221,21.79683
2351.91200,195.99276,445.07314,-0.13321,779.09932,21.81731
2355.41200,196.28435,444.85857,-0.13321,780.26571,21.80679
2358.91200,196.57595,445.72097,-0.13321,781.43210,21.84907
2362.41200,196.86759,445.79641,-0.13321,782.59864,21.85277
2365.91200,197.15931,445.59729,-0.13321,783.76555,21.84300
2369.41200,197.45097,445.79376,-0.13321,784.93218,21.85263
2372.91200,197.74262,446.23800,-0.13321,786.09877,21.87441
2376.41200,198.03435,446.58184,-0.13321,787.26568,21.89127
2379.91200,198.32598,447.39977,-0.13321,788.43222,21.93136
2383.41200,198.61765,446.56917,-0.13321,789.59894,21.89065
2386.91200,198.90942,447.73100,-0.13321,790.76600,21.94760
2390.41200,199.20101,447.73268,-0.13321,791.93234,21.94768
2393.91200,199.49259,447.27721,-0.13321,793.09869,21.92535
2397.41200,199.78426,448.17152,-0.13321,794.26537,21.96919
2400.91200,200.07595,448.03531,-0.13321,795.43214,21.96251
2404.41200,200.36763,448.23135,-0.13321,796.59882,21.97213
2407.91200,200.65939,448.08257,-0.13321,797.76587,21.96483
2411.41200,200.95099,447.72103,-0.13321,798.93227,21.94711
2414.91200,201.24257,448.75219,-0.13321,800.09861,21.99766
2418.41200,201.53435,449.02381,-0.13321,801.26572,22.01097
2421.91200,201.82606,447.82292,-0.13320,802.43254,21.95210
2425.41200,202.11771,448.36686,-0.13321,803.59917,21.97877
2428.91200,202.40925,449.24365,-0.13321,804.76532,22.02175
2432.41200,202.70096,448.05584,-0.13320,805.93214,21.96352
2435.91200,202.99261,449.48123,-0.13321,807.09877,22.03339
2439.41200,203.28432,449.73916,-0.13320,808.26559,22.04604
2442.91200,203.57603,449.27523,-0.13320,809.43241,22.02329
2446.41200,203.86770,450.00827,-0.13321,810.59914,22.05923
2449.91200,204.15928,449.94089,-0.13320,811.76548,22.05593
2453.41200,204.45094,450.35877,-0.13320,812.93201,22.07641
2456.91200,204.74264,449.82606,-0.13320,814.09893,22.05030
2460.41200,205.03448,450.60557,-0.13320,815.26623,22.08851
2463.91200,205.32601,450.53456,-0.13320,816.43238,22.08503
2467.41200,205.61755,450.46550,-0.13320,817.59853,22.08164
2470.91200,205.90939,451.18560,-0.13320,818.76583,22.11694
2474.41200,206.20098,451.10183,-0.13320,819.93227,22.11283
2477.91200,206.49269,451.69969,-0.13320,821.09909,22.14214
2481.41200,206.78435,451.84400,-0.13320,822.26572,22.14922
2484.91200,207.07607,452.45178,-0.13320,823.43264,22.17901
2488.41200,207.36760,452.98524,-0.13320,824.59869,22.20516
2491.91200,207.65938,453.54776,-0.13320,825.76580,22.23273
2495.41200,207.95107,453.34254,-0.13320,826.93262,22.22267
2498.91200,208.24268,453.48592,-0.13320,828.09906,22.22970
2502.41200,208.53432,454.01547,-0.13320,829.26559,22.25566
2505.91200,208.82599,454.04686,-0.13320,830.43232,22.25720
2509.41200,209.11768,454.50591,-0.13320,831.59904,22.27970
2512.91200,209.40935,454.51289,-0.13320,832.76567,22.28004
2516.41200,209.70106,454.54013,-0.13320,833.93259,22.28138
2519.91200,209.99260,455.14437,-0.13320,835.09874,22.31100
2523.41200,210.28429,455.54694,-0.13320,836.26547,22.33073
2526.91200,210.57602,455.49208,-0.13320,837.43238,22.32804
2530.41200,210.86767,455.82871,-0.13320,838.59901,22.34455
2533.91200,211.15933,456.31900,-0.13320,839.76564,22.36858
2537.41200,211.45098,456.02284,-0.13320,840.93227,22.35406
2540.91200,211.74258,456.37260,-0.13320,842.09862,22.37121
2544.41200,212.03421,456.97950,-0.13320,843.26515,22.40096
2547.91200,212.32605,456.58634,-0.13320,844.43254,22.38168
2551.41200,212.61770,457.51249,-0.13320,845.59908,22.42708
2554.91200,212.90924,457.61573,-0.13320,846.76533,22.43214
2558.41200,213.20101,457.92894,-0.13320,847.93234,22.44750
2561.91200,213.49261,458.20642,-0.13320,849.09878,22.46110
2565.41200,213.78443,458.00018,-0.13320,850.26598,22.45099
2568.91200,214.07604,458.68754,-0.13320,851.43251,22.48468
2572.41200,214.36756,458.76806,-0.13320,852.59857,22.48863
2575.91200,214.65940,459.49128,-0.13320,853.76596,22.52408
2579.41200,214.95100,459.43949,-0.13320,854.93231,22.52154
2582.91200,215.24271,459.57277,-0.13320,856.09913,22.52808
2586.41200,215.53442,459.66739,-0.13320,857.26595,22.53271
2589.91200,215.82602,460.65785,-0.13320,858.43239,22.58127
2593.41200,216.11767,460.48015,-0.13320,859.59902,22.57256
2596.91200,216.40932,460.81012,-0.13320,860.76555,22.58873
2600.41200,216.70097,461.01618,-0.13320,861.93218,22.59883
2603.91200,216.99274,460.82097,-0.13320,863.09929,22.58926
2607.41200,217.28434,461.03988,-0.13320,864.26563,22.59999
2610.91200,217.57593,461.59797,-0.13320,865.43207,22.62735
2614.41200,217.86764,461.47346,-0.13320,866.59889,22.62125
2617.91200,218.15930,461.33446,-0.13320,867.76552,22.61443
2621.41200,218.45102,462.10908,-0.13320,868.93244,22.65241
2624.91200,218.74266,462.19388,-0.13319,870.09897,22.65656
2628.41200,219.03438,463.08073,-0.13320,871.26589,22.70004
2631.91200,219.32596,462.78988,-0.13320,872.43214,22.68578
2635.41200,219.61764,463.88688,-0.13320,873.59886,22.73955
2638.91200,219.90940,463.48805,-0.13320,874.76587,22.72000
2642.41200,220.20105,463.53391,-0.13320,875.93250,22.72225
2645.91200,220.49252,463.32553,-0.13319,877.09837,22.71204
2649.41200,220.78425,464.10854,-0.13320,878.26529,22.75042
2652.91200,221.07601,463.98388,-0.13320,879.43239,22.74431
2656.41200,221.36772,464.12381,-0.13320,880.59921,22.75117
2659.91200,221.65937,464.56526,-0.13319,881.76584,22.77281
2663.41200,221.95103,465.60178,-0.13320,882.93238,22.82362
2666.91200,222.24268,465.26999,-0.13320,884.09901,22.80735
2670.41200,222.53433,465.96327,-0.13320,885.26564,22.84134
2673.91200,222.82604,466.28909,-0.13320,886.43246,22.85731
2677.41200,223.11764,467.11899,-0.13320,887.59890,22.89799
2680.91200,223.40929,467.24076,-0.13319,888.76543,22.90396
2684.41200,223.70094,467.45520,-0.13320,889.93206,22.91447
2687.91200,223.99262,467.87425,-0.13319,891.09879,22.93501
2691.41200,224.28431,468.36822,-0.13319,892.26551,22.95923
2694.91200,224.57603,468.99524,-0.13319,893.43243,22.98996
2698.41200,224.86769,468.90550,-0.13320,894.59906,22.98556
2701.91200,225.15934,468.94746,-0.13320,895.76569,22.98762
2705.41200,225.45092,469.03552,-0.13320,896.93203,22.99194
2708.91200,225.74270,469.32152,-0.13319,898.09914,23.00596
2712.41200,226.03441,469.68260,-0.13319,899.26596,23.02366
2715.91200,226.32595,469.64237,-0.13319,900.43211,23.02168
2719.41200,226.61760,470.13131,-0.13320,901.59874,23.04565
2722.91200,226.90931,470.40102,-0.13319,902.76556,23.05887
2726.41200,227.20102,470.90030,-0.13320,903.93238,23.08335
2729.91200,227.49268,471.07069,-0.13319,905.09901,23.09170
2733.41200,227.78427,471.59139,-0.13319,906.26535,23.11723
2736.91200,228.07606,472.20667,-0.13319,907.43256,23.14739
2740.41200,228.36763,471.95666,-0.13319,908.59880,23.13513
2743.91200,228.65929,472.27005,-0.13319,909.76543,23.15049
2747.41200,228.95118,472.66786,-0.13320,910.93302,23.16999
2750.91200,229.24267,473.18102,-0.13320,912.09898,23.19515
2754.41200,229.53425,473.65772,-0.13320,913.26532,23.21852
2757.91200,229.82603,473.47690,-0.13320,914.43243,23.20965
2761.41200,230.11766,474.29162,-0.13319,915.59896,23.24959
2764.91200,230.40934,474.47253,-0.13319,916.76569,23.25846
2768.41200,230.70097,474.66997,-0.13319,917.93222,23.26814
2771.91200,230.99264,474.60082,-0.13319,919.09885,23.26475
2775.41200,231.28428,475.15919,-0.13319,920.26539,23.29212
2778.91200,231.57595,475.61065,-0.13319,921.43211,23.31425
2782.41200,231.86777,475.69466,-0.13319,922.59941,23.31837
2785.91200,232.15931,476.08269,-0.13319,923.76556,23.33739
2789.41200,232.45096,476.84135,-0.13319,924.93219,23.37458
2792.91200,232.74262,476.90365,-0.13319,926.09873,23.37763
2796.41200,233.03427,476.75073,-0.13319,927.26536,23.37013
2799.91200,233.32611,477.25504,-0.13319,928.43275,23.39486
2803.41200,233.61770,477.39106,-0.13319,929.59909,23.40152
2806.91200,233.90923,478.11172,-0.13319,930.76525,23.43685
2810.41200,234.20095,477.93463,-0.13319,931.93216,23.42817
2813.91200,234.49264,478.65538,-0.13319,933.09889,23.46350
2817.41200,234.78432,478.02259,-0.13319,934.26561,23.43248
2820.91200,235.07589,478.27391,-0.13319,935.43186,23.44480
2824.41200,235.36762,478.55088,-0.13319,936.59878,23.45838
2827.91200,235.65926,478.85049,-0.13319,937.76531,23.47306
2831.41200,235.95093,479.48030,-0.13319,938.93204,23.50394
2834.91200,236.24269,480.08133,-0.13320,940.09905,23.53340
2838.41200,236.53435,480.32370,-0.13319,941.26568,23.54528
2841.91200,236.82605,480.32543,-0.13320,942.43250,23.54536
2845.41200,237.11765,480.47486,-0.13320,943.59894,23.55269
2848.91200,237.40925,480.90476,-0.13319,944.76528,23.57376
2852.41200,237.70109,481.65666,-0.13319,945.93267,23.61062
2855.91200,237.99267,481.52464,-0.13319,947.09902,23.60415
2859.41200,238.28421,481.82751,-0.13319,948.26517,23.61900
2862.91200,238.57597,481.64348,-0.13319,949.43218,23.60997
2866.41200,238.86770,482.31538,-0.13319,950.59910,23.64291
2869.91200,239.15933,483.35651,-0.13319,951.76563,23.69395
2873.41200,239.45106,482.79669,-0.13319,952.93255,23.66650
2876.91200,239.74264,484.04615,-0.13319,954.09889,23.72775
2880.41200,240.03431,483.42370,-0.13319,955.26552,23.69724
2883.91200,240.32595,484.29640,-0.13319,956.43206,23.74002
2887.41200,240.61767,483.78841,-0.13319,957.59897,23.71512
2890.91200,240.90944,484.80886,-0.13319,958.76608,23.76514
2894.41200,241.20098,484.53128,-0.13319,959.93223,23.75153
2897.91200,241.49256,484.86069,-0.13319,961.09858,23.76768
2901.41200,241.78429,484.95145,-0.13319,962.26549,23.77213
2904.91200,242.07612,485.26200,-0.13319,963.43279,23.78735
2908.41200,242.36765,485.61180,-0.13319,964.59894,23.80450
2911.91200,242.65930,485.91904,-0.13320,965.76548,23.81956
2915.41200,242.95101,485.44556,-0.13319,966.93239,23.79635
2918.91200,243.24274,485.59774,-0.13320,968.09921,23.80381
2922.41200,243.53426,486.30391,-0.13320,969.26537,23.83843
2925.91200,243.82610,486.23453,-0.13319,970.43266,23.83503
2929.41200,244.11762,486.83500,-0.13319,971.59882,23.86446
2932.91200,244.40929,487.18220,-0.13319,972.76545,23.88148
2936.41200,244.70087,487.62746,-0.13320,973.93179,23.90331
2939.91200,244.99271,486.92557,-0.13319,975.09918,23.86890
2943.41200,245.28429,487.58602,-0.13319,976.26543,23.90128
2946.91200,245.57602,488.00884,-0.13319,977.43235,23.92200
2950.41200,245.86767,488.88172,-0.13319,978.59898,23.96479
2953.91200,246.15932,488.26477,-0.13319,979.76561,23.93455
2957.41200,246.45103,489.04172,-0.13319,980.93243,23.97263
2960.91200,246.74274,488.92195,-0.13320,982.09925,23.96676
2964.41200,247.03434,489.22310,-0.13319,983.26569,23.98152
2967.91200,247.32593,489.47721,-0.13319,984.43203,23.99398
2971.41200,247.61759,490.25491,-0.13320,985.59866,24.03210
2974.91200,247.90930,489.69029,-0.13319,986.76548,24.00443
2978.41200,248.20101,489.71190,-0.13319,987.93230,24.00549
2981.91200,248.49266,489.92853,-0.13320,989.09893,24.01610
2985.41200,248.78431,489.94916,-0.13319,990.26556,24.01711
2988.91200,249.07596,489.04591,-0.13320,991.43219,23.97284
2992.41200,249.36762,488.72647,-0.13320,992.59882,23.95718
2995.91200,249.65934,484.82162,-0.13320,993.76574,23.76577
2997.74425,249.81210,3.60049,-0.13320,994.37675,0.17649