File: Manufatura Aditiva/Dados/Ensaios AMR/Ensaios/Ensaios FDM/Tracao_OLABI_28_05_2018_FDM_ZY4.is_metal_RawData/Specimen_RawData_5.csv
Time,Extension,Load,Strain 1,Tensile strain,Tensile stress
(sec),(mm),(N),(mm/mm),(%),(MPa)
0.00000,0.00006,0.70518,-0.00001,-0.00143,0.03380
0.10000,0.00407,2.41364,0.00001,0.00149,0.11570
0.20000,0.01369,5.77965,0.00015,0.01480,0.27706
0.30000,0.02350,9.64668,0.00029,0.02853,0.46244
0.40000,0.03259,12.80750,0.00041,0.04118,0.61397
0.50000,0.04143,16.66347,0.00053,0.05321,0.79881
0.60000,0.04986,19.75094,0.00065,0.06478,0.94682
0.70000,0.05823,22.38388,0.00076,0.07613,1.07304
0.80000,0.06667,25.26435,0.00088,0.08814,1.21112
0.90000,0.07498,28.27335,0.00100,0.10012,1.35537
1.00000,0.08329,31.09976,0.00112,0.11186,1.49086
1.10000,0.09178,34.79964,0.00124,0.12413,1.66822
1.20000,0.10003,37.59484,0.00136,0.13634,1.80222
1.30000,0.10834,41.41613,0.00149,0.14877,1.98540
1.40000,0.11677,44.70638,0.00161,0.16110,2.14313
1.50000,0.12508,47.52334,0.00173,0.17276,2.27817
1.60000,0.13339,50.25803,0.00185,0.18481,2.40927
1.70000,0.14170,53.79209,0.00197,0.19733,2.57868
1.80000,0.14995,56.90237,0.00209,0.20901,2.72778
1.90000,0.15832,60.15625,0.00222,0.22171,2.88377
2.00000,0.16663,62.60511,0.00234,0.23380,3.00116
2.10000,0.17494,66.48095,0.00246,0.24635,3.18696
2.20000,0.18325,68.92803,0.00259,0.25859,3.30427
2.30000,0.19163,71.58095,0.00271,0.27129,3.43144
2.40000,0.20000,75.43092,0.00283,0.28335,3.61600
2.50000,0.20837,78.71030,0.00296,0.29635,3.77321
2.60000,0.21668,81.70889,0.00309,0.30898,3.91696
2.70000,0.22499,84.41054,0.00321,0.32113,4.04647
2.80000,0.23330,87.19608,0.00334,0.33391,4.18000
2.90000,0.24155,90.20187,0.00346,0.34628,4.32409
3.00000,0.24998,93.06494,0.00359,0.35893,4.46134
3.10000,0.25841,96.68503,0.00372,0.37178,4.63488
3.20000,0.26672,99.17234,0.00384,0.38416,4.75412
3.30000,0.27503,103.28337,0.00397,0.39683,4.95119
3.40000,0.28340,105.21458,0.00410,0.40984,5.04377
3.50000,0.29165,107.99933,0.00423,0.42280,5.17727
3.60000,0.30002,110.95101,0.00435,0.43521,5.31876
3.70000,0.30839,113.89265,0.00448,0.44834,5.45978
3.80000,0.31670,116.10211,0.00461,0.46088,5.56570
3.90000,0.32508,119.82113,0.00474,0.47381,5.74398
4.00000,0.33339,123.01300,0.00487,0.48674,5.89699
4.10000,0.34164,125.68525,0.00499,0.49942,6.02509
4.20000,0.35001,128.76816,0.00512,0.51206,6.17288
4.30000,0.35832,131.54011,0.00526,0.52553,6.30576
4.40000,0.36657,134.37814,0.00538,0.53826,6.44181
4.50000,0.37500,137.67519,0.00551,0.55135,6.59987
4.60000,0.38331,140.67118,0.00564,0.56447,6.74349
4.70000,0.39162,143.75255,0.00577,0.57680,6.89120
4.80000,0.40005,147.02926,0.00590,0.58981,7.04828
4.90000,0.40836,149.73623,0.00603,0.60287,7.17805
5.00000,0.41667,151.70465,0.00615,0.61522,7.27241
5.10000,0.42504,154.92298,0.00629,0.62878,7.42669
5.20000,0.43329,157.95112,0.00642,0.64183,7.57185
5.30000,0.44155,161.37022,0.00655,0.65530,7.73576
5.40000,0.45010,163.39076,0.00668,0.66842,7.83262
5.50000,0.45829,166.72319,0.00682,0.68162,7.99237
5.60000,0.46666,169.16734,0.00694,0.69449,8.10954
5.70000,0.47509,172.60109,0.00708,0.70767,8.27414
5.80000,0.48328,175.25759,0.00720,0.72001,8.40149
5.90000,0.49159,177.75892,0.00733,0.73341,8.52140
6.00000,0.50008,180.99074,0.00747,0.74698,8.67632
6.10000,0.50827,184.23011,0.00761,0.76072,8.83161
6.20000,0.51664,186.35704,0.00774,0.77351,8.93357
6.30000,0.52507,189.87646,0.00787,0.78676,9.10229
6.40000,0.53332,192.62991,0.00799,0.79949,9.23428
6.50000,0.54169,195.08580,0.00813,0.81286,9.35201
6.60000,0.55000,198.17962,0.00826,0.82645,9.50032
6.70000,0.55825,200.54551,0.00840,0.83956,9.61374
6.80000,0.56674,203.06888,0.00853,0.85300,9.73471
6.90000,0.57506,206.71361,0.00866,0.86648,9.90943
7.00000,0.58331,209.43682,0.00880,0.87951,10.03997
7.10000,0.59174,212.17335,0.00893,0.89267,10.17115
7.20000,0.59993,214.79563,0.00906,0.90598,10.29686
7.30000,0.60824,217.86012,0.00919,0.91923,10.44377
7.40000,0.61673,220.63137,0.00932,0.93234,10.57662
7.50000,0.62498,223.36666,0.00946,0.94598,10.70774
7.60000,0.63323,226.62613,0.00959,0.95925,10.86399
7.70000,0.64172,228.65860,0.00973,0.97257,10.96142
7.80000,0.64997,231.83506,0.00986,0.98580,11.11370
7.90000,0.65828,234.27696,0.00999,0.99861,11.23076
8.00000,0.66671,236.81843,0.01012,1.01202,11.35259
8.10000,0.67496,240.00667,0.01025,1.02532,11.50543
8.20000,0.68327,243.33387,0.01039,1.03857,11.66493
8.30000,0.69170,245.13141,0.01052,1.05193,11.75110
8.40000,0.70002,248.39970,0.01065,1.06522,11.90777
8.50000,0.70839,251.40718,0.01079,1.07909,12.05194
8.60000,0.71670,253.86072,0.01093,1.09256,12.16956
8.70000,0.72501,256.54547,0.01105,1.10522,12.29826
8.80000,0.73338,259.59399,0.01118,1.11826,12.44440
8.90000,0.74169,261.93331,0.01132,1.13203,12.55655
9.00000,0.75000,264.27533,0.01146,1.14557,12.66882
9.10000,0.75837,267.76181,0.01159,1.15893,12.83595
9.20000,0.76662,270.02855,0.01172,1.17227,12.94462
9.30000,0.77499,273.33370,0.01186,1.18576,13.10306
9.40000,0.78336,275.48228,0.01200,1.19959,13.20606
9.50000,0.79167,278.51732,0.01213,1.21263,13.35155
9.60000,0.79992,280.83057,0.01226,1.22608,13.46244
9.70000,0.80835,283.58791,0.01239,1.23910,13.59462
9.80000,0.81666,286.11564,0.01253,1.25274,13.71580
9.90000,0.82498,288.99927,0.01266,1.26628,13.85403
10.00000,0.83341,291.98043,0.01280,1.28005,13.99694
10.10000,0.84172,294.03483,0.01294,1.29384,14.09543
10.20000,0.85003,296.77744,0.01306,1.30645,14.22690
10.30000,0.85840,299.53674,0.01321,1.32057,14.35918
10.40000,0.86665,302.23585,0.01334,1.33368,14.48857
10.50000,0.87496,304.56316,0.01347,1.34747,14.60013
10.60000,0.88333,307.19426,0.01361,1.36114,14.72626
10.70000,0.89158,309.97091,0.01374,1.37443,14.85937
10.80000,0.89995,312.21549,0.01388,1.38783,14.96697
10.90000,0.90832,315.28655,0.01402,1.40158,15.11419
11.00000,0.91669,317.05685,0.01415,1.41471,15.19905
11.10000,0.92506,320.43504,0.01429,1.42866,15.36100
11.20000,0.93337,322.40401,0.01442,1.44167,15.45539
11.30000,0.94168,325.44995,0.01455,1.45529,15.60140
11.40000,0.95006,328.57617,0.01470,1.46952,15.75127
11.50000,0.95825,329.77790,0.01483,1.48303,15.80888
11.60000,0.96650,333.36531,0.01496,1.49648,15.98085
11.70000,0.97505,335.02285,0.01510,1.50990,16.06031
11.80000,0.98330,338.06069,0.01524,1.52362,16.20594
11.90000,0.99161,340.28857,0.01537,1.53681,16.31274
12.00000,1.00010,343.29076,0.01551,1.55096,16.45666
12.10000,1.00829,345.71833,0.01565,1.56491,16.57303
12.20000,1.01666,348.31874,0.01579,1.57854,16.69769
12.30000,1.02515,350.51564,0.01593,1.59258,16.80300
12.40000,1.03328,353.20572,0.01606,1.60619,16.93196
12.50000,1.04159,356.14909,0.01620,1.61986,17.07306
12.60000,1.05008,357.44617,0.01634,1.63373,17.13524
12.70000,1.05827,360.21613,0.01647,1.64712,17.26802
12.80000,1.06664,363.43185,0.01661,1.66078,17.42218
12.90000,1.07507,365.44946,0.01675,1.67504,17.51890
13.00000,1.08327,367.53388,0.01689,1.68905,17.61882
13.10000,1.09164,370.07809,0.01703,1.70281,17.74079
13.20000,1.10001,372.80475,0.01716,1.71633,17.87149
13.30000,1.10832,374.97461,0.01730,1.73013,17.97551
13.40000,1.11675,377.38308,0.01744,1.74380,18.09097
13.50000,1.12506,380.15586,0.01757,1.75747,18.22389
13.60000,1.13325,382.02268,0.01771,1.77121,18.31338
13.70000,1.14168,384.93043,0.01785,1.78467,18.45278
13.80000,1.14993,387.08164,0.01799,1.79885,18.55590
13.90000,1.15824,388.91665,0.01813,1.81258,18.64387
14.00000,1.16679,391.41662,0.01827,1.82655,18.76371
14.10000,1.17492,393.60491,0.01840,1.84040,18.86861
14.20000,1.18323,395.99445,0.01854,1.85440,18.98316
14.30000,1.19178,398.57514,0.01869,1.86856,19.10687
14.40000,1.20003,400.66675,0.01882,1.88241,19.20714
14.50000,1.20841,402.86481,0.01896,1.89624,19.31251
14.60000,1.21678,405.33352,0.01910,1.91022,19.43086
14.70000,1.22497,407.27775,0.01924,1.92375,19.52406
14.80000,1.23328,410.32215,0.01937,1.93738,19.67000
14.90000,1.24171,412.31709,0.01951,1.95128,19.76563
15.00000,1.24990,414.76069,0.01965,1.96527,19.88278
15.10000,1.25827,416.69384,0.01979,1.97935,19.97545
15.20000,1.26670,419.00398,0.01994,1.99366,20.08619
15.30000,1.27495,420.87291,0.02007,2.00732,20.17579
15.40000,1.28338,423.46739,0.02021,2.02116,20.30016
15.50000,1.29175,425.54340,0.02035,2.03528,20.39968
15.60000,1.29994,427.38877,0.02049,2.04864,20.48814
15.70000,1.30831,429.79461,0.02063,2.06282,20.60347
15.80000,1.31650,432.44278,0.02077,2.07655,20.73042
15.90000,1.32494,433.68503,0.02091,2.09116,20.78997
16.00000,1.33337,436.54554,0.02105,2.10529,20.92710
16.10000,1.34156,438.52739,0.02119,2.11911,21.02210
16.20000,1.34993,440.90534,0.02133,2.13339,21.13610
16.30000,1.35836,442.69324,0.02148,2.14760,21.22181
16.40000,1.36667,445.11878,0.02161,2.16134,21.33808
16.50000,1.37498,447.03027,0.02175,2.17530,21.42971
16.60000,1.38341,449.67495,0.02190,2.18976,21.55650
16.70000,1.39166,451.49471,0.02204,2.20371,21.64373
16.80000,1.39997,453.42185,0.02217,2.21748,21.73611
16.90000,1.40840,455.53017,0.02232,2.23196,21.83718
17.00000,1.41671,457.87259,0.02246,2.24628,21.94947
17.10000,1.42502,459.73598,0.02260,2.26006,22.03880
17.20000,1.43339,462.11891,0.02274,2.27420,22.15303
17.30000,1.44164,464.40726,0.02289,2.28892,22.26273
17.40000,1.45001,465.86711,0.02303,2.30262,22.33271
17.50000,1.45839,468.02140,0.02317,2.31736,22.43599
17.60000,1.46670,470.25336,0.02331,2.33138,22.54298
17.70000,1.47507,472.17305,0.02346,2.34550,22.63501
17.80000,1.48338,474.39830,0.02360,2.35996,22.74168
17.90000,1.49163,476.29746,0.02374,2.37387,22.83272
18.00000,1.49994,478.43480,0.02389,2.38864,22.93518
18.10000,1.50825,480.55900,0.02403,2.40251,23.03701
18.20000,1.51662,482.77993,0.02417,2.41733,23.14348
18.30000,1.52505,484.25212,0.02432,2.43162,23.21405
18.40000,1.53330,486.36869,0.02445,2.44546,23.31552
18.50000,1.54161,487.65289,0.02460,2.45986,23.37708
18.60000,1.55004,490.39479,0.02474,2.47427,23.50852
18.70000,1.55829,491.83085,0.02489,2.48872,23.57736
18.80000,1.56666,493.82146,0.02503,2.50294,23.67279
18.90000,1.57503,495.37416,0.02518,2.51786,23.74722
19.00000,1.58323,497.11294,0.02532,2.53194,23.83057
19.10000,1.59160,499.48543,0.02546,2.54619,23.94431
19.20000,1.60003,501.65937,0.02561,2.56065,24.04852
19.30000,1.60828,503.43033,0.02575,2.57543,24.13342
19.40000,1.61665,504.81507,0.02589,2.58944,24.19980
19.50000,1.62502,506.61918,0.02604,2.60433,24.28628
19.60000,1.63333,508.27735,0.02619,2.61862,24.36577
19.70000,1.64176,510.48785,0.02634,2.63355,24.47174
19.80000,1.65013,512.34793,0.02648,2.64841,24.56091
19.90000,1.65838,513.96238,0.02663,2.66314,24.63830
20.00000,1.66669,515.08048,0.02677,2.67726,24.69190
20.10000,1.67500,517.74634,0.02692,2.69156,24.81970
20.20000,1.68325,518.88293,0.02707,2.70656,24.87418
20.30000,1.69168,521.18436,0.02721,2.72119,24.98451
20.40000,1.69999,522.48165,0.02736,2.73598,25.04670
20.50000,1.70825,524.02061,0.02751,2.75062,25.12047
20.60000,1.71674,526.27483,0.02765,2.76547,25.22854
20.70000,1.72505,527.50823,0.02780,2.78019,25.28766
20.80000,1.73330,528.50703,0.02795,2.79479,25.33554
20.90000,1.74179,530.13917,0.02810,2.80968,25.41378
21.00000,1.74998,532.07045,0.02824,2.82443,25.50637
21.10000,1.75829,533.75578,0.02839,2.83903,25.58716
21.20000,1.76672,535.35569,0.02854,2.85416,25.66385
21.30000,1.77491,536.71855,0.02869,2.86912,25.72919
21.40000,1.78328,538.61397,0.02883,2.88337,25.82005
21.50000,1.79171,540.12826,0.02899,2.89854,25.89264
21.60000,1.80002,541.46913,0.02913,2.91349,25.95692
21.70000,1.80839,542.13046,0.02929,2.92873,25.98862
21.80000,1.81676,545.14082,0.02943,2.94335,26.13293
21.90000,1.82507,545.75060,0.02958,2.95825,26.16216
22.00000,1.83339,547.38061,0.02973,2.97265,26.24030
22.10000,1.84170,548.66574,0.02988,2.98768,26.30191
22.20000,1.84995,549.78542,0.03003,3.00251,26.35559
22.30000,1.85832,551.22091,0.03017,3.01709,26.42440
22.40000,1.86669,553.07942,0.03032,3.03220,26.51349
22.50000,1.87500,554.27304,0.03047,3.04735,26.57071
22.60000,1.88337,554.96930,0.03059,3.05931,26.60409
22.70000,1.89168,556.21075,0.03074,3.07404,26.66360
22.80000,1.89993,557.57575,0.03089,3.10704,26.72904
22.90000,1.90830,559.59853,0.03103,3.14052,26.82601
22.97800,1.91482,560.24599,0.03115,3.16659,26.85704
23.07800,1.92313,561.83599,0.03130,3.19984,26.93327
23.17800,1.93144,563.58175,0.03146,3.23308,27.01695
23.27800,1.93975,564.37114,0.03161,3.26632,27.05479
23.37800,1.94806,566.08040,0.03175,3.29957,27.13673
23.47800,1.95643,566.92781,0.03191,3.33305,27.17736
23.57800,1.96474,568.36316,0.03206,3.36629,27.24616
23.67800,1.97305,569.41072,0.03221,3.39953,27.29638
23.77800,1.98148,570.23414,0.03236,3.43325,27.33586
23.87800,1.98985,571.96729,0.03251,3.46674,27.41894
23.97800,1.99816,573.41759,0.03266,3.49998,27.48846
24.07800,2.00654,573.83706,0.03281,3.53346,27.50857
24.17800,2.01491,575.12056,0.03297,3.56694,27.57010
24.27800,2.02322,576.15563,0.03312,3.60019,27.61972
24.37800,2.03153,577.62014,0.03327,3.63343,27.68992
24.47800,2.03984,578.24571,0.03398,3.66667,27.71991
24.57800,2.04821,579.66076,0.03337,3.70016,27.78775
24.67800,2.05652,580.20470,0.03363,3.73340,27.81382
24.77800,2.06489,581.48061,0.03282,3.76688,27.87499
24.87800,2.07320,582.74474,0.02806,3.80012,27.93559
24.97800,2.08151,583.83271,0.02524,3.83337,27.98774
25.07800,2.08994,583.62791,0.00011,3.86709,27.97792
25.17800,2.09825,584.00170,0.00130,3.90033,27.99584
25.27800,2.10650,586.23091,0.00134,3.93333,28.10271
25.37800,2.11481,587.07837,0.00075,3.96658,28.14333
25.47800,2.12318,587.67037,0.00036,4.00006,28.17171
25.57800,2.13150,588.55554,-0.00029,4.03330,28.21415
25.67800,2.13981,588.82139,-0.00014,4.06654,28.22689
25.77800,2.14818,590.09073,0.00178,4.10003,28.28774
25.87800,2.15649,591.05260,0.00165,4.13327,28.33385
25.97800,2.16480,591.60842,0.00176,4.16651,28.36049
26.07800,2.17323,592.85113,0.00220,4.20023,28.42007
26.17800,2.18148,593.05024,0.00070,4.23324,28.42961
26.27800,2.18979,594.16071,0.00037,4.26648,28.48285
26.37800,2.19816,594.55987,-0.00988,4.29996,28.50198
26.47800,2.20647,594.77421,-0.01948,4.33321,28.51226
26.57800,2.21478,595.93557,-0.13958,4.36645,28.56793
26.67800,2.22315,597.08920,-0.12612,4.39993,28.62323
26.77800,2.23146,597.80399,-0.14018,4.43317,28.65750
26.87800,2.23983,597.29875,-0.13105,4.46666,28.63328
26.97800,2.24814,598.94300,-0.14017,4.49990,28.71210
27.07800,2.25646,599.48815,-0.14014,4.53314,28.73823
27.17800,2.26489,599.92638,-0.13872,4.56686,28.75924
27.27800,2.27320,599.97933,-0.13956,4.60011,28.76178
27.37800,2.28151,600.85235,-0.13960,4.63335,28.80363
27.47800,2.28988,600.43987,-0.13960,4.66683,28.78386
27.57800,2.29819,602.43499,-0.13960,4.70007,28.87950
27.67800,2.30650,602.41548,-0.13960,4.73332,28.87856
27.77800,2.31487,602.62610,-0.13960,4.76680,28.88866
27.87800,2.32312,603.16664,-0.13960,4.79980,28.91457
27.97800,2.33149,602.76520,-0.13961,4.83328,28.89533
28.07800,2.33986,603.85661,-0.13961,4.86677,28.94765
28.17800,2.34817,603.77475,-0.13961,4.90001,28.94372
28.27800,2.35648,603.63337,-0.13961,4.93325,28.93695
28.37800,2.36491,604.02169,-0.13962,4.96697,28.95556
28.47800,2.37316,604.53801,-0.13961,4.99998,28.98031
28.57800,2.38148,604.50598,-0.13961,5.03322,28.97878
28.67800,2.38985,604.53163,-0.13961,5.06670,28.98001
28.77800,2.39810,605.02323,-0.13961,5.09971,29.00357
28.87800,2.40647,604.47226,-0.13961,5.13319,28.97716
28.97800,2.41478,604.74663,-0.13961,5.16643,28.99031
29.07800,2.42315,604.12679,-0.13961,5.19991,28.96060
29.17800,2.43146,604.12404,-0.13961,5.23316,28.96047
29.27800,2.43977,603.85056,-0.13961,5.26640,28.94736
29.37800,2.44808,602.94056,-0.13962,5.29964,28.90373
29.47800,2.45651,602.49250,-0.13962,5.33336,28.88226
29.57800,2.46482,600.86097,-0.13962,5.36661,28.80404
29.67800,2.47313,598.94952,-0.13962,5.39985,28.71241
29.77800,2.48150,590.10289,-0.13962,5.43333,28.28832
29.82600,2.48557,6.38323,-0.13962,5.44959,0.30600