File: Manufatura Aditiva/Dados/Ensaios AMR/Ensaios/Ensaios FDM/Tracao_OLABI_28_05_2018_FDM_ZY4.is_metal_RawData/Specimen_RawData_3.csv
Time,Extension,Load,Strain 1,Tensile strain,Tensile stress
(sec),(mm),(N),(mm/mm),(%),(MPa)
0.00000,0.00006,14.56594,0.00041,0.04118,0.72224
0.10000,0.00407,16.27401,0.00045,0.04468,0.80693
0.20000,0.01369,19.24179,0.00061,0.06075,0.95409
0.30000,0.02344,23.20954,0.00077,0.07743,1.15083
0.40000,0.03259,25.99061,0.00093,0.09346,1.28872
0.50000,0.04143,29.98064,0.00109,0.10913,1.48657
0.60000,0.04986,32.48046,0.00124,0.12423,1.61052
0.70000,0.05823,35.89906,0.00139,0.13885,1.78003
0.80000,0.06667,38.79013,0.00154,0.15395,1.92338
0.90000,0.07498,41.61945,0.00168,0.16844,2.06367
1.00000,0.08323,45.13038,0.00183,0.18258,2.23776
1.10000,0.09178,48.39307,0.00198,0.19764,2.39953
1.20000,0.10003,50.97922,0.00212,0.21167,2.52777
1.30000,0.10834,54.51269,0.00226,0.22602,2.70297
1.40000,0.11677,57.56060,0.00241,0.24100,2.85410
1.50000,0.12508,59.64002,0.00256,0.25556,2.95721
1.60000,0.13339,63.43774,0.00270,0.26973,3.14551
1.70000,0.14170,66.42835,0.00284,0.28438,3.29380
1.80000,0.14995,69.16038,0.00299,0.29873,3.42926
1.90000,0.15832,72.46309,0.00313,0.31257,3.59303
2.00000,0.16663,75.12962,0.00327,0.32666,3.72524
2.10000,0.17494,79.00147,0.00341,0.34150,3.91723
2.20000,0.18325,81.01855,0.00356,0.35564,4.01724
2.30000,0.19163,84.86385,0.00370,0.36984,4.20791
2.40000,0.20000,86.96218,0.00384,0.38406,4.31195
2.50000,0.20837,90.88683,0.00398,0.39825,4.50655
2.60000,0.21668,93.87265,0.00413,0.41308,4.65460
2.70000,0.22499,96.94465,0.00427,0.42682,4.80693
2.80000,0.23330,99.86403,0.00441,0.44094,4.95168
2.90000,0.24161,101.94230,0.00455,0.45540,5.05473
3.00000,0.24998,105.62912,0.00470,0.46993,5.23754
3.10000,0.25841,108.22429,0.00484,0.48413,5.36622
3.20000,0.26672,110.98663,0.00497,0.49750,5.50319
3.30000,0.27503,113.51043,0.00512,0.51190,5.62833
3.40000,0.28340,117.36929,0.00527,0.52670,5.81967
3.50000,0.29165,119.63391,0.00540,0.54049,5.93196
3.60000,0.30002,122.07947,0.00555,0.55495,6.05322
3.70000,0.30839,126.02231,0.00569,0.56890,6.24872
3.80000,0.31670,128.08038,0.00583,0.58290,6.35077
3.90000,0.32508,131.17742,0.00597,0.59666,6.50433
4.00000,0.33339,134.82084,0.00611,0.61077,6.68499
4.10000,0.34164,137.47942,0.00625,0.62486,6.81681
4.20000,0.35001,139.87470,0.00639,0.63901,6.93558
4.30000,0.35832,142.94737,0.00654,0.65390,7.08794
4.40000,0.36663,146.71844,0.00668,0.66782,7.27492
4.50000,0.37500,149.49124,0.00683,0.68256,7.41241
4.60000,0.38331,151.60956,0.00696,0.69643,7.51744
4.70000,0.39162,155.15764,0.00710,0.71006,7.69337
4.80000,0.40005,158.49721,0.00724,0.72442,7.85896
4.90000,0.40836,160.55318,0.00738,0.73824,7.96091
5.00000,0.41667,163.66446,0.00752,0.75228,8.11518
5.10000,0.42510,166.34066,0.00767,0.76703,8.24787
5.20000,0.43329,168.87286,0.00781,0.78095,8.37343
5.30000,0.44155,172.53330,0.00795,0.79501,8.55493
5.40000,0.45004,175.05300,0.00809,0.80936,8.67987
5.50000,0.45829,177.72330,0.00823,0.82276,8.81227
5.60000,0.46660,180.37139,0.00837,0.83675,8.94358
5.70000,0.47509,183.18837,0.00851,0.85132,9.08326
5.80000,0.48328,186.36566,0.00865,0.86523,9.24080
5.90000,0.49159,188.84565,0.00879,0.87922,9.36377
6.00000,0.50008,192.01072,0.00894,0.89371,9.52070
6.10000,0.50827,195.01557,0.00908,0.90754,9.66970
6.20000,0.51664,197.68260,0.00922,0.92164,9.80194
6.30000,0.52507,200.81019,0.00936,0.93638,9.95702
6.40000,0.53332,203.42520,0.00950,0.94984,10.08668
6.50000,0.54169,205.88313,0.00964,0.96418,10.20856
6.60000,0.55000,209.61154,0.00979,0.97885,10.39343
6.70000,0.55825,211.70645,0.00992,0.99246,10.49730
6.80000,0.56674,214.50606,0.01007,1.00668,10.63612
6.90000,0.57506,217.06759,0.01021,1.02064,10.76313
7.00000,0.58331,220.19949,0.01034,1.03432,10.91842
7.10000,0.59174,223.23884,0.01049,1.04880,11.06913
7.20000,0.59993,225.10157,0.01063,1.06324,11.16149
7.30000,0.60824,228.35073,0.01077,1.07733,11.32260
7.40000,0.61673,231.48067,0.01091,1.09121,11.47779
7.50000,0.62498,233.45149,0.01105,1.10544,11.57551
7.60000,0.63323,236.83691,0.01119,1.11916,11.74338
7.70000,0.64166,239.39293,0.01133,1.13262,11.87012
7.80000,0.64997,242.05383,0.01147,1.14707,12.00205
7.90000,0.65828,245.20201,0.01161,1.16088,12.15815
8.00000,0.66671,247.72568,0.01175,1.17549,12.28329
8.10000,0.67496,250.75113,0.01190,1.18993,12.43330
8.20000,0.68327,253.29739,0.01204,1.20394,12.55956
8.30000,0.69170,256.41837,0.01218,1.21806,12.71431
8.40000,0.70002,259.03096,0.01232,1.23173,12.84385
8.50000,0.70839,261.89853,0.01246,1.24568,12.98604
8.60000,0.71670,264.64392,0.01260,1.26002,13.12217
8.70000,0.72501,267.18804,0.01274,1.27408,13.24831
8.80000,0.73338,269.35367,0.01288,1.28819,13.35570
8.90000,0.74169,272.79339,0.01303,1.30268,13.52625
9.00000,0.75000,275.18854,0.01316,1.31644,13.64501
9.10000,0.75837,277.82263,0.01331,1.33113,13.77562
9.20000,0.76662,281.21423,0.01345,1.34469,13.94379
9.30000,0.77499,283.59497,0.01359,1.35874,14.06184
9.40000,0.78336,286.15098,0.01373,1.37287,14.18858
9.50000,0.79167,289.39433,0.01387,1.38685,14.34940
9.60000,0.79992,291.46227,0.01401,1.40124,14.45193
9.70000,0.80835,293.44284,0.01415,1.41502,14.55014
9.80000,0.81666,296.90680,0.01429,1.42885,14.72190
9.90000,0.82498,299.46791,0.01443,1.44272,14.84889
10.00000,0.83341,301.47927,0.01457,1.45692,14.94862
10.10000,0.84172,305.00828,0.01472,1.47179,15.12360
10.20000,0.85003,306.73733,0.01485,1.48529,15.20934
10.30000,0.85846,309.58799,0.01500,1.49977,15.35068
10.40000,0.86665,312.02442,0.01514,1.51390,15.47149
10.50000,0.87502,314.86561,0.01528,1.52779,15.61237
10.60000,0.88333,317.16784,0.01542,1.54207,15.72653
10.70000,0.89158,319.67035,0.01556,1.55584,15.85061
10.80000,0.89995,322.61345,0.01570,1.57022,15.99654
10.90000,0.90832,325.03163,0.01584,1.58422,16.11645
11.00000,0.91669,327.48326,0.01599,1.59893,16.23801
11.10000,0.92506,330.05620,0.01613,1.61328,16.36559
11.20000,0.93337,332.79851,0.01627,1.62712,16.50156
11.30000,0.94168,335.34279,0.01641,1.64139,16.62772
11.40000,0.95006,337.89540,0.01656,1.65554,16.75429
11.50000,0.95825,340.02771,0.01669,1.66914,16.86001
11.60000,0.96650,342.94305,0.01684,1.68390,17.00457
11.70000,0.97499,345.09553,0.01698,1.69829,17.11130
11.80000,0.98330,347.98787,0.01712,1.71246,17.25471
11.90000,0.99161,350.67818,0.01727,1.72666,17.38811
12.00000,1.00010,352.99351,0.01741,1.74132,17.50291
12.10000,1.00829,355.43335,0.01756,1.75571,17.62389
12.20000,1.01666,357.70072,0.01770,1.76953,17.73632
12.30000,1.02515,361.24766,0.01784,1.78387,17.91219
12.40000,1.03328,362.71464,0.01798,1.79784,17.98493
12.50000,1.04159,365.39626,0.01812,1.81234,18.11790
12.60000,1.05008,368.03244,0.01827,1.82730,18.24861
12.70000,1.05827,369.90666,0.01841,1.84145,18.34154
12.80000,1.06664,372.75874,0.01856,1.85558,18.48296
12.90000,1.07507,375.12016,0.01870,1.87026,18.60005
13.00000,1.08327,377.18045,0.01884,1.88449,18.70220
13.10000,1.09164,380.44085,0.01899,1.89870,18.86387
13.20000,1.10001,382.37891,0.01913,1.91292,18.95997
13.30000,1.10832,384.41673,0.01928,1.92773,19.06101
13.40000,1.11675,387.04607,0.01942,1.94179,19.19138
13.50000,1.12506,389.12648,0.01956,1.95574,19.29454
13.60000,1.13325,391.34352,0.01970,1.97029,19.40447
13.70000,1.14168,393.73655,0.01985,1.98465,19.52313
13.80000,1.14993,396.18122,0.01999,1.99906,19.64434
13.90000,1.15824,398.59116,0.02013,2.01336,19.76384
14.00000,1.16679,400.90848,0.02028,2.02839,19.87874
14.10000,1.17492,403.30552,0.02042,2.04247,19.99760
14.20000,1.18323,406.06293,0.02057,2.05667,20.13432
14.30000,1.19178,407.68473,0.02071,2.07091,20.21474
14.40000,1.20003,410.49216,0.02086,2.08551,20.35394
14.50000,1.20841,412.30796,0.02100,2.10022,20.44398
14.60000,1.21678,415.35473,0.02115,2.11488,20.59505
14.70000,1.22497,417.06669,0.02129,2.12889,20.67993
14.80000,1.23328,419.62881,0.02143,2.14303,20.80697
14.90000,1.24171,420.16804,0.02153,2.15310,20.83371
15.00000,1.24990,422.69928,0.02167,2.16731,20.95922
15.10000,1.25827,424.88133,0.02181,2.18149,21.06742
15.20000,1.26670,426.86928,0.02196,2.19591,21.16599
15.30000,1.27495,428.82562,0.02211,2.21057,21.26299
15.40000,1.28338,430.90046,0.02225,2.22485,21.36587
15.50000,1.29169,433.17960,0.02239,2.23939,21.47888
15.60000,1.29994,435.91596,0.02253,2.25313,21.61456
15.70000,1.30831,437.79439,0.02268,2.26783,21.70770
15.80000,1.31656,439.87334,0.02282,2.28227,21.81078
15.90000,1.32494,441.91796,0.02296,2.29640,21.91216
16.00000,1.33337,444.51351,0.02311,2.31082,22.04086
16.10000,1.34156,446.15525,0.02325,2.32498,22.12227
16.20000,1.34993,448.41869,0.02340,2.33951,22.23450
16.30000,1.35842,451.24292,0.02354,2.35446,22.37454
16.40000,1.36667,452.02249,0.02368,2.36820,22.41319
16.50000,1.37498,454.90111,0.02383,2.38264,22.55592
16.60000,1.38341,456.73754,0.02397,2.39676,22.64698
16.70000,1.39166,458.58142,0.02411,2.41148,22.73841
16.80000,1.39997,460.60602,0.02426,2.42595,22.83880
16.90000,1.40840,463.15067,0.02440,2.44042,22.96497
17.00000,1.41671,464.55022,0.02455,2.45478,23.03437
17.10000,1.42496,466.70535,0.02469,2.46914,23.14123
17.20000,1.43339,468.87724,0.02484,2.48368,23.24892
17.30000,1.44164,471.03805,0.02498,2.49789,23.35606
17.40000,1.45001,472.95457,0.02513,2.51258,23.45109
17.50000,1.45833,474.85395,0.02527,2.52697,23.54527
17.60000,1.46670,476.52675,0.02541,2.54144,23.62822
17.70000,1.47507,478.86777,0.02556,2.55588,23.74429
17.80000,1.48338,480.93847,0.02570,2.57012,23.84697
17.90000,1.49163,482.61988,0.02583,2.58302,23.93034
18.00000,1.49994,484.42278,0.02597,2.59725,24.01973
18.10000,1.50825,485.63718,0.02610,2.61014,24.07995
18.20000,1.51662,487.51477,0.02624,2.62381,24.17305
18.30000,1.52505,489.39339,0.02639,2.63865,24.26620
18.40000,1.53330,491.38712,0.02653,2.65295,24.36506
18.50000,1.54161,492.70377,0.02667,2.66747,24.43034
18.60000,1.55004,495.29891,0.02682,2.68152,24.55902
18.70000,1.55829,496.80937,0.02696,2.69561,24.63391
18.80000,1.56666,498.49642,0.02710,2.71049,24.71756
18.90000,1.57503,500.62165,0.02725,2.72492,24.82294
19.00000,1.58323,503.40686,0.02739,2.73941,24.96104
19.10000,1.59160,504.13702,0.02754,2.75439,24.99725
19.20000,1.60003,505.88408,0.02769,2.76874,25.08388
19.30000,1.60828,507.98031,0.02784,2.78371,25.18781
19.40000,1.61665,509.15987,0.02798,2.79790,25.24630
19.50000,1.62502,511.69302,0.02812,2.81237,25.37191
19.60000,1.63333,513.54403,0.02827,2.82723,25.46369
19.70000,1.64176,514.60527,0.02842,2.84179,25.51631
19.80000,1.65013,517.03542,0.02857,2.85652,25.63681
19.90000,1.65838,517.73977,0.02871,2.87141,25.67173
20.00000,1.66669,519.75120,0.02886,2.88589,25.77147
20.10000,1.67500,522.00640,0.02901,2.90091,25.88329
20.20000,1.68331,523.72427,0.02915,2.91541,25.96847
20.30000,1.69168,525.19906,0.02930,2.93012,26.04159
20.40000,1.69999,526.54878,0.02945,2.94510,26.10852
20.50000,1.70825,528.43443,0.02960,2.95991,26.20202
20.60000,1.71674,529.86750,0.02975,2.97505,26.27308
20.70000,1.72499,531.77178,0.02989,2.98949,26.36750
20.80000,1.73330,533.19698,0.03005,3.00453,26.43817
20.90000,1.74179,534.25063,0.03019,3.01949,26.49041
21.00000,1.74998,535.53199,0.03034,3.03404,26.55395
21.10000,1.75829,537.54430,0.03049,3.04871,26.65372
21.20000,1.76672,539.18557,0.03064,3.06425,26.73511
21.30000,1.77491,540.74964,0.03079,3.09702,26.81266
21.40000,1.78334,542.25703,0.03093,3.13074,26.88740
21.45200,1.78771,543.16754,0.03101,3.14820,26.93255
21.55200,1.79602,543.93141,0.03116,3.18144,26.97042
21.65200,1.80433,545.88043,0.03131,3.21468,27.06706
21.75200,1.81282,547.08514,0.03146,3.24864,27.12680
21.85200,1.82101,548.50737,0.03161,3.28141,27.19732
21.95200,1.82938,550.38985,0.03176,3.31489,27.29066
22.05200,1.83775,551.35540,0.03191,3.34837,27.33854
22.15200,1.84600,553.01450,0.03205,3.38138,27.42080
22.25200,1.85425,554.47458,0.03220,3.41438,27.49320
22.35200,1.86268,555.61322,0.03235,3.44810,27.54966
22.45200,1.87105,556.86133,0.03250,3.48158,27.61154
22.55200,1.87930,558.35159,0.03265,3.51459,27.68544
22.65200,1.88773,559.91095,0.03281,3.54831,27.76276
22.75200,1.89598,560.76348,0.03296,3.58131,27.80503
22.85200,1.90424,562.42757,0.03308,3.61432,27.88754
22.95200,1.91267,563.29672,0.03313,3.64804,27.93064
23.05200,1.92092,564.42209,0.03006,3.68104,27.98644
23.15200,1.92929,567.29205,0.02412,3.71452,28.12874
23.25200,1.93760,567.69955,0.00893,3.74777,28.14895
23.35200,1.94591,568.11222,0.00871,3.78101,28.16941
23.45200,1.95428,569.01257,0.00893,3.81449,28.21405
23.55200,1.96259,570.66516,0.00869,3.84773,28.29600
23.65200,1.97096,571.61734,0.00626,3.88122,28.34321
23.75200,1.97927,572.77484,0.00424,3.91446,28.40060
23.85200,1.98764,573.69913,0.00370,3.94794,28.44643
23.95200,1.99601,574.97746,0.00382,3.98142,28.50982
24.05200,2.00444,575.81221,0.00449,4.01514,28.55121
24.15200,2.01269,577.07587,0.00649,4.04815,28.61387
24.25200,2.02106,578.13842,0.00934,4.08163,28.66655
24.35200,2.02938,579.04283,0.02030,4.11487,28.71140
24.45200,2.03769,580.63189,-0.01063,4.14812,28.79019
24.55200,2.04606,580.68545,-0.13499,4.18160,28.79284
24.65200,2.05437,581.79530,-0.13231,4.21484,28.84788
24.75200,2.06268,582.90334,-0.13367,4.24808,28.90282
24.85200,2.07105,584.08137,-0.13359,4.28157,28.96123
24.95200,2.07936,585.29777,-0.13354,4.31481,29.02154
25.05200,2.08773,586.03180,-0.13358,4.34829,29.05794
25.15200,2.09604,586.51194,-0.13356,4.38153,29.08175
25.25200,2.10435,587.43875,-0.13357,4.41478,29.12770
25.35200,2.11272,588.94721,-0.13358,4.44826,29.20250
25.45200,2.12103,589.64952,-0.13357,4.48150,29.23732
25.55200,2.12934,590.00049,-0.13358,4.51474,29.25472
25.65200,2.13765,590.54974,-0.13357,4.54799,29.28196
25.75200,2.14596,591.68679,-0.13357,4.58123,29.33834
25.85200,2.15433,592.11017,-0.13358,4.61471,29.35933
25.95200,2.16271,593.57923,-0.13358,4.64820,29.43217
26.05200,2.17108,593.00810,-0.13358,4.68168,29.40385
26.15200,2.17933,593.69151,-0.13358,4.71468,29.43774
26.25200,2.18764,594.32457,-0.13358,4.74792,29.46913
26.35200,2.19601,594.60704,-0.13358,4.78141,29.48314
26.45200,2.20426,595.11485,-0.13358,4.81441,29.50831
26.55200,2.21263,595.04868,-0.13358,4.84789,29.50503
26.65200,2.22100,594.97482,-0.13359,4.88137,29.50137
26.75200,2.22931,595.33869,-0.13359,4.91462,29.51941
26.85200,2.23768,595.16137,-0.13359,4.94810,29.51062
26.95200,2.24605,594.39437,-0.13359,4.98158,29.47259
27.05200,2.25430,593.45961,-0.13359,5.01458,29.42624
27.15200,2.26267,592.24153,-0.13359,5.04807,29.36584
27.25200,2.27104,591.10099,-0.13359,5.08155,29.30929
27.35200,2.27935,590.12566,-0.13359,5.11479,29.26093
27.45200,2.28773,587.45341,-0.13359,5.14827,29.12843
27.55200,2.29610,85.93196,-0.13359,5.18176,4.26087
27.56400,2.29711,7.17603,-0.13359,5.18582,0.35582