File: Manufatura Aditiva/Classificação Orientação/Ensaios/Ensaios FDM/Tracao_OLABI_25_05_2018_FDM_YZ5.is_metal_RawData/Specimen_RawData_1.csv
Time,Extension,Load,Strain 1,Tensile strain,Tensile stress
(sec),(mm),(N),(mm/mm),(%),(MPa)
0.00000,0.00006,9.90463,0.00036,0.03634,0.48872
0.50000,0.04119,27.62723,0.00098,0.09764,1.36320
1.00000,0.08329,46.19798,0.00165,0.16487,2.27954
1.50000,0.12514,65.20508,0.00232,0.23176,3.21740
2.00000,0.16663,82.73141,0.00299,0.29863,4.08220
2.50000,0.20837,101.54998,0.00366,0.36627,5.01076
3.00000,0.24998,119.92203,0.00433,0.43332,5.91728
3.50000,0.29165,136.69380,0.00501,0.50091,6.74485
4.00000,0.33333,155.61598,0.00569,0.56851,7.67852
4.50000,0.37500,173.52290,0.00636,0.63623,8.56210
5.00000,0.41667,190.85080,0.00704,0.70448,9.41710
5.50000,0.45829,208.16613,0.00772,0.77241,10.27149
6.00000,0.50002,226.49444,0.00842,0.84174,11.17586
6.50000,0.54169,243.46435,0.00910,0.90951,12.01320
7.00000,0.58331,260.22205,0.00978,0.97779,12.84007
7.50000,0.62492,278.08596,0.01046,1.04578,13.72153
8.00000,0.66671,295.28763,0.01115,1.11480,14.57030
8.50000,0.70839,312.04119,0.01183,1.18300,15.39697
9.00000,0.75000,328.07800,0.01249,1.24903,16.18827
9.50000,0.79167,344.40260,0.01317,1.31717,16.99377
10.00000,0.83341,360.46733,0.01385,1.38530,17.78645
10.50000,0.87502,377.11016,0.01454,1.45384,18.60765
11.00000,0.91669,393.74288,0.01523,1.52282,19.42836
11.50000,0.95825,409.57010,0.01591,1.59089,20.20932
12.00000,1.00010,425.35011,0.01660,1.66024,20.98795
12.50000,1.04165,441.89137,0.01729,1.72871,21.80414
13.00000,1.08327,457.42667,0.01796,1.79553,22.57069
13.50000,1.12506,473.01068,0.01863,1.86310,23.33965
14.00000,1.16679,487.83915,0.01932,1.93248,24.07133
14.50000,1.20841,503.19126,0.02002,2.00214,24.82884
15.00000,1.24996,518.84945,0.02071,2.07139,25.60146
15.50000,1.29169,532.55078,0.02141,2.14145,26.27752
16.00000,1.33337,546.23554,0.02210,2.21022,26.95277
16.50000,1.37498,560.88567,0.02277,2.27724,27.67564
17.00000,1.41677,575.08368,0.02348,2.34753,28.37621
17.50000,1.45839,589.18782,0.02418,2.41778,29.07215
18.00000,1.49994,602.95421,0.02489,2.48876,29.75142
18.50000,1.54167,616.55515,0.02558,2.55788,30.42253
19.00000,1.58329,630.35502,0.02628,2.62832,31.10345
19.50000,1.62502,642.87949,0.02696,2.69620,31.72145
20.00000,1.66669,655.47186,0.02768,2.76787,32.34279
20.50000,1.70831,668.95308,0.02840,2.83977,33.00799
21.00000,1.74998,680.25128,0.02912,2.91250,33.56547
21.50000,1.79165,693.20914,0.02985,2.98476,34.20485
22.00000,1.83339,705.48062,0.03057,3.07609,34.81036
22.42400,1.86866,715.18519,0.03116,3.21719,35.28921
22.92400,1.91027,727.15119,0.03189,3.38365,35.87964
23.42400,1.95195,738.59729,0.03263,3.55034,36.44442
23.92400,1.99368,748.91965,0.03337,3.71727,36.95376
24.42400,2.03535,760.44686,0.03412,3.88396,37.52254
24.92400,2.07703,769.95934,0.01121,4.05066,37.99192
25.42400,2.11870,780.74164,-0.00381,4.21735,38.52394
25.92400,2.16031,789.56792,0.04764,4.38380,38.95946
26.42400,2.20193,799.56595,-0.13843,4.55026,39.45279
26.92400,2.24366,809.65981,-0.14107,4.71719,39.95084
27.42400,2.28533,818.21941,-0.14109,4.88388,40.37320
27.92400,2.32701,826.99209,-0.14111,5.05058,40.80607
28.42400,2.36874,835.27155,-0.14112,5.21751,41.21460
28.92400,2.41029,843.24898,-0.14113,5.38372,41.60823
29.42400,2.45197,849.85429,-0.14113,5.55042,41.93415
29.92400,2.49364,857.92374,-0.14114,5.71711,42.33232
30.42400,2.53537,865.12426,-0.14114,5.88404,42.68761
30.92400,2.57699,871.75062,-0.14115,6.05050,43.01458
31.42400,2.61872,878.23924,-0.14114,6.21743,43.33474
31.92400,2.66033,882.98554,-0.14115,6.38388,43.56894
32.42400,2.70207,888.93613,-0.14115,6.55081,43.86256
32.92400,2.74368,893.91535,-0.14115,6.71727,44.10825
33.42400,2.78529,898.43823,-0.14114,6.88372,44.33142
33.92400,2.82703,901.72570,-0.14115,7.05066,44.49363
34.42400,2.86864,905.10361,-0.14115,7.21711,44.66031
34.92400,2.91043,908.13907,-0.14115,7.38428,44.81008
35.42400,2.95205,909.82253,-0.14115,7.55073,44.89315
35.92400,2.99366,912.15400,-0.14115,7.71719,45.00819
36.42400,3.03533,913.61990,-0.14115,7.88388,45.08052
36.92400,3.07701,914.89963,-0.14115,8.05057,45.14367
37.42400,3.11862,915.06755,-0.14115,8.21703,45.15195
37.92400,3.16029,915.43458,-0.14115,8.38372,45.17006
38.42400,3.20209,914.99891,-0.14115,8.55089,45.14857
38.92400,3.24370,914.48948,-0.14115,8.71735,45.12343
39.42400,3.28525,913.30288,-0.14115,8.88356,45.06488
39.92400,3.32699,912.07977,-0.14115,9.05049,45.00453
40.42400,3.36872,909.73629,-0.14115,9.21743,44.88889
40.92400,3.41033,908.22838,-0.14115,9.38388,44.81449
41.42400,3.45195,905.42184,-0.14115,9.55033,44.67601
41.92400,3.49368,903.43067,-0.14115,9.71727,44.57776
42.42400,3.53547,899.89323,-0.14116,9.88444,44.40321
42.92400,3.57703,897.59203,-0.14115,10.05065,44.28966
43.42400,3.61858,894.15992,-0.14115,10.21687,44.12031
43.92400,3.66031,890.77000,-0.14115,10.38380,43.95304
44.42400,3.70211,887.33984,-0.14116,10.55097,43.78379
44.92400,3.74360,884.22364,-0.14115,10.71695,43.63003
45.42400,3.78533,880.77923,-0.14115,10.88388,43.46007
45.92400,3.82695,876.76244,-0.14115,11.05033,43.26188
46.42400,3.86868,873.62016,-0.14115,11.21726,43.10683
46.92400,3.91035,869.88602,-0.14115,11.38396,42.92257
47.42400,3.95197,866.90830,-0.14115,11.55041,42.77564
47.92400,3.99370,863.16932,-0.14116,11.71734,42.59115
48.42400,4.03531,860.19840,-0.14116,11.88380,42.44456
48.92400,4.07693,857.04532,-0.14115,12.05025,42.28897
49.42400,4.11860,853.73251,-0.14116,12.21695,42.12551
49.92400,4.16033,850.28298,-0.14116,12.38388,41.95530
50.42400,4.20201,846.86158,-0.14115,12.55057,41.78648
50.92400,4.24368,843.08321,-0.14116,12.71726,41.60005
51.42400,4.28529,840.04942,-0.14116,12.88372,41.45035
51.92400,4.32697,836.68279,-0.14116,13.05041,41.28423
52.42400,4.36864,833.44914,-0.14115,13.21710,41.12468
52.92400,4.41031,830.17526,-0.14115,13.38380,40.96313
53.42400,4.45199,826.14217,-0.14116,13.55049,40.76413
53.92400,4.49366,822.65325,-0.14115,13.71718,40.59198
54.42400,4.53533,818.77252,-0.14115,13.88388,40.40049
54.92400,4.57701,815.14195,-0.14116,14.05057,40.22135
55.42400,4.61862,810.55872,-0.14115,14.21702,39.99520
55.92400,4.66041,805.79557,-0.14115,14.38419,39.76017
56.42400,4.70203,801.14361,-0.14116,14.55065,39.53063
56.92400,4.74358,795.51945,-0.14115,14.71687,39.25312
57.42400,4.78525,789.71107,-0.14116,14.88356,38.96652
57.92400,4.82698,783.22608,-0.14116,15.05049,38.64653
58.42400,4.86872,776.60242,-0.14116,15.21742,38.31970
58.92400,4.91033,769.24386,-0.14116,15.38387,37.95661
59.42400,4.95200,761.42168,-0.14115,15.55057,37.57064
59.92400,4.99368,753.19074,-0.14115,15.71726,37.16451
60.42400,5.03535,745.15021,-0.14116,15.88396,36.76777
60.92400,5.07696,736.23909,-0.14115,16.05041,36.32806
61.42400,5.11864,727.66514,-0.14115,16.21710,35.90500
61.92400,5.16037,718.46433,-0.14116,16.38403,35.45101
62.42400,5.20192,709.42072,-0.14116,16.55025,35.00477
62.92400,5.24366,700.64329,-0.14115,16.71718,34.57167
63.42400,5.28527,692.72094,-0.14116,16.88363,34.18076
63.92400,5.32700,686.00923,-0.14116,17.05057,33.84959
64.42400,5.36868,679.94916,-0.14116,17.21726,33.55056
64.92400,5.41035,674.55233,-0.14116,17.38396,33.28427
65.42400,5.45196,669.74987,-0.14116,17.55041,33.04730
65.92400,5.49370,665.56702,-0.14115,17.71734,32.84091
66.42400,5.53531,662.89604,-0.14115,17.88379,32.70912
66.92400,5.57710,659.10271,-0.14116,18.05097,32.52194
67.42400,5.61866,657.06382,-0.14116,18.21718,32.42134
67.92400,5.66039,655.11339,-0.14116,18.38411,32.32510
68.42400,5.70194,654.52438,-0.14116,18.55033,32.29604
68.92400,5.74368,652.88143,-0.14116,18.71726,32.21497
69.42400,5.78535,652.00832,-0.14116,18.88395,32.17189
69.92400,5.82708,651.80827,-0.14115,19.05088,32.16201
70.42400,5.86864,651.75542,-0.14116,19.21710,32.15941
70.92400,5.91031,651.24799,-0.14116,19.38379,32.13437
71.42400,5.95210,651.63705,-0.14115,19.55096,32.15357
71.92400,5.99372,651.50983,-0.14116,19.71742,32.14729
72.42400,6.03533,651.55863,-0.14115,19.88387,32.14970
72.92400,6.07694,651.54298,-0.14115,20.05032,32.14893
73.42400,6.11868,651.37092,-0.14115,20.21726,32.14043
73.92400,6.16029,652.02606,-0.14116,20.38371,32.17276
74.42400,6.20208,651.82880,-0.14116,20.55088,32.16303
74.92400,6.24358,652.75882,-0.14116,20.71686,32.20892
75.42400,6.28537,653.12088,-0.14116,20.88403,32.22678
75.92400,6.32692,653.64363,-0.14116,21.05024,32.25258
76.42400,6.36854,653.96726,-0.14116,21.21670,32.26855
76.92400,6.41033,654.21332,-0.14116,21.38387,32.28069
77.42400,6.45206,654.53714,-0.14116,21.55080,32.29667
77.92400,6.49368,654.31190,-0.14115,21.71726,32.28555
78.42400,6.53529,655.28164,-0.14116,21.88371,32.33340
78.92400,6.57696,655.69868,-0.14116,22.05040,32.35398
79.42400,6.61870,655.81165,-0.14115,22.21733,32.35955
79.92400,6.66031,656.27913,-0.14115,22.38379,32.38262
80.42400,6.70192,656.03764,-0.14116,22.55024,32.37070
80.92400,6.74366,656.76346,-0.14116,22.71718,32.40652
81.42400,6.78533,657.45059,-0.14116,22.88387,32.44042
81.92400,6.82700,657.20319,-0.14116,23.05056,32.42822
82.42400,6.86862,657.68636,-0.14115,23.21702,32.45206
82.92400,6.91041,658.21675,-0.14115,23.38419,32.47823
83.42400,6.95202,658.49633,-0.14115,23.55064,32.49202
83.92400,6.99364,658.67198,-0.14115,23.71709,32.50069
84.42400,7.03525,658.36688,-0.14116,23.88355,32.48563
84.92400,7.07704,658.25582,-0.14116,24.05072,32.48016
85.42400,7.11872,658.93130,-0.14115,24.21741,32.51348
85.92400,7.16033,658.91962,-0.14115,24.38387,32.51291
86.42400,7.20194,659.17834,-0.14115,24.55032,32.52568
86.92400,7.24368,659.09992,-0.14115,24.71725,32.52180
87.42400,7.28541,659.53094,-0.14115,24.88419,32.54307
87.92400,7.32702,659.31417,-0.14115,25.05064,32.53238
88.42400,7.36870,659.44088,-0.14116,25.21733,32.53863
88.92400,7.41037,659.29648,-0.14116,25.38403,32.53151
89.42400,7.45204,659.88270,-0.14116,25.55072,32.56043
89.92400,7.49372,659.52232,-0.14116,25.71741,32.54265
90.42400,7.53539,659.81764,-0.14115,25.88411,32.55722
90.92400,7.57706,660.32875,-0.14116,26.05080,32.58244
91.42400,7.61868,659.88353,-0.14115,26.21725,32.56047
91.92400,7.66029,660.21290,-0.14115,26.38371,32.57672
92.42400,7.70202,660.64545,-0.14116,26.55064,32.59806
92.92400,7.74376,660.18803,-0.14115,26.71757,32.57550
93.42400,7.78531,659.82454,-0.14116,26.88379,32.55756
93.92400,7.82704,659.45177,-0.14115,27.05072,32.53917
94.42400,7.86866,660.17099,-0.14115,27.21717,32.57465
94.92400,7.91033,660.29564,-0.14116,27.38387,32.58081
95.42400,7.95194,660.17346,-0.14116,27.55032,32.57478
95.92400,7.99374,659.57466,-0.14115,27.71749,32.54523
96.42400,8.03535,660.25071,-0.14115,27.88394,32.57859
96.92400,8.07702,659.99115,-0.14116,28.05064,32.56578
97.42400,8.11864,659.46099,-0.14115,28.21709,32.53962
97.92400,8.16037,660.22114,-0.14115,28.38402,32.57713
98.42400,8.20192,659.79189,-0.14115,28.55024,32.55595
98.92400,8.24372,659.88130,-0.14116,28.71741,32.56036
99.42400,8.28527,660.21066,-0.14116,28.88362,32.57661
99.92400,8.32694,660.01052,-0.14115,29.05032,32.56674
100.42400,8.36874,660.16628,-0.14115,29.21749,32.57442
100.92400,8.41035,659.88614,-0.14115,29.38394,32.56060
101.42400,8.45202,660.12847,-0.14115,29.55064,32.57256
101.92400,8.49364,659.72810,-0.14115,29.71709,32.55280
102.42400,8.53525,659.66928,-0.14115,29.88354,32.54990
102.92400,8.57698,659.76488,-0.14115,30.05048,32.55462
103.42400,8.61872,659.82635,-0.14115,30.21741,32.55765
103.92400,8.66033,659.89112,-0.14115,30.38386,32.56084
104.42400,8.70206,660.10957,-0.14115,30.55079,32.57162
104.92400,8.74361,659.56563,-0.14115,30.71701,32.54478
105.42400,8.78535,660.19474,-0.14115,30.88394,32.57583
105.92400,8.82696,660.11860,-0.14115,31.05040,32.57207
106.42400,8.86875,660.74734,-0.14115,31.21757,32.60309
106.92400,8.91031,660.55194,-0.14116,31.38379,32.59345
107.42400,8.95192,660.34780,-0.14115,31.55024,32.58338
107.92400,8.99360,661.31460,-0.14115,31.71693,32.63108
108.42400,9.03539,661.32178,-0.14116,31.88410,32.63144
108.92400,9.07688,661.16378,-0.14115,32.05008,32.62364
109.42400,9.11861,661.67242,-0.14115,32.21701,32.64874
109.92400,9.16029,661.50464,-0.14115,32.38370,32.64046
110.42400,9.20196,661.46357,-0.14115,32.55040,32.63844
110.92400,9.24369,662.23470,-0.14115,32.71733,32.67648
111.42400,9.28531,661.62236,-0.14116,32.88378,32.64627
111.92400,9.32710,661.03390,-0.14116,33.05095,32.61723
112.42400,9.36865,661.90227,-0.14115,33.21717,32.66008
112.92400,9.41027,661.95475,-0.14116,33.38362,32.66267
113.42400,9.45194,661.78809,-0.14115,33.55032,32.65445
113.92400,9.49373,661.59260,-0.14115,33.71749,32.64480
114.42400,9.53535,661.40047,-0.14116,33.88394,32.63532
114.92400,9.57690,661.94632,-0.14115,34.05015,32.66225
115.42400,9.61863,662.12718,-0.14115,34.21709,32.67118
115.92400,9.66031,661.80909,-0.14116,34.38378,32.65548
116.42400,9.70198,661.41589,-0.14115,34.55047,32.63608
116.92400,9.74365,661.89440,-0.14115,34.71717,32.65969
117.42400,9.78539,662.16546,-0.14115,34.88410,32.67307
117.92400,9.82694,661.96602,-0.14115,35.05031,32.66323
118.42400,9.86867,661.61002,-0.14115,35.21724,32.64566
118.92400,9.91029,662.19782,-0.14115,35.38370,32.67466
119.42400,9.95196,661.95102,-0.14115,35.55039,32.66249
119.92400,9.99375,661.80723,-0.14115,35.71756,32.65539
120.42400,10.03537,662.21259,-0.14115,35.88401,32.67539
120.92400,10.07692,662.16053,-0.14115,36.05023,32.67282
121.42400,10.11865,662.33231,-0.14115,36.21716,32.68130
121.92400,10.16039,662.45105,-0.14115,36.38409,32.68716
122.42400,10.20200,662.18874,-0.14115,36.55055,32.67422
122.92400,10.24361,662.46577,-0.14115,36.71700,32.68789
123.42400,10.28529,662.32011,-0.14115,36.88370,32.68070
123.92400,10.32696,662.48029,-0.14115,37.05039,32.68860
124.42400,10.36863,661.95130,-0.14115,37.21709,32.66250
124.92400,10.41043,662.16332,-0.14115,37.38426,32.67296
125.42400,10.45192,662.61338,-0.14115,37.55023,32.69517
125.92400,10.49371,662.51373,-0.14115,37.71740,32.69025
126.42400,10.53533,662.52574,-0.14115,37.88386,32.69085
126.92400,10.57700,662.16635,-0.14115,38.05055,32.67311
127.42400,10.61867,662.80831,-0.14115,38.21724,32.70479
127.92400,10.66041,662.65818,-0.14115,38.38417,32.69738
128.42401,10.70196,662.80188,-0.14115,38.55039,32.70447
128.92401,10.74363,662.56500,-0.14115,38.71708,32.69278
129.42401,10.78531,662.50679,-0.14115,38.88378,32.68991
129.92401,10.82710,661.86753,-0.14115,39.05095,32.65837
130.42401,10.86865,662.20788,-0.14115,39.21716,32.67516
130.92401,10.91033,661.59507,-0.14115,39.38386,32.64492
131.42402,10.95200,661.29579,-0.14115,39.55055,32.63016
131.92402,10.99373,661.20974,-0.14115,39.71748,32.62591
132.42402,11.03535,661.13072,-0.14115,39.88393,32.62201
132.92402,11.07702,660.75823,-0.14115,40.05063,32.60363
133.42402,11.11875,660.87809,-0.14116,40.21756,32.60955
133.92402,11.16031,660.83791,-0.14115,40.38377,32.60756
134.42402,11.20198,660.42854,-0.14115,40.55047,32.58736
134.92402,11.24359,661.70366,-0.14115,40.71692,32.65028
135.42402,11.28551,660.92936,-0.14115,40.88457,32.61208
135.92402,11.32700,661.13672,-0.14115,41.05054,32.62231
136.42402,11.36855,661.55475,-0.14115,41.21676,32.64293
136.92402,11.41023,661.19120,-0.14115,41.38345,32.62500
137.42402,11.45202,661.45496,-0.14115,41.55062,32.63801
137.92402,11.49369,661.39954,-0.14115,41.71732,32.63528
138.42402,11.53531,661.40662,-0.14115,41.88378,32.63562
138.92402,11.57698,660.39474,-0.14115,42.05046,32.58570
139.42402,11.61865,661.08126,-0.14115,42.21716,32.61957
139.92402,11.66033,660.56047,-0.14115,42.38385,32.59387
140.42402,11.70200,660.74328,-0.14115,42.55055,32.60289
140.92402,11.74367,660.46524,-0.14115,42.71724,32.58917
141.42402,11.78535,660.29234,-0.14115,42.88393,32.58064
141.92402,11.82702,660.71888,-0.14115,43.05063,32.60169
142.42402,11.86863,660.97188,-0.14115,43.21707,32.61417
142.92402,11.91031,660.47013,-0.14115,43.38377,32.58942
143.42402,11.95210,660.17914,-0.14116,43.55094,32.57506
143.92402,11.99365,660.06072,-0.14115,43.71715,32.56921
144.42402,12.03527,660.23790,-0.14116,43.88361,32.57796
144.92402,12.07694,660.44601,-0.14115,44.05031,32.58823
145.42402,12.11873,660.13532,-0.14115,44.21748,32.57290
145.92402,12.16035,660.44400,-0.14115,44.38393,32.58813
146.42402,12.20202,660.12582,-0.14115,44.55062,32.57243
146.92402,12.24363,659.35142,-0.14115,44.71708,32.53421
147.42402,12.28536,659.64651,-0.14115,44.88401,32.54877
147.92402,12.32692,660.04959,-0.14115,45.05022,32.56866
148.42402,12.36871,659.28819,-0.14115,45.21740,32.53109
148.92402,12.41039,659.54966,-0.14115,45.38409,32.54399
149.42402,12.45206,659.81816,-0.14115,45.55078,32.55725
149.92402,12.49361,660.16130,-0.14115,45.71700,32.57418
150.42402,12.53535,659.67487,-0.14115,45.88393,32.55017
150.92402,12.57708,659.83408,-0.14115,46.05086,32.55803
151.42402,12.61869,659.76260,-0.14115,46.21731,32.55450
151.92402,12.66031,660.16582,-0.14115,46.38377,32.57440
152.42402,12.70198,660.31711,-0.14115,46.55046,32.58186
152.92402,12.74365,660.00274,-0.14115,46.71715,32.56635
153.42402,12.78533,660.56810,-0.14115,46.88385,32.59425
153.92402,12.82706,660.56447,-0.14115,47.05078,32.59407
154.42402,12.86861,660.69299,-0.14115,47.21699,32.60041
154.92402,12.91040,661.53011,-0.14115,47.38417,32.64172
155.42402,12.95196,661.37025,-0.14115,47.55038,32.63383
155.92402,12.99375,661.16941,-0.14115,47.71756,32.62392
156.42402,13.03536,661.52485,-0.14115,47.88401,32.64146
156.92402,13.07710,661.14683,-0.14115,48.05094,32.62281
157.42402,13.11865,661.68769,-0.14115,48.21716,32.64949
157.92402,13.16032,661.19675,-0.14115,48.38385,32.62527
158.42402,13.20194,661.69994,-0.14115,48.55030,32.65010
158.92402,13.24367,661.23535,-0.14115,48.71723,32.62717
159.42402,13.28522,661.49523,-0.14115,48.88345,32.64000
159.92402,13.32696,660.82231,-0.14115,49.05038,32.60679
160.42402,13.36863,660.43246,-0.14115,49.21708,32.58755
160.92402,13.41030,660.73197,-0.14115,49.38377,32.60234
161.42402,13.45198,660.47888,-0.14115,49.55046,32.58985
161.92402,13.49359,660.20242,-0.14115,49.71692,32.57621
162.42402,13.53532,660.29425,-0.14115,49.88385,32.58074
162.92402,13.57706,660.23017,-0.14115,50.05078,32.57758
163.42402,13.61867,660.50170,-0.14115,50.21723,32.59097
163.92402,13.66028,660.72838,-0.14115,50.38369,32.60216
164.42402,13.70208,659.91865,-0.14115,50.55086,32.56220
164.92402,13.74363,660.61220,-0.14115,50.71707,32.59642
165.42402,13.78530,660.53392,-0.14115,50.88376,32.59256
165.92402,13.82692,661.02273,-0.14115,51.05022,32.61668
166.42402,13.86871,661.11581,-0.14115,51.21740,32.62128
166.92402,13.91032,661.32145,-0.14115,51.38384,32.63142
167.42402,13.95206,661.71912,-0.14115,51.55078,32.65104
167.92402,13.99367,661.20201,-0.14115,51.71723,32.62553
168.42402,14.03534,661.77989,-0.14115,51.88392,32.65404
168.92402,14.07702,661.34445,-0.14115,52.05062,32.63256
169.42402,14.11863,661.61938,-0.14115,52.21707,32.64612
169.92402,14.16030,661.91070,-0.14115,52.38376,32.66050
170.42402,14.20204,661.66441,-0.14115,52.55070,32.64835
170.92402,14.24365,662.47857,-0.14115,52.71716,32.68852
171.42402,14.28526,662.39946,-0.14115,52.88360,32.68461
171.92402,14.32700,662.22046,-0.14115,53.05054,32.67578
172.42402,14.36867,662.51415,-0.14115,53.21723,32.69027
172.92402,14.41034,662.39904,-0.14115,53.38392,32.68459
173.42402,14.45190,662.99383,-0.14115,53.55014,32.71394
173.92402,14.49363,662.80155,-0.14115,53.71707,32.70445
174.42402,14.53536,663.12547,-0.14115,53.88400,32.72044
174.92402,14.57698,663.37404,-0.14115,54.05046,32.73270
175.42402,14.61865,662.98787,-0.14115,54.21715,32.71365
175.92402,14.66032,662.87257,-0.14115,54.38384,32.70796
176.42402,14.70200,662.75415,-0.14115,54.55053,32.70211
176.92402,14.74361,663.01581,-0.14115,54.71699,32.71503
177.42402,14.78534,662.86065,-0.14115,54.88392,32.70737
177.92402,14.82702,663.43793,-0.14115,55.05062,32.73586
178.42402,14.86875,663.47937,-0.14115,55.21755,32.73790
178.92402,14.91024,663.52249,-0.14115,55.38353,32.74003
179.42402,14.95204,663.74815,-0.14115,55.55069,32.75116
179.92402,14.99365,663.37665,-0.14115,55.71715,32.73283
180.42402,15.03538,663.90964,-0.14115,55.88408,32.75913
180.92402,15.07700,663.73167,-0.14115,56.05053,32.75035
181.42402,15.11861,664.04343,-0.14115,56.21699,32.76573
181.92402,15.16022,664.45991,-0.14115,56.38344,32.78628
182.42402,15.20202,664.87109,-0.14115,56.55061,32.80657
182.92402,15.24369,665.00995,-0.14115,56.71731,32.81342
183.42402,15.28536,664.86415,-0.14115,56.88400,32.80623
183.92402,15.32698,664.35901,-0.14115,57.05045,32.78130
184.42402,15.36865,664.50359,-0.14115,57.21715,32.78844
184.92402,15.41038,665.04995,-0.14115,57.38408,32.81540
185.42402,15.45194,664.42369,-0.14115,57.55029,32.78450
185.92402,15.49373,664.70336,-0.14115,57.71747,32.79829
186.42402,15.53534,664.09023,-0.14115,57.88392,32.76804
186.92402,15.57702,664.32394,-0.14115,58.05061,32.77957
187.42402,15.61863,664.24608,-0.14115,58.21707,32.77573
187.92402,15.66042,665.01857,-0.14115,58.38423,32.81385
188.42402,15.70198,664.10750,-0.14115,58.55045,32.76889
188.92402,15.74365,665.06476,-0.14115,58.71714,32.81613
189.42402,15.78526,664.78755,-0.14115,58.88360,32.80245
189.92402,15.82699,664.31565,-0.14115,59.05053,32.77916
190.42402,15.86873,664.82411,-0.14115,59.21746,32.80425
190.92402,15.91034,664.38974,-0.14115,59.38392,32.78282
191.42402,15.95207,664.89498,-0.14115,59.55085,32.80775
191.92402,15.99369,665.44292,-0.14115,59.71730,32.83479
192.42402,16.03530,665.48325,-0.14115,59.88376,32.83678
192.92402,16.07697,665.20781,-0.14115,60.05045,32.82318
193.42402,16.11871,665.20632,-0.14115,60.21739,32.82311
193.92402,16.16032,665.06672,-0.14115,60.38384,32.81622
194.42402,16.20200,665.14327,-0.14115,60.55053,32.82000
194.92402,16.24361,664.91188,-0.14115,60.71699,32.80858
195.42402,16.28528,665.29368,-0.14115,60.88368,32.82742
195.92402,16.32695,665.84833,-0.14115,61.05037,32.85479
196.42402,16.36863,665.54095,-0.14115,61.21706,32.83962
196.92402,16.41024,666.20870,-0.14115,61.38352,32.87257
197.42402,16.45198,666.30249,-0.14115,61.55045,32.87720
197.92402,16.49371,666.73784,-0.14115,61.71738,32.89868
198.42402,16.53526,666.60778,-0.14115,61.88360,32.89227
198.92402,16.57699,666.20093,-0.14115,62.05053,32.87219
199.42402,16.61873,666.12870,-0.14115,62.21746,32.86863
199.92402,16.66034,666.44042,-0.14115,62.38392,32.88401
200.42402,16.70190,665.91320,-0.14115,62.55013,32.85799
200.92402,16.74363,665.79231,-0.14115,62.71706,32.85203
201.42402,16.78542,666.49760,-0.14115,62.88424,32.88683
201.92402,16.82703,665.29200,-0.14115,63.05068,32.82734
202.42402,16.86859,665.65643,-0.14115,63.21690,32.84532
202.92402,16.91032,665.12804,-0.14115,63.38384,32.81925
203.42402,16.95205,664.69344,-0.14115,63.55076,32.79781
203.92402,16.99367,664.47528,-0.14115,63.71722,32.78704
204.42402,17.03534,664.33069,-0.14115,63.88391,32.77991
204.92402,17.07695,664.27514,-0.14115,64.05036,32.77716
205.42402,17.11869,663.72873,-0.14115,64.21729,32.75020
205.92402,17.16036,664.58932,-0.14115,64.38400,32.79267
206.42402,17.20197,664.20031,-0.14115,64.55045,32.77347
206.92402,17.24371,663.88259,-0.14115,64.71738,32.75780
207.42402,17.28538,663.99653,-0.14115,64.88407,32.76342
207.92402,17.32699,664.66304,-0.14115,65.05052,32.79631
208.42402,17.36867,664.09553,-0.14115,65.21721,32.76830
208.92402,17.41034,664.27449,-0.14115,65.38392,32.77713
209.42402,17.45207,664.08580,-0.14115,65.55085,32.76782
209.92402,17.49357,663.89469,-0.14115,65.71682,32.75839
210.42402,17.53536,663.64529,-0.14115,65.88399,32.74609
210.92402,17.57697,663.80431,-0.14115,66.05045,32.75393
211.42402,17.61871,663.33744,-0.14115,66.21737,32.73090
211.92402,17.66026,663.20878,-0.14115,66.38359,32.72455
212.42402,17.70194,663.32058,-0.14114,66.55029,32.73006
212.92402,17.74373,663.47350,-0.14115,66.71746,32.73761
213.42402,17.78540,663.54237,-0.14115,66.88415,32.74101
213.92402,17.82701,663.28733,-0.14115,67.05060,32.72842
214.42402,17.86863,663.40286,-0.14114,67.21706,32.73412
214.92402,17.91042,663.08049,-0.14115,67.38424,32.71822
215.42402,17.95197,663.64272,-0.14114,67.55045,32.74596
215.92402,17.99365,662.96142,-0.14115,67.71714,32.71234
216.42402,18.03526,662.95504,-0.14115,67.88359,32.71203
216.92402,18.07705,663.20435,-0.14115,68.05077,32.72433
217.42402,18.11867,662.36495,-0.14115,68.21721,32.68291
217.92402,18.16034,662.21952,-0.14115,68.38391,32.67574
218.42402,18.20195,662.28281,-0.14115,68.55036,32.67886
218.92402,18.24369,663.08747,-0.14115,68.71729,32.71856
219.42402,18.28530,662.64519,-0.14115,68.88375,32.69674
219.92402,18.32697,662.46591,-0.14115,69.05044,32.68789
220.42402,18.36865,662.10730,-0.14115,69.21713,32.67020
220.92402,18.41038,661.64909,-0.14115,69.38406,32.64759
221.42402,18.45199,662.89762,-0.14115,69.55053,32.70919
221.92402,18.49361,662.84547,-0.14115,69.71698,32.70662
222.42402,18.53528,662.36220,-0.14115,69.88367,32.68278
222.92402,18.57695,662.24346,-0.14115,70.05036,32.67692
223.42402,18.61863,663.02228,-0.14115,70.21706,32.71535
223.92402,18.66024,663.43816,-0.14115,70.38351,32.73587
224.42402,18.70197,662.96058,-0.14115,70.55044,32.71230
224.92402,18.74365,663.16165,-0.14115,70.71714,32.72222
225.42402,18.78538,662.71513,-0.14115,70.88407,32.70019
225.92402,18.82699,662.94898,-0.14115,71.05052,32.71173
226.42402,18.86867,663.08039,-0.14115,71.21722,32.71821
226.92402,18.91034,662.95229,-0.14115,71.38391,32.71189
227.42402,18.95195,662.74186,-0.14115,71.55036,32.70151
227.92402,18.99363,662.07922,-0.14115,71.71706,32.66881
228.42402,19.03530,663.25050,-0.14115,71.88375,32.72661
228.92402,19.07703,662.78116,-0.14115,72.05068,32.70345
229.42402,19.11865,662.61855,-0.14115,72.21713,32.69542
229.92402,19.16026,662.45538,-0.14115,72.38359,32.68737
230.42402,19.20205,662.43676,-0.14115,72.55077,32.68645
230.92402,19.24373,662.94959,-0.14115,72.71745,32.71176
231.42402,19.28528,662.55918,-0.14115,72.88367,32.69249
231.92402,19.32695,663.43648,-0.14115,73.05036,32.73578
232.42402,19.36869,663.05478,-0.14115,73.21730,32.71695
232.92402,19.41036,662.70395,-0.14115,73.38398,32.69964
233.42402,19.45197,662.89706,-0.14115,73.55044,32.70917
233.92402,19.49359,663.55281,-0.14115,73.71689,32.74152
234.42402,19.53538,663.11234,-0.14115,73.88406,32.71979
234.92402,19.57699,663.25357,-0.14115,74.05052,32.72676
235.42402,19.61861,662.94065,-0.14115,74.21697,32.71132
235.92402,19.66034,663.87961,-0.14115,74.38390,32.75765
236.42402,19.70207,663.10517,-0.14115,74.55084,32.71944
236.92402,19.74369,662.87057,-0.14115,74.71730,32.70786
237.42402,19.78524,663.23308,-0.14114,74.88351,32.72575
237.92402,19.82697,663.05720,-0.14115,75.05044,32.71707
238.42402,19.86876,662.37729,-0.14115,75.21760,32.68352
238.92402,19.91026,662.69184,-0.14115,75.38359,32.69904
239.42402,19.95199,662.32597,-0.14115,75.55051,32.68099
239.92402,19.99361,662.31936,-0.14115,75.71697,32.68066
240.42402,20.03546,662.55722,-0.14115,75.88438,32.69240
240.92402,20.07695,662.01529,-0.14115,76.05035,32.66566
241.42402,20.11857,662.94707,-0.14115,76.21681,32.71164
241.92402,20.16036,662.09882,-0.14115,76.38398,32.66978
242.42402,20.20203,662.70013,-0.14115,76.55067,32.69945
242.92402,20.24364,662.26623,-0.14115,76.71713,32.67804
243.42402,20.28532,662.75215,-0.14115,76.88382,32.70201
243.92402,20.32705,662.93054,-0.14115,77.05075,32.71082
244.42402,20.36866,663.40561,-0.14115,77.21721,32.73426
244.92402,20.41034,663.38135,-0.14115,77.38390,32.73306
245.42402,20.45201,663.69153,-0.14115,77.55060,32.74837
245.92402,20.49368,663.13143,-0.14115,77.71728,32.72073
246.42402,20.53530,664.18694,-0.14115,77.88374,32.77281
246.92402,20.57703,664.72837,-0.14115,78.05068,32.79953
247.42402,20.61859,664.57628,-0.14115,78.21689,32.79202
247.92402,20.66044,664.13977,-0.14115,78.38430,32.77048
248.42402,20.70199,664.54438,-0.14115,78.55051,32.79045
248.92402,20.74372,664.72557,-0.14115,78.71745,32.79939
249.42402,20.78528,664.34569,-0.14115,78.88366,32.78065
249.92402,20.82701,664.30061,-0.14115,79.05059,32.77842
250.42402,20.86862,664.04059,-0.14115,79.21705,32.76559
250.92402,20.91030,664.41842,-0.14115,79.38374,32.78424
251.42402,20.95197,664.65847,-0.14115,79.55043,32.79608
251.92402,20.99364,664.04985,-0.14115,79.71712,32.76605
252.42402,21.03532,664.01977,-0.14115,79.88383,32.76456
252.92402,21.07693,663.66084,-0.14115,80.05027,32.74685
253.42402,21.11872,663.94219,-0.14115,80.21744,32.76074
253.92402,21.16040,663.37851,-0.14115,80.38414,32.73292
254.42402,21.20201,663.09427,-0.14115,80.55059,32.71890
254.92402,21.24362,664.32161,-0.14115,80.71705,32.77946
255.42402,21.28530,664.60641,-0.14115,80.88374,32.79351
255.92402,21.32703,664.32543,-0.14115,81.05067,32.77965
256.42402,21.36871,664.41866,-0.14115,81.21737,32.78425
256.92402,21.41026,664.56851,-0.14115,81.38358,32.79164
257.42402,21.45199,664.83463,-0.14115,81.55051,32.80477
257.92402,21.49366,664.48003,-0.14115,81.71720,32.78727
258.42402,21.53528,665.36260,-0.14115,81.88366,32.83082
258.92402,21.57701,665.03873,-0.14115,82.05060,32.81484
259.42402,21.61868,664.93070,-0.14115,82.21728,32.80951
259.92402,21.66042,665.01866,-0.14115,82.38422,32.81385
260.42402,21.70191,664.57097,-0.14115,82.55019,32.79176
260.92402,21.74370,664.49875,-0.14115,82.71736,32.78820
261.42402,21.78532,664.82644,-0.14115,82.88381,32.80437
261.92402,21.82699,664.50262,-0.14115,83.05051,32.78839
262.42400,21.86866,664.31714,-0.14115,83.21721,32.77924
262.92400,21.91028,664.45465,-0.14115,83.38366,32.78602
263.42400,21.95207,663.78871,-0.14115,83.55083,32.75316
263.92400,21.99374,664.66471,-0.14115,83.71753,32.79639
264.42400,22.03530,664.22983,-0.14114,83.88374,32.77493
264.92400,22.07697,664.50783,-0.14115,84.05043,32.78865
265.42400,22.11876,665.08357,-0.14115,84.21761,32.81705
265.92400,22.16032,664.64664,-0.14115,84.38382,32.79550
266.42400,22.20199,664.74248,-0.14115,84.55051,32.80022
266.92400,22.24366,664.23113,-0.14114,84.71721,32.77499
267.42400,22.28540,664.42308,-0.14115,84.88414,32.78447
267.92400,22.32695,664.97768,-0.14115,85.05035,32.81183
268.42400,22.36868,664.73661,-0.14114,85.21729,32.79993
268.92400,22.41030,665.12153,-0.14115,85.38374,32.81893
269.42400,22.45209,664.32157,-0.14115,85.55090,32.77946
269.92400,22.49364,665.07417,-0.14115,85.71712,32.81659
270.42400,22.53532,664.63002,-0.14115,85.88382,32.79468
270.92400,22.57699,664.59542,-0.14115,86.05052,32.79297
271.42400,22.61878,664.02201,-0.14114,86.21768,32.76468
271.92400,22.66034,664.12408,-0.14115,86.38390,32.76971
272.42400,22.70201,664.37628,-0.14115,86.55059,32.78215
272.92400,22.74362,664.25512,-0.14115,86.71705,32.77618
273.42400,22.78536,664.60022,-0.14114,86.88397,32.79321
273.92400,22.82697,663.88831,-0.14115,87.05043,32.75808
274.42400,22.86864,663.81632,-0.14115,87.21713,32.75452
274.92400,22.91032,663.85269,-0.14114,87.38381,32.75632
275.42400,22.95199,663.37073,-0.14115,87.55051,32.73254
275.92400,22.99366,663.35215,-0.14115,87.71720,32.73162
276.42400,23.03528,663.55523,-0.14115,87.88366,32.74164
276.92400,23.07701,663.17171,-0.14115,88.05059,32.72272
277.42400,23.11868,663.14437,-0.14115,88.21728,32.72137
277.92400,23.16030,663.16896,-0.14115,88.38374,32.72258
278.42400,23.20191,662.59480,-0.14115,88.55019,32.69425
278.92400,23.24370,663.50698,-0.14114,88.71736,32.73926
279.42400,23.28532,662.54586,-0.14115,88.88381,32.69184
279.92400,23.32693,662.07526,-0.14115,89.05027,32.66862
280.42400,23.36866,662.31694,-0.14115,89.21721,32.68054
280.92400,23.41034,662.80439,-0.14115,89.38389,32.70459
281.42400,23.45195,662.30809,-0.14115,89.55035,32.68011
281.92400,23.49362,662.83392,-0.14115,89.71704,32.70605
282.42400,23.53535,662.55382,-0.14114,89.88397,32.69223
282.92400,23.57697,662.69049,-0.14114,90.05042,32.69897
283.42400,23.61870,662.22502,-0.14115,90.21736,32.67601
283.92400,23.66032,662.45054,-0.14115,90.38381,32.68713
284.42400,23.70193,661.48718,-0.14115,90.55027,32.63960
284.92400,23.74366,661.74241,-0.14115,90.71720,32.65219
285.42400,23.78539,662.39838,-0.14115,90.88413,32.68456
285.92400,23.82695,662.15536,-0.14115,91.05034,32.67257
286.42400,23.86862,662.05035,-0.14114,91.21704,32.66739
286.92400,23.91030,662.26521,-0.14115,91.38373,32.67799
287.42400,23.95203,662.15615,-0.14115,91.55067,32.67261
287.92400,23.99370,662.86032,-0.14115,91.71735,32.70736
288.42400,24.03526,662.25841,-0.14115,91.88358,32.67765
288.92400,24.07699,662.40598,-0.14115,92.05050,32.68494
289.42400,24.11860,661.73812,-0.14115,92.21695,32.65198
289.92400,24.16034,662.24486,-0.14115,92.38389,32.67699
290.42400,24.20201,662.03722,-0.14115,92.55059,32.66674
290.92400,24.24374,661.84970,-0.14115,92.71752,32.65749
291.42400,24.28523,662.10087,-0.14114,92.88349,32.66988
291.92400,24.32703,662.53869,-0.14115,93.05066,32.69148
292.42400,24.36870,661.69258,-0.14115,93.21736,32.64973
292.92400,24.41037,662.13580,-0.14115,93.38405,32.67160
293.42400,24.45193,661.68834,-0.14115,93.55027,32.64952
293.92400,24.49360,661.90213,-0.14115,93.71696,32.66008
294.42400,24.53533,661.66576,-0.14115,93.88389,32.64841
294.92400,24.57701,661.29109,-0.14114,94.05057,32.62992
295.42400,24.61856,661.30282,-0.14115,94.21680,32.63050
295.92400,24.66029,660.92857,-0.14114,94.38373,32.61204
296.42400,24.70203,660.47106,-0.14115,94.55066,32.58946
296.92400,24.74364,660.39613,-0.14114,94.71712,32.58577
297.42400,24.78532,660.22966,-0.14115,94.88381,32.57755
297.92400,24.82699,660.50473,-0.14114,95.05050,32.59112
298.42400,24.86878,660.38389,-0.14115,95.21767,32.58516
298.92400,24.91034,660.97020,-0.14115,95.38389,32.61409
299.42400,24.95201,660.22486,-0.14115,95.55058,32.57731
299.92400,24.99362,660.72270,-0.14115,95.71704,32.60188
300.42400,25.03547,660.32778,-0.14115,95.88444,32.58239
300.92400,25.07697,660.41532,-0.14115,96.05042,32.58671
301.42400,25.11858,660.07297,-0.14114,96.21687,32.56982
301.92400,25.16031,660.28866,-0.14115,96.38381,32.58046
302.42400,25.20205,660.58906,-0.14115,96.55074,32.59528
302.92400,25.24360,660.55846,-0.14115,96.71695,32.59377
303.42400,25.28533,660.41485,-0.14115,96.88388,32.58669
303.92400,25.32707,660.27809,-0.14115,97.05081,32.57994
304.42400,25.36868,660.35688,-0.14115,97.21727,32.58383
304.92400,25.41029,660.57853,-0.14114,97.38373,32.59476
305.42400,25.45197,661.03642,-0.14115,97.55042,32.61736
305.92400,25.49370,661.30208,-0.14115,97.71735,32.63047
306.42400,25.53537,661.46180,-0.14115,97.88405,32.63835
306.92400,25.57699,661.13109,-0.14115,98.05049,32.62203
307.42400,25.61854,661.68401,-0.14115,98.21672,32.64931
307.92400,25.66040,661.65300,-0.14115,98.38413,32.64778
308.42400,25.70201,661.72965,-0.14115,98.55058,32.65156
308.92400,25.74362,661.51046,-0.14115,98.71703,32.64075
309.42400,25.78530,661.17714,-0.14115,98.88373,32.62430
309.92400,25.82703,660.99917,-0.14115,99.05066,32.61552
310.42400,25.86858,661.47265,-0.14115,99.21687,32.63888
310.92400,25.91031,660.61211,-0.14115,99.38380,32.59642
311.42400,25.95205,660.71134,-0.14115,99.55074,32.60132
311.92400,25.99366,661.04797,-0.14115,99.71719,32.61793
312.42400,26.03539,660.62054,-0.14115,99.88412,32.59684
312.92400,26.07695,660.62193,-0.14115,100.05034,32.59690
313.42400,26.11862,660.93067,-0.14115,100.21703,32.61214
313.92400,26.16035,661.21272,-0.14115,100.38396,32.62606
314.42400,26.20209,661.81794,-0.14115,100.55090,32.65592
314.92400,26.24364,662.02963,-0.14115,100.71712,32.66637
315.42400,26.28531,661.92676,-0.14115,100.88381,32.66129
315.92400,26.32699,662.45915,-0.14114,101.05050,32.68756
316.42400,26.36872,662.64141,-0.14115,101.21742,32.69655
316.92400,26.41033,661.80434,-0.14115,101.38389,32.65525
317.42400,26.45201,662.15335,-0.14115,101.55058,32.67247
317.92400,26.49362,662.14064,-0.14115,101.71703,32.67184
318.42400,26.53529,662.72034,-0.14115,101.88372,32.70045
318.92400,26.57703,662.84211,-0.14115,102.05065,32.70646
319.42400,26.61870,663.18098,-0.14115,102.21734,32.72318
319.92400,26.66043,663.07266,-0.14114,102.38428,32.71783
320.42400,26.70193,663.17646,-0.14115,102.55026,32.72295
320.92400,26.74360,663.61884,-0.14115,102.71695,32.74478
321.42400,26.78533,662.94735,-0.14115,102.88389,32.71165
321.92400,26.82713,663.17450,-0.14115,103.05105,32.72286
322.42400,26.86868,663.32775,-0.14115,103.21727,32.73042
322.92400,26.91035,663.48477,-0.14115,103.38396,32.73817
323.42400,26.95197,663.33013,-0.14115,103.55041,32.73054
323.92400,26.99370,662.79345,-0.14115,103.71735,32.70406
324.42400,27.03531,662.61222,-0.14114,103.88380,32.69511
324.92400,27.07699,662.59867,-0.14115,104.05049,32.69444
325.42400,27.11872,662.68486,-0.14114,104.21742,32.69870
325.92400,27.16033,662.60723,-0.14114,104.38387,32.69487
326.42400,27.20195,662.38460,-0.14115,104.55034,32.68388
326.92400,27.24368,662.55052,-0.14115,104.71728,32.69207
327.42400,27.28541,662.29752,-0.14115,104.88421,32.67958
327.92400,27.32703,662.21547,-0.14115,105.05065,32.67554
328.42400,27.36870,662.13193,-0.14114,105.21735,32.67141
328.92400,27.41025,662.19955,-0.14115,105.38356,32.67475
329.42400,27.45211,661.37924,-0.14115,105.55098,32.63427
329.92400,27.49366,662.58479,-0.14114,105.71719,32.69376
330.42400,27.53527,663.00854,-0.14114,105.88365,32.71467
330.92400,27.57695,662.44625,-0.14115,106.05034,32.68692
331.42400,27.61868,662.17859,-0.14114,106.21727,32.67372
331.92400,27.66029,662.95885,-0.14114,106.38372,32.71222
332.42400,27.70191,662.55056,-0.14115,106.55017,32.69207
332.92400,27.74364,662.65659,-0.14114,106.71711,32.69730
333.42400,27.78537,662.78931,-0.14114,106.88404,32.70385
333.92400,27.82699,662.54549,-0.14115,107.05050,32.69182
334.42400,27.86860,663.60161,-0.14115,107.21694,32.74393
334.92400,27.91039,664.27886,-0.14115,107.38412,32.77735
335.42400,27.95206,663.96305,-0.14115,107.55080,32.76176
335.92400,27.99362,664.68297,-0.14115,107.71703,32.79729
336.42400,28.03523,665.25573,-0.14115,107.88348,32.82555
336.92400,28.07703,664.90737,-0.14115,108.05066,32.80836
337.42400,28.11864,665.16139,-0.14115,108.21711,32.82090
337.92400,28.16031,664.83873,-0.14115,108.38380,32.80497
338.42400,28.20193,664.54019,-0.14115,108.55025,32.79025
338.92400,28.24366,664.43649,-0.14115,108.71718,32.78513
339.42400,28.28527,664.86625,-0.14115,108.88364,32.80633
339.92400,28.32700,664.54918,-0.14115,109.05057,32.79069
340.42400,28.36862,664.48771,-0.14115,109.21702,32.78765
340.92400,28.41029,663.90834,-0.14114,109.38373,32.75907
341.42400,28.45203,664.19691,-0.14114,109.55065,32.77330
341.92400,28.49358,664.14080,-0.14115,109.71687,32.77053
342.42400,28.53531,664.44180,-0.14115,109.88381,32.78539
342.92400,28.57699,663.74298,-0.14115,110.05049,32.75091
343.42400,28.61872,664.01707,-0.14115,110.21743,32.76443
343.92400,28.66027,663.80980,-0.14115,110.38364,32.75420
344.42400,28.70195,663.59113,-0.14115,110.55033,32.74342
344.92400,28.74362,664.16799,-0.14115,110.71702,32.77188
345.42400,28.78535,663.82298,-0.14115,110.88396,32.75486
345.92400,28.82697,664.11681,-0.14115,111.05042,32.76935
346.42400,28.86870,664.08059,-0.14115,111.21734,32.76757
346.92400,28.91031,663.74075,-0.14115,111.38380,32.75080
347.42400,28.95192,664.03039,-0.14115,111.55025,32.76509
347.92400,28.99366,663.46969,-0.14115,111.71718,32.73742
348.42400,29.03527,664.01139,-0.14115,111.88363,32.76415
348.92400,29.07701,663.86899,-0.14115,112.05057,32.75713
349.42400,29.11868,663.78796,-0.14115,112.21726,32.75313
349.92400,29.16035,663.99872,-0.14115,112.38396,32.76353
350.42400,29.20196,664.15607,-0.14115,112.55040,32.77129
350.92400,29.24376,664.32660,-0.14115,112.71758,32.77971
351.42400,29.28531,663.94270,-0.14115,112.88379,32.76076
351.92400,29.32698,664.00715,-0.14115,113.05048,32.76394
352.42400,29.36854,664.00729,-0.14115,113.21671,32.76395
352.92400,29.41039,663.60547,-0.14115,113.38412,32.74412
353.42400,29.45194,663.86559,-0.14115,113.55033,32.75696
353.92400,29.49368,664.24827,-0.14115,113.71726,32.77584
354.42400,29.53535,663.76012,-0.14115,113.88396,32.75175
354.92400,29.57697,664.18354,-0.14115,114.05041,32.77264
355.42400,29.61864,664.71519,-0.14115,114.21710,32.79888
355.92400,29.66031,664.87626,-0.14115,114.38379,32.80683
356.42400,29.70204,664.51603,-0.14115,114.55072,32.78905
356.92400,29.74366,664.30401,-0.14114,114.71719,32.77859
357.42400,29.78533,664.82555,-0.14115,114.88388,32.80433
357.92400,29.82700,665.19128,-0.14115,115.05057,32.82237
358.42400,29.86874,664.17926,-0.14115,115.21749,32.77243
358.92400,29.91035,664.29414,-0.14115,115.38396,32.77810
359.42400,29.95202,664.35803,-0.14114,115.55064,32.78125
359.92400,29.99364,664.63123,-0.14115,115.71710,32.79473
360.42400,30.03537,665.23612,-0.14114,115.88404,32.82458
360.92400,30.07699,664.95687,-0.14114,116.05049,32.81080
361.42400,30.11866,664.10643,-0.14115,116.21718,32.76884
361.92400,30.16033,664.57023,-0.14115,116.38387,32.79173
362.42400,30.20206,664.91282,-0.14114,116.55080,32.80863
362.92400,30.24368,664.50117,-0.14115,116.71726,32.78832
363.42400,30.28529,664.66639,-0.14115,116.88371,32.79647
363.92400,30.32696,664.22056,-0.14115,117.05041,32.77447
364.42400,30.36876,664.65554,-0.14115,117.21758,32.79594
364.92400,30.41037,664.41325,-0.14115,117.38403,32.78398
365.42400,30.45192,664.80790,-0.14115,117.55024,32.80345
365.92400,30.49366,665.12153,-0.14115,117.71718,32.81893
366.42400,30.53533,664.83840,-0.14115,117.88386,32.80496
366.92400,30.57706,665.40153,-0.14114,118.05080,32.83274
367.42400,30.61862,665.77322,-0.14115,118.21702,32.85109
367.92400,30.66029,665.72763,-0.14114,118.38372,32.84883
368.42400,30.70196,666.47553,-0.14114,118.55041,32.88574
368.92400,30.74364,665.82225,-0.14115,118.71710,32.85350
369.42400,30.78531,665.22975,-0.14114,118.88379,32.82427
369.92400,30.82704,666.09103,-0.14115,119.05073,32.86677
370.42400,30.86866,665.16418,-0.14115,119.21718,32.82103
370.92400,30.91027,665.48549,-0.14114,119.38363,32.83689
371.42400,30.95194,665.53666,-0.14114,119.55032,32.83941
371.92400,30.99374,665.29107,-0.14115,119.71749,32.82729
372.42400,31.03547,665.55981,-0.14115,119.88443,32.84055
372.92400,31.07696,664.85084,-0.14114,120.05041,32.80557
373.42400,31.11864,664.38233,-0.14115,120.21710,32.78246
373.92400,31.16037,664.93563,-0.14114,120.38403,32.80976
374.42400,31.20204,664.20631,-0.14114,120.55073,32.77377
374.92400,31.24360,664.21209,-0.14115,120.71694,32.77406
375.42400,31.28533,663.56631,-0.14114,120.88386,32.74219
375.92400,31.32700,663.12775,-0.14114,121.05056,32.72055
376.42400,31.36868,662.73571,-0.14115,121.21725,32.70121
376.92400,31.41035,662.80090,-0.14114,121.38394,32.70442
377.42400,31.45202,662.44900,-0.14114,121.55064,32.68706
377.92400,31.49375,662.02404,-0.14114,121.71756,32.66609
378.42400,31.53531,661.11879,-0.14114,121.88379,32.62142
378.92400,31.57698,661.31502,-0.14114,122.05048,32.63110
379.42400,31.61866,661.35265,-0.14114,122.21717,32.63296
379.92400,31.66045,661.02622,-0.14115,122.38435,32.61686
380.42400,31.70194,661.18175,-0.14115,122.55031,32.62453
380.92400,31.74368,661.27460,-0.14114,122.71725,32.62911
381.42400,31.78523,660.56037,-0.14115,122.88345,32.59387
381.92400,31.82702,660.98166,-0.14114,123.05064,32.61465
382.42400,31.86863,661.42562,-0.14114,123.21708,32.63656
382.92400,31.91037,662.24551,-0.14114,123.38402,32.67702
383.42400,31.95198,661.97342,-0.14114,123.55047,32.66359
383.92400,31.99371,662.88100,-0.14114,123.71740,32.70837
384.42400,32.03533,663.23858,-0.14114,123.88387,32.72602
384.92400,32.07700,663.49781,-0.14114,124.05056,32.73881
385.42400,32.11873,663.72170,-0.14114,124.21749,32.74986
385.92400,32.16035,663.47993,-0.14114,124.38395,32.73793
386.42400,32.20190,663.77358,-0.14113,124.55015,32.75241
386.92400,32.24364,664.02773,-0.14113,124.71709,32.76496
387.42400,32.28543,664.14513,-0.14114,124.88426,32.77075
387.92400,32.32698,664.61493,-0.14114,125.05047,32.79393
388.42400,32.36865,664.20548,-0.14114,125.21716,32.77373
388.92400,32.41027,664.48105,-0.14114,125.38362,32.78733
389.42400,32.45206,663.92720,-0.14114,125.55081,32.76000
389.92400,32.49367,664.10908,-0.14114,125.71725,32.76897
390.42400,32.53535,663.86391,-0.14114,125.88395,32.75687
390.92400,32.57690,664.64855,-0.14114,126.05015,32.79559
391.42400,32.61870,664.34257,-0.14114,126.21733,32.78049
391.92400,32.66031,664.44762,-0.14114,126.38378,32.78568
392.42400,32.70198,664.18797,-0.14114,126.55047,32.77287
392.92400,32.74360,664.14122,-0.14114,126.71692,32.77056
393.42400,32.78539,663.98005,-0.14114,126.88409,32.76260
393.92400,32.82700,663.85218,-0.14114,127.05055,32.75629
394.42400,32.86855,663.86955,-0.14114,127.21676,32.75715
394.92400,32.91035,663.58238,-0.14114,127.38395,32.74298
395.42400,32.95202,663.13930,-0.14114,127.55064,32.72112
395.92400,32.99375,663.53674,-0.14114,127.71757,32.74073
396.42400,33.03525,663.45264,-0.14114,127.88354,32.73658
396.92400,33.07698,662.96495,-0.14114,128.05047,32.71252
397.42400,33.11865,662.84779,-0.14114,128.21717,32.70674
397.92400,33.16027,663.12887,-0.14114,128.38361,32.72060
398.42400,33.20194,662.42525,-0.14114,128.55031,32.68589
398.92400,33.24368,662.60491,-0.14114,128.71726,32.69475
399.42400,33.28535,662.13431,-0.14113,128.88393,32.67153
399.92400,33.32690,662.40588,-0.14114,129.05015,32.68493
400.42400,33.36857,661.83894,-0.14114,129.21684,32.65696
400.92400,33.41037,660.76647,-0.14114,129.38402,32.60404
401.42400,33.45210,660.72131,-0.14114,129.55096,32.60181
401.92400,33.49359,659.33075,-0.14114,129.71692,32.53320
402.42400,33.53527,657.68813,-0.14114,129.88362,32.45214
402.92400,33.57700,655.71731,-0.14114,130.05054,32.35490
403.42400,33.61873,654.16535,-0.14114,130.21748,32.27832
403.92400,33.66029,649.69100,-0.14114,130.38369,32.05754
404.42400,33.70202,637.84649,-0.14114,130.55062,31.47310
404.62003,33.71846,5.15600,-0.14112,130.61640,0.25441