File: Manufatura Aditiva/Classificação Orientação/Ensaios/Ensaios FDM/Tracao_OLABI_25_05_2018_FDM_YZ5.is_metal_RawData/Specimen_RawData_5.csv
Time,Extension,Load,Strain 1,Tensile strain,Tensile stress
(sec),(mm),(N),(mm/mm),(%),(MPa)
0.00000,0.00006,17.49990,0.00064,0.06431,0.86269
0.80000,0.06667,46.96678,0.00167,0.16697,2.31532
1.60000,0.13339,76.81184,0.00275,0.27450,3.78660
2.40000,0.20000,105.77958,0.00382,0.38243,5.21462
3.20000,0.26672,134.87205,0.00491,0.49132,6.64879
4.00000,0.33339,163.15150,0.00600,0.60020,8.04288
4.80000,0.40005,190.97994,0.00710,0.71044,9.41474
5.60000,0.46666,218.93608,0.00820,0.82005,10.79290
6.40000,0.53332,247.45588,0.00929,0.92936,12.19884
7.20000,0.59993,274.85620,0.01040,1.04044,13.54959
8.00000,0.66671,302.64831,0.01151,1.15096,14.91966
8.80000,0.73338,329.18646,0.01261,1.26106,16.22791
9.60000,0.79992,355.99109,0.01372,1.37204,17.54930
10.40000,0.86665,381.95413,0.01483,1.48326,18.82920
11.20000,0.93331,406.94783,0.01590,1.59025,20.06132
12.00000,1.00010,432.26313,0.01698,1.69833,21.30929
12.80000,1.06670,457.85345,0.01810,1.81001,22.57081
13.60000,1.13325,482.87162,0.01923,1.92253,23.80413
14.40000,1.20003,506.88898,0.02036,2.03564,24.98812
15.20000,1.26670,531.62039,0.02149,2.14862,26.20730
16.00000,1.33337,554.12492,0.02262,2.26205,27.31671
16.80000,1.40003,577.25422,0.02376,2.37567,28.45691
17.60000,1.46670,599.31269,0.02491,2.49073,29.54433
18.40000,1.53324,620.26009,0.02606,2.60586,30.57698
19.20000,1.60003,642.59549,0.02722,2.72217,31.67805
20.00000,1.66669,663.39970,0.02840,2.83966,32.70363
20.80000,1.73330,682.84590,0.02957,2.95742,33.66227
21.60000,1.79996,701.26886,0.03074,3.11006,34.57047
22.37000,1.86418,719.66797,0.03190,3.36692,35.47749
23.17000,1.93078,737.50960,0.03312,3.63334,36.35703
23.97000,1.99751,754.36560,0.03472,3.90024,37.18798
24.77000,2.06423,770.00842,0.00379,4.16714,37.95913
25.57000,2.13084,786.16515,-0.02034,4.43356,38.75560
26.37000,2.19744,800.22635,0.02073,4.69998,39.44878
27.17000,2.26423,814.11032,-0.13530,4.96712,40.13322
27.97000,2.33083,826.82502,-0.13531,5.23355,40.76001
28.77000,2.39744,838.61658,-0.13533,5.49997,41.34130
29.57000,2.46416,849.62118,-0.13534,5.76687,41.88380
30.37000,2.53083,859.41246,-0.13534,6.03353,42.36648
31.17000,2.59749,867.23529,-0.13534,6.30019,42.75212
31.97000,2.66410,874.28764,-0.13534,6.56661,43.09978
32.77000,2.73083,880.44787,-0.13534,6.83351,43.40346
33.57000,2.79755,886.31054,-0.13534,7.10041,43.69247
34.37000,2.86422,889.86428,-0.13534,7.36707,43.86766
35.17000,2.93082,893.10119,-0.13534,7.63349,44.02723
35.97000,2.99743,894.77729,-0.13534,7.89992,44.10986
36.77000,3.06409,895.33404,-0.13535,8.16658,44.13730
37.57000,3.13082,895.63122,-0.13535,8.43348,44.15195
38.37000,3.19754,894.36229,-0.13535,8.70038,44.08940
39.17000,3.26415,892.52340,-0.13535,8.96680,43.99875
39.97000,3.33081,889.97381,-0.13535,9.23346,43.87306
40.77000,3.39742,886.84885,-0.13535,9.49988,43.71901
41.57000,3.46426,883.11071,-0.13535,9.76726,43.53473
42.37000,3.53087,879.50425,-0.13535,10.03368,43.35694
43.17000,3.59735,875.35810,-0.13535,10.29963,43.15255
43.97000,3.66414,871.03471,-0.13535,10.56677,42.93942
44.77000,3.73074,866.05018,-0.13535,10.83319,42.69370
45.57000,3.79759,861.91650,-0.13535,11.10057,42.48992
46.37000,3.86414,857.58939,-0.13535,11.36675,42.27660
47.17000,3.93074,853.51709,-0.13535,11.63317,42.07585
47.97000,3.99747,848.50956,-0.13535,11.90007,41.82899
48.77000,4.06431,845.33701,-0.13535,12.16745,41.67260
49.57000,4.13092,840.97628,-0.13535,12.43387,41.45763
50.37000,4.19746,837.31329,-0.13535,12.70006,41.27705
51.17000,4.26413,833.24602,-0.13535,12.96672,41.07655
51.97000,4.33079,829.64683,-0.13535,13.23338,40.89912
52.77000,4.39746,826.07297,-0.13535,13.50004,40.72294
53.57000,4.46412,822.84138,-0.13535,13.76670,40.56363
54.37000,4.53085,819.29220,-0.13535,14.03360,40.38867
55.17000,4.59751,816.81050,-0.13535,14.30026,40.26633
55.97000,4.66424,813.32000,-0.13535,14.56716,40.09426
56.77000,4.73084,810.23388,-0.13535,14.83358,39.94212
57.57000,4.79745,806.75259,-0.13535,15.10001,39.77050
58.37000,4.86423,803.96030,-0.13535,15.36715,39.63285
59.17000,4.93078,800.48377,-0.13535,15.63333,39.46147
59.97000,4.99750,796.60751,-0.13535,15.90023,39.27038
60.77000,5.06417,793.39519,-0.13535,16.16689,39.11202
61.57000,5.13084,789.16056,-0.13535,16.43355,38.90327
62.37000,5.19750,785.53231,-0.13535,16.70021,38.72441
63.17000,5.26411,780.75314,-0.13535,16.96663,38.48881
63.97000,5.33089,775.58006,-0.13535,17.23377,38.23379
64.77000,5.39762,769.71226,-0.13535,17.50067,37.94452
65.57000,5.46410,762.68665,-0.13535,17.76662,37.59818
66.37000,5.53083,755.81279,-0.13535,18.03352,37.25932
67.17001,5.59755,748.01757,-0.13535,18.30042,36.87504
67.97000,5.66422,738.62909,-0.13535,18.56708,36.41222
68.77001,5.73082,729.17431,-0.13535,18.83350,35.94613
69.57000,5.79749,719.26699,-0.13535,19.10016,35.45772
70.37000,5.86415,707.33265,-0.13535,19.36682,34.86940
71.17001,5.93088,695.91519,-0.13535,19.63373,34.30655
71.97000,5.99754,685.50892,-0.13535,19.90038,33.79355
72.77001,6.06409,676.06824,-0.13535,20.16657,33.32815
73.57000,6.13075,667.01625,-0.13535,20.43323,32.88192
74.37000,6.19754,660.71590,-0.13535,20.70037,32.57133
75.17001,6.26420,655.66334,-0.13535,20.96703,32.32225
75.97000,6.33081,650.51401,-0.13535,21.23345,32.06841
76.77001,6.39754,647.74347,-0.13535,21.50035,31.93183
77.57001,6.46414,646.28413,-0.13535,21.76677,31.85988
78.37000,6.53081,644.00914,-0.13535,22.03344,31.74773
79.17001,6.59753,643.79112,-0.13535,22.30033,31.73699
79.97000,6.66414,644.17720,-0.13535,22.56676,31.75602
80.77001,6.73086,643.82264,-0.13535,22.83366,31.73854
81.57001,6.79741,644.50689,-0.13535,23.09984,31.77227
82.37000,6.86413,644.33515,-0.13535,23.36674,31.76381
83.17001,6.93092,645.27113,-0.13535,23.63388,31.80995
83.97000,6.99752,645.87402,-0.13535,23.90030,31.83967
84.77001,7.06413,646.54183,-0.13535,24.16672,31.87259
85.57001,7.13079,646.63151,-0.13535,24.43338,31.87701
86.37000,7.19746,647.76079,-0.13535,24.70005,31.93268
87.17001,7.26418,648.88196,-0.13536,24.96695,31.98795
87.97000,7.33079,649.18422,-0.13535,25.23337,32.00285
88.77001,7.39751,648.82059,-0.13535,25.50027,31.98492
89.57001,7.46412,649.09714,-0.13535,25.76669,31.99856
90.37000,7.53085,649.34390,-0.13535,26.03359,32.01072
91.17001,7.59751,649.34082,-0.13535,26.30025,32.01057
91.97000,7.66406,649.20527,-0.13535,26.56643,32.00389
92.77001,7.73084,649.83023,-0.13535,26.83358,32.03470
93.57001,7.79745,650.21385,-0.13535,27.10000,32.05361
94.37000,7.86417,650.73702,-0.13535,27.36690,32.07940
95.17001,7.93084,650.63820,-0.13535,27.63356,32.07453
95.97000,7.99750,650.32374,-0.13535,27.90022,32.05902
96.77001,8.06417,650.45096,-0.13535,28.16688,32.06530
97.57001,8.13071,650.50912,-0.13535,28.43306,32.06816
98.37000,8.19756,650.69338,-0.13535,28.70044,32.07725
99.17001,8.26416,650.80519,-0.13535,28.96686,32.08276
99.97000,8.33077,650.78260,-0.13535,29.23329,32.08165
100.77001,8.39743,651.06554,-0.13535,29.49995,32.09559
101.57001,8.46422,651.04989,-0.13535,29.76709,32.09482
102.37000,8.53082,651.89959,-0.13535,30.03351,32.13671
103.17001,8.59749,651.22847,-0.13535,30.30017,32.10363
103.97000,8.66415,651.84995,-0.13535,30.56683,32.13426
104.77001,8.73076,652.61964,-0.13535,30.83325,32.17221
105.57001,8.79767,652.78378,-0.13535,31.10087,32.18030
106.37000,8.86421,651.79318,-0.13535,31.36705,32.13147
107.17001,8.93076,652.15351,-0.13535,31.63323,32.14923
107.97001,8.99742,652.66341,-0.13535,31.89990,32.17436
108.77001,9.06421,652.53116,-0.13535,32.16703,32.16784
109.57001,9.13087,651.79733,-0.13535,32.43370,32.13167
110.37000,9.19742,651.54750,-0.13535,32.69988,32.11935
111.17001,9.26414,652.00608,-0.13535,32.96678,32.14196
111.97001,9.33087,652.01856,-0.13535,33.23368,32.14257
112.77001,9.39753,651.68794,-0.13535,33.50034,32.12628
113.57001,9.46420,651.97535,-0.13535,33.76700,32.14045
114.37000,9.53080,652.74527,-0.13535,34.03342,32.17840
115.17001,9.59747,653.20358,-0.13535,34.30009,32.20099
115.97001,9.66413,653.25163,-0.13535,34.56675,32.20336
116.77001,9.73086,653.63222,-0.13535,34.83365,32.22212
117.57001,9.79752,653.26085,-0.13535,35.10031,32.20382
118.37000,9.86413,653.42146,-0.13535,35.36673,32.21173
119.17001,9.93080,653.71431,-0.13535,35.63339,32.22617
119.97001,9.99752,652.83352,-0.13535,35.90029,32.18275
120.77001,10.06418,653.65424,-0.13535,36.16695,32.22321
121.57001,10.13091,653.12861,-0.13535,36.43385,32.19730
122.37000,10.19752,652.90201,-0.13535,36.70028,32.18613
123.17001,10.26418,653.91543,-0.13535,36.96694,32.23608
123.97001,10.33085,653.39240,-0.13535,37.23359,32.21030
124.77001,10.39757,654.20326,-0.13535,37.50050,32.25027
125.57001,10.46412,653.83725,-0.13535,37.76668,32.23223
126.37000,10.53078,654.34994,-0.13535,38.03334,32.25750
127.17001,10.59751,654.19688,-0.13535,38.30024,32.24996
127.97001,10.66423,654.33714,-0.13535,38.56714,32.25687
128.77001,10.73084,654.68629,-0.13535,38.83356,32.27409
129.57001,10.79738,654.61649,-0.13535,39.09974,32.27065
130.37001,10.86417,654.59968,-0.13535,39.36689,32.26982
131.17002,10.93083,653.83739,-0.13535,39.63355,32.23224
131.97000,10.99756,654.34733,-0.13535,39.90045,32.25738
132.77000,11.06416,653.93369,-0.13535,40.16687,32.23698
133.57000,11.13083,654.50249,-0.13535,40.43353,32.26503
134.37002,11.19750,654.14822,-0.13535,40.70019,32.24756
135.17002,11.26416,653.81727,-0.13535,40.96686,32.23125
135.97000,11.33089,654.05210,-0.13535,41.23375,32.24282
136.77000,11.39749,654.67660,-0.13535,41.50017,32.27361
137.57000,11.46416,653.87608,-0.13535,41.76684,32.23415
138.37002,11.53076,654.68559,-0.13536,42.03326,32.27405
139.17002,11.59743,655.59391,-0.13535,42.29992,32.31883
139.97000,11.66421,655.35018,-0.13535,42.56706,32.30681
140.77000,11.73082,655.88448,-0.13535,42.83348,32.33315
141.57000,11.79742,656.05300,-0.13535,43.09990,32.34146
142.37002,11.86409,657.04808,-0.13535,43.36656,32.39051
143.17002,11.93087,657.79625,-0.13535,43.63370,32.42740
143.97000,11.99760,657.35942,-0.13535,43.90061,32.40586
144.77000,12.06408,657.24631,-0.13535,44.16654,32.40029
145.57000,12.13081,656.88109,-0.13535,44.43345,32.38228
146.37002,12.19753,656.81352,-0.13535,44.70035,32.37895
147.17002,12.26420,656.34893,-0.13535,44.96701,32.35605
147.97000,12.33081,656.48393,-0.13535,45.23343,32.36271
148.77000,12.39747,656.64081,-0.13535,45.50009,32.37044
149.57000,12.46420,656.40677,-0.13535,45.76699,32.35890
150.37002,12.53086,656.70516,-0.13535,46.03366,32.37361
151.17002,12.59759,656.75429,-0.13535,46.30055,32.37603
151.97000,12.66407,657.69516,-0.13535,46.56650,32.42241
152.77000,12.73080,657.81088,-0.13535,46.83340,32.42812
153.57000,12.79752,657.35807,-0.13535,47.10030,32.40580
154.37002,12.86413,657.75639,-0.13535,47.36672,32.42543
155.17002,12.93079,657.97940,-0.13535,47.63339,32.43643
155.97000,12.99752,657.41781,-0.13535,47.90028,32.40874
156.77000,13.06418,657.61334,-0.13535,48.16694,32.41838
157.57000,13.13085,657.55215,-0.13535,48.43360,32.41536
158.37002,13.19751,657.69870,-0.13535,48.70026,32.42259
159.17002,13.26412,656.85338,-0.13535,48.96669,32.38092
159.97000,13.33078,657.47346,-0.13535,49.23334,32.41148
160.77000,13.39745,656.93934,-0.13535,49.50001,32.38515
161.57000,13.46417,657.01273,-0.13535,49.76691,32.38877
162.37002,13.53096,656.80500,-0.13535,50.03405,32.37853
163.17002,13.59751,657.22787,-0.13535,50.30023,32.39938
163.97000,13.66417,657.22303,-0.13535,50.56689,32.39914
164.77000,13.73078,657.84422,-0.13535,50.83331,32.42976
165.57000,13.79756,657.96128,-0.13535,51.10046,32.43554
166.37002,13.86423,657.88855,-0.13535,51.36712,32.43195
167.17002,13.93077,657.52789,-0.13535,51.63330,32.41417
167.97000,13.99750,657.84026,-0.13535,51.90020,32.42957
168.77000,14.06422,658.69722,-0.13535,52.16710,32.47181
169.57000,14.13095,658.58420,-0.13535,52.43400,32.46624
170.37002,14.19749,658.96325,-0.13535,52.70019,32.48493
171.17002,14.26404,659.86738,-0.13535,52.96637,32.52950
171.97000,14.33082,658.82723,-0.13535,53.23350,32.47822
172.77000,14.39755,659.30705,-0.13535,53.50040,32.50188
173.57000,14.46421,659.05321,-0.13536,53.76707,32.48936
174.37002,14.53082,659.07459,-0.13535,54.03349,32.49042
175.17002,14.59748,658.84348,-0.13535,54.30015,32.47902
175.97000,14.66421,659.54369,-0.13535,54.56705,32.51354
176.77000,14.73082,659.69084,-0.13536,54.83347,32.52079
177.57000,14.79748,658.80236,-0.13535,55.10013,32.47700
178.37002,14.86415,659.46276,-0.13535,55.36680,32.50955
179.17002,14.93081,659.03203,-0.13535,55.63346,32.48832
179.97000,14.99742,658.62439,-0.13535,55.89988,32.46822
180.77000,15.06420,658.72297,-0.13535,56.16702,32.47308
181.57000,15.13081,658.80888,-0.13535,56.43344,32.47732
182.37002,15.19753,658.24641,-0.13535,56.70034,32.44959
183.17002,15.26420,658.54350,-0.13535,56.96700,32.46423
183.97000,15.33074,658.31789,-0.13535,57.23318,32.45311
184.77000,15.39759,659.18211,-0.13535,57.50057,32.49572
185.57000,15.46419,658.39444,-0.13535,57.76699,32.45689
186.37002,15.53080,658.69559,-0.13535,58.03341,32.47173
187.17002,15.59746,658.33041,-0.13535,58.30007,32.45373
187.97002,15.66419,658.18783,-0.13535,58.56696,32.44670
188.77000,15.73079,658.31402,-0.13535,58.83339,32.45292
189.57000,15.79746,658.36497,-0.13536,59.10004,32.45543
190.37002,15.86418,658.12971,-0.13535,59.36695,32.44384
191.17002,15.93079,658.18881,-0.13535,59.63337,32.44675
191.97002,15.99751,658.41414,-0.13535,59.90027,32.45786
192.77000,16.06424,658.80949,-0.13535,60.16717,32.47735
193.57000,16.13085,658.44404,-0.13536,60.43360,32.45933
194.37002,16.19751,659.31631,-0.13535,60.70025,32.50233
195.17002,16.26412,659.67087,-0.13535,60.96668,32.51981
195.97002,16.33078,659.09633,-0.13535,61.23334,32.49149
196.77000,16.39751,659.08837,-0.13535,61.50024,32.49110
197.57000,16.46411,659.55473,-0.13535,61.76666,32.51408
198.37002,16.53072,659.80279,-0.13535,62.03308,32.52631
199.17002,16.59750,660.16512,-0.13535,62.30022,32.54417
199.97002,16.66429,660.12237,-0.13536,62.56736,32.54207
200.77000,16.73083,659.91716,-0.13536,62.83355,32.53195
201.57000,16.79744,660.38016,-0.13535,63.09996,32.55478
202.37002,16.86410,660.38352,-0.13536,63.36663,32.55494
203.17002,16.93089,660.88634,-0.13535,63.63377,32.57973
203.97002,16.99755,660.31152,-0.13535,63.90042,32.55139
204.77000,17.06410,660.80429,-0.13535,64.16661,32.57568
205.57000,17.13070,661.26515,-0.13535,64.43303,32.59840
206.37002,17.19755,661.21696,-0.13535,64.70041,32.59603
207.17002,17.26434,660.77164,-0.13536,64.96755,32.57408
207.97002,17.33088,660.48857,-0.13535,65.23374,32.56012
208.77000,17.39743,660.72480,-0.13535,65.49991,32.57177
209.57000,17.46409,660.64163,-0.13535,65.76658,32.56767
210.37002,17.53082,660.39250,-0.13535,66.03347,32.55539
211.17002,17.59754,660.24265,-0.13535,66.30037,32.54800
211.97002,17.66415,660.45159,-0.13535,66.56680,32.55830
212.77000,17.73081,660.06668,-0.13536,66.83345,32.53932
213.57000,17.79748,659.44451,-0.13535,67.10012,32.50865
214.37002,17.86420,659.52637,-0.13536,67.36702,32.51269
215.17002,17.93087,659.95585,-0.13535,67.63369,32.53386
215.97002,17.99747,659.78030,-0.13535,67.90010,32.52520
216.77000,18.06420,660.53900,-0.13535,68.16701,32.56261
217.57000,18.13080,660.50538,-0.13535,68.43343,32.56095
218.37002,18.19747,660.40684,-0.13535,68.70009,32.55609
219.17002,18.26425,660.43991,-0.13535,68.96723,32.55772
219.97002,18.33080,660.72200,-0.13536,69.23341,32.57163
220.77000,18.39747,660.93365,-0.13535,69.50008,32.58206
221.57000,18.46413,661.30920,-0.13535,69.76674,32.60057
222.37002,18.53092,660.81393,-0.13535,70.03388,32.57616
223.17002,18.59746,661.08601,-0.13536,70.30005,32.58957
223.97002,18.66413,660.05411,-0.13535,70.56672,32.53870
224.77000,18.73085,660.43460,-0.13535,70.83362,32.55746
225.57000,18.79752,660.68824,-0.13536,71.10028,32.56997
226.37002,18.86424,661.27181,-0.13536,71.36718,32.59873
227.17002,18.93079,661.13696,-0.13536,71.63336,32.59208
227.97002,18.99745,661.30194,-0.13535,71.90002,32.60022
228.77000,19.06418,660.65453,-0.13536,72.16693,32.56830
229.57000,19.13084,661.07544,-0.13536,72.43358,32.58905
230.37002,19.19757,661.51973,-0.13536,72.70048,32.61095
231.17002,19.26412,660.92568,-0.13535,72.96667,32.58167
231.97002,19.33084,661.02240,-0.13536,73.23356,32.58644
232.77000,19.39751,660.43749,-0.13536,73.50023,32.55760
233.57000,19.46423,660.40838,-0.13536,73.76713,32.55617
234.37002,19.53083,660.21639,-0.13536,74.03355,32.54670
235.17002,19.59744,660.82040,-0.13536,74.29997,32.57648
235.97002,19.66411,660.40228,-0.13535,74.56663,32.55587
236.77000,19.73083,660.76503,-0.13535,74.83353,32.57375
237.57000,19.79755,660.30663,-0.13535,75.10043,32.55115
238.37002,19.86422,660.37462,-0.13536,75.36709,32.55450
239.17002,19.93077,660.31986,-0.13536,75.63328,32.55180
239.97002,19.99743,660.66845,-0.13536,75.89994,32.56899
240.77000,20.06422,660.49360,-0.13536,76.16708,32.56037
241.57000,20.13088,661.01383,-0.13535,76.43374,32.58601
242.37002,20.19743,661.07861,-0.13536,76.69992,32.58921
243.17002,20.26409,660.88443,-0.13536,76.96658,32.57964
243.97002,20.33076,661.05868,-0.13535,77.23324,32.58823
244.77000,20.39754,660.83781,-0.13536,77.50039,32.57734
245.57000,20.46421,660.47534,-0.13535,77.76705,32.55947
246.37002,20.53075,659.92028,-0.13536,78.03323,32.53210
247.17002,20.59748,659.89099,-0.13535,78.30013,32.53066
247.97002,20.66421,659.40605,-0.13535,78.56703,32.50676
248.77000,20.73093,659.58677,-0.13536,78.83393,32.51566
249.57000,20.79748,658.97414,-0.13535,79.10011,32.48547
250.37002,20.86408,660.19427,-0.13536,79.36653,32.54561
251.17002,20.93086,660.01192,-0.13535,79.63367,32.53662
251.97002,20.99747,659.92693,-0.13536,79.90009,32.53243
252.77002,21.06413,660.31986,-0.13536,80.16675,32.55180
253.57000,21.13086,660.94869,-0.13536,80.43365,32.58280
254.37002,21.19753,660.45593,-0.13535,80.70032,32.55851
255.17002,21.26413,660.30300,-0.13536,80.96673,32.55097
255.97002,21.33080,661.17565,-0.13536,81.23340,32.59399
256.77002,21.39752,660.22296,-0.13536,81.50030,32.54703
257.57000,21.46413,660.80927,-0.13536,81.76672,32.57593
258.37003,21.53073,660.51190,-0.13536,82.03315,32.56127
259.17002,21.59752,660.38384,-0.13536,82.30029,32.55496
259.97000,21.66424,660.11366,-0.13536,82.56718,32.54164
260.77002,21.73085,660.78086,-0.13536,82.83361,32.57453
261.57000,21.79739,660.36009,-0.13535,83.09978,32.55379
262.37003,21.86406,660.59092,-0.13535,83.36645,32.56517
263.17000,21.93084,660.74845,-0.13536,83.63359,32.57293
263.97000,21.99763,659.88470,-0.13536,83.90073,32.53035
264.77003,22.06417,661.28550,-0.13536,84.16691,32.59941
265.57000,22.13072,660.99563,-0.13536,84.43310,32.58512
266.37003,22.19745,660.03990,-0.13535,84.70000,32.53800
267.17000,22.26417,660.38496,-0.13536,84.96690,32.55501
267.97000,22.33084,660.01853,-0.13536,85.23355,32.53695
268.77003,22.39744,660.64852,-0.13536,85.49998,32.56800
269.57000,22.46423,662.06655,-0.13536,85.76712,32.63791
270.37003,22.53083,661.56993,-0.13536,86.03354,32.61343
271.17000,22.59756,661.93384,-0.13536,86.30044,32.63137
271.97000,22.66422,662.26027,-0.13535,86.56710,32.64746
272.77003,22.73077,662.72318,-0.13535,86.83329,32.67028
273.57000,22.79749,662.84691,-0.13536,87.10018,32.67638
274.37003,22.86410,663.05380,-0.13536,87.36661,32.68658
275.17000,22.93088,663.08999,-0.13536,87.63375,32.68836
275.97000,22.99755,662.77944,-0.13536,87.90041,32.67305
276.77003,23.06415,662.44979,-0.13536,88.16683,32.65680
277.57000,23.13082,663.43364,-0.13536,88.43349,32.70530
278.37003,23.19749,662.99741,-0.13536,88.70015,32.68380
279.17000,23.26421,663.52277,-0.13535,88.96705,32.70970
279.97000,23.33082,663.18680,-0.13535,89.23347,32.69313
280.77003,23.39748,662.99927,-0.13536,89.50013,32.68389
281.57000,23.46415,662.81715,-0.13536,89.76679,32.67492
282.37003,23.53093,663.27364,-0.13536,90.03394,32.69742
283.17000,23.59753,663.15411,-0.13536,90.30035,32.69152
283.97000,23.66414,662.92961,-0.13536,90.56678,32.68046
284.77003,23.73081,662.86447,-0.13536,90.83344,32.67725
285.57000,23.79753,663.13194,-0.13536,91.10034,32.69043
286.37003,23.86420,663.52813,-0.13536,91.36700,32.70996
287.17000,23.93080,663.56575,-0.13536,91.63343,32.71182
287.97000,23.99747,663.78019,-0.13536,91.90008,32.72239
288.77003,24.06419,663.46927,-0.13536,92.16698,32.70706
289.57000,24.13080,663.70755,-0.13536,92.43341,32.71881
290.37003,24.19752,663.72161,-0.13536,92.70030,32.71950
291.17000,24.26413,663.42619,-0.13536,92.96672,32.70494
291.97000,24.33086,663.65292,-0.13536,93.23363,32.71611
292.77003,24.39746,663.82838,-0.13536,93.50005,32.72477
293.57000,24.46424,664.81857,-0.13536,93.76719,32.77358
294.37003,24.53085,663.52575,-0.13536,94.03361,32.70985
295.17000,24.59746,664.05516,-0.13536,94.30004,32.73594
295.97000,24.66412,664.16143,-0.13536,94.56670,32.74118
296.77003,24.73073,664.09586,-0.13536,94.83312,32.73795
297.57000,24.79751,663.93297,-0.13536,95.10025,32.72992
298.37003,24.86424,663.74429,-0.13536,95.36715,32.72062
299.17000,24.93078,664.25675,-0.13535,95.63335,32.74588
299.97000,24.99739,664.75826,-0.13536,95.89976,32.77060
300.77003,25.06417,664.25991,-0.13536,96.16690,32.74604
301.57000,25.13096,664.81950,-0.13536,96.43404,32.77362
302.37003,25.19750,664.28836,-0.13536,96.70022,32.74744
303.17000,25.26411,664.33605,-0.13536,96.96664,32.74979
303.97000,25.33084,663.66415,-0.13536,97.23355,32.71667
304.77003,25.39756,663.22112,-0.13536,97.50044,32.69483
305.57000,25.46417,662.75033,-0.13536,97.76688,32.67162
306.37003,25.53083,662.60044,-0.13536,98.03353,32.66423
307.17000,25.59738,662.02534,-0.13536,98.29971,32.63588
307.97000,25.66416,661.47563,-0.13536,98.56685,32.60878
308.77003,25.73095,660.83376,-0.13536,98.83399,32.57714
309.57000,25.79749,660.92741,-0.13536,99.10017,32.58175
310.37003,25.86410,660.68335,-0.13536,99.36660,32.56973
311.17000,25.93088,661.36764,-0.13536,99.63374,32.60346
311.97000,25.99749,661.10599,-0.13536,99.90016,32.59056
312.77003,26.06415,661.46585,-0.13536,100.16682,32.60830
313.57000,26.13082,661.86045,-0.13536,100.43347,32.62775
314.37003,26.19748,662.19787,-0.13536,100.70014,32.64439
315.17000,26.26409,662.49124,-0.13536,100.96656,32.65885
315.97000,26.33075,662.45929,-0.13536,101.23322,32.65727
316.77003,26.39754,662.47582,-0.13536,101.50036,32.65809
317.57000,26.46420,662.34185,-0.13536,101.76703,32.65148
318.37003,26.53081,661.76262,-0.13536,102.03345,32.62293
319.17000,26.59747,661.84467,-0.13536,102.30011,32.62697
319.97000,26.66420,661.91466,-0.13536,102.56702,32.63042
320.77003,26.73086,661.70618,-0.13536,102.83366,32.62014
321.57000,26.79747,661.68122,-0.13536,103.10010,32.61892
322.37003,26.86414,662.01659,-0.13536,103.36676,32.63545
323.17000,26.93086,660.90892,-0.13536,103.63364,32.58084
323.97000,26.99759,661.29663,-0.13536,103.90055,32.59996
324.77003,27.06413,661.28243,-0.13536,104.16673,32.59925
325.57000,27.13080,661.39181,-0.13536,104.43339,32.60465
326.37003,27.19746,661.12396,-0.13536,104.70005,32.59145
327.17000,27.26425,660.81993,-0.13536,104.96720,32.57646
327.97000,27.33091,661.62553,-0.13536,105.23386,32.61617
328.77003,27.39746,661.09323,-0.13536,105.50004,32.58993
329.57000,27.46413,661.02408,-0.13536,105.76671,32.58652
330.37003,27.53079,661.17025,-0.13536,106.03337,32.59373
331.17000,27.59751,661.00089,-0.13536,106.30027,32.58538
331.97000,27.66418,660.72675,-0.13536,106.56693,32.57186
332.77003,27.73084,662.11238,-0.13536,106.83359,32.64017
333.57000,27.79745,661.38059,-0.13536,107.10001,32.60410
334.37003,27.86411,661.17207,-0.13536,107.36667,32.59381
335.17000,27.93090,662.00662,-0.13536,107.63381,32.63496
335.97000,27.99757,662.31815,-0.13536,107.90048,32.65031
336.77003,28.06411,661.94087,-0.13536,108.16666,32.63171
337.57000,28.13078,661.94395,-0.13536,108.43331,32.63187
338.37003,28.19750,662.61599,-0.13536,108.70022,32.66500
339.17000,28.26423,662.78242,-0.13536,108.96711,32.67320
339.97000,28.33083,663.10181,-0.13536,109.23355,32.68895
340.77003,28.39750,662.82968,-0.13536,109.50019,32.67553
341.57000,28.46410,663.35988,-0.13536,109.76663,32.70167
342.37003,28.53089,662.80481,-0.13536,110.03376,32.67430
343.17000,28.59761,663.31481,-0.13536,110.30066,32.69945
343.97000,28.66416,663.12025,-0.13536,110.56684,32.68985
344.77003,28.73076,662.94642,-0.13536,110.83326,32.68129
345.57000,28.79749,663.03713,-0.13536,111.10017,32.68576
346.37003,28.86422,662.95424,-0.13536,111.36707,32.68167
347.17000,28.93082,662.86577,-0.13536,111.63348,32.67731
347.97003,28.99749,662.99550,-0.13536,111.90015,32.68370
348.77003,29.06421,663.33213,-0.13536,112.16705,32.70030
349.57000,29.13082,662.85385,-0.13536,112.43347,32.67672
350.37003,29.19754,662.53510,-0.13536,112.70037,32.66101
351.17000,29.26420,663.26363,-0.13536,112.96703,32.69692
351.97003,29.33081,662.05049,-0.13536,113.23346,32.63712
352.77003,29.39748,663.11774,-0.13536,113.50012,32.68973
353.57000,29.46408,662.22562,-0.13536,113.76654,32.64575
354.37003,29.53087,661.98045,-0.13536,114.03368,32.63367
355.17000,29.59747,662.03503,-0.13536,114.30011,32.63636
355.97003,29.66414,661.80234,-0.13536,114.56676,32.62489
356.77003,29.73074,661.59843,-0.13536,114.83319,32.61483
357.57000,29.79747,660.77677,-0.13536,115.10009,32.57433
358.37003,29.86431,660.80200,-0.13536,115.36746,32.57557
359.17000,29.93086,661.81356,-0.13536,115.63364,32.62544
359.97003,29.99740,661.43284,-0.13536,115.89983,32.60667
360.77003,30.06407,661.32518,-0.13536,116.16650,32.60136
361.57000,30.13097,661.32559,-0.13536,116.43411,32.60138
362.37003,30.19746,662.14851,-0.13536,116.70005,32.64195
363.17000,30.26413,662.50167,-0.13536,116.96671,32.65936
363.97003,30.33073,662.06683,-0.13536,117.23313,32.63792
364.77003,30.39758,661.75843,-0.13536,117.50052,32.62272
365.57000,30.46430,662.33259,-0.13536,117.76741,32.65102
366.37003,30.53079,662.36132,-0.13536,118.03336,32.65244
367.17000,30.59745,662.44756,-0.13536,118.30001,32.65669
367.97003,30.66412,662.19973,-0.13536,118.56668,32.64448
368.77003,30.73084,663.27578,-0.13536,118.83358,32.69752
369.57000,30.79751,663.29087,-0.13536,119.10024,32.69827
370.37003,30.86411,663.65818,-0.13536,119.36667,32.71637
371.17000,30.93084,664.21670,-0.13536,119.63357,32.74391
371.97003,30.99744,663.94224,-0.13536,119.89998,32.73038
372.77003,31.06423,664.35803,-0.13536,120.16712,32.75087
373.57000,31.13089,664.50997,-0.13536,120.43378,32.75837
374.37003,31.19744,664.22480,-0.13536,120.69997,32.74430
375.17000,31.26416,664.51430,-0.13536,120.96686,32.75858
375.97003,31.33077,665.11082,-0.13536,121.23328,32.78798
376.77003,31.39755,664.99142,-0.13536,121.50043,32.78210
377.57000,31.46416,664.94136,-0.13537,121.76685,32.77963
378.37003,31.53076,665.85918,-0.13536,122.03326,32.82487
379.17000,31.59749,664.52608,-0.13536,122.30016,32.75916
379.97003,31.66422,664.91328,-0.13536,122.56707,32.77825
380.77003,31.73088,664.42695,-0.13536,122.83373,32.75427
381.57000,31.79742,663.98941,-0.13536,123.09991,32.73270
382.37003,31.86409,664.23677,-0.13536,123.36657,32.74490
383.17000,31.93088,663.77530,-0.13536,123.63372,32.72215
383.97003,31.99748,663.84254,-0.13536,123.90013,32.72546
384.77003,32.06415,664.34741,-0.13536,124.16681,32.75035
385.57000,32.13081,664.17987,-0.13536,124.43346,32.74209
386.37003,32.19742,664.18257,-0.13536,124.69988,32.74223
387.17000,32.26414,664.59528,-0.13536,124.96679,32.76257
387.97003,32.33087,664.57721,-0.13536,125.23369,32.76168
388.77003,32.39747,665.14434,-0.13536,125.50009,32.78964
389.57000,32.46414,665.56083,-0.13536,125.76677,32.81017
390.37003,32.53086,665.03207,-0.13536,126.03366,32.78410
391.17000,32.59747,665.45438,-0.13536,126.30008,32.80492
391.97003,32.66413,664.73391,-0.13536,126.56674,32.76941
392.77003,32.73080,665.46090,-0.13536,126.83340,32.80524
393.57000,32.79746,665.30327,-0.13536,127.10006,32.79747
394.37003,32.86407,665.56330,-0.13536,127.36650,32.81029
395.17000,32.93086,665.17289,-0.13536,127.63363,32.79104
395.97003,32.99764,665.11841,-0.13536,127.90078,32.78836
396.77003,33.06413,665.23151,-0.13536,128.16672,32.79393
397.57000,33.13079,664.96124,-0.13536,128.43338,32.78061
398.37003,33.19746,665.70169,-0.13536,128.70004,32.81711
399.17000,33.26418,665.37005,-0.13536,128.96694,32.80076
399.97003,33.33091,665.09130,-0.13536,129.23384,32.78702
400.77003,33.39745,664.61978,-0.13536,129.50002,32.76378
401.57000,33.46412,664.56432,-0.13536,129.76669,32.76104
402.37003,33.53084,663.93535,-0.13536,130.03358,32.73004
403.17000,33.59757,664.46238,-0.13536,130.30047,32.75602
403.97003,33.66417,664.45326,-0.13536,130.56691,32.75557
404.77003,33.73078,664.12226,-0.13536,130.83333,32.73925
405.57000,33.79744,663.96063,-0.13536,131.09998,32.73129
406.37003,33.86423,664.05199,-0.13536,131.36714,32.73579
407.17000,33.93089,664.85959,-0.13536,131.63378,32.77560
407.97003,33.99744,664.25125,-0.13536,131.89996,32.74561
408.77003,34.06417,664.64422,-0.13536,132.16687,32.76498
409.57000,34.13083,664.85517,-0.13536,132.43353,32.77538
410.37003,34.19749,664.75496,-0.13536,132.70019,32.77044
411.17000,34.26416,665.10276,-0.13536,132.96686,32.78759
411.97003,34.33083,665.96474,-0.13536,133.23352,32.83008
412.77003,34.39743,665.57606,-0.13536,133.49993,32.81092
413.57000,34.46410,666.12889,-0.13536,133.76660,32.83817
414.37003,34.53088,666.00265,-0.13536,134.03374,32.83195
415.17000,34.59761,666.14537,-0.13537,134.30064,32.83899
415.97003,34.66415,665.52795,-0.13536,134.56683,32.80855
416.77003,34.73082,665.78328,-0.13536,134.83348,32.82113
417.57000,34.79748,665.10588,-0.13536,135.10014,32.78774
418.37003,34.86415,665.49536,-0.13536,135.36682,32.80694
419.17000,34.93087,665.63515,-0.13536,135.63371,32.81383
419.97003,34.99748,666.08316,-0.13536,135.90013,32.83592
420.77003,35.06409,666.25774,-0.13536,136.16656,32.84452
421.57000,35.13093,666.09085,-0.13536,136.43392,32.83630
422.37003,35.19753,665.52777,-0.13536,136.70034,32.80854
423.17000,35.26408,666.44833,-0.13536,136.96654,32.85392
423.97003,35.33075,666.05364,-0.13536,137.23320,32.83446
424.77003,35.39753,666.10081,-0.13536,137.50032,32.83679
425.57000,35.46420,665.11375,-0.13536,137.76700,32.78813
426.37003,35.53080,665.42909,-0.13536,138.03341,32.80367
427.17000,35.59741,665.07151,-0.13536,138.29983,32.78605
427.97003,35.66413,664.29088,-0.13536,138.56674,32.74756
428.77003,35.73086,664.58960,-0.13536,138.83364,32.76229
429.57000,35.79764,664.56050,-0.13536,139.10078,32.76086
430.37003,35.86419,663.77306,-0.13537,139.36697,32.72204
431.17000,35.93080,663.58508,-0.13536,139.63339,32.71277
431.97003,35.99746,663.47579,-0.13536,139.90005,32.70738
432.77003,36.06412,663.09650,-0.13536,140.16670,32.68869
433.57000,36.13085,662.88905,-0.13536,140.43361,32.67846
434.37003,36.19751,662.73124,-0.13536,140.70027,32.67068
435.17000,36.26412,663.90922,-0.13536,140.96668,32.72875
435.97003,36.33079,663.44440,-0.13536,141.23336,32.70583
436.77003,36.39757,664.45242,-0.13536,141.50048,32.75553
437.57000,36.46424,664.57163,-0.13536,141.76717,32.76140
438.37003,36.53078,664.67072,-0.13536,142.03334,32.76629
439.17000,36.59739,664.54965,-0.13536,142.29976,32.76032
439.97003,36.66411,664.34061,-0.13536,142.56665,32.75002
440.77003,36.73084,664.58792,-0.13536,142.83357,32.76221
441.57000,36.79750,663.45949,-0.13536,143.10023,32.70658
442.37003,36.86411,663.78820,-0.13536,143.36663,32.72278
443.17000,36.93077,664.20068,-0.13536,143.63331,32.74312
443.97003,36.99756,663.93218,-0.13536,143.90044,32.72988
444.77003,37.06422,663.66480,-0.13536,144.16710,32.71670
445.57000,37.13083,663.58806,-0.13536,144.43353,32.71292
446.37003,37.19755,663.95332,-0.13536,144.70042,32.73092
447.17000,37.26410,663.53264,-0.13536,144.96660,32.71019
447.97003,37.33082,664.15444,-0.13536,145.23351,32.74084
448.77003,37.39749,664.59798,-0.13536,145.50016,32.76270
449.57000,37.46409,663.93102,-0.13536,145.76659,32.72982
450.37003,37.53082,664.15472,-0.13536,146.03349,32.74085
451.17000,37.59749,663.71267,-0.13536,146.30015,32.71906
451.97003,37.66421,664.15486,-0.13536,146.56705,32.74086
452.77003,37.73088,663.57753,-0.13536,146.83372,32.71240
453.57000,37.79748,664.30164,-0.13536,147.10014,32.74809
454.37003,37.86415,664.67784,-0.13536,147.36680,32.76664
455.17000,37.93075,664.19924,-0.13536,147.63323,32.74305
455.97003,37.99766,663.80627,-0.13536,147.90083,32.72367
456.77003,38.06414,664.50592,-0.13536,148.16678,32.75816
457.57000,38.13075,664.04310,-0.13536,148.43321,32.73535
458.37003,38.19747,663.85111,-0.13536,148.70011,32.72588
459.17000,38.26420,664.06811,-0.13536,148.96699,32.73658
459.97003,38.33086,663.33385,-0.13536,149.23366,32.70039
460.77003,38.39747,663.52026,-0.13536,149.50008,32.70958
461.57000,38.46413,663.18489,-0.13536,149.76674,32.69304
462.37003,38.53080,663.47537,-0.13536,150.03341,32.70736
463.17000,38.59758,663.43104,-0.13537,150.30055,32.70518
463.97003,38.66419,663.01622,-0.13536,150.56697,32.68473
464.77003,38.73074,663.34438,-0.13536,150.83315,32.70090
465.57000,38.79746,662.45319,-0.13536,151.10006,32.65697
466.37003,38.86418,662.90987,-0.13536,151.36695,32.67949
467.17000,38.93091,662.62605,-0.13536,151.63386,32.66549
467.97003,38.99746,662.64216,-0.13536,151.90004,32.66629
468.77003,39.06418,662.81902,-0.13537,152.16694,32.67501
469.57000,39.13079,662.74959,-0.13537,152.43337,32.67158
470.37003,39.19751,663.69763,-0.13536,152.70025,32.71832
471.17000,39.26417,662.69212,-0.13536,152.96690,32.66875
471.97003,39.33084,662.71094,-0.13536,153.23358,32.66968
472.77003,39.39751,662.95238,-0.13537,153.50024,32.68158
473.57000,39.46411,662.54046,-0.13536,153.76664,32.66127
474.37003,39.53090,662.81208,-0.13536,154.03380,32.67466
475.17000,39.59756,662.19270,-0.13536,154.30046,32.64413
475.97003,39.66411,662.25263,-0.13536,154.56663,32.64708
476.77003,39.73084,662.60900,-0.13536,154.83356,32.66465
477.57003,39.79744,662.42530,-0.13536,155.09996,32.65560
478.37003,39.86422,662.53757,-0.13536,155.36711,32.66113
479.17000,39.93083,662.09175,-0.13537,155.63354,32.63915
479.97003,39.99744,662.77795,-0.13536,155.89995,32.67298
480.77003,40.06416,662.41808,-0.13536,156.16685,32.65524
481.57003,40.13082,663.02079,-0.13536,156.43351,32.68495
482.37003,40.19749,662.60980,-0.13536,156.70017,32.66469
483.17000,40.26410,662.99224,-0.13537,156.96660,32.68354
483.97003,40.33076,662.68509,-0.13536,157.23325,32.66840
484.77003,40.39755,662.03754,-0.13536,157.50040,32.63648
485.57003,40.46421,663.32994,-0.13536,157.76706,32.70019
486.37003,40.53088,663.49227,-0.13536,158.03373,32.70819
487.17000,40.59748,663.35653,-0.13536,158.30014,32.70150
487.97003,40.66415,663.43248,-0.13536,158.56680,32.70525
488.77003,40.73082,662.71317,-0.13536,158.83347,32.66979
489.57003,40.79748,663.19574,-0.13536,159.10013,32.69358
490.37003,40.86420,663.05804,-0.13536,159.36702,32.68679
491.17000,40.93081,663.10191,-0.13536,159.63346,32.68895
491.97003,40.99742,662.99164,-0.13536,159.89988,32.68351
492.77003,41.06420,663.22368,-0.13536,160.16699,32.69495
493.57003,41.13093,663.57600,-0.13536,160.43391,32.71232
494.37003,41.19747,662.98791,-0.13536,160.70008,32.68333
495.17000,41.26408,663.31802,-0.13536,160.96652,32.69960
495.97003,41.33080,662.55401,-0.13536,161.23341,32.66194
496.77003,41.39747,662.42195,-0.13536,161.50007,32.65543
497.57003,41.46425,662.44104,-0.13536,161.76721,32.65637
498.37003,41.53079,662.18930,-0.13536,162.03338,32.64396
499.17000,41.59740,661.79619,-0.13537,162.29981,32.62458
499.97003,41.66407,661.91130,-0.13536,162.56647,32.63026
500.77003,41.73091,662.54926,-0.13536,162.83386,32.66171
501.57003,41.79758,662.62945,-0.13537,163.10052,32.66566
502.37003,41.86406,662.56844,-0.13536,163.36646,32.66265
503.17000,41.93085,663.19164,-0.13536,163.63360,32.69337
503.97003,41.99751,662.52858,-0.13536,163.90026,32.66069
504.77003,42.06418,662.77659,-0.13537,164.16692,32.67291
505.57003,42.13078,663.07071,-0.13536,164.43335,32.68741
506.37003,42.19751,662.86451,-0.13536,164.70025,32.67725
507.17000,42.26417,662.72495,-0.13536,164.96691,32.67037
507.97003,42.33078,662.86158,-0.13536,165.23331,32.67710
508.77003,42.39757,662.94083,-0.13536,165.50047,32.68101
509.57003,42.46417,662.42907,-0.13536,165.76689,32.65578
510.37003,42.53077,662.61124,-0.13536,166.03330,32.66476
511.17000,42.59744,661.96658,-0.13536,166.29997,32.63298
511.97003,42.66417,662.19266,-0.13536,166.56687,32.64413
512.77003,42.73083,661.85393,-0.13536,166.83353,32.62743
513.57000,42.79750,661.91624,-0.13536,167.10020,32.63050
514.37000,42.86416,661.93920,-0.13536,167.36686,32.63163
515.17003,42.93077,662.56113,-0.13536,167.63328,32.66229
515.97003,42.99761,661.76034,-0.13537,167.90066,32.62281
516.77003,43.06422,662.02064,-0.13536,168.16708,32.63565
517.57000,43.13076,661.46730,-0.13537,168.43326,32.60837
518.37000,43.19737,661.42930,-0.13536,168.69969,32.60649
519.17003,43.26415,660.77900,-0.13536,168.96682,32.57444
519.97003,43.33094,661.27274,-0.13536,169.23398,32.59878
520.77003,43.39749,660.73444,-0.13536,169.50015,32.57224
521.57000,43.46409,661.11851,-0.13536,169.76657,32.59118
522.37000,43.53081,660.77076,-0.13537,170.03347,32.57403
523.17003,43.59754,660.83334,-0.13537,170.30038,32.57712
523.97003,43.66426,661.25114,-0.13536,170.56726,32.59771
524.77000,43.73075,660.64866,-0.13536,170.83321,32.56801
525.57000,43.79748,660.62114,-0.13536,171.10013,32.56666
526.37000,43.86414,661.00047,-0.13536,171.36679,32.58536
527.17006,43.93086,661.03563,-0.13537,171.63366,32.58709
527.97006,43.99753,660.86040,-0.13536,171.90033,32.57845
528.77000,44.06414,661.64983,-0.13536,172.16675,32.61737
529.57000,44.13080,661.60015,-0.13536,172.43341,32.61492
530.37000,44.19747,661.60387,-0.13537,172.70008,32.61510
531.17006,44.26419,661.08401,-0.13536,172.96698,32.58947
531.97006,44.33092,661.03539,-0.13536,173.23388,32.58708
532.77000,44.39746,660.62650,-0.13536,173.50007,32.56692
533.57000,44.46413,660.55544,-0.13536,173.76673,32.56342
534.37000,44.53079,660.12610,-0.13536,174.03338,32.54225
535.17006,44.59758,661.28736,-0.13537,174.30053,32.59950
535.97006,44.66413,661.28671,-0.13536,174.56671,32.59947
536.77000,44.73073,662.54456,-0.13536,174.83313,32.66148
537.57000,44.79746,662.46153,-0.13537,175.10004,32.65738
538.37000,44.86424,662.80561,-0.13536,175.36716,32.67434
539.17006,44.93079,662.61808,-0.13536,175.63336,32.66510
539.97006,44.99740,663.62401,-0.13536,175.89979,32.71469
540.77000,45.06418,663.63411,-0.13536,176.16692,32.71519
541.57000,45.13084,663.30782,-0.13536,176.43356,32.69910
542.37006,45.19751,663.64859,-0.13536,176.70025,32.71590
543.17006,45.26417,663.53921,-0.13536,176.96691,32.71051
543.97006,45.33078,663.52901,-0.13536,177.23331,32.71001
544.77000,45.39751,663.41441,-0.13536,177.50024,32.70436
545.57000,45.46411,663.13534,-0.13536,177.76664,32.69060
546.37006,45.53083,663.05604,-0.13536,178.03354,32.68669
547.17006,45.59750,662.60505,-0.13536,178.30021,32.66446
547.97006,45.66422,661.87265,-0.13536,178.56710,32.62835
548.77000,45.73077,662.29352,-0.13536,178.83329,32.64910
549.57000,45.79749,662.18073,-0.13536,179.10019,32.64354
550.37006,45.86428,661.97198,-0.13536,179.36733,32.63325
551.17006,45.93082,661.92416,-0.13536,179.63350,32.63089
551.97006,45.99743,662.10078,-0.13536,179.89993,32.63960
552.77000,46.06409,662.06772,-0.13536,180.16659,32.63797
553.57000,46.13088,662.00853,-0.13536,180.43373,32.63505
554.37006,46.19755,662.29948,-0.13536,180.70041,32.64939
555.17006,46.26409,662.63191,-0.13536,180.96658,32.66578
555.97006,46.33082,663.49804,-0.13536,181.23348,32.70848
556.77000,46.39748,664.00021,-0.13536,181.50015,32.73323
557.57000,46.46427,664.76217,-0.13536,181.76727,32.77080
558.37006,46.53081,664.83980,-0.13536,182.03347,32.77462
559.17006,46.59736,665.43454,-0.13536,182.29964,32.80394
559.97006,46.66409,665.55478,-0.13537,182.56655,32.80987
560.77000,46.73087,666.30128,-0.13536,182.83367,32.84667
561.57000,46.79759,666.13369,-0.13536,183.10059,32.83841
562.37006,46.86414,666.56969,-0.13537,183.36676,32.85990
563.17006,46.93074,667.31814,-0.13536,183.63317,32.89680
563.97006,46.99747,667.41421,-0.13536,183.90007,32.90154
564.77000,47.06420,667.80243,-0.13536,184.16699,32.92067
565.57000,47.13086,668.11265,-0.13536,184.43365,32.93597
566.37006,47.19753,668.06762,-0.13536,184.70032,32.93375
567.17006,47.26413,668.19191,-0.13536,184.96674,32.93987
567.97006,47.33080,668.06106,-0.13536,185.23339,32.93342
568.77000,47.39746,667.95424,-0.13536,185.50005,32.92816
569.57000,47.46424,668.35466,-0.13536,185.76719,32.94790
570.37006,47.53079,667.96658,-0.13536,186.03338,32.92876
571.17006,47.59740,668.64407,-0.13536,186.29980,32.96216
571.97006,47.66418,667.73403,-0.13536,186.56694,32.91730
572.77000,47.73091,667.77375,-0.13536,186.83383,32.91926
573.57000,47.79751,668.35647,-0.13537,187.10024,32.94799
574.37006,47.86418,668.40323,-0.13537,187.36693,32.95029
575.17006,47.93078,667.91819,-0.13537,187.63334,32.92638
575.97006,47.99751,668.08322,-0.13536,187.90023,32.93452
576.77000,48.06424,668.52728,-0.13537,188.16715,32.95641
577.57000,48.13078,668.17026,-0.13536,188.43333,32.93880
578.37006,48.19744,668.20402,-0.13536,188.69998,32.94047
579.17006,48.26417,669.07662,-0.13536,188.96689,32.98349
579.97006,48.33089,669.53432,-0.13536,189.23378,33.00605
580.77000,48.39756,669.40710,-0.13536,189.50044,32.99978
581.57000,48.46411,669.59201,-0.13536,189.76665,33.00889
582.37006,48.53083,669.55644,-0.13536,190.03352,33.00714
583.17006,48.59749,670.66168,-0.13536,190.30018,33.06163
583.97006,48.66416,670.25106,-0.13536,190.56685,33.04138
584.77000,48.73083,671.63631,-0.13536,190.83351,33.10967
585.57000,48.79749,671.53135,-0.13537,191.10017,33.10450
586.37006,48.86416,672.26090,-0.13536,191.36684,33.14046
587.17006,48.93088,672.11841,-0.13536,191.63374,33.13344
587.97006,48.99761,672.93863,-0.13536,191.90063,33.17387
588.77000,49.06415,673.11479,-0.13536,192.16683,33.18256
589.57000,49.13076,672.15031,-0.13536,192.43324,33.13501
590.37006,49.19742,672.55655,-0.13536,192.69990,33.15504
591.17006,49.26421,672.75381,-0.13537,192.96705,33.16476
591.97006,49.33087,672.54272,-0.13536,193.23369,33.15435
592.77000,49.39748,672.65606,-0.13536,193.50013,33.15994
593.57000,49.46409,672.71413,-0.13536,193.76656,33.16280
594.37006,49.53081,672.23278,-0.13536,194.03344,33.13908
595.17006,49.59765,671.73745,-0.13536,194.30083,33.11466
595.97006,49.66414,671.10951,-0.13536,194.56677,33.08370
596.77000,49.73080,671.05554,-0.13536,194.83343,33.08104
597.57000,49.79747,671.44064,-0.13536,195.10008,33.10003
598.37006,49.86420,670.72650,-0.13537,195.36700,33.06482
599.17006,49.93086,671.13587,-0.13536,195.63366,33.08500
599.97006,49.99747,671.55389,-0.13536,195.90007,33.10561
600.77000,50.06419,671.82062,-0.13537,196.16699,33.11876
601.57000,50.13080,671.76246,-0.13536,196.43340,33.11589
602.37006,50.19752,671.85885,-0.13537,196.70030,33.12064
603.17006,50.26419,673.08545,-0.13536,196.96696,33.18111
603.97006,50.33085,673.22762,-0.13536,197.23362,33.18812
604.77000,50.39746,673.29695,-0.13537,197.50005,33.19154
605.57000,50.46412,673.63405,-0.13536,197.76671,33.20815
606.37006,50.53085,674.41119,-0.13536,198.03361,33.24646
607.17006,50.59751,674.78409,-0.13536,198.30025,33.26485
607.97006,50.66412,675.09497,-0.13536,198.56669,33.28017
608.77000,50.73072,674.79913,-0.13536,198.83311,33.26559
609.57000,50.79745,674.92044,-0.13536,199.10001,33.27157
610.37006,50.86418,675.08672,-0.13536,199.36693,33.27977
611.17006,50.93090,674.96877,-0.13537,199.63382,33.27395
611.97006,50.99745,675.29813,-0.13536,199.90000,33.29019
612.77000,51.06411,675.79681,-0.13536,200.16668,33.31477
613.57000,51.13084,676.40119,-0.13536,200.43356,33.34457
614.37006,51.19756,677.45424,-0.13537,200.70045,33.39648
615.17006,51.26405,678.16982,-0.13536,200.96638,33.43176
615.97006,51.33078,678.35297,-0.13537,201.23332,33.44078
616.77000,51.39749,678.81215,-0.13537,201.50020,33.46342
617.57000,51.46428,679.59521,-0.13536,201.76735,33.50202
618.37006,51.53083,679.78920,-0.13537,202.03352,33.51159
619.17006,51.59738,680.00392,-0.13536,202.29971,33.52217
619.97006,51.66410,680.86893,-0.13536,202.56660,33.56481
620.77000,51.73082,680.68686,-0.13537,202.83351,33.55584
621.57000,51.79761,681.29287,-0.13536,203.10066,33.58571
622.37006,51.86416,682.16273,-0.13537,203.36685,33.62859
623.17006,51.93076,683.05740,-0.13536,203.63326,33.67270
623.97006,51.99749,683.52683,-0.13537,203.90015,33.69584
624.77000,52.06421,684.34277,-0.13537,204.16706,33.73606
625.57000,52.13082,685.27935,-0.13536,204.43349,33.78223
626.37006,52.19742,686.58637,-0.13536,204.69990,33.84666
627.17006,52.26415,687.48547,-0.13536,204.96681,33.89099
627.97006,52.33081,688.47719,-0.13536,205.23345,33.93988
628.77000,52.39747,689.60162,-0.13537,205.50010,33.99531
629.57000,52.46426,691.28042,-0.13536,205.76727,34.07807
630.37006,52.53081,692.79904,-0.13536,206.03344,34.15293
631.17006,52.59747,693.67033,-0.13537,206.30009,34.19588
631.97006,52.66414,694.78806,-0.13536,206.56676,34.25098
632.77000,52.73093,695.36199,-0.13537,206.83391,34.27928
633.57000,52.79747,695.97512,-0.13536,207.10008,34.30950
634.37006,52.86413,697.50976,-0.13536,207.36673,34.38515
635.17006,52.93086,698.21635,-0.13536,207.63366,34.41999
635.97006,52.99747,698.33156,-0.13536,207.90007,34.42567
636.77000,53.06425,699.69925,-0.13536,208.16722,34.49309
637.57000,53.13085,700.16435,-0.13536,208.43363,34.51602
638.37006,53.19746,700.87528,-0.13536,208.70006,34.55107
639.17006,53.26413,701.95291,-0.13536,208.96671,34.60419
639.97006,53.33085,702.15259,-0.13536,209.23362,34.61403
640.77000,53.39751,702.46896,-0.13537,209.50027,34.62963
641.57000,53.46412,703.32140,-0.13536,209.76667,34.67165
642.37006,53.53091,702.78156,-0.13536,210.03385,34.64504
643.17006,53.59751,702.09098,-0.13536,210.30025,34.61100
643.97006,53.66424,701.43272,-0.13536,210.56716,34.57854
644.77000,53.73084,699.94358,-0.13536,210.83360,34.50513
645.57000,53.79751,697.25984,-0.13536,211.10024,34.37284
646.37006,53.86411,693.91755,-0.13536,211.36665,34.20807
647.17006,53.93078,687.20174,-0.13536,211.63332,33.87700
647.97006,53.99751,674.84230,-0.13536,211.90023,33.26772
648.77000,54.06423,644.13706,-0.13536,212.16712,31.75404
649.12400,54.09377,4.07409,-0.13537,212.28528,0.20084