File: Tração/Dados/Specimen_RawData_5.csv
Time,Extension,Load,Strain 1,Tensile strain,Tensile stress
(sec),(mm),(N),,(%),(MPa)
0.00000,0.00000,-0.34030,0.00000,0.00000,-0.00537
0.10000,0.00078,0.61065,0.00000,0.00311,0.00963
0.20000,0.00395,2.97422,0.00000,0.01578,0.04690
0.30000,0.00975,11.15327,0.00000,0.03898,0.17586
0.40000,0.01525,16.62842,0.00000,0.06099,0.26220
0.50000,0.02015,20.33260,0.00000,0.08060,0.32060
0.60000,0.02469,22.65119,0.00000,0.09877,0.35716
0.70000,0.02906,26.57309,0.00000,0.11623,0.41900
0.80000,0.03336,28.93260,0.00000,0.13345,0.45621
0.90000,0.03743,32.14065,0.00000,0.14971,0.50679
1.00000,0.04149,35.10044,0.00000,0.16598,0.55346
1.10000,0.04574,38.32397,0.00000,0.18296,0.60429
1.20000,0.04992,39.76194,0.00000,0.19970,0.62696
1.30000,0.05423,42.81743,0.00000,0.21692,0.67514
1.40000,0.05835,45.83028,0.00000,0.23342,0.72265
1.50000,0.06242,48.52043,0.00000,0.24968,0.76507
1.60000,0.06655,51.43984,0.00000,0.26618,0.81110
1.70000,0.07073,54.44555,0.00000,0.28292,0.85849
1.80000,0.07504,58.06897,0.00000,0.30014,0.91563
1.90000,0.07922,60.40914,0.00000,0.31688,0.95253
2.00000,0.08335,64.35415,0.00000,0.33339,1.01473
2.10000,0.08747,66.93367,0.00000,0.34989,1.05540
2.20000,0.09160,69.83610,0.00000,0.36639,1.10117
2.30000,0.09584,73.29736,0.00000,0.38337,1.15575
2.40000,0.10009,76.38897,0.00000,0.40035,1.20449
2.50000,0.10427,79.22963,0.00000,0.41709,1.24928
2.60000,0.10834,82.60117,0.00000,0.43335,1.30245
2.70000,0.11240,86.27975,0.00000,0.44962,1.36045
2.80000,0.11659,89.38189,0.00000,0.46636,1.40936
2.90000,0.12077,93.25323,0.00000,0.48310,1.47041
3.00000,0.12502,97.03832,0.00000,0.50008,1.53009
3.10000,0.12921,100.79845,0.00000,0.51682,1.58938
3.20000,0.13327,104.14229,0.00000,0.53308,1.64210
3.30000,0.13740,108.30424,0.00000,0.54958,1.70773
3.40000,0.14158,111.46774,0.00000,0.56633,1.75761
3.50000,0.14583,115.76953,0.00000,0.58331,1.82544
3.60000,0.15007,119.86946,0.00000,0.60029,1.89009
3.70000,0.15426,124.48343,0.00000,0.61703,1.96284
3.80000,0.15838,128.15564,0.00000,0.63353,2.02075
3.90000,0.16239,133.11587,0.00000,0.64955,2.09896
4.00000,0.16663,137.63194,0.00000,0.66653,2.17017
4.10000,0.17082,143.25941,0.00000,0.68327,2.25890
4.20000,0.17506,148.16516,0.00000,0.70025,2.33625
4.30000,0.17925,153.75729,0.00000,0.71700,2.42443
4.40000,0.18325,158.31327,0.00000,0.73302,2.49627
4.50000,0.18738,163.82666,0.00000,0.74952,2.58320
4.60000,0.19163,169.45521,0.00000,0.76650,2.67195
4.70000,0.19587,174.76076,0.00000,0.78348,2.75561
4.80000,0.20018,180.07206,0.00000,0.80070,2.83936
4.90000,0.20418,185.77875,0.00000,0.81672,2.92934
5.00000,0.20825,192.09476,0.00000,0.83299,3.02893
5.10000,0.21237,197.02937,0.00000,0.84949,3.10674
5.20000,0.21656,202.85312,0.00000,0.86623,3.19857
5.30000,0.22092,209.10955,0.00000,0.88369,3.29722
5.40000,0.22505,214.69202,0.00000,0.90019,3.38524
5.50000,0.22905,221.35279,0.00000,0.91621,3.49027
5.60000,0.23318,227.89754,0.00000,0.93272,3.59346
5.70000,0.23736,234.16425,0.00000,0.94946,3.69228
5.80000,0.24167,240.98770,0.00000,0.96668,3.79987
5.90000,0.24591,247.58005,0.00000,0.98366,3.90382
6.00000,0.25004,253.92720,0.00000,1.00016,4.00390
6.10000,0.25411,260.56254,0.00000,1.01642,4.10852
6.20000,0.25823,267.70069,0.00000,1.03292,4.22108
6.30000,0.26248,274.35245,0.00000,1.04990,4.32596
6.40000,0.26672,281.78759,0.00000,1.06688,4.44320
6.50000,0.27091,288.37014,0.00000,1.08362,4.54699
6.60000,0.27503,295.35575,0.00000,1.10013,4.65714
6.70000,0.27904,303.00315,0.00000,1.11615,4.77772
6.80000,0.28328,311.03827,0.00000,1.13313,4.90442
6.90000,0.28747,317.90058,0.00000,1.14987,5.01262
7.00000,0.29165,326.35925,0.00000,1.16661,5.14600
7.10000,0.29584,334.54185,0.00000,1.18335,5.27502
7.20000,0.29996,343.20422,0.00000,1.19986,5.41161
7.30000,0.30409,352.39190,0.00000,1.21636,5.55648
7.40000,0.30827,361.24547,0.00000,1.23310,5.69608
7.50000,0.31246,370.64508,0.00000,1.24984,5.84429
7.60000,0.31665,380.32203,0.00000,1.26658,5.99688
7.70000,0.32089,390.27426,0.00000,1.28356,6.15380
7.80000,0.32496,399.27904,0.00000,1.29982,6.29579
7.90000,0.32908,409.59241,0.00000,1.31633,6.45841
8.00000,0.33327,419.65963,0.00000,1.33307,6.61715
8.10000,0.33745,430.83676,0.00000,1.34981,6.79339
8.20000,0.34170,439.83613,0.00000,1.36679,6.93529
8.30000,0.34594,451.09694,0.00000,1.38377,7.11285
8.40000,0.34995,461.13292,0.00000,1.39979,7.27110
8.50000,0.35407,471.28508,0.00000,1.41629,7.43117
8.60000,0.35826,482.23794,0.00000,1.43303,7.60388
8.70000,0.36250,493.03733,0.00000,1.45001,7.77416
8.80000,0.36681,504.98373,0.00000,1.46723,7.96253
8.90000,0.37087,515.34423,0.00000,1.48350,8.12589
9.00000,0.37494,525.59641,0.00000,1.49976,8.28755
9.10000,0.37901,536.74825,0.00000,1.51602,8.46339
9.20000,0.38325,547.35537,0.00000,1.53300,8.63064
9.30000,0.38756,558.76425,0.00000,1.55022,8.81054
9.40000,0.39174,569.84476,0.00000,1.56696,8.98525
9.50000,0.39581,579.77741,0.00000,1.58323,9.14187
9.60000,0.39987,591.08865,0.00000,1.59949,9.32022
9.70000,0.40406,602.42200,0.00000,1.61623,9.49893
9.80000,0.40830,614.22759,0.00000,1.63321,9.68508
9.90000,0.41255,624.96015,0.00000,1.65019,9.85431
10.00000,0.41673,635.83553,0.00000,1.66693,10.02579
10.10000,0.42074,647.08041,0.00000,1.68295,10.20310
10.20000,0.42486,658.58690,0.00000,1.69946,10.38453
10.30000,0.42917,671.26225,0.00000,1.71668,10.58439
10.40000,0.43335,683.00250,0.00000,1.73342,10.76951
10.50000,0.43754,694.38163,0.00000,1.75016,10.94894
10.60000,0.44172,704.93342,0.00000,1.76690,11.11532
10.70000,0.44579,716.52727,0.00000,1.78316,11.29813
10.80000,0.44998,728.58306,0.00000,1.79990,11.48822
10.90000,0.45416,739.96573,0.00000,1.81664,11.66770
11.00000,0.45835,752.04554,0.00000,1.83339,11.85818
11.10000,0.46253,762.87473,0.00000,1.85013,12.02893
11.20000,0.46666,774.87673,0.00000,1.86663,12.21818
11.30000,0.47078,787.46751,0.00000,1.88313,12.41671
11.40000,0.47491,798.60389,0.00000,1.89963,12.59230
11.50000,0.47909,810.20324,0.00000,1.91637,12.77520
11.60000,0.48328,821.87075,0.00000,1.93311,12.95917
11.70000,0.48752,834.05171,0.00000,1.95009,13.15124
11.80000,0.49171,845.60569,0.00000,1.96683,13.33342
11.90000,0.49577,858.04956,0.00000,1.98310,13.52964
12.00000,0.49990,870.25482,0.00000,1.99960,13.72209
12.10000,0.50409,882.02348,0.00000,2.01634,13.90765
12.20000,0.50833,894.39377,0.00000,2.03332,14.10271
12.30000,0.51258,906.08578,0.00000,2.05030,14.28707
12.40000,0.51658,918.20797,0.00000,2.06632,14.47821
12.50000,0.52071,929.25169,0.00000,2.08283,14.65234
12.60000,0.52489,941.92801,0.00000,2.09957,14.85222
12.70000,0.52914,953.44754,0.00000,2.11655,15.03386
12.80000,0.53344,965.61657,0.00000,2.13377,15.22574
12.90000,0.53757,977.22923,0.00000,2.15027,15.40885
13.00000,0.54157,989.20185,0.00000,2.16629,15.59763
13.10000,0.54570,1001.07240,0.00000,2.18279,15.78481
13.20000,0.54994,1013.82388,0.00000,2.19977,15.98587
13.30000,0.55419,1026.74970,0.00000,2.21676,16.18968
13.40000,0.55837,1038.72074,0.00000,2.23350,16.37844
13.50000,0.56250,1049.84855,0.00000,2.25000,16.55390
13.60000,0.56657,1061.32049,0.00000,2.26626,16.73479
13.70000,0.57069,1073.99868,0.00000,2.28276,16.93470
13.80000,0.57500,1085.37069,0.00000,2.29998,17.11401
13.90000,0.57918,1097.50386,0.00000,2.31672,17.30533
14.00000,0.58343,1108.30851,0.00000,2.33370,17.47569
14.10000,0.58749,1120.23223,0.00000,2.34997,17.66371
14.20000,0.59156,1130.64339,0.00000,2.36623,17.82787
14.30000,0.59580,1142.85043,0.00000,2.38321,18.02035
14.40000,0.59999,1154.36148,0.00000,2.39995,18.20185
14.50000,0.60417,1166.16916,0.00000,2.41669,18.38803
14.60000,0.60836,1177.59192,0.00000,2.43343,18.56815
14.70000,0.61242,1187.74557,0.00000,2.44970,18.72825
14.80000,0.61661,1199.47139,0.00000,2.46644,18.91314
14.90000,0.62079,1210.62621,0.00000,2.48318,19.08903
15.00000,0.62498,1223.29229,0.00000,2.49992,19.28875
15.10000,0.62922,1235.03646,0.00000,2.51690,19.47393
15.20000,0.63335,1245.50965,0.00000,2.53340,19.63907
15.30000,0.63748,1256.33683,0.00000,2.54990,19.80979
15.40000,0.64160,1268.42847,0.00000,2.56640,20.00045
15.50000,0.64579,1279.41901,0.00000,2.58315,20.17375
15.60000,0.65003,1293.15034,0.00000,2.60013,20.39026
15.70000,0.65422,1304.43443,0.00000,2.61687,20.56819
15.80000,0.65828,1315.47805,0.00000,2.63313,20.74232
15.90000,0.66241,1326.85574,0.00000,2.64963,20.92172
16.00000,0.66647,1338.25568,0.00000,2.66589,21.10148
16.10000,0.67078,1350.78309,0.00000,2.68311,21.29901
16.20000,0.67502,1363.36312,0.00000,2.70009,21.49737
16.30000,0.67927,1375.16782,0.00000,2.71707,21.68350
16.40000,0.68333,1384.97939,0.00000,2.73334,21.83821
16.50000,0.68740,1397.07047,0.00000,2.74960,22.02886
16.60000,0.69159,1409.36170,0.00000,2.76634,22.22267
16.70000,0.69583,1421.13855,0.00000,2.78332,22.40837
16.80000,0.70013,1433.42614,0.00000,2.80054,22.60212
16.90000,0.70432,1444.76909,0.00000,2.81728,22.78097
17.00000,0.70827,1456.31842,0.00000,2.83307,22.96308
17.10000,0.71239,1468.66441,0.00000,2.84957,23.15775
17.20000,0.71658,1481.08378,0.00000,2.86631,23.35358
17.30000,0.72088,1493.65785,0.00000,2.88353,23.55184
17.40000,0.72513,1505.71372,0.00000,2.90051,23.74194
17.50000,0.72919,1517.33272,0.00000,2.91677,23.92515
17.60000,0.73326,1528.78594,0.00000,2.93303,24.10574
17.70000,0.73732,1541.29518,0.00000,2.94930,24.30298
17.80000,0.74157,1552.68805,0.00000,2.96628,24.48262
17.90000,0.74587,1566.32066,0.00000,2.98350,24.69758
18.00000,0.75006,1577.41327,0.00000,3.00024,24.87249
18.10000,0.75412,1589.64694,0.00000,3.01650,25.06539
18.20000,0.75819,1600.82877,0.00000,3.03276,25.24170
18.30000,0.76238,1612.79757,0.00000,3.04950,25.43043
18.40000,0.76662,1624.19621,0.00000,3.06648,25.61016
18.50000,0.77087,1637.45955,0.00000,3.08346,25.81929
18.60000,0.77511,1648.89377,0.00000,3.10044,25.99959
18.70000,0.77912,1660.38387,0.00000,3.11647,26.18076
18.80000,0.78324,1674.05736,0.00000,3.13297,26.39636
18.90000,0.78743,1688.28163,0.00000,3.14971,26.62065
19.00000,0.79161,1701.79196,0.00000,3.16645,26.83368
19.10000,0.79598,1717.26793,0.00000,3.18391,27.07770
19.20000,0.80010,1729.37978,0.00000,3.20041,27.26868
19.30000,0.80417,1742.09233,0.00000,3.21667,27.46913
19.40000,0.80817,1755.45197,0.00000,3.23270,27.67978
19.50000,0.81242,1768.87549,0.00000,3.24968,27.89145
19.60000,0.81672,1783.50210,0.00000,3.26690,28.12208
19.70000,0.82091,1796.66094,0.00000,3.28364,28.32956
19.80000,0.82509,1809.27627,0.00000,3.30038,28.52848
19.90000,0.82904,1821.42369,0.00000,3.31616,28.72002
20.00000,0.83317,1834.80084,0.00000,3.33267,28.93095
20.10000,0.83747,1849.87150,0.00000,3.34989,29.16858
20.20000,0.84172,1863.90895,0.00000,3.36687,29.38992
20.30000,0.84590,1876.84782,0.00000,3.38361,29.59394
20.40000,0.85003,1890.19665,0.00000,3.40011,29.80443
20.50000,0.85403,1903.48141,0.00000,3.41613,30.01390
20.60000,0.85828,1917.63155,0.00000,3.43311,30.23702
20.70000,0.86246,1931.03906,0.00000,3.44985,30.44842
20.80000,0.86677,1946.18087,0.00000,3.46707,30.68718
20.90000,0.87095,1959.53455,0.00000,3.48381,30.89774
21.00000,0.87490,1971.67154,0.00000,3.49960,31.08911
21.10000,0.87908,1986.15510,0.00000,3.51634,31.31749
21.20000,0.88321,1999.58235,0.00000,3.53284,31.52921
21.30000,0.88746,2013.66302,0.00000,3.54982,31.75123
21.40000,0.89176,2027.63211,0.00000,3.56704,31.97149
21.50000,0.89595,2040.68329,0.00000,3.58378,32.17728
21.60000,0.89995,2053.54188,0.00000,3.59981,32.38004
21.70000,0.90408,2067.09970,0.00000,3.61631,32.59381
21.80000,0.90826,2080.04843,0.00000,3.63305,32.79799
21.90000,0.91251,2093.75303,0.00000,3.65003,33.01408
22.00000,0.91669,2108.03691,0.00000,3.66677,33.23931
22.10000,0.92088,2121.26840,0.00000,3.68351,33.44794
22.20000,0.92488,2134.21844,0.00000,3.69953,33.65213
22.30000,0.92907,2148.51759,0.00000,3.71628,33.87760
22.40000,0.93325,2161.58424,0.00000,3.73302,34.08364
22.50000,0.93750,2175.39780,0.00000,3.75000,34.30145
22.60000,0.94174,2188.69839,0.00000,3.76698,34.51117
22.70000,0.94581,2201.34649,0.00000,3.78324,34.71061
22.80000,0.94988,2214.27940,0.00000,3.79950,34.91453
22.90000,0.95400,2227.59433,0.00000,3.81600,35.12448
23.00000,0.95825,2240.72710,0.00000,3.83299,35.33155
23.10000,0.96255,2254.50303,0.00000,3.85020,35.54877
23.20000,0.96674,2267.53987,0.00000,3.86695,35.75433
23.30000,0.97080,2280.15780,0.00000,3.88321,35.95329
23.40000,0.97493,2292.92922,0.00000,3.89971,36.15467
23.50000,0.97911,2306.22347,0.00000,3.91645,36.36429
23.60000,0.98330,2319.94372,0.00000,3.93319,36.58063
23.70000,0.98754,2333.68687,0.00000,3.95017,36.79733
23.80000,0.99173,2346.27500,0.00000,3.96691,36.99582
23.90000,0.99573,2358.24957,0.00000,3.98294,37.18464
24.00000,0.99992,2371.47491,0.00000,3.99968,37.39317
24.10000,1.00416,2384.95935,0.00000,4.01666,37.60579
24.20000,1.00829,2398.32569,0.00000,4.03316,37.81655
24.30000,1.01253,2411.78796,0.00000,4.05014,38.02882
24.40000,1.01666,2423.36355,0.00000,4.06664,38.21135
24.50000,1.02073,2435.74865,0.00000,4.08290,38.40663
24.60000,1.02497,2448.83597,0.00000,4.09989,38.61299
24.70000,1.02910,2461.24957,0.00000,4.11639,38.80873
24.80000,1.03334,2475.11026,0.00000,4.13337,39.02728
24.90000,1.03753,2487.01628,0.00000,4.15011,39.21502
25.00000,1.04165,2499.50942,0.00000,4.16661,39.41201
25.10000,1.04584,2511.85223,0.00000,4.18335,39.60662
25.20000,1.04996,2523.83836,0.00000,4.19985,39.79562
25.30000,1.05415,2536.93927,0.00000,4.21659,40.00220
25.40000,1.05833,2550.26333,0.00000,4.23334,40.21229
25.50000,1.06252,2561.88903,0.00000,4.25008,40.39560
25.60000,1.06670,2574.77928,0.00000,4.26682,40.59885
25.70000,1.07083,2587.45030,0.00000,4.28332,40.79865
25.80000,1.07496,2600.16192,0.00000,4.29982,40.99908
25.90000,1.07914,2612.48145,0.00000,4.31656,41.19334
26.00000,1.08333,2625.82991,0.00000,4.33330,41.40382
26.10000,1.08757,2638.14721,0.00000,4.35028,41.59803
26.20000,1.09164,2649.50991,0.00000,4.36655,41.77720
26.30000,1.09576,2661.40755,0.00000,4.38305,41.96480
26.40000,1.09995,2674.68430,0.00000,4.39979,42.17414
26.50000,1.10413,2686.53333,0.00000,4.41653,42.36098
26.60000,1.10838,2700.53670,0.00000,4.43351,42.58178
26.70000,1.11250,2712.08063,0.00000,4.45001,42.76381
26.80000,1.11657,2724.80305,0.00000,4.46627,42.96441
26.90000,1.12075,2737.54951,0.00000,4.48302,43.16540
27.00000,1.12494,2749.76138,0.00000,4.49976,43.35795
27.10000,1.12924,2762.88390,0.00000,4.51698,43.56487
27.20000,1.13337,2775.73466,0.00000,4.53348,43.76750
27.30000,1.13744,2787.70737,0.00000,4.54974,43.95628
27.40000,1.14156,2799.57093,0.00000,4.56624,44.14334
27.50000,1.14575,2811.71352,0.00000,4.58298,44.33481
27.60000,1.14999,2823.65326,0.00000,4.59996,44.52307
27.70000,1.15418,2836.35668,0.00000,4.61671,44.72338
27.80000,1.15836,2847.93135,0.00000,4.63345,44.90589
27.90000,1.16249,2859.80850,0.00000,4.64995,45.09317
28.00000,1.16661,2871.50815,0.00000,4.66645,45.27765
28.10000,1.17086,2883.62615,0.00000,4.68343,45.46872
28.20000,1.17498,2895.09930,0.00000,4.69993,45.64963
28.30000,1.17923,2908.05288,0.00000,4.71691,45.85388
28.40000,1.18335,2918.26651,0.00000,4.73341,46.01492
28.50000,1.18742,2930.24853,0.00000,4.74968,46.20386
28.60000,1.19160,2942.31325,0.00000,4.76642,46.39409
28.70000,1.19579,2954.10249,0.00000,4.78316,46.57998
28.80000,1.19998,2966.37118,0.00000,4.79990,46.77343
28.90000,1.20416,2979.24299,0.00000,4.81664,46.97639
29.00000,1.20829,2990.02621,0.00000,4.83314,47.14642
29.10000,1.21241,3001.97136,0.00000,4.84965,47.33477
29.20000,1.21660,3014.21806,0.00000,4.86639,47.52788
29.30000,1.22078,3026.11180,0.00000,4.88313,47.71542
29.40000,1.22503,3038.66956,0.00000,4.90011,47.91343
29.50000,1.22921,3050.05852,0.00000,4.91685,48.09301
29.60000,1.23334,3061.30983,0.00000,4.93335,48.27042
29.70000,1.23740,3072.55592,0.00000,4.94961,48.44774
29.76000,1.24045,5.95648,0.00000,4.96181,0.09392