File: Tração/Dados/Specimen_RawData_4.csv
Time,Extension,Load,Strain 1,Tensile strain,Tensile stress
(sec),(mm),(N),,(%),(MPa)
0.00000,0.00000,-0.76132,0.00000,0.00000,-0.01259
0.10000,0.00102,0.73940,0.00000,0.00407,0.01223
0.20000,0.00508,9.81419,0.00000,0.02033,0.16227
0.30000,0.01058,23.12683,0.00000,0.04233,0.38239
0.40000,0.01578,35.60071,0.00000,0.06314,0.58864
0.50000,0.02039,45.14206,0.00000,0.08155,0.74640
0.60000,0.02469,52.19986,0.00000,0.09877,0.86309
0.70000,0.02900,59.70094,0.00000,0.11599,0.98712
0.80000,0.03330,65.98484,0.00000,0.13321,1.09102
0.90000,0.03755,72.91143,0.00000,0.15019,1.20555
1.00000,0.04179,79.46631,0.00000,0.16717,1.31393
1.10000,0.04586,85.90787,0.00000,0.18343,1.42043
1.20000,0.04992,92.88482,0.00000,0.19970,1.53579
1.30000,0.05417,99.14762,0.00000,0.21668,1.63935
1.40000,0.05835,105.49966,0.00000,0.23342,1.74437
1.50000,0.06260,112.90696,0.00000,0.25040,1.86685
1.60000,0.06678,119.95592,0.00000,0.26714,1.98340
1.70000,0.07085,125.64678,0.00000,0.28340,2.07749
1.80000,0.07504,132.28662,0.00000,0.30014,2.18728
1.90000,0.07910,138.99534,0.00000,0.31641,2.29820
2.00000,0.08335,144.88512,0.00000,0.33339,2.39559
2.10000,0.08759,151.59453,0.00000,0.35037,2.50652
2.20000,0.09172,157.56277,0.00000,0.36687,2.60520
2.30000,0.09590,164.73989,0.00000,0.38361,2.72387
2.40000,0.10003,171.14254,0.00000,0.40011,2.82974
2.50000,0.10415,177.92047,0.00000,0.41661,2.94181
2.60000,0.10834,185.02250,0.00000,0.43335,3.05923
2.70000,0.11258,190.96314,0.00000,0.45033,3.15746
2.80000,0.11677,198.04402,0.00000,0.46708,3.27454
2.90000,0.12083,204.42219,0.00000,0.48334,3.38000
3.00000,0.12496,211.50291,0.00000,0.49984,3.49707
3.10000,0.12921,218.30779,0.00000,0.51682,3.60959
3.20000,0.13333,224.50632,0.00000,0.53332,3.71208
3.30000,0.13770,231.40770,0.00000,0.55078,3.82619
3.40000,0.14170,236.86762,0.00000,0.56680,3.91646
3.50000,0.14583,243.19575,0.00000,0.58331,4.02109
3.60000,0.15001,250.30368,0.00000,0.60005,4.13862
3.70000,0.15420,255.81180,0.00000,0.61679,4.22969
3.80000,0.15844,263.33558,0.00000,0.63377,4.35409
3.90000,0.16263,269.78420,0.00000,0.65051,4.46072
4.00000,0.16663,276.79119,0.00000,0.66653,4.57657
4.10000,0.17076,283.70922,0.00000,0.68304,4.69096
4.20000,0.17494,290.75013,0.00000,0.69978,4.80738
4.30000,0.17925,298.06446,0.00000,0.71700,4.92831
4.40000,0.18349,305.43071,0.00000,0.73398,5.05011
4.50000,0.18756,312.17483,0.00000,0.75024,5.16162
4.60000,0.19163,321.13548,0.00000,0.76650,5.30978
4.70000,0.19581,329.69976,0.00000,0.78324,5.45139
4.80000,0.20006,338.72377,0.00000,0.80022,5.60059
4.90000,0.20424,349.05497,0.00000,0.81696,5.77141
5.00000,0.20843,358.32173,0.00000,0.83370,5.92463
5.10000,0.21249,368.16208,0.00000,0.84997,6.08734
5.20000,0.21656,378.15617,0.00000,0.86623,6.25258
5.30000,0.22080,387.90400,0.00000,0.88321,6.41376
5.40000,0.22505,398.19116,0.00000,0.90019,6.58385
5.50000,0.22923,407.48194,0.00000,0.91693,6.73747
5.60000,0.23342,418.72589,0.00000,0.93367,6.92338
5.70000,0.23754,428.16903,0.00000,0.95017,7.07951
5.80000,0.24167,438.75431,0.00000,0.96668,7.25454
5.90000,0.24585,449.74159,0.00000,0.98342,7.43620
6.00000,0.25004,460.63988,0.00000,1.00016,7.61640
6.10000,0.25422,471.74161,0.00000,1.01690,7.79996
6.20000,0.25841,481.26411,0.00000,1.03364,7.95741
6.30000,0.26254,492.17637,0.00000,1.05014,8.13784
6.40000,0.26666,502.66073,0.00000,1.06664,8.31119
6.50000,0.27079,513.32549,0.00000,1.08315,8.48752
6.60000,0.27503,524.40595,0.00000,1.10013,8.67073
6.70000,0.27928,534.07019,0.00000,1.11711,8.83053
6.80000,0.28352,543.69615,0.00000,1.13409,8.98969
6.90000,0.28753,553.18563,0.00000,1.15011,9.14659
7.00000,0.29165,564.51838,0.00000,1.16661,9.33397
7.10000,0.29584,574.85211,0.00000,1.18335,9.50483
7.20000,0.30008,585.11994,0.00000,1.20033,9.67460
7.30000,0.30433,596.64608,0.00000,1.21731,9.86518
7.40000,0.30839,606.43996,0.00000,1.23358,10.02712
7.50000,0.31246,617.22291,0.00000,1.24984,10.20541
7.60000,0.31665,628.91259,0.00000,1.26658,10.39869
7.70000,0.32083,640.65452,0.00000,1.28332,10.59283
7.80000,0.32514,654.13872,0.00000,1.30054,10.81579
7.90000,0.32938,665.38844,0.00000,1.31752,11.00179
8.00000,0.33339,677.10136,0.00000,1.33354,11.19546
8.10000,0.33745,689.00604,0.00000,1.34981,11.39230
8.20000,0.34158,701.59743,0.00000,1.36631,11.60049
8.30000,0.34594,713.61866,0.00000,1.38377,11.79925
8.40000,0.35019,724.71215,0.00000,1.40075,11.98267
8.50000,0.35425,733.46649,0.00000,1.41701,12.12742
8.60000,0.35832,737.91086,0.00000,1.43327,12.20091
8.70000,0.36238,744.72227,0.00000,1.44954,12.31353
8.80000,0.36657,755.81777,0.00000,1.46628,12.49699
8.90000,0.37087,768.60161,0.00000,1.48350,12.70836
9.00000,0.37512,780.07439,0.00000,1.50048,12.89806
9.10000,0.37924,789.81193,0.00000,1.51698,13.05906
9.20000,0.38331,803.33641,0.00000,1.53324,13.28268
9.30000,0.38750,814.46003,0.00000,1.54998,13.46660
9.40000,0.39168,825.89127,0.00000,1.56672,13.65561
9.50000,0.39593,838.61742,0.00000,1.58370,13.86603
9.60000,0.40017,850.66557,0.00000,1.60068,14.06524
9.70000,0.40424,862.73467,0.00000,1.61695,14.26479
9.80000,0.40830,876.48714,0.00000,1.63321,14.49218
9.90000,0.41249,888.89394,0.00000,1.64995,14.69732
10.00000,0.41667,901.20723,0.00000,1.66669,14.90091
10.10000,0.42098,914.14871,0.00000,1.68391,15.11489
10.20000,0.42516,927.47221,0.00000,1.70065,15.33519
10.30000,0.42923,940.57564,0.00000,1.71691,15.55185
10.40000,0.43329,953.72126,0.00000,1.73318,15.76920
10.50000,0.43742,967.20802,0.00000,1.74968,15.99220
10.60000,0.44166,981.23904,0.00000,1.76666,16.22419
10.70000,0.44591,996.12651,0.00000,1.78364,16.47035
10.80000,0.45010,1011.17138,0.00000,1.80038,16.71910
10.90000,0.45416,1025.65000,0.00000,1.81664,16.95850
11.00000,0.45823,1040.93924,0.00000,1.83291,17.21130
11.10000,0.46241,1056.41168,0.00000,1.84965,17.46712
11.20000,0.46672,1071.38231,0.00000,1.86687,17.71465
11.30000,0.47102,1085.84780,0.00000,1.88409,17.95383
11.40000,0.47515,1099.78849,0.00000,1.90059,18.18433
11.50000,0.47915,1114.40923,0.00000,1.91661,18.42608
11.60000,0.48328,1129.81228,0.00000,1.93311,18.68076
11.70000,0.48746,1144.28578,0.00000,1.94985,18.92007
11.80000,0.49183,1159.26545,0.00000,1.96731,19.16775
11.90000,0.49601,1173.03841,0.00000,1.98405,19.39548
12.00000,0.50008,1186.74403,0.00000,2.00032,19.62209
12.10000,0.50414,1203.00185,0.00000,2.01658,19.89090
12.20000,0.50827,1217.01360,0.00000,2.03308,20.12258
12.30000,0.51258,1231.71927,0.00000,2.05030,20.36573
12.40000,0.51682,1246.49378,0.00000,2.06728,20.61002
12.50000,0.52101,1260.02431,0.00000,2.08402,20.83373
12.60000,0.52501,1274.02684,0.00000,2.10005,21.06526
12.70000,0.52908,1285.96146,0.00000,2.11631,21.26259
12.80000,0.53332,1279.67959,0.00000,2.13329,21.15872
12.90000,0.53751,1281.28324,0.00000,2.15003,21.18524
13.00000,0.54175,1299.18158,0.00000,2.16701,21.48118
13.10000,0.54594,1316.63363,0.00000,2.18375,21.76974
13.20000,0.54994,1330.34205,0.00000,2.19977,21.99640
13.30000,0.55413,1345.10743,0.00000,2.21652,22.24053
13.40000,0.55831,1359.22218,0.00000,2.23326,22.47391
13.50000,0.56256,1372.34470,0.00000,2.25024,22.69088
13.60000,0.56686,1387.30220,0.00000,2.26746,22.93820
13.70000,0.57093,1399.77206,0.00000,2.28372,23.14438
13.80000,0.57494,1413.54250,0.00000,2.29974,23.37206
13.90000,0.57906,1428.00994,0.00000,2.31624,23.61127
14.00000,0.58331,1442.42728,0.00000,2.33322,23.84966
14.10000,0.58761,1457.46237,0.00000,2.35044,24.09825
14.20000,0.59180,1470.91141,0.00000,2.36719,24.32063
14.30000,0.59592,1484.67971,0.00000,2.38369,24.54827
14.40000,0.59993,1499.31023,0.00000,2.39971,24.79018
14.50000,0.60411,1513.90592,0.00000,2.41645,25.03151
14.60000,0.60836,1529.32983,0.00000,2.43343,25.28654
14.70000,0.61260,1543.99881,0.00000,2.45041,25.52908
14.80000,0.61679,1557.56772,0.00000,2.46715,25.75344
14.90000,0.62085,1572.04550,0.00000,2.48342,25.99282
15.00000,0.62492,1587.49167,0.00000,2.49968,26.24821
15.10000,0.62916,1602.66906,0.00000,2.51666,26.49916
15.20000,0.63335,1617.98336,0.00000,2.53340,26.75237
15.30000,0.63765,1633.16652,0.00000,2.55062,27.00341
15.40000,0.64178,1648.28487,0.00000,2.56712,27.25339
15.50000,0.64579,1662.56912,0.00000,2.58315,27.48957
15.60000,0.64991,1679.39812,0.00000,2.59965,27.76783
15.70000,0.65410,1697.96087,0.00000,2.61639,28.07475
15.80000,0.65840,1715.84543,0.00000,2.63361,28.37046
15.90000,0.66259,1732.69436,0.00000,2.65035,28.64905
16.00000,0.66671,1749.32182,0.00000,2.66685,28.92397
16.10000,0.67084,1766.93667,0.00000,2.68335,29.21522
16.20000,0.67502,1784.49713,0.00000,2.70009,29.50557
16.30000,0.67921,1800.85208,0.00000,2.71683,29.77599
16.40000,0.68339,1817.64308,0.00000,2.73358,30.05362
16.50000,0.68764,1836.27792,0.00000,2.75056,30.36174
16.60000,0.69170,1853.18943,0.00000,2.76682,30.64136
16.70000,0.69577,1870.60330,0.00000,2.78308,30.92929
16.80000,0.70002,1888.08832,0.00000,2.80006,31.21839
16.90000,0.70420,1905.40347,0.00000,2.81680,31.50469
17.00000,0.70839,1923.02857,0.00000,2.83354,31.79611
17.10000,0.71257,1941.69991,0.00000,2.85028,32.10483
17.20000,0.71664,1957.73859,0.00000,2.86655,32.37002
17.30000,0.72076,1976.98679,0.00000,2.88305,32.68827
17.40000,0.72495,1993.85770,0.00000,2.89979,32.96722
17.50000,0.72919,2011.76163,0.00000,2.91677,33.26326
17.60000,0.73344,2030.38491,0.00000,2.93375,33.57118
17.70000,0.73756,2046.35877,0.00000,2.95025,33.83530
17.80000,0.74163,2063.51876,0.00000,2.96652,34.11903
17.90000,0.74581,2080.27698,0.00000,2.98326,34.39611
18.00000,0.74994,2097.59958,0.00000,2.99976,34.68253
18.10000,0.75424,2112.81106,0.00000,3.01698,34.93404
18.20000,0.75843,2124.03759,0.00000,3.03372,35.11967
18.30000,0.76256,2130.33371,0.00000,3.05022,35.22377
18.40000,0.76668,2147.57621,0.00000,3.06672,35.50887
18.50000,0.77087,2169.83221,0.00000,3.08346,35.87685
18.60000,0.77505,2193.30918,0.00000,3.10020,36.26503
18.70000,0.77924,2213.58072,0.00000,3.11695,36.60021
18.80000,0.78342,2232.55847,0.00000,3.13369,36.91400
18.90000,0.78755,2250.40056,0.00000,3.15019,37.20900
19.00000,0.79155,2268.49783,0.00000,3.16621,37.50823
19.10000,0.79586,2286.99706,0.00000,3.18343,37.81411
19.20000,0.80004,2304.99394,0.00000,3.20017,38.11167
19.30000,0.80423,2323.21993,0.00000,3.21691,38.41303
19.40000,0.80841,2342.29099,0.00000,3.23365,38.72836
19.50000,0.81248,2360.20833,0.00000,3.24992,39.02461
19.60000,0.81666,2379.96876,0.00000,3.26666,39.35133
19.70000,0.82085,2397.05183,0.00000,3.28340,39.63379
19.80000,0.82498,2414.39864,0.00000,3.29990,39.92061
19.90000,0.82922,2431.23230,0.00000,3.31688,40.19895
20.00000,0.83341,2444.27677,0.00000,3.33362,40.41463
20.10000,0.83753,2460.45366,0.00000,3.35012,40.68211
20.20000,0.84166,2476.55008,0.00000,3.36663,40.94825
20.30000,0.84578,2493.08106,0.00000,3.38313,41.22158
20.40000,0.85003,2512.26015,0.00000,3.40011,41.53869
20.50000,0.85421,2530.08902,0.00000,3.41685,41.83348
20.60000,0.85846,2549.28153,0.00000,3.43383,42.15082
20.70000,0.86252,2567.70756,0.00000,3.45009,42.45548
20.80000,0.86665,2584.90108,0.00000,3.46659,42.73977
20.90000,0.87083,2603.36678,0.00000,3.48334,43.04509
21.00000,0.87508,2622.20427,0.00000,3.50032,43.35655
21.10000,0.87932,2641.34705,0.00000,3.51730,43.67307
21.20000,0.88339,2658.19076,0.00000,3.53356,43.95157
21.30000,0.88746,2676.27910,0.00000,3.54982,44.25064
21.40000,0.89158,2695.43901,0.00000,3.56632,44.56744
21.50000,0.89583,2715.05658,0.00000,3.58330,44.89181
21.60000,0.90007,2734.23400,0.00000,3.60028,45.20890
21.70000,0.90426,2752.82655,0.00000,3.61703,45.51631
21.80000,0.90832,2770.37192,0.00000,3.63329,45.80642
21.90000,0.91239,2789.92616,0.00000,3.64955,46.12973
22.00000,0.91663,2808.39894,0.00000,3.66653,46.43517
22.10000,0.92094,2827.85166,0.00000,3.68375,46.75681
22.20000,0.92512,2846.30489,0.00000,3.70049,47.06192
22.30000,0.92925,2863.83145,0.00000,3.71699,47.35171
22.40000,0.93325,2881.63815,0.00000,3.73302,47.64613
22.50000,0.93744,2901.28887,0.00000,3.74976,47.97105
22.60000,0.94174,2920.78648,0.00000,3.76698,48.29343
22.70000,0.94593,2939.63980,0.00000,3.78372,48.60516
22.80000,0.95017,2958.55328,0.00000,3.80070,48.91788
22.90000,0.95424,2976.78467,0.00000,3.81696,49.21932
23.00000,0.95831,2995.67748,0.00000,3.83322,49.53170
23.10000,0.96255,3014.76177,0.00000,3.85020,49.84725
23.20000,0.96668,3033.87418,0.00000,3.86671,50.16327
23.30000,0.97086,3052.59041,0.00000,3.88345,50.47272
23.40000,0.97505,3070.76257,0.00000,3.90019,50.77319
23.50000,0.97911,3088.23138,0.00000,3.91645,51.06203
23.60000,0.98330,3106.55721,0.00000,3.93319,51.36503
23.70000,0.98748,3124.07129,0.00000,3.94993,51.65462
23.80000,0.99167,3139.79276,0.00000,3.96667,51.91456
23.90000,0.99591,3148.40302,0.00000,3.98365,52.05693
24.00000,1.00010,3125.73649,0.00000,4.00040,51.68215
24.10000,1.00422,3151.70139,0.00000,4.01690,52.11147
24.20000,1.00835,3184.08608,0.00000,4.03340,52.64693
24.30000,1.01248,3214.30229,0.00000,4.04990,53.14653
24.40000,1.01672,3242.95871,0.00000,4.06688,53.62035
24.50000,1.02097,3266.75400,0.00000,4.08386,54.01379
24.60000,1.02515,3285.80178,0.00000,4.10060,54.32873
24.70000,1.02922,3304.22744,0.00000,4.11686,54.63339
24.80000,1.03328,3322.83266,0.00000,4.13313,54.94102
24.90000,1.03747,3337.36613,0.00000,4.14987,55.18132
25.00000,1.04171,3347.59764,0.00000,4.16685,55.35049
25.10000,1.04608,3358.01728,0.00000,4.18431,55.52277
25.20000,1.05008,3374.61792,0.00000,4.20033,55.79725
25.30000,1.05409,3396.39112,0.00000,4.21635,56.15726
25.40000,1.05827,3422.46108,0.00000,4.23310,56.58831
25.50000,1.06252,3446.10699,0.00000,4.25008,56.97928
25.60000,1.06676,3467.71888,0.00000,4.26706,57.33662
25.70000,1.07101,3487.92672,0.00000,4.28404,57.67075
25.80000,1.07502,3504.74678,0.00000,4.30006,57.94886
25.90000,1.07908,3522.99139,0.00000,4.31632,58.25052
26.00000,1.08327,3539.90458,0.00000,4.33306,58.53017
26.10000,1.08757,3557.49764,0.00000,4.35028,58.82106
26.20000,1.09182,3575.26802,0.00000,4.36726,59.11488
26.30000,1.09594,3592.94973,0.00000,4.38377,59.40724
26.40000,1.09995,3611.08854,0.00000,4.39979,59.70715
26.50000,1.10407,3630.40417,0.00000,4.41629,60.02652
26.60000,1.10832,3649.24483,0.00000,4.43327,60.33804
26.70000,1.11256,3667.71333,0.00000,4.45025,60.64341
26.80000,1.11681,3686.98128,0.00000,4.46723,60.96199
26.90000,1.12087,3702.41255,0.00000,4.48349,61.21714
27.00000,1.12494,3717.86430,0.00000,4.49976,61.47263
27.10000,1.12912,3733.27769,0.00000,4.51650,61.72747
27.20000,1.13337,3748.03580,0.00000,4.53348,61.97149
27.30000,1.13761,3763.55276,0.00000,4.55046,62.22805
27.40000,1.14180,3778.18123,0.00000,4.56720,62.46993
27.50000,1.14587,3791.68428,0.00000,4.58346,62.69319
27.60000,1.14999,3808.73531,0.00000,4.59996,62.97512
27.70000,1.15412,3825.81800,0.00000,4.61647,63.25757
27.80000,1.15836,3843.51239,0.00000,4.63345,63.55014
27.90000,1.16261,3862.00882,0.00000,4.65043,63.85596
28.00000,1.16673,3879.25766,0.00000,4.66693,64.14117
28.10000,1.17092,3895.04097,0.00000,4.68367,64.40213
28.20000,1.17492,3911.42778,0.00000,4.69969,64.67308
28.30000,1.17917,3929.27229,0.00000,4.71667,64.96812
28.40000,1.18335,3947.32989,0.00000,4.73341,65.26670
28.50000,1.18754,3964.25053,0.00000,4.75016,65.54647
28.60000,1.19178,3981.65397,0.00000,4.76714,65.83423
28.70000,1.19585,3997.81317,0.00000,4.78340,66.10141
28.80000,1.19992,4014.65110,0.00000,4.79966,66.37981
28.90000,1.20416,4033.15686,0.00000,4.81664,66.68579
29.00000,1.20835,4050.17287,0.00000,4.83338,66.96714
29.10000,1.21265,4067.74431,0.00000,4.85060,67.25768
29.20000,1.21678,4083.37601,0.00000,4.86710,67.51614
29.30000,1.22078,4099.24686,0.00000,4.88313,67.77855
29.40000,1.22503,4116.39288,0.00000,4.90011,68.06205
29.50000,1.22921,4132.30881,0.00000,4.91685,68.32521
29.60000,1.23346,4149.38144,0.00000,4.93383,68.60750
29.70000,1.23764,4165.84872,0.00000,4.95057,68.87978
29.80000,1.24165,4182.50449,0.00000,4.96659,69.15517
29.90000,1.24577,4199.34578,0.00000,4.98310,69.43362
30.00000,1.24996,4215.65622,0.00000,4.99984,69.70331
30.10000,1.25414,4233.26641,0.00000,5.01658,69.99448
30.20000,1.25839,4250.55847,0.00000,5.03356,70.28040
30.30000,1.26251,4267.18928,0.00000,5.05006,70.55538
30.40000,1.26670,4283.33841,0.00000,5.06680,70.82240
30.50000,1.27077,4299.09118,0.00000,5.08306,71.08286
30.60000,1.27501,4314.44235,0.00000,5.10004,71.33668
30.70000,1.27926,4330.62837,0.00000,5.11702,71.60430
30.80000,1.28338,4346.59012,0.00000,5.13353,71.86823
30.90000,1.28751,4363.12705,0.00000,5.15003,72.14165
31.00000,1.29163,4378.96177,0.00000,5.16653,72.40347
31.10000,1.29588,4395.16455,0.00000,5.18351,72.67137
31.20000,1.30006,4410.34585,0.00000,5.20025,72.92239
31.30000,1.30419,4426.78444,0.00000,5.21675,73.19419
31.40000,1.30837,4443.34187,0.00000,5.23349,73.46796
31.50000,1.31250,4458.62934,0.00000,5.25000,73.72073
31.60000,1.31668,4474.98001,0.00000,5.26674,73.99107
31.70000,1.32087,4490.63033,0.00000,5.28348,74.24984
31.80000,1.32499,4506.06383,0.00000,5.29998,74.50502
31.90000,1.32918,4523.21991,0.00000,5.31672,74.78869
32.00000,1.33337,4538.24364,0.00000,5.33346,75.03709
32.10000,1.33749,4553.38620,0.00000,5.34996,75.28747
32.20000,1.34168,4568.77090,0.00000,5.36670,75.54185
32.30000,1.34580,4584.77549,0.00000,5.38321,75.80647
32.40000,1.34999,4599.87968,0.00000,5.39995,76.05621
32.50000,1.35417,4615.94276,0.00000,5.41669,76.32181
32.60000,1.35836,4630.82530,0.00000,5.43343,76.56788
32.70000,1.36248,4645.96637,0.00000,5.44993,76.81823
32.80000,1.36661,4662.00337,0.00000,5.46643,77.08339
32.90000,1.37085,4677.09973,0.00000,5.48341,77.33300
33.00000,1.37498,4692.56118,0.00000,5.49992,77.58865
33.10000,1.37922,4707.98500,0.00000,5.51690,77.84367
33.20000,1.38341,4722.14893,0.00000,5.53364,78.07786
33.30000,1.38753,4736.85674,0.00000,5.55014,78.32104
33.40000,1.39172,4752.79354,0.00000,5.56688,78.58455
33.50000,1.39585,4766.19974,0.00000,5.58338,78.80621
33.60000,1.40009,4782.20321,0.00000,5.60036,79.07082
33.70000,1.40422,4796.25463,0.00000,5.61686,79.30315
33.80000,1.40834,4809.84859,0.00000,5.63337,79.52792
33.90000,1.41253,4825.87591,0.00000,5.65011,79.79292
34.00000,1.41671,4840.55951,0.00000,5.66685,80.03571
34.10000,1.42090,4854.07524,0.00000,5.68359,80.25918
34.20000,1.42508,4869.72556,0.00000,5.70033,80.51795
34.30000,1.42927,4883.52440,0.00000,5.71707,80.74610
34.40000,1.43339,4898.21732,0.00000,5.73357,80.98904
34.50000,1.43752,4912.58539,0.00000,5.75007,81.22661
34.60000,1.44170,4926.47141,0.00000,5.76682,81.45621
34.70000,1.44589,4940.82868,0.00000,5.78356,81.69360
34.80000,1.45001,4954.14957,0.00000,5.80006,81.91385
34.90000,1.45420,4969.03174,0.00000,5.81680,82.15992
35.00000,1.45833,4982.29600,0.00000,5.83330,82.37923
35.10000,1.46251,4995.75399,0.00000,5.85004,82.60175
35.20000,1.46670,5008.75376,0.00000,5.86678,82.81670
35.30000,1.47088,5020.99283,0.00000,5.88352,83.01906
35.40000,1.47507,5031.06937,0.00000,5.90027,83.18567
35.50000,1.47925,4929.43041,0.00000,5.91701,81.50513
35.60000,1.48344,4918.60993,0.00000,5.93375,81.32623
35.70000,1.48762,4955.83937,0.00000,5.95049,81.94179
35.80000,1.49169,4992.03019,0.00000,5.96675,82.54018
35.90000,1.49593,5027.71996,0.00000,5.98373,83.13029
36.00000,1.50006,5060.63402,0.00000,6.00023,83.67451
36.10000,1.50418,5089.62199,0.00000,6.01674,84.15380
36.20000,1.50825,5115.12309,0.00000,6.03300,84.57545
36.30000,1.51249,5138.47172,0.00000,6.04998,84.96150
36.40000,1.51668,5159.44250,0.00000,6.06672,85.30824
36.50000,1.52087,5177.47700,0.00000,6.08346,85.60643
36.60000,1.52505,5193.11167,0.00000,6.10020,85.86494
36.70000,1.52912,5207.01334,0.00000,6.11647,86.09480
36.80000,1.53330,5224.37990,0.00000,6.13321,86.38194
36.90000,1.53755,5241.49239,0.00000,6.15019,86.66489
37.00000,1.54167,5258.10756,0.00000,6.16669,86.93961
37.10000,1.54586,5273.82828,0.00000,6.18343,87.19954
37.20000,1.55004,5288.51487,0.00000,6.20017,87.44238
37.30000,1.55417,5303.25621,0.00000,6.21667,87.68611
37.40000,1.55829,5316.98801,0.00000,6.23317,87.91316
37.50000,1.56248,5327.23144,0.00000,6.24992,88.08253
37.60000,1.56672,5339.53905,0.00000,6.26689,88.28603
37.70000,1.57091,5347.89115,0.00000,6.28364,88.42413
37.80000,1.57503,5356.55841,0.00000,6.30014,88.56744
37.90000,1.57922,5364.40276,0.00000,6.31688,88.69714
38.00000,1.58341,5371.71662,0.00000,6.33362,88.81807
38.10000,1.58759,5369.99330,0.00000,6.35036,88.78957
38.20000,1.59178,5278.78776,0.00000,6.36710,87.28154
38.30000,1.59590,5290.10445,0.00000,6.38360,87.46866
38.40000,1.60009,5317.65260,0.00000,6.40035,87.92415
38.50000,1.60409,5346.45952,0.00000,6.41637,88.40045
38.60000,1.60834,5375.01276,0.00000,6.43335,88.87257
38.70000,1.61252,5401.83336,0.00000,6.45009,89.31602
38.80000,1.61671,5426.59536,0.00000,6.46683,89.72545
38.90000,1.62095,5448.06048,0.00000,6.48381,90.08037
39.00000,1.62496,5463.53869,0.00000,6.49984,90.33629
39.10000,1.62914,5473.51912,0.00000,6.51658,90.50130
39.20000,1.63333,5474.14608,0.00000,6.53332,90.51167
39.30000,1.63757,5463.19932,0.00000,6.55030,90.33067
39.40000,1.64182,5462.60402,0.00000,6.56728,90.32083
39.50000,1.64589,5471.88856,0.00000,6.58354,90.47435
39.60000,1.65001,5486.07260,0.00000,6.60004,90.70887
39.70000,1.65414,5501.37088,0.00000,6.61654,90.96182
39.80000,1.65832,5516.13867,0.00000,6.63329,91.20599
39.90000,1.66257,5530.41808,0.00000,6.65027,91.44210
40.00000,1.66675,5543.53297,0.00000,6.66701,91.65894
40.10000,1.67088,5554.58441,0.00000,6.68351,91.84167
40.20000,1.67500,5563.83654,0.00000,6.70001,91.99465
40.30000,1.67919,5573.33939,0.00000,6.71675,92.15178
40.40000,1.68343,5582.46411,0.00000,6.73373,92.30265
40.50000,1.68762,5591.97254,0.00000,6.75047,92.45986
40.60000,1.69180,5601.03767,0.00000,6.76721,92.60975
40.70000,1.69587,5609.60062,0.00000,6.78348,92.75134
40.80000,1.69993,5618.66164,0.00000,6.79974,92.90115
40.90000,1.70424,5630.55463,0.00000,6.81696,93.09779
41.00000,1.70837,5640.83308,0.00000,6.83346,93.26775
41.10000,1.71255,5651.36373,0.00000,6.85020,93.44186
41.20000,1.71674,5661.99087,0.00000,6.86694,93.61758
41.30000,1.72080,5671.29031,0.00000,6.88321,93.77133
41.40000,1.72499,5681.71889,0.00000,6.89995,93.94376
41.50000,1.72917,5693.15702,0.00000,6.91669,94.13289
41.60000,1.73336,5704.11533,0.00000,6.93343,94.31408
41.70000,1.73760,5715.74867,0.00000,6.95041,94.50642
41.80000,1.74173,5725.28802,0.00000,6.96691,94.66415
41.90000,1.74585,5734.84451,0.00000,6.98341,94.82217
42.00000,1.75004,5745.33716,0.00000,7.00015,94.99565
42.10000,1.75422,5755.06911,0.00000,7.01689,95.15656
42.20000,1.75841,5765.60460,0.00000,7.03364,95.33076
42.30000,1.76265,5776.43253,0.00000,7.05062,95.50980
42.40000,1.76672,5785.32107,0.00000,7.06688,95.65676
42.50000,1.77085,5794.39364,0.00000,7.08338,95.80677
42.60000,1.77497,5804.57002,0.00000,7.09988,95.97504
42.70000,1.77916,5814.05051,0.00000,7.11662,96.13179
42.80000,1.78334,5824.41352,0.00000,7.13337,96.30313
42.90000,1.78759,5834.91586,0.00000,7.15034,96.47678
43.00000,1.79165,5843.90573,0.00000,7.16661,96.62543
43.10000,1.79578,5852.82706,0.00000,7.18311,96.77293
43.20000,1.79996,5862.23155,0.00000,7.19985,96.92843
43.30000,1.80415,5871.69416,0.00000,7.21659,97.08489
43.40000,1.80839,5883.06300,0.00000,7.23357,97.27287
43.50000,1.81258,5892.42652,0.00000,7.25031,97.42769
43.60000,1.81670,5901.01220,0.00000,7.26682,97.56965
43.70000,1.82083,5911.21837,0.00000,7.28332,97.73840
43.80000,1.82501,5919.89309,0.00000,7.30006,97.88183
43.90000,1.82926,5930.18606,0.00000,7.31704,98.05202
44.00000,1.83339,5939.21766,0.00000,7.33354,98.20135
44.10000,1.83757,5948.32823,0.00000,7.35028,98.35199
44.20000,1.84170,5956.71013,0.00000,7.36678,98.49058
44.30000,1.84582,5965.32449,0.00000,7.38328,98.63301
44.40000,1.85007,5974.83777,0.00000,7.40027,98.79031
44.50000,1.85425,5983.10083,0.00000,7.41701,98.92693
44.60000,1.85838,5992.94566,0.00000,7.43351,99.08971
44.70000,1.86250,6000.11721,0.00000,7.45001,99.20829
44.80000,1.86669,6009.29148,0.00000,7.46675,99.35998
44.90000,1.87093,6018.27651,0.00000,7.48373,99.50854
45.00000,1.87506,6026.24938,0.00000,7.50023,99.64037
45.10000,1.87918,6034.48115,0.00000,7.51674,99.77647
45.20000,1.88337,6043.76756,0.00000,7.53348,99.93002
45.30000,1.88743,6050.41757,0.00000,7.54974,100.03997
45.40000,1.89168,6059.65890,0.00000,7.56672,100.19277
45.50000,1.89586,6068.63722,0.00000,7.58346,100.34122
45.60000,1.90005,6076.25619,0.00000,7.60020,100.46720
45.70000,1.90424,6084.76661,0.00000,7.61694,100.60791
45.80000,1.90836,6091.46245,0.00000,7.63344,100.71863
45.90000,1.91255,6098.90744,0.00000,7.65019,100.84172
46.00000,1.91667,6107.52031,0.00000,7.66669,100.98413
46.10000,1.92080,6115.63623,0.00000,7.68319,101.11832
46.20000,1.92504,6123.67764,0.00000,7.70017,101.25128
46.30000,1.92923,6131.96529,0.00000,7.71691,101.38831
46.40000,1.93341,6138.67380,0.00000,7.73365,101.49924
46.50000,1.93754,6146.86795,0.00000,7.75015,101.63472
46.60000,1.94166,6153.69603,0.00000,7.76666,101.74762
46.70000,1.94585,6161.14214,0.00000,7.78340,101.87074
46.80000,1.95003,6168.91459,0.00000,7.80014,101.99925
46.90000,1.95428,6177.82027,0.00000,7.81712,102.14650
47.00000,1.95840,6183.65742,0.00000,7.83362,102.24301
47.10000,1.96247,6191.38852,0.00000,7.84988,102.37084
47.20000,1.96660,6198.78955,0.00000,7.86638,102.49321
47.30000,1.97078,6205.77447,0.00000,7.88313,102.60870
47.40000,1.97503,6213.88406,0.00000,7.90010,102.74279
47.50000,1.97921,6220.05872,0.00000,7.91685,102.84489
47.60000,1.98334,6227.65087,0.00000,7.93335,102.97042
47.70000,1.98746,6235.05563,0.00000,7.94985,103.09285
47.80000,1.99165,6241.56781,0.00000,7.96659,103.20052
47.90000,1.99589,6248.56725,0.00000,7.98357,103.31626
48.00000,2.00008,6255.70416,0.00000,8.00031,103.43427
48.10000,2.00420,6263.23894,0.00000,8.01681,103.55885
48.20000,2.00833,6269.16960,0.00000,8.03332,103.65691
48.30000,2.01251,6276.75354,0.00000,8.05006,103.78230
48.40000,2.01676,6283.41138,0.00000,8.06704,103.89239
48.50000,2.02094,6290.21004,0.00000,8.08378,104.00480
48.60000,2.02507,6297.10257,0.00000,8.10028,104.11876
48.70000,2.02926,6303.29847,0.00000,8.11702,104.22121
48.80000,2.03338,6309.75291,0.00000,8.13352,104.32793
48.90000,2.03757,6315.93317,0.00000,8.15026,104.43011
49.00000,2.04169,6322.21401,0.00000,8.16677,104.53396
49.10000,2.04588,6330.21221,0.00000,8.18351,104.66621
49.20000,2.05006,6336.63163,0.00000,8.20025,104.77235
49.30000,2.05419,6340.48134,0.00000,8.21675,104.83600
49.40000,2.05837,6347.02295,0.00000,8.23349,104.94416
49.50000,2.06256,6352.11319,0.00000,8.25023,105.02833
49.60000,2.06662,6358.11761,0.00000,8.26650,105.12761
49.70000,2.07087,6365.52647,0.00000,8.28348,105.25011
49.80000,2.07505,6370.94006,0.00000,8.30022,105.33961
49.90000,2.07918,6376.85806,0.00000,8.31672,105.43747
50.00000,2.08331,6382.67472,0.00000,8.33322,105.53365
50.10000,2.08749,6390.02547,0.00000,8.34996,105.65518
50.20000,2.09174,6396.12898,0.00000,8.36694,105.75610
50.30000,2.09586,6403.08186,0.00000,8.38344,105.87106
50.40000,2.10011,6408.22127,0.00000,8.40042,105.95604
50.50000,2.10417,6413.23701,0.00000,8.41669,106.03897
50.60000,2.10830,6419.38150,0.00000,8.43319,106.14056
50.70000,2.11254,6425.50811,0.00000,8.45017,106.24187
50.80000,2.11673,6431.45889,0.00000,8.46691,106.34026
50.90000,2.12097,6437.34336,0.00000,8.48389,106.43755
51.00000,2.12504,6442.32109,0.00000,8.50015,106.51986
51.10000,2.12910,6447.96938,0.00000,8.51642,106.61325
51.20000,2.13329,6455.02135,0.00000,8.53316,106.72985
51.30000,2.13747,6460.07210,0.00000,8.54990,106.81336
51.40000,2.14178,6465.94018,0.00000,8.56712,106.91039
51.50000,2.14596,6471.83582,0.00000,8.58386,107.00787
51.60000,2.14997,6476.51330,0.00000,8.59988,107.08521
51.70000,2.15416,6482.12656,0.00000,8.61662,107.17802
51.80000,2.15834,6488.32470,0.00000,8.63336,107.28050
51.90000,2.16253,6493.55948,0.00000,8.65010,107.36706
52.00000,2.16677,6499.58998,0.00000,8.66708,107.46677
52.10000,2.17090,6505.14290,0.00000,8.68359,107.55858
52.20000,2.17496,6510.61162,0.00000,8.69985,107.64900
52.30000,2.17915,6516.11686,0.00000,8.71659,107.74003
52.40000,2.18339,6521.44626,0.00000,8.73357,107.82815
52.50000,2.18758,6526.17365,0.00000,8.75031,107.90631
52.60000,2.19176,6533.12877,0.00000,8.76705,108.02131
52.70000,2.19589,6538.10799,0.00000,8.78356,108.10364
52.80000,2.19995,6542.14621,0.00000,8.79982,108.17041
52.90000,2.20420,6548.74146,0.00000,8.81680,108.27946
53.00000,2.20838,6553.44725,0.00000,8.83354,108.35726
53.10000,2.21257,6560.13340,0.00000,8.85028,108.46781
53.20000,2.21676,6566.07524,0.00000,8.86702,108.56606
53.30000,2.22088,6570.85627,0.00000,8.88352,108.64511
53.40000,2.22501,6575.61198,0.00000,8.90002,108.72374
53.50000,2.22913,6580.26338,0.00000,8.91653,108.80065
53.60000,2.23332,6586.25215,0.00000,8.93327,108.89967
53.70000,2.23756,6592.71479,0.00000,8.95025,109.00653
53.80000,2.24175,6597.63664,0.00000,8.96699,109.08791
53.90000,2.24587,6601.56682,0.00000,8.98349,109.15289
54.00000,2.25000,6607.50344,0.00000,8.99999,109.25105
54.10000,2.25412,6612.63019,0.00000,9.01649,109.33582
54.20000,2.25837,6619.01981,0.00000,9.03347,109.44147
54.30000,2.26255,6623.84704,0.00000,9.05022,109.52128
54.40000,2.26680,6629.39027,0.00000,9.06720,109.61294
54.50000,2.27086,6632.69758,0.00000,9.08346,109.66762
54.60000,2.27499,6637.84519,0.00000,9.09996,109.75273
54.70000,2.27918,6643.25282,0.00000,9.11670,109.84214
54.80000,2.28336,6648.62990,0.00000,9.13344,109.93105
54.90000,2.28767,6655.07838,0.00000,9.15066,110.03767
55.00000,2.29179,6659.19557,0.00000,9.16716,110.10574
55.10000,2.29586,6663.88124,0.00000,9.18343,110.18322
55.20000,2.30004,6669.25684,0.00000,9.20017,110.27210
55.30000,2.30417,6674.41264,0.00000,9.21667,110.35735
55.40000,2.30847,6680.64281,0.00000,9.23389,110.46037
55.50000,2.31266,6686.80966,0.00000,9.25063,110.56233
55.60000,2.31666,6691.33589,0.00000,9.26665,110.63717
55.70000,2.32079,6696.91414,0.00000,9.28316,110.72940
55.80000,2.32491,6702.23385,0.00000,9.29966,110.81736
55.90000,2.32916,6707.13410,0.00000,9.31664,110.89838
56.00000,2.33346,6714.32167,0.00000,9.33386,111.01723
56.10000,2.33759,6719.71366,0.00000,9.35036,111.10638
56.20000,2.34172,6724.62359,0.00000,9.36686,111.18756
56.30000,2.34578,6729.76971,0.00000,9.38312,111.27264
56.40000,2.35003,6735.71229,0.00000,9.40010,111.37090
56.50000,2.35421,6740.83084,0.00000,9.41684,111.45554
56.60000,2.35840,6747.63396,0.00000,9.43359,111.56802
56.70000,2.36258,6753.47745,0.00000,9.45033,111.66464
56.80000,2.36665,6757.26160,0.00000,9.46659,111.72721
56.90000,2.37083,6762.51650,0.00000,9.48333,111.81409
57.00000,2.37508,6768.33317,0.00000,9.50031,111.91027
57.10000,2.37926,6774.54919,0.00000,9.51705,112.01305
57.20000,2.38351,6781.29867,0.00000,9.53403,112.12465
57.30000,2.38751,6785.76902,0.00000,9.55006,112.19856
57.40000,2.39164,6789.99349,0.00000,9.56656,112.26841
57.50000,2.39582,6795.70362,0.00000,9.58330,112.36282
57.60000,2.40001,6801.53519,0.00000,9.60004,112.45924
57.70000,2.40420,6808.66614,0.00000,9.61678,112.57715
57.80000,2.40844,6813.52094,0.00000,9.63376,112.65742
57.90000,2.41257,6818.92708,0.00000,9.65026,112.74681
58.00000,2.41663,6822.29549,0.00000,9.66653,112.80251
58.10000,2.42076,6828.40720,0.00000,9.68303,112.90356
58.20000,2.42500,6833.93031,0.00000,9.70001,112.99488
58.30000,2.42925,6840.01148,0.00000,9.71699,113.09543
58.40000,2.43349,6846.00249,0.00000,9.73397,113.19449
58.50000,2.43756,6849.52289,0.00000,9.75023,113.25269
58.60000,2.44162,6855.36340,0.00000,9.76649,113.34927
58.70000,2.44581,6860.55124,0.00000,9.78323,113.43504
58.80000,2.44999,6864.17967,0.00000,9.79998,113.49503
58.90000,2.45430,6869.69385,0.00000,9.81719,113.58620
59.00000,2.45842,6873.77602,0.00000,9.83370,113.65370
59.10000,2.46249,6876.82927,0.00000,9.84996,113.70419
59.20000,2.46668,6881.08504,0.00000,9.86670,113.77455
59.30000,2.47086,6884.55924,0.00000,9.88344,113.83200
59.40000,2.47511,6889.22256,0.00000,9.90042,113.90910
59.50000,2.47929,6893.82404,0.00000,9.91716,113.98518
59.60000,2.48348,6483.87894,0.00000,9.93390,107.20699
59.64800,2.48658,-55.38951,0.00000,9.94634,-0.91583