File: Manufatura Aditiva/Dados/Ensaios AMR/Ensaios/Ensaios SLS/Tracao_OLABI_08_06_2018_SLS_ZX3.is_metal_RawData/Specimen_RawData_3.csv
Time,Extension,Load,Strain 1,Tensile strain,Tensile stress
(sec),(mm),(N),(mm/mm),(%),(MPa)
0.00000,0.00006,31.23066,0.00159,0.15904,1.60468
0.10000,0.00419,32.94411,0.00162,0.16214,1.69272
0.20000,0.01375,37.69410,0.00177,0.17708,1.93678
0.30000,0.02356,43.42849,0.00193,0.19304,2.23143
0.40000,0.03270,48.44496,0.00208,0.20816,2.48918
0.50000,0.04143,53.12874,0.00223,0.22302,2.72984
0.60000,0.04986,56.83029,0.00237,0.23696,2.92003
0.70000,0.05823,61.74054,0.00251,0.25060,3.17233
0.80000,0.06673,66.06308,0.00265,0.26455,3.39443
0.90000,0.07498,70.70603,0.00278,0.27804,3.63299
1.00000,0.08329,75.00455,0.00292,0.29155,3.85386
1.10000,0.09178,79.24418,0.00306,0.30595,4.07170
1.20000,0.10003,82.83838,0.00320,0.31982,4.25637
1.30000,0.10840,87.18061,0.00333,0.33348,4.47948
1.40000,0.11683,92.40056,0.00348,0.34756,4.74769
1.50000,0.12496,95.85270,0.00360,0.36041,4.92507
1.60000,0.13333,100.71201,0.00374,0.37439,5.17475
1.70000,0.14170,104.65302,0.00389,0.38880,5.37724
1.80000,0.14989,109.56567,0.00402,0.40195,5.62966
1.90000,0.15832,112.68170,0.00417,0.41654,5.78977
2.00000,0.16663,116.70195,0.00430,0.42994,5.99634
2.10000,0.17494,121.04271,0.00444,0.44419,6.21937
2.20000,0.18331,124.56684,0.00457,0.45719,6.40045
2.30000,0.19163,128.15279,0.00471,0.47142,6.58470
2.40000,0.19994,132.54799,0.00485,0.48500,6.81053
2.50000,0.20837,136.48251,0.00499,0.49883,7.01270
2.60000,0.21668,140.23453,0.00513,0.51345,7.20548
2.70000,0.22493,143.70118,0.00527,0.52693,7.38360
2.80000,0.23336,148.16364,0.00540,0.54047,7.61289
2.90000,0.24167,151.65734,0.00554,0.55449,7.79240
3.00000,0.24992,156.17061,0.00568,0.56832,8.02430
3.10000,0.25841,160.13660,0.00582,0.58198,8.22808
3.20000,0.26666,164.00770,0.00595,0.59520,8.42699
3.30000,0.27497,165.36253,0.00602,0.60229,8.49660
3.40000,0.28340,169.55287,0.00616,0.61628,8.71191
3.50000,0.29171,173.00269,0.00630,0.63028,8.88916
3.60000,0.30002,176.26019,0.00645,0.64515,9.05654
3.70000,0.30833,180.53362,0.00659,0.65873,9.27612
3.80000,0.31665,183.68288,0.00672,0.67223,9.43793
3.90000,0.32502,187.67572,0.00686,0.68595,9.64309
4.00000,0.33333,191.33691,0.00700,0.69975,9.83121
4.10000,0.34164,195.46496,0.00714,0.71402,10.04331
4.20000,0.34995,198.90054,0.00728,0.72773,10.21984
4.30000,0.35826,203.19517,0.00742,0.74205,10.44050
4.40000,0.36657,206.56788,0.00756,0.75555,10.61380
4.50000,0.37500,210.08290,0.00769,0.76949,10.79441
4.60000,0.38331,213.12756,0.00784,0.78359,10.95085
4.70000,0.39162,217.25073,0.00797,0.79748,11.16270
4.80000,0.39999,220.90108,0.00811,0.81109,11.35026
4.90000,0.40824,224.32285,0.00825,0.82534,11.52608
5.00000,0.41661,228.74316,0.00840,0.83957,11.75320
5.10000,0.42504,232.31709,0.00853,0.85333,11.93684
5.20000,0.43335,235.16058,0.00867,0.86706,12.08294
5.30000,0.44166,239.24026,0.00882,0.88150,12.29256
5.40000,0.45010,242.94450,0.00895,0.89502,12.48289
5.50000,0.45829,246.64202,0.00909,0.90915,12.67287
5.60000,0.46666,249.93264,0.00923,0.92317,12.84195
5.70000,0.47503,253.28454,0.00937,0.93698,13.01418
5.80000,0.48334,257.47002,0.00951,0.95058,13.22923
5.90000,0.49165,260.83563,0.00965,0.96474,13.40217
6.00000,0.50002,264.41743,0.00979,0.97883,13.58620
6.10000,0.50827,267.58304,0.00992,0.99247,13.74886
6.20000,0.51664,270.64029,0.01006,1.00593,13.90595
6.30000,0.52495,274.94442,0.01021,1.02065,14.12710
6.40000,0.53326,277.45964,0.01034,1.03435,14.25634
6.50000,0.54169,281.53548,0.01049,1.04896,14.46576
6.60000,0.55000,285.19433,0.01064,1.06359,14.65376
6.70000,0.55831,288.63284,0.01077,1.07739,14.83043
6.80000,0.56674,292.30881,0.01091,1.09130,15.01931
6.90000,0.57500,295.49056,0.01105,1.10532,15.18279
7.00000,0.58331,298.76349,0.01119,1.11890,15.35096
7.10000,0.59174,302.08561,0.01134,1.13363,15.52166
7.20000,0.59993,305.29117,0.01147,1.14731,15.68637
7.30000,0.60818,308.79935,0.01162,1.16155,15.86662
7.40000,0.61673,312.52133,0.01176,1.17616,16.05786
7.50000,0.62498,315.42613,0.01190,1.18980,16.20712
7.60000,0.63329,318.86098,0.01204,1.20420,16.38360
7.70000,0.64178,322.08594,0.01219,1.21852,16.54931
7.80000,0.64997,324.33381,0.01232,1.23216,16.66481
7.90000,0.65828,327.85572,0.01246,1.24621,16.84577
8.00000,0.66677,331.55321,0.01261,1.26091,17.03575
8.10000,0.67496,331.51880,0.01266,1.26582,17.03398
8.20000,0.68333,335.37638,0.01280,1.27980,17.23219
8.30000,0.69176,339.15231,0.01295,1.29498,17.42621
8.40000,0.70002,341.86852,0.01309,1.30866,17.56577
8.50000,0.70839,344.57017,0.01323,1.32265,17.70458
8.60000,0.71670,347.84894,0.01337,1.33730,17.87305
8.70000,0.72489,351.24116,0.01351,1.35109,18.04735
8.80000,0.73344,353.93473,0.01366,1.36571,18.18575
8.90000,0.74169,357.15988,0.01380,1.38004,18.35147
9.00000,0.75000,360.16256,0.01394,1.39368,18.50575
9.10000,0.75843,363.92980,0.01408,1.40787,18.69931
9.20000,0.76662,366.87241,0.01423,1.42256,18.85051
9.30000,0.77493,369.66000,0.01437,1.43670,18.99374
9.40000,0.78336,373.04154,0.01452,1.45184,19.16749
9.50000,0.79161,375.00765,0.01467,1.46657,19.26851
9.60000,0.79992,378.65024,0.01481,1.48079,19.45568
9.70000,0.80835,381.51299,0.01495,1.49508,19.60277
9.80000,0.81666,384.03720,0.01509,1.50882,19.73247
9.90000,0.82498,387.07699,0.01523,1.52289,19.88865
10.00000,0.83341,389.72693,0.01537,1.53739,20.02481
10.10000,0.84166,392.74655,0.01552,1.55185,20.17997
10.20000,0.84991,395.78993,0.01566,1.56638,20.33634
10.30000,0.85840,398.93580,0.01581,1.58101,20.49798
10.40000,0.86665,401.76944,0.01596,1.59600,20.64358
10.50000,0.87502,404.20718,0.01610,1.60984,20.76883
10.60000,0.88333,407.09819,0.01625,1.62454,20.91738
10.70000,0.89164,410.21919,0.01639,1.63881,21.07774
10.80000,0.90007,412.58950,0.01654,1.65388,21.19953
10.90000,0.90832,415.06439,0.01668,1.66819,21.32669
11.00000,0.91669,417.67373,0.01683,1.68305,21.46077
11.10000,0.92506,421.07776,0.01698,1.69811,21.63567
11.20000,0.93331,423.91680,0.01712,1.71241,21.78155
11.30000,0.94162,425.96809,0.01727,1.72695,21.88694
11.40000,0.95000,428.68853,0.01742,1.74168,22.02673
11.50000,0.95825,431.83267,0.01756,1.75650,22.18828
11.60000,0.96656,434.30594,0.01771,1.77087,22.31536
11.70000,0.97505,437.02163,0.01786,1.78595,22.45489
11.80000,0.98336,439.39338,0.01801,1.80068,22.57676
11.90000,0.99161,442.49245,0.01815,1.81544,22.73599
12.00000,1.00004,444.99272,0.01831,1.83061,22.86446
12.10000,1.00835,447.76080,0.01845,1.84526,23.00669
12.20000,1.01666,450.54476,0.01860,1.86018,23.14973
12.30000,1.02509,452.59935,0.01876,1.87565,23.25530
12.40000,1.03328,455.22717,0.01890,1.89030,23.39032
12.50000,1.04165,457.98230,0.01905,1.90516,23.53189
12.60000,1.05002,460.65436,0.01920,1.92007,23.66918
12.70000,1.05827,463.10667,0.01935,1.93513,23.79519
12.80000,1.06664,465.75083,0.01950,1.94994,23.93105
12.90000,1.07502,467.80766,0.01965,1.96518,24.03673
13.00000,1.08333,470.09671,0.01980,1.98034,24.15435
13.10000,1.09176,472.19871,0.01996,1.99605,24.26235
13.20000,1.10001,474.64021,0.02011,2.01099,24.38780
13.30000,1.10838,477.53453,0.02025,2.02548,24.53651
13.40000,1.11675,477.11437,0.02033,2.03260,24.51493
13.50000,1.12500,479.65907,0.02048,2.04755,24.64568
13.60000,1.13325,482.51613,0.02063,2.06306,24.79248
13.70000,1.14168,484.54348,0.02078,2.07830,24.89664
13.80000,1.14993,486.63318,0.02094,2.09375,25.00402
13.90000,1.15824,489.66384,0.02109,2.10918,25.15974
14.00000,1.16673,491.25203,0.02125,2.12474,25.24134
14.10000,1.17498,493.77237,0.02140,2.14013,25.37084
14.20000,1.18329,495.44196,0.02155,2.15495,25.45663
14.30000,1.19178,497.92277,0.02171,2.17092,25.58410
14.40000,1.19998,501.10170,0.02186,2.18643,25.74743
14.50000,1.20829,503.04434,0.02202,2.20225,25.84725
14.60000,1.21672,505.34117,0.02218,2.21810,25.96527
14.70000,1.22491,506.69331,0.02234,2.23362,26.03474
14.80000,1.23334,508.08107,0.02246,2.24553,26.10604
14.90000,1.24171,510.70983,0.02262,2.26162,26.24112
15.00000,1.24996,512.88595,0.02277,2.27668,26.35293
15.10000,1.25833,514.87540,0.02293,2.29295,26.45515
15.20000,1.26670,516.56808,0.02308,2.30845,26.54212
15.30000,1.27495,519.12554,0.02324,2.32388,26.67353
15.40000,1.28344,521.66451,0.02340,2.33975,26.80398
15.50000,1.29175,522.62386,0.02355,2.35518,26.85328
15.60000,1.29994,524.93163,0.02371,2.37143,26.97186
15.70000,1.30837,526.76382,0.02387,2.38723,27.06600
15.80000,1.31662,528.53962,0.02403,2.40312,27.15724
15.90000,1.32488,530.21717,0.02419,2.41887,27.24343
16.00000,1.33343,533.10944,0.02435,2.43487,27.39204
16.10000,1.34162,534.38037,0.02451,2.45096,27.45735
16.20000,1.34993,536.72730,0.02467,2.46723,27.57794
16.30000,1.35848,538.27255,0.02483,2.48341,27.65733
16.40000,1.36667,540.74656,0.02500,2.49994,27.78445
16.50000,1.37504,541.82331,0.02516,2.51627,27.83978
16.60000,1.38341,544.15287,0.02532,2.53226,27.95947
16.70000,1.39160,545.37444,0.02548,2.54802,28.02224
16.80000,1.39997,547.50238,0.02564,2.56409,28.13158
16.90000,1.40840,549.32428,0.02580,2.58040,28.22519
17.00000,1.41659,551.38636,0.02597,2.59661,28.33114
17.10000,1.42496,553.21916,0.02613,2.61324,28.42531
17.20000,1.43333,554.61009,0.02630,2.62990,28.49678
17.30000,1.44164,556.93942,0.02646,2.64604,28.61647
17.40000,1.45001,558.10050,0.02662,2.66242,28.67613
17.50000,1.45839,559.11094,0.02679,2.67882,28.72804
17.60000,1.46664,561.47398,0.02695,2.69488,28.84946
17.70000,1.47501,563.01998,0.02711,2.71107,28.92890
17.80000,1.48320,565.14926,0.02728,2.72783,29.03830
17.90000,1.49157,566.81363,0.02744,2.74407,29.12382
18.00000,1.50000,568.50500,0.02761,2.76100,29.21073
18.10000,1.50819,570.43307,0.02778,2.77759,29.30979
18.20000,1.51656,571.54293,0.02794,2.79392,29.36682
18.30000,1.52505,573.23221,0.02811,2.81064,29.45362
18.40000,1.53336,574.37792,0.02827,2.82737,29.51249
18.50000,1.54167,576.57058,0.02844,2.84381,29.62515
18.60000,1.55004,577.92282,0.02861,2.86086,29.69463
18.70000,1.55829,579.42416,0.02877,2.87740,29.77177
18.80000,1.56666,580.82901,0.02894,2.89372,29.84395
18.90000,1.57509,582.42404,0.02911,2.91086,29.92591
19.00000,1.58335,584.56245,0.02928,2.92785,30.03578
19.10000,1.59166,585.70607,0.02944,2.94434,30.09455
19.20000,1.60003,587.34007,0.02961,2.96130,30.17850
19.30000,1.60834,589.22078,0.02978,2.97811,30.27514
19.40000,1.61665,590.23658,0.02995,2.99470,30.32733
19.50000,1.62502,591.41112,0.03012,3.01195,30.38768
19.60000,1.63333,592.44428,0.03029,3.02900,30.44077
19.70000,1.64176,594.95242,0.03046,3.04606,30.56964
19.80000,1.65007,595.94293,0.03063,3.06264,30.62053
19.90000,1.65832,597.78299,0.03079,3.07931,30.71508
20.00000,1.66663,598.89364,0.03096,3.11255,30.77214
20.10000,1.67488,600.21495,0.03113,3.14555,30.84004
20.14800,1.67895,601.05608,0.03121,3.16182,30.88326
20.24800,1.68732,602.04738,0.03139,3.19530,30.93419
20.34800,1.69569,602.24640,0.03155,3.22878,30.94442
20.44800,1.70394,601.87066,0.03162,3.26178,30.92511
20.54800,1.71231,603.37009,0.03179,3.29527,31.00215
20.64800,1.72068,605.01504,0.03196,3.32875,31.08667
20.74800,1.72899,606.58031,0.03213,3.36199,31.16710
20.84800,1.73730,607.85883,0.03230,3.39523,31.23279
20.94800,1.74567,608.48617,0.03247,3.42872,31.26502
21.04800,1.75392,611.25159,0.03264,3.46172,31.40712
21.14800,1.76236,612.29439,0.03281,3.49544,31.46070
21.24800,1.77067,613.43182,0.03298,3.52869,31.51914
21.34800,1.77892,614.70731,0.03316,3.56169,31.58468
21.44800,1.78741,615.73205,0.03333,3.59565,31.63733
21.54800,1.79566,617.02244,0.03350,3.62865,31.70363
21.64800,1.80403,618.32597,0.03367,3.66214,31.77061
21.74800,1.81246,619.24737,0.03385,3.69586,31.81795
21.84800,1.82071,620.57367,0.03402,3.72886,31.88610
21.94800,1.82902,622.38290,0.03419,3.76210,31.97906
22.04800,1.83745,623.09667,0.03450,3.79582,32.01574
22.14800,1.84564,624.76001,0.03474,3.82859,32.10120
22.24800,1.85395,625.86004,0.03479,3.86183,32.15772
22.34800,1.86238,626.53911,0.03457,3.89555,32.19262
22.44800,1.87063,627.40850,0.03594,3.92856,32.23729
22.54800,1.87894,628.80232,0.01991,3.96180,32.30890
22.64800,1.88743,630.87521,0.00583,3.99576,32.41541
22.74800,1.89557,631.27191,0.00588,4.02829,32.43579
22.84800,1.90394,633.52617,0.00598,4.06177,32.55162
22.94800,1.91237,634.00692,0.00595,4.09549,32.57632
23.04800,1.92056,635.15776,0.00681,4.12825,32.63546
23.14800,1.92905,636.02724,0.00787,4.16221,32.68013
23.24800,1.93730,637.51289,0.00603,4.19522,32.75647
23.34800,1.94561,638.78149,0.00684,4.22846,32.82165
23.44800,1.95404,639.40776,0.00781,4.26218,32.85383
23.54800,1.96235,640.72763,0.00859,4.29543,32.92165
23.64800,1.97066,641.89178,0.00817,4.32867,32.98146
23.74800,1.97909,643.61421,0.00825,4.36239,33.06996
23.84800,1.98734,644.31177,0.00866,4.39539,33.10580
23.94800,1.99571,645.24370,0.00755,4.42888,33.15369
24.04800,2.00408,646.56199,0.00165,4.46236,33.22142
24.14800,2.01233,647.49252,-0.01140,4.49536,33.26924
24.24800,2.02059,648.62790,-0.01760,4.52836,33.32757
24.34800,2.02902,649.27228,-0.02065,4.56209,33.36068
24.44800,2.03739,650.86498,-0.02523,4.59557,33.44252
24.54800,2.04564,652.16734,-0.04737,4.62857,33.50944
24.64800,2.05407,652.72842,-0.13615,4.66229,33.53827
24.74800,2.06232,654.11041,-0.13542,4.69530,33.60927
24.84800,2.07063,655.30473,-0.13540,4.72854,33.67064
24.94800,2.07906,656.11568,-0.13541,4.76226,33.71231
25.04800,2.08731,656.46833,-0.13540,4.79527,33.73043
25.14800,2.09568,657.81460,-0.13541,4.82875,33.79960
25.24800,2.10393,659.20805,-0.13541,4.86175,33.87120
25.34800,2.11224,660.55097,-0.13541,4.89499,33.94020
25.44800,2.12061,660.94873,-0.13541,4.92848,33.96064
25.54800,2.12886,662.33911,-0.13542,4.96148,34.03208
25.64800,2.13729,663.27080,-0.13541,4.99520,34.07995
25.74800,2.14567,663.28417,-0.13541,5.02868,34.08064
25.84800,2.15398,665.19491,-0.13541,5.06193,34.17881
25.94800,2.16235,665.82663,-0.13541,5.09541,34.21127
26.04800,2.17078,666.67493,-0.13542,5.12913,34.25486
26.14800,2.17903,668.00104,-0.13541,5.16213,34.32300
26.24800,2.18734,669.24975,-0.13542,5.19538,34.38716
26.34800,2.19571,670.09511,-0.13542,5.22886,34.43060
26.44800,2.20402,670.78485,-0.13542,5.26210,34.46603
26.54800,2.21239,671.59878,-0.13542,5.29558,34.50785
26.64800,2.22070,672.64596,-0.13542,5.32883,34.56166
26.74800,2.22901,673.42254,-0.13542,5.36207,34.60156
26.84800,2.23738,674.61417,-0.13542,5.39555,34.66279
26.94800,2.24569,675.25767,-0.13542,5.42880,34.69585
27.04800,2.25406,676.60189,-0.13542,5.46228,34.76492
27.14800,2.26237,677.52143,-0.13542,5.49552,34.81217
27.24800,2.27069,677.91743,-0.13542,5.52876,34.83252
27.34800,2.27906,679.07334,-0.13542,5.56224,34.89191
27.44800,2.28737,680.00825,-0.13542,5.59549,34.93995
27.54800,2.29568,680.57952,-0.13542,5.62873,34.96930
27.64800,2.30399,681.26442,-0.13543,5.66197,35.00449
27.74800,2.31230,682.73814,-0.13542,5.69522,35.08022
27.84800,2.32067,683.57647,-0.13542,5.72870,35.12329
27.94800,2.32898,684.74105,-0.13543,5.76194,35.18313
28.04800,2.33735,685.20848,-0.13542,5.79542,35.20715
28.14800,2.34560,685.65039,-0.13543,5.82843,35.22985
28.24800,2.35391,686.60048,-0.13543,5.86167,35.27867
28.34800,2.36234,688.13264,-0.13543,5.89539,35.35739
28.44800,2.37059,689.37954,-0.13542,5.92840,35.42146
28.54800,2.37896,689.54248,-0.13543,5.96188,35.42983
28.64800,2.38733,689.84916,-0.13543,5.99536,35.44559
28.74800,2.39559,691.28280,-0.13543,6.02836,35.51925
28.84800,2.40396,691.76070,-0.13543,6.06185,35.54381
28.94800,2.41233,692.96043,-0.13543,6.09533,35.60545
29.04800,2.42064,693.54782,-0.13543,6.12857,35.63563
29.14800,2.42901,694.10601,-0.13543,6.16205,35.66431
29.24800,2.43738,694.97670,-0.13543,6.19553,35.70905
29.34800,2.44569,696.18840,-0.13543,6.22878,35.77131
29.44800,2.45406,697.11935,-0.13543,6.26226,35.81915
29.54800,2.46237,697.62841,-0.13543,6.29550,35.84530
29.64800,2.47068,698.91680,-0.13543,6.32875,35.91150
29.74800,2.47905,698.78078,-0.13543,6.36223,35.90451
29.84800,2.48730,700.75220,-0.13543,6.39523,36.00581
29.94800,2.49561,700.62317,-0.13543,6.42847,35.99918
30.04800,2.50404,702.00125,-0.13543,6.46220,36.06998
30.14800,2.51229,702.85932,-0.13543,6.49520,36.11407
30.24800,2.52067,703.36554,-0.13543,6.52868,36.14008
30.34800,2.52910,704.37226,-0.13543,6.56240,36.19181
30.44800,2.53735,704.83522,-0.13543,6.59541,36.21560
30.54800,2.54566,705.98824,-0.13543,6.62865,36.27484
30.64800,2.55403,705.91746,-0.13543,6.66213,36.27121
30.74800,2.56222,707.58816,-0.13543,6.69490,36.35705
30.84800,2.57059,708.06681,-0.13543,6.72838,36.38164
30.94800,2.57896,708.96382,-0.13543,6.76186,36.42773
31.04800,2.58733,706.70797,-0.13543,6.79534,36.31182
31.14800,2.59564,707.27249,-0.13543,6.82859,36.34083
31.24800,2.60401,708.13512,-0.13543,6.86207,36.38515
31.34800,2.61232,709.35111,-0.13543,6.89531,36.44763
31.44800,2.62063,710.54203,-0.13543,6.92855,36.50882
31.54800,2.62900,710.88355,-0.13544,6.96204,36.52637
31.64800,2.63737,711.74148,-0.13543,6.99552,36.57045
31.74800,2.64563,712.70657,-0.13544,7.02852,36.62004
31.84800,2.65394,713.37931,-0.13544,7.06177,36.65461
31.94800,2.66231,714.37783,-0.13543,7.09525,36.70591
32.04800,2.67068,716.15037,-0.13543,7.12873,36.79699
32.14800,2.67893,716.03437,-0.13543,7.16173,36.79103
32.24800,2.68730,716.63214,-0.13543,7.19522,36.82174
32.34800,2.69567,717.08616,-0.13544,7.22870,36.84507
32.44800,2.70398,718.05017,-0.13543,7.26194,36.89460
32.54800,2.71241,718.80696,-0.13544,7.29566,36.93349
32.64800,2.72072,719.60292,-0.13543,7.32890,36.97439
32.74800,2.72903,720.62397,-0.13543,7.36215,37.02685
32.84800,2.73734,721.01597,-0.13543,7.39539,37.04699
32.94800,2.74565,722.40871,-0.13543,7.42863,37.11855
33.04800,2.75402,722.33938,-0.13543,7.46212,37.11499
33.14800,2.76233,722.90101,-0.13544,7.49536,37.14385
33.24800,2.77070,724.05385,-0.13543,7.52884,37.20308
33.34800,2.77902,725.00939,-0.13543,7.56208,37.25218
33.44800,2.78739,724.59769,-0.13543,7.59557,37.23103
33.54800,2.79576,726.37792,-0.13544,7.62905,37.32250
33.64800,2.80401,726.28865,-0.13544,7.66205,37.31791
33.74800,2.81232,726.84204,-0.13543,7.69529,37.34634
33.84800,2.82063,727.88941,-0.13544,7.72854,37.40016
33.94800,2.82894,728.45533,-0.13544,7.76178,37.42924
34.04800,2.83731,729.05445,-0.13543,7.79526,37.46002
34.14800,2.84562,730.07490,-0.13544,7.82851,37.51245
34.24800,2.85393,731.31816,-0.13543,7.86175,37.57634
34.34800,2.86230,730.82773,-0.13543,7.89523,37.55114
34.44800,2.87067,732.03733,-0.13544,7.92871,37.61329
34.54800,2.87904,732.52940,-0.13543,7.96219,37.63857
34.64800,2.88741,732.53005,-0.13544,7.99568,37.63860
34.74800,2.89566,733.63562,-0.13544,8.02868,37.69541
34.84800,2.90404,734.14203,-0.13544,8.06216,37.72143
34.94800,2.91235,735.02725,-0.13544,8.09541,37.76691
35.04800,2.92066,735.46097,-0.13544,8.12865,37.78920
35.14800,2.92891,735.77799,-0.13544,8.16165,37.80549
35.24800,2.93740,736.27871,-0.13544,8.19561,37.83122
35.34800,2.94559,737.14727,-0.13544,8.22838,37.87584
35.44800,2.95396,738.06169,-0.13544,8.26186,37.92283
35.54800,2.96245,738.67007,-0.13544,8.29582,37.95409
35.64800,2.97064,738.98253,-0.13543,8.32858,37.97014
35.74800,2.97901,739.83576,-0.13544,8.36207,38.01398
35.84800,2.98744,740.27595,-0.13544,8.39579,38.03660
35.94800,2.99557,740.82250,-0.13544,8.42831,38.06469
36.04800,3.00394,742.04593,-0.13543,8.46180,38.12754
36.14800,3.01231,741.91219,-0.13544,8.49528,38.12067
36.24800,3.02057,742.79681,-0.13543,8.52828,38.16613
36.34800,3.02894,742.82680,-0.13544,8.56176,38.16767
36.44800,3.03731,743.43546,-0.13544,8.59525,38.19894
36.54800,3.04562,744.64707,-0.13543,8.62849,38.26120
36.64800,3.05399,744.91594,-0.13544,8.66197,38.27501
36.74800,3.06236,744.79273,-0.13544,8.69545,38.26868
36.84800,3.07067,746.20638,-0.13544,8.72870,38.34132
36.94800,3.07910,746.45355,-0.13544,8.76242,38.35402
37.04800,3.08735,747.38222,-0.13544,8.79542,38.40173
37.14800,3.09554,747.56560,-0.13544,8.82819,38.41116
37.24800,3.10409,748.09846,-0.13544,8.86239,38.43853
37.34800,3.11228,749.18517,-0.13544,8.89515,38.49437
37.44800,3.12065,749.24943,-0.13544,8.92863,38.49767
37.54800,3.12908,749.85465,-0.13544,8.96235,38.52877
37.64800,3.13727,750.36185,-0.13544,8.99512,38.55483
37.74800,3.14570,750.53563,-0.13544,9.02884,38.56376
37.84800,3.15413,751.50602,-0.13544,9.06256,38.61362
37.94800,3.16227,752.04032,-0.13544,9.09509,38.64108
38.04800,3.17064,752.40913,-0.13544,9.12857,38.66002
38.14800,3.17901,752.45202,-0.13544,9.16205,38.66223
38.24800,3.18726,753.58613,-0.13544,9.19506,38.72050
38.34800,3.19569,754.37292,-0.13544,9.22878,38.76093
38.44800,3.20400,753.80858,-0.13544,9.26202,38.73193
38.54800,3.21225,755.50028,-0.13544,9.29502,38.81885
38.64800,3.22068,755.82946,-0.13544,9.32874,38.83577
38.74800,3.22899,755.47337,-0.13544,9.36199,38.81747
38.84800,3.23724,757.05498,-0.13544,9.39499,38.89874
38.94800,3.24567,757.32153,-0.13544,9.42871,38.91243
39.04800,3.25398,757.91087,-0.13544,9.46195,38.94271
39.14800,3.26229,758.43357,-0.13544,9.49520,38.96957
39.24800,3.27072,758.55954,-0.13544,9.52892,38.97604
39.34800,3.27898,758.58575,-0.13544,9.56192,38.97739
39.44800,3.28729,759.30478,-0.13544,9.59516,39.01434
39.54800,3.29572,759.54446,-0.13544,9.62889,39.02665
39.64800,3.30397,760.71629,-0.13544,9.66189,39.08686
39.74800,3.31228,761.25660,-0.13544,9.69513,39.11462
39.84800,3.32071,761.13036,-0.13544,9.72885,39.10814
39.94800,3.32902,761.70312,-0.13544,9.76210,39.13757
40.04800,3.33733,762.30667,-0.13544,9.79534,39.16858
40.14800,3.34576,762.84856,-0.13544,9.82906,39.19642
40.24800,3.35407,763.36297,-0.13544,9.86231,39.22285
40.34800,3.36238,763.52693,-0.13544,9.89555,39.23128
40.44800,3.37075,764.27707,-0.13544,9.92903,39.26982
40.54800,3.37894,764.02309,-0.13544,9.96180,39.25677
40.64800,3.38731,765.32583,-0.13544,9.99528,39.32371
40.74800,3.39568,765.59056,-0.13544,10.02876,39.33731
40.84800,3.40400,766.03070,-0.13544,10.06200,39.35992
40.94800,3.41243,766.83792,-0.13544,10.09572,39.40140
41.04800,3.42068,766.81119,-0.13544,10.12873,39.40003
41.14800,3.42899,767.07373,-0.13544,10.16197,39.41352
41.24800,3.43736,767.82666,-0.13544,10.19545,39.45220
41.34800,3.44561,768.73661,-0.13544,10.22846,39.49896
41.44800,3.45392,769.00255,-0.13544,10.26170,39.51262
41.54800,3.46235,769.10933,-0.13544,10.29542,39.51811
41.64800,3.47060,769.54234,-0.13544,10.32842,39.54036
41.74800,3.47897,770.07548,-0.13544,10.36191,39.56775
41.84800,3.48740,770.81965,-0.13544,10.39563,39.60599
41.94800,3.49565,770.79213,-0.13544,10.42863,39.60457
42.04800,3.50396,771.29179,-0.13544,10.46188,39.63025
42.14800,3.51245,770.96070,-0.13544,10.49583,39.61324
42.24800,3.52064,771.51172,-0.13544,10.52860,39.64155
42.34800,3.52901,772.35247,-0.13544,10.56208,39.68475
42.44800,3.53745,772.65552,-0.13544,10.59580,39.70032
42.54800,3.54564,773.54312,-0.13544,10.62857,39.74592
42.64800,3.55401,773.80645,-0.13544,10.66205,39.75945
42.74800,3.56232,774.18238,-0.13544,10.69529,39.77877
42.84800,3.57057,774.29800,-0.13544,10.72830,39.78471
42.94800,3.57906,775.69322,-0.13544,10.76226,39.85640
43.04800,3.58737,775.21699,-0.13544,10.79550,39.83193
43.14800,3.59556,775.76158,-0.13544,10.82826,39.85991
43.24800,3.60405,776.34403,-0.13544,10.86222,39.88984
43.34800,3.61230,776.27022,-0.13544,10.89523,39.88605
43.44800,3.62061,776.55525,-0.13544,10.92847,39.90069
43.54800,3.62904,777.35232,-0.13544,10.96219,39.94165
43.64800,3.63723,777.63577,-0.13544,10.99496,39.95621
43.74800,3.64554,778.13682,-0.13544,11.02820,39.98196
43.84800,3.65409,778.18953,-0.13544,11.06240,39.98466
43.94800,3.66235,778.38497,-0.13544,11.09540,39.99471
44.04800,3.67060,779.61725,-0.13544,11.12841,40.05802
44.14800,3.67915,779.20933,-0.13545,11.16261,40.03706
44.24800,3.68728,780.50741,-0.13544,11.19513,40.10376
44.34800,3.69565,780.21274,-0.13544,11.22862,40.08862
44.44800,3.70414,781.39314,-0.13545,11.26258,40.14927
44.54800,3.71227,781.43729,-0.13544,11.29510,40.15154
44.64800,3.72064,781.63622,-0.13544,11.32858,40.16176
44.74800,3.72907,781.53517,-0.13545,11.36230,40.15657
44.84800,3.73726,782.19082,-0.13544,11.39507,40.19026
44.94800,3.74575,782.78976,-0.13545,11.42903,40.22103
45.04800,3.75400,782.67576,-0.13544,11.46203,40.21518
45.14800,3.76225,782.70165,-0.13544,11.49504,40.21650
45.24800,3.77074,783.78227,-0.13544,11.52900,40.27203
45.34800,3.77905,784.33184,-0.13544,11.56224,40.30027
45.44800,3.78731,784.01659,-0.13545,11.59524,40.28407
45.54800,3.79568,785.35182,-0.13544,11.62873,40.35268
45.64800,3.80393,785.47830,-0.13544,11.66173,40.35917
45.74800,3.81230,785.73748,-0.13544,11.69521,40.37249
45.84800,3.82073,786.00701,-0.13544,11.72893,40.38634
45.94800,3.82898,786.41586,-0.13545,11.76194,40.40734
46.04800,3.83723,787.17573,-0.13544,11.79494,40.44639
46.14800,3.84572,786.67495,-0.13544,11.82890,40.42066
46.24800,3.85403,787.07868,-0.13544,11.86214,40.44140
46.34800,3.86228,787.65918,-0.13544,11.89515,40.47123
46.44800,3.87077,788.14803,-0.13545,11.92911,40.49635
46.54800,3.87896,788.00283,-0.13545,11.96187,40.48889
46.64800,3.88733,788.46700,-0.13545,11.99536,40.51274
46.74800,3.89570,788.88219,-0.13545,12.02884,40.53407
46.84800,3.90389,789.46128,-0.13544,12.06160,40.56382
46.94800,3.91233,789.75894,-0.13544,12.09532,40.57912
47.04800,3.92064,789.86250,-0.13544,12.12857,40.58444
47.14800,3.92895,790.12802,-0.13544,12.16181,40.59808
47.24800,3.93732,789.93673,-0.13544,12.19529,40.58825
47.34800,3.94569,790.86944,-0.13544,12.22877,40.63618
47.44800,3.95400,790.62609,-0.13545,12.26202,40.62368
47.54800,3.96237,791.53692,-0.13544,12.29550,40.67048
47.64800,3.97062,791.29068,-0.13545,12.32850,40.65782
47.74800,3.97899,791.87779,-0.13544,12.36198,40.68799
47.84800,3.98736,792.39421,-0.13544,12.39547,40.71452
47.94800,3.99561,792.25032,-0.13544,12.42847,40.70713
48.04800,4.00392,793.05274,-0.13544,12.46171,40.74836
48.14800,4.01235,793.26844,-0.13545,12.49544,40.75945
48.24800,4.02066,793.50928,-0.13544,12.52868,40.77182
48.34800,4.02897,793.57401,-0.13545,12.56192,40.77514
48.44800,4.03734,794.02532,-0.13544,12.59540,40.79833
48.54800,4.04560,794.31525,-0.13545,12.62841,40.81323
48.64800,4.05397,794.94733,-0.13545,12.66189,40.84571
48.74800,4.06240,795.07278,-0.13544,12.69561,40.85215
48.84800,4.07065,795.52773,-0.13545,12.72861,40.87553
48.94800,4.07896,795.51982,-0.13544,12.76186,40.87512
49.04800,4.08733,794.13056,-0.13545,12.79534,40.80374
49.14800,4.09558,793.74788,-0.13544,12.82834,40.78408
49.24800,4.10401,793.64525,-0.13544,12.86206,40.77880
49.34800,4.11232,794.47906,-0.13544,12.89531,40.82165
49.44800,4.12063,794.55040,-0.13545,12.92855,40.82531
49.54800,4.12900,795.47968,-0.13545,12.96203,40.87306
49.64800,4.13737,795.77239,-0.13545,12.99551,40.88810
49.74800,4.14562,795.62990,-0.13545,13.02852,40.88078
49.84800,4.15405,796.04238,-0.13545,13.06224,40.90197
49.94800,4.16230,796.31321,-0.13544,13.09524,40.91589
50.04800,4.17062,797.70312,-0.13545,13.12848,40.98730
50.14800,4.17905,797.61529,-0.13545,13.16221,40.98279
50.24800,4.18730,796.94111,-0.13544,13.19521,40.94815
50.34800,4.19555,798.24347,-0.13544,13.22822,41.01507
50.44800,4.20404,798.86252,-0.13545,13.26218,41.04688
50.54800,4.21235,798.76762,-0.13544,13.29542,41.04200
50.64800,4.22066,799.40008,-0.13545,13.32866,41.07450
50.74800,4.22915,799.22397,-0.13545,13.36262,41.06545
50.84800,4.23734,800.10528,-0.13545,13.39539,41.11073
50.94800,4.24559,800.26826,-0.13545,13.42839,41.11911
51.04800,4.25402,800.23920,-0.13545,13.46211,41.11761
51.14800,4.26227,800.90258,-0.13545,13.49511,41.15170
51.24800,4.27064,801.04135,-0.13545,13.52860,41.15883
51.34800,4.27907,801.54156,-0.13544,13.56232,41.18453
51.44800,4.28727,801.77095,-0.13545,13.59508,41.19632
51.54800,4.29564,802.35451,-0.13545,13.62856,41.22630
51.64800,4.30407,801.60638,-0.13544,13.66229,41.18786
51.74800,4.31226,802.46786,-0.13545,13.69505,41.23212
51.84800,4.32075,803.23648,-0.13545,13.72901,41.27162
51.94800,4.32900,802.82539,-0.13544,13.76202,41.25050
52.04800,4.33725,803.74610,-0.13545,13.79502,41.29780
52.14800,4.34568,804.05734,-0.13545,13.82874,41.31380
52.24800,4.35399,803.76472,-0.13545,13.86198,41.29876
52.34800,4.36230,804.26149,-0.13545,13.89523,41.32428
52.44800,4.37073,804.65609,-0.13545,13.92895,41.34456
52.54800,4.37898,804.70722,-0.13545,13.96195,41.34719
52.64800,4.38723,804.67928,-0.13545,13.99495,41.34575
52.74800,4.39572,804.67165,-0.13545,14.02892,41.34536
52.84800,4.40403,805.04250,-0.13545,14.06216,41.36441
52.94800,4.41234,805.69349,-0.13545,14.09540,41.39786
53.04800,4.42072,806.47012,-0.13544,14.12888,41.43777
53.14800,4.42897,806.35492,-0.13545,14.16189,41.43185
53.24800,4.43728,806.40707,-0.13545,14.19513,41.43453
53.34800,4.44571,806.75483,-0.13544,14.22885,41.45240
53.44800,4.45396,806.70668,-0.13544,14.26186,41.44992
53.54800,4.46233,807.33364,-0.13545,14.29534,41.48214
53.64800,4.47070,807.18463,-0.13545,14.32882,41.47448
53.74800,4.47895,807.86236,-0.13545,14.36182,41.50930
53.84800,4.48744,807.37201,-0.13545,14.39578,41.48411
53.94800,4.49563,807.62049,-0.13545,14.42855,41.49688
54.04800,4.50394,808.06632,-0.13545,14.46179,41.51978
54.14800,4.51231,807.80433,-0.13545,14.49527,41.50632
54.24800,4.52056,808.43940,-0.13545,14.52828,41.53895
54.34800,4.52893,808.66925,-0.13545,14.56176,41.55076
54.44800,4.53730,809.15652,-0.13544,14.59524,41.57580
54.54800,4.54562,809.01440,-0.13545,14.62848,41.56850
54.64800,4.55393,810.06121,-0.13545,14.66173,41.62228
54.74800,4.56230,809.72202,-0.13545,14.69521,41.60485
54.84800,4.57067,810.06810,-0.13545,14.72869,41.62264
54.94800,4.57904,810.03122,-0.13545,14.76217,41.62074
55.04800,4.58735,810.31881,-0.13545,14.79542,41.63552
55.14800,4.59572,810.43262,-0.13545,14.82890,41.64137
55.24800,4.60403,810.65129,-0.13545,14.86214,41.65260
55.34800,4.61234,810.96897,-0.13545,14.89538,41.66893
55.44800,4.62065,811.45326,-0.13545,14.92863,41.69381
55.54800,4.62896,811.42997,-0.13544,14.96187,41.69261
55.64800,4.63733,811.65815,-0.13545,14.99535,41.70434
55.74800,4.64570,811.89973,-0.13545,15.02883,41.71675
55.84800,4.65407,811.64371,-0.13545,15.06232,41.70359
55.94800,4.66232,812.32805,-0.13545,15.09532,41.73876
56.04800,4.67070,812.07491,-0.13545,15.12880,41.72575
56.14800,4.67913,811.74253,-0.13545,15.16252,41.70867
56.24800,4.68738,812.48181,-0.13545,15.19553,41.74666
56.34800,4.69569,812.92940,-0.13545,15.22877,41.76966
56.44800,4.70406,813.25220,-0.13545,15.26225,41.78624
56.54800,4.71225,813.63954,-0.13545,15.29502,41.80614
56.64800,4.72068,813.21811,-0.13545,15.32874,41.78449
56.74800,4.72899,813.37048,-0.13545,15.36198,41.79232
56.84800,4.73730,814.34511,-0.13545,15.39523,41.84240
56.94800,4.74555,814.07372,-0.13545,15.42823,41.82845
57.04800,4.75404,813.96382,-0.13545,15.46219,41.82281
57.14800,4.76229,814.94311,-0.13545,15.49519,41.87312
57.24800,4.77066,813.76368,-0.13545,15.52867,41.81252
57.34800,4.77903,814.68187,-0.13545,15.56216,41.85970
57.44800,4.78728,814.59498,-0.13545,15.59516,41.85524
57.54800,4.79560,815.15135,-0.13545,15.62840,41.88382
57.64800,4.80397,814.87698,-0.13545,15.66188,41.86972
57.74800,4.81228,815.61618,-0.13545,15.69513,41.90771
57.84800,4.82071,815.42404,-0.13545,15.72885,41.89783
57.94800,4.82902,815.83103,-0.13545,15.76209,41.91875
58.04800,4.83733,816.01078,-0.13544,15.79534,41.92798
58.14800,4.84576,816.12533,-0.13545,15.82906,41.93387
58.24800,4.85401,815.79303,-0.13545,15.86206,41.91679
58.34800,4.86232,815.95797,-0.13545,15.89531,41.92527
58.44800,4.87075,817.19439,-0.13545,15.92903,41.98880
58.54800,4.87900,817.32832,-0.13545,15.96203,41.99568
58.64800,4.88731,816.84068,-0.13545,15.99527,41.97062
58.74800,4.89568,816.94657,-0.13545,16.02875,41.97607
58.84800,4.90393,816.48054,-0.13545,16.06176,41.95212
58.94800,4.91230,817.61023,-0.13544,16.09524,42.01017
59.04800,4.92067,817.48934,-0.13545,16.12872,42.00395
59.14800,4.92899,817.42974,-0.13545,16.16196,42.00089
59.24800,4.93736,818.16306,-0.13545,16.19545,42.03857
59.34800,4.94573,818.34663,-0.13545,16.22893,42.04800
59.44800,4.95398,818.77075,-0.13544,16.26193,42.06979
59.54800,4.96229,818.21140,-0.13545,16.29518,42.04105
59.64800,4.97066,817.89596,-0.13545,16.32866,42.02485
59.74800,4.97891,819.08330,-0.13545,16.36166,42.08585
59.84800,4.98728,819.45797,-0.13545,16.39514,42.10511
59.94800,4.99565,819.18715,-0.13545,16.42863,42.09119
60.04800,5.00396,818.97629,-0.13545,16.46187,42.08036
60.14800,5.01233,819.31148,-0.13545,16.49535,42.09758
60.24800,5.02070,819.38878,-0.13545,16.52883,42.10155
60.34800,5.02907,819.51059,-0.13545,16.56231,42.10781
60.44800,5.03738,820.10571,-0.13545,16.59556,42.13839
60.54800,5.04564,819.82911,-0.13545,16.62856,42.12418
60.64800,5.05401,819.60941,-0.13545,16.66204,42.11288
60.74800,5.06238,820.13784,-0.13545,16.69553,42.14004
60.84800,5.07063,820.65752,-0.13545,16.72853,42.16674
60.94800,5.07900,820.60872,-0.13545,16.76201,42.16423
61.04800,5.08731,820.15870,-0.13545,16.79526,42.14111
61.14800,5.09562,819.66491,-0.13545,16.82850,42.11574
61.24800,5.10399,821.43480,-0.13545,16.86198,42.20668
61.34800,5.11236,820.81053,-0.13545,16.89546,42.17460
61.44800,5.12067,820.93850,-0.13545,16.92870,42.18118
61.54800,5.12898,820.75996,-0.13545,16.96195,42.17200
61.64800,5.13729,820.77766,-0.13545,16.99519,42.17291
61.74800,5.14560,821.64481,-0.13545,17.02843,42.21747
61.84800,5.15391,821.55988,-0.13545,17.06168,42.21310
61.94800,5.16234,821.33897,-0.13545,17.09540,42.20175
62.04800,5.17065,821.87634,-0.13545,17.12864,42.22937
62.14800,5.17897,822.30726,-0.13545,17.16188,42.25151
62.24800,5.18728,822.55015,-0.13545,17.19513,42.26398
62.34800,5.19565,822.49893,-0.13544,17.22861,42.26135
62.44800,5.20402,822.04640,-0.13545,17.26209,42.23810
62.54800,5.21233,822.93227,-0.13545,17.29534,42.28362
62.64800,5.22064,822.45907,-0.13545,17.32858,42.25931
62.74800,5.22895,822.27299,-0.13545,17.36182,42.24974
62.84800,5.23732,822.63052,-0.13545,17.39530,42.26812
62.94800,5.24563,822.80831,-0.13545,17.42854,42.27725
63.04800,5.25394,823.28748,-0.13545,17.46179,42.30187
63.14800,5.26231,823.12450,-0.13545,17.49527,42.29350
63.24800,5.27068,822.96282,-0.13545,17.52875,42.28519
63.34800,5.27905,824.00497,-0.13545,17.56224,42.33874
63.44800,5.28730,823.55216,-0.13545,17.59524,42.31547
63.54800,5.29567,823.76217,-0.13545,17.62872,42.32626
63.64800,5.30410,823.81284,-0.13545,17.66244,42.32887
63.74800,5.31236,823.61409,-0.13545,17.69544,42.31865
63.84800,5.32067,823.84758,-0.13545,17.72869,42.33065
63.94800,5.32898,825.16773,-0.13545,17.76193,42.39848
64.04800,5.33729,824.10937,-0.13545,17.79517,42.34410
64.14800,5.34560,824.77499,-0.13545,17.82842,42.37830
64.24800,5.35403,824.50248,-0.13545,17.86214,42.36430
64.34800,5.36234,824.28651,-0.13545,17.89538,42.35320
64.44800,5.37065,824.19673,-0.13545,17.92863,42.34859
64.54800,5.37908,824.88367,-0.13545,17.96235,42.38389
64.64800,5.38733,824.33419,-0.13545,17.99535,42.35565
64.74800,5.39564,824.93192,-0.13545,18.02859,42.38636
64.84800,5.40401,825.30072,-0.13545,18.06207,42.40532
64.94800,5.41226,825.00996,-0.13545,18.09508,42.39038
65.04800,5.42063,825.31683,-0.13545,18.12856,42.40614
65.14800,5.42895,825.96187,-0.13545,18.16180,42.43929
65.24800,5.43732,825.72028,-0.13545,18.19529,42.42687
65.34800,5.44563,825.69811,-0.13545,18.22853,42.42574
65.44800,5.45394,825.70808,-0.13545,18.26177,42.42625
65.54801,5.46231,825.86501,-0.13545,18.29525,42.43431
65.64800,5.47074,825.84834,-0.13545,18.32898,42.43345
65.74800,5.47905,826.10874,-0.13545,18.36222,42.44683
65.84800,5.48730,826.30813,-0.13545,18.39522,42.45708
65.94801,5.49573,826.47633,-0.13545,18.42894,42.46572
66.04801,5.50398,826.21323,-0.13545,18.46195,42.45220
66.14800,5.51229,826.15865,-0.13545,18.49519,42.44940
66.24800,5.52072,826.93361,-0.13545,18.52891,42.48922
66.34800,5.52897,826.79931,-0.13545,18.56192,42.48232
66.44801,5.53728,826.63130,-0.13545,18.59516,42.47368
66.54801,5.54577,827.27624,-0.13545,18.62912,42.50682
66.64800,5.55402,827.44304,-0.13545,18.66212,42.51539
66.74800,5.56240,826.58371,-0.13545,18.69560,42.47124
66.84800,5.57077,826.48704,-0.13545,18.72909,42.46627
66.94801,5.57896,827.50553,-0.13545,18.76185,42.51860
67.04801,5.58733,827.16979,-0.13545,18.79534,42.50135
67.14800,5.59564,827.15508,-0.13545,18.82858,42.50060
67.24800,5.60401,826.98800,-0.13545,18.86206,42.49201
67.34800,5.61232,827.19261,-0.13545,18.89530,42.50252
67.44801,5.62063,827.15694,-0.13545,18.92854,42.50069
67.54801,5.62900,827.61599,-0.13545,18.96203,42.52428
67.64800,5.63737,827.82535,-0.13545,18.99551,42.53503
67.74800,5.64568,827.99038,-0.13545,19.02875,42.54351
67.84800,5.65393,827.56700,-0.13545,19.06176,42.52176
67.94801,5.66236,827.33147,-0.13545,19.09548,42.50966
68.04801,5.67061,828.20626,-0.13545,19.12848,42.55461
68.14800,5.67893,828.35965,-0.13545,19.16173,42.56249
68.24800,5.68730,828.28011,-0.13545,19.19520,42.55840
68.34800,5.69561,828.08388,-0.13545,19.22845,42.54832
68.44801,5.70392,827.92370,-0.13545,19.26169,42.54009
68.54801,5.71235,828.90932,-0.13545,19.29541,42.59073
68.64800,5.72060,827.94446,-0.13545,19.32842,42.54116
68.74800,5.72897,829.02331,-0.13545,19.36190,42.59659
68.84800,5.73740,828.54349,-0.13545,19.39562,42.57193
68.94801,5.74571,828.79448,-0.13545,19.42886,42.58483
69.04801,5.75402,829.19504,-0.13545,19.46211,42.60541
69.14800,5.76239,828.91844,-0.13545,19.49559,42.59120
69.24800,5.77064,829.53935,-0.13545,19.52859,42.62310
69.34800,5.77895,828.92962,-0.13545,19.56183,42.59177
69.44801,5.78732,828.84245,-0.13545,19.59532,42.58730
69.54801,5.79563,829.33931,-0.13545,19.62856,42.61282
69.64800,5.80401,828.90326,-0.13545,19.66204,42.59042
69.74800,5.81232,829.30923,-0.13545,19.69528,42.61128
69.84800,5.82069,829.19803,-0.13545,19.72877,42.60556
69.94801,5.82906,829.67887,-0.13545,19.76225,42.63027
70.04801,5.83737,829.66639,-0.13545,19.79549,42.62963
70.14800,5.84562,829.77517,-0.13545,19.82850,42.63522
70.24800,5.85405,829.25586,-0.13545,19.86222,42.60854
70.34800,5.86224,830.05158,-0.13545,19.89498,42.64942
70.44801,5.87061,829.52101,-0.13545,19.92846,42.62216
70.54801,5.87904,829.99105,-0.13545,19.96218,42.64631
70.64800,5.88729,830.18765,-0.13545,19.99519,42.65641
70.74800,5.89566,830.11687,-0.13545,20.02867,42.65277
70.84800,5.90403,830.13475,-0.13545,20.06215,42.65369
70.94801,5.91234,830.61289,-0.13545,20.09540,42.67826
71.04801,5.92071,830.40325,-0.13545,20.12888,42.66749
71.14800,5.92908,830.17666,-0.13545,20.16236,42.65585
71.24800,5.93728,830.09824,-0.13545,20.19513,42.65182
71.34801,5.94565,830.04106,-0.13545,20.22861,42.64888
71.44801,5.95402,829.81922,-0.13545,20.26209,42.63748
71.54801,5.96227,831.04102,-0.13545,20.29509,42.70026
71.64800,5.97070,830.80502,-0.13545,20.32881,42.68813
71.74800,5.97907,830.07012,-0.13545,20.36230,42.65038
71.84801,5.98726,830.58868,-0.13545,20.39506,42.67702
71.94801,5.99575,830.33750,-0.13545,20.42902,42.66411
72.04801,6.00406,830.71552,-0.13545,20.46226,42.68354
72.14800,6.01231,830.68926,-0.13545,20.49527,42.68219
72.24800,6.02080,831.17513,-0.13545,20.52923,42.70715
72.34801,6.02899,830.71217,-0.13545,20.56199,42.68336
72.44801,6.03724,830.50588,-0.13545,20.59500,42.67276
72.54801,6.04573,831.00237,-0.13545,20.62896,42.69828
72.64800,6.05393,830.62844,-0.13545,20.66172,42.67906
72.74800,6.06230,831.04633,-0.13545,20.69520,42.70053
72.84801,6.07073,830.96372,-0.13545,20.72893,42.69629
72.94801,6.07892,831.48135,-0.13545,20.76169,42.72289
73.04801,6.08729,831.32638,-0.13545,20.79517,42.71492
73.14800,6.09572,831.24544,-0.13545,20.82889,42.71077
73.24800,6.10397,831.41532,-0.13545,20.86190,42.71949
73.34801,6.11234,830.96009,-0.13545,20.89538,42.69610
73.44801,6.12071,831.07799,-0.13545,20.92886,42.70216
73.54801,6.12896,831.36093,-0.13545,20.96187,42.71670
73.64800,6.13733,831.15073,-0.13545,20.99535,42.70590
73.74800,6.14564,831.61350,-0.13545,21.02859,42.72968
73.84801,6.15389,831.88023,-0.13545,21.06159,42.74338
73.94801,6.16238,831.79595,-0.13545,21.09555,42.73905
74.04801,6.17069,831.74631,-0.13545,21.12880,42.73650
74.14800,6.17900,831.79884,-0.13545,21.16204,42.73920
74.24800,6.18743,831.39297,-0.13545,21.19576,42.71835
74.34801,6.19569,831.89234,-0.13545,21.22877,42.74400
74.44801,6.20394,831.71614,-0.13545,21.26177,42.73495
74.54801,6.21237,831.92484,-0.13545,21.29549,42.74567
74.64800,6.22062,831.71641,-0.13545,21.32849,42.73496
74.74800,6.22893,832.50916,-0.13545,21.36174,42.77570
74.84801,6.23736,831.84708,-0.13545,21.39546,42.74168
74.94801,6.24561,831.83404,-0.13545,21.42846,42.74101
75.04801,6.25392,831.70980,-0.13545,21.46170,42.73462
75.14800,6.26241,832.35148,-0.13545,21.49567,42.76759
75.24800,6.27066,831.84233,-0.13545,21.52867,42.74143
75.34801,6.27897,831.85397,-0.13545,21.56191,42.74203
75.44801,6.28734,831.89448,-0.13545,21.59539,42.74411
75.54801,6.29559,832.00196,-0.13545,21.62840,42.74963
75.64800,6.30396,831.69155,-0.13545,21.66188,42.73368
75.74800,6.31234,831.79493,-0.13545,21.69536,42.73900
75.84801,6.32059,832.03055,-0.13545,21.72837,42.75111
75.94801,6.32896,832.03251,-0.13545,21.76185,42.75121
76.04801,6.33733,832.11875,-0.13545,21.79533,42.75564
76.14800,6.34564,832.63731,-0.13545,21.82857,42.78228
76.24800,6.35401,832.17220,-0.13545,21.86206,42.75838
76.34801,6.36238,832.46287,-0.13545,21.89554,42.77332
76.44801,6.37069,832.19409,-0.13545,21.92878,42.75951
76.54801,6.37912,831.65355,-0.13545,21.96250,42.73174
76.64800,6.38731,832.41249,-0.13545,21.99527,42.77073
76.74800,6.39556,832.37328,-0.13545,22.02827,42.76871
76.84801,6.40399,832.28843,-0.13545,22.06199,42.76435
76.94801,6.41224,832.32382,-0.13545,22.09500,42.76617
77.04801,6.42061,831.75702,-0.13545,22.12848,42.73705
77.14800,6.42910,831.74789,-0.13545,22.16244,42.73658
77.24800,6.43730,831.61164,-0.13545,22.19520,42.72958
77.34801,6.44561,831.95325,-0.13545,22.22845,42.74713
77.44801,6.45410,831.96163,-0.13545,22.26241,42.74756
77.54801,6.46235,832.80522,-0.13545,22.29541,42.79091
77.64800,6.47072,832.34096,-0.13545,22.32889,42.76706
77.74800,6.47903,832.75195,-0.13546,22.36214,42.78817
77.84801,6.48728,832.89593,-0.13545,22.39514,42.79557
77.94801,6.49565,832.47861,-0.13545,22.42862,42.77413
78.04801,6.50396,832.45160,-0.13545,22.46187,42.77274
78.14800,6.51227,833.15028,-0.13545,22.49511,42.80864
78.24800,6.52064,832.09248,-0.13545,22.52859,42.75429
78.34801,6.52895,832.34590,-0.13545,22.56183,42.76731
78.44801,6.53726,833.15447,-0.13545,22.59507,42.80885
78.54801,6.54575,832.48299,-0.13545,22.62904,42.77435
78.64800,6.55406,832.33388,-0.13546,22.66228,42.76669
78.74800,6.56232,832.40913,-0.13545,22.69528,42.77056
78.84801,6.57080,832.46036,-0.13545,22.72924,42.77319
78.94801,6.57900,832.23563,-0.13545,22.76201,42.76164
79.04801,6.58725,832.17686,-0.13545,22.79501,42.75862
79.14800,6.59580,832.83586,-0.13546,22.82921,42.79248
79.24800,6.60399,831.98939,-0.13545,22.86198,42.74899
79.34801,6.61230,832.63656,-0.13545,22.89522,42.78224
79.44801,6.62073,832.22808,-0.13545,22.92894,42.76125
79.54801,6.62898,832.38538,-0.13545,22.96194,42.76934
79.64800,6.63729,832.77887,-0.13545,22.99519,42.78955
79.74800,6.64578,832.21970,-0.13546,23.02915,42.76082
79.84801,6.65397,832.65547,-0.13545,23.06191,42.78321
79.94801,6.66234,832.61067,-0.13545,23.09539,42.78091
80.04801,6.67071,832.39265,-0.13545,23.12888,42.76971
80.14800,6.67890,832.71991,-0.13545,23.16164,42.78653
80.24800,6.68733,832.58357,-0.13545,23.19536,42.77952
80.34801,6.69571,832.38510,-0.13546,23.22885,42.76932
80.44801,6.70396,832.43512,-0.13545,23.26185,42.77189
80.54801,6.71239,832.93179,-0.13545,23.29557,42.79741
80.64800,6.72076,831.92447,-0.13545,23.32905,42.74566
80.74800,6.72895,832.68313,-0.13545,23.36181,42.78463
80.84801,6.73738,832.40783,-0.13545,23.39554,42.77049
80.94801,6.74563,833.26055,-0.13545,23.42854,42.81430
81.04801,6.75382,832.88942,-0.13545,23.46131,42.79523
81.14800,6.76237,833.23400,-0.13545,23.49550,42.81294
81.24800,6.77062,832.02235,-0.13545,23.52851,42.75068
81.34801,6.77887,832.59111,-0.13545,23.56151,42.77991
81.44801,6.78742,833.05892,-0.13545,23.59571,42.80394
81.54801,6.79567,832.61291,-0.13545,23.62871,42.78103
81.64800,6.80398,832.87489,-0.13545,23.66196,42.79449
81.74800,6.81242,832.32224,-0.13545,23.69568,42.76609
81.84801,6.82067,832.40466,-0.13545,23.72868,42.77033
81.94801,6.82898,832.57789,-0.13545,23.76193,42.77923
82.04801,6.83735,832.58199,-0.13545,23.79541,42.77944
82.14800,6.84560,832.38902,-0.13546,23.82841,42.76952
82.24800,6.85397,832.44424,-0.13545,23.86190,42.77236
82.34801,6.86234,832.11614,-0.13545,23.89538,42.75550
82.44801,6.87059,832.85915,-0.13545,23.92838,42.79368
82.54801,6.87902,832.50878,-0.13545,23.96210,42.77568
82.64800,6.88733,832.28499,-0.13545,23.99534,42.76418
82.74800,6.89564,832.16317,-0.13546,24.02859,42.75792
82.84801,6.90407,832.44322,-0.13545,24.06231,42.77231
82.94801,6.91238,831.96182,-0.13545,24.09555,42.74757
83.04801,6.92063,831.92000,-0.13545,24.12856,42.74543
83.14800,6.92900,831.79846,-0.13545,24.16204,42.73918
83.24800,6.93731,832.44881,-0.13545,24.19528,42.77259
83.34801,6.94557,832.36964,-0.13545,24.22829,42.76853
83.44801,6.95400,832.36480,-0.13546,24.26201,42.76828
83.54801,6.96225,832.38250,-0.13546,24.29501,42.76919
83.64800,6.97062,833.18148,-0.13545,24.32849,42.81024
83.74800,6.97899,831.80964,-0.13545,24.36198,42.73975
83.84801,6.98730,831.55604,-0.13546,24.39522,42.72672
83.94801,6.99567,831.33802,-0.13545,24.42870,42.71552
84.04801,7.00410,832.41323,-0.13545,24.46242,42.77077
84.14800,7.01235,832.25807,-0.13546,24.49543,42.76279
84.24800,7.02066,831.66137,-0.13545,24.52867,42.73214
84.34801,7.02897,831.98287,-0.13546,24.56191,42.74865
84.44801,7.03728,831.93714,-0.13545,24.59515,42.74630
84.54801,7.04565,831.56070,-0.13545,24.62863,42.72696
84.64800,7.05402,832.02198,-0.13545,24.66212,42.75066
84.74800,7.06233,831.58631,-0.13545,24.69536,42.72828
84.84801,7.07077,832.17984,-0.13545,24.72908,42.75877
84.94801,7.07908,831.93099,-0.13545,24.76233,42.74599
85.04801,7.08739,831.53658,-0.13545,24.79557,42.72572
85.14800,7.09576,831.46021,-0.13545,24.82905,42.72180
85.24800,7.10401,832.25193,-0.13545,24.86205,42.76248
85.34801,7.11226,831.42957,-0.13545,24.89506,42.72023
85.44801,7.12069,831.09094,-0.13545,24.92878,42.70283
85.54801,7.12900,831.37630,-0.13545,24.96202,42.71749
85.64800,7.13725,832.05877,-0.13545,24.99503,42.75256
85.74800,7.14568,831.29955,-0.13546,25.02875,42.71355
85.84801,7.15393,831.16349,-0.13545,25.06175,42.70655
85.94801,7.16230,831.78338,-0.13545,25.09523,42.73840
86.04801,7.17079,831.15771,-0.13545,25.12919,42.70626
86.14800,7.17898,831.65709,-0.13545,25.16196,42.73191
86.24800,7.18724,831.59385,-0.13545,25.19496,42.72867
86.34801,7.19573,831.64610,-0.13545,25.22892,42.73135
86.44801,7.20392,831.73299,-0.13545,25.26169,42.73582
86.54801,7.21229,830.95813,-0.13545,25.29517,42.69600
86.64800,7.22066,831.46961,-0.13546,25.32865,42.72228
86.74800,7.22891,831.03441,-0.13545,25.36165,42.69992
86.84801,7.23734,830.73471,-0.13545,25.39538,42.68452
86.94801,7.24571,830.81676,-0.13545,25.42886,42.68874
87.04801,7.25402,830.87943,-0.13545,25.46210,42.69196
87.14800,7.26245,830.59371,-0.13545,25.49582,42.67728
87.24800,7.27070,830.68823,-0.13545,25.52882,42.68213
87.34801,7.27901,830.23254,-0.13545,25.56207,42.65872
87.44801,7.28744,830.95934,-0.13545,25.59579,42.69606
87.54801,7.29563,830.63673,-0.13545,25.62855,42.67949
87.64800,7.30388,830.52581,-0.13545,25.66156,42.67379
87.74800,7.31237,830.83948,-0.13546,25.69552,42.68991
87.84801,7.32068,830.24390,-0.13545,25.72876,42.65931
87.94801,7.32894,830.18066,-0.13545,25.76177,42.65606
88.04801,7.33749,829.79649,-0.13545,25.79597,42.63631
88.14800,7.34562,829.86364,-0.13546,25.82849,42.63977
88.24800,7.35393,829.93554,-0.13545,25.86173,42.64346
88.34801,7.36242,829.56487,-0.13546,25.89569,42.62441
88.44801,7.37061,829.51132,-0.13545,25.92846,42.62166
88.54801,7.37898,829.15602,-0.13545,25.96194,42.60340
88.64800,7.38735,829.19812,-0.13545,25.99542,42.60557
88.74800,7.39560,829.19467,-0.13545,26.02843,42.60539
88.84801,7.40397,829.40394,-0.13545,26.06191,42.61615
88.94801,7.41234,829.02256,-0.13545,26.09539,42.59655
89.04801,7.42065,828.83528,-0.13545,26.12863,42.58693
89.14800,7.42902,828.92058,-0.13545,26.16212,42.59131
89.24800,7.43733,828.38992,-0.13546,26.19536,42.56404
89.34801,7.44571,827.89818,-0.13545,26.22884,42.53878
89.44801,7.45402,828.87737,-0.13546,26.26208,42.58909
89.54801,7.46239,827.71610,-0.13545,26.29557,42.52942
89.64800,7.47070,827.74423,-0.13545,26.32881,42.53086
89.74800,7.47901,827.04565,-0.13546,26.36205,42.49497
89.84801,7.48732,827.31154,-0.13545,26.39530,42.50863
89.94801,7.49569,827.10814,-0.13546,26.42878,42.49818
90.04801,7.50406,826.64462,-0.13545,26.46226,42.47437
90.14800,7.51237,826.31838,-0.13545,26.49550,42.45760
90.24800,7.52068,826.13472,-0.13545,26.52875,42.44817
90.34801,7.52911,825.65192,-0.13546,26.56247,42.42336
90.44801,7.53736,825.48559,-0.13545,26.59547,42.41481
90.54801,7.54567,825.36209,-0.13546,26.62871,42.40847
90.64800,7.55398,824.42705,-0.13546,26.66196,42.36042
90.74800,7.56235,823.60459,-0.13545,26.69544,42.31816
90.84801,7.57067,822.09930,-0.13545,26.72868,42.24082
90.94801,7.57898,821.09952,-0.13545,26.76193,42.18945
91.04801,7.58735,820.00913,-0.13545,26.79541,42.13342
91.14800,7.59566,815.68668,-0.13546,26.82865,41.91133
91.24800,7.60409,89.67962,-0.13545,26.86237,4.60789
91.25800,7.60492,7.01741,-0.13545,26.86572,0.36057