File: Manufatura Aditiva/Dados/Ensaios AMR/Ensaios/Ensaios SLS/Tracao_OLABI_08_06_2018_SLS_ZX3.is_metal_RawData/Specimen_RawData_4.csv
Time,Extension,Load,Strain 1,Tensile strain,Tensile stress
(sec),(mm),(N),(mm/mm),(%),(MPa)
0.00000,0.00006,34.78143,0.00126,0.12594,1.78166
0.10000,0.00419,36.22816,0.00129,0.12911,1.85577
0.20000,0.01381,41.14285,0.00144,0.14440,2.10752
0.30000,0.02362,46.63827,0.00161,0.16053,2.38902
0.40000,0.03270,51.56887,0.00176,0.17567,2.64159
0.50000,0.04143,55.95724,0.00190,0.19039,2.86638
0.60000,0.04986,60.31477,0.00204,0.20404,3.08960
0.70000,0.05823,65.78076,0.00217,0.21750,3.36959
0.80000,0.06673,69.73493,0.00231,0.23102,3.57214
0.90000,0.07498,74.16361,0.00245,0.24476,3.79900
1.00000,0.08329,77.94755,0.00258,0.25844,3.99283
1.10000,0.09178,83.03677,0.00273,0.27299,4.25352
1.20000,0.10003,87.15463,0.00286,0.28621,4.46445
1.30000,0.10840,91.28650,0.00300,0.30038,4.67611
1.40000,0.11683,95.51311,0.00315,0.31466,4.89261
1.50000,0.12496,99.35199,0.00327,0.32740,5.08926
1.60000,0.13333,103.24421,0.00341,0.34118,5.28864
1.70000,0.14170,107.34433,0.00355,0.35524,5.49866
1.80000,0.14989,111.78388,0.00369,0.36858,5.72608
1.90000,0.15832,116.03237,0.00383,0.38297,5.94370
2.00000,0.16663,119.52642,0.00397,0.39656,6.12268
2.10000,0.17494,123.63419,0.00411,0.41133,6.33310
2.20000,0.18331,127.27421,0.00425,0.42485,6.51956
2.30000,0.19163,131.64647,0.00438,0.43826,6.74353
2.40000,0.19994,135.85537,0.00453,0.45256,6.95913
2.50000,0.20837,139.74338,0.00466,0.46588,7.15829
2.60000,0.21668,144.03040,0.00480,0.48002,7.37789
2.70000,0.22493,147.74359,0.00494,0.49409,7.56809
2.80000,0.23336,151.16741,0.00509,0.50857,7.74348
2.90000,0.24167,155.11049,0.00523,0.52257,7.94546
3.00000,0.24992,158.86094,0.00536,0.53587,8.13758
3.10000,0.25841,162.74914,0.00550,0.55025,8.33675
3.20000,0.26666,167.01419,0.00564,0.56393,8.55522
3.30000,0.27497,170.35337,0.00578,0.57750,8.72627
3.40000,0.28346,174.08824,0.00592,0.59238,8.91759
3.50000,0.29171,178.85837,0.00606,0.60616,9.16193
3.60000,0.30002,181.70106,0.00620,0.62019,9.30755
3.70000,0.30839,186.15196,0.00634,0.63396,9.53555
3.80000,0.31665,189.59305,0.00647,0.64732,9.71181
3.90000,0.32496,193.36019,0.00661,0.66125,9.90478
4.00000,0.33333,196.92346,0.00676,0.67559,10.08731
4.10000,0.34164,201.17646,0.00690,0.68984,10.30517
4.20000,0.34995,204.85169,0.00704,0.70396,10.49343
4.30000,0.35826,208.54329,0.00718,0.71780,10.68253
4.40000,0.36657,211.53921,0.00731,0.73126,10.83599
4.50000,0.37500,215.36264,0.00745,0.74518,11.03185
4.60000,0.38331,219.38095,0.00760,0.75953,11.23768
4.70000,0.39162,222.44395,0.00773,0.77336,11.39459
4.80000,0.39999,226.41534,0.00788,0.78775,11.59802
4.90000,0.40824,229.88769,0.00802,0.80200,11.77589
5.00000,0.41661,233.78825,0.00816,0.81614,11.97569
5.10000,0.42504,237.40535,0.00831,0.83092,12.16098
5.20000,0.43335,241.11688,0.00844,0.84417,12.35110
5.30000,0.44166,244.92978,0.00858,0.85819,12.54641
5.40000,0.45010,248.31870,0.00873,0.87255,12.72001
5.50000,0.45829,251.78317,0.00886,0.88646,12.89747
5.60000,0.46666,255.33037,0.00901,0.90086,13.07918
5.70000,0.47503,258.55761,0.00915,0.91483,13.24449
5.80000,0.48334,262.15087,0.00929,0.92861,13.42855
5.90000,0.49171,265.81944,0.00943,0.94294,13.61647
6.00000,0.50002,269.85761,0.00957,0.95683,13.82333
6.10000,0.50827,273.31603,0.00971,0.97086,14.00048
6.20000,0.51664,276.82974,0.00985,0.98520,14.18047
6.30000,0.52501,279.35244,0.00999,0.99932,14.30970
6.40000,0.53326,283.51755,0.01013,1.01349,14.52305
6.50000,0.54169,287.21022,0.01028,1.02761,14.71221
6.60000,0.55000,290.26098,0.01042,1.04230,14.86848
6.70000,0.55831,293.47823,0.01056,1.05625,15.03328
6.80000,0.56674,297.06983,0.01070,1.07050,15.21726
6.90000,0.57500,300.55384,0.01085,1.08477,15.39573
7.00000,0.58331,303.81060,0.01099,1.09900,15.56255
7.10000,0.59174,306.92148,0.01114,1.11395,15.72191
7.20000,0.59993,310.28790,0.01128,1.12819,15.89435
7.30000,0.60824,313.61107,0.01143,1.14259,16.06458
7.40000,0.61673,316.59980,0.01157,1.15679,16.21767
7.50000,0.62498,320.74593,0.01171,1.17073,16.43006
7.60000,0.63329,323.72109,0.01185,1.18529,16.58246
7.70000,0.64178,326.66845,0.01201,1.20063,16.73343
7.80000,0.64997,330.62438,0.01215,1.21501,16.93608
7.90000,0.65828,333.54820,0.01229,1.22929,17.08585
8.00000,0.66677,336.67076,0.01244,1.24429,17.24580
8.10000,0.67490,339.41262,0.01258,1.25836,17.38625
8.20000,0.68333,342.93197,0.01273,1.27255,17.56653
8.30000,0.69176,346.26641,0.01287,1.28726,17.73733
8.40000,0.69996,348.71742,0.01301,1.30150,17.86288
8.50000,0.70839,352.42580,0.01316,1.31600,18.05284
8.60000,0.71664,355.57556,0.01331,1.33133,18.21419
8.70000,0.72489,358.30026,0.01345,1.34542,18.35376
8.80000,0.73344,361.73426,0.01360,1.36027,18.52966
8.90000,0.74175,364.73658,0.01375,1.37501,18.68346
9.00000,0.75000,367.53151,0.01389,1.38883,18.82663
9.10000,0.75843,371.18590,0.01404,1.40409,19.01382
9.20000,0.76668,372.81790,0.01419,1.41920,19.09742
9.30000,0.77493,376.45088,0.01434,1.43375,19.28352
9.40000,0.78336,379.86550,0.01449,1.44891,19.45843
9.50000,0.79161,383.46464,0.01464,1.46376,19.64279
9.60000,0.79992,385.69542,0.01478,1.47788,19.75706
9.70000,0.80835,386.30515,0.01486,1.48610,19.78830
9.80000,0.81660,388.93640,0.01500,1.50013,19.92308
9.90000,0.82498,392.89808,0.01515,1.51451,20.12602
10.00000,0.83341,394.69711,0.01529,1.52912,20.21817
10.10000,0.84166,397.61052,0.01544,1.54385,20.36741
10.20000,0.84991,400.55444,0.01559,1.55892,20.51821
10.30000,0.85840,403.81914,0.01574,1.57384,20.68544
10.40000,0.86665,406.50051,0.01588,1.58835,20.82279
10.50000,0.87502,409.25769,0.01603,1.60336,20.96403
10.60000,0.88333,412.00104,0.01618,1.61833,21.10456
10.70000,0.89164,414.78816,0.01633,1.63344,21.24733
10.80000,0.90007,417.15312,0.01648,1.64843,21.36847
10.90000,0.90832,420.80646,0.01663,1.66329,21.55561
11.00000,0.91669,423.16937,0.01678,1.67802,21.67665
11.10000,0.92506,425.15532,0.01693,1.69295,21.77838
11.20000,0.93331,429.13449,0.01708,1.70827,21.98221
11.30000,0.94162,430.45939,0.01723,1.72332,22.05008
11.40000,0.95000,433.74249,0.01739,1.73880,22.21825
11.50000,0.95825,436.31094,0.01754,1.75420,22.34982
11.60000,0.96656,439.07324,0.01769,1.76922,22.49132
11.70000,0.97505,441.60923,0.01784,1.78435,22.62122
11.80000,0.98330,443.92212,0.01799,1.79920,22.73970
11.90000,0.99161,447.08662,0.01814,1.81447,22.90180
12.00000,1.00004,449.45665,0.01829,1.82918,23.02320
12.10000,1.00835,451.62076,0.01845,1.84466,23.13406
12.20000,1.01666,454.06204,0.01860,1.85967,23.25911
12.30000,1.02509,457.12520,0.01875,1.87527,23.41602
12.40000,1.03328,458.93262,0.01890,1.89030,23.50860
12.50000,1.04165,461.40421,0.01906,1.90568,23.63521
12.60000,1.04996,464.53425,0.01921,1.92127,23.79555
12.70000,1.05827,466.78511,0.01937,1.93662,23.91084
12.80000,1.06658,469.07794,0.01952,1.95225,24.02829
12.90000,1.07502,471.41509,0.01967,1.96738,24.14801
13.00000,1.08339,473.57255,0.01983,1.98314,24.25853
13.10000,1.09176,476.20176,0.01999,1.99878,24.39321
13.20000,1.10001,478.80299,0.02014,2.01431,24.52645
13.30000,1.10838,480.99742,0.02030,2.02984,24.63886
13.40000,1.11675,483.67791,0.02046,2.04577,24.77617
13.50000,1.12500,485.50693,0.02061,2.06146,24.86986
13.60000,1.13325,487.95114,0.02077,2.07718,24.99506
13.70000,1.14168,490.01914,0.02093,2.09323,25.10100
13.80000,1.14993,492.32347,0.02109,2.10850,25.21903
13.90000,1.15824,494.60572,0.02124,2.12447,25.33594
14.00000,1.16673,496.70641,0.02141,2.14091,25.44355
14.10000,1.17498,498.86275,0.02156,2.15629,25.55401
14.20000,1.18329,500.74528,0.02172,2.17201,25.65044
14.30000,1.19178,503.47713,0.02188,2.18769,25.79037
14.40000,1.19998,505.38154,0.02204,2.20381,25.88793
14.50000,1.20829,507.36619,0.02220,2.21980,25.98959
14.60000,1.21672,509.38982,0.02237,2.23670,26.09325
14.70000,1.22491,511.44515,0.02252,2.25247,26.19853
14.80000,1.23334,513.02733,0.02269,2.26904,26.27958
14.90000,1.24171,515.86912,0.02285,2.28535,26.42515
15.00000,1.24996,517.89475,0.02301,2.30089,26.52891
15.10000,1.25833,519.71390,0.02317,2.31697,26.62210
15.20000,1.26670,521.21617,0.02333,2.33273,26.69905
15.30000,1.27495,523.41679,0.02349,2.34937,26.81178
15.40000,1.28338,525.72046,0.02366,2.36567,26.92978
15.50000,1.29175,527.47373,0.02382,2.38211,27.01959
15.60000,1.29994,529.50387,0.02398,2.39820,27.12358
15.70000,1.30837,530.86104,0.02415,2.41460,27.19310
15.80000,1.31662,533.06166,0.02431,2.43060,27.30583
15.90000,1.32488,535.37907,0.02447,2.44714,27.42454
16.00000,1.33343,537.30095,0.02464,2.46363,27.52298
16.10000,1.34162,538.48969,0.02480,2.47991,27.58388
16.20000,1.34993,540.24528,0.02497,2.49669,27.67381
16.30000,1.35848,541.95668,0.02514,2.51351,27.76147
16.40000,1.36667,544.12335,0.02530,2.52965,27.87246
16.50000,1.37504,545.48415,0.02546,2.54635,27.94217
16.60000,1.38341,547.11276,0.02563,2.56338,28.02559
16.70000,1.39166,549.00460,0.02580,2.57985,28.12250
16.80000,1.39997,550.55274,0.02597,2.59654,28.20180
16.90000,1.40840,552.69999,0.02613,2.61348,28.31179
17.00000,1.41659,553.80748,0.02630,2.62961,28.36852
17.10000,1.42496,556.00749,0.02646,2.64636,28.48122
17.20000,1.43333,557.94702,0.02664,2.66360,28.58057
17.30000,1.44164,560.18475,0.02680,2.68009,28.69520
17.40000,1.45001,560.86471,0.02697,2.69694,28.73003
17.50000,1.45839,562.28945,0.02714,2.71356,28.80301
17.60000,1.46664,564.22115,0.02730,2.72993,28.90196
17.70000,1.47501,565.70861,0.02747,2.74680,28.97815
17.80000,1.48320,566.77088,0.02764,2.76357,29.03257
17.90000,1.49157,568.57597,0.02781,2.78068,29.12503
18.00000,1.50000,570.50092,0.02798,2.79778,29.22364
18.10000,1.50819,572.13120,0.02814,2.81446,29.30715
18.20000,1.51656,573.29014,0.02831,2.83060,29.36651
18.30000,1.52505,574.93146,0.02848,2.84801,29.45059
18.40000,1.53336,576.35708,0.02865,2.86470,29.52362
18.50000,1.54167,577.61176,0.02882,2.88195,29.58789
18.60000,1.55010,577.26796,0.02893,2.89271,29.57028
18.70000,1.55829,578.78345,0.02908,2.90775,29.64791
18.80000,1.56666,580.54547,0.02924,2.92417,29.73816
18.90000,1.57509,582.24676,0.02941,2.94112,29.82531
19.00000,1.58335,583.58596,0.02958,2.95839,29.89391
19.10000,1.59166,584.61153,0.02975,2.97510,29.94645
19.20000,1.60003,586.68451,0.02993,2.99256,30.05263
19.30000,1.60828,588.35321,0.03009,3.00903,30.13811
19.40000,1.61665,589.42391,0.03027,3.02673,30.19296
19.50000,1.62502,590.88641,0.03044,3.04388,30.26787
19.60000,1.63333,592.14183,0.03061,3.07712,30.33218
19.70000,1.64176,594.11549,0.03078,3.11084,30.43328
19.80000,1.65001,594.79759,0.03096,3.14385,30.46822
19.83000,1.65252,595.17915,0.03101,3.15389,30.48777
19.93000,1.66077,596.43192,0.03117,3.18690,30.55194
20.03000,1.66914,597.80087,0.03135,3.22038,30.62206
20.13000,1.67739,599.81947,0.03152,3.25338,30.72547
20.23000,1.68576,600.78660,0.03169,3.28686,30.77501
20.33000,1.69420,602.45330,0.03187,3.32059,30.86038
20.43000,1.70245,602.73991,0.03204,3.35359,30.87506
20.53000,1.71082,604.55892,0.03221,3.38707,30.96824
20.63000,1.71919,605.71274,0.03239,3.42055,31.02735
20.73000,1.72750,607.01170,0.03255,3.45380,31.09388
20.83000,1.73581,607.90894,0.03273,3.48704,31.13984
20.93000,1.74418,609.53763,0.03290,3.52052,31.22327
21.03000,1.75243,611.28358,0.03308,3.55353,31.31271
21.13000,1.76080,612.24652,0.03325,3.58701,31.36204
21.23000,1.76917,613.83322,0.03343,3.62049,31.44331
21.33000,1.77748,615.09516,0.03360,3.65373,31.50796
21.43000,1.78585,615.82960,0.03377,3.68721,31.54558
21.53000,1.79416,617.28512,0.03395,3.72046,31.62013
21.63000,1.80247,618.96313,0.03413,3.75370,31.70609
21.73000,1.81090,619.44551,0.03431,3.78742,31.73080
21.83000,1.81927,621.32790,0.03448,3.82090,31.82722
21.93000,1.82753,621.74685,0.03484,3.85391,31.84869
22.03000,1.83596,623.17774,0.03476,3.88763,31.92198
22.13000,1.84415,623.97420,0.03499,3.92039,31.96278
22.23000,1.85246,625.29915,0.03432,3.95364,32.03065
22.33000,1.86089,626.80794,0.02698,3.98736,32.10794
22.43000,1.86914,627.64515,-0.00100,4.02036,32.15082
22.53000,1.87745,627.88315,-0.00091,4.05360,32.16301
22.63000,1.88588,629.55301,0.00033,4.08733,32.24855
22.73000,1.89413,630.36168,0.00077,4.12033,32.28997
22.83000,1.90238,632.23722,0.00089,4.15333,32.38605
22.93000,1.91087,632.20975,-0.00057,4.18729,32.38464
23.03000,1.91912,633.92785,0.00001,4.22030,32.47265
23.13000,1.92749,635.43450,0.00175,4.25378,32.54983
23.23000,1.93586,635.85145,0.00346,4.28726,32.57119
23.33000,1.94412,637.48909,0.00411,4.32026,32.65508
23.43000,1.95255,638.05804,0.00496,4.35399,32.68422
23.53000,1.96086,639.51821,0.00607,4.38723,32.75901
23.63000,1.96917,640.69764,0.00603,4.42047,32.81943
23.73000,1.97754,641.77997,-0.00067,4.45395,32.87487
23.83000,1.98585,641.81597,-0.08843,4.48720,32.87672
23.93000,1.99422,643.38790,-0.13759,4.52068,32.95724
24.03000,2.00265,644.65790,-0.13733,4.55440,33.02229
24.13000,2.01084,645.85339,-0.13732,4.58716,33.08353
24.23000,2.01909,646.76921,-0.13735,4.62017,33.13044
24.33000,2.02752,647.35608,-0.13735,4.65389,33.16051
24.43000,2.03583,648.49970,-0.13734,4.68713,33.21909
24.53000,2.04420,649.55978,-0.13734,4.72062,33.27339
24.63000,2.05251,650.38754,-0.13734,4.75386,33.31579
24.73000,2.06082,651.53721,-0.13734,4.78710,33.37468
24.83000,2.06913,652.50481,-0.13734,4.82034,33.42425
24.93000,2.07751,653.24861,-0.13734,4.85383,33.46235
25.03000,2.08582,654.15078,-0.13735,4.88707,33.50856
25.13000,2.09413,655.83084,-0.13734,4.92031,33.59462
25.23000,2.10250,656.38409,-0.13734,4.95379,33.62296
25.33000,2.11081,657.15266,-0.13734,4.98704,33.66233
25.43000,2.11906,659.22248,-0.13734,5.02004,33.76836
25.53000,2.12743,659.32940,-0.13734,5.05352,33.77383
25.63000,2.13574,660.29066,-0.13734,5.08677,33.82307
25.73000,2.14411,661.72848,-0.13734,5.12025,33.89672
25.83000,2.15248,661.86702,-0.13734,5.15373,33.90382
25.93000,2.16085,662.95946,-0.13735,5.18721,33.95978
26.03000,2.16922,664.21754,-0.13734,5.22070,34.02423
26.13000,2.17753,665.48893,-0.13734,5.25394,34.08935
26.23000,2.18584,665.79226,-0.13734,5.28718,34.10489
26.33000,2.19421,666.94026,-0.13734,5.32066,34.16370
26.43000,2.20253,668.26516,-0.13734,5.35391,34.23156
26.53000,2.21084,668.58768,-0.13734,5.38715,34.24809
26.63000,2.21921,669.32635,-0.13734,5.42063,34.28592
26.73000,2.22752,670.34625,-0.13734,5.45387,34.33817
26.83000,2.23589,671.50700,-0.13735,5.48736,34.39762
26.93000,2.24420,672.13005,-0.13734,5.52060,34.42954
27.03000,2.25257,673.51088,-0.13735,5.55408,34.50027
27.13000,2.26088,672.99646,-0.13735,5.58732,34.47392
27.23000,2.26919,674.39927,-0.13735,5.62057,34.54578
27.33000,2.27756,675.51243,-0.13735,5.65405,34.60280
27.43000,2.28581,676.12440,-0.13735,5.68705,34.63415
27.53000,2.29418,677.65824,-0.13735,5.72054,34.71272
27.63000,2.30249,678.18235,-0.13735,5.75378,34.73957
27.73000,2.31080,679.33276,-0.13735,5.78702,34.79850
27.83000,2.31917,680.28285,-0.13735,5.82050,34.84716
27.93000,2.32749,680.64323,-0.13735,5.85375,34.86562
28.03000,2.33586,681.20761,-0.13735,5.88723,34.89454
28.13000,2.34411,682.37176,-0.13735,5.92023,34.95417
28.23000,2.35248,683.38769,-0.13735,5.95371,35.00621
28.33000,2.36085,684.53476,-0.13735,5.98720,35.06496
28.43000,2.36910,684.64791,-0.13735,6.02020,35.07076
28.53000,2.37747,686.20220,-0.13735,6.05368,35.15038
28.63000,2.38584,686.33864,-0.13735,6.08716,35.15737
28.73000,2.39409,687.45967,-0.13735,6.12017,35.21479
28.83000,2.40246,688.46182,-0.13735,6.15365,35.26613
28.93000,2.41089,689.11891,-0.13735,6.18737,35.29979
29.03000,2.41914,689.35207,-0.13735,6.22038,35.31173
29.13000,2.42751,690.15343,-0.13735,6.25386,35.35278
29.23000,2.43588,691.03283,-0.13735,6.28734,35.39783
29.33000,2.44419,691.64322,-0.13735,6.32058,35.42909
29.43000,2.45250,692.67480,-0.13735,6.35382,35.48194
29.53000,2.46088,693.84002,-0.13735,6.38731,35.54162
29.63000,2.46913,694.13222,-0.13735,6.42031,35.55659
29.73000,2.47750,694.49232,-0.13735,6.45379,35.57504
29.83000,2.48587,696.12181,-0.13735,6.48727,35.65851
29.93000,2.49418,696.13704,-0.13735,6.52052,35.65929
30.03000,2.50249,697.22896,-0.13735,6.55376,35.71522
30.13000,2.51080,698.25747,-0.13735,6.58700,35.76791
30.23000,2.51917,698.79862,-0.13735,6.62049,35.79562
30.33000,2.52760,699.88747,-0.13735,6.65421,35.85140
30.43000,2.53585,700.21162,-0.13735,6.68721,35.86800
30.53000,2.54416,701.38397,-0.13735,6.72045,35.92806
30.63000,2.55253,701.90360,-0.13735,6.75394,35.95468
30.73000,2.56072,702.92521,-0.13735,6.78670,36.00701
30.83000,2.56909,703.08293,-0.13735,6.82018,36.01509
30.93000,2.57747,704.00345,-0.13735,6.85367,36.06224
31.03000,2.58584,704.86842,-0.13735,6.88715,36.10655
31.13000,2.59415,705.13957,-0.13735,6.92039,36.12044
31.23000,2.60252,706.04384,-0.13735,6.95387,36.16676
31.33000,2.61077,707.18117,-0.13735,6.98688,36.22502
31.43000,2.61914,707.38173,-0.13735,7.02036,36.23529
31.53000,2.62751,708.03599,-0.13735,7.05384,36.26881
31.63000,2.63588,708.72330,-0.13735,7.08732,36.30401
31.73000,2.64413,709.31083,-0.13735,7.12033,36.33411
31.83000,2.65250,709.89160,-0.13735,7.15381,36.36386
31.93000,2.66081,711.02772,-0.13735,7.18705,36.42205
32.03000,2.66912,711.87387,-0.13735,7.22030,36.46540
32.13000,2.67743,711.96128,-0.13735,7.25354,36.46988
32.23000,2.68586,712.49367,-0.13735,7.28726,36.49715
32.33000,2.69417,713.43654,-0.13735,7.32050,36.54544
32.43000,2.70249,713.86984,-0.13735,7.35375,36.56764
32.53000,2.71086,715.28479,-0.13735,7.38723,36.64012
32.63000,2.71923,715.17653,-0.13735,7.42071,36.63457
32.73000,2.72748,715.83018,-0.13735,7.45371,36.66806
32.83000,2.73585,716.60895,-0.13735,7.48720,36.70795
32.93000,2.74416,717.79098,-0.13735,7.52044,36.76850
33.03000,2.75247,717.97217,-0.13735,7.55368,36.77778
33.13000,2.76084,718.43672,-0.13735,7.58716,36.80158
33.23000,2.76921,719.27966,-0.13735,7.62064,36.84476
33.33000,2.77746,719.44329,-0.13735,7.65365,36.85314
33.43000,2.78589,720.31869,-0.13735,7.68737,36.89798
33.53000,2.79426,721.35637,-0.13735,7.72085,36.95113
33.63000,2.80251,721.89150,-0.13735,7.75386,36.97855
33.73000,2.81082,721.81188,-0.13735,7.78710,36.97447
33.83000,2.81913,722.85300,-0.13735,7.82034,37.02780
33.93000,2.82744,722.87088,-0.13735,7.85358,37.02872
34.03000,2.83576,724.34340,-0.13735,7.88683,37.10415
34.13000,2.84413,724.13702,-0.13735,7.92031,37.09357
34.23000,2.85244,725.33330,-0.13735,7.95355,37.15485
34.33000,2.86081,725.97405,-0.13735,7.98704,37.18768
34.43000,2.86924,726.12306,-0.13735,8.02076,37.19531
34.53000,2.87755,726.77606,-0.13735,8.05400,37.22876
34.63000,2.88586,727.20326,-0.13735,8.08724,37.25064
34.73000,2.89417,728.70199,-0.13735,8.12049,37.32741
34.83000,2.90248,728.60406,-0.13735,8.15373,37.32240
34.93000,2.91085,729.26297,-0.13735,8.18721,37.35615
35.03000,2.91910,729.59512,-0.13735,8.22021,37.37316
35.13000,2.92741,730.47583,-0.13735,8.25346,37.41827
35.23000,2.93590,731.24035,-0.13735,8.28742,37.45744
35.33000,2.94409,731.32310,-0.13735,8.32018,37.46168
35.43000,2.95246,732.24227,-0.13735,8.35366,37.50876
35.53000,2.96090,732.66085,-0.13735,8.38739,37.53020
35.63000,2.96921,733.49131,-0.13735,8.42063,37.57274
35.73000,2.97758,732.96409,-0.13735,8.45411,37.54573
35.83000,2.98595,733.99651,-0.13735,8.48759,37.59862
35.93000,2.99414,734.80466,-0.13735,8.52036,37.64002
36.03000,3.00245,735.70805,-0.13735,8.55360,37.68629
36.13000,3.01088,735.72495,-0.13735,8.58732,37.68716
36.23000,3.01907,736.07066,-0.13735,8.62009,37.70487
36.33000,3.02744,736.70535,-0.13735,8.65357,37.73738
36.43000,3.03587,737.08058,-0.13735,8.68729,37.75660
36.53000,3.04406,738.23151,-0.13735,8.72005,37.81556
36.63000,3.05249,737.90811,-0.13736,8.75378,37.79899
36.73000,3.06092,738.05330,-0.13735,8.78750,37.80643
36.83000,3.06917,739.43655,-0.13735,8.82050,37.87729
36.93000,3.07760,739.76517,-0.13736,8.85422,37.89412
37.03000,3.08586,740.97975,-0.13735,8.88723,37.95633
37.13000,3.09405,740.89672,-0.13735,8.91999,37.95208
37.23000,3.10254,741.52653,-0.13735,8.95395,37.98434
37.33000,3.11079,742.32668,-0.13735,8.98695,38.02533
37.43000,3.11916,742.49501,-0.13735,9.02044,38.03395
37.53000,3.12759,740.58245,-0.13736,9.05416,37.93598
37.63000,3.13578,740.89179,-0.13735,9.08692,37.95183
37.73000,3.14415,742.01594,-0.13735,9.12040,38.00941
37.83000,3.15264,742.43913,-0.13736,9.15436,38.03109
37.93000,3.16083,742.79574,-0.13735,9.18713,38.04936
38.03000,3.16908,744.28068,-0.13735,9.22013,38.12542
38.13000,3.17751,743.97377,-0.13735,9.25386,38.10970
38.23000,3.18576,745.22779,-0.13735,9.28686,38.17394
38.33000,3.19413,745.48898,-0.13735,9.32034,38.18732
38.43000,3.20256,745.94235,-0.13735,9.35406,38.21054
38.53000,3.21076,746.52592,-0.13735,9.38683,38.24043
38.63000,3.21913,747.29845,-0.13735,9.42031,38.28001
38.73000,3.22750,747.22334,-0.13735,9.45379,38.27616
38.83000,3.23575,747.91261,-0.13735,9.48680,38.31147
38.93000,3.24418,748.54600,-0.13735,9.52052,38.34391
39.03000,3.25249,749.42666,-0.13735,9.55376,38.38902
39.13000,3.26080,749.55523,-0.13735,9.58700,38.39561
39.23000,3.26923,750.15747,-0.13735,9.62072,38.42646
39.33000,3.27748,750.36827,-0.13735,9.65373,38.43726
39.43000,3.28579,750.52856,-0.13736,9.68697,38.44547
39.53000,3.29416,751.37895,-0.13735,9.72045,38.48903
39.63000,3.30241,752.02598,-0.13735,9.75346,38.52217
39.73000,3.31078,752.71870,-0.13736,9.78694,38.55766
39.83000,3.31921,753.00280,-0.13735,9.82066,38.57221
39.93000,3.32746,753.31298,-0.13735,9.85366,38.58810
40.03000,3.33584,753.95051,-0.13735,9.88715,38.62075
40.13000,3.34427,754.09333,-0.13735,9.92087,38.62807
40.23000,3.35258,754.72337,-0.13735,9.95411,38.66034
40.33000,3.36083,755.35402,-0.13735,9.98711,38.69265
40.43000,3.36920,756.04920,-0.13735,10.02060,38.72826
40.53000,3.37745,756.09498,-0.13735,10.05360,38.73060
40.63000,3.38582,756.47333,-0.13736,10.08708,38.74998
40.73000,3.39419,757.42798,-0.13735,10.12056,38.79889
40.83000,3.40250,758.20191,-0.13736,10.15381,38.83853
40.93000,3.41087,757.69341,-0.13736,10.18729,38.81248
41.03000,3.41918,758.38948,-0.13736,10.22053,38.84814
41.13000,3.42749,758.72615,-0.13736,10.25377,38.86538
41.23000,3.43580,759.67088,-0.13736,10.28702,38.91378
41.33000,3.44411,759.29305,-0.13735,10.32026,38.89442
41.43000,3.45242,760.03540,-0.13735,10.35350,38.93245
41.53000,3.46079,760.16947,-0.13736,10.38698,38.93932
41.63000,3.46917,760.77254,-0.13735,10.42047,38.97021
41.73000,3.47742,761.99984,-0.13735,10.45347,39.03308
41.83000,3.48591,761.70503,-0.13735,10.48743,39.01797
41.93000,3.49416,762.18531,-0.13735,10.52044,39.04258
42.03000,3.50247,762.80911,-0.13735,10.55368,39.07453
42.13000,3.51096,763.23408,-0.13736,10.58764,39.09630
42.23000,3.51915,763.09163,-0.13736,10.62040,39.08900
42.33000,3.52752,763.67483,-0.13736,10.65389,39.11888
42.43000,3.53595,764.09159,-0.13735,10.68761,39.14023
42.53000,3.54414,764.99698,-0.13735,10.72037,39.18660
42.63000,3.55245,765.64313,-0.13735,10.75362,39.21970
42.73000,3.56088,765.47605,-0.13735,10.78734,39.21114
42.83000,3.56913,766.53855,-0.13735,10.82034,39.26557
42.93000,3.57744,766.84956,-0.13736,10.85358,39.28150
43.03000,3.58587,766.63918,-0.13735,10.88730,39.27073
43.13000,3.59413,766.94316,-0.13735,10.92031,39.28630
43.23000,3.60250,767.08631,-0.13736,10.95379,39.29363
43.33000,3.61087,767.15583,-0.13735,10.98727,39.29719
43.43000,3.61906,768.41847,-0.13735,11.02004,39.36187
43.53000,3.62749,768.43603,-0.13736,11.05376,39.36277
43.63000,3.63580,768.89093,-0.13735,11.08700,39.38607
43.73000,3.64405,769.77843,-0.13735,11.12000,39.43153
43.83000,3.65260,769.20600,-0.13736,11.15420,39.40221
43.93000,3.66085,769.59617,-0.13735,11.18721,39.42220
44.03000,3.66910,770.37313,-0.13736,11.22021,39.46199
44.13000,3.67765,770.50342,-0.13735,11.25441,39.46867
44.23000,3.68584,771.17770,-0.13735,11.28718,39.50321
44.33000,3.69415,771.32578,-0.13736,11.32042,39.51080
44.43000,3.70270,771.38492,-0.13736,11.35462,39.51382
44.53000,3.71078,772.25449,-0.13736,11.38690,39.55837
44.63000,3.71909,772.82563,-0.13735,11.42015,39.58762
44.73000,3.72758,772.60747,-0.13736,11.45411,39.57645
44.83000,3.73583,773.38894,-0.13736,11.48711,39.61648
44.93000,3.74420,772.72160,-0.13735,11.52059,39.58229
45.03000,3.75257,774.27193,-0.13736,11.55408,39.66171
45.13000,3.76076,773.82396,-0.13736,11.58684,39.63876
45.23000,3.76919,773.53208,-0.13736,11.62056,39.62381
45.33000,3.77762,774.69395,-0.13736,11.65428,39.68333
45.43000,3.78575,775.04604,-0.13735,11.68681,39.70136
45.53000,3.79418,775.39571,-0.13736,11.72053,39.71928
45.63000,3.80249,775.89420,-0.13735,11.75377,39.74481
45.73000,3.81074,776.54878,-0.13736,11.78678,39.77834
45.83000,3.81923,775.94775,-0.13736,11.82074,39.74755
45.93000,3.82748,776.74636,-0.13735,11.85374,39.78846
46.03000,3.83573,776.92852,-0.13735,11.88674,39.79779
46.13000,3.84423,777.15418,-0.13736,11.92071,39.80935
46.23000,3.85248,777.60220,-0.13736,11.95371,39.83230
46.33000,3.86079,777.90702,-0.13736,11.98695,39.84792
46.43000,3.86928,778.38525,-0.13735,12.02091,39.87241
46.53000,3.87747,778.78148,-0.13736,12.05368,39.89271
46.63000,3.88584,779.06027,-0.13736,12.08716,39.90699
46.73000,3.89415,778.99508,-0.13735,12.12040,39.90365
46.83000,3.90240,779.93437,-0.13735,12.15341,39.95177
46.93000,3.91077,779.90210,-0.13735,12.18689,39.95011
47.03000,3.91920,779.77162,-0.13736,12.22061,39.94343
47.13000,3.92745,780.49460,-0.13736,12.25361,39.98046
47.23000,3.93576,780.86066,-0.13736,12.28686,39.99921
47.33000,3.94419,780.48902,-0.13735,12.32058,39.98018
47.43000,3.95244,781.25140,-0.13735,12.35358,40.01923
47.53000,3.96081,781.37750,-0.13736,12.38706,40.02569
47.63000,3.96919,782.26468,-0.13736,12.42054,40.07113
47.73000,3.97750,782.17462,-0.13735,12.45379,40.06652
47.83000,3.98581,782.38426,-0.13736,12.48703,40.07726
47.93000,3.99412,783.04019,-0.13736,12.52027,40.11086
48.03000,4.00243,783.07316,-0.13735,12.55352,40.11255
48.13000,4.01086,782.77662,-0.13735,12.58724,40.09736
48.23000,4.01911,783.03469,-0.13735,12.62024,40.11058
48.33000,4.02748,783.74669,-0.13736,12.65372,40.14705
48.43000,4.03585,783.67665,-0.13736,12.68721,40.14346
48.53000,4.04410,784.13524,-0.13736,12.72021,40.16695
48.63000,4.05247,784.50302,-0.13736,12.75369,40.18579
48.73000,4.06090,784.97287,-0.13736,12.78741,40.20986
48.83000,4.06915,784.80300,-0.13736,12.82042,40.20116
48.93000,4.07746,785.60421,-0.13735,12.85366,40.24220
49.03000,4.08583,786.03281,-0.13735,12.88714,40.26416
49.13000,4.09409,786.13982,-0.13736,12.92015,40.26964
49.23000,4.10246,785.64025,-0.13736,12.95363,40.24405
49.33000,4.11089,786.49335,-0.13736,12.98735,40.28775
49.43000,4.11914,786.39090,-0.13735,13.02035,40.28250
49.53000,4.12751,786.51570,-0.13736,13.05383,40.28889
49.63000,4.13588,787.95888,-0.13736,13.08732,40.36282
49.73000,4.14413,787.53885,-0.13736,13.12032,40.34130
49.83000,4.15250,787.55217,-0.13736,13.15380,40.34198
49.93000,4.16081,788.23352,-0.13736,13.18705,40.37688
50.03000,4.16912,787.68460,-0.13736,13.22029,40.34877
50.13000,4.17749,788.38766,-0.13736,13.25377,40.38478
50.23000,4.18580,788.81765,-0.13736,13.28701,40.40681
50.33000,4.19405,788.77509,-0.13736,13.32002,40.40463
50.43000,4.20248,789.99316,-0.13736,13.35374,40.46702
50.53000,4.21079,789.32615,-0.13736,13.38698,40.43285
50.63000,4.21917,790.11442,-0.13735,13.42047,40.47323
50.73000,4.22766,790.36281,-0.13736,13.45443,40.48596
50.83000,4.23585,790.29817,-0.13736,13.48719,40.48265
50.93000,4.24410,790.10129,-0.13736,13.52019,40.47256
51.03000,4.25253,791.50908,-0.13736,13.55391,40.54467
51.13000,4.26078,791.10404,-0.13735,13.58692,40.52393
51.23000,4.26915,790.88928,-0.13736,13.62040,40.51292
51.33000,4.27758,791.58479,-0.13736,13.65412,40.54855
51.43000,4.28577,791.44444,-0.13735,13.68689,40.54136
51.53000,4.29414,791.94633,-0.13736,13.72037,40.56707
51.63000,4.30257,792.18224,-0.13736,13.75409,40.57915
51.73000,4.31076,792.73060,-0.13736,13.78686,40.60725
51.83000,4.31919,792.97684,-0.13736,13.82058,40.61986
51.93000,4.32750,792.48752,-0.13736,13.85382,40.59480
52.03000,4.33575,792.85474,-0.13736,13.88682,40.61361
52.13000,4.34418,793.16329,-0.13736,13.92055,40.62941
52.23000,4.35250,793.70523,-0.13736,13.95379,40.65717
52.33000,4.36081,793.41363,-0.13736,13.98703,40.64223
52.43000,4.36918,794.21718,-0.13736,14.02051,40.68340
52.53000,4.37749,794.16502,-0.13736,14.05376,40.68073
52.63000,4.38580,794.38277,-0.13736,14.08700,40.69188
52.73000,4.39423,794.57927,-0.13736,14.12072,40.70194
52.83000,4.40248,794.59893,-0.13736,14.15372,40.70295
52.93000,4.41085,794.27110,-0.13736,14.18720,40.68616
53.03000,4.41928,794.98021,-0.13736,14.22093,40.72248
53.13000,4.42747,795.16210,-0.13735,14.25369,40.73180
53.23000,4.43578,795.11348,-0.13736,14.28693,40.72931
53.33000,4.44415,795.79810,-0.13736,14.32042,40.76438
53.43000,4.45240,796.31228,-0.13735,14.35342,40.79071
53.53000,4.46083,795.93826,-0.13736,14.38714,40.77156
53.63000,4.46920,796.35885,-0.13736,14.42062,40.79310
53.73000,4.47746,796.50572,-0.13736,14.45363,40.80062
53.83000,4.48589,797.16053,-0.13736,14.48735,40.83417
53.93000,4.49420,796.62930,-0.13736,14.52059,40.80696
54.03000,4.50251,797.15252,-0.13736,14.55383,40.83376
54.13000,4.51082,797.40668,-0.13736,14.58708,40.84678
54.23000,4.51907,796.95331,-0.13736,14.62008,40.82355
54.33000,4.52744,797.90233,-0.13736,14.65356,40.87217
54.43000,4.53581,797.55597,-0.13735,14.68704,40.85442
54.53000,4.54412,797.72072,-0.13735,14.72029,40.86286
54.63000,4.55243,798.16561,-0.13736,14.75353,40.88565
54.73000,4.56080,798.44827,-0.13736,14.78701,40.90013
54.83000,4.56911,798.49251,-0.13736,14.82026,40.90240
54.93000,4.57748,798.71407,-0.13736,14.85374,40.91375
55.03000,4.58591,798.98126,-0.13735,14.88746,40.92743
55.13000,4.59422,799.34327,-0.13736,14.92070,40.94598
55.23000,4.60254,799.60069,-0.13735,14.95395,40.95916
55.33000,4.61085,798.96413,-0.13736,14.98719,40.92656
55.43000,4.61916,799.29773,-0.13736,15.02043,40.94365
55.53000,4.62747,799.78062,-0.13736,15.05368,40.96838
55.63000,4.63584,800.06318,-0.13736,15.08716,40.98285
55.73000,4.64415,799.77317,-0.13736,15.12040,40.96800
55.83000,4.65252,799.75780,-0.13736,15.15388,40.96721
55.93000,4.66089,800.30868,-0.13736,15.18736,40.99543
56.03000,4.66920,800.74929,-0.13736,15.22061,41.01800
56.13000,4.67757,800.79837,-0.13735,15.25409,41.02052
56.23000,4.68594,800.57858,-0.13736,15.28757,41.00925
56.33000,4.69419,800.94514,-0.13736,15.32058,41.02803
56.43000,4.70250,801.49202,-0.13736,15.35382,41.05605
56.53000,4.71081,801.50124,-0.13736,15.38706,41.05652
56.63000,4.71912,801.12852,-0.13736,15.42030,41.03743
56.73000,4.72755,801.54063,-0.13736,15.45402,41.05854
56.83000,4.73575,802.44737,-0.13736,15.48679,41.10498
56.93000,4.74412,801.36312,-0.13736,15.52027,41.04944
57.03000,4.75249,802.28373,-0.13736,15.55375,41.09660
57.13000,4.76080,802.12159,-0.13736,15.58700,41.08829
57.23000,4.76917,802.88192,-0.13736,15.62048,41.12724
57.33000,4.77754,803.09641,-0.13736,15.65396,41.13823
57.43000,4.78573,803.52025,-0.13735,15.68673,41.15994
57.53000,4.79410,802.82120,-0.13736,15.72021,41.12413
57.63000,4.80253,803.32570,-0.13736,15.75393,41.14997
57.73000,4.81078,803.23499,-0.13736,15.78693,41.14533
57.83000,4.81915,803.10730,-0.13735,15.82042,41.13879
57.93000,4.82758,803.13208,-0.13736,15.85414,41.14006
58.03000,4.83583,803.77711,-0.13736,15.88714,41.17310
58.13000,4.84420,804.18987,-0.13736,15.92062,41.19424
58.23000,4.85257,803.96337,-0.13736,15.95410,41.18264
58.33000,4.86083,804.19136,-0.13736,15.98711,41.19432
58.43000,4.86920,804.66783,-0.13736,16.02059,41.21872
58.53000,4.87757,804.41404,-0.13736,16.05407,41.20573
58.63000,4.88582,804.72995,-0.13736,16.08708,41.22191
58.73000,4.89419,804.89144,-0.13736,16.12056,41.23018
58.83000,4.90244,805.39519,-0.13736,16.15356,41.25599
58.93000,4.91075,804.97172,-0.13735,16.18680,41.23429
59.03000,4.91918,805.15314,-0.13736,16.22052,41.24358
59.13000,4.92749,805.55631,-0.13735,16.25377,41.26424
59.23000,4.93586,805.41214,-0.13736,16.28725,41.25685
59.33000,4.94423,805.60371,-0.13736,16.32073,41.26667
59.43000,4.95242,805.59561,-0.13736,16.35350,41.26625
59.53000,4.96079,805.52520,-0.13736,16.38698,41.26264
59.63000,4.96916,806.05559,-0.13736,16.42046,41.28981
59.73000,4.97742,806.58477,-0.13735,16.45347,41.31692
59.83000,4.98579,805.80488,-0.13735,16.48695,41.27697
59.93000,4.99416,805.94933,-0.13736,16.52043,41.28437
60.03000,5.00247,806.45457,-0.13736,16.55367,41.31025
60.13000,5.01078,806.71599,-0.13736,16.58692,41.32364
60.23000,5.01921,806.63124,-0.13736,16.62064,41.31930
60.33000,5.02758,806.14751,-0.13736,16.65412,41.29452
60.43000,5.03589,807.21704,-0.13736,16.68736,41.34931
60.53000,5.04420,807.25672,-0.13736,16.72060,41.35134
60.63000,5.05251,807.22040,-0.13736,16.75385,41.34948
60.73000,5.06088,807.75255,-0.13736,16.78733,41.37674
60.83000,5.06913,807.48014,-0.13736,16.82033,41.36279
60.93000,5.07750,807.58827,-0.13736,16.85382,41.36832
61.03000,5.08587,807.90035,-0.13736,16.88730,41.38431
61.13000,5.09412,807.28717,-0.13736,16.92030,41.35290
61.23000,5.10250,807.52103,-0.13735,16.95379,41.36488
61.33000,5.11087,807.71632,-0.13736,16.98727,41.37488
61.43000,5.11918,807.58203,-0.13736,17.02051,41.36800
61.53000,5.12749,808.00559,-0.13736,17.05375,41.38970
61.63000,5.13580,808.46027,-0.13735,17.08699,41.41299
61.73000,5.14405,808.13086,-0.13735,17.12000,41.39612
61.83000,5.15242,808.64541,-0.13736,17.15348,41.42247
61.93000,5.16085,808.24625,-0.13735,17.18720,41.40203
62.03000,5.16916,808.77524,-0.13736,17.22044,41.42913
62.13000,5.17747,808.50208,-0.13736,17.25369,41.41513
62.23000,5.18584,808.79852,-0.13736,17.28717,41.43032
62.33000,5.19409,809.08099,-0.13736,17.32018,41.44479
62.43000,5.20246,808.76807,-0.13736,17.35366,41.42876
62.53000,5.21083,809.57385,-0.13736,17.38714,41.47003
62.63000,5.21914,809.77622,-0.13736,17.42038,41.48040
62.73000,5.22751,809.16518,-0.13736,17.45386,41.44910
62.83000,5.23577,809.29343,-0.13736,17.48687,41.45567
62.93000,5.24414,809.70656,-0.13736,17.52035,41.47683
63.03000,5.25245,809.48453,-0.13735,17.55359,41.46546
63.13000,5.26082,809.83415,-0.13736,17.58708,41.48337
63.23000,5.26919,809.85036,-0.13736,17.62056,41.48420
63.33000,5.27750,810.03020,-0.13736,17.65380,41.49341
63.43000,5.28581,810.34927,-0.13736,17.68704,41.50975
63.53000,5.29418,810.11020,-0.13736,17.72052,41.49751
63.63000,5.30255,809.20951,-0.13736,17.75401,41.45137
63.73000,5.31086,810.19131,-0.13736,17.78725,41.50166
63.83000,5.31917,810.35886,-0.13736,17.82049,41.51025
63.93000,5.32748,810.28482,-0.13736,17.85373,41.50645
64.03001,5.33573,810.42936,-0.13736,17.88674,41.51385
64.13000,5.34410,810.56422,-0.13736,17.92022,41.52076
64.23000,5.35253,810.28054,-0.13736,17.95394,41.50623
64.33000,5.36079,810.90340,-0.13736,17.98695,41.53814
64.43000,5.36916,810.72608,-0.13736,18.02043,41.52906
64.53001,5.37759,810.58238,-0.13736,18.05415,41.52169
64.63000,5.38578,810.52929,-0.13736,18.08691,41.51897
64.73000,5.39415,810.59607,-0.13736,18.12040,41.52240
64.83000,5.40252,810.59597,-0.13736,18.15388,41.52239
64.93000,5.41077,810.48124,-0.13736,18.18688,41.51651
65.03001,5.41908,810.83924,-0.13736,18.22013,41.53485
65.13000,5.42751,811.34187,-0.13736,18.25385,41.56060
65.23000,5.43576,810.99728,-0.13736,18.28685,41.54295
65.33000,5.44413,811.23747,-0.13736,18.32033,41.55525
65.43000,5.45244,811.24147,-0.13736,18.35358,41.55546
65.53001,5.46081,810.97512,-0.13736,18.38706,41.54181
65.63001,5.46924,811.07756,-0.13736,18.42078,41.54706
65.73000,5.47755,811.51333,-0.13736,18.45402,41.56938
65.83000,5.48581,811.75398,-0.13736,18.48703,41.58171
65.93000,5.49424,811.17079,-0.13736,18.52075,41.55183
66.03001,5.50249,811.57899,-0.13736,18.55375,41.57275
66.13001,5.51080,811.98514,-0.13736,18.58699,41.59355
66.23000,5.51917,812.10081,-0.13736,18.62048,41.59948
66.33000,5.52748,811.55943,-0.13736,18.65372,41.57174
66.43000,5.53585,811.92572,-0.13736,18.68720,41.59051
66.53001,5.54428,811.63179,-0.13736,18.72092,41.57545
66.63001,5.55253,811.75268,-0.13736,18.75393,41.58164
66.73000,5.56084,812.13014,-0.13736,18.78717,41.60098
66.83000,5.56927,811.76208,-0.13736,18.82089,41.58213
66.93000,5.57746,811.05419,-0.13736,18.85366,41.54586
67.03001,5.58583,811.64539,-0.13736,18.88714,41.57615
67.13001,5.59420,811.81629,-0.13736,18.92062,41.58490
67.23000,5.60245,811.38723,-0.13736,18.95362,41.56292
67.33000,5.61077,811.41349,-0.13736,18.98687,41.56427
67.43000,5.61914,811.08706,-0.13736,19.02035,41.54755
67.53001,5.62751,811.86304,-0.13736,19.05383,41.58730
67.63001,5.63588,811.31365,-0.13736,19.08731,41.55915
67.73000,5.64419,810.73670,-0.13736,19.12056,41.52960
67.83000,5.65244,811.15142,-0.13736,19.15356,41.55084
67.93000,5.66081,811.37959,-0.13736,19.18704,41.56253
68.03001,5.66912,811.32408,-0.13736,19.22029,41.55969
68.13001,5.67743,811.69475,-0.13736,19.25353,41.57867
68.23000,5.68580,811.84059,-0.13736,19.28701,41.58615
68.33000,5.69411,811.24483,-0.13736,19.32025,41.55563
68.43000,5.70242,810.70736,-0.13736,19.35350,41.52810
68.53001,5.71085,810.92939,-0.13736,19.38722,41.53947
68.63001,5.71910,810.64040,-0.13736,19.42022,41.52467
68.73000,5.72741,811.25554,-0.13736,19.45346,41.55618
68.83000,5.73585,811.05717,-0.13736,19.48719,41.54602
68.93000,5.74422,810.63705,-0.13736,19.52067,41.52449
69.03001,5.75253,811.08734,-0.13736,19.55391,41.54756
69.13001,5.76096,810.63006,-0.13736,19.58763,41.52414
69.23000,5.76915,810.70652,-0.13736,19.62040,41.52805
69.33000,5.77746,810.47583,-0.13736,19.65364,41.51624
69.43000,5.78583,810.10899,-0.13736,19.68712,41.49744
69.53001,5.79414,810.18461,-0.13736,19.72037,41.50132
69.63001,5.80251,809.89096,-0.13736,19.75385,41.48628
69.73000,5.81082,809.33832,-0.13736,19.78709,41.45797
69.83000,5.81919,809.11508,-0.13736,19.82057,41.44653
69.93000,5.82756,809.24919,-0.13736,19.85405,41.45340
70.03001,5.83587,808.96588,-0.13736,19.88730,41.43889
70.13001,5.84418,808.58925,-0.13736,19.92054,41.41960
70.23000,5.85249,808.05374,-0.13736,19.95378,41.39217
70.33000,5.86080,807.89812,-0.13736,19.98702,41.38419
70.43000,5.86906,806.54398,-0.13736,20.02003,41.31483
70.53001,5.87749,805.66173,-0.13736,20.05375,41.26964
70.63001,5.88580,802.73394,-0.13736,20.08699,41.11966
70.73000,5.89423,11.74372,-0.13735,20.12071,0.60157
70.73200,5.89441,0.79307,-0.13735,20.12143,0.04062