File: Manufatura Aditiva/Dados/Ensaios AMR/Ensaios/Ensaios SLS/Tracao_OLABI_08_06_2018_SLS_ZX3.is_metal_RawData/Specimen_RawData_5.csv
Time,Extension,Load,Strain 1,Tensile strain,Tensile stress
(sec),(mm),(N),(mm/mm),(%),(MPa)
0.00000,0.00006,32.49376,0.00130,0.12970,1.65436
0.10000,0.00419,34.09435,0.00133,0.13289,1.73585
0.20000,0.01375,39.50103,0.00148,0.14842,2.01112
0.30000,0.02356,44.66894,0.00166,0.16560,2.27424
0.40000,0.03270,49.67125,0.00181,0.18118,2.52892
0.50000,0.04143,54.60701,0.00196,0.19609,2.78021
0.60000,0.04986,59.32033,0.00211,0.21052,3.02018
0.70000,0.05823,63.71974,0.00225,0.22452,3.24417
0.80000,0.06673,68.18010,0.00239,0.23888,3.47126
0.90000,0.07498,72.15051,0.00253,0.25293,3.67341
1.00000,0.08329,76.53069,0.00267,0.26702,3.89642
1.10000,0.09178,81.88849,0.00282,0.28200,4.16920
1.20000,0.10003,85.76047,0.00295,0.29506,4.36633
1.30000,0.10840,90.05837,0.00309,0.30939,4.58515
1.40000,0.11683,94.69570,0.00324,0.32381,4.82125
1.50000,0.12496,98.16582,0.00337,0.33734,4.99793
1.60000,0.13333,102.42511,0.00352,0.35167,5.21478
1.70000,0.14170,106.90847,0.00366,0.36593,5.44304
1.80000,0.14989,111.58567,0.00380,0.38002,5.68118
1.90000,0.15832,115.65223,0.00394,0.39384,5.88822
2.00000,0.16663,119.36525,0.00408,0.40765,6.07726
2.10000,0.17494,124.32033,0.00422,0.42241,6.32954
2.20000,0.18331,128.24030,0.00436,0.43619,6.52911
2.30000,0.19163,132.25891,0.00450,0.45000,6.73371
2.40000,0.19994,135.90412,0.00464,0.46423,6.91930
2.50000,0.20837,140.16199,0.00478,0.47849,7.13609
2.60000,0.21668,144.07028,0.00493,0.49254,7.33507
2.70000,0.22493,148.03992,0.00507,0.50656,7.53718
2.80000,0.23336,152.10978,0.00521,0.52055,7.74438
2.90000,0.24167,156.44291,0.00535,0.53455,7.96500
3.00000,0.24992,160.51393,0.00549,0.54888,8.17227
3.10000,0.25841,164.57115,0.00563,0.56311,8.37883
3.20000,0.26666,167.89123,0.00577,0.57697,8.54787
3.30000,0.27497,171.97985,0.00591,0.59135,8.75603
3.40000,0.28346,176.68998,0.00605,0.60520,8.99584
3.50000,0.29171,179.80372,0.00619,0.61900,9.15437
3.60000,0.30002,183.83921,0.00633,0.63269,9.35983
3.70000,0.30839,188.26739,0.00647,0.64696,9.58528
3.80000,0.31665,191.75078,0.00660,0.66044,9.76263
3.90000,0.32502,195.42908,0.00675,0.67524,9.94991
4.00000,0.33333,199.00564,0.00690,0.68971,10.13200
4.10000,0.34164,203.19137,0.00704,0.70368,10.34511
4.20000,0.34995,207.12118,0.00718,0.71773,10.54519
4.30000,0.35826,211.31507,0.00731,0.73139,10.75871
4.40000,0.36657,214.70566,0.00745,0.74507,10.93134
4.50000,0.37500,218.04408,0.00759,0.75914,11.10131
4.60000,0.38337,222.43296,0.00774,0.77350,11.32476
4.70000,0.39162,225.73920,0.00788,0.78788,11.49309
4.80000,0.39999,230.12992,0.00802,0.80218,11.71663
4.90000,0.40824,233.30813,0.00816,0.81614,11.87845
5.00000,0.41661,237.16160,0.00830,0.82982,12.07464
5.10000,0.42504,240.81348,0.00844,0.84425,12.26057
5.20000,0.43335,244.76270,0.00858,0.85848,12.46163
5.30000,0.44166,248.12615,0.00873,0.87268,12.63288
5.40000,0.45010,252.40402,0.00887,0.88680,12.85068
5.50000,0.45829,255.70982,0.00901,0.90058,13.01899
5.60000,0.46666,259.43702,0.00915,0.91452,13.20875
5.70000,0.47503,262.89874,0.00928,0.92803,13.38500
5.80000,0.48334,266.64999,0.00942,0.94239,13.57598
5.90000,0.49171,269.48019,0.00957,0.95670,13.72008
6.00000,0.50002,273.91077,0.00971,0.97086,13.94565
6.10000,0.50827,277.87325,0.00985,0.98527,14.14740
6.20000,0.51664,281.32836,0.00999,0.99942,14.32331
6.30000,0.52495,285.03558,0.01013,1.01348,14.51205
6.40000,0.53326,288.97093,0.01027,1.02731,14.71241
6.50000,0.54169,292.07913,0.01041,1.04131,14.87066
6.60000,0.55000,295.59201,0.01056,1.05552,15.04951
6.70000,0.55831,298.77652,0.01070,1.06951,15.21165
6.80000,0.56674,302.59101,0.01084,1.08380,15.40585
6.90000,0.57500,305.46456,0.01098,1.09833,15.55216
7.00000,0.58331,309.13495,0.01112,1.11211,15.73903
7.10000,0.59174,313.07985,0.01127,1.12653,15.93987
7.20000,0.59993,316.16292,0.01140,1.14002,16.09684
7.30000,0.60818,319.44625,0.01154,1.15443,16.26401
7.40000,0.61673,322.87438,0.01169,1.16874,16.43854
7.50000,0.62498,325.95457,0.01183,1.18293,16.59537
7.60000,0.63329,329.48996,0.01198,1.19766,16.77536
7.70000,0.64178,332.74184,0.01212,1.21219,16.94093
7.80000,0.64997,336.21499,0.01226,1.22600,17.11776
7.90000,0.65828,339.49798,0.01240,1.23991,17.28490
8.00000,0.66677,343.36511,0.01255,1.25457,17.48179
8.10000,0.67496,346.47256,0.01269,1.26876,17.64000
8.20000,0.68333,349.44154,0.01283,1.28267,17.79116
8.30000,0.69176,352.50494,0.01298,1.29808,17.94713
8.40000,0.70002,355.69707,0.01312,1.31189,18.10965
8.50000,0.70839,359.20059,0.01326,1.32622,18.28802
8.60000,0.71664,362.30586,0.01341,1.34090,18.44612
8.70000,0.72489,365.85482,0.01355,1.35478,18.62681
8.80000,0.73344,368.77638,0.01369,1.36943,18.77556
8.90000,0.74175,371.98600,0.01384,1.38421,18.93897
9.00000,0.75000,374.95021,0.01399,1.39861,19.08989
9.10000,0.75843,378.08057,0.01414,1.41368,19.24926
9.20000,0.76668,381.63511,0.01428,1.42792,19.43024
9.30000,0.77493,384.67990,0.01442,1.44246,19.58526
9.40000,0.78336,386.82504,0.01457,1.45702,19.69447
9.50000,0.79167,389.95899,0.01471,1.47126,19.85403
9.60000,0.79992,393.52491,0.01486,1.48607,20.03558
9.70000,0.80835,396.57452,0.01501,1.50092,20.19085
9.80000,0.81666,399.17468,0.01516,1.51568,20.32323
9.90000,0.82498,402.30942,0.01530,1.53016,20.48283
10.00000,0.83341,405.25314,0.01545,1.54465,20.63271
10.10000,0.84166,408.09140,0.01559,1.55873,20.77721
10.20000,0.84991,411.09975,0.01574,1.57369,20.93037
10.30000,0.85840,414.17778,0.01588,1.58808,21.08709
10.40000,0.86665,416.97924,0.01603,1.60333,21.22972
10.50000,0.87502,419.98303,0.01618,1.61797,21.38265
10.60000,0.88333,422.39884,0.01633,1.63252,21.50565
10.70000,0.89164,425.57241,0.01647,1.64733,21.66722
10.80000,0.90007,428.12214,0.01662,1.66227,21.79704
10.90000,0.90832,430.99294,0.01677,1.67696,21.94320
11.00000,0.91669,433.71520,0.01691,1.69141,22.08180
11.10000,0.92506,436.44863,0.01706,1.70603,22.22096
11.20000,0.93331,439.50025,0.01722,1.72167,22.37633
11.30000,0.94162,441.65109,0.01737,1.73673,22.48584
11.40000,0.95000,445.20572,0.01751,1.75149,22.66681
11.50000,0.95825,447.57514,0.01767,1.76657,22.78745
11.60000,0.96656,450.44255,0.01781,1.78130,22.93344
11.70000,0.97505,453.15665,0.01797,1.79663,23.07162
11.80000,0.98336,455.66992,0.01811,1.81098,23.19958
11.90000,0.99161,458.13364,0.01826,1.82609,23.32502
12.00000,1.00010,459.27581,0.01836,1.83608,23.38317
12.10000,1.00835,462.49055,0.01851,1.85118,23.54684
12.20000,1.01666,465.08568,0.01866,1.86610,23.67897
12.30000,1.02509,467.68347,0.01882,1.88151,23.81123
12.40000,1.03328,470.53527,0.01896,1.89624,23.95642
12.50000,1.04165,472.32034,0.01912,1.91168,24.04731
12.60000,1.05002,475.04697,0.01927,1.92700,24.18613
12.70000,1.05827,477.91377,0.01942,1.94210,24.33208
12.80000,1.06664,480.17558,0.01957,1.95726,24.44724
12.90000,1.07496,482.59757,0.01972,1.97225,24.57055
13.00000,1.08333,484.97417,0.01987,1.98698,24.69155
13.10000,1.09176,487.13158,0.02003,2.00265,24.80139
13.20000,1.10001,489.14310,0.02015,2.01547,24.90380
13.30000,1.10832,491.32765,0.02031,2.03068,25.01503
13.40000,1.11675,494.02826,0.02047,2.04677,25.15252
13.50000,1.12500,496.65421,0.02062,2.06166,25.28622
13.60000,1.13325,499.63370,0.02077,2.07700,25.43791
13.70000,1.14168,501.13029,0.02092,2.09247,25.51411
13.80000,1.14999,503.48388,0.02108,2.10802,25.63394
13.90000,1.15824,505.95300,0.02124,2.12373,25.75965
14.00000,1.16673,507.22430,0.02140,2.13982,25.82438
14.10000,1.17498,510.29897,0.02155,2.15532,25.98092
14.20000,1.18329,512.05009,0.02171,2.17132,26.07007
14.30000,1.19178,515.33813,0.02187,2.18663,26.23748
14.40000,1.19998,516.85041,0.02203,2.20256,26.31447
14.50000,1.20829,519.57532,0.02218,2.21846,26.45320
14.60000,1.21672,521.59429,0.02235,2.23457,26.55600
14.70000,1.22491,523.95170,0.02250,2.24993,26.67602
14.80000,1.23334,526.30934,0.02266,2.26587,26.79605
14.90000,1.24171,527.26176,0.02282,2.28178,26.84455
15.00000,1.24990,529.98546,0.02298,2.29783,26.98322
15.10000,1.25833,532.04452,0.02313,2.31344,27.08805
15.20000,1.26670,533.52108,0.02330,2.32963,27.16323
15.30000,1.27495,535.82243,0.02346,2.34593,27.28040
15.40000,1.28338,538.15399,0.02362,2.36196,27.39910
15.50000,1.29175,539.77007,0.02378,2.37800,27.48138
15.60000,1.29994,541.47448,0.02394,2.39381,27.56816
15.70000,1.30837,544.17546,0.02410,2.40983,27.70568
15.80000,1.31662,545.53892,0.02426,2.42648,27.77509
15.90000,1.32488,548.07663,0.02443,2.44253,27.90429
16.00000,1.33343,548.99524,0.02459,2.45870,27.95107
16.10000,1.34162,551.44434,0.02475,2.47492,28.07576
16.20000,1.34993,553.79104,0.02491,2.49103,28.19523
16.30000,1.35848,555.74174,0.02508,2.50756,28.29455
16.40000,1.36667,557.93934,0.02524,2.52418,28.40644
16.50000,1.37504,559.60459,0.02541,2.54085,28.49122
16.60000,1.38341,560.80958,0.02558,2.55804,28.55257
16.70000,1.39160,562.45071,0.02574,2.57416,28.63612
16.80000,1.39997,564.24788,0.02590,2.59001,28.72762
16.90000,1.40840,566.44036,0.02607,2.60656,28.83925
17.00000,1.41659,568.28200,0.02623,2.62322,28.93301
17.10000,1.42496,570.22180,0.02639,2.63919,29.03177
17.20000,1.43333,571.48435,0.02656,2.65639,29.09606
17.30000,1.44164,573.59012,0.02673,2.67285,29.20327
17.40000,1.45001,574.99832,0.02690,2.68968,29.27496
17.50000,1.45839,576.69762,0.02706,2.70636,29.36148
17.60000,1.46664,578.00729,0.02723,2.72260,29.42816
17.70000,1.47501,580.42402,0.02739,2.73929,29.55120
17.80000,1.48320,581.92862,0.02756,2.75611,29.62781
17.90000,1.49157,583.04081,0.02773,2.77327,29.68443
18.00000,1.50000,585.27100,0.02790,2.78959,29.79798
18.10000,1.50819,586.71520,0.02806,2.80626,29.87151
18.20000,1.51662,588.41901,0.02823,2.82307,29.95825
18.30000,1.52505,589.88924,0.02840,2.84025,30.03311
18.40000,1.53336,591.53056,0.02857,2.85704,30.11667
18.50000,1.54167,593.30007,0.02874,2.87377,30.20676
18.60000,1.55004,594.50706,0.02891,2.89072,30.26821
18.70000,1.55829,595.58656,0.02908,2.90795,30.32317
18.80000,1.56666,596.97786,0.02924,2.92427,30.39401
18.90000,1.57509,599.45793,0.02942,2.94158,30.52028
19.00000,1.58335,600.46059,0.02958,2.95844,30.57133
19.10000,1.59166,602.19197,0.02975,2.97549,30.65948
19.20000,1.60003,603.67524,0.02993,2.99268,30.73499
19.30000,1.60834,604.93369,0.03010,3.00976,30.79906
19.40000,1.61665,606.34059,0.03026,3.02610,30.87070
19.50000,1.62502,607.61585,0.03043,3.04348,30.93562
19.60000,1.63333,609.01805,0.03061,3.07672,31.00701
19.70000,1.64176,610.68558,0.03078,3.11044,31.09191
19.78400,1.64875,611.69546,0.03093,3.13843,31.14333
19.88400,1.65695,612.86497,0.03110,3.17119,31.20287
19.98400,1.66526,614.99663,0.03127,3.20443,31.31140
20.08400,1.67357,615.69936,0.03143,3.23768,31.34718
20.18400,1.68194,617.20558,0.03161,3.27116,31.42387
20.28400,1.69031,618.58711,0.03179,3.30464,31.49420
20.38400,1.69862,619.91164,0.03196,3.33788,31.56164
20.48400,1.70693,620.54093,0.03213,3.37113,31.59368
20.58400,1.71536,622.48670,0.03230,3.40485,31.69274
20.68400,1.72361,623.62016,0.03248,3.43785,31.75045
20.78400,1.73198,625.40984,0.03265,3.47133,31.84157
20.88400,1.74041,626.06260,0.03283,3.50506,31.87481
20.98400,1.74860,627.62289,0.03299,3.53782,31.95424
21.08400,1.75691,628.75878,0.03317,3.57106,32.01208
21.18400,1.76540,630.10743,0.03334,3.60502,32.08074
21.28400,1.77366,631.59522,0.03352,3.63803,32.15649
21.38400,1.78197,632.66223,0.03369,3.67127,32.21081
21.48400,1.79040,633.46284,0.03387,3.70499,32.25158
21.58400,1.79865,634.96870,0.03404,3.73800,32.32824
21.68400,1.80702,636.72359,0.03422,3.77148,32.41759
21.78400,1.81551,637.02767,0.03439,3.80544,32.43307
21.88400,1.82370,639.13846,0.03457,3.83820,32.54054
21.98400,1.83201,640.00739,0.03474,3.87145,32.58478
22.08400,1.84038,641.41327,0.03491,3.90493,32.65636
22.18400,1.84863,641.39417,0.03555,3.93793,32.65538
22.28400,1.85700,643.85943,0.03594,3.97141,32.78090
22.38400,1.86537,644.61282,0.03440,4.00490,32.81926
22.48400,1.87362,644.71932,0.00175,4.03790,32.82468
22.58400,1.88205,646.67263,0.00359,4.07162,32.92413
22.68400,1.89036,647.90659,0.00440,4.10486,32.98695
22.78400,1.89862,649.21402,0.00474,4.13787,33.05352
22.88400,1.90705,650.02022,0.00515,4.17159,33.09456
22.98400,1.91530,651.07057,0.00572,4.20459,33.14804
23.08400,1.92361,652.42536,0.00628,4.23784,33.21701
23.18400,1.93204,653.63864,0.00637,4.27156,33.27879
23.28400,1.94029,655.40341,0.00739,4.30456,33.36864
23.38400,1.94860,655.84187,0.00806,4.33780,33.39096
23.48400,1.95709,657.11834,0.00758,4.37176,33.45595
23.58400,1.96534,657.78778,0.00755,4.40477,33.49003
23.68400,1.97365,657.70261,0.00641,4.43801,33.48569
23.78400,1.98214,659.44293,0.00644,4.47197,33.57430
23.88400,1.99039,660.23958,0.00089,4.50498,33.61486
23.98400,1.99870,660.68242,-0.01875,4.53822,33.63741
24.08400,2.00707,662.28411,-0.02470,4.57170,33.71896
24.18400,2.01532,663.27420,-0.02542,4.60470,33.76936
24.28400,2.02369,665.03715,-0.13793,4.63819,33.85912
24.38400,2.03201,665.10201,-0.13352,4.67143,33.86242
24.48400,2.04032,667.26697,-0.13359,4.70467,33.97265
24.58400,2.04869,667.84052,-0.13360,4.73815,34.00185
24.68400,2.05700,669.47914,-0.13359,4.77140,34.08528
24.78400,2.06531,669.65516,-0.13360,4.80464,34.09424
24.88400,2.07368,670.96301,-0.13360,4.83812,34.16082
24.98400,2.08199,672.41355,-0.13360,4.87136,34.23468
25.08400,2.09036,673.25882,-0.13360,4.90485,34.27771
25.18400,2.09867,673.68918,-0.13360,4.93809,34.29962
25.28400,2.10698,675.24952,-0.13360,4.97133,34.37906
25.38400,2.11523,676.33055,-0.13360,5.00434,34.43410
25.48400,2.12360,676.73209,-0.13360,5.03782,34.45455
25.58400,2.13191,678.35767,-0.13360,5.07106,34.53731
25.68400,2.14022,679.00452,-0.13361,5.10431,34.57024
25.78400,2.14866,679.90138,-0.13361,5.13803,34.61591
25.88400,2.15703,680.61133,-0.13361,5.17151,34.65205
25.98400,2.16534,682.15411,-0.13361,5.20475,34.73060
26.08400,2.17371,682.47002,-0.13361,5.23823,34.74668
26.18400,2.18208,684.30272,-0.13361,5.27171,34.83999
26.28400,2.19039,684.43278,-0.13361,5.30496,34.84661
26.38400,2.19864,685.61560,-0.13361,5.33796,34.90683
26.48400,2.20701,686.61640,-0.13361,5.37144,34.95779
26.58400,2.21538,687.15969,-0.13361,5.40493,34.98545
26.68400,2.22369,688.36920,-0.13361,5.43817,35.04703
26.78400,2.23206,689.27412,-0.13361,5.47165,35.09310
26.88400,2.24037,689.97149,-0.13362,5.50489,35.12860
26.98400,2.24868,690.75529,-0.13361,5.53814,35.16851
27.08400,2.25705,691.51577,-0.13361,5.57162,35.20723
27.18400,2.26542,692.52048,-0.13362,5.60510,35.25838
27.28400,2.27373,693.91495,-0.13361,5.63834,35.32938
27.38400,2.28199,694.28561,-0.13362,5.67135,35.34825
27.48400,2.29036,695.16301,-0.13362,5.70483,35.39292
27.58400,2.29867,695.88823,-0.13362,5.73807,35.42985
27.68400,2.30698,697.03218,-0.13362,5.77132,35.48809
27.78400,2.31535,698.40741,-0.13361,5.80480,35.55811
27.88400,2.32360,699.03000,-0.13362,5.83780,35.58980
27.98400,2.33197,699.41883,-0.13362,5.87128,35.60960
28.08400,2.34034,700.90173,-0.13362,5.90477,35.68510
28.18400,2.34865,701.10024,-0.13362,5.93801,35.69521
28.28400,2.35696,701.85740,-0.13362,5.97125,35.73376
28.38400,2.36527,703.46370,-0.13362,6.00450,35.81554
28.48400,2.37364,704.04084,-0.13362,6.03798,35.84492
28.58400,2.38195,704.93352,-0.13362,6.07122,35.89037
28.68400,2.39032,705.75271,-0.13362,6.10470,35.93208
28.78400,2.39863,706.77795,-0.13362,6.13795,35.98428
28.88400,2.40701,707.27598,-0.13362,6.17143,36.00963
28.98400,2.41532,708.36698,-0.13362,6.20467,36.06518
29.08400,2.42363,708.79995,-0.13362,6.23791,36.08722
29.18400,2.43206,709.87456,-0.13362,6.27163,36.14193
29.28400,2.44037,710.87372,-0.13362,6.30488,36.19280
29.38400,2.44862,711.18232,-0.13362,6.33788,36.20852
29.48400,2.45705,712.54335,-0.13362,6.37160,36.27781
29.58400,2.46536,712.89721,-0.13362,6.40485,36.29583
29.68400,2.47367,714.04399,-0.13362,6.43809,36.35421
29.78400,2.48210,714.12721,-0.13362,6.47181,36.35845
29.88400,2.49029,714.81885,-0.13362,6.50457,36.39366
29.98400,2.49860,716.32913,-0.13362,6.53782,36.47055
30.08400,2.50703,717.18837,-0.13363,6.57154,36.51430
30.18400,2.51528,717.10520,-0.13363,6.60454,36.51007
30.28400,2.52365,718.26517,-0.13362,6.63802,36.56913
30.38400,2.53203,719.23127,-0.13363,6.67151,36.61831
30.48400,2.54034,719.67435,-0.13363,6.70475,36.64087
30.58400,2.54865,720.76931,-0.13362,6.73799,36.69662
30.68400,2.55696,721.71181,-0.13362,6.77124,36.74461
30.78400,2.56527,722.71680,-0.13362,6.80448,36.79577
30.88400,2.57364,723.42027,-0.13363,6.83796,36.83159
30.98400,2.58195,723.73250,-0.13363,6.87120,36.84748
31.08400,2.59032,724.11504,-0.13363,6.90469,36.86696
31.18400,2.59869,725.25432,-0.13362,6.93817,36.92496
31.28400,2.60700,725.82774,-0.13363,6.97141,36.95416
31.38400,2.61525,726.82747,-0.13362,7.00441,37.00506
31.48400,2.62368,726.95492,-0.13363,7.03814,37.01155
31.58400,2.63199,727.63357,-0.13363,7.07138,37.04610
31.68400,2.64036,728.40285,-0.13363,7.10486,37.08527
31.78400,2.64867,729.30539,-0.13363,7.13810,37.13122
31.88400,2.65693,730.11871,-0.13362,7.17111,37.17263
31.98400,2.66530,730.78712,-0.13363,7.20459,37.20666
32.08400,2.67367,730.93046,-0.13363,7.23807,37.21395
32.18400,2.68198,732.00213,-0.13363,7.27132,37.26852
32.28400,2.69029,732.19342,-0.13363,7.30456,37.27826
32.38400,2.69866,733.08153,-0.13363,7.33804,37.32347
32.48400,2.70703,734.11888,-0.13363,7.37152,37.37629
32.58400,2.71540,734.57859,-0.13363,7.40500,37.39969
32.68400,2.72371,735.47084,-0.13363,7.43825,37.44512
32.78400,2.73202,735.74297,-0.13363,7.47149,37.45898
32.88400,2.74033,736.84603,-0.13363,7.50473,37.51514
32.98400,2.74864,737.42107,-0.13363,7.53798,37.54441
33.08400,2.75701,737.80739,-0.13363,7.57146,37.56408
33.18400,2.76538,738.79347,-0.13363,7.60494,37.61428
33.28400,2.77369,739.16968,-0.13363,7.63818,37.63344
33.38400,2.78201,739.59827,-0.13363,7.67143,37.65526
33.48400,2.79038,740.99065,-0.13363,7.70491,37.72615
33.58400,2.79863,741.37319,-0.13363,7.73791,37.74563
33.68400,2.80700,741.79964,-0.13363,7.77140,37.76734
33.78400,2.81537,742.19438,-0.13363,7.80488,37.78744
33.88400,2.82362,743.14615,-0.13363,7.83788,37.83590
33.98400,2.83193,743.52217,-0.13363,7.87112,37.85504
34.08400,2.84030,743.95714,-0.13363,7.90461,37.87719
34.18400,2.84861,744.43584,-0.13363,7.93785,37.90156
34.28400,2.85692,745.47632,-0.13363,7.97109,37.95453
34.38400,2.86535,745.76000,-0.13363,8.00481,37.96898
34.48400,2.87372,747.01100,-0.13363,8.03830,38.03267
34.58400,2.88203,747.56290,-0.13363,8.07154,38.06076
34.68400,2.89046,748.03275,-0.13363,8.10526,38.08469
34.78400,2.89865,748.35559,-0.13363,8.13802,38.10112
34.88400,2.90697,748.76128,-0.13363,8.17127,38.12178
34.98400,2.91540,749.74778,-0.13363,8.20499,38.17200
35.08400,2.92365,750.40087,-0.13363,8.23799,38.20525
35.18400,2.93202,750.68162,-0.13363,8.27147,38.21955
35.28400,2.94033,751.12991,-0.13363,8.30472,38.24237
35.38400,2.94858,751.75394,-0.13363,8.33772,38.27414
35.48400,2.95701,752.28680,-0.13363,8.37144,38.30127
35.58400,2.96538,753.07144,-0.13363,8.40492,38.34122
35.68400,2.97369,753.97179,-0.13363,8.43817,38.38706
35.78400,2.98212,754.13226,-0.13363,8.47189,38.39523
35.88400,2.99031,754.59988,-0.13363,8.50465,38.41904
35.98400,2.99856,755.41651,-0.13363,8.53766,38.46062
36.08400,3.00699,755.89553,-0.13363,8.57138,38.48500
36.18400,3.01530,756.27086,-0.13363,8.60462,38.50412
36.28400,3.02355,757.07948,-0.13363,8.63762,38.54528
36.38400,3.03204,757.54356,-0.13363,8.67158,38.56891
36.48400,3.04030,758.25830,-0.13363,8.70459,38.60530
36.58400,3.04861,758.91414,-0.13363,8.73783,38.63869
36.68400,3.05716,759.52406,-0.13363,8.77203,38.66975
36.78400,3.06535,760.13892,-0.13363,8.80480,38.70105
36.88400,3.07366,759.88853,-0.13364,8.83804,38.68830
36.98400,3.08215,761.36380,-0.13363,8.87200,38.76341
37.08400,3.09028,761.01148,-0.13364,8.90452,38.74547
37.18400,3.09865,761.92077,-0.13364,8.93801,38.79177
37.28400,3.10708,762.71207,-0.13363,8.97173,38.83206
37.38400,3.11527,762.79608,-0.13363,9.00449,38.83633
37.48400,3.12370,763.57541,-0.13363,9.03821,38.87601
37.58400,3.13207,764.14947,-0.13364,9.07170,38.90524
37.68400,3.14026,764.21127,-0.13364,9.10446,38.90839
37.78400,3.14869,765.27088,-0.13363,9.13818,38.96233
37.88400,3.15706,765.52667,-0.13364,9.17166,38.97536
37.98400,3.16526,766.27401,-0.13363,9.20443,39.01340
38.08400,3.17369,766.72207,-0.13364,9.23815,39.03622
38.18400,3.18200,767.56431,-0.13364,9.27139,39.07910
38.28400,3.19025,767.51811,-0.13363,9.30440,39.07675
38.38400,3.19868,768.76269,-0.13364,9.33812,39.14011
38.48400,3.20699,768.56702,-0.13364,9.37136,39.13015
38.58400,3.21524,769.08465,-0.13364,9.40437,39.15651
38.68400,3.22373,769.35613,-0.13363,9.43833,39.17033
38.78400,3.23192,769.90854,-0.13364,9.47109,39.19845
38.88400,3.24023,770.83232,-0.13363,9.50433,39.24548
38.98400,3.24872,771.65063,-0.13363,9.53829,39.28715
39.08400,3.25697,771.58362,-0.13364,9.57130,39.28373
39.18400,3.26534,772.40295,-0.13363,9.60478,39.32545
39.28400,3.27371,772.56970,-0.13364,9.63826,39.33394
39.38400,3.28196,773.42708,-0.13364,9.67127,39.37759
39.48400,3.29034,773.21227,-0.13363,9.70475,39.36665
39.58400,3.29865,774.32846,-0.13364,9.73799,39.42348
39.68400,3.30702,774.59514,-0.13364,9.77147,39.43706
39.78400,3.31533,775.00744,-0.13364,9.80472,39.45805
39.88400,3.32364,775.56306,-0.13363,9.83796,39.48634
39.98400,3.33201,776.11185,-0.13363,9.87144,39.51428
40.08400,3.34038,776.17019,-0.13364,9.90492,39.51725
40.18400,3.34875,776.91805,-0.13364,9.93840,39.55533
40.28400,3.35700,776.95758,-0.13364,9.97141,39.55734
40.38400,3.36537,777.35120,-0.13364,10.00489,39.57738
40.48400,3.37368,778.80048,-0.13364,10.03813,39.65117
40.58400,3.38193,778.48020,-0.13364,10.07114,39.63486
40.68400,3.39036,778.85678,-0.13364,10.10486,39.65403
40.78400,3.39861,779.16887,-0.13364,10.13786,39.66992
40.88400,3.40698,780.15397,-0.13364,10.17134,39.72008
40.98400,3.41541,780.17418,-0.13364,10.20507,39.72111
41.08400,3.42367,781.05759,-0.13363,10.23807,39.76608
41.18400,3.43198,781.02243,-0.13364,10.27131,39.76429
41.28400,3.44035,781.33866,-0.13364,10.30480,39.78040
41.38400,3.44860,781.67329,-0.13364,10.33780,39.79743
41.48400,3.45691,782.57201,-0.13363,10.37104,39.84319
41.58400,3.46534,782.90151,-0.13364,10.40476,39.85996
41.68400,3.47365,783.13369,-0.13364,10.43801,39.87178
41.78400,3.48196,783.67069,-0.13364,10.47125,39.89912
41.88400,3.49033,784.19549,-0.13364,10.50473,39.92585
41.98400,3.49864,784.21133,-0.13364,10.53797,39.92665
42.08400,3.50707,785.09217,-0.13364,10.57170,39.97150
42.18400,3.51538,785.11415,-0.13364,10.60494,39.97262
42.28400,3.52369,785.37492,-0.13364,10.63818,39.98589
42.38400,3.53206,785.70517,-0.13364,10.67166,40.00271
42.48400,3.54038,786.60008,-0.13364,10.70491,40.04827
42.58400,3.54863,786.54690,-0.13364,10.73791,40.04556
42.68400,3.55706,787.05978,-0.13364,10.77163,40.07167
42.78400,3.56525,786.93824,-0.13364,10.80440,40.06549
42.88400,3.57362,787.92134,-0.13364,10.83788,40.11554
42.98400,3.58211,788.71781,-0.13364,10.87184,40.15609
43.08400,3.59036,788.39986,-0.13364,10.90484,40.13990
43.18400,3.59861,789.10915,-0.13364,10.93785,40.17601
43.28400,3.60710,790.18082,-0.13364,10.97181,40.23058
43.38400,3.61529,790.25188,-0.13364,11.00457,40.23420
43.48400,3.62360,789.88038,-0.13364,11.03781,40.21528
43.58400,3.63203,790.77678,-0.13364,11.07154,40.26092
43.68400,3.64022,791.44286,-0.13364,11.10430,40.29483
43.78400,3.64859,791.62270,-0.13364,11.13778,40.30399
43.88400,3.65708,792.45241,-0.13364,11.17174,40.34623
43.98400,3.66528,792.18000,-0.13364,11.20451,40.33236
44.08400,3.67365,792.78918,-0.13364,11.23799,40.36338
44.18400,3.68208,793.11049,-0.13364,11.27171,40.37973
44.28400,3.69027,793.50416,-0.13364,11.30448,40.39978
44.38400,3.69876,794.10905,-0.13364,11.33844,40.43058
44.48400,3.70707,793.70858,-0.13364,11.37168,40.41019
44.58400,3.71526,794.30658,-0.13364,11.40444,40.44063
44.68400,3.72375,795.32284,-0.13364,11.43840,40.49237
44.78400,3.73200,794.76098,-0.13364,11.47141,40.46377
44.88400,3.74025,795.48052,-0.13364,11.50441,40.50040
44.98400,3.74880,795.72015,-0.13364,11.53861,40.51260
45.08400,3.75699,796.50581,-0.13364,11.57138,40.55260
45.18400,3.76524,796.52611,-0.13364,11.60438,40.55363
45.28400,3.77379,796.43531,-0.13364,11.63858,40.54901
45.38400,3.78198,796.81063,-0.13364,11.67134,40.56812
45.48400,3.79030,797.72556,-0.13364,11.70459,40.61470
45.58400,3.79873,797.59452,-0.13364,11.73831,40.60803
45.68400,3.80692,798.13432,-0.13364,11.77107,40.63551
45.78400,3.81529,798.68641,-0.13364,11.80456,40.66362
45.88400,3.82372,798.21851,-0.13364,11.83828,40.63980
45.98400,3.83191,799.45093,-0.13364,11.87104,40.70255
46.08400,3.84034,799.76218,-0.13364,11.90476,40.71839
46.18400,3.84871,799.93606,-0.13364,11.93824,40.72725
46.28400,3.85696,799.89079,-0.13364,11.97125,40.72494
46.38400,3.86539,800.28856,-0.13364,12.00497,40.74519
46.48400,3.87370,801.01313,-0.13364,12.03821,40.78208
46.58400,3.88201,801.25453,-0.13364,12.07145,40.79437
46.68400,3.89038,801.47004,-0.13364,12.10494,40.80535
46.78400,3.89863,801.92704,-0.13364,12.13794,40.82861
46.88400,3.90694,802.40658,-0.13364,12.17118,40.85303
46.98400,3.91531,802.31316,-0.13364,12.20467,40.84827
47.08400,3.92369,802.88555,-0.13364,12.23815,40.87741
47.18400,3.93194,803.12798,-0.13364,12.27115,40.88976
47.28400,3.94037,803.26423,-0.13364,12.30487,40.89669
47.38400,3.94862,803.32495,-0.13364,12.33788,40.89978
47.48400,3.95699,803.23657,-0.13364,12.37136,40.89529
47.58400,3.96542,803.98088,-0.13364,12.40508,40.93318
47.68400,3.97361,804.56035,-0.13364,12.43784,40.96268
47.78400,3.98192,804.96948,-0.13364,12.47109,40.98351
47.88400,3.99035,805.15342,-0.13364,12.50481,40.99288
47.98400,3.99860,805.52548,-0.13364,12.53781,41.01182
48.08400,4.00697,805.82267,-0.13364,12.57129,41.02695
48.18400,4.01534,806.18402,-0.13364,12.60478,41.04535
48.28400,4.02365,806.23003,-0.13364,12.63802,41.04769
48.38400,4.03202,806.15440,-0.13364,12.67150,41.04384
48.48400,4.04033,806.98654,-0.13364,12.70474,41.08621
48.58400,4.04865,807.17951,-0.13364,12.73799,41.09603
48.68400,4.05702,807.12019,-0.13364,12.77147,41.09301
48.78400,4.06533,807.33811,-0.13364,12.80471,41.10411
48.88400,4.07364,808.05365,-0.13364,12.83796,41.14054
48.98400,4.08201,808.31666,-0.13364,12.87144,41.15393
49.08400,4.09032,809.03955,-0.13364,12.90468,41.19073
49.18400,4.09857,808.85692,-0.13364,12.93768,41.18143
49.28400,4.10700,808.73007,-0.13364,12.97141,41.17498
49.38400,4.11531,809.11648,-0.13364,13.00465,41.19465
49.48400,4.12362,809.76021,-0.13364,13.03789,41.22742
49.58400,4.13211,810.00244,-0.13364,13.07185,41.23976
49.68400,4.14030,809.67825,-0.13364,13.10462,41.22325
49.78400,4.14861,809.84784,-0.13364,13.13786,41.23189
49.88400,4.15710,810.69060,-0.13364,13.17182,41.27479
49.98400,4.16529,811.02736,-0.13364,13.20459,41.29194
50.08400,4.17367,811.21689,-0.13364,13.23807,41.30159
50.18400,4.18204,811.24622,-0.13364,13.27155,41.30308
50.28400,4.19023,812.16143,-0.13364,13.30432,41.34968
50.38400,4.19860,812.03505,-0.13364,13.33780,41.34324
50.48400,4.20703,812.24618,-0.13364,13.37152,41.35399
50.58400,4.21534,812.66053,-0.13364,13.40476,41.37509
50.68400,4.22371,813.34068,-0.13364,13.43824,41.40972
50.78400,4.23208,812.67562,-0.13365,13.47172,41.37586
50.88400,4.24027,813.94874,-0.13364,13.50449,41.44067
50.98400,4.24870,813.66152,-0.13364,13.53821,41.42605
51.08400,4.25701,813.91847,-0.13364,13.57145,41.43913
51.18400,4.26526,813.95721,-0.13364,13.60446,41.44110
51.28400,4.27375,814.64434,-0.13364,13.63842,41.47609
51.38400,4.28206,814.76904,-0.13365,13.67166,41.48244
51.48400,4.29031,814.94525,-0.13364,13.70466,41.49141
51.58400,4.29874,814.83657,-0.13364,13.73839,41.48588
51.68400,4.30694,815.23480,-0.13364,13.77115,41.50615
51.78400,4.31525,815.36537,-0.13364,13.80439,41.51280
51.88400,4.32380,816.17953,-0.13364,13.83859,41.55425
51.98400,4.33193,816.43835,-0.13364,13.87112,41.56743
52.08400,4.34030,815.82395,-0.13364,13.90460,41.53615
52.18400,4.34873,816.65870,-0.13364,13.93832,41.57865
52.28400,4.35692,816.83099,-0.13364,13.97109,41.58742
52.38400,4.36535,816.85465,-0.13364,14.00481,41.58862
52.48400,4.37372,817.80218,-0.13364,14.03829,41.63687
52.58400,4.38197,817.20194,-0.13364,14.07129,41.60630
52.68400,4.39028,817.53526,-0.13364,14.10454,41.62328
52.78400,4.39871,817.98369,-0.13364,14.13826,41.64611
52.88400,4.40702,818.49918,-0.13364,14.17150,41.67235
52.98400,4.41539,818.79096,-0.13364,14.20498,41.68721
53.08400,4.42371,818.81592,-0.13364,14.23823,41.68848
53.18400,4.43196,819.19618,-0.13364,14.27123,41.70784
53.28400,4.44033,819.20344,-0.13364,14.30471,41.70821
53.38400,4.44864,818.93513,-0.13364,14.33795,41.69455
53.48400,4.45701,818.91185,-0.13364,14.37144,41.69336
53.58400,4.46538,817.60911,-0.13364,14.40492,41.62704
53.68400,4.47363,817.76772,-0.13364,14.43792,41.63511
53.78400,4.48200,818.44022,-0.13365,14.47141,41.66935
53.88400,4.49043,819.22496,-0.13364,14.50513,41.70930
53.98400,4.49868,819.26789,-0.13364,14.53813,41.71149
54.08400,4.50693,819.89216,-0.13364,14.57113,41.74327
54.18400,4.51530,820.23749,-0.13364,14.60462,41.76086
54.28400,4.52355,820.29132,-0.13364,14.63762,41.76360
54.38400,4.53192,820.62315,-0.13364,14.67110,41.78049
54.48400,4.54035,820.83046,-0.13365,14.70482,41.79105
54.58400,4.54866,820.87899,-0.13364,14.73807,41.79351
54.68400,4.55692,821.45361,-0.13364,14.77107,41.82277
54.78400,4.56529,821.55177,-0.13364,14.80455,41.82777
54.88400,4.57366,822.01743,-0.13364,14.83803,41.85148
54.98400,4.58203,821.41738,-0.13364,14.87152,41.82093
55.08400,4.59040,822.44156,-0.13364,14.90500,41.87307
55.18400,4.59871,821.90642,-0.13364,14.93824,41.84583
55.28400,4.60702,822.72328,-0.13365,14.97149,41.88742
55.38400,4.61533,823.05837,-0.13364,15.00473,41.90448
55.48400,4.62370,822.99169,-0.13364,15.03821,41.90108
55.58400,4.63201,823.03053,-0.13365,15.07145,41.90306
55.68400,4.64026,823.68515,-0.13364,15.10446,41.93639
55.78400,4.64869,824.16292,-0.13364,15.13818,41.96071
55.88400,4.65706,824.18947,-0.13364,15.17166,41.96206
55.98400,4.66537,824.02555,-0.13364,15.20490,41.95372
56.08400,4.67374,824.28697,-0.13365,15.23838,41.96703
56.18400,4.68211,824.40283,-0.13365,15.27187,41.97293
56.28400,4.69037,824.63333,-0.13364,15.30487,41.98466
56.38400,4.69868,825.09331,-0.13364,15.33811,42.00808
56.48400,4.70705,825.28638,-0.13364,15.37160,42.01791
56.58400,4.71524,824.65056,-0.13364,15.40436,41.98554
56.68400,4.72361,825.38594,-0.13364,15.43784,42.02298
56.78400,4.73198,825.27101,-0.13365,15.47133,42.01713
56.88400,4.74029,826.37137,-0.13364,15.50457,42.07315
56.98400,4.74866,826.11032,-0.13364,15.53805,42.05986
57.08400,4.75697,825.75353,-0.13365,15.57129,42.04169
57.18400,4.76534,827.08905,-0.13364,15.60477,42.10969
57.28400,4.77371,826.59740,-0.13364,15.63826,42.08466
57.38400,4.78196,826.47810,-0.13364,15.67126,42.07858
57.48400,4.79027,827.09724,-0.13364,15.70451,42.11011
57.58400,4.79864,827.10208,-0.13365,15.73799,42.11035
57.68400,4.80696,827.51978,-0.13364,15.77123,42.13162
57.78400,4.81533,827.27252,-0.13365,15.80471,42.11903
57.88400,4.82370,827.53496,-0.13365,15.83819,42.13239
57.98400,4.83207,828.33031,-0.13364,15.87168,42.17289
58.08400,4.84038,827.56011,-0.13365,15.90492,42.13367
58.18400,4.84875,827.98749,-0.13364,15.93840,42.15543
58.28400,4.85700,828.29921,-0.13364,15.97140,42.17130
58.38400,4.86531,828.36756,-0.13365,16.00465,42.17478
58.48400,4.87374,829.23509,-0.13365,16.03837,42.21895
58.58400,4.88199,828.90121,-0.13365,16.07137,42.20195
58.68400,4.89030,828.68375,-0.13364,16.10461,42.19088
58.78400,4.89867,828.99760,-0.13365,16.13810,42.20686
58.88400,4.90692,829.93964,-0.13364,16.17110,42.25482
58.98400,4.91529,829.19523,-0.13364,16.20458,42.21692
59.08400,4.92366,830.18355,-0.13365,16.23806,42.26724
59.18400,4.93198,829.81428,-0.13364,16.27131,42.24844
59.28400,4.94041,829.57195,-0.13365,16.30503,42.23610
59.38400,4.94872,830.09619,-0.13364,16.33827,42.26279
59.48400,4.95697,829.99347,-0.13365,16.37128,42.25756
59.58400,4.96534,830.06201,-0.13365,16.40476,42.26105
59.68400,4.97359,830.23421,-0.13364,16.43776,42.26982
59.78400,4.98196,830.28208,-0.13365,16.47124,42.27226
59.88400,4.99027,830.09340,-0.13364,16.50448,42.26265
59.98400,4.99864,830.21745,-0.13364,16.53797,42.26897
60.08400,5.00695,830.90980,-0.13365,16.57121,42.30421
60.18400,5.01532,831.36205,-0.13364,16.60469,42.32724
60.28400,5.02369,831.60168,-0.13364,16.63817,42.33944
60.38400,5.03200,831.22598,-0.13365,16.67142,42.32031
60.48400,5.04043,831.61760,-0.13365,16.70514,42.34025
60.58400,5.04862,831.54561,-0.13365,16.73791,42.33659
60.68400,5.05699,831.76736,-0.13364,16.77139,42.34788
60.78400,5.06537,832.05765,-0.13365,16.80487,42.36266
60.88400,5.07362,831.89923,-0.13365,16.83787,42.35459
60.98400,5.08199,832.06752,-0.13364,16.87135,42.36316
61.08400,5.09030,832.09528,-0.13365,16.90460,42.36457
61.18400,5.09861,832.48634,-0.13365,16.93784,42.38448
61.28400,5.10704,832.44946,-0.13365,16.97156,42.38261
61.38400,5.11535,832.74255,-0.13364,17.00481,42.39753
61.48400,5.12366,832.36387,-0.13365,17.03805,42.37825
61.58400,5.13197,832.89295,-0.13365,17.07129,42.40519
61.68400,5.14028,832.92844,-0.13364,17.10453,42.40699
61.78400,5.14865,833.58921,-0.13365,17.13801,42.44063
61.88400,5.15696,832.89612,-0.13365,17.17126,42.40535
61.98400,5.16533,833.32164,-0.13364,17.20474,42.42701
62.08400,5.17364,832.99745,-0.13365,17.23798,42.41050
62.18400,5.18196,833.77073,-0.13364,17.27123,42.44987
62.28400,5.19027,833.78861,-0.13365,17.30447,42.45079
62.38400,5.19864,834.26926,-0.13364,17.33795,42.47526
62.48400,5.20707,834.24868,-0.13364,17.37167,42.47421
62.58400,5.21532,833.78041,-0.13365,17.40468,42.45037
62.68400,5.22369,833.93287,-0.13365,17.43816,42.45813
62.78400,5.23200,834.56468,-0.13365,17.47140,42.49030
62.88400,5.24025,835.02000,-0.13365,17.50441,42.51348
62.98400,5.24862,834.56477,-0.13365,17.53789,42.49030
63.08400,5.25699,835.26513,-0.13365,17.57137,42.52596
63.18400,5.26530,834.55760,-0.13365,17.60461,42.48994
63.28400,5.27367,834.81558,-0.13365,17.63810,42.50307
63.38400,5.28210,835.40604,-0.13365,17.67182,42.53313
63.48400,5.29035,835.20254,-0.13365,17.70482,42.52277
63.58400,5.29866,835.50895,-0.13364,17.73806,42.53837
63.68400,5.30709,835.62806,-0.13364,17.77178,42.54444
63.78400,5.31535,835.81246,-0.13364,17.80479,42.55383
63.88400,5.32366,835.39635,-0.13365,17.83803,42.53264
63.98400,5.33197,835.79803,-0.13365,17.87127,42.55309
64.08400,5.34022,835.40175,-0.13364,17.90428,42.53292
64.18400,5.34865,835.82215,-0.13365,17.93800,42.55432
64.28400,5.35696,836.36995,-0.13365,17.97124,42.58221
64.38400,5.36533,836.35738,-0.13365,18.00472,42.58157
64.48400,5.37370,836.55408,-0.13365,18.03821,42.59158
64.58400,5.38201,836.82379,-0.13365,18.07145,42.60532
64.68400,5.39032,836.04129,-0.13365,18.10469,42.56548
64.78400,5.39869,836.08814,-0.13365,18.13817,42.56786
64.88400,5.40694,836.36800,-0.13365,18.17118,42.58211
64.98400,5.41525,836.62551,-0.13364,18.20442,42.59522
65.08400,5.42368,837.41182,-0.13365,18.23814,42.63525
65.18400,5.43193,837.14891,-0.13365,18.27115,42.62187
65.28400,5.44025,837.37215,-0.13365,18.30439,42.63324
65.38400,5.44868,837.02262,-0.13365,18.33811,42.61544
65.48400,5.45693,837.64093,-0.13365,18.37111,42.64692
65.58400,5.46530,837.38836,-0.13364,18.40460,42.63406
65.68401,5.47379,837.15273,-0.13365,18.43856,42.62206
65.78401,5.48204,837.31357,-0.13365,18.47156,42.63025
65.88400,5.49035,837.44489,-0.13364,18.50481,42.63694
65.98400,5.49872,837.84293,-0.13365,18.53829,42.65720
66.08400,5.50691,837.61076,-0.13365,18.57105,42.64538
66.18401,5.51534,837.80373,-0.13365,18.60477,42.65521
66.28401,5.52371,838.18231,-0.13365,18.63825,42.67448
66.38400,5.53196,837.95870,-0.13365,18.67126,42.66310
66.48400,5.54039,838.81794,-0.13365,18.70498,42.70684
66.58400,5.54870,838.31055,-0.13365,18.73822,42.68101
66.68401,5.55701,838.10734,-0.13365,18.77146,42.67067
66.78401,5.56544,838.40415,-0.13365,18.80518,42.68578
66.88400,5.57370,838.80797,-0.13365,18.83819,42.70634
66.98400,5.58201,838.24620,-0.13365,18.87143,42.67773
67.08400,5.59038,838.39158,-0.13365,18.90492,42.68513
67.18401,5.59863,838.98846,-0.13365,18.93792,42.71553
67.28401,5.60694,838.63158,-0.13365,18.97116,42.69736
67.38400,5.61537,839.27931,-0.13365,19.00488,42.73034
67.48400,5.62368,839.66460,-0.13364,19.03813,42.74995
67.58400,5.63199,838.90501,-0.13364,19.07137,42.71128
67.68401,5.64036,838.56918,-0.13365,19.10485,42.69418
67.78401,5.64867,839.11428,-0.13364,19.13809,42.72193
67.88400,5.65698,839.15666,-0.13365,19.17134,42.72409
67.98400,5.66535,839.60928,-0.13365,19.20482,42.74714
68.08400,5.67360,839.32169,-0.13364,19.23782,42.73249
68.18401,5.68192,839.39508,-0.13365,19.27107,42.73623
68.28401,5.69029,839.05822,-0.13365,19.30455,42.71908
68.38400,5.69866,839.56160,-0.13365,19.33803,42.74471
68.48400,5.70697,839.90656,-0.13365,19.37127,42.76227
68.58400,5.71528,839.60397,-0.13365,19.40452,42.74686
68.68401,5.72365,840.26745,-0.13365,19.43800,42.78064
68.78401,5.73202,839.38399,-0.13365,19.47148,42.73566
68.88400,5.74039,839.58432,-0.13365,19.50496,42.74586
68.98400,5.74870,839.85012,-0.13365,19.53821,42.75940
69.08400,5.75707,839.65147,-0.13365,19.57169,42.74928
69.18401,5.76532,839.87238,-0.13365,19.60469,42.76053
69.28401,5.77363,840.59136,-0.13365,19.63794,42.79713
69.38400,5.78200,840.87150,-0.13365,19.67142,42.81140
69.48400,5.79031,840.14116,-0.13364,19.70466,42.77421
69.58400,5.79856,839.80327,-0.13365,19.73766,42.75701
69.68401,5.80705,840.76272,-0.13365,19.77162,42.80586
69.78401,5.81531,840.60747,-0.13365,19.80463,42.79795
69.88400,5.82368,840.97926,-0.13365,19.83811,42.81688
69.98400,5.83205,840.46042,-0.13365,19.87159,42.79047
70.08400,5.84036,840.48081,-0.13365,19.90483,42.79151
70.18401,5.84867,840.00574,-0.13365,19.93808,42.76732
70.28401,5.85698,840.42465,-0.13365,19.97132,42.78865
70.38400,5.86529,840.32258,-0.13365,20.00456,42.78345
70.48400,5.87360,840.30051,-0.13365,20.03781,42.78233
70.58400,5.88197,840.87104,-0.13365,20.07129,42.81137
70.68401,5.89028,840.17795,-0.13365,20.10453,42.77608
70.78401,5.89865,841.25455,-0.13365,20.13801,42.83090
70.88400,5.90702,841.14848,-0.13365,20.17150,42.82550
70.98400,5.91533,841.04184,-0.13365,20.20474,42.82007
71.08400,5.92370,840.86973,-0.13365,20.23822,42.81131
71.18401,5.93195,841.02200,-0.13365,20.27122,42.81906
71.28401,5.94027,841.40599,-0.13365,20.30447,42.83861
71.38400,5.94870,841.15937,-0.13365,20.33819,42.82605
71.48400,5.95695,840.78433,-0.13365,20.37119,42.80696
71.58400,5.96532,840.67415,-0.13365,20.40467,42.80135
71.68401,5.97375,841.31472,-0.13365,20.43840,42.83396
71.78401,5.98200,841.01176,-0.13365,20.47140,42.81854
71.88400,5.99031,841.42638,-0.13365,20.50464,42.83965
71.98400,5.99880,841.58340,-0.13365,20.53860,42.84764
72.08400,6.00699,840.90112,-0.13365,20.57137,42.81290
72.18401,6.01536,841.72804,-0.13365,20.60485,42.85501
72.28401,6.02379,841.29171,-0.13365,20.63857,42.83279
72.38400,6.03198,841.24692,-0.13365,20.67134,42.83051
72.48400,6.04023,841.97875,-0.13364,20.70434,42.86777
72.58400,6.04866,841.58247,-0.13365,20.73806,42.84760
72.68401,6.05691,842.09731,-0.13365,20.77107,42.87381
72.78401,6.06534,841.86457,-0.13365,20.80479,42.86196
72.88400,6.07372,841.92129,-0.13365,20.83827,42.86485
72.98400,6.08191,841.34657,-0.13365,20.87103,42.83559
73.08401,6.09034,841.62904,-0.13365,20.90475,42.84997
73.18401,6.09871,841.58862,-0.13365,20.93824,42.84791
73.28401,6.10696,841.41167,-0.13365,20.97124,42.83890
73.38400,6.11545,842.03528,-0.13365,21.00520,42.87065
73.48400,6.12364,841.13786,-0.13365,21.03796,42.82496
73.58401,6.13195,841.78913,-0.13365,21.07121,42.85812
73.68401,6.14038,841.55882,-0.13365,21.10493,42.84639
73.78401,6.14863,841.33307,-0.13365,21.13793,42.83490
73.88400,6.15694,842.07086,-0.13365,21.17118,42.87246
73.98400,6.16537,841.68306,-0.13365,21.20490,42.85271
74.08401,6.17362,841.53172,-0.13365,21.23790,42.84501
74.18401,6.18199,841.93153,-0.13365,21.27138,42.86537
74.28401,6.19048,841.70261,-0.13365,21.30534,42.85371
74.38400,6.19868,841.59933,-0.13364,21.33811,42.84845
74.48400,6.20693,841.92464,-0.13365,21.37111,42.86502
74.58401,6.21536,841.16003,-0.13365,21.40483,42.82609
74.68401,6.22361,841.06205,-0.13365,21.43784,42.82110
74.78401,6.23192,841.67253,-0.13365,21.47108,42.85218
74.88400,6.24041,841.94634,-0.13365,21.50504,42.86612
74.98400,6.24860,842.15747,-0.13365,21.53780,42.87687
75.08401,6.25697,841.93768,-0.13365,21.57129,42.86568
75.18401,6.26534,841.98276,-0.13365,21.60477,42.86797
75.28401,6.27365,841.44808,-0.13365,21.63801,42.84075
75.38400,6.28208,842.13149,-0.13365,21.67173,42.87555
75.48400,6.29027,842.16800,-0.13365,21.70450,42.87741
75.58401,6.29858,842.60320,-0.13365,21.73774,42.89956
75.68401,6.30695,841.19271,-0.13365,21.77122,42.82775
75.78401,6.31527,842.07216,-0.13365,21.80447,42.87253
75.88400,6.32358,841.80171,-0.13365,21.83771,42.85876
75.98400,6.33201,842.01004,-0.13365,21.87143,42.86937
76.08401,6.34026,841.59104,-0.13365,21.90444,42.84803
76.18401,6.34863,842.24073,-0.13365,21.93792,42.88111
76.28401,6.35712,841.75048,-0.13365,21.97188,42.85615
76.38400,6.36537,841.46187,-0.13365,22.00488,42.84145
76.48400,6.37368,841.36240,-0.13365,22.03812,42.83639
76.58401,6.38211,841.95854,-0.13365,22.07185,42.86674
76.68401,6.39030,841.66182,-0.13365,22.10461,42.85163
76.78401,6.39855,841.98713,-0.13365,22.13761,42.86820
76.88400,6.40698,841.67542,-0.13365,22.17134,42.85233
76.98400,6.41529,841.56832,-0.13365,22.20458,42.84687
77.08401,6.42366,841.47109,-0.13365,22.23806,42.84192
77.18401,6.43203,841.55230,-0.13365,22.27154,42.84606
77.28401,6.44034,841.88106,-0.13365,22.30479,42.86280
77.38400,6.44871,841.53609,-0.13364,22.33827,42.84523
77.48400,6.45703,841.14615,-0.13365,22.37151,42.82538
77.58401,6.46534,841.81987,-0.13365,22.40475,42.85968
77.68401,6.47377,841.31304,-0.13365,22.43847,42.83388
77.78401,6.48202,841.54475,-0.13365,22.47148,42.84568
77.88400,6.49027,840.96249,-0.13365,22.50448,42.81603
77.98400,6.49870,841.55425,-0.13365,22.53820,42.84616
78.08401,6.50695,841.14047,-0.13365,22.57121,42.82509
78.18401,6.51526,841.57223,-0.13365,22.60445,42.84707
78.28401,6.52369,841.40515,-0.13365,22.63817,42.83857
78.38400,6.53194,841.39872,-0.13365,22.67118,42.83824
78.48400,6.54031,841.42601,-0.13365,22.70466,42.83963
78.58401,6.54880,841.50862,-0.13365,22.73862,42.84383
78.68401,6.55699,841.04426,-0.13365,22.77138,42.82019
78.78401,6.56530,841.39695,-0.13365,22.80463,42.83815
78.88400,6.57379,841.44277,-0.13365,22.83859,42.84048
78.98400,6.58193,841.08161,-0.13365,22.87111,42.82209
79.08401,6.59030,841.40059,-0.13365,22.90459,42.83833
79.18401,6.59873,841.07248,-0.13365,22.93832,42.82163
79.28401,6.60692,841.16450,-0.13365,22.97108,42.82631
79.38400,6.61529,841.68557,-0.13365,23.00456,42.85284
79.48400,6.62372,841.28240,-0.13365,23.03828,42.83232
79.58401,6.63191,840.67723,-0.13365,23.07105,42.80151
79.68401,6.64040,841.03318,-0.13365,23.10501,42.81963
79.78401,6.64871,840.75835,-0.13365,23.13825,42.80564
79.88400,6.65690,841.05004,-0.13365,23.17102,42.82049
79.98400,6.66539,841.17018,-0.13365,23.20497,42.82660
80.08401,6.67364,841.19495,-0.13365,23.23798,42.82787
80.18401,6.68189,841.16226,-0.13365,23.27098,42.82620
80.28401,6.69044,841.03364,-0.13365,23.30518,42.81965
80.38400,6.69864,840.82345,-0.13365,23.33795,42.80895
80.48400,6.70689,840.50139,-0.13365,23.37095,42.79255
80.58401,6.71550,839.83140,-0.13365,23.40539,42.75844
80.68401,6.72363,840.67546,-0.13365,23.43792,42.80141
80.78401,6.73194,841.00245,-0.13365,23.47116,42.81807
80.88400,6.74043,840.80547,-0.13365,23.50512,42.80804
80.98400,6.74856,840.67043,-0.13365,23.53764,42.80116
81.08401,6.75687,840.76952,-0.13365,23.57089,42.80621
81.18401,6.76536,840.11666,-0.13365,23.60485,42.77297
81.28401,6.77361,840.29986,-0.13365,23.63785,42.78229
81.38400,6.78198,840.52058,-0.13365,23.67133,42.79353
81.48400,6.79041,840.74326,-0.13365,23.70505,42.80487
81.58401,6.79860,840.53427,-0.13365,23.73782,42.79423
81.68401,6.80703,840.03406,-0.13365,23.77154,42.76876
81.78401,6.81546,840.54032,-0.13365,23.80526,42.79454
81.88400,6.82360,840.41264,-0.13365,23.83779,42.78804
81.98400,6.83197,840.33506,-0.13365,23.87127,42.78408
82.08401,6.84034,840.33208,-0.13365,23.90475,42.78394
82.18401,6.84859,839.92872,-0.13365,23.93776,42.76340
82.28401,6.85702,839.95117,-0.13365,23.97148,42.76454
82.38400,6.86527,840.11042,-0.13365,24.00448,42.77265
82.48400,6.87358,840.48202,-0.13365,24.03772,42.79157
82.58401,6.88207,840.04896,-0.13365,24.07168,42.76952
82.68401,6.89032,839.74693,-0.13365,24.10469,42.75414
82.78401,6.89869,839.55536,-0.13365,24.13817,42.74439
82.88400,6.90706,840.17077,-0.13365,24.17165,42.77572
82.98400,6.91531,839.81538,-0.13365,24.20465,42.75763
83.08401,6.92362,839.31182,-0.13365,24.23790,42.73199
83.18401,6.93199,839.79340,-0.13365,24.27138,42.75651
83.28401,6.94030,839.21421,-0.13365,24.30462,42.72702
83.38400,6.94862,838.87950,-0.13365,24.33787,42.70998
83.48400,6.95699,839.08541,-0.13365,24.37135,42.72046
83.58401,6.96530,838.67228,-0.13365,24.40459,42.69943
83.68401,6.97361,839.14408,-0.13365,24.43784,42.72345
83.78401,6.98198,839.10739,-0.13365,24.47132,42.72158
83.88400,6.99035,838.79950,-0.13365,24.50480,42.70591
83.98400,6.99866,838.11814,-0.13365,24.53804,42.67122
84.08401,7.00703,838.74119,-0.13365,24.57152,42.70294
84.18401,7.01534,837.87292,-0.13365,24.60477,42.65873
84.28401,7.02371,838.78785,-0.13365,24.63825,42.70531
84.38400,7.03196,838.51414,-0.13365,24.67125,42.69138
84.48400,7.04027,837.70249,-0.13365,24.70450,42.65005
84.58401,7.04870,838.30375,-0.13365,24.73822,42.68066
84.68401,7.05701,838.16433,-0.13365,24.77146,42.67357
84.78401,7.06532,838.28820,-0.13365,24.80470,42.67987
84.88400,7.07375,837.88559,-0.13365,24.83843,42.65937
84.98400,7.08201,837.83688,-0.13365,24.87143,42.65689
85.08401,7.09038,837.64615,-0.13365,24.90491,42.64719
85.18401,7.09875,837.11157,-0.13365,24.93839,42.61997
85.28401,7.10694,837.08409,-0.13365,24.97116,42.61857
85.38400,7.11525,836.81149,-0.13365,25.00440,42.60469
85.48400,7.12368,836.89522,-0.13365,25.03812,42.60895
85.58401,7.13199,836.63287,-0.13365,25.07136,42.59560
85.68401,7.14030,836.20036,-0.13365,25.10461,42.57357
85.78401,7.14873,836.80386,-0.13365,25.13833,42.60430
85.88400,7.15692,836.80693,-0.13365,25.17109,42.60446
85.98400,7.16535,836.41997,-0.13365,25.20481,42.58475
86.08401,7.17372,836.32842,-0.13365,25.23830,42.58009
86.18401,7.18191,835.93735,-0.13365,25.27106,42.56018
86.28401,7.19034,835.62471,-0.13365,25.30478,42.54427
86.38400,7.19865,835.90988,-0.13365,25.33803,42.55878
86.48400,7.20691,835.92432,-0.13365,25.37103,42.55952
86.58401,7.21534,835.55914,-0.13365,25.40475,42.54093
86.68401,7.22359,835.08827,-0.13365,25.43775,42.51696
86.78401,7.23196,834.96394,-0.13365,25.47123,42.51062
86.88400,7.24039,835.06908,-0.13365,25.50496,42.51598
86.98400,7.24864,834.68705,-0.13365,25.53796,42.49653
87.08401,7.25701,835.27863,-0.13365,25.57144,42.52665
87.18401,7.26544,834.48561,-0.13365,25.60516,42.48627
87.28401,7.27369,834.66070,-0.13365,25.63817,42.49519
87.38400,7.28200,834.12183,-0.13365,25.67141,42.46775
87.48400,7.29037,833.45696,-0.13365,25.70490,42.43390
87.58401,7.29862,833.56416,-0.13365,25.73790,42.43936
87.68401,7.30693,833.43918,-0.13365,25.77114,42.43299
87.78401,7.31542,833.75499,-0.13365,25.80510,42.44907
87.88400,7.32367,832.86222,-0.13365,25.83810,42.40362
87.98400,7.33205,831.83581,-0.13365,25.87159,42.35136
88.08401,7.34042,832.49900,-0.13365,25.90507,42.38513
88.18401,7.34861,831.89569,-0.13365,25.93783,42.35441
88.28401,7.35698,832.05067,-0.13365,25.97132,42.36230
88.38400,7.36529,831.58435,-0.13365,26.00456,42.33856
88.48400,7.37360,831.68857,-0.13365,26.03780,42.34386
88.58401,7.38197,830.95804,-0.13365,26.07128,42.30667
88.68401,7.39028,830.48670,-0.13365,26.10452,42.28267
88.78401,7.39865,830.18849,-0.13365,26.13801,42.26749
88.88400,7.40702,830.20478,-0.13365,26.17149,42.26832
88.98400,7.41533,828.65609,-0.13365,26.20474,42.18947
89.08401,7.42364,828.39821,-0.13365,26.23798,42.17634
89.18401,7.43201,828.76487,-0.13365,26.27146,42.19501
89.28401,7.44038,827.38949,-0.13365,26.30494,42.12498
89.38400,7.44863,826.65430,-0.13365,26.33795,42.08755
89.48400,7.45700,825.78668,-0.13365,26.37143,42.04338
89.58401,7.46538,824.69052,-0.13365,26.40491,41.98757
89.68401,7.47369,823.35724,-0.13365,26.43815,41.91969
89.78401,7.48206,821.77287,-0.13365,26.47164,41.83903
89.88400,7.49031,820.68713,-0.13365,26.50464,41.78375
89.98400,7.49868,818.27715,-0.13365,26.53812,41.66105
90.08401,7.50705,815.23480,-0.13365,26.57160,41.50615
90.18401,7.51542,811.85568,-0.13365,26.60508,41.33411
90.28401,7.52379,569.02478,-0.13365,26.63857,28.97083
90.32001,7.52690,6.12587,-0.13365,26.65100,0.31189