File: Manufatura Aditiva/Dados/Ensaios AMR/Ensaios/Ensaios SLS/Tracao_OLABI_08_06_2018_SLS_YZ4.is_metal_RawData/Specimen_RawData_3.csv
Time,Extension,Load,Strain 1,Tensile strain,Tensile stress
(sec),(mm),(N),(mm/mm),(%),(MPa)
0.00000,0.00006,28.70453,0.00180,0.18036,1.31233
0.20000,0.01375,35.21751,0.00199,0.19858,1.61009
0.40000,0.03270,45.89289,0.00229,0.22866,2.09815
0.60000,0.04986,55.29386,0.00257,0.25694,2.52795
0.80000,0.06673,63.91471,0.00284,0.28427,2.92208
1.00000,0.08335,72.38622,0.00311,0.31081,3.30939
1.20000,0.10003,80.70081,0.00338,0.33788,3.68952
1.40000,0.11683,89.89945,0.00365,0.36530,4.11006
1.60000,0.13339,98.38688,0.00392,0.39236,4.49810
1.80000,0.14989,106.33066,0.00419,0.41899,4.86127
2.00000,0.16663,114.02726,0.00446,0.44624,5.21315
2.20000,0.18331,122.56649,0.00474,0.47351,5.60355
2.40000,0.19994,130.04380,0.00500,0.50047,5.94540
2.60000,0.21668,138.38215,0.00528,0.52827,6.32662
2.80000,0.23336,146.20754,0.00555,0.55463,6.68438
3.00000,0.24998,154.61727,0.00582,0.58164,7.06886
3.20000,0.26672,161.32969,0.00608,0.60778,7.37575
3.40000,0.28346,167.69613,0.00630,0.62971,7.66681
3.60000,0.30002,175.43655,0.00656,0.65633,8.02069
3.80000,0.31665,182.93668,0.00683,0.68343,8.36358
4.00000,0.33327,190.61426,0.00711,0.71107,8.71459
4.20000,0.34995,198.44782,0.00738,0.73772,9.07273
4.40000,0.36657,205.17209,0.00764,0.76440,9.38015
4.60000,0.38331,213.27052,0.00792,0.79190,9.75040
4.80000,0.39999,220.80655,0.00819,0.81903,10.09494
5.00000,0.41667,228.02311,0.00846,0.84620,10.42487
5.20000,0.43335,235.44903,0.00873,0.87256,10.76437
5.40000,0.45010,242.04033,0.00900,0.90012,11.06571
5.60000,0.46666,249.12045,0.00926,0.92647,11.38941
5.80000,0.48334,256.93211,0.00953,0.95295,11.74654
6.00000,0.50002,264.11656,0.00980,0.98038,12.07500
6.20000,0.51664,270.96183,0.01007,1.00740,12.38796
6.40000,0.53332,277.19184,0.01034,1.03377,12.67279
6.60000,0.55000,282.58779,0.01054,1.05439,12.91948
6.80000,0.56674,289.38125,0.01081,1.08140,13.23007
7.00000,0.58331,296.73665,0.01109,1.10903,13.56634
7.20000,0.59993,302.96068,0.01137,1.13655,13.85090
7.40000,0.61673,310.42916,0.01162,1.16246,14.19234
7.60000,0.63329,316.50576,0.01190,1.18986,14.47016
7.80000,0.64997,323.03259,0.01217,1.21712,14.76855
8.00000,0.66671,329.86156,0.01244,1.24440,15.08076
8.20000,0.68333,335.97846,0.01271,1.27061,15.36042
8.40000,0.70002,342.82731,0.01298,1.29756,15.67354
8.60000,0.71670,349.07379,0.01325,1.32473,15.95912
8.80000,0.73344,355.02133,0.01352,1.35181,16.23103
9.00000,0.75000,359.40688,0.01372,1.37246,16.43153
9.20000,0.76668,366.04526,0.01400,1.40023,16.73503
9.40000,0.78336,371.68001,0.01427,1.42730,16.99264
9.60000,0.79992,377.74339,0.01454,1.45389,17.26985
9.80000,0.81666,383.63752,0.01481,1.48086,17.53932
10.00000,0.83341,389.50690,0.01508,1.50834,17.80766
10.20000,0.84991,395.22671,0.01535,1.53472,18.06916
10.40000,0.86665,400.56095,0.01560,1.56039,18.31303
10.60000,0.88333,406.04379,0.01587,1.58725,18.56370
10.80000,0.90007,412.06409,0.01614,1.61449,18.83894
11.00000,0.91669,415.44158,0.01635,1.63523,18.99335
11.20000,0.93331,420.83147,0.01663,1.66309,19.23977
11.40000,0.95000,426.05507,0.01690,1.68974,19.47858
11.60000,0.96656,431.47635,0.01717,1.71735,19.72644
11.80000,0.98330,437.70932,0.01745,1.74525,20.01140
12.00000,1.00004,442.42502,0.01773,1.77261,20.22699
12.20000,1.01666,448.14190,0.01800,1.79989,20.48836
12.40000,1.03328,452.66310,0.01828,1.82770,20.69506
12.60000,1.04996,456.17688,0.01849,1.84889,20.85571
12.80000,1.06664,461.40063,0.01877,1.87696,21.09453
13.00000,1.08333,466.20932,0.01904,1.90429,21.31437
13.20000,1.10001,471.17341,0.01932,1.93235,21.54132
13.40000,1.11675,476.07953,0.01960,1.96040,21.76562
13.60000,1.13325,480.84357,0.01988,1.98787,21.98343
13.80000,1.14993,485.88063,0.02016,2.01575,22.21372
14.00000,1.16673,489.39572,0.02043,2.04288,22.37442
14.20000,1.18329,492.84007,0.02067,2.06683,22.53189
14.40000,1.19998,497.93911,0.02095,2.09481,22.76501
14.60000,1.21672,502.50138,0.02124,2.12365,22.97359
14.80000,1.23334,506.63846,0.02152,2.15209,23.16273
15.00000,1.24996,511.34690,0.02180,2.18038,23.37800
15.20000,1.26670,514.88136,0.02209,2.20894,23.53959
15.40000,1.28338,518.36297,0.02232,2.23233,23.69876
15.60000,1.29994,521.92677,0.02260,2.25995,23.86169
15.80000,1.31656,525.46351,0.02288,2.28754,24.02339
16.00000,1.33343,529.21805,0.02316,2.31594,24.19504
16.20000,1.34993,533.59023,0.02345,2.34502,24.39493
16.40000,1.36667,537.29098,0.02374,2.37425,24.56412
16.60000,1.38341,541.36780,0.02403,2.40326,24.75051
16.80000,1.39997,543.16805,0.02426,2.42557,24.83281
17.00000,1.41659,546.60989,0.02455,2.45515,24.99017
17.20000,1.43333,550.23520,0.02484,2.48447,25.15591
17.40000,1.45001,554.55426,0.02514,2.51358,25.35337
17.60000,1.46664,558.09766,0.02543,2.54269,25.51537
17.80000,1.48320,561.72688,0.02573,2.57251,25.68129
18.00000,1.50000,562.94147,0.02595,2.59519,25.73682
18.20000,1.51656,566.75230,0.02625,2.62465,25.91105
18.40000,1.53336,570.41114,0.02655,2.65491,26.07832
18.60000,1.55004,573.14597,0.02684,2.68430,26.20335
18.80000,1.56666,577.31140,0.02714,2.71408,26.39379
19.00000,1.58335,580.60721,0.02744,2.74359,26.54447
19.20000,1.60003,581.54180,0.02767,2.76678,26.58720
19.40000,1.61671,584.67179,0.02797,2.79724,26.73030
19.60000,1.63333,588.24122,0.02827,2.82703,26.89349
19.80000,1.65007,591.25111,0.02858,2.85780,27.03109
20.00000,1.66663,594.58804,0.02887,2.88740,27.18365
20.20000,1.68325,596.49479,0.02916,2.91632,27.27083
20.40000,1.69993,598.37736,0.02941,2.94139,27.35690
20.60000,1.71674,601.67559,0.02971,2.97069,27.50768
20.80000,1.73330,604.10732,0.03001,3.00093,27.61886
21.00000,1.74992,607.32607,0.03031,3.03103,27.76602
21.20000,1.76672,610.00204,0.03062,3.06187,27.88836
21.40000,1.78334,612.71559,0.03092,3.12836,28.01242
21.56600,1.79715,614.42335,0.03115,3.18360,28.09049
21.76600,1.81401,616.29186,0.03142,3.25104,28.17592
21.96600,1.83052,618.54692,0.03173,3.31705,28.27902
22.16600,1.84714,622.36870,0.03204,3.38354,28.45374
22.36600,1.86382,624.41323,0.03235,3.45026,28.54721
22.56600,1.88056,626.78568,0.03266,3.51723,28.65568
22.76600,1.89712,627.39248,0.03290,3.58347,28.68342
22.96600,1.91380,630.45481,0.03349,3.65020,28.82343
23.16600,1.93054,633.52203,0.03323,3.71716,28.96366
23.36600,1.94710,635.12558,0.00669,3.78341,29.03697
23.56600,1.96385,637.94479,0.00515,3.85037,29.16586
23.76600,1.98059,639.24734,0.00404,3.91734,29.22541
23.96600,1.99721,642.11115,0.00523,3.98382,29.35634
24.16600,2.01383,644.23913,0.00498,4.05031,29.45362
24.36600,2.03051,646.64716,0.00572,4.11704,29.56372
24.56600,2.04719,648.84531,0.00766,4.18376,29.66421
24.76600,2.06381,650.06730,0.01604,4.25025,29.72008
24.96600,2.08049,651.98112,0.06396,4.31697,29.80758
25.16600,2.09718,654.39632,-0.13248,4.38370,29.91800
25.36600,2.11374,657.55374,-0.05697,4.44994,30.06235
25.56600,2.13042,658.25526,-0.05771,4.51667,30.09442
25.76600,2.14716,661.01635,-0.05680,4.58363,30.22065
25.96600,2.16384,661.80723,-0.05750,4.65036,30.25681
26.16600,2.18058,664.50383,-0.05704,4.71732,30.38009
26.36600,2.19714,665.36963,-0.05738,4.78357,30.41968
26.56600,2.21383,667.45779,-0.05714,4.85029,30.51515
26.76600,2.23051,669.59290,-0.05734,4.91702,30.61276
26.96600,2.24719,672.10975,-0.05722,4.98374,30.72783
27.16600,2.26393,673.07949,-0.05732,5.05071,30.77216
27.36600,2.28055,675.34992,-0.05725,5.11719,30.87596
27.56600,2.29717,677.37903,-0.05730,5.18368,30.96873
27.76600,2.31379,679.10878,-0.05726,5.25016,31.04781
27.96600,2.33047,680.15005,-0.05730,5.31689,31.09542
28.16600,2.34716,682.86536,-0.05728,5.38362,31.21956
28.36600,2.36384,684.25792,-0.05731,5.45034,31.28322
28.56600,2.38046,685.31190,-0.05729,5.51683,31.33141
28.76600,2.39714,686.97734,-0.05731,5.58355,31.40755
28.96600,2.41382,689.36287,-0.05730,5.65028,31.51661
29.16600,2.43056,690.80060,-0.05734,5.71724,31.58234
29.36600,2.44718,692.16746,-0.05728,5.78373,31.64483
29.56600,2.46387,694.29362,-0.05733,5.85045,31.74204
29.76600,2.48055,695.56735,-0.05729,5.91718,31.80027
29.96600,2.49717,697.94958,-0.05734,5.98366,31.90918
30.16600,2.51385,699.01724,-0.05733,6.05039,31.95800
30.36600,2.53053,701.45885,-0.05734,6.11711,32.06962
30.56600,2.54715,702.64074,-0.05734,6.18360,32.12366
30.76600,2.56371,704.87643,-0.05734,6.24985,32.22587
30.96600,2.58051,705.92668,-0.05733,6.31705,32.27388
31.16600,2.59720,707.72590,-0.05733,6.38377,32.35614
31.36600,2.61382,709.19930,-0.05732,6.45026,32.42350
31.56600,2.63050,711.00448,-0.05734,6.51699,32.50603
31.76600,2.64718,711.72132,-0.05731,6.58371,32.53881
31.96600,2.66380,713.86779,-0.05733,6.65020,32.63694
32.16600,2.68048,715.47725,-0.05734,6.71692,32.71052
32.36600,2.69716,717.30772,-0.05734,6.78365,32.79421
32.56600,2.71385,718.17143,-0.05733,6.85037,32.83369
32.76600,2.73053,719.85736,-0.05732,6.91710,32.91077
32.96600,2.74715,722.00983,-0.05732,6.98358,33.00918
33.16600,2.76389,722.70534,-0.05733,7.05055,33.04098
33.36600,2.78051,724.61292,-0.05734,7.11703,33.12819
33.56600,2.79713,725.95901,-0.05735,7.18352,33.18973
33.76600,2.81381,727.14859,-0.05736,7.25024,33.24412
33.96600,2.83043,728.92639,-0.05738,7.31673,33.32540
34.16600,2.84706,730.56645,-0.05743,7.38322,33.40038
34.36600,2.86380,731.64916,-0.05740,7.45018,33.44988
34.56600,2.88054,733.55548,-0.05737,7.51714,33.53703
34.76600,2.89716,734.37211,-0.05737,7.58363,33.57437
34.96600,2.91390,735.30888,-0.05736,7.65059,33.61720
35.16600,2.93046,737.64175,-0.05734,7.71684,33.72385
35.36600,2.94708,738.97890,-0.05735,7.78333,33.78498
35.56600,2.96394,739.59762,-0.05734,7.85077,33.81327
35.76600,2.98057,740.39451,-0.05734,7.91725,33.84970
35.96600,2.99707,740.90469,-0.05733,7.98326,33.87302
36.16600,3.01381,743.14522,-0.05735,8.05023,33.97546
36.36600,3.03049,744.39864,-0.05733,8.11695,34.03276
36.56600,3.04711,745.79935,-0.05734,8.18344,34.09680
36.76600,3.06385,746.70459,-0.05734,8.25040,34.13819
36.96600,3.08065,748.04798,-0.05737,8.31761,34.19960
37.16600,3.09710,749.59714,-0.05733,8.38337,34.27043
37.36600,3.11384,751.26747,-0.05738,8.45034,34.34679
37.56600,3.13064,753.19414,-0.05736,8.51754,34.43488
37.76600,3.14720,754.17543,-0.05739,8.58379,34.47974
37.96600,3.16376,754.65930,-0.05737,8.65004,34.50187
38.16600,3.18050,756.41754,-0.05740,8.71700,34.58225
38.36600,3.19718,757.31380,-0.05737,8.78372,34.62323
38.56600,3.21380,759.00760,-0.05735,8.85021,34.70066
38.76600,3.23043,760.56281,-0.05733,8.91670,34.77177
38.96600,3.24717,762.10732,-0.05736,8.98366,34.84238
39.16600,3.26379,763.53094,-0.05735,9.05015,34.90746
39.36600,3.28047,764.05914,-0.05737,9.11687,34.93161
39.56600,3.29721,765.32778,-0.05737,9.18384,34.98961
39.76600,3.31377,766.87299,-0.05736,9.25008,35.06026
39.96600,3.33051,767.49278,-0.05735,9.31705,35.08859
40.16600,3.34720,768.78481,-0.05733,9.38377,35.14766
40.36600,3.36388,770.25457,-0.05733,9.45050,35.21486
40.56600,3.38050,771.70441,-0.05737,9.51698,35.28114
40.76600,3.39712,772.43093,-0.05736,9.58347,35.31436
40.96600,3.41392,773.51951,-0.05735,9.65067,35.36412
41.16600,3.43048,774.73773,-0.05734,9.71692,35.41982
41.36600,3.44710,776.07511,-0.05735,9.78341,35.48096
41.56600,3.46384,776.72610,-0.05735,9.85037,35.51073
41.76600,3.48047,778.15820,-0.05736,9.91686,35.57620
41.96600,3.49715,779.03196,-0.05736,9.98358,35.61615
42.16600,3.51389,780.64273,-0.05736,10.05054,35.68979
42.36600,3.53057,780.39896,-0.05739,10.11727,35.67864
42.56600,3.54713,781.81876,-0.05735,10.18352,35.74355
42.76600,3.56381,783.67284,-0.05735,10.25024,35.82832
42.96600,3.58055,783.87754,-0.05735,10.31720,35.83768
43.16600,3.59706,783.90874,-0.05737,10.38321,35.83910
43.36600,3.61380,784.78437,-0.05736,10.45018,35.87914
43.56600,3.63060,786.81568,-0.05739,10.51738,35.97200
43.76600,3.64710,788.21843,-0.05738,10.58339,36.03614
43.96600,3.66378,789.19204,-0.05739,10.65011,36.08065
44.16600,3.68058,790.10483,-0.05741,10.71732,36.12238
44.36600,3.69720,790.48546,-0.05739,10.78380,36.13978
44.56600,3.71376,791.50079,-0.05742,10.85005,36.18620
44.76600,3.73051,793.34034,-0.05733,10.91701,36.27030
44.96600,3.74725,793.76847,-0.05735,10.98398,36.28988
45.16600,3.76375,795.48731,-0.05732,11.04999,36.36846
45.36600,3.78049,796.37645,-0.05733,11.11695,36.40911
45.56600,3.79723,797.39634,-0.05732,11.18391,36.45574
45.76600,3.81379,798.65372,-0.05729,11.25016,36.51322
45.96600,3.83047,799.43147,-0.05733,11.31689,36.54878
46.16600,3.84721,800.21089,-0.05731,11.38385,36.58442
46.36600,3.86384,800.94710,-0.05733,11.45034,36.61807
46.56600,3.88052,802.13761,-0.05732,11.51706,36.67250
46.76600,3.89714,803.06483,-0.05735,11.58355,36.71489
46.96600,3.91382,803.78866,-0.05735,11.65027,36.74799
47.16600,3.93044,805.24758,-0.05739,11.71676,36.81468
47.36600,3.94712,805.81680,-0.05737,11.78348,36.84071
47.56600,3.96392,807.15744,-0.05735,11.85069,36.90200
47.76600,3.98043,806.80810,-0.05736,11.91669,36.88603
47.96600,3.99711,808.78977,-0.05733,11.98342,36.97663
48.16600,4.01385,809.78982,-0.05737,12.05038,37.02235
48.36600,4.03047,809.80808,-0.05735,12.11687,37.02318
48.56600,4.04715,810.66368,-0.05736,12.18359,37.06230
48.76600,4.06389,812.14067,-0.05735,12.25056,37.12983
48.96600,4.08051,812.41010,-0.05736,12.31704,37.14214
49.16600,4.09707,810.71900,-0.05735,12.38329,37.06483
49.36600,4.11382,812.21266,-0.05736,12.45025,37.13312
49.56600,4.13056,813.64661,-0.05737,12.51722,37.19867
49.76600,4.14712,814.74055,-0.05736,12.58347,37.24869
49.96600,4.16380,816.35518,-0.05737,12.65019,37.32251
50.16600,4.18054,817.10117,-0.05737,12.71715,37.35661
50.36600,4.19704,817.04333,-0.05736,12.78316,37.35397
50.56600,4.21384,817.87538,-0.05738,12.85037,37.39201
50.76600,4.23064,818.83827,-0.05736,12.91757,37.43603
50.96600,4.24721,819.42743,-0.05737,12.98382,37.46296
51.16600,4.26377,820.95927,-0.05736,13.05006,37.53300
51.36600,4.28057,822.29618,-0.05737,13.11727,37.59412
51.56600,4.29719,822.16961,-0.05735,13.18375,37.58833
51.76600,4.31381,823.57498,-0.05737,13.25024,37.65258
51.96600,4.33049,824.28586,-0.05736,13.31696,37.68509
52.16600,4.34723,825.73500,-0.05737,13.38393,37.75134
52.36600,4.36380,825.71916,-0.05737,13.45017,37.75061
52.56600,4.38048,825.97816,-0.05736,13.51690,37.76245
52.76600,4.39722,827.01901,-0.05736,13.58386,37.81004
52.96600,4.41390,827.76081,-0.05736,13.65059,37.84396
53.16600,4.43046,828.62675,-0.05736,13.71684,37.88354
53.36600,4.44714,829.69572,-0.05736,13.78356,37.93242
53.56600,4.46382,830.29913,-0.05736,13.85029,37.96000
53.76600,4.48051,831.14868,-0.05735,13.91701,37.99884
53.96600,4.49719,831.74631,-0.05736,13.98374,38.02617
54.16600,4.51381,832.91149,-0.05736,14.05022,38.07943
54.36600,4.53043,833.83676,-0.05735,14.11671,38.12174
54.56600,4.54711,834.11625,-0.05737,14.18343,38.13451
54.76600,4.56379,833.65524,-0.05737,14.25016,38.11344
54.96600,4.58053,834.45888,-0.05738,14.31712,38.15018
55.16600,4.59721,835.44003,-0.05738,14.38385,38.19504
55.36600,4.61384,836.63296,-0.05738,14.45033,38.24958
55.56600,4.63046,837.19203,-0.05739,14.51682,38.27514
55.76600,4.64720,837.17117,-0.05740,14.58378,38.27418
55.96600,4.66388,837.87562,-0.05745,14.65051,38.30639
56.16600,4.68062,839.10860,-0.05749,14.71747,38.36276
56.36600,4.69718,837.32074,-0.05739,14.78372,38.28102
56.56600,4.71374,838.55642,-0.05744,14.84997,38.33751
56.76600,4.73054,839.38166,-0.05738,14.91717,38.37524
56.96600,4.74711,840.84189,-0.05738,14.98342,38.44200
57.16600,4.76379,841.34722,-0.05737,15.05014,38.46510
57.36600,4.78047,841.03905,-0.05737,15.11687,38.45102
57.56600,4.79709,841.28892,-0.05738,15.18335,38.46244
57.76600,4.81383,841.73214,-0.05739,15.25032,38.48270
57.96600,4.83057,843.32507,-0.05742,15.31728,38.55553
58.16600,4.84725,844.17816,-0.05742,15.38401,38.59453
58.36600,4.86382,844.35865,-0.05748,15.45025,38.60278
58.56600,4.88044,845.26418,-0.05741,15.51674,38.64418
58.76600,4.89718,845.92672,-0.05744,15.58370,38.67447
58.96600,4.91380,846.80477,-0.05745,15.65019,38.71461
59.16600,4.93048,847.53204,-0.05739,15.71691,38.74786
59.36600,4.94722,848.69731,-0.05743,15.78388,38.80114
59.56600,4.96378,848.23454,-0.05737,15.85013,38.77998
59.76600,4.98046,849.39133,-0.05736,15.91685,38.83287
59.96600,4.99715,849.88447,-0.05734,15.98357,38.85542
60.16600,5.01383,850.70301,-0.05739,16.05030,38.89284
60.36600,5.03057,850.76904,-0.05737,16.11726,38.89585
60.56600,5.04713,849.45504,-0.05740,16.18351,38.83578
60.76600,5.06387,850.62329,-0.05737,16.25047,38.88919
60.96600,5.08049,851.60546,-0.05737,16.31696,38.93409
61.16600,5.09711,852.47504,-0.05737,16.38345,38.97385
61.36600,5.11386,852.65562,-0.05738,16.45041,38.98211
61.56600,5.13048,853.64524,-0.05737,16.51690,39.02735
61.76600,5.14710,854.05344,-0.05738,16.58338,39.04601
61.96600,5.16378,854.13018,-0.05739,16.65011,39.04952
62.16600,5.18052,855.30486,-0.05738,16.71707,39.10323
62.36600,5.19720,855.33280,-0.05739,16.78380,39.10450
62.56600,5.21382,855.49541,-0.05738,16.85028,39.11194
62.76600,5.23044,856.38165,-0.05739,16.91677,39.15245
62.96600,5.24713,856.91679,-0.05741,16.98349,39.17692
63.16600,5.26381,857.59191,-0.05738,17.05022,39.20779
63.36600,5.28061,858.18199,-0.05738,17.11742,39.23476
63.56600,5.29717,858.52686,-0.05737,17.18367,39.25053
63.76600,5.31385,858.82042,-0.05737,17.25039,39.26395
63.96600,5.33047,859.16715,-0.05736,17.31688,39.27980
64.16600,5.34715,858.26339,-0.05737,17.38361,39.23849
64.36600,5.36383,858.95518,-0.05736,17.45033,39.27011
64.56600,5.38052,859.00836,-0.05737,17.51706,39.27254
64.76601,5.39714,859.80743,-0.05736,17.58354,39.30908
64.96600,5.41382,860.26601,-0.05736,17.65027,39.33004
65.16600,5.43044,860.46085,-0.05735,17.71675,39.33895
65.36600,5.44718,861.36004,-0.05738,17.78372,39.38006
65.56600,5.46380,861.58244,-0.05738,17.85020,39.39023
65.76601,5.48054,861.99716,-0.05739,17.91717,39.40919
65.96600,5.49723,863.06268,-0.05737,17.98389,39.45790
66.16600,5.51379,863.14259,-0.05738,18.05014,39.46156
66.36601,5.53047,863.31191,-0.05738,18.11686,39.46930
66.56600,5.54721,863.79135,-0.05739,18.18383,39.49121
66.76601,5.56389,864.57552,-0.05744,18.25055,39.52707
66.96600,5.58045,861.43231,-0.05754,18.31680,39.38336
67.16600,5.59719,863.04694,-0.05746,18.38377,39.45718
67.36601,5.61387,863.89631,-0.05746,18.45049,39.49601
67.56600,5.63050,864.20923,-0.05744,18.51697,39.51032
67.76601,5.64712,865.04389,-0.05743,18.58346,39.54848
67.96600,5.66386,865.55788,-0.05738,18.65043,39.57198
68.16600,5.68042,865.77581,-0.05740,18.71667,39.58194
68.36601,5.69716,866.35826,-0.05739,18.78364,39.60857
68.56600,5.71384,866.17554,-0.05738,18.85036,39.60022
68.76601,5.73046,865.39239,-0.05739,18.91685,39.56441
68.96600,5.74720,866.23775,-0.05739,18.98381,39.60306
69.16600,5.76383,867.16674,-0.05739,19.05030,39.64553
69.36601,5.78051,867.20427,-0.05736,19.11702,39.64725
69.56600,5.79713,867.74649,-0.05739,19.18351,39.67204
69.76601,5.81381,868.09807,-0.05738,19.25023,39.68811
69.96600,5.83055,868.48894,-0.05740,19.31720,39.70598
70.16600,5.84711,868.64401,-0.05740,19.38344,39.71307
70.36601,5.86379,869.54786,-0.05737,19.45017,39.75439
70.56600,5.88048,869.60457,-0.05740,19.51689,39.75699
70.76601,5.89716,869.55549,-0.05739,19.58362,39.75474
70.96600,5.91384,870.36081,-0.05737,19.65034,39.79156
71.16600,5.93052,870.86288,-0.05740,19.71707,39.81451
71.36601,5.94720,871.21576,-0.05738,19.78379,39.83065
71.56600,5.96382,871.14898,-0.05741,19.85028,39.82759
71.76601,5.98056,871.86443,-0.05739,19.91724,39.86031
71.96600,5.99724,871.78797,-0.05739,19.98397,39.85681
72.16600,6.01381,871.99006,-0.05737,20.05022,39.86605
72.36601,6.03043,872.91570,-0.05737,20.11670,39.90837
72.56600,6.04723,872.69126,-0.05737,20.18391,39.89811
72.76601,6.06385,873.06965,-0.05738,20.25039,39.91541
72.96600,6.08041,873.65070,-0.05740,20.31664,39.94197
73.16600,6.09721,873.77317,-0.05739,20.38384,39.94757
73.36601,6.11389,873.46481,-0.05741,20.45057,39.93347
73.56600,6.13046,874.09290,-0.05741,20.51681,39.96218
73.76601,6.14714,873.91511,-0.05740,20.58354,39.95406
73.96600,6.16388,874.59814,-0.05736,20.65050,39.98529
74.16600,6.18050,873.62984,-0.05742,20.71699,39.94102
74.36601,6.19718,874.00815,-0.05744,20.78371,39.95831
74.56600,6.21386,873.70016,-0.05746,20.85044,39.94423
74.76601,6.23042,874.41811,-0.05742,20.91669,39.97705
74.96600,6.24710,874.39176,-0.05739,20.98341,39.97585
75.16600,6.26385,874.63371,-0.05739,21.05037,39.98691
75.36601,6.28053,875.24857,-0.05734,21.11710,40.01502
75.56600,6.29715,875.55600,-0.05739,21.18359,40.02908
75.76601,6.31383,875.91689,-0.05734,21.25031,40.04558
75.96600,6.33045,876.06562,-0.05735,21.31680,40.05238
76.16600,6.34713,876.32677,-0.05733,21.38352,40.06432
76.36601,6.36387,876.67219,-0.05733,21.45049,40.08011
76.56600,6.38061,877.41492,-0.05735,21.51745,40.11406
76.76601,6.39712,877.02591,-0.05735,21.58346,40.09628
76.96600,6.41380,877.22521,-0.05737,21.65018,40.10539
77.16600,6.43054,877.21506,-0.05737,21.71715,40.10493
77.36601,6.44716,877.23713,-0.05738,21.78363,40.10593
77.56600,6.46390,877.31667,-0.05739,21.85060,40.10957
77.76601,6.48052,877.91467,-0.05739,21.91708,40.13691
77.96600,6.49714,878.09060,-0.05741,21.98357,40.14495
78.16600,6.51377,878.27425,-0.05739,22.05006,40.15335
78.36601,6.53045,878.40548,-0.05737,22.11678,40.15935
78.56600,6.54731,878.08743,-0.05739,22.18422,40.14481
78.76601,6.56381,878.61419,-0.05738,22.25023,40.16889
78.96600,6.58043,878.16203,-0.05739,22.31672,40.14822
79.16600,6.59729,879.14001,-0.05738,22.38416,40.19293
79.36601,6.61379,878.92730,-0.05739,22.45017,40.18321
79.56600,6.63048,879.56758,-0.05740,22.51689,40.21248
79.76601,6.64728,879.19971,-0.05737,22.58409,40.19566
79.96600,6.66390,879.57177,-0.05740,22.65058,40.21267
80.16600,6.68040,879.62709,-0.05740,22.71659,40.21520
80.36601,6.69714,879.86682,-0.05741,22.78355,40.22616
80.56600,6.71394,879.85480,-0.05738,22.85076,40.22561
80.76601,6.73044,880.09201,-0.05738,22.91676,40.23646
80.96600,6.74712,880.14323,-0.05738,22.98349,40.23880
81.16600,6.76387,880.19818,-0.05738,23.05045,40.24131
81.36601,6.78043,881.03246,-0.05739,23.11670,40.27945
81.56600,6.79717,880.63488,-0.05739,23.18366,40.26128
81.76601,6.81397,880.70408,-0.05739,23.25087,40.26444
81.96600,6.83047,880.56326,-0.05743,23.31688,40.25800
82.16600,6.84715,880.57993,-0.05749,23.38360,40.25876
82.36601,6.86377,878.87254,-0.05748,23.45009,40.18070
82.56600,6.88052,879.28763,-0.05741,23.51705,40.19968
82.76601,6.89714,879.20604,-0.05737,23.58354,40.19595
82.96600,6.91388,880.06593,-0.05740,23.65050,40.23526
83.16600,6.93056,880.52405,-0.05736,23.71723,40.25621
83.36601,6.94712,880.67297,-0.05739,23.78347,40.26302
83.56600,6.96374,880.91148,-0.05737,23.84996,40.27392
83.76601,6.98048,881.00070,-0.05740,23.91692,40.27800
83.96600,6.99716,880.88410,-0.05738,23.98365,40.27267
84.16600,7.01385,881.51926,-0.05741,24.05037,40.30171
84.36601,7.03047,881.69463,-0.05740,24.11686,40.30973
84.56600,7.04715,880.91670,-0.05741,24.18358,40.27416
84.76601,7.06383,881.04857,-0.05745,24.25031,40.28019
84.96600,7.08057,881.58818,-0.05751,24.31727,40.30486
85.16600,7.09731,881.36373,-0.05746,24.38424,40.29460
85.36601,7.11375,882.51624,-0.05750,24.45001,40.34729
85.56600,7.13043,882.12406,-0.05744,24.51673,40.32936
85.76601,7.14718,881.88015,-0.05740,24.58370,40.31821
85.96600,7.16380,881.86860,-0.05741,24.65018,40.31768
86.16600,7.18048,882.43652,-0.05738,24.71690,40.34364
86.36601,7.19716,882.16402,-0.05739,24.78363,40.33118
86.56600,7.21384,882.81482,-0.05735,24.85036,40.36094
86.76601,7.23040,883.40761,-0.05738,24.91660,40.38804
86.96600,7.24720,882.99196,-0.05734,24.98381,40.36904
87.16600,7.26395,882.67708,-0.05736,25.05077,40.35464
87.36601,7.28051,882.15386,-0.05736,25.11702,40.33072
87.56600,7.29713,882.19494,-0.05738,25.18350,40.33260
87.76601,7.31387,883.04970,-0.05737,25.25047,40.37168
87.96600,7.33049,882.76640,-0.05736,25.31695,40.35873
88.16601,7.34717,882.84295,-0.05735,25.38368,40.36222
88.36601,7.36385,883.58447,-0.05740,25.45041,40.39613
88.56600,7.38047,882.95834,-0.05736,25.51689,40.36750
88.76601,7.39710,883.44589,-0.05740,25.58338,40.38979
88.96600,7.41378,882.81007,-0.05744,25.65010,40.36072
89.16601,7.43058,882.84751,-0.05739,25.71730,40.36243
89.36601,7.44714,883.45092,-0.05743,25.78355,40.39002
89.56600,7.46388,883.40305,-0.05756,25.85052,40.38783
89.76601,7.48050,882.85450,-0.05752,25.91700,40.36275
89.96600,7.49718,880.60582,-0.05739,25.98373,40.25995
90.16601,7.51392,881.28187,-0.05746,26.05069,40.29086
90.36601,7.53055,881.59209,-0.05734,26.11718,40.30504
90.56600,7.54717,881.30068,-0.05744,26.18366,40.29171
90.76601,7.56385,881.87158,-0.05734,26.25039,40.31781
90.96600,7.58047,882.28667,-0.05742,26.31687,40.33679
91.16601,7.59715,882.56700,-0.05735,26.38360,40.34961
91.36601,7.61383,882.06930,-0.05741,26.45032,40.32685
91.56600,7.63045,882.56476,-0.05736,26.51681,40.34951
91.76601,7.64714,882.42320,-0.05739,26.58354,40.34304
91.96600,7.66382,882.87750,-0.05739,26.65026,40.36380
92.16601,7.68044,883.15448,-0.05737,26.71674,40.37647
92.36601,7.69718,883.05930,-0.05738,26.78371,40.37212
92.56600,7.71386,883.01040,-0.05738,26.85044,40.36988
92.76601,7.73048,882.97725,-0.05739,26.91692,40.36837
92.96600,7.74716,883.32342,-0.05736,26.98365,40.38419
93.16601,7.76378,883.90820,-0.05738,27.05013,40.41093
93.36601,7.78047,883.75136,-0.05736,27.11686,40.40376
93.56600,7.79715,883.53725,-0.05738,27.18358,40.39397
93.76601,7.81383,883.12384,-0.05738,27.25030,40.37507
93.96600,7.83045,883.34158,-0.05737,27.31679,40.38502
94.16601,7.84713,883.75285,-0.05737,27.38352,40.40382
94.36601,7.86387,883.65087,-0.05738,27.45048,40.39916
94.56600,7.88055,883.67965,-0.05738,27.51721,40.40048
94.76601,7.89717,883.66400,-0.05740,27.58369,40.39976
94.96600,7.91392,883.23252,-0.05740,27.65066,40.38004
95.16601,7.93048,883.43089,-0.05738,27.71690,40.38911
95.36601,7.94716,883.36132,-0.05741,27.78363,40.38593
95.56600,7.96384,883.32891,-0.05742,27.85035,40.38444
95.76601,7.98052,883.15438,-0.05740,27.91708,40.37646
95.96600,7.99714,883.35667,-0.05740,27.98356,40.38571
96.16601,8.01376,883.13427,-0.05740,28.05005,40.37555
96.36601,8.03051,883.52924,-0.05741,28.11702,40.39360
96.56600,8.04719,883.88966,-0.05742,28.18374,40.41008
96.76601,8.06381,883.39653,-0.05740,28.25022,40.38754
96.96600,8.08049,882.95508,-0.05738,28.31695,40.36735
97.16601,8.09711,883.14703,-0.05738,28.38344,40.37613
97.36601,8.11379,883.29157,-0.05738,28.45016,40.38274
97.56600,8.13053,882.97622,-0.05738,28.51713,40.36832
97.76601,8.14716,882.85068,-0.05738,28.58361,40.36258
97.96600,8.16390,883.12011,-0.05738,28.65058,40.37490
98.16601,8.18046,882.44285,-0.05738,28.71682,40.34393
98.36601,8.19720,882.59010,-0.05738,28.78379,40.35067
98.56600,8.21382,880.72466,-0.05739,28.85027,40.26538
98.76601,8.23050,881.37034,-0.05738,28.91700,40.29490
98.96600,8.24718,881.06813,-0.05737,28.98372,40.28108
99.16601,8.26380,881.02268,-0.05737,29.05021,40.27901
99.36601,8.28049,881.78953,-0.05738,29.11694,40.31406
99.56600,8.29711,881.58380,-0.05739,29.18342,40.30466
99.76601,8.31385,881.52522,-0.05740,29.25038,40.30198
99.96600,8.33053,881.18901,-0.05740,29.31711,40.28661
100.16601,8.34715,881.79223,-0.05736,29.38359,40.31419
100.36601,8.36389,882.05580,-0.05734,29.45056,40.32624
100.56600,8.38045,882.17342,-0.05736,29.51681,40.33162
100.76601,8.39713,881.36028,-0.05737,29.58353,40.29444
100.96600,8.41394,882.58777,-0.05737,29.65074,40.35056
101.16601,8.43050,881.83144,-0.05737,29.71698,40.31598
101.36601,8.44712,881.93081,-0.05736,29.78347,40.32052
101.56600,8.46392,882.16867,-0.05736,29.85067,40.33140
101.76601,8.48054,882.11028,-0.05737,29.91716,40.32873
101.96600,8.49710,881.71652,-0.05735,29.98340,40.31073
102.16601,8.51384,882.05067,-0.05734,30.05037,40.32600
102.36601,8.53053,882.15228,-0.05732,30.11709,40.33065
102.56600,8.54715,881.42222,-0.05734,30.18358,40.29727
102.76601,8.56377,881.77919,-0.05734,30.25006,40.31359
102.96600,8.58057,881.78227,-0.05736,30.31727,40.31373
103.16601,8.59713,881.68643,-0.05735,30.38352,40.30935
103.36601,8.61387,881.80313,-0.05738,30.45048,40.31469
103.56600,8.63055,882.23172,-0.05739,30.51721,40.33428
103.76601,8.64717,881.84215,-0.05741,30.58369,40.31647
103.96600,8.66386,881.71968,-0.05744,30.65042,40.31087
104.16601,8.68042,881.51917,-0.05740,30.71666,40.30170
104.36601,8.69716,881.77901,-0.05741,30.78363,40.31358
104.56600,8.71378,880.95851,-0.05737,30.85011,40.27607
104.76601,8.73040,880.99027,-0.05741,30.91660,40.27752
104.96600,8.74720,881.16881,-0.05739,30.98380,40.28569
105.16601,8.76382,881.25048,-0.05736,31.05029,40.28942
105.36601,8.78051,880.90189,-0.05736,31.11701,40.27348
105.56600,8.79725,880.98673,-0.05737,31.18398,40.27736
105.76601,8.81381,880.92918,-0.05738,31.25022,40.27473
105.96600,8.83049,880.70212,-0.05737,31.31695,40.26435
106.16601,8.84717,880.51194,-0.05735,31.38367,40.25565
106.36601,8.86385,880.03548,-0.05733,31.45040,40.23387
106.56600,8.88047,880.19371,-0.05731,31.51688,40.24110
106.76601,8.89715,880.58552,-0.05730,31.58361,40.25902
106.96600,8.91384,880.01136,-0.05733,31.65033,40.23277
107.16601,8.93040,880.62985,-0.05732,31.71658,40.26105
107.36601,8.94714,879.82882,-0.05733,31.78355,40.22442
107.56600,8.96394,880.13476,-0.05734,31.85075,40.23841
107.76601,8.98044,879.85471,-0.05736,31.91676,40.22561
107.96600,8.99712,879.85760,-0.05733,31.98348,40.22574
108.16601,9.01392,879.61880,-0.05736,32.05068,40.21482
108.36601,9.03048,879.85517,-0.05738,32.11693,40.22563
108.56600,9.04717,879.23221,-0.05737,32.18366,40.19715
108.76601,9.06391,879.87417,-0.05740,32.25062,40.22650
108.96600,9.08053,879.81196,-0.05737,32.31711,40.22365
109.16601,9.09709,879.61825,-0.05737,32.38336,40.21480
109.36601,9.11377,878.82373,-0.05733,32.45008,40.17847
109.56600,9.13063,879.04688,-0.05735,32.51752,40.18867
109.76601,9.14713,878.92320,-0.05732,32.58353,40.18302
109.96600,9.16376,879.60465,-0.05736,32.65001,40.21418
110.16601,9.18056,878.69717,-0.05736,32.71722,40.17269
110.36601,9.19712,878.67146,-0.05736,32.78347,40.17151
110.56600,9.21380,878.85531,-0.05734,32.85019,40.17992
110.76601,9.23060,879.09624,-0.05736,32.91739,40.19093
110.96600,9.24716,878.49209,-0.05736,32.98364,40.16331
111.16601,9.26378,878.23039,-0.05736,33.05013,40.15134
111.36601,9.28046,878.31374,-0.05736,33.11685,40.15516
111.56600,9.29721,877.85944,-0.05735,33.18382,40.13439
111.76601,9.31383,877.39015,-0.05736,33.25030,40.11293
111.96600,9.33051,877.32803,-0.05736,33.31702,40.11009
112.16601,9.34719,877.61087,-0.05737,33.38375,40.12302
112.36601,9.36375,877.67523,-0.05738,33.45000,40.12597
112.56600,9.38043,877.45916,-0.05739,33.51672,40.11609
112.76601,9.39717,877.22633,-0.05737,33.58369,40.10544
112.96600,9.41392,876.68849,-0.05738,33.65065,40.08085
113.16601,9.43048,877.15453,-0.05738,33.71690,40.10216
113.36601,9.44722,876.53073,-0.05739,33.78386,40.07364
113.56600,9.46384,876.70851,-0.05739,33.85035,40.08177
113.76601,9.48046,875.98478,-0.05737,33.91683,40.04868
113.96600,9.49720,876.32639,-0.05736,33.98380,40.06430
114.16601,9.51388,876.23950,-0.05737,34.05052,40.06033
114.36601,9.53039,876.02958,-0.05737,34.11653,40.05073
114.56600,9.54713,876.29789,-0.05738,34.18350,40.06300
114.76601,9.56393,875.74646,-0.05738,34.25070,40.03778
114.96600,9.58055,875.68574,-0.05739,34.31719,40.03501
115.16601,9.59711,875.51968,-0.05739,34.38343,40.02742
115.36601,9.61385,875.72383,-0.05738,34.45040,40.03675
115.56600,9.63047,875.70800,-0.05738,34.51688,40.03603
115.76601,9.64709,875.16708,-0.05741,34.58337,40.01130
115.96600,9.66384,874.62161,-0.05740,34.65033,39.98636
116.16601,9.68058,875.24485,-0.05740,34.71730,40.01485
116.36601,9.69708,874.64591,-0.05739,34.78330,39.98747
116.56600,9.71376,874.23213,-0.05739,34.85003,39.96855
116.76601,9.73056,874.52345,-0.05738,34.91724,39.98187
116.96600,9.74718,874.55036,-0.05739,34.98372,39.98310
117.16601,9.76386,873.87273,-0.05740,35.05044,39.95212
117.36601,9.78054,874.24340,-0.05739,35.11717,39.96907
117.56600,9.79710,873.84246,-0.05739,35.18341,39.95074
117.76601,9.81373,873.39040,-0.05737,35.24990,39.93007
117.96600,9.83047,873.06006,-0.05739,35.31686,39.91497
118.16601,9.84721,873.53149,-0.05739,35.38383,39.93652
118.36601,9.86383,873.00939,-0.05739,35.45031,39.91265
118.56600,9.88045,872.67160,-0.05739,35.51680,39.89721
118.76601,9.89719,872.64897,-0.05739,35.58377,39.89617
118.96600,9.91381,872.63137,-0.05738,35.65025,39.89537
119.16601,9.93056,872.48711,-0.05741,35.71721,39.88877
119.36601,9.94724,871.81674,-0.05742,35.78394,39.85812
119.56600,9.96386,871.56594,-0.05742,35.85042,39.84666
119.76601,9.98048,871.50158,-0.05737,35.91691,39.84372
119.96600,9.99710,871.74075,-0.05736,35.98340,39.85465
120.16601,10.01378,871.86312,-0.05736,36.05012,39.86024
120.36601,10.03046,871.72743,-0.05736,36.11685,39.85404
120.56601,10.04715,870.99019,-0.05737,36.18358,39.82034
120.76601,10.06383,870.65483,-0.05737,36.25030,39.80500
120.96600,10.08045,871.01078,-0.05737,36.31679,39.82128
121.16601,10.09713,870.66041,-0.05737,36.38351,39.80526
121.36601,10.11393,869.98306,-0.05737,36.45071,39.77429
121.56601,10.13049,869.86981,-0.05738,36.51696,39.76911
121.76601,10.14717,869.85985,-0.05737,36.58369,39.76866
121.96600,10.16386,869.11945,-0.05736,36.65041,39.73481
122.16601,10.18054,869.03088,-0.05736,36.71713,39.73076
122.36601,10.19716,869.29100,-0.05736,36.78362,39.74265
122.56601,10.21384,869.27153,-0.05737,36.85035,39.74176
122.76601,10.23052,868.79656,-0.05736,36.91707,39.72005
122.96600,10.24708,868.08894,-0.05735,36.98332,39.68769
123.16601,10.26382,868.35902,-0.05736,37.05028,39.70004
123.36601,10.28056,867.87743,-0.05738,37.11725,39.67802
123.56601,10.29719,867.56116,-0.05739,37.18373,39.66357
123.76601,10.31381,867.86011,-0.05740,37.25022,39.67723
123.96600,10.33049,867.76931,-0.05740,37.31694,39.67308
124.16601,10.34717,867.50975,-0.05741,37.38367,39.66121
124.36601,10.36385,867.12139,-0.05746,37.45039,39.64346
124.56601,10.38053,866.73172,-0.05750,37.51712,39.62564
124.76601,10.39727,866.67063,-0.05751,37.58408,39.62285
124.96600,10.41371,865.89754,-0.05749,37.64985,39.58751
125.16601,10.43046,865.74191,-0.05758,37.71681,39.58039
125.36601,10.44720,865.57185,-0.05748,37.78378,39.57262
125.56601,10.46376,864.92160,-0.05749,37.85003,39.54289
125.76601,10.48050,865.11839,-0.05745,37.91699,39.55188
125.96600,10.49718,865.19383,-0.05742,37.98372,39.55534
126.16601,10.51380,864.61846,-0.05749,38.05020,39.52903
126.36601,10.53048,864.49450,-0.05739,38.11693,39.52336
126.56601,10.54710,864.58353,-0.05741,38.18341,39.52743
126.76601,10.56385,863.73407,-0.05738,38.25038,39.48860
126.96600,10.58053,863.24792,-0.05739,38.31710,39.46637
127.16601,10.59715,863.66050,-0.05737,38.38359,39.48523
127.36601,10.61383,863.09509,-0.05738,38.45031,39.45938
127.56601,10.63045,862.48685,-0.05741,38.51680,39.43158
127.76601,10.64713,862.33569,-0.05741,38.58352,39.42466
127.96600,10.66387,862.69788,-0.05737,38.65049,39.44122
128.16600,10.68050,861.87609,-0.05737,38.71697,39.40365
128.36602,10.69712,861.63534,-0.05738,38.78346,39.39265
128.56601,10.71380,861.08753,-0.05739,38.85019,39.36760
128.76601,10.73054,860.92148,-0.05742,38.91715,39.36001
128.96600,10.74716,860.60120,-0.05742,38.98363,39.34537
129.16600,10.76384,860.21246,-0.05739,39.05036,39.32759
129.36602,10.78046,860.25931,-0.05742,39.11685,39.32973
129.56601,10.79715,860.56618,-0.05737,39.18357,39.34377
129.76601,10.81377,859.71635,-0.05740,39.25006,39.30491
129.96600,10.83057,859.27276,-0.05739,39.31726,39.28463
130.16600,10.84719,859.51127,-0.05740,39.38375,39.29554
130.36602,10.86381,859.39299,-0.05740,39.45023,39.29013
130.56601,10.88055,858.36099,-0.05739,39.51719,39.24295
130.76601,10.89717,858.08979,-0.05741,39.58368,39.23055
130.96600,10.91379,857.69258,-0.05739,39.65017,39.21239
131.16600,10.93048,857.94106,-0.05740,39.71689,39.22375
131.36602,10.94716,857.38255,-0.05741,39.78362,39.19822
131.56602,10.96378,857.40453,-0.05743,39.85010,39.19922
131.76600,10.98052,856.42515,-0.05743,39.91707,39.15444
131.96600,10.99726,856.21057,-0.05744,39.98404,39.14463
132.16600,11.01382,855.57830,-0.05740,40.05028,39.11573
132.36602,11.03050,855.87651,-0.05740,40.11700,39.12936
132.56602,11.04718,854.70174,-0.05740,40.18373,39.07565
132.76600,11.06387,854.48511,-0.05741,40.25046,39.06575
132.96600,11.08043,854.31878,-0.05738,40.31670,39.05814
133.16600,11.09717,853.39295,-0.05741,40.38366,39.01582
133.36602,11.11385,853.72394,-0.05736,40.45039,39.03095
133.56602,11.13041,852.58186,-0.05741,40.51664,38.97873
133.76600,11.14715,852.39382,-0.05739,40.58360,38.97014
133.96600,11.16383,851.54967,-0.05741,40.65033,38.93155
134.16600,11.18051,851.16122,-0.05737,40.71705,38.91378
134.36602,11.19720,850.83079,-0.05739,40.78377,38.89868
134.56602,11.21388,850.34370,-0.05739,40.85051,38.87641
134.76600,11.23050,850.26789,-0.05741,40.91699,38.87294
134.96600,11.24718,849.84973,-0.05742,40.98371,38.85382
135.16600,11.26386,849.10905,-0.05742,41.05044,38.81996
135.36602,11.28054,848.76511,-0.05741,41.11716,38.80424
135.56602,11.29716,847.90224,-0.05741,41.18365,38.76479
135.76600,11.31379,846.99448,-0.05740,41.25013,38.72329
135.96600,11.33053,847.30405,-0.05740,41.31710,38.73744
136.16600,11.34709,846.14130,-0.05741,41.38335,38.68428
136.36602,11.36383,846.01529,-0.05743,41.45031,38.67852
136.56602,11.38057,844.79926,-0.05743,41.51728,38.62292
136.76600,11.39713,844.38212,-0.05742,41.58352,38.60386
136.96600,11.41375,843.65867,-0.05746,41.65001,38.57078
137.16600,11.43050,843.14933,-0.05743,41.71697,38.54749
137.36602,11.44724,842.98756,-0.05740,41.78393,38.54010
137.56602,11.46386,841.56804,-0.05743,41.85042,38.47520
137.76600,11.48048,840.96184,-0.05738,41.91691,38.44749
137.96600,11.49722,840.60859,-0.05739,41.98387,38.43134
138.16600,11.51378,839.74106,-0.05738,42.05012,38.39167
138.36602,11.53046,839.28490,-0.05739,42.11685,38.37082
138.56602,11.54726,838.71679,-0.05737,42.18405,38.34484
138.76600,11.56377,837.74673,-0.05738,42.25006,38.30050
138.96600,11.58039,837.06072,-0.05739,42.31654,38.26913
139.16600,11.59719,836.60875,-0.05738,42.38375,38.24847
139.36602,11.61381,835.27453,-0.05739,42.45023,38.18747
139.56602,11.63055,834.26191,-0.05739,42.51719,38.14117
139.76600,11.64717,834.03382,-0.05738,42.58368,38.13074
139.96600,11.66391,832.97091,-0.05745,42.65064,38.08215
140.16600,11.68048,832.30389,-0.05742,42.71689,38.05166
140.36602,11.69710,830.95981,-0.05740,42.78338,37.99021
140.56602,11.71384,830.23217,-0.05742,42.85034,37.95694
140.76600,11.73046,830.04097,-0.05735,42.91683,37.94820
140.96600,11.74714,829.01167,-0.05737,42.98355,37.90114
141.16600,11.76382,828.09478,-0.05736,43.05027,37.85922
141.36602,11.78044,827.80886,-0.05737,43.11677,37.84615
141.56602,11.79712,826.26576,-0.05733,43.18348,37.77560
141.76600,11.81387,825.22584,-0.05735,43.25045,37.72806
141.96600,11.83055,824.55780,-0.05736,43.31718,37.69752
142.16600,11.84711,823.50345,-0.05736,43.38342,37.64931
142.36602,11.86379,823.33870,-0.05739,43.45015,37.64178
142.56602,11.88053,821.80686,-0.05739,43.51711,37.57175
142.76600,11.89715,820.68695,-0.05740,43.58360,37.52055
142.96600,11.91383,819.53043,-0.05738,43.65032,37.46767
143.16600,11.93051,818.69159,-0.05740,43.71705,37.42933
143.36602,11.94714,817.54448,-0.05738,43.78354,37.37688
143.56602,11.96376,816.21902,-0.05738,43.85002,37.31628
143.76600,11.98056,815.53953,-0.05737,43.91722,37.28522
143.96600,11.99730,813.97695,-0.05732,43.98419,37.21378
144.16600,12.01380,812.75403,-0.05734,44.05019,37.15787
144.36602,12.03042,811.60069,-0.05735,44.11668,37.10514
144.56602,12.04728,810.49614,-0.05737,44.18413,37.05464
144.76600,12.06385,808.99289,-0.05735,44.25037,36.98591
144.96600,12.08047,808.05290,-0.05735,44.31686,36.94294
145.16600,12.09727,806.81443,-0.05736,44.38406,36.88632
145.36602,12.11383,805.59282,-0.05736,44.45031,36.83047
145.56602,12.13045,803.97958,-0.05739,44.51680,36.75671
145.76600,12.14719,802.49486,-0.05737,44.58376,36.68884
145.96600,12.16387,801.36424,-0.05739,44.65049,36.63714
146.16600,12.18049,799.66392,-0.05738,44.71697,36.55941
146.36602,12.19718,798.81847,-0.05739,44.78369,36.52076
146.56602,12.21386,797.20123,-0.05738,44.85042,36.44682
146.76600,12.23042,795.67572,-0.05738,44.91666,36.37707
146.96600,12.24710,794.14528,-0.05736,44.98339,36.30710
147.16600,12.26396,792.45865,-0.05738,45.05083,36.22999
147.36602,12.28046,790.79792,-0.05738,45.11684,36.15407
147.56602,12.29714,788.70207,-0.05739,45.18357,36.05825
147.76600,12.31377,786.01120,-0.05738,45.25005,35.93523
147.96600,12.33051,784.63871,-0.05738,45.31702,35.87248
148.16600,12.34725,782.11585,-0.05736,45.38398,35.75714
148.36602,12.36387,779.40132,-0.05738,45.45046,35.63303
148.56602,12.38055,776.27590,-0.05736,45.51719,35.49014
148.76600,12.39711,772.94447,-0.05736,45.58344,35.33783
148.96600,12.41379,769.85438,-0.05736,45.65016,35.19656
149.16600,12.43053,765.65407,-0.05737,45.71713,35.00453
149.36602,12.44716,761.82415,-0.05736,45.78361,34.82943
149.56602,12.46378,756.14881,-0.05738,45.85010,34.56996
149.76600,12.48052,747.15163,-0.05739,45.91707,34.15863
149.96600,12.49714,736.54591,-0.05740,45.98355,33.67375
150.16600,12.51376,718.15141,-0.05739,46.05004,32.83278
150.26600,12.52225,9.49381,-0.05745,46.08400,0.43404