File: Manufatura Aditiva/Dados/Ensaios AMR/Ensaios/Ensaios SLS/Tracao_OLABI_08_06_2018_SLS_YZ4.is_metal_RawData/Specimen_RawData_1.csv
Time,Extension,Load,Strain 1,Tensile strain,Tensile stress
(sec),(mm),(N),(mm/mm),(%),(MPa)
0.00000,0.00006,23.22766,0.00081,0.08054,1.06193
0.20000,0.01202,28.43304,0.00095,0.09474,1.29992
0.40000,0.03223,39.87247,0.00127,0.12659,1.82291
0.60000,0.04980,49.02035,0.00155,0.15464,2.24114
0.80000,0.06667,57.98008,0.00182,0.18193,2.65076
1.00000,0.08335,66.70239,0.00209,0.20874,3.04953
1.20000,0.10003,72.57652,0.00229,0.22901,3.31809
1.40000,0.11683,82.55697,0.00256,0.25630,3.77438
1.60000,0.13333,89.98700,0.00282,0.28232,4.11407
1.80000,0.14995,98.37534,0.00308,0.30821,4.49757
2.00000,0.16663,106.64178,0.00335,0.33480,4.87550
2.20000,0.18331,114.42284,0.00361,0.36119,5.23124
2.40000,0.19994,122.50470,0.00387,0.38715,5.60073
2.60000,0.21668,129.14251,0.00411,0.41061,5.90420
2.80000,0.23336,136.82278,0.00435,0.43474,6.25533
3.00000,0.24998,144.82561,0.00461,0.46056,6.62120
3.20000,0.26672,152.71561,0.00486,0.48644,6.98192
3.40000,0.28346,161.19380,0.00512,0.51231,7.36953
3.60000,0.30002,167.56604,0.00537,0.53693,7.66086
3.80000,0.31665,173.28055,0.00557,0.55726,7.92212
4.00000,0.33333,180.20096,0.00582,0.58221,8.23851
4.20000,0.34995,187.49684,0.00607,0.60695,8.57207
4.40000,0.36663,194.24484,0.00632,0.63159,8.88058
4.60000,0.38331,199.40501,0.00651,0.65064,9.11649
4.80000,0.39999,206.28793,0.00675,0.67499,9.43117
5.00000,0.41667,213.42842,0.00699,0.69898,9.75762
5.20000,0.43335,219.85155,0.00722,0.72228,10.05128
5.40000,0.45010,225.74980,0.00741,0.74150,10.32093
5.60000,0.46666,232.13532,0.00764,0.76439,10.61287
5.80000,0.48334,237.79317,0.00787,0.78672,10.87154
6.00000,0.50002,242.65882,0.00805,0.80502,11.09399
6.20000,0.51664,249.01726,0.00827,0.82704,11.38469
6.40000,0.53326,254.74171,0.00848,0.84808,11.64640
6.60000,0.55000,259.10770,0.00865,0.86509,11.84601
6.80000,0.56668,264.23519,0.00885,0.88535,12.08043
7.00000,0.58331,268.47762,0.00901,0.90133,12.27438
7.20000,0.59993,274.22153,0.00921,0.92096,12.53699
7.40000,0.61667,277.66000,0.00936,0.93556,12.69419
7.60000,0.63329,281.95670,0.00951,0.95052,12.89063
7.80000,0.64997,286.21554,0.00967,0.96712,13.08534
8.00000,0.66677,289.41727,0.00981,0.98079,13.23171
8.20000,0.68333,293.18281,0.00995,0.99543,13.40387
8.40000,0.70002,296.62636,0.01009,1.00875,13.56130
8.60000,0.71670,300.10981,0.01021,1.02109,13.72056
8.80000,0.73338,302.49062,0.01033,1.03344,13.82941
9.00000,0.75000,306.02464,0.01047,1.04652,13.99098
9.20000,0.76662,309.75586,0.01060,1.06007,14.16156
9.40000,0.78336,313.48914,0.01074,1.07353,14.33224
9.60000,0.79992,316.97005,0.01088,1.08754,14.49138
9.80000,0.81666,319.69182,0.01101,1.10103,14.61582
10.00000,0.83341,323.33555,0.01115,1.11457,14.78240
10.20000,0.84991,325.88593,0.01128,1.12796,14.89900
10.40000,0.86671,329.15215,0.01142,1.14158,15.04833
10.60000,0.88333,332.93203,0.01156,1.15609,15.22114
10.80000,0.90007,335.83438,0.01170,1.17019,15.35383
11.00000,0.91669,339.91539,0.01185,1.18454,15.54041
11.20000,0.93331,343.05523,0.01199,1.19945,15.68396
11.40000,0.95000,346.72869,0.01215,1.21482,15.85190
11.60000,0.96650,350.96745,0.01230,1.23024,16.04569
11.80000,0.98330,353.97613,0.01245,1.24536,16.18324
12.00000,1.00010,358.10533,0.01261,1.26075,16.37203
12.20000,1.01666,360.81914,0.01276,1.27573,16.49610
12.40000,1.03328,365.14141,0.01292,1.29154,16.69370
12.60000,1.05002,369.78254,0.01310,1.31041,16.90589
12.80000,1.06664,373.36436,0.01328,1.32791,17.06964
13.00000,1.08339,377.21021,0.01345,1.34542,17.24547
13.20000,1.10001,380.64939,0.01362,1.36246,17.40271
13.40000,1.11675,384.85907,0.01380,1.37957,17.59517
13.60000,1.13325,387.75438,0.01396,1.39643,17.72754
13.80000,1.14993,391.59595,0.01413,1.41328,17.90317
14.00000,1.16673,395.55235,0.01430,1.42985,18.08405
14.20000,1.18329,398.66320,0.01446,1.44627,18.22627
14.40000,1.19998,401.70983,0.01462,1.46237,18.36556
14.60000,1.21672,404.97477,0.01478,1.47769,18.51483
14.80000,1.23334,407.95472,0.01494,1.49378,18.65106
15.00000,1.24996,411.51969,0.01511,1.51092,18.81405
15.20000,1.26670,415.17746,0.01529,1.52879,18.98128
15.40000,1.28344,418.71411,0.01546,1.54644,19.14297
15.60000,1.29994,422.61011,0.01564,1.56446,19.32108
15.80000,1.31656,425.70210,0.01582,1.58249,19.46245
16.00000,1.33343,429.21221,0.01601,1.60114,19.62292
16.20000,1.34993,433.64367,0.01621,1.62050,19.82552
16.40000,1.36667,437.11369,0.01640,1.63992,19.98417
16.60000,1.38341,440.67707,0.01660,1.65956,20.14708
16.80000,1.39997,444.87496,0.01679,1.67870,20.33900
17.00000,1.41659,447.64946,0.01697,1.69656,20.46585
17.20000,1.43333,451.27901,0.01717,1.71693,20.63178
17.40000,1.45001,455.30605,0.01737,1.73697,20.81589
17.60000,1.46664,459.00303,0.01757,1.75735,20.98491
17.80000,1.48320,462.86872,0.01778,1.77781,21.16165
18.00000,1.50000,466.25319,0.01798,1.79836,21.31638
18.20000,1.51656,470.00139,0.01819,1.81871,21.48774
18.40000,1.53336,473.69907,0.01840,1.84015,21.65679
18.60000,1.55004,477.81877,0.01861,1.86124,21.84514
18.80000,1.56666,481.31342,0.01882,1.88229,22.00491
19.00000,1.58335,484.59792,0.01904,1.90366,22.15507
19.20000,1.60003,488.18532,0.01926,1.92586,22.31908
19.40000,1.61665,491.87085,0.01948,1.94773,22.48758
19.60000,1.63339,495.94021,0.01970,1.96982,22.67363
19.80000,1.65007,498.85977,0.01992,1.99178,22.80710
20.00000,1.66663,502.85487,0.02014,2.01414,22.98975
20.20000,1.68325,506.57634,0.02037,2.03750,23.15989
20.40000,1.69993,509.34181,0.02060,2.06018,23.28633
20.60000,1.71674,512.41429,0.02083,2.08314,23.42679
20.80000,1.73330,516.82508,0.02106,2.10580,23.62845
21.00000,1.74992,519.18528,0.02129,2.12887,23.73635
21.20000,1.76672,522.72365,0.02153,2.15294,23.89812
21.40000,1.78334,526.44727,0.02177,2.17680,24.06836
21.60000,1.79996,529.82145,0.02201,2.20067,24.22262
21.80000,1.81682,532.91656,0.02225,2.22458,24.36413
22.00000,1.83339,536.16632,0.02249,2.24851,24.51270
22.20000,1.84995,539.65221,0.02273,2.27310,24.67207
22.40000,1.86669,542.54830,0.02297,2.29736,24.80448
22.60000,1.88337,546.37371,0.02322,2.32221,24.97937
22.80000,1.89987,549.56237,0.02347,2.34666,25.12515
23.00000,1.91661,552.68556,0.02371,2.37148,25.26794
23.20000,1.93335,555.69103,0.02397,2.39724,25.40534
23.40000,1.94997,559.02582,0.02422,2.42195,25.55780
23.60000,1.96666,561.80162,0.02448,2.44779,25.68471
23.80000,1.98340,564.96598,0.02473,2.47307,25.82938
24.00000,2.00008,568.27227,0.02499,2.49864,25.98054
24.20000,2.01670,570.90917,0.02524,2.52413,26.10109
24.40000,2.03338,573.81135,0.02550,2.54993,26.23377
24.60000,2.05006,576.24597,0.02577,2.57696,26.34508
24.80000,2.06668,579.31920,0.02603,2.60304,26.48558
25.00000,2.08331,582.36243,0.02629,2.62915,26.62472
25.20000,2.09999,585.18788,0.02656,2.65571,26.75389
25.40000,2.11661,588.57449,0.02683,2.68256,26.90872
25.60000,2.13329,591.68260,0.02709,2.70948,27.05082
25.80000,2.14991,594.08899,0.02736,2.73625,27.16084
26.00000,2.16671,596.64655,0.02764,2.76366,27.27777
26.20000,2.18339,598.31222,0.02788,2.78755,27.35392
26.40000,2.20001,601.42009,0.02815,2.81540,27.49600
26.60000,2.21670,604.03277,0.02843,2.84284,27.61545
26.80000,2.23338,606.61696,0.02871,2.87083,27.73360
27.00000,2.25000,609.37046,0.02899,2.89853,27.85948
27.20000,2.26674,611.72731,0.02927,2.92672,27.96723
27.40000,2.28336,614.66629,0.02954,2.95447,28.10160
27.60000,2.29998,617.01569,0.02983,2.98303,28.20901
27.80000,2.31666,620.01026,0.03012,3.01151,28.34592
28.00000,2.33328,621.96506,0.03040,3.03959,28.43529
28.20000,2.35003,625.12197,0.03068,3.06819,28.57962
28.40000,2.36665,627.29237,0.03097,3.13467,28.67884
28.58800,2.38231,629.57159,0.03124,3.19733,28.78305
28.78800,2.39899,631.88849,0.03153,3.26406,28.88897
28.98800,2.41561,634.86309,0.03182,3.33054,29.02497
29.18800,2.43236,637.12061,0.03212,3.39751,29.12818
29.38800,2.44898,639.31849,0.03241,3.46400,29.22866
29.58800,2.46566,642.02878,0.03271,3.53072,29.35257
29.78800,2.48240,644.52183,0.03300,3.59768,29.46655
29.98800,2.49896,646.50774,0.03330,3.66393,29.55734
30.18800,2.51564,648.35255,0.03360,3.73066,29.64168
30.38800,2.53238,651.28771,0.03309,3.79762,29.77588
30.58800,2.54901,652.90667,0.00572,3.86411,29.84989
30.78800,2.56563,655.01565,0.00382,3.93059,29.94631
30.98800,2.58231,657.46726,0.00384,3.99732,30.05840
31.18800,2.59899,659.58421,0.00416,4.06404,30.15518
31.38800,2.61561,662.30078,0.00196,4.13053,30.27938
31.58800,2.63235,663.68226,0.00260,4.19749,30.34254
31.78800,2.64903,665.21079,0.00307,4.26422,30.41242
31.98800,2.66559,668.39526,0.00475,4.33046,30.55801
32.18800,2.68234,670.23905,-0.12867,4.39743,30.64230
32.38800,2.69902,672.22002,-0.13729,4.46415,30.73287
32.58800,2.71570,674.36355,-0.13729,4.53088,30.83087
32.78800,2.73238,676.39113,-0.13729,4.59760,30.92356
32.98800,2.74900,678.43930,-0.13728,4.66409,31.01720
33.18800,2.76568,680.09351,-0.13727,4.73082,31.09283
33.38800,2.78236,681.84165,-0.13728,4.79754,31.17275
33.58800,2.79899,684.04297,-0.13728,4.86403,31.27340
33.78800,2.81567,685.74990,-0.13728,4.93075,31.35143
33.98800,2.83229,687.69488,-0.13728,4.99724,31.44036
34.18800,2.84891,690.03394,-0.13728,5.06372,31.54729
34.38800,2.86571,691.80573,-0.13728,5.13093,31.62830
34.58800,2.88239,694.60138,-0.13728,5.19765,31.75611
34.78800,2.89901,695.65848,-0.13728,5.26414,31.80444
34.98800,2.91569,697.41872,-0.13728,5.33086,31.88491
35.18800,2.93238,699.42442,-0.13728,5.39759,31.97661
35.38800,2.94894,701.12958,-0.13728,5.46383,32.05457
35.58800,2.96574,702.99502,-0.13729,5.53104,32.13985
35.78800,2.98242,705.01291,-0.13728,5.59776,32.23211
35.98800,2.99892,706.88347,-0.13728,5.66377,32.31763
36.18800,3.01560,708.33173,-0.13728,5.73050,32.38384
36.38800,3.03234,710.31312,-0.13729,5.79746,32.47443
36.58800,3.04897,711.74502,-0.13728,5.86394,32.53989
36.78800,3.06571,713.89494,-0.13728,5.93091,32.63818
36.98800,3.08245,715.25928,-0.13729,5.99787,32.70056
37.18800,3.09901,717.22334,-0.13728,6.06412,32.79035
37.38800,3.11563,718.78382,-0.13729,6.13061,32.86169
37.58800,3.13237,720.97108,-0.13729,6.19757,32.96169
37.78800,3.14905,722.25691,-0.13729,6.26430,33.02048
37.98800,3.16561,723.99015,-0.13729,6.33054,33.09972
38.18800,3.18236,725.60157,-0.13729,6.39751,33.17339
38.38800,3.19898,727.12484,-0.13729,6.46399,33.24303
38.58800,3.21560,728.60303,-0.13729,6.53048,33.31061
38.78800,3.23228,730.30796,-0.13729,6.59720,33.38856
38.98800,3.24902,731.72124,-0.13729,6.66417,33.45317
39.18800,3.26570,733.10803,-0.13729,6.73089,33.51657
39.38800,3.28232,734.62022,-0.13729,6.79738,33.58571
39.58800,3.29900,736.10023,-0.13729,6.86410,33.65337
39.78800,3.31563,737.76124,-0.13729,6.93059,33.72931
39.98800,3.33237,739.05475,-0.13729,6.99755,33.78845
40.18800,3.34905,740.81621,-0.13729,7.06428,33.86898
40.38800,3.36573,741.92621,-0.13729,7.13100,33.91973
40.58800,3.38229,743.28217,-0.13729,7.19725,33.98172
40.78800,3.39897,744.69442,-0.13729,7.26397,34.04629
40.98800,3.41577,746.46361,-0.13729,7.33118,34.12717
41.18800,3.43234,747.63214,-0.13729,7.39743,34.18060
41.38800,3.44896,749.27895,-0.13729,7.46391,34.25588
41.58800,3.46564,750.74290,-0.13729,7.53064,34.32281
41.78800,3.48232,751.28740,-0.13729,7.59736,34.34771
41.98800,3.49900,753.29286,-0.13729,7.66409,34.43939
42.18800,3.51574,754.43843,-0.13729,7.73105,34.49177
42.38800,3.53242,756.08050,-0.13729,7.79778,34.56684
42.58800,3.54898,757.11878,-0.13729,7.86402,34.61431
42.78800,3.56561,758.85346,-0.13729,7.93051,34.69361
42.98800,3.58247,759.77198,-0.13729,7.99795,34.73561
43.18800,3.59891,761.41609,-0.13729,8.06372,34.81078
43.38800,3.61559,762.77335,-0.13729,8.13045,34.87283
43.58800,3.63239,764.13010,-0.13729,8.19765,34.93486
43.78800,3.64895,765.70073,-0.13729,8.26390,35.00666
43.98800,3.66563,766.87806,-0.13729,8.33062,35.06049
44.18800,3.68243,767.61045,-0.13729,8.39782,35.09397
44.38800,3.69906,768.96795,-0.13729,8.46431,35.15604
44.58800,3.71562,770.47721,-0.13729,8.53056,35.22504
44.78800,3.73230,772.12742,-0.13729,8.59728,35.30048
44.98800,3.74910,772.62148,-0.13729,8.66449,35.32307
45.18800,3.76560,774.17623,-0.13729,8.73049,35.39415
45.38800,3.78228,775.15594,-0.13729,8.79722,35.43894
45.58800,3.79902,776.55157,-0.13729,8.86418,35.50275
45.78800,3.81559,777.44350,-0.13729,8.93043,35.54353
45.98800,3.83227,779.00006,-0.13729,8.99715,35.61469
46.18800,3.84907,780.58676,-0.13729,9.06436,35.68723
46.38800,3.86569,781.10620,-0.13729,9.13084,35.71098
46.58800,3.88237,782.13532,-0.13729,9.19757,35.75803
46.78800,3.89893,783.26035,-0.13729,9.26381,35.80946
46.98800,3.91567,784.09370,-0.13729,9.33078,35.84756
47.18800,3.93230,785.38647,-0.13729,9.39726,35.90667
47.38800,3.94892,787.06024,-0.13729,9.46375,35.98318
47.58800,3.96578,787.74784,-0.13729,9.53119,36.01462
47.78800,3.98228,788.39390,-0.13729,9.59720,36.04416
47.98800,3.99896,789.95368,-0.13729,9.66393,36.11547
48.18800,4.01564,790.82940,-0.13729,9.73065,36.15551
48.38800,4.03232,791.83495,-0.13729,9.79737,36.20148
48.58800,4.04900,793.46318,-0.13729,9.86410,36.27592
48.78800,4.06563,794.15431,-0.13729,9.93059,36.30752
48.98800,4.08231,795.61397,-0.13729,9.99731,36.37425
49.18800,4.09893,796.05654,-0.13729,10.06380,36.39448
49.38800,4.11561,797.66307,-0.13729,10.13052,36.46793
49.58800,4.13247,798.69833,-0.13729,10.19797,36.51526
49.78800,4.14897,799.59184,-0.13729,10.26397,36.55611
49.98800,4.16559,800.58109,-0.13729,10.33046,36.60134
50.18800,4.18239,801.45476,-0.13730,10.39766,36.64128
50.38800,4.19890,802.88155,-0.13729,10.46367,36.70651
50.58800,4.21570,803.77674,-0.13729,10.53087,36.74744
50.78800,4.23238,804.29520,-0.13729,10.59760,36.77114
50.98800,4.24900,804.79151,-0.13729,10.66408,36.79383
51.18800,4.26562,806.57545,-0.13729,10.73057,36.87539
51.38800,4.28236,806.90430,-0.13729,10.79753,36.89043
51.58800,4.29904,808.39042,-0.13729,10.86426,36.95837
51.78800,4.31561,809.14926,-0.13729,10.93051,36.99306
51.98800,4.33229,810.38177,-0.13729,10.99723,37.04941
52.18800,4.34903,810.93535,-0.13729,11.06420,37.07472
52.38800,4.36565,811.45186,-0.13729,11.13068,37.09834
52.58800,4.38233,812.47268,-0.13729,11.19741,37.14500
52.78800,4.39901,813.24428,-0.13729,11.26413,37.18028
52.98800,4.41575,813.90711,-0.13729,11.33110,37.21058
53.18800,4.43231,815.70446,-0.13729,11.39734,37.29276
53.38800,4.44900,816.09804,-0.13729,11.46407,37.31075
53.58800,4.46568,816.53940,-0.13729,11.53079,37.33093
53.78800,4.48236,817.89875,-0.13729,11.59752,37.39308
53.98800,4.49898,818.90719,-0.13729,11.66401,37.43918
54.18800,4.51560,819.64983,-0.13729,11.73049,37.47313
54.38800,4.53228,820.34459,-0.13729,11.79722,37.50489
54.58800,4.54896,821.23494,-0.13729,11.86394,37.54560
54.78800,4.56565,822.47769,-0.13729,11.93066,37.60242
54.98800,4.58239,823.31849,-0.13729,11.99763,37.64086
55.18800,4.59907,823.29828,-0.13729,12.06435,37.63993
55.38800,4.61563,823.85354,-0.13729,12.13060,37.66532
55.58800,4.63231,825.37718,-0.13729,12.19733,37.73498
55.78800,4.64905,826.02520,-0.13729,12.26429,37.76460
55.98800,4.66567,827.10627,-0.13729,12.33078,37.81403
56.18800,4.68241,827.72644,-0.13729,12.39774,37.84238
56.38800,4.69898,829.51831,-0.13729,12.46399,37.92430
56.58800,4.71560,829.72180,-0.13729,12.53047,37.93361
56.78800,4.73234,829.54960,-0.13729,12.59744,37.92574
56.98800,4.74896,830.53475,-0.13729,12.66392,37.97078
57.18800,4.76564,831.20605,-0.13729,12.73065,38.00146
57.38800,4.78232,831.94859,-0.13729,12.79738,38.03541
57.58800,4.79900,832.77859,-0.13729,12.86410,38.07336
57.78800,4.81563,833.76858,-0.13729,12.93059,38.11862
57.98800,4.83237,835.07691,-0.13729,12.99755,38.17844
58.18800,4.84911,835.69763,-0.13729,13.06451,38.20681
58.38800,4.86567,835.20599,-0.13729,13.13076,38.18434
58.58800,4.88235,835.70164,-0.13729,13.19748,38.20700
58.78800,4.89903,836.70244,-0.13729,13.26421,38.25275
58.98800,4.91565,838.01793,-0.13729,13.33070,38.31289
59.18800,4.93233,838.44624,-0.13729,13.39742,38.33248
59.38800,4.94902,839.72402,-0.13729,13.46415,38.39089
59.58800,4.96564,840.20728,-0.13729,13.53063,38.41299
59.78800,4.98226,841.30391,-0.13729,13.59712,38.46312
59.98800,4.99900,841.63286,-0.13729,13.66408,38.47816
60.18800,5.01568,841.70951,-0.13729,13.73081,38.48167
60.38800,5.03236,842.21996,-0.13729,13.79753,38.50500
60.58800,5.04898,842.63207,-0.13729,13.86402,38.52385
60.78800,5.06566,843.91758,-0.13729,13.93074,38.58262
60.98800,5.08235,844.10431,-0.13729,13.99747,38.59115
61.18800,5.09891,845.25822,-0.13729,14.06372,38.64391
61.38800,5.11571,845.99024,-0.13729,14.13092,38.67738
61.58800,5.13233,846.30093,-0.13729,14.19740,38.69158
61.78800,5.14895,847.45456,-0.13729,14.26389,38.74432
61.98800,5.16563,847.84189,-0.13729,14.33062,38.76203
62.18800,5.18231,847.39365,-0.13729,14.39734,38.74154
62.38800,5.19899,848.31491,-0.13729,14.46406,38.78366
62.58800,5.21568,848.71491,-0.13729,14.53079,38.80194
62.78800,5.23230,849.75222,-0.13729,14.59728,38.84937
62.98800,5.24898,849.89816,-0.13729,14.66400,38.85604
63.18800,5.26560,850.42203,-0.13729,14.73049,38.87999
63.38800,5.28240,850.36512,-0.13729,14.79769,38.87739
63.58800,5.29902,851.82050,-0.13729,14.86418,38.94393
63.78800,5.31570,852.06656,-0.13729,14.93090,38.95518
63.98800,5.33233,853.08375,-0.13729,14.99739,39.00168
64.18800,5.34901,853.71519,-0.13729,15.06411,39.03055
64.38800,5.36563,853.84967,-0.13729,15.13060,39.03670
64.58800,5.38231,853.98452,-0.13729,15.19732,39.04286
64.78800,5.39905,854.72520,-0.13729,15.26429,39.07673
64.98801,5.41561,855.57839,-0.13729,15.33053,39.11573
65.18800,5.43229,856.17974,-0.13729,15.39726,39.14322
65.38800,5.44903,856.82468,-0.13729,15.46422,39.17271
65.58801,5.46560,856.97379,-0.13729,15.53047,39.17953
65.78800,5.48234,857.99089,-0.13729,15.59744,39.22603
65.98801,5.49908,858.19662,-0.13729,15.66440,39.23543
66.18800,5.51564,858.66190,-0.13729,15.73065,39.25671
66.38800,5.53232,859.35174,-0.13729,15.79737,39.28824
66.58801,5.54900,860.07640,-0.13729,15.86410,39.32137
66.78800,5.56574,859.40510,-0.13729,15.93106,39.29068
66.98801,5.58237,860.04864,-0.13729,15.99755,39.32010
67.18800,5.59899,860.56925,-0.13729,16.06403,39.34391
67.38800,5.61573,861.15077,-0.13729,16.13100,39.37049
67.58801,5.63229,861.36768,-0.13729,16.19724,39.38041
67.78800,5.64903,862.14291,-0.13729,16.26421,39.41585
67.98801,5.66565,862.73206,-0.13729,16.33070,39.44279
68.18800,5.68227,863.18869,-0.13729,16.39718,39.46366
68.38800,5.69895,864.06507,-0.13729,16.46390,39.50373
68.58801,5.71564,864.09850,-0.13729,16.53063,39.50526
68.78800,5.73232,864.41236,-0.13729,16.59735,39.51961
68.98801,5.74906,865.21581,-0.13729,16.66432,39.55634
69.18800,5.76568,864.59871,-0.13729,16.73080,39.52813
69.38800,5.78236,865.37944,-0.13729,16.79753,39.56382
69.58801,5.79892,865.83700,-0.13729,16.86378,39.58474
69.78800,5.81566,865.88040,-0.13729,16.93074,39.58672
69.98801,5.83241,866.57591,-0.13729,16.99771,39.61852
70.18800,5.84903,866.73340,-0.13729,17.06419,39.62572
70.38800,5.86565,867.46253,-0.13729,17.13068,39.65906
70.58801,5.88227,867.56758,-0.13729,17.19716,39.66386
70.78800,5.89901,868.25341,-0.13729,17.26413,39.69521
70.98801,5.91569,869.00564,-0.13729,17.33085,39.72960
71.18800,5.93231,869.05221,-0.13729,17.39734,39.73174
71.38800,5.94905,869.62404,-0.13729,17.46430,39.75788
71.58801,5.96568,870.34628,-0.13729,17.53079,39.79090
71.78800,5.98236,869.84588,-0.13729,17.59751,39.76802
71.98801,5.99910,870.23340,-0.13729,17.66448,39.78574
72.18800,6.01566,870.09715,-0.13729,17.73072,39.77951
72.38800,6.03228,870.44770,-0.13729,17.79721,39.79553
72.58801,6.04896,871.16463,-0.13729,17.86394,39.82831
72.78800,6.06564,871.97190,-0.13729,17.93066,39.86522
72.98801,6.08227,871.52980,-0.13729,17.99715,39.84501
73.18800,6.09901,872.07537,-0.13729,18.06411,39.86995
73.38800,6.11581,872.38559,-0.13729,18.13131,39.88413
73.58801,6.13225,872.23370,-0.13729,18.19708,39.87719
73.78800,6.14893,873.21205,-0.13729,18.26381,39.92192
73.98801,6.16573,873.88316,-0.13729,18.33101,39.95260
74.18800,6.18235,874.10957,-0.13729,18.39750,39.96295
74.38800,6.19897,874.60354,-0.13729,18.46398,39.98553
74.58801,6.21566,874.74780,-0.13729,18.53071,39.99213
74.78800,6.23228,874.74110,-0.13729,18.59719,39.99182
74.98801,6.24890,875.12527,-0.13729,18.66368,40.00938
75.18800,6.26570,874.31464,-0.13729,18.73088,39.97232
75.38800,6.28238,875.58022,-0.13729,18.79761,40.03019
75.58801,6.29888,875.40150,-0.13729,18.86362,40.02201
75.78800,6.31556,875.80141,-0.13729,18.93034,40.04030
75.98801,6.33230,876.27266,-0.13729,18.99730,40.06184
76.18800,6.34899,876.19238,-0.13729,19.06403,40.05817
76.38800,6.36573,876.26828,-0.13729,19.13099,40.06164
76.58801,6.38241,877.55043,-0.13729,19.19772,40.12026
76.78800,6.39891,877.74796,-0.13729,19.26372,40.12929
76.98801,6.41559,877.84762,-0.13729,19.33045,40.13385
77.18800,6.43239,878.49209,-0.13729,19.39765,40.16331
77.38800,6.44901,877.50126,-0.13729,19.46414,40.11801
77.58801,6.46570,878.62052,-0.13729,19.53087,40.16918
77.78800,6.48232,878.56473,-0.13729,19.59735,40.16663
77.98801,6.49900,878.50867,-0.13729,19.66408,40.16407
78.18800,6.51556,878.94043,-0.13729,19.73033,40.18381
78.38800,6.53224,879.48628,-0.13729,19.79705,40.20876
78.58801,6.54916,878.50094,-0.13729,19.86473,40.16372
78.78800,6.56566,879.27636,-0.13729,19.93074,40.19917
78.98801,6.58222,879.11114,-0.13729,19.99698,40.19161
79.18800,6.59909,879.26229,-0.13729,20.06443,40.19852
79.38800,6.61565,879.56740,-0.13729,20.13067,40.21247
79.58801,6.63227,880.15543,-0.13729,20.19716,40.23936
79.78800,6.64907,880.81015,-0.13729,20.26436,40.26929
79.98801,6.66575,880.24558,-0.13729,20.33109,40.24348
80.18800,6.68225,881.31651,-0.13729,20.39710,40.29244
80.38800,6.69893,881.63735,-0.13729,20.46382,40.30711
80.58801,6.71580,881.27395,-0.13729,20.53126,40.29049
80.78800,6.73230,881.55353,-0.13729,20.59727,40.30328
80.98801,6.74892,881.57281,-0.13729,20.66376,40.30416
81.18800,6.76572,882.37189,-0.13729,20.73096,40.34069
81.38800,6.78234,882.59988,-0.13729,20.79745,40.35111
81.58801,6.79896,881.95456,-0.13729,20.86393,40.32161
81.78800,6.81576,882.81287,-0.13729,20.93114,40.36085
81.98801,6.83232,882.86661,-0.13729,20.99738,40.36331
82.18800,6.84895,882.89995,-0.13729,21.06387,40.36483
82.38800,6.86563,883.78685,-0.13729,21.13059,40.40538
82.58801,6.88237,882.92547,-0.13729,21.19756,40.36600
82.78800,6.89905,882.41743,-0.13729,21.26428,40.34277
82.98801,6.91567,882.53384,-0.13729,21.33077,40.34809
83.18800,6.93229,883.41376,-0.13729,21.39726,40.38832
83.38800,6.94897,883.60589,-0.13729,21.46398,40.39711
83.58801,6.96560,883.63923,-0.13729,21.53047,40.39863
83.78800,6.98234,883.84850,-0.13729,21.59743,40.40820
83.98801,6.99902,884.16180,-0.13729,21.66416,40.42252
84.18800,7.01570,884.33931,-0.13729,21.73088,40.43064
84.38800,7.03232,884.79165,-0.13729,21.79737,40.45132
84.58801,7.04900,884.16310,-0.13729,21.86409,40.42258
84.78800,7.06568,884.82592,-0.13729,21.93082,40.45288
84.98801,7.08236,884.34191,-0.13729,21.99754,40.43076
85.18800,7.09911,884.72096,-0.13729,22.06451,40.44809
85.38800,7.11561,884.75011,-0.13729,22.13051,40.44942
85.58801,7.13229,885.49331,-0.13729,22.19724,40.48339
85.78800,7.14903,885.37913,-0.13729,22.26420,40.47818
85.98801,7.16565,885.27296,-0.13729,22.33069,40.47332
86.18800,7.18227,885.77950,-0.13729,22.39717,40.49648
86.38800,7.19895,886.12242,-0.13729,22.46390,40.51216
86.58801,7.21569,886.14589,-0.13729,22.53086,40.51323
86.78800,7.23226,886.47120,-0.13729,22.59711,40.52810
86.98801,7.24900,886.16302,-0.13729,22.66407,40.51402
87.18800,7.26580,886.02239,-0.13729,22.73128,40.50758
87.38800,7.28230,886.32442,-0.13729,22.79728,40.52139
87.58801,7.29898,885.22704,-0.13729,22.86401,40.47122
87.78800,7.31578,885.53680,-0.13729,22.93122,40.48538
87.98801,7.33234,885.74402,-0.13729,22.99746,40.49486
88.18800,7.34897,886.14048,-0.13729,23.06395,40.51299
88.38800,7.36565,886.07138,-0.13729,23.13067,40.50982
88.58801,7.38233,885.77904,-0.13729,23.19740,40.49646
88.78800,7.39895,886.55148,-0.13729,23.26388,40.53177
88.98801,7.41563,886.63204,-0.13729,23.33061,40.53546
89.18800,7.43237,886.75302,-0.13729,23.39757,40.54099
89.38800,7.44899,886.47371,-0.13729,23.46406,40.52822
89.58801,7.46568,887.40624,-0.13729,23.53078,40.57085
89.78800,7.48236,886.87930,-0.13729,23.59751,40.54676
89.98801,7.49898,886.89271,-0.13729,23.66399,40.54737
90.18800,7.51572,886.99367,-0.13729,23.73096,40.55199
90.38800,7.53234,887.62324,-0.13729,23.79744,40.58077
90.58801,7.54902,887.25062,-0.13729,23.86417,40.56374
90.78800,7.56570,886.77015,-0.13729,23.93090,40.54177
90.98801,7.58226,887.10096,-0.13729,23.99714,40.55690
91.18800,7.59901,887.25444,-0.13729,24.06411,40.56391
91.38801,7.61569,887.21737,-0.13729,24.13083,40.56222
91.58801,7.63225,887.55647,-0.13729,24.19708,40.57772
91.78800,7.64899,887.16047,-0.13729,24.26404,40.55962
91.98801,7.66567,887.48857,-0.13729,24.33077,40.57462
92.18800,7.68235,887.72690,-0.13729,24.39749,40.58551
92.38801,7.69903,888.07745,-0.13729,24.46422,40.60154
92.58801,7.71571,887.95805,-0.13729,24.53094,40.59608
92.78800,7.73234,887.75326,-0.13729,24.59743,40.58672
92.98801,7.74896,887.63284,-0.13729,24.66392,40.58121
93.18800,7.76564,888.29165,-0.13729,24.73064,40.61133
93.38801,7.78226,887.64392,-0.13729,24.79713,40.58172
93.58801,7.79900,888.02259,-0.13729,24.86409,40.59903
93.78800,7.81574,886.70431,-0.13729,24.93105,40.53876
93.98801,7.83224,887.13504,-0.13729,24.99706,40.55845
94.18800,7.84898,887.82134,-0.13729,25.06402,40.58983
94.38801,7.86573,887.89957,-0.13729,25.13099,40.59341
94.58801,7.88235,887.74851,-0.13729,25.19748,40.58650
94.78800,7.89903,888.01952,-0.13729,25.26420,40.59889
94.98801,7.91565,887.58925,-0.13729,25.33069,40.57922
95.18800,7.93239,887.68620,-0.13729,25.39765,40.58365
95.38801,7.94895,888.65478,-0.13729,25.46390,40.62793
95.58801,7.96563,888.46665,-0.13729,25.53062,40.61933
95.78800,7.98238,888.19452,-0.13729,25.59758,40.60689
95.98801,7.99900,888.46181,-0.13729,25.66407,40.61911
96.18800,8.01568,888.64313,-0.13729,25.73080,40.62740
96.38801,8.03230,888.08620,-0.13729,25.79728,40.60194
96.58801,8.04898,888.08909,-0.13729,25.86401,40.60207
96.78800,8.06566,888.40676,-0.13729,25.93074,40.61659
96.98801,8.08228,887.82385,-0.13729,25.99722,40.58994
97.18800,8.09896,888.95243,-0.13729,26.06394,40.64154
97.38801,8.11559,888.35871,-0.13729,26.13043,40.61440
97.58801,8.13233,888.42213,-0.13729,26.19739,40.61730
97.78800,8.14901,888.58558,-0.13729,26.26412,40.62477
97.98801,8.16569,888.43079,-0.13729,26.33085,40.61769
98.18800,8.18237,888.66279,-0.13729,26.39757,40.62830
98.38801,8.19899,888.56500,-0.13729,26.46405,40.62383
98.58801,8.21567,888.41859,-0.13729,26.53078,40.61713
98.78800,8.23230,888.38050,-0.13729,26.59727,40.61539
98.98801,8.24904,888.83489,-0.13729,26.66423,40.63617
99.18800,8.26572,888.27563,-0.13729,26.73095,40.61060
99.38801,8.28234,888.53091,-0.13729,26.79744,40.62227
99.58801,8.29890,888.11666,-0.13729,26.86369,40.60333
99.78800,8.31570,889.06894,-0.13729,26.93089,40.64687
99.98801,8.33238,888.23875,-0.13729,26.99762,40.60891
100.18800,8.34900,888.21799,-0.13729,27.06410,40.60796
100.38801,8.36569,888.12672,-0.13729,27.13083,40.60379
100.58801,8.38231,888.91070,-0.13729,27.19732,40.63963
100.78800,8.39893,888.34651,-0.13729,27.26380,40.61384
100.98801,8.41573,888.32323,-0.13729,27.33100,40.61277
101.18800,8.43235,888.16723,-0.13729,27.39749,40.60564
101.38801,8.44897,888.75741,-0.13729,27.46397,40.63263
101.58801,8.46565,888.20131,-0.13729,27.53070,40.60720
101.78800,8.48239,888.37743,-0.13729,27.59766,40.61525
101.98801,8.49896,888.10781,-0.13729,27.66391,40.60293
102.18800,8.51564,887.73025,-0.13729,27.73063,40.58567
102.38801,8.53238,887.96066,-0.13729,27.79760,40.59620
102.58801,8.54900,887.48923,-0.13729,27.86409,40.57465
102.78800,8.56556,887.35297,-0.13729,27.93033,40.56842
102.98801,8.58242,887.95368,-0.13729,27.99778,40.59588
103.18800,8.59904,888.41971,-0.13729,28.06426,40.61719
103.38801,8.61573,887.79479,-0.13729,28.13099,40.58862
103.58801,8.63235,888.45072,-0.13729,28.19747,40.61860
103.78800,8.64897,888.06804,-0.13729,28.26396,40.60111
103.98801,8.66565,887.81528,-0.13729,28.33068,40.58955
104.18800,8.68227,887.54194,-0.13729,28.39717,40.57706
104.38801,8.69901,888.15186,-0.13729,28.46413,40.60494
104.58801,8.71557,888.11386,-0.13729,28.53038,40.60320
104.78800,8.73225,887.98646,-0.13729,28.59710,40.59738
104.98801,8.74906,888.16443,-0.13729,28.66431,40.60551
105.18800,8.76568,887.56438,-0.13729,28.73079,40.57808
105.38801,8.78236,887.67176,-0.13729,28.79752,40.58299
105.58801,8.79910,887.55880,-0.13729,28.86448,40.57783
105.78800,8.81566,887.82189,-0.13729,28.93073,40.58986
105.98801,8.83228,887.91633,-0.13729,28.99722,40.59417
106.18800,8.84896,887.59810,-0.13729,29.06394,40.57962
106.38801,8.86570,887.24783,-0.13729,29.13090,40.56361
106.58801,8.88233,887.85766,-0.13729,29.19739,40.59149
106.78800,8.89889,887.37002,-0.13729,29.26364,40.56919
106.98801,8.91563,887.29272,-0.13729,29.33060,40.56566
107.18800,8.93225,888.01663,-0.13729,29.39709,40.59876
107.38801,8.94899,887.21262,-0.13729,29.46405,40.56200
107.58801,8.96579,887.42124,-0.13729,29.53126,40.57154
107.78800,8.98229,887.73808,-0.13729,29.59726,40.58602
107.98801,8.99892,887.25714,-0.13729,29.66375,40.56403
108.18800,9.01566,887.49044,-0.13729,29.73071,40.57470
108.38801,9.03240,886.96843,-0.13729,29.79768,40.55083
108.58801,9.04902,886.41830,-0.13729,29.86417,40.52568
108.78800,9.06570,887.44517,-0.13729,29.93089,40.57263
108.98801,9.08238,887.14780,-0.13729,29.99762,40.55904
109.18800,9.09888,886.82100,-0.13729,30.06362,40.54409
109.38801,9.11563,887.73780,-0.13729,30.13059,40.58601
109.58801,9.13243,886.47278,-0.13729,30.19779,40.52818
109.78800,9.14899,886.88992,-0.13729,30.26404,40.54725
109.98801,9.16555,886.61667,-0.13729,30.33029,40.53475
110.18800,9.18235,887.17919,-0.13729,30.39749,40.56047
110.38801,9.19903,887.05672,-0.13729,30.46421,40.55487
110.58801,9.21571,886.85099,-0.13729,30.53094,40.54547
110.78800,9.23234,886.93928,-0.13729,30.59742,40.54950
110.98801,9.24902,886.41420,-0.13729,30.66415,40.52550
111.18800,9.26558,886.53229,-0.13729,30.73039,40.53090
111.38801,9.28232,886.31371,-0.13729,30.79736,40.52090
111.58801,9.29906,886.35422,-0.13729,30.86432,40.52275
111.78800,9.31562,886.28037,-0.13729,30.93057,40.51938
111.98801,9.33236,886.78142,-0.13729,30.99754,40.54229
112.18800,9.34898,886.20521,-0.13729,31.06402,40.51594
112.38801,9.36561,886.41820,-0.13729,31.13050,40.52568
112.58801,9.38235,886.28139,-0.13729,31.19747,40.51942
112.78800,9.39897,885.41899,-0.13729,31.26396,40.48000
112.98801,9.41571,885.78016,-0.13729,31.33092,40.49651
113.18800,9.43233,885.65527,-0.13729,31.39741,40.49080
113.38801,9.44901,885.82449,-0.13729,31.46413,40.49854
113.58801,9.46575,886.01429,-0.13729,31.53110,40.50721
113.78800,9.48231,885.74057,-0.13729,31.59734,40.49470
113.98801,9.49900,885.27203,-0.13729,31.66407,40.47328
114.18800,9.51568,885.44730,-0.13729,31.73079,40.48129
114.38801,9.53230,885.72232,-0.13729,31.79727,40.49387
114.58801,9.54898,885.74011,-0.13729,31.86401,40.49468
114.78800,9.56572,885.21671,-0.13729,31.93097,40.47075
114.98801,9.58240,884.91794,-0.13729,31.99770,40.45709
115.18800,9.59896,885.79068,-0.13729,32.06394,40.49699
115.38801,9.61564,885.36190,-0.13729,32.13066,40.47739
115.58801,9.63239,885.56670,-0.13729,32.19763,40.48675
115.78800,9.64895,885.05996,-0.13729,32.26388,40.46358
115.98801,9.66569,884.63333,-0.13729,32.33084,40.44408
116.18800,9.68243,884.64431,-0.13729,32.39780,40.44458
116.38801,9.69899,884.52920,-0.13729,32.46405,40.43932
116.58801,9.71561,884.24040,-0.13729,32.53054,40.42611
116.78800,9.73235,884.08161,-0.13729,32.59750,40.41885
116.98801,9.74904,884.23099,-0.13729,32.66422,40.42569
117.18800,9.76566,883.74298,-0.13729,32.73071,40.40337
117.38801,9.78234,882.93161,-0.13729,32.79743,40.36628
117.58801,9.79896,882.81333,-0.13729,32.86392,40.36087
117.78800,9.81558,883.85763,-0.13729,32.93041,40.40862
117.98801,9.83226,883.86824,-0.13729,32.99713,40.40910
118.18800,9.84900,883.19285,-0.13729,33.06410,40.37822
118.38801,9.86562,882.88309,-0.13729,33.13058,40.36406
118.58801,9.88231,883.26894,-0.13729,33.19731,40.38170
118.78800,9.89899,882.82526,-0.13729,33.26403,40.36142
118.98801,9.91567,883.87523,-0.13729,33.33076,40.40942
119.18800,9.93235,882.94772,-0.13729,33.39748,40.36702
119.38801,9.94903,883.00249,-0.13729,33.46421,40.36952
119.58801,9.96565,883.33394,-0.13729,33.53069,40.38467
119.78800,9.98233,882.56663,-0.13729,33.59742,40.34959
119.98801,9.99896,883.19303,-0.13729,33.66390,40.37823
120.18800,10.01564,883.05548,-0.13729,33.73063,40.37194
120.38801,10.03226,882.76463,-0.13729,33.79712,40.35864
120.58801,10.04900,882.79918,-0.13729,33.86408,40.36023
120.78800,10.06568,883.12505,-0.13729,33.93080,40.37512
120.98801,10.08236,882.54875,-0.13729,33.99753,40.34877
121.18800,10.09898,882.10292,-0.13729,34.06402,40.32839
121.38801,10.11572,881.86814,-0.13729,34.13098,40.31766
121.58801,10.13234,881.87791,-0.13729,34.19746,40.31810
121.78800,10.14903,881.93389,-0.13729,34.26419,40.32066
121.98801,10.16571,882.09333,-0.13729,34.33092,40.32795
122.18800,10.18233,882.20472,-0.13729,34.39740,40.33305
122.38801,10.19895,881.35805,-0.13729,34.46389,40.29434
122.58801,10.21563,882.19754,-0.13729,34.53061,40.33272
122.78801,10.23237,881.76467,-0.13729,34.59758,40.31293
122.98801,10.24893,881.60606,-0.13729,34.66382,40.30568
123.18800,10.26562,881.21230,-0.13728,34.73055,40.28767
123.38801,10.28236,881.52317,-0.13729,34.79751,40.30189
123.58801,10.29904,881.43600,-0.13729,34.86424,40.29790
123.78801,10.31560,881.38776,-0.13729,34.93049,40.29570
123.98801,10.33234,881.28289,-0.13729,34.99745,40.29090
124.18800,10.34902,881.47502,-0.13729,35.06418,40.29969
124.38801,10.36570,880.84629,-0.13729,35.13090,40.27094
124.58801,10.38239,880.89462,-0.13729,35.19762,40.27315
124.78801,10.39907,881.42315,-0.13729,35.26435,40.29731
124.98801,10.41557,880.69737,-0.13729,35.33036,40.26413
125.18800,10.43231,880.47124,-0.13729,35.39732,40.25380
125.38801,10.44899,880.72401,-0.13729,35.46405,40.26535
125.58801,10.46561,880.61476,-0.13729,35.53054,40.26036
125.78801,10.48235,880.05615,-0.13729,35.59750,40.23482
125.98801,10.49898,880.01639,-0.13729,35.66399,40.23300
126.18800,10.51566,879.84120,-0.13729,35.73071,40.22499
126.38801,10.53234,879.80209,-0.13729,35.79744,40.22320
126.58801,10.54896,880.03250,-0.13729,35.86392,40.23373
126.78801,10.56570,879.60316,-0.13729,35.93088,40.21411
126.98801,10.58238,879.69303,-0.13729,35.99761,40.21822
127.18800,10.59894,879.37079,-0.13729,36.06385,40.20348
127.38801,10.61562,879.41773,-0.13729,36.13058,40.20563
127.58801,10.63231,879.25969,-0.13729,36.19731,40.19840
127.78801,10.64899,879.47119,-0.13729,36.26403,40.20807
127.98801,10.66567,879.20809,-0.13729,36.33076,40.19604
128.18800,10.68235,878.99817,-0.13729,36.39748,40.18645
128.38800,10.69897,878.87496,-0.13729,36.46396,40.18081
128.58802,10.71559,878.80883,-0.13729,36.53046,40.17779
128.78801,10.73239,878.26932,-0.13729,36.59765,40.15313
128.98801,10.74901,878.32985,-0.13729,36.66414,40.15589
129.18800,10.76564,878.49135,-0.13729,36.73063,40.16328
129.38800,10.78238,878.31160,-0.13729,36.79759,40.15506
129.58802,10.79894,877.89772,-0.13729,36.86384,40.13614
129.78801,10.81556,877.95705,-0.13729,36.93032,40.13885
129.98801,10.83236,877.95360,-0.13729,36.99753,40.13869
130.18800,10.84904,877.93749,-0.13729,37.06426,40.13795
130.38800,10.86566,877.71052,-0.13729,37.13074,40.12758
130.58802,10.88229,878.27891,-0.13729,37.19723,40.15356
130.78801,10.89903,877.79230,-0.13729,37.26419,40.13132
130.98801,10.91565,877.36621,-0.13729,37.33068,40.11184
131.18800,10.93227,877.62764,-0.13729,37.39716,40.12379
131.38800,10.94901,877.23117,-0.13729,37.46413,40.10566
131.58802,10.96557,877.26181,-0.13729,37.53037,40.10706
131.78802,10.98231,876.17086,-0.13729,37.59734,40.05719
131.98800,10.99905,876.72928,-0.13729,37.66430,40.08272
132.18800,11.01568,876.69194,-0.13729,37.73079,40.08101
132.38800,11.03236,876.40136,-0.13729,37.79751,40.06773
132.58802,11.04898,876.40211,-0.13729,37.86400,40.06776
132.78802,11.06566,876.21231,-0.13729,37.93072,40.05908
132.98800,11.08228,875.97091,-0.13729,37.99721,40.04805
133.18800,11.09902,876.38823,-0.13729,38.06418,40.06713
133.38800,11.11570,876.13966,-0.13729,38.13090,40.05576
133.58802,11.13227,875.57007,-0.13729,38.19714,40.02972
133.78802,11.14895,876.18837,-0.13729,38.26387,40.05799
133.98800,11.16569,875.29933,-0.13729,38.33084,40.01734
134.18800,11.18237,875.39963,-0.13729,38.39756,40.02193
134.38800,11.19911,874.95474,-0.13729,38.46452,40.00159
134.58802,11.21567,875.60592,-0.13729,38.53077,40.03136
134.78802,11.23235,874.96154,-0.13729,38.59749,40.00190
134.98800,11.24897,874.13061,-0.13729,38.66398,39.96391
135.18800,11.26566,874.64964,-0.13729,38.73071,39.98764
135.38800,11.28246,874.89476,-0.13729,38.79791,39.99885
135.58802,11.29896,874.73132,-0.13729,38.86392,39.99137
135.78802,11.31564,874.26277,-0.13729,38.93065,39.96995
135.98800,11.33238,874.71455,-0.13729,38.99761,39.99061
136.18800,11.34894,874.25234,-0.13729,39.06385,39.96947
136.38800,11.36556,874.57085,-0.13729,39.13034,39.98404
136.58802,11.38236,873.69652,-0.13729,39.19754,39.94407
136.78802,11.39905,874.11013,-0.13729,39.26427,39.96297
136.98800,11.41555,874.28344,-0.13729,39.33028,39.97090
137.18800,11.43229,873.55608,-0.13729,39.39724,39.93764
137.38800,11.44909,873.45960,-0.13729,39.46444,39.93323
137.58802,11.46571,872.77209,-0.13729,39.53093,39.90180
137.78802,11.48233,873.04851,-0.13729,39.59742,39.91444
137.98800,11.49907,872.21768,-0.13729,39.66438,39.87645
138.18800,11.51564,872.91403,-0.13729,39.73063,39.90829
138.38800,11.53232,872.28054,-0.13729,39.79735,39.87933
138.58802,11.54906,872.93452,-0.13729,39.86432,39.90923
138.78802,11.56562,872.91179,-0.13729,39.93056,39.90819
138.98800,11.58224,872.62103,-0.13729,39.99705,39.89489
139.18800,11.59898,871.96082,-0.13729,40.06401,39.86471
139.38800,11.61572,871.83919,-0.13729,40.13098,39.85915
139.58802,11.63234,871.36505,-0.13729,40.19746,39.83747
139.78802,11.64903,871.58335,-0.13729,40.26419,39.84745
139.98800,11.66571,871.25385,-0.13729,40.33091,39.83239
140.18800,11.68227,871.24538,-0.13729,40.39716,39.83200
140.38800,11.69895,871.42810,-0.13729,40.46388,39.84035
140.58802,11.71569,870.79844,-0.13729,40.53085,39.81157
140.78802,11.73237,871.41190,-0.13729,40.59757,39.83961
140.98800,11.74893,871.12784,-0.13729,40.66382,39.82663
141.18800,11.76556,871.40156,-0.13729,40.73031,39.83914
141.38800,11.78230,870.56998,-0.13729,40.79727,39.80112
141.58802,11.79898,870.48300,-0.13729,40.86399,39.79715
141.78802,11.81572,870.79583,-0.13729,40.93096,39.81145
141.98800,11.83240,870.20546,-0.13729,40.99768,39.78446
142.18800,11.84896,869.56089,-0.13729,41.06393,39.75499
142.38800,11.86558,869.92616,-0.13729,41.13041,39.77169
142.58802,11.88238,869.37565,-0.13729,41.19762,39.74652
142.78802,11.89901,869.18129,-0.13729,41.26411,39.73764
142.98800,11.91563,869.40648,-0.13729,41.33059,39.74793
143.18800,11.93231,869.44122,-0.13729,41.39732,39.74952
143.38800,11.94899,869.42157,-0.13729,41.46404,39.74862
143.58802,11.96561,869.32471,-0.13729,41.53053,39.74419
143.78802,11.98235,869.45072,-0.13729,41.59749,39.74995
143.98800,11.99909,868.98273,-0.13729,41.66446,39.72856
144.18800,12.01559,868.83027,-0.13729,41.73046,39.72159
144.38800,12.03222,869.03954,-0.13729,41.79695,39.73116
144.58802,12.04914,868.50878,-0.13729,41.86463,39.70689
144.78802,12.06570,867.72507,-0.13729,41.93088,39.67106
144.98800,12.08226,868.56969,-0.13729,41.99713,39.70967
145.18800,12.09906,868.03855,-0.13729,42.06433,39.68539
145.38800,12.11568,867.51096,-0.13729,42.13082,39.66127
145.58802,12.13230,867.61490,-0.13729,42.19730,39.66602
145.78802,12.14899,867.65504,-0.13729,42.26403,39.66786
145.98800,12.16573,867.71753,-0.13729,42.33099,39.67072
146.18800,12.18229,867.23398,-0.13729,42.39724,39.64861
146.38800,12.19897,866.93745,-0.13729,42.46396,39.63505
146.58802,12.21571,867.32609,-0.13729,42.53093,39.65282
146.78802,12.23227,866.48613,-0.13729,42.59717,39.61442
146.98800,12.24895,867.02062,-0.13729,42.66390,39.63885
147.18800,12.26575,866.10354,-0.13729,42.73110,39.59692
147.38800,12.28232,866.50094,-0.13729,42.79735,39.61509
147.58802,12.29900,866.39365,-0.13729,42.86407,39.61019
147.78802,12.31556,865.70764,-0.13729,42.93032,39.57883
147.98800,12.33236,865.46298,-0.13729,42.99752,39.56764
148.18800,12.34904,865.63667,-0.13729,43.06425,39.57558
148.38800,12.36566,865.49306,-0.13729,43.13073,39.56902
148.58802,12.38234,865.04677,-0.13729,43.19746,39.54861
148.78802,12.39897,865.46717,-0.13729,43.26394,39.56783
148.98800,12.41565,865.36026,-0.13729,43.33067,39.56294
149.18800,12.43233,864.90875,-0.13729,43.39739,39.54230
149.38800,12.44901,864.53669,-0.13729,43.46412,39.52529
149.58802,12.46563,864.45305,-0.13729,43.53061,39.52147
149.78802,12.48231,864.78721,-0.13729,43.59733,39.53674
149.98800,12.49893,864.14460,-0.13729,43.66382,39.50737
150.18800,12.51567,864.10539,-0.13729,43.73078,39.50557
150.38800,12.53236,863.61729,-0.13729,43.79751,39.48326
150.58802,12.54904,863.13691,-0.13729,43.86423,39.46130
150.78802,12.56560,863.55396,-0.13729,43.93048,39.48036
150.98800,12.58234,863.21384,-0.13729,43.99745,39.46481
151.18800,12.59908,863.31787,-0.13729,44.06441,39.46957
151.38800,12.61570,862.82315,-0.13729,44.13089,39.44695
151.58802,12.63232,863.04434,-0.13729,44.19738,39.45706
151.78802,12.64900,862.82231,-0.13729,44.26410,39.44691
151.98800,12.66563,862.61770,-0.13729,44.33059,39.43756
152.18800,12.68231,862.51441,-0.13729,44.39732,39.43283
152.38800,12.69899,861.73909,-0.13729,44.46404,39.39739
152.58802,12.71567,862.01793,-0.13729,44.53076,39.41014
152.78802,12.73229,862.05695,-0.13729,44.59726,39.41192
152.98800,12.74897,861.13112,-0.13729,44.66397,39.36959
153.18800,12.76571,861.37345,-0.13729,44.73094,39.38067
153.38800,12.78234,860.68781,-0.13729,44.79743,39.34933
153.58802,12.79908,861.11585,-0.13729,44.86439,39.36890
153.78802,12.81570,859.81973,-0.13729,44.93087,39.30964
153.98800,12.83226,860.85945,-0.13729,44.99712,39.35717
154.18800,12.84894,859.89563,-0.13729,45.06385,39.31311
154.38800,12.86562,860.02406,-0.13729,45.13057,39.31898
154.58802,12.88230,859.45744,-0.13729,45.19730,39.29308
154.78802,12.89899,859.03071,-0.13729,45.26403,39.27357
154.98800,12.91561,858.99346,-0.13729,45.33051,39.27186
155.18800,12.93235,859.55476,-0.13729,45.39748,39.29752
155.38800,12.94897,858.43643,-0.13729,45.46396,39.24640
155.58802,12.96565,858.87657,-0.13729,45.53068,39.26652
155.78802,12.98239,858.40272,-0.13729,45.59765,39.24485
155.98800,12.99907,858.57725,-0.13729,45.66437,39.25283
156.18800,13.01569,857.65515,-0.13729,45.73086,39.21068
156.38800,13.03232,857.73421,-0.13729,45.79735,39.21429
156.58802,13.04900,856.97984,-0.13729,45.86407,39.17980
156.78802,13.06568,857.28597,-0.13729,45.93080,39.19380
156.98800,13.08230,856.81034,-0.13729,45.99728,39.17205
157.18800,13.09898,856.98795,-0.13729,46.06401,39.18018
157.38800,13.11560,856.80988,-0.13729,46.13049,39.17203
157.58802,13.13228,856.21607,-0.13729,46.19721,39.14489
157.78802,13.14908,856.19353,-0.13729,46.26442,39.14386
157.98800,13.16571,855.73401,-0.13729,46.33091,39.12284
158.18800,13.18233,855.86710,-0.13729,46.39739,39.12893
158.38800,13.19907,854.87152,-0.13729,46.46436,39.08341
158.58802,13.21569,855.06449,-0.13729,46.53084,39.09224
158.78802,13.23237,854.63198,-0.13729,46.59757,39.07246
158.98800,13.24905,853.87677,-0.13729,46.66429,39.03794
159.18800,13.26567,854.26038,-0.13729,46.73078,39.05547
159.38800,13.28229,854.23086,-0.13729,46.79726,39.05412
159.58802,13.29898,853.42638,-0.13729,46.86399,39.01735
159.78802,13.31572,853.04482,-0.13729,46.93095,38.99990
159.98800,13.33234,853.41707,-0.13729,46.99744,39.01692
160.18800,13.34902,852.09124,-0.13729,47.06416,38.95630
160.38800,13.36570,852.02092,-0.13729,47.13089,38.95309
160.58802,13.38232,851.93040,-0.13729,47.19738,38.94895
160.78802,13.39900,851.34199,-0.13729,47.26410,38.92205
160.98800,13.41569,851.22371,-0.13729,47.33083,38.91664
161.18800,13.43237,850.89058,-0.13729,47.39755,38.90141
161.38800,13.44899,849.94277,-0.13729,47.46404,38.85808
161.58802,13.46561,850.28326,-0.13729,47.53053,38.87365
161.78802,13.48229,849.57946,-0.13729,47.59725,38.84147
161.98800,13.49897,849.03454,-0.13729,47.66397,38.81656
162.18800,13.51565,848.69098,-0.13729,47.73070,38.80085
162.38800,13.53234,848.09065,-0.13729,47.79743,38.77340
162.58802,13.54896,847.59723,-0.13729,47.86391,38.75085
162.78802,13.56558,848.10201,-0.13729,47.93040,38.77392
162.98800,13.58232,846.97241,-0.13729,47.99736,38.72228
163.18800,13.59900,845.90372,-0.13729,48.06408,38.67342
163.38800,13.61568,846.05636,-0.13729,48.13081,38.68040
163.58802,13.63236,846.01287,-0.13729,48.19754,38.67841
163.78802,13.64898,845.15419,-0.13729,48.26402,38.63915
163.98800,13.66561,844.10300,-0.13729,48.33051,38.59109
164.18800,13.68235,843.91283,-0.13729,48.39748,38.58240
164.38800,13.69909,843.42808,-0.13729,48.46444,38.56024
164.58802,13.71559,843.90407,-0.13728,48.53044,38.58200
164.78802,13.73227,842.28525,-0.13729,48.59717,38.50799
164.98800,13.74907,842.05540,-0.13729,48.66437,38.49748
165.18800,13.76563,841.74201,-0.13729,48.73062,38.48315
165.38800,13.78231,841.20752,-0.13729,48.79734,38.45872
165.58802,13.79906,840.28635,-0.13729,48.86431,38.41660
165.78802,13.81562,839.81082,-0.13729,48.93056,38.39486
165.98800,13.83230,839.68770,-0.13729,48.99728,38.38923
166.18800,13.84898,838.80220,-0.13729,49.06401,38.34875
166.38800,13.86578,838.56229,-0.13729,49.13121,38.33778
166.58802,13.88234,837.37439,-0.13729,49.19745,38.28347
166.78802,13.89890,836.62663,-0.13729,49.26370,38.24929
166.98800,13.91571,836.19440,-0.13729,49.33091,38.22953
167.18800,13.93227,835.91128,-0.13729,49.39715,38.21658
167.38800,13.94901,835.05651,-0.13729,49.46412,38.17750
167.58802,13.96575,833.29491,-0.13729,49.53108,38.09697
167.78802,13.98231,833.29771,-0.13729,49.59733,38.09709
167.98800,13.99893,832.31162,-0.13729,49.66381,38.05201
168.18800,14.01561,831.44614,-0.13729,49.73054,38.01244
168.38800,14.03241,830.55366,-0.13729,49.79774,37.97164
168.58802,14.04904,829.79258,-0.13729,49.86423,37.93684
168.78802,14.06566,829.24226,-0.13729,49.93072,37.91168
168.98800,14.08234,828.10465,-0.13729,49.99744,37.85967
169.18800,14.09896,827.19112,-0.13729,50.06393,37.81791
169.38800,14.11576,827.34544,-0.13729,50.13112,37.82496
169.58802,14.13244,826.70571,-0.13729,50.19786,37.79572
169.78802,14.14906,825.16763,-0.13729,50.26434,37.72540
169.98800,14.16563,823.74839,-0.13729,50.33059,37.66051
170.18800,14.18231,823.12925,-0.13729,50.39731,37.63221
170.38800,14.19899,822.28957,-0.13729,50.46404,37.59382
170.58802,14.21561,821.30088,-0.13729,50.53052,37.54861
170.78802,14.23235,820.38688,-0.13729,50.59749,37.50683
170.98800,14.24909,818.99939,-0.13729,50.66445,37.44339
171.18800,14.26559,818.36209,-0.13729,50.73046,37.41426
171.38802,14.28227,816.87570,-0.13729,50.79718,37.34630
171.58802,14.29914,815.94726,-0.13729,50.86462,37.30386
171.78802,14.31570,814.83042,-0.13729,50.93087,37.25280
171.98800,14.33232,813.70380,-0.13729,50.99736,37.20129
172.18800,14.34894,812.15594,-0.13729,51.06384,37.13052
172.38802,14.36568,811.44143,-0.13729,51.13081,37.09786
172.58802,14.38218,809.47345,-0.13729,51.19681,37.00788
172.78802,14.39892,807.57970,-0.13729,51.26378,36.92131
172.98800,14.41578,806.45215,-0.13729,51.33122,36.86975
173.18800,14.43223,805.26816,-0.13729,51.39699,36.81562
173.38802,14.44891,803.20034,-0.13729,51.46372,36.72109
173.58802,14.46577,801.47404,-0.13729,51.53115,36.64216
173.78802,14.48233,799.44208,-0.13729,51.59740,36.54927
173.98800,14.49901,798.57623,-0.13729,51.66413,36.50968
174.18800,14.51569,796.02059,-0.13729,51.73085,36.39284
174.38802,14.53231,794.43548,-0.13729,51.79734,36.32037
174.58802,14.54888,791.07955,-0.13729,51.86359,36.16694
174.78802,14.56574,788.03701,-0.13729,51.93103,36.02784
174.98800,14.58248,784.37012,-0.13729,51.99800,35.86020
175.18800,14.59892,781.47901,-0.13729,52.06376,35.72802
175.38802,14.61554,777.78148,-0.13729,52.13025,35.55898
175.58802,14.63240,774.26801,-0.13729,52.19769,35.39835
175.78802,14.64896,770.58030,-0.13729,52.26394,35.22975
175.98800,14.66570,766.45762,-0.13729,52.33090,35.04127
176.18800,14.68239,761.85032,-0.13729,52.39763,34.83063
176.38802,14.69901,757.69504,-0.13729,52.46412,34.64066
176.58802,14.71563,752.30054,-0.13729,52.53060,34.39403
176.78802,14.73231,743.23006,-0.13729,52.59733,33.97934
176.98800,14.74911,731.83947,-0.13729,52.66453,33.45858
177.18800,14.76567,720.31864,-0.13729,52.73077,32.93186
177.38802,14.78229,707.67803,-0.13729,52.79726,32.35395
177.58802,14.79898,693.37473,-0.13729,52.86399,31.70003
177.78802,14.81560,659.23333,-0.13729,52.93047,30.13914
177.83802,14.81990,9.35760,-0.13727,52.94769,0.42781