File: Manufatura Aditiva/Dados/Ensaios AMR/Ensaios/Ensaios SLS/Tracao_OLABI_08_06_2018_SLS_YZ4.is_metal_RawData/Specimen_RawData_5.csv
Time,Extension,Load,Strain 1,Tensile strain,Tensile stress
(sec),(mm),(N),(mm/mm),(%),(MPa)
0.00000,0.00006,29.91887,0.00139,0.13943,1.38493
0.20000,0.01381,35.67960,0.00158,0.15810,1.65159
0.40000,0.03270,46.17941,0.00190,0.19036,2.13762
0.60000,0.04986,54.84851,0.00219,0.21938,2.53891
0.80000,0.06673,63.38789,0.00247,0.24673,2.93419
1.00000,0.08329,71.68104,0.00274,0.27381,3.31808
1.20000,0.10003,79.70214,0.00299,0.29949,3.68937
1.40000,0.11683,86.94496,0.00325,0.32458,4.02463
1.60000,0.13333,94.61319,0.00352,0.35158,4.37959
1.80000,0.14989,102.02028,0.00379,0.37884,4.72246
2.00000,0.16663,109.88328,0.00406,0.40629,5.08644
2.20000,0.18331,117.89534,0.00434,0.43401,5.45731
2.40000,0.19994,125.47785,0.00461,0.46098,5.80830
2.60000,0.21668,133.01019,0.00488,0.48848,6.15697
2.80000,0.23336,140.32044,0.00515,0.51532,6.49535
3.00000,0.24992,146.58549,0.00537,0.53738,6.78536
3.20000,0.26666,154.11058,0.00564,0.56415,7.13369
3.40000,0.28346,160.77746,0.00592,0.59184,7.44230
3.60000,0.30002,169.06769,0.00619,0.61855,7.82605
3.80000,0.31665,175.00037,0.00645,0.64519,8.10067
4.00000,0.33333,182.94678,0.00671,0.67127,8.46850
4.20000,0.34995,188.97086,0.00693,0.69306,8.74735
4.40000,0.36657,196.05064,0.00720,0.72010,9.07507
4.60000,0.38331,202.69195,0.00746,0.74617,9.38250
4.80000,0.39999,208.74818,0.00772,0.77169,9.66284
5.00000,0.41661,215.94248,0.00798,0.79768,9.99586
5.20000,0.43335,221.39184,0.00819,0.81876,10.24810
5.40000,0.45010,228.06267,0.00845,0.84486,10.55689
5.60000,0.46666,234.91059,0.00871,0.87054,10.87388
5.80000,0.48334,240.61634,0.00895,0.89514,11.13799
6.00000,0.50002,247.55520,0.00921,0.92142,11.45919
6.20000,0.51664,252.27531,0.00942,0.94203,11.67768
6.40000,0.53326,259.37529,0.00967,0.96697,12.00634
6.60000,0.55000,265.11319,0.00993,0.99266,12.27194
6.80000,0.56674,269.81754,0.01013,1.01312,12.48970
7.00000,0.58331,276.24439,0.01038,1.03754,12.78720
7.20000,0.59993,282.26604,0.01062,1.06214,13.06594
7.40000,0.61673,288.44175,0.01087,1.08657,13.35181
7.60000,0.63329,293.76242,0.01107,1.10700,13.59810
7.80000,0.64997,298.72130,0.01132,1.13184,13.82764
8.00000,0.66671,304.65920,0.01156,1.15617,14.10250
8.20000,0.68333,308.90778,0.01176,1.17551,14.29917
8.40000,0.70002,314.55099,0.01201,1.20060,14.56039
8.60000,0.71670,320.55683,0.01226,1.22611,14.83840
8.80000,0.73344,324.78345,0.01246,1.24622,15.03404
9.00000,0.75000,330.70392,0.01270,1.27048,15.30810
9.20000,0.76662,335.20095,0.01292,1.29213,15.51626
9.40000,0.78336,340.16934,0.01315,1.31542,15.74625
9.60000,0.79992,345.90119,0.01339,1.33940,16.01157
9.80000,0.81666,349.83119,0.01360,1.35965,16.19349
10.00000,0.83341,355.62792,0.01384,1.38361,16.46182
10.20000,0.84991,360.19776,0.01407,1.40665,16.67335
10.40000,0.86665,364.24980,0.01427,1.42724,16.86092
10.60000,0.88333,369.20279,0.01451,1.45149,17.09019
10.80000,0.90007,372.78137,0.01471,1.47094,17.25584
11.00000,0.91669,377.99447,0.01495,1.49550,17.49715
11.20000,0.93331,381.67159,0.01515,1.51533,17.66736
11.40000,0.95000,385.86778,0.01539,1.53893,17.86160
11.60000,0.96656,391.09765,0.01562,1.56237,18.10369
11.80000,0.98330,393.75462,0.01581,1.58138,18.22668
12.00000,1.00004,398.93356,0.01605,1.60512,18.46641
12.20000,1.01666,401.92264,0.01624,1.62408,18.60477
12.40000,1.03328,406.93916,0.01648,1.64836,18.83698
12.60000,1.05002,410.16731,0.01667,1.66731,18.98641
12.80000,1.06664,414.81419,0.01691,1.69102,19.20152
13.00000,1.08333,417.50092,0.01710,1.71041,19.32588
13.20000,1.10001,422.46664,0.01734,1.73439,19.55574
13.40000,1.11675,425.93563,0.01755,1.75527,19.71632
13.60000,1.13325,429.64458,0.01776,1.77571,19.88801
13.80000,1.14999,433.35967,0.01799,1.79948,20.05998
14.00000,1.16673,437.34275,0.01820,1.82025,20.24435
14.20000,1.18329,441.57752,0.01845,1.84463,20.44038
14.40000,1.19998,444.45563,0.01866,1.86603,20.57360
14.60000,1.21672,448.55173,0.01888,1.88797,20.76321
14.80000,1.23334,452.20954,0.01911,1.91108,20.93253
15.00000,1.24996,454.98153,0.01931,1.93067,21.06084
15.20000,1.26670,459.33942,0.01955,1.95500,21.26256
15.40000,1.28344,462.29386,0.01977,1.97737,21.39932
15.60000,1.29994,466.35899,0.02001,2.00085,21.58750
15.80000,1.31662,470.20069,0.02024,2.02447,21.76533
16.00000,1.33343,473.63387,0.02047,2.04731,21.92425
16.20000,1.34993,476.82906,0.02072,2.07167,22.07215
16.40000,1.36667,481.10238,0.02095,2.09496,22.26996
16.60000,1.38341,484.05458,0.02119,2.11922,22.40661
16.80000,1.39997,487.39165,0.02144,2.14412,22.56109
17.00000,1.41659,490.95820,0.02168,2.16761,22.72618
17.20000,1.43333,494.74845,0.02193,2.19276,22.90163
17.40000,1.45001,497.93241,0.02217,2.21655,23.04901
17.60000,1.46664,500.74034,0.02241,2.24077,23.17899
17.80000,1.48320,504.97805,0.02267,2.26664,23.37515
18.00000,1.50000,507.58175,0.02291,2.29137,23.49567
18.20000,1.51656,511.07788,0.02316,2.31584,23.65751
18.40000,1.53336,514.41984,0.02342,2.34201,23.81221
18.60000,1.55004,517.69987,0.02368,2.36846,23.96404
18.80000,1.56666,521.23629,0.02394,2.39399,24.12774
19.00000,1.58335,524.82015,0.02421,2.42086,24.29363
19.20000,1.60003,527.53864,0.02448,2.44827,24.41947
19.40000,1.61671,531.35888,0.02476,2.47598,24.59630
19.60000,1.63339,533.95270,0.02502,2.50213,24.71637
19.80000,1.65001,537.68624,0.02530,2.52983,24.88919
20.00000,1.66663,541.10801,0.02558,2.55816,25.04759
20.20000,1.68325,543.77904,0.02584,2.58386,25.17123
20.40000,1.69993,546.76319,0.02612,2.61204,25.30936
20.60000,1.71674,549.77988,0.02640,2.64010,25.44900
20.80000,1.73330,552.38828,0.02666,2.66582,25.56974
21.00000,1.74992,555.39799,0.02695,2.69483,25.70906
21.20000,1.76672,557.87684,0.02721,2.72068,25.82381
21.40000,1.78334,560.45405,0.02748,2.74770,25.94310
21.60000,1.79996,563.94348,0.02777,2.77715,26.10463
21.80000,1.81676,566.30308,0.02802,2.80202,26.21385
22.00000,1.83339,569.58692,0.02831,2.83118,26.36586
22.20000,1.84995,572.01223,0.02861,2.86071,26.47812
22.40000,1.86669,573.37587,0.02885,2.88463,26.54125
22.60000,1.88337,577.12425,0.02915,2.91494,26.71476
22.80000,1.89993,580.57909,0.02945,2.94479,26.87468
23.00000,1.91661,583.29403,0.02974,2.97422,27.00035
23.20000,1.93335,584.68250,0.02999,2.99868,27.06462
23.40000,1.94997,588.10264,0.03029,3.02911,27.22294
23.60000,1.96666,590.53944,0.03060,3.07843,27.33574
23.80000,1.98340,591.91631,0.03084,3.14539,27.39947
23.93200,1.99434,594.05006,0.03104,3.18916,27.49824
24.13200,2.01096,596.68222,0.03136,3.25564,27.62008
24.33200,2.02770,599.77472,0.03167,3.32261,27.76324
24.53200,2.04438,601.43899,0.03192,3.38933,27.84027
24.73200,2.06100,603.91729,0.03223,3.45582,27.95499
24.93200,2.07768,606.40061,0.03254,3.52254,28.06994
25.13200,2.09431,609.23430,0.03285,3.58903,28.20111
25.33200,2.11093,609.96590,0.03309,3.65551,28.23498
25.53200,2.12761,613.39498,0.03341,3.72224,28.39371
25.73200,2.14429,616.04613,0.03407,3.78896,28.51643
25.93200,2.16103,618.39866,0.03420,3.85593,28.62533
26.13200,2.17765,619.38697,0.02072,3.92241,28.67108
26.33200,2.19439,620.75490,0.00792,3.98938,28.73440
26.53200,2.21102,624.77561,0.00880,4.05587,28.92051
26.73200,2.22764,627.40003,0.00710,4.12235,29.04200
26.93200,2.24438,628.97909,0.00957,4.18931,29.11509
27.13200,2.26100,631.29235,0.00892,4.25580,29.22217
27.33200,2.27774,632.87625,0.01639,4.32277,29.29549
27.53200,2.29436,636.11390,0.00074,4.38925,29.44535
27.73200,2.31098,637.82381,-0.06279,4.45574,29.52451
27.93200,2.32760,639.08943,-0.06075,4.52222,29.58309
28.13200,2.34429,641.94081,-0.05466,4.58895,29.71508
28.33200,2.36097,643.96742,-0.05646,4.65567,29.80889
28.53200,2.37759,647.00898,-0.05591,4.72216,29.94968
28.73200,2.39427,648.35809,-0.05609,4.78888,30.01213
28.93200,2.41101,649.59819,-0.05603,4.85585,30.06954
29.13200,2.42769,652.05819,-0.05606,4.92257,30.18341
29.33200,2.44437,654.61267,-0.05608,4.98930,30.30165
29.53200,2.46106,657.54713,-0.05611,5.05602,30.43749
29.73200,2.47768,657.36291,-0.05619,5.12251,30.42896
29.93200,2.49430,660.08535,-0.05622,5.18899,30.55498
30.13200,2.51098,661.95736,-0.05621,5.25572,30.64163
30.33200,2.52772,664.57139,-0.05617,5.32268,30.76264
30.53200,2.54434,666.74720,-0.05621,5.38917,30.86335
30.73200,2.56084,667.30273,-0.05624,5.45518,30.88907
30.93200,2.57764,669.09362,-0.05624,5.52238,30.97197
31.13200,2.59433,671.42230,-0.05622,5.58911,31.07976
31.33200,2.61095,674.06781,-0.05618,5.65559,31.20222
31.53200,2.62769,675.69655,-0.05618,5.72256,31.27761
31.73200,2.64431,677.52092,-0.05618,5.78904,31.36206
31.93200,2.66099,678.39921,-0.05618,5.85577,31.40272
32.13200,2.67761,680.49254,-0.05618,5.92225,31.49962
32.33200,2.69435,682.30685,-0.05616,5.98922,31.58360
32.53200,2.71103,684.63511,-0.05616,6.05594,31.69138
32.73200,2.72766,686.68970,-0.05618,6.12243,31.78648
32.93200,2.74434,686.65100,-0.05618,6.18915,31.78469
33.13200,2.76102,689.02508,-0.05618,6.25588,31.89458
33.33200,2.77764,691.22361,-0.05617,6.32236,31.99635
33.53200,2.79444,693.26730,-0.05616,6.38957,32.09095
33.73200,2.81100,694.76394,-0.05617,6.45581,32.16023
33.93200,2.82762,695.98230,-0.05616,6.52230,32.21663
34.13200,2.84431,695.93876,-0.05616,6.58903,32.21461
34.33200,2.86099,698.37621,-0.05616,6.65575,32.32744
34.53200,2.87773,700.32347,-0.05617,6.72271,32.41758
34.73200,2.89435,701.97992,-0.05616,6.78920,32.49426
34.93200,2.91103,704.14506,-0.05620,6.85593,32.59448
35.13200,2.92759,706.05692,-0.05621,6.92217,32.68298
35.33200,2.94427,705.71583,-0.05621,6.98890,32.66719
35.53200,2.96107,708.09834,-0.05620,7.05610,32.77747
35.73200,2.97770,709.80168,-0.05620,7.12259,32.85632
35.93200,2.99432,712.02270,-0.05621,7.18907,32.95913
36.13200,3.01106,713.86090,-0.05622,7.25604,33.04422
36.33200,3.02762,715.63856,-0.05616,7.32228,33.12651
36.53200,3.04424,717.25952,-0.05619,7.38877,33.20154
36.73200,3.06104,716.85989,-0.05621,7.45597,33.18304
36.93200,3.07778,719.26992,-0.05621,7.52294,33.29460
37.13200,3.09423,720.45932,-0.05622,7.58871,33.34966
37.33200,3.11097,722.32867,-0.05624,7.65567,33.43619
37.53200,3.12777,723.55238,-0.05618,7.72287,33.49283
37.73200,3.14433,726.06895,-0.05617,7.78912,33.60933
37.93200,3.16101,726.70663,-0.05619,7.85585,33.63884
38.13200,3.17769,727.70696,-0.05619,7.92257,33.68515
38.33200,3.19431,728.72052,-0.05619,7.98906,33.73206
38.53200,3.21093,730.57404,-0.05620,8.05554,33.81786
38.73200,3.22768,732.09112,-0.05620,8.12251,33.88809
38.93200,3.24436,733.96624,-0.05621,8.18923,33.97488
39.13200,3.26098,735.02907,-0.05622,8.25572,34.02408
39.33200,3.27760,736.62288,-0.05620,8.32220,34.09786
39.53200,3.29434,737.22405,-0.05622,8.38917,34.12569
39.73200,3.31096,738.64381,-0.05622,8.45565,34.19141
39.93200,3.32764,740.32205,-0.05624,8.52238,34.26909
40.13200,3.34444,741.14511,-0.05624,8.58958,34.30719
40.33200,3.36101,743.12659,-0.05623,8.65583,34.39891
40.53200,3.37763,744.22690,-0.05622,8.72231,34.44984
40.73200,3.39437,746.13318,-0.05621,8.78928,34.53809
40.93200,3.41099,745.71501,-0.05623,8.85576,34.51873
41.13200,3.42767,746.61090,-0.05625,8.92249,34.56020
41.33200,3.44429,748.34265,-0.05627,8.98897,34.64036
41.53200,3.46097,750.33917,-0.05625,9.05570,34.73278
41.73200,3.47760,751.13457,-0.05622,9.12219,34.76960
41.93200,3.49434,753.07451,-0.05621,9.18915,34.85940
42.13200,3.51114,754.28938,-0.05621,9.25635,34.91563
42.33200,3.52770,755.62596,-0.05623,9.32260,34.97750
42.53200,3.54426,755.93865,-0.05623,9.38885,34.99198
42.73200,3.56106,756.49284,-0.05625,9.45605,35.01763
42.93200,3.57762,758.39981,-0.05625,9.52230,35.10590
43.13200,3.59431,759.84793,-0.05626,9.58902,35.17294
43.33200,3.61105,760.87862,-0.05627,9.65599,35.22065
43.53200,3.62767,762.72869,-0.05628,9.72247,35.30628
43.73200,3.64423,763.90523,-0.05628,9.78872,35.36074
43.93200,3.66103,764.69537,-0.05623,9.85592,35.39732
44.13200,3.67777,766.28039,-0.05623,9.92289,35.47069
44.33200,3.69433,765.89966,-0.05624,9.98914,35.45306
44.53200,3.71095,767.20393,-0.05624,10.05562,35.51344
44.73200,3.72776,768.48348,-0.05622,10.12282,35.57267
44.93200,3.74438,768.80287,-0.05623,10.18931,35.58745
45.13200,3.76094,771.37337,-0.05622,10.25556,35.70644
45.33200,3.77780,772.33859,-0.05620,10.32300,35.75112
45.53200,3.79430,773.69413,-0.05618,10.38901,35.81387
45.73200,3.81092,774.68744,-0.05619,10.45549,35.85985
45.93200,3.82766,775.87650,-0.05618,10.52246,35.91489
46.13200,3.84440,776.57681,-0.05620,10.58942,35.94730
46.33200,3.86097,776.46598,-0.05620,10.65567,35.94217
46.53200,3.87765,777.89440,-0.05622,10.72239,36.00829
46.73200,3.89433,779.09678,-0.05619,10.78912,36.06395
46.93200,3.91095,780.27099,-0.05619,10.85560,36.11831
47.13200,3.92763,781.41419,-0.05620,10.92233,36.17122
47.33200,3.94437,782.94389,-0.05621,10.98929,36.24203
47.53200,3.96099,783.75684,-0.05620,11.05578,36.27966
47.73200,3.97762,784.66712,-0.05619,11.12227,36.32180
47.93200,3.99430,786.01688,-0.05619,11.18899,36.38428
48.13200,4.01104,786.60650,-0.05614,11.25595,36.41157
48.33200,4.02766,786.41959,-0.05616,11.32244,36.40292
48.53200,4.04428,787.31021,-0.05618,11.38893,36.44415
48.73200,4.06102,788.70133,-0.05619,11.45589,36.50854
48.93200,4.07764,789.59437,-0.05619,11.52238,36.54988
49.13200,4.09420,791.63983,-0.05620,11.58862,36.64456
49.33200,4.11101,792.16873,-0.05620,11.65583,36.66904
49.53200,4.12769,792.96278,-0.05620,11.72255,36.70580
49.73200,4.14431,793.95128,-0.05623,11.78904,36.75156
49.93200,4.16099,794.88494,-0.05623,11.85576,36.79478
50.13200,4.17767,795.93817,-0.05623,11.92249,36.84353
50.33200,4.19423,796.93990,-0.05623,11.98873,36.88990
50.53200,4.21097,797.52291,-0.05623,12.05570,36.91689
50.73200,4.22777,797.21948,-0.05623,12.12290,36.90284
50.93200,4.24428,797.67974,-0.05623,12.18891,36.92415
51.13200,4.26096,799.27966,-0.05621,12.25563,36.99821
51.33200,4.27776,800.50537,-0.05619,12.32284,37.05494
51.53200,4.29432,801.32848,-0.05620,12.38908,37.09304
51.73200,4.31094,802.59833,-0.05620,12.45557,37.15182
51.93200,4.32768,803.35895,-0.05620,12.52253,37.18703
52.13200,4.34436,804.34829,-0.05622,12.58926,37.23283
52.33200,4.36099,805.04129,-0.05620,12.65575,37.26491
52.53200,4.37767,805.59226,-0.05622,12.72247,37.29041
52.73200,4.39441,806.20935,-0.05623,12.78944,37.31898
52.93200,4.41103,807.67972,-0.05621,12.85592,37.38704
53.13200,4.42765,806.81555,-0.05621,12.92241,37.34704
53.33200,4.44433,807.50994,-0.05622,12.98913,37.37918
53.53200,4.46095,808.42283,-0.05623,13.05562,37.42144
53.73200,4.47764,809.15671,-0.05623,13.12234,37.45541
53.93200,4.49438,810.47220,-0.05621,13.18931,37.51630
54.13200,4.51100,810.67504,-0.05622,13.25579,37.52569
54.33200,4.52762,812.22393,-0.05622,13.32228,37.59739
54.53200,4.54430,812.30337,-0.05622,13.38900,37.60107
54.73200,4.56098,813.73611,-0.05623,13.45573,37.66739
54.93200,4.57766,814.02604,-0.05622,13.52246,37.68081
55.13200,4.59434,815.44081,-0.05622,13.58918,37.74630
55.33200,4.61103,816.03639,-0.05622,13.65590,37.77386
55.53200,4.62765,817.02024,-0.05623,13.72239,37.81941
55.73200,4.64433,817.57773,-0.05624,13.78912,37.84521
55.93200,4.66101,817.74266,-0.05624,13.85584,37.85285
56.13200,4.67775,817.30224,-0.05624,13.92280,37.83246
56.33200,4.69437,818.33843,-0.05626,13.98929,37.88043
56.53200,4.71093,818.72409,-0.05627,14.05554,37.89828
56.73200,4.72767,819.65709,-0.05627,14.12250,37.94147
56.93200,4.74430,820.90050,-0.05627,14.18899,37.99902
57.13200,4.76098,821.80807,-0.05628,14.25571,38.04103
57.33200,4.77772,822.16756,-0.05625,14.32268,38.05767
57.53200,4.79428,823.29083,-0.05624,14.38892,38.10967
57.73200,4.81096,824.01987,-0.05624,14.45565,38.14342
57.93200,4.82770,824.22923,-0.05625,14.52261,38.15311
58.13200,4.84438,824.74919,-0.05625,14.58934,38.17718
58.33200,4.86095,825.85048,-0.05626,14.65559,38.22815
58.53200,4.87769,826.39512,-0.05625,14.72255,38.25336
58.73200,4.89437,827.33585,-0.05627,14.78927,38.29691
58.93200,4.91093,828.04356,-0.05625,14.85552,38.32967
59.13200,4.92767,828.11099,-0.05625,14.92248,38.33279
59.33200,4.94441,827.17687,-0.05624,14.98945,38.28955
59.53200,4.96097,828.40025,-0.05624,15.05570,38.34618
59.73200,4.97759,829.60343,-0.05625,15.12218,38.40188
59.93200,4.99434,829.94597,-0.05624,15.18915,38.41773
60.13200,5.01096,830.59818,-0.05624,15.25563,38.44792
60.33200,5.02770,830.80297,-0.05624,15.32260,38.45741
60.53200,5.04438,831.53453,-0.05624,15.38932,38.49127
60.73200,5.06100,833.03219,-0.05627,15.45581,38.56059
60.93200,5.07768,833.03610,-0.05626,15.52253,38.56077
61.13200,5.09424,833.71373,-0.05626,15.58878,38.59214
61.33200,5.11104,834.23192,-0.05627,15.65598,38.61613
61.53200,5.12767,834.75551,-0.05629,15.72247,38.64037
61.73200,5.14423,835.85866,-0.05633,15.78872,38.69143
61.93200,5.16097,836.23827,-0.05635,15.85568,38.70900
62.13200,5.17765,836.72954,-0.05632,15.92240,38.73174
62.33200,5.19427,837.57294,-0.05628,15.98889,38.77078
62.53200,5.21101,837.47180,-0.05627,16.05586,38.76610
62.73200,5.22763,838.13546,-0.05628,16.12234,38.79682
62.93200,5.24432,837.04134,-0.05630,16.18906,38.74617
63.13200,5.26100,837.23674,-0.05627,16.25579,38.75522
63.33200,5.27768,838.41430,-0.05629,16.32252,38.80973
63.53200,5.29436,838.21574,-0.05624,16.38924,38.80054
63.73200,5.31098,840.01506,-0.05624,16.45573,38.88383
63.93200,5.32766,840.24612,-0.05624,16.52245,38.89452
64.13200,5.34428,840.55495,-0.05626,16.58894,38.90882
64.33200,5.36097,842.36758,-0.05625,16.65566,38.99272
64.53200,5.37777,842.02169,-0.05623,16.72287,38.97671
64.73200,5.39433,842.35864,-0.05624,16.78911,38.99231
64.93201,5.41095,842.91799,-0.05622,16.85560,39.01820
65.13200,5.42769,843.44298,-0.05621,16.92256,39.04250
65.33200,5.44431,843.80349,-0.05622,16.98905,39.05919
65.53200,5.46099,844.43819,-0.05623,17.05577,39.08857
65.73200,5.47773,844.42403,-0.05625,17.12274,39.08791
65.93201,5.49435,845.45501,-0.05626,17.18922,39.13564
66.13200,5.51098,845.25021,-0.05625,17.25571,39.12616
66.33200,5.52766,845.81962,-0.05624,17.32243,39.15252
66.53201,5.54446,846.64635,-0.05626,17.38964,39.19078
66.73200,5.56102,847.05595,-0.05624,17.45589,39.20974
66.93201,5.57764,847.18214,-0.05626,17.52237,39.21559
67.13200,5.59438,847.78769,-0.05626,17.58934,39.24362
67.33200,5.61094,848.20669,-0.05625,17.65558,39.26301
67.53201,5.62769,846.95602,-0.05623,17.72255,39.20512
67.73200,5.64431,846.65772,-0.05623,17.78903,39.19131
67.93201,5.66099,847.88082,-0.05625,17.85576,39.24793
68.13200,5.67761,848.48404,-0.05624,17.92224,39.27585
68.33200,5.69429,849.12973,-0.05624,17.98897,39.30574
68.53201,5.71103,849.82254,-0.05625,18.05593,39.33781
68.73200,5.72759,850.01523,-0.05624,18.12218,39.34673
68.93201,5.74439,849.90095,-0.05624,18.18938,39.34144
69.13200,5.76108,851.12769,-0.05623,18.25611,39.39822
69.33200,5.77764,851.09146,-0.05621,18.32235,39.39655
69.53201,5.79432,851.18264,-0.05620,18.38908,39.40077
69.73200,5.81094,852.04206,-0.05621,18.45556,39.44055
69.93201,5.82774,851.69114,-0.05624,18.52277,39.42430
70.13200,5.84436,852.88538,-0.05624,18.58926,39.47958
70.33200,5.86098,853.08524,-0.05624,18.65574,39.48884
70.53201,5.87767,852.98223,-0.05622,18.72246,39.48407
70.73200,5.89429,854.14695,-0.05624,18.78895,39.53798
70.93201,5.91103,853.67896,-0.05621,18.85592,39.51632
71.13200,5.92777,854.49787,-0.05619,18.92288,39.55423
71.33200,5.94427,854.48446,-0.05620,18.98889,39.55360
71.53201,5.96095,854.65573,-0.05621,19.05561,39.56153
71.73200,5.97769,855.10220,-0.05622,19.12258,39.58220
71.93201,5.99437,855.50379,-0.05622,19.18930,39.60079
72.13200,6.01100,855.44363,-0.05622,19.25579,39.59800
72.33200,6.02768,855.73457,-0.05622,19.32251,39.61147
72.53201,6.04436,856.11399,-0.05621,19.38924,39.62904
72.73200,6.06092,857.12438,-0.05621,19.45549,39.67581
72.93201,6.07766,856.91223,-0.05622,19.52245,39.66599
73.13200,6.09446,857.18399,-0.05622,19.58965,39.67857
73.33200,6.11096,855.46821,-0.05622,19.65566,39.59914
73.53201,6.12765,856.09397,-0.05623,19.72239,39.62811
73.73200,6.14439,856.46296,-0.05622,19.78935,39.64519
73.93201,6.16101,857.15912,-0.05623,19.85584,39.67741
74.13200,6.17763,857.76616,-0.05624,19.92232,39.70551
74.33200,6.19437,858.25799,-0.05625,19.98929,39.72828
74.53201,6.21105,858.05710,-0.05625,20.05601,39.71898
74.73200,6.22761,858.71136,-0.05624,20.12226,39.74927
74.93201,6.24429,858.96542,-0.05625,20.18898,39.76103
75.13200,6.26110,859.27257,-0.05624,20.25618,39.77525
75.33200,6.27766,859.19714,-0.05625,20.32243,39.77175
75.53201,6.29428,860.21312,-0.05627,20.38892,39.81878
75.73200,6.31096,860.07323,-0.05625,20.45564,39.81231
75.93201,6.32764,859.67444,-0.05621,20.52237,39.79385
76.13200,6.34432,860.92176,-0.05620,20.58910,39.85159
76.33200,6.36100,860.14243,-0.05621,20.65582,39.81551
76.53201,6.37780,861.08418,-0.05622,20.72302,39.85910
76.73200,6.39425,861.41406,-0.05620,20.78879,39.87437
76.93201,6.41093,861.00660,-0.05619,20.85552,39.85551
77.13200,6.42773,861.37606,-0.05621,20.92272,39.87262
77.33200,6.44429,862.08833,-0.05621,20.98897,39.90559
77.53201,6.46103,861.70100,-0.05622,21.05593,39.88766
77.73200,6.47777,862.05034,-0.05621,21.12289,39.90383
77.93201,6.49427,862.29714,-0.05622,21.18890,39.91525
78.13200,6.51090,862.21555,-0.05623,21.25539,39.91147
78.33200,6.52764,863.03400,-0.05623,21.32235,39.94936
78.53201,6.54438,862.70571,-0.05623,21.38932,39.93416
78.73200,6.56094,862.68056,-0.05623,21.45556,39.93300
78.93201,6.57768,863.21216,-0.05623,21.52253,39.95761
79.13200,6.59442,863.48215,-0.05623,21.58949,39.97010
79.33200,6.61092,864.20607,-0.05623,21.65550,40.00361
79.53201,6.62767,864.14935,-0.05624,21.72246,40.00099
79.73200,6.64441,863.79377,-0.05624,21.78943,39.98453
79.93201,6.66097,864.42921,-0.05622,21.85567,40.01394
80.13200,6.67759,864.31978,-0.05622,21.92216,40.00888
80.33200,6.69445,864.51275,-0.05622,21.98960,40.01781
80.53201,6.71107,864.25161,-0.05623,22.05609,40.00572
80.73200,6.72763,864.68467,-0.05623,22.12234,40.02577
80.93201,6.74431,864.65338,-0.05623,22.18906,40.02432
81.13200,6.76100,865.34377,-0.05622,22.25579,40.05628
81.33200,6.77762,865.30363,-0.05622,22.32227,40.05442
81.53201,6.79436,865.25343,-0.05623,22.38924,40.05210
81.73200,6.81110,863.90469,-0.05624,22.45620,39.98966
81.93201,6.82760,864.04132,-0.05625,22.52221,39.99599
82.13200,6.84428,864.54749,-0.05626,22.58893,40.01942
82.33200,6.86102,864.92151,-0.05630,22.65590,40.03673
82.53201,6.87764,865.19541,-0.05632,22.72238,40.04941
82.73200,6.89433,865.02759,-0.05632,22.78911,40.04164
82.93201,6.91101,865.45981,-0.05629,22.85583,40.06165
83.13200,6.92763,865.82676,-0.05631,22.92232,40.07864
83.33200,6.94425,865.54429,-0.05629,22.98881,40.06556
83.53201,6.96093,865.99728,-0.05630,23.05553,40.08653
83.73200,6.97767,866.16017,-0.05628,23.12250,40.09407
83.93201,6.99435,866.57340,-0.05626,23.18922,40.11320
84.13200,7.01104,866.52106,-0.05625,23.25594,40.11077
84.33200,7.02766,866.50299,-0.05625,23.32243,40.10994
84.53201,7.04428,866.47980,-0.05621,23.38892,40.10886
84.73200,7.06096,866.93186,-0.05621,23.45564,40.12979
84.93201,7.07776,866.79971,-0.05623,23.52284,40.12367
85.13200,7.09438,867.25866,-0.05623,23.58933,40.14492
85.33200,7.11094,867.50379,-0.05623,23.65558,40.15626
85.53201,7.12762,867.13023,-0.05623,23.72230,40.13897
85.73200,7.14437,867.40572,-0.05624,23.78927,40.15172
85.93201,7.16093,867.51832,-0.05624,23.85551,40.15694
86.13200,7.17767,867.83804,-0.05623,23.92248,40.17173
86.33200,7.19441,868.05811,-0.05623,23.98944,40.18192
86.53201,7.21091,868.45774,-0.05623,24.05545,40.20042
86.73200,7.22759,868.46966,-0.05623,24.12217,40.20097
86.93201,7.24445,868.14677,-0.05622,24.18962,40.18603
87.13200,7.26108,868.15804,-0.05622,24.25610,40.18655
87.33200,7.27764,868.13075,-0.05622,24.32235,40.18528
87.53201,7.29432,868.26961,-0.05622,24.38907,40.19171
87.73200,7.31106,869.02082,-0.05622,24.45604,40.22649
87.93201,7.32768,868.31413,-0.05623,24.52253,40.19378
88.13200,7.34430,868.26105,-0.05622,24.58901,40.19131
88.33200,7.36104,867.62374,-0.05623,24.65598,40.16182
88.53201,7.37760,868.76834,-0.05624,24.72222,40.21480
88.73200,7.39429,868.56540,-0.05625,24.78895,40.20541
88.93201,7.41103,868.66021,-0.05626,24.85591,40.20979
89.13200,7.42765,869.01654,-0.05626,24.92240,40.22629
89.33200,7.44433,869.11637,-0.05626,24.98912,40.23091
89.53201,7.46101,868.74776,-0.05625,25.05585,40.21384
89.73200,7.47769,868.60349,-0.05626,25.12257,40.20717
89.93201,7.49437,868.21793,-0.05627,25.18930,40.18932
90.13200,7.51100,868.72447,-0.05629,25.25578,40.21277
90.33200,7.52774,868.58710,-0.05630,25.32275,40.20641
90.53201,7.54430,868.69812,-0.05634,25.38899,40.21155
90.73200,7.56104,869.32471,-0.05631,25.45596,40.24055
90.93201,7.57766,869.36606,-0.05635,25.52244,40.24247
91.13200,7.59428,869.42436,-0.05630,25.58893,40.24517
91.33200,7.61102,869.43200,-0.05626,25.65590,40.24552
91.53201,7.62764,869.12690,-0.05626,25.72238,40.23140
91.73200,7.64427,869.07689,-0.05626,25.78887,40.22908
91.93201,7.66101,869.28494,-0.05625,25.85583,40.23871
92.13200,7.67763,869.66632,-0.05624,25.92232,40.25637
92.33200,7.69437,869.03609,-0.05623,25.98928,40.22719
92.53201,7.71105,869.57067,-0.05622,26.05601,40.25194
92.73200,7.72761,869.75629,-0.05622,26.12225,40.26053
92.93201,7.74441,869.28969,-0.05625,26.18946,40.23893
93.13200,7.76098,868.92005,-0.05625,26.25570,40.22182
93.33200,7.77754,869.20457,-0.05624,26.32195,40.23499
93.53201,7.79434,869.39810,-0.05624,26.38915,40.24395
93.73200,7.81102,869.24536,-0.05622,26.45588,40.23688
93.93201,7.82758,869.53277,-0.05622,26.52212,40.25018
94.13200,7.84426,869.69510,-0.05624,26.58885,40.25770
94.33200,7.86100,869.09048,-0.05623,26.65581,40.22971
94.53201,7.87768,869.92616,-0.05622,26.72254,40.26839
94.73200,7.89437,869.41440,-0.05624,26.78926,40.24471
94.93201,7.91111,869.12876,-0.05625,26.85623,40.23148
95.13200,7.92767,869.60029,-0.05624,26.92247,40.25331
95.33200,7.94435,869.39298,-0.05624,26.98920,40.24371
95.53201,7.96103,869.35479,-0.05624,27.05593,40.24194
95.73200,7.97771,869.92020,-0.05624,27.12265,40.26812
95.93201,7.99439,869.51740,-0.05625,27.18938,40.24947
96.13200,8.01095,869.38795,-0.05625,27.25562,40.24348
96.33201,8.02764,869.64285,-0.05625,27.32235,40.25528
96.53201,8.04432,869.86534,-0.05623,27.38907,40.26558
96.73200,8.06094,869.75098,-0.05623,27.45556,40.26028
96.93201,8.07768,869.54962,-0.05623,27.52252,40.25097
97.13200,8.09424,869.34883,-0.05624,27.58877,40.24167
97.33201,8.11092,869.22366,-0.05624,27.65549,40.23587
97.53201,8.12766,869.62618,-0.05624,27.72246,40.25451
97.73200,8.14435,869.68718,-0.05624,27.78918,40.25733
97.93201,8.16109,867.61303,-0.05624,27.85615,40.16132
98.13200,8.17765,867.05452,-0.05624,27.92239,40.13547
98.33201,8.19433,867.84102,-0.05625,27.98912,40.17188
98.53201,8.21095,867.63734,-0.05625,28.05561,40.16245
98.73200,8.22769,867.55203,-0.05628,28.12257,40.15850
98.93201,8.24437,868.08410,-0.05628,28.18930,40.18312
99.13200,8.26099,868.23665,-0.05627,28.25578,40.19019
99.33201,8.27762,868.06426,-0.05627,28.32226,40.18221
99.53201,8.29430,868.84117,-0.05626,28.38899,40.21817
99.73200,8.31098,868.60955,-0.05625,28.45572,40.20745
99.93201,8.32772,868.48317,-0.05625,28.52268,40.20160
100.13200,8.34440,868.77374,-0.05625,28.58941,40.21505
100.33201,8.36102,869.18734,-0.05625,28.65589,40.23420
100.53201,8.37758,868.76228,-0.05625,28.72214,40.21452
100.73200,8.39433,868.93290,-0.05625,28.78910,40.22242
100.93201,8.41107,868.94864,-0.05624,28.85607,40.22314
101.13200,8.42763,868.74468,-0.05625,28.92231,40.21370
101.33201,8.44431,868.75893,-0.05626,28.98904,40.21436
101.53201,8.46105,868.98329,-0.05625,29.05600,40.22475
101.73200,8.47767,869.08527,-0.05625,29.12249,40.22947
101.93201,8.49429,868.73956,-0.05624,29.18897,40.21347
102.13200,8.51103,869.40965,-0.05627,29.25594,40.24448
102.33201,8.52766,868.92843,-0.05626,29.32242,40.22221
102.53201,8.54428,868.91642,-0.05624,29.38891,40.22165
102.73200,8.56102,868.84098,-0.05624,29.45588,40.21816
102.93201,8.57770,868.50356,-0.05625,29.52260,40.20254
103.13200,8.59432,868.31627,-0.05625,29.58909,40.19387
103.33201,8.61100,868.67465,-0.05626,29.65581,40.21046
103.53201,8.62774,868.54417,-0.05625,29.72277,40.20442
103.73200,8.64424,868.54352,-0.05624,29.78878,40.20439
103.93201,8.66093,868.35288,-0.05624,29.85551,40.19557
104.13200,8.67773,868.18477,-0.05625,29.92271,40.18779
104.33201,8.69435,868.13560,-0.05627,29.98920,40.18551
104.53201,8.71097,868.42142,-0.05627,30.05568,40.19874
104.73200,8.72759,867.68037,-0.05628,30.12217,40.16444
104.93201,8.74433,868.18514,-0.05628,30.18914,40.18780
105.13200,8.76101,867.94076,-0.05627,30.25586,40.17649
105.33201,8.77769,867.79688,-0.05624,30.32258,40.16983
105.53201,8.79444,867.49317,-0.05624,30.38955,40.15577
105.73200,8.81100,868.05010,-0.05625,30.45579,40.18155
105.93201,8.82762,867.88982,-0.05625,30.52228,40.17413
106.13200,8.84442,868.00689,-0.05627,30.58949,40.17955
106.33201,8.86104,867.36428,-0.05627,30.65597,40.14981
106.53201,8.87760,867.31091,-0.05626,30.72222,40.14734
106.73200,8.89434,868.03706,-0.05627,30.78918,40.18095
106.93201,8.91097,867.40572,-0.05631,30.85567,40.15172
107.13200,8.92753,867.62477,-0.05630,30.92192,40.16187
107.33201,8.94439,867.65168,-0.05628,30.98936,40.16311
107.53201,8.96107,867.32265,-0.05629,31.05608,40.14788
107.73200,8.97757,867.36381,-0.05628,31.12209,40.14978
107.93201,8.99431,867.65233,-0.05627,31.18905,40.16314
108.13200,9.01111,866.77279,-0.05627,31.25626,40.12243
108.33201,9.02762,867.63026,-0.05627,31.32226,40.16212
108.53201,9.04436,867.14746,-0.05626,31.38923,40.13977
108.73200,9.06116,866.46713,-0.05626,31.45643,40.10828
108.93201,9.07760,867.05675,-0.05625,31.52220,40.13557
109.13200,9.09428,866.90160,-0.05625,31.58892,40.12839
109.33201,9.11108,866.35780,-0.05626,31.65613,40.10321
109.53201,9.12770,867.07240,-0.05627,31.72261,40.13630
109.73200,9.14426,866.64781,-0.05628,31.78886,40.11664
109.93201,9.16095,866.43323,-0.05627,31.85559,40.10671
110.13200,9.17769,865.91728,-0.05626,31.92255,40.08282
110.33201,9.19431,866.59389,-0.05625,31.98904,40.11414
110.53201,9.21099,866.45763,-0.05625,32.05576,40.10784
110.73200,9.22779,865.95910,-0.05626,32.12296,40.08476
110.93201,9.24423,866.40548,-0.05625,32.18873,40.10542
111.13200,9.26097,865.43867,-0.05626,32.25570,40.06067
111.33201,9.27766,866.16315,-0.05625,32.32242,40.09421
111.53201,9.29434,865.35392,-0.05625,32.38915,40.05675
111.73200,9.31102,865.84734,-0.05626,32.45587,40.07959
111.93201,9.32764,865.35718,-0.05627,32.52236,40.05690
112.13200,9.34432,865.62363,-0.05627,32.58908,40.06923
112.33201,9.36094,865.62270,-0.05626,32.65557,40.06919
112.53201,9.37762,865.20873,-0.05626,32.72229,40.05003
112.73200,9.39436,865.05748,-0.05629,32.78926,40.04303
112.93201,9.41099,864.99844,-0.05626,32.85575,40.04029
113.13200,9.42767,864.74596,-0.05624,32.92247,40.02861
113.33201,9.44441,865.38801,-0.05625,32.98944,40.05833
113.53201,9.46103,864.53743,-0.05625,33.05592,40.01895
113.73200,9.47771,864.16891,-0.05625,33.12265,40.00189
113.93201,9.49439,864.03806,-0.05627,33.18937,39.99584
114.13200,9.51101,864.26577,-0.05629,33.25586,40.00638
114.33201,9.52751,864.89217,-0.05628,33.32186,40.03537
114.53201,9.54432,863.42208,-0.05627,33.38907,39.96732
114.73200,9.56112,863.65063,-0.05629,33.45627,39.97790
114.93201,9.57762,863.81342,-0.05628,33.52228,39.98544
115.13200,9.59430,863.57398,-0.05628,33.58900,39.97435
115.33201,9.61110,863.26869,-0.05624,33.65621,39.96022
115.53201,9.62760,863.78939,-0.05625,33.72222,39.98433
115.73200,9.64428,862.83116,-0.05625,33.78894,39.93997
115.93201,9.66103,863.42273,-0.05625,33.85590,39.96735
116.13200,9.67771,863.34776,-0.05624,33.92263,39.96388
116.33201,9.69427,863.34534,-0.05624,33.98888,39.96377
116.53201,9.71101,862.99498,-0.05625,34.05584,39.94755
116.73200,9.72775,862.74743,-0.05627,34.12280,39.93609
116.93201,9.74425,862.47530,-0.05626,34.18881,39.92350
117.13200,9.76099,863.03633,-0.05624,34.25578,39.94947
117.33201,9.77773,862.64266,-0.05625,34.32274,39.93124
117.53201,9.79424,862.85453,-0.05626,34.38875,39.94105
117.73200,9.81098,862.50715,-0.05626,34.45571,39.92497
117.93201,9.82766,862.35367,-0.05626,34.52244,39.91787
118.13200,9.84434,862.23697,-0.05626,34.58916,39.91246
118.33201,9.86102,862.03646,-0.05627,34.65589,39.90318
118.53201,9.87758,861.54398,-0.05628,34.72213,39.88039
118.73200,9.89432,861.27762,-0.05627,34.78910,39.86806
118.93201,9.91095,861.08716,-0.05630,34.85558,39.85924
119.13200,9.92769,860.24161,-0.05626,34.92255,39.82010
119.33201,9.94443,860.68371,-0.05630,34.98951,39.84056
119.53201,9.96105,861.08334,-0.05626,35.05600,39.85907
119.73200,9.97761,860.71165,-0.05626,35.12225,39.84186
119.93201,9.99429,861.12618,-0.05627,35.18897,39.86105
120.13200,10.01097,860.09903,-0.05627,35.25569,39.81350
120.33201,10.02765,860.08273,-0.05628,35.32242,39.81275
120.53201,10.04433,860.05153,-0.05626,35.38914,39.81130
120.73200,10.06102,860.30560,-0.05625,35.45587,39.82306
120.93201,10.07764,859.71355,-0.05627,35.52235,39.79566
121.13200,10.09432,858.93050,-0.05626,35.58908,39.75941
121.33201,10.11106,859.19928,-0.05626,35.65605,39.77185
121.53201,10.12762,858.61441,-0.05625,35.72229,39.74478
121.73200,10.14430,859.01162,-0.05626,35.78902,39.76316
121.93201,10.16110,858.99793,-0.05627,35.85622,39.76253
122.13200,10.17761,858.27783,-0.05627,35.92223,39.72920
122.33201,10.19429,858.62260,-0.05627,35.98895,39.74516
122.53201,10.21109,857.76905,-0.05627,36.05615,39.70565
122.73200,10.22771,858.48542,-0.05628,36.12264,39.73881
122.93201,10.24427,857.43144,-0.05629,36.18889,39.69002
123.13200,10.26095,857.97580,-0.05628,36.25561,39.71522
123.33201,10.27769,857.18539,-0.05629,36.32258,39.67863
123.53201,10.29431,857.42194,-0.05629,36.38906,39.68958
123.73200,10.31094,857.46041,-0.05629,36.45555,39.69136
123.93201,10.32774,857.13947,-0.05628,36.52275,39.67651
124.13200,10.34430,856.86874,-0.05627,36.58900,39.66397
124.33201,10.36098,857.09253,-0.05624,36.65572,39.67433
124.53201,10.37772,856.77328,-0.05624,36.72269,39.65955
124.73200,10.39434,855.83394,-0.05624,36.78918,39.61607
124.93201,10.41096,855.56256,-0.05624,36.85566,39.60351
125.13200,10.42759,856.13057,-0.05625,36.92215,39.62980
125.33201,10.44433,855.82826,-0.05625,36.98911,39.61581
125.53201,10.46095,855.26137,-0.05624,37.05560,39.58957
125.73200,10.47769,855.09913,-0.05625,37.12256,39.58206
125.93201,10.49437,855.14672,-0.05626,37.18929,39.58426
126.13200,10.51099,855.04884,-0.05625,37.25577,39.57973
126.33201,10.52767,854.62378,-0.05624,37.32250,39.56005
126.53201,10.54430,854.55449,-0.05624,37.38899,39.55685
126.73200,10.56098,853.71379,-0.05624,37.45570,39.51793
126.93201,10.57778,854.17582,-0.05627,37.52291,39.53932
127.13200,10.59434,853.99039,-0.05629,37.58916,39.53074
127.33201,10.61096,852.87243,-0.05628,37.65564,39.47898
127.53201,10.62764,852.85027,-0.05630,37.72237,39.47796
127.73200,10.64432,853.07956,-0.05627,37.78909,39.48857
127.93201,10.66106,852.29063,-0.05628,37.85606,39.45205
128.13200,10.67763,851.89724,-0.05631,37.92231,39.43385
128.33200,10.69425,852.50502,-0.05631,37.98879,39.46198
128.53202,10.71099,852.17897,-0.05628,38.05576,39.44688
128.73201,10.72761,852.20765,-0.05629,38.12224,39.44822
128.93201,10.74435,851.66283,-0.05629,38.18921,39.42299
129.13200,10.76109,851.36816,-0.05633,38.25617,39.40936
129.33200,10.77759,851.18348,-0.05629,38.32217,39.40081
129.53202,10.79428,850.76448,-0.05632,38.38890,39.38141
129.73201,10.81096,850.76811,-0.05628,38.45563,39.38158
129.93201,10.82776,850.51758,-0.05629,38.52283,39.36998
130.13200,10.84432,849.81741,-0.05628,38.58908,39.33757
130.33200,10.86100,850.20131,-0.05626,38.65580,39.35534
130.53202,10.87774,849.23208,-0.05625,38.72277,39.31047
130.73201,10.89424,848.80181,-0.05625,38.78878,39.29056
130.93201,10.91098,848.69247,-0.05625,38.85574,39.28550
131.13200,10.92773,848.75375,-0.05624,38.92271,39.28833
131.33200,10.94429,848.86067,-0.05625,38.98895,39.29329
131.53202,10.96091,848.38886,-0.05625,39.05544,39.27144
131.73202,10.97765,848.29358,-0.05626,39.12240,39.26703
131.93200,10.99439,848.05470,-0.05625,39.18936,39.25598
132.13200,11.01101,847.41609,-0.05625,39.25585,39.22641
132.33200,11.02763,847.10279,-0.05625,39.32234,39.21191
132.53202,11.04437,847.23206,-0.05626,39.38930,39.21790
132.73202,11.06094,846.42507,-0.05625,39.45555,39.18054
132.93200,11.07768,845.95419,-0.05625,39.52251,39.15874
133.13200,11.09442,845.58818,-0.05626,39.58948,39.14180
133.33200,11.11098,845.08685,-0.05627,39.65572,39.11860
133.53202,11.12754,844.62846,-0.05627,39.72197,39.09738
133.73202,11.14428,844.35623,-0.05625,39.78893,39.08478
133.93200,11.16102,843.78030,-0.05626,39.85590,39.05812
134.13200,11.17771,843.85900,-0.05626,39.92262,39.06176
134.33200,11.19439,843.12297,-0.05627,39.98935,39.02769
134.53202,11.21107,842.77252,-0.05626,40.05607,39.01147
134.73202,11.22763,843.03105,-0.05626,40.12232,39.02343
134.93200,11.24431,841.76129,-0.05628,40.18904,38.96466
135.13200,11.26105,841.64031,-0.05631,40.25601,38.95906
135.33200,11.27773,841.15267,-0.05632,40.32274,38.93649
135.53202,11.29435,840.70135,-0.05630,40.38922,38.91559
135.73202,11.31098,839.90600,-0.05632,40.45570,38.87878
135.93200,11.32766,839.34693,-0.05630,40.52244,38.85290
136.13200,11.34428,838.91992,-0.05627,40.58892,38.83313
136.33200,11.36102,838.56843,-0.05625,40.65588,38.81686
136.53202,11.37776,838.52364,-0.05625,40.72285,38.81479
136.73202,11.39432,837.89695,-0.05624,40.78909,38.78578
136.93200,11.41094,836.75450,-0.05625,40.85558,38.73289
137.13200,11.42774,836.98519,-0.05624,40.92278,38.74358
137.33200,11.44431,835.90262,-0.05624,40.98903,38.69346
137.53202,11.46105,836.24190,-0.05626,41.05599,38.70917
137.73202,11.47773,835.71831,-0.05630,41.12272,38.68493
137.93200,11.49435,834.43085,-0.05630,41.18921,38.62534
138.13200,11.51091,834.64980,-0.05627,41.25545,38.63547
138.33200,11.52771,833.07633,-0.05627,41.32265,38.56264
138.53202,11.54445,833.28653,-0.05629,41.38962,38.57236
138.73202,11.56090,832.25844,-0.05628,41.45539,38.52478
138.93200,11.57758,832.10133,-0.05626,41.52211,38.51750
139.13200,11.59438,830.92581,-0.05625,41.58932,38.46309
139.33200,11.61094,830.24204,-0.05626,41.65556,38.43144
139.53202,11.62774,829.29963,-0.05626,41.72277,38.38781
139.73202,11.64436,828.57972,-0.05624,41.78925,38.35449
139.93200,11.66098,828.28216,-0.05625,41.85574,38.34072
140.13200,11.67760,827.64765,-0.05624,41.92222,38.31134
140.33200,11.69429,827.07303,-0.05624,41.98895,38.28474
140.53202,11.71103,825.80764,-0.05625,42.05591,38.22617
140.73202,11.72765,825.43446,-0.05625,42.12239,38.20890
140.93200,11.74427,825.11976,-0.05626,42.18889,38.19433
141.13200,11.76095,823.79067,-0.05627,42.25561,38.13281
141.33200,11.77763,822.42154,-0.05627,42.32233,38.06943
141.53202,11.79431,822.63080,-0.05627,42.38906,38.07912
141.73202,11.81106,821.56295,-0.05627,42.45602,38.02969
141.93200,11.82768,820.70502,-0.05626,42.52250,37.98997
142.13200,11.84430,819.37360,-0.05626,42.58900,37.92834
142.33200,11.86098,819.41672,-0.05626,42.65572,37.93034
142.53202,11.87766,818.36935,-0.05625,42.72244,37.88186
142.73202,11.89428,817.09400,-0.05625,42.78893,37.82282
142.93200,11.91102,815.65296,-0.05625,42.85589,37.75612
143.13200,11.92770,815.34265,-0.05625,42.92262,37.74175
143.33200,11.94433,814.44578,-0.05626,42.98911,37.70024
143.53202,11.96095,813.30398,-0.05626,43.05559,37.64738
143.73202,11.97775,813.09574,-0.05626,43.12280,37.63774
143.93200,11.99437,812.09149,-0.05625,43.18928,37.59126
144.13200,12.01093,810.51234,-0.05624,43.25553,37.51816
144.33200,12.02767,809.21082,-0.05625,43.32249,37.45792
144.53202,12.04435,808.99652,-0.05624,43.38922,37.44799
144.73202,12.06098,807.46710,-0.05625,43.45571,37.37720
144.93200,12.07766,806.57722,-0.05627,43.52243,37.33601
145.13200,12.09440,805.58080,-0.05630,43.58939,37.28988
145.33200,12.11102,804.76273,-0.05628,43.65588,37.25201
145.53202,12.12764,802.67703,-0.05629,43.72236,37.15547
145.73202,12.14438,802.24350,-0.05631,43.78933,37.13540
145.93200,12.16100,801.37281,-0.05628,43.85582,37.09510
146.13200,12.17762,800.00088,-0.05630,43.92230,37.03159
146.33200,12.19437,798.55714,-0.05630,43.98926,36.96476
146.53202,12.21093,797.59052,-0.05629,44.05551,36.92002
146.73202,12.22761,796.65445,-0.05628,44.12224,36.87669
146.93200,12.24423,795.09215,-0.05627,44.18872,36.80437
147.13200,12.26109,793.40329,-0.05627,44.25616,36.72619
147.33200,12.27765,792.60878,-0.05628,44.32241,36.68941
147.53202,12.29433,791.59262,-0.05626,44.38914,36.64238
147.73202,12.31101,789.93123,-0.05628,44.45586,36.56547
147.93200,12.32764,788.04623,-0.05627,44.52235,36.47822
148.13200,12.34432,787.18988,-0.05626,44.58907,36.43858
148.33200,12.36106,785.39131,-0.05626,44.65604,36.35532
148.53202,12.37762,784.38837,-0.05623,44.72229,36.30890
148.73202,12.39430,782.67595,-0.05622,44.78901,36.22963
148.93200,12.41098,781.23813,-0.05621,44.85573,36.16307
149.13200,12.42766,779.55206,-0.05623,44.92246,36.08503
149.33200,12.44435,777.96769,-0.05623,44.98919,36.01169
149.53202,12.46097,776.05159,-0.05623,45.05567,35.92299
149.73202,12.47765,774.09316,-0.05623,45.12239,35.83234
149.93200,12.49427,771.71326,-0.05624,45.18888,35.72217
150.13200,12.51089,769.28488,-0.05624,45.25537,35.60976
150.33200,12.52775,766.67266,-0.05624,45.32281,35.48885
150.53202,12.54437,763.33424,-0.05625,45.38930,35.33431
150.73202,12.56093,759.91158,-0.05626,45.45554,35.17588
150.93200,12.57773,755.23597,-0.05627,45.52274,34.95945
151.13200,12.59430,749.90401,-0.05630,45.58899,34.71264
151.33200,12.61098,744.00846,-0.05633,45.65572,34.43974
151.53202,12.62772,735.34297,-0.05631,45.72268,34.03861
151.73202,12.64434,724.29976,-0.05628,45.78917,33.52743
151.93200,12.66096,325.21738,-0.05628,45.85565,15.05413
151.96000,12.66330,0.21129,-0.05633,45.86498,0.00978