File: Manufatura Aditiva/Dados/Ensaios AMR/Ensaios/Ensaios FDM/Tracao_OLABI_28_05_2018_FDM_ZX6.is_metal_RawData/Specimen_RawData_2.csv
Time,Extension,Load,Strain 1,Tensile strain,Tensile stress
(sec),(mm),(N),(mm/mm),(%),(MPa)
0.00000,0.00000,4.85060,0.00001,0.00092,0.23328
0.10000,0.00401,6.34521,0.00004,0.00386,0.30516
0.20000,0.01369,9.02236,0.00017,0.01671,0.43392
0.30000,0.02344,14.03120,0.00031,0.03146,0.67481
0.40000,0.03259,16.79228,0.00045,0.04489,0.80760
0.50000,0.04137,20.03945,0.00059,0.05862,0.96376
0.60000,0.04986,23.73040,0.00072,0.07165,1.14127
0.70000,0.05829,26.93342,0.00084,0.08422,1.29532
0.80000,0.06667,29.87964,0.00097,0.09673,1.43701
0.90000,0.07504,33.02276,0.00109,0.10943,1.58817
1.00000,0.08329,36.09652,0.00121,0.12100,1.73600
1.10000,0.09172,39.16346,0.00134,0.13427,1.88350
1.20000,0.10009,42.20107,0.00147,0.14675,2.02959
1.30000,0.10834,45.20137,0.00159,0.15915,2.17389
1.40000,0.11677,48.65640,0.00173,0.17259,2.34005
1.50000,0.12508,52.37055,0.00185,0.18545,2.51867
1.60000,0.13339,55.34367,0.00198,0.19788,2.66166
1.70000,0.14164,58.33901,0.00211,0.21077,2.80572
1.80000,0.15001,60.88707,0.00223,0.22332,2.92826
1.90000,0.15832,64.19908,0.00236,0.23607,3.08755
2.00000,0.16663,67.54372,0.00249,0.24919,3.24840
2.10000,0.17500,70.19143,0.00262,0.26249,3.37574
2.20000,0.18325,73.79864,0.00275,0.27541,3.54922
2.30000,0.19157,76.76493,0.00288,0.28838,3.69188
2.40000,0.20000,79.78895,0.00301,0.30101,3.83732
2.50000,0.20837,83.64098,0.00314,0.31434,4.02257
2.60000,0.21668,85.95175,0.00327,0.32731,4.13371
2.70000,0.22499,89.10709,0.00340,0.34022,4.28546
2.80000,0.23330,92.60823,0.00354,0.35355,4.45384
2.90000,0.24161,95.67308,0.00367,0.36656,4.60124
3.00000,0.24998,98.32638,0.00380,0.37959,4.72884
3.10000,0.25841,101.53570,0.00393,0.39284,4.88319
3.20000,0.26672,104.24843,0.00405,0.40549,5.01366
3.30000,0.27503,107.58569,0.00419,0.41859,5.17415
3.40000,0.28340,111.05598,0.00432,0.43227,5.34105
3.50000,0.29165,113.91330,0.00446,0.44550,5.47847
3.60000,0.30002,116.83580,0.00459,0.45870,5.61902
3.70000,0.30839,119.16854,0.00472,0.47209,5.73121
3.80000,0.31670,123.03579,0.00485,0.48548,5.91720
3.90000,0.32508,125.64397,0.00499,0.49898,6.04264
4.00000,0.33339,129.07141,0.00512,0.51196,6.20748
4.10000,0.34164,132.17956,0.00526,0.52558,6.35696
4.20000,0.34995,134.70880,0.00538,0.53831,6.47860
4.30000,0.35832,137.58313,0.00551,0.55141,6.61683
4.40000,0.36663,141.71338,0.00565,0.56492,6.81547
4.50000,0.37500,143.77248,0.00579,0.57901,6.91450
4.60000,0.38331,146.75688,0.00592,0.59248,7.05803
4.70000,0.39162,150.11234,0.00606,0.60563,7.21940
4.80000,0.40005,152.91867,0.00619,0.61935,7.35437
4.90000,0.40836,155.95310,0.00633,0.63269,7.50031
5.00000,0.41667,158.67461,0.00646,0.64550,7.63119
5.10000,0.42510,161.58839,0.00659,0.65928,7.77133
5.20000,0.43329,165.29448,0.00673,0.67292,7.94956
5.30000,0.44161,167.77741,0.00687,0.68664,8.06898
5.40000,0.45010,170.52072,0.00701,0.70074,8.20091
5.50000,0.45829,173.63977,0.00714,0.71442,8.35092
5.60000,0.46666,176.92985,0.00728,0.72803,8.50915
5.70000,0.47509,179.67124,0.00742,0.74198,8.64099
5.80000,0.48328,182.52875,0.00755,0.75464,8.77842
5.90000,0.49159,186.28669,0.00768,0.76827,8.95915
6.00000,0.50002,188.99260,0.00782,0.78212,9.08929
6.10000,0.50827,190.80184,0.00796,0.79591,9.17630
6.20000,0.51664,194.15753,0.00809,0.80906,9.33768
6.30000,0.52507,197.52041,0.00823,0.82279,9.49942
6.40000,0.53332,200.14094,0.00836,0.83628,9.62545
6.50000,0.54169,202.71274,0.00850,0.84975,9.74913
6.60000,0.55000,205.95125,0.00864,0.86385,9.90488
6.70000,0.55825,209.00555,0.00877,0.87731,10.05177
6.80000,0.56674,211.41875,0.00891,0.89138,10.16783
6.90000,0.57506,215.40711,0.00905,0.90547,10.35965
7.00000,0.58331,218.01142,0.00918,0.91839,10.48490
7.10000,0.59174,220.74771,0.00932,0.93250,10.61649
7.20000,0.59993,223.93451,0.00946,0.94600,10.76976
7.30000,0.60824,226.93658,0.00959,0.95944,10.91414
7.40000,0.61667,229.59451,0.00973,0.97318,11.04197
7.50000,0.62492,232.76056,0.00987,0.98718,11.19423
7.60000,0.63329,235.40482,0.01002,1.00161,11.32140
7.70000,0.64166,238.22472,0.01015,1.01530,11.45702
7.80000,0.64997,241.42871,0.01029,1.02884,11.61111
7.90000,0.65834,243.55096,0.01043,1.04287,11.71318
8.00000,0.66671,247.11380,0.01056,1.05624,11.88453
8.10000,0.67496,249.22313,0.01070,1.06995,11.98597
8.20000,0.68327,251.86390,0.01083,1.08339,12.11298
8.30000,0.69170,255.11915,0.01097,1.09742,12.26953
8.40000,0.70002,257.47409,0.01111,1.11119,12.38279
8.50000,0.70839,260.76471,0.01125,1.12507,12.54105
8.60000,0.71670,263.92788,0.01139,1.13899,12.69317
8.70000,0.72501,266.58375,0.01153,1.15250,12.82090
8.80000,0.73338,269.23269,0.01166,1.16598,12.94830
8.90000,0.74169,272.48510,0.01180,1.18008,13.10472
9.00000,0.75000,274.81224,0.01194,1.19372,13.21664
9.10000,0.75837,277.60353,0.01208,1.20777,13.35088
9.20000,0.76662,280.12535,0.01221,1.22125,13.47216
9.30000,0.77499,283.11536,0.01235,1.23500,13.61596
9.40000,0.78336,285.61107,0.01249,1.24871,13.73599
9.50000,0.79167,288.61691,0.01263,1.26255,13.88055
9.60000,0.79992,291.39027,0.01277,1.27712,14.01393
9.70000,0.80835,293.57863,0.01291,1.29130,14.11918
9.80000,0.81666,296.99137,0.01305,1.30530,14.28331
9.90000,0.82498,299.44060,0.01319,1.31915,14.40110
10.00000,0.83341,302.80207,0.01333,1.33324,14.56276
10.10000,0.84172,305.57408,0.01347,1.34709,14.69608
10.20000,0.85003,307.84428,0.01361,1.36070,14.80526
10.30000,0.85840,310.85659,0.01375,1.37501,14.95013
10.40000,0.86665,312.64445,0.01389,1.38868,15.03612
10.50000,0.87502,316.01116,0.01403,1.40254,15.19803
10.60000,0.88333,318.89854,0.01417,1.41716,15.33690
10.70000,0.89164,320.99122,0.01431,1.43079,15.43754
10.80000,0.89995,324.09213,0.01444,1.44409,15.58667
10.90000,0.90832,325.88677,0.01458,1.45811,15.67298
11.00000,0.91669,328.84174,0.01470,1.47013,15.81510
11.10000,0.92506,331.19479,0.01485,1.48454,15.92826
11.20000,0.93331,333.44955,0.01498,1.49819,16.03670
11.30000,0.94168,336.41041,0.01512,1.51237,16.17910
11.40000,0.95006,338.79485,0.01526,1.52615,16.29378
11.50000,0.95825,341.74309,0.01540,1.54032,16.43557
11.60000,0.96650,344.54719,0.01555,1.55453,16.57043
11.70000,0.97505,346.89317,0.01568,1.56847,16.68325
11.80000,0.98330,349.72038,0.01582,1.58237,16.81922
11.90000,0.99161,352.47917,0.01597,1.59678,16.95190
12.00000,1.00010,354.47150,0.01610,1.61009,17.04772
12.10000,1.00829,357.02304,0.01625,1.62483,17.17043
12.20000,1.01666,360.04458,0.01638,1.63838,17.31575
12.30000,1.02509,362.85410,0.01653,1.65320,17.45086
12.40000,1.03328,365.06832,0.01667,1.66681,17.55735
12.50000,1.04165,368.49321,0.01681,1.68083,17.72207
12.60000,1.05008,371.01726,0.01696,1.69575,17.84346
12.70000,1.05827,373.03639,0.01710,1.70974,17.94057
12.80000,1.06670,375.73737,0.01724,1.72367,18.07047
12.90000,1.07502,377.85012,0.01739,1.73866,18.17207
13.00000,1.08327,380.59447,0.01753,1.75290,18.30406
13.10000,1.09164,382.61055,0.01767,1.76667,18.40102
13.20000,1.10001,386.24995,0.01781,1.78124,18.57605
13.30000,1.10832,388.35967,0.01795,1.79545,18.67751
13.40000,1.11675,390.60991,0.01810,1.80967,18.78574
13.50000,1.12506,392.85976,0.01824,1.82383,18.89394
13.60000,1.13325,395.21726,0.01839,1.83856,19.00732
13.70000,1.14168,397.96173,0.01852,1.85249,19.13931
13.80000,1.14993,400.41539,0.01867,1.86690,19.25731
13.90000,1.15824,402.73247,0.01881,1.88116,19.36875
14.00000,1.16679,405.31107,0.01895,1.89546,19.49276
14.10000,1.17492,407.62448,0.01910,1.90973,19.60402
14.20000,1.18323,409.55041,0.01924,1.92449,19.69665
14.30000,1.19178,412.74400,0.01939,1.93938,19.85024
14.40000,1.19998,415.91404,0.01954,1.95385,20.00270
14.50000,1.20841,417.78674,0.01968,1.96796,20.09276
14.60000,1.21678,420.86267,0.01983,1.98283,20.24069
14.70000,1.22497,423.20364,0.01997,1.99660,20.35328
14.80000,1.23334,425.65046,0.02011,2.01129,20.47095
14.90000,1.24165,427.79404,0.02026,2.02560,20.57404
15.00000,1.24996,431.11946,0.02041,2.04058,20.73397
15.10000,1.25827,433.37867,0.02055,2.05489,20.84263
15.20000,1.26670,435.97436,0.02069,2.06933,20.96746
15.30000,1.27501,437.57092,0.02084,2.08388,21.04425
15.40000,1.28338,439.73075,0.02098,2.09827,21.14812
15.50000,1.29169,442.35373,0.02113,2.11294,21.27427
15.60000,1.30000,445.74579,0.02127,2.12726,21.43740
15.70000,1.30831,446.70440,0.02142,2.14198,21.48351
15.80000,1.31656,450.20650,0.02157,2.15689,21.65193
15.90000,1.32494,451.72325,0.02172,2.17160,21.72488
16.00000,1.33337,454.15359,0.02186,2.18585,21.84176
16.10000,1.34156,456.63198,0.02201,2.20079,21.96096
16.20000,1.34993,458.98580,0.02215,2.21546,22.07416
16.30000,1.35842,460.62591,0.02230,2.23023,22.15304
16.40000,1.36667,463.02117,0.02245,2.24490,22.26823
16.50000,1.37498,465.80872,0.02260,2.25971,22.40230
16.60000,1.38341,467.60091,0.02274,2.27441,22.48849
16.70000,1.39166,469.79832,0.02289,2.28941,22.59417
16.80000,1.40003,471.80122,0.02304,2.30378,22.69050
16.90000,1.40840,474.46536,0.02318,2.31841,22.81862
17.00000,1.41671,476.55795,0.02332,2.33227,22.91926
17.10000,1.42502,477.99321,0.02346,2.34611,22.98829
17.20000,1.43333,480.42675,0.02361,2.36124,23.10533
17.30000,1.44164,482.80312,0.02376,2.37598,23.21961
17.40000,1.45001,484.10231,0.02391,2.39069,23.28210
17.50000,1.45833,487.69917,0.02406,2.40561,23.45508
17.60000,1.46670,488.90421,0.02421,2.42056,23.51304
17.70000,1.47507,491.17655,0.02436,2.43608,23.62232
17.80000,1.48338,492.37749,0.02451,2.45126,23.68008
17.90000,1.49163,494.98724,0.02466,2.46617,23.80559
18.00000,1.49994,497.76002,0.02481,2.48103,23.93894
18.10000,1.50825,499.53321,0.02496,2.49563,24.02422
18.20000,1.51656,501.51488,0.02511,2.51071,24.11953
18.30000,1.52505,503.35489,0.02526,2.52599,24.20802
18.40000,1.53324,505.03854,0.02540,2.53963,24.28899
18.50000,1.54161,506.84973,0.02553,2.55291,24.37610
18.60000,1.55004,509.14627,0.02568,2.56840,24.48655
18.70000,1.55829,510.50885,0.02583,2.58275,24.55207
18.80000,1.56666,512.84814,0.02599,2.59856,24.66458
18.90000,1.57503,515.12565,0.02614,2.61367,24.77411
19.00000,1.58323,516.83779,0.02629,2.62896,24.85645
19.10000,1.59160,518.22872,0.02644,2.64431,24.92335
19.20000,1.60003,521.15116,0.02660,2.65992,25.06390
19.30000,1.60828,522.15187,0.02675,2.67494,25.11203
19.40000,1.61665,524.53014,0.02691,2.69065,25.22641
19.50000,1.62502,526.26003,0.02706,2.70598,25.30960
19.60000,1.63333,528.27080,0.02722,2.72153,25.40631
19.70000,1.64176,530.31328,0.02737,2.73705,25.50454
19.80000,1.65013,532.08447,0.02753,2.75272,25.58972
19.90000,1.65838,533.06632,0.02768,2.76818,25.63694
20.00000,1.66669,535.93810,0.02784,2.78364,25.77505
20.10000,1.67500,537.55096,0.02799,2.79925,25.85262
20.20000,1.68331,538.97556,0.02815,2.81541,25.92113
20.30000,1.69168,541.33232,0.02831,2.83055,26.03448
20.40000,1.69999,542.55133,0.02847,2.84709,26.09311
20.50000,1.70825,545.41375,0.02863,2.86255,26.23077
20.60000,1.71674,546.96761,0.02878,2.87839,26.30550
20.70000,1.72499,548.25787,0.02894,2.89420,26.36755
20.80000,1.73330,549.90486,0.02910,2.90974,26.44676
20.90000,1.74173,551.83028,0.02926,2.92579,26.53936
21.00000,1.74998,553.32454,0.02941,2.94137,26.61123
21.10000,1.75829,556.05173,0.02958,2.95770,26.74238
21.20000,1.76672,557.72341,0.02974,2.97399,26.82278
21.30000,1.77497,558.68584,0.02990,2.99029,26.86907
21.40000,1.78334,560.33959,0.03006,3.00559,26.94860
21.50000,1.79171,561.77140,0.03022,3.02215,27.01746
21.60000,1.80002,563.51959,0.03038,3.03795,27.10154
21.70000,1.80839,565.49883,0.03054,3.07144,27.19673
21.80000,1.81676,567.23943,0.03071,3.10492,27.28044
21.90000,1.82507,568.31902,0.03087,3.13816,27.33236
21.91800,1.82657,568.45834,0.03090,3.14414,27.33906
22.01800,1.83494,571.01334,0.03106,3.17762,27.46194
22.11800,1.84313,572.19532,0.03122,3.21039,27.51878
22.21800,1.85144,573.63478,0.03139,3.24363,27.58801
22.31800,1.85987,575.15190,0.03155,3.27735,27.66098
22.41800,1.86818,576.99685,0.03171,3.31059,27.74971
22.51800,1.87649,578.31211,0.03188,3.34384,27.81296
22.61800,1.88486,579.52730,0.03205,3.37732,27.87140
22.71800,1.89317,581.34743,0.03221,3.41056,27.95894
22.81800,1.90143,582.76886,0.03237,3.44357,28.02730
22.91800,1.90980,584.34228,0.03254,3.47705,28.10297
23.01800,1.91811,585.95780,0.03270,3.51029,28.18067
23.11800,1.92642,587.05276,0.03287,3.54353,28.23333
23.21800,1.93479,589.01072,0.03303,3.57702,28.32749
23.31800,1.94310,589.35708,0.03320,3.61026,28.34415
23.41800,1.95141,590.73470,0.03336,3.64350,28.41040
23.51800,1.95978,592.21233,0.03351,3.67698,28.48147
23.61800,1.96809,593.06296,0.03368,3.71023,28.52238
23.71800,1.97646,594.97845,0.03385,3.74371,28.61450
23.81800,1.98477,595.47075,0.03402,3.77695,28.63818
23.91800,1.99320,597.32301,0.03419,3.81067,28.72726
24.01800,2.00157,598.92060,0.03436,3.84415,28.80409
24.11800,2.00982,600.05873,0.03445,3.87716,28.85883
24.21800,2.01819,601.85716,0.03468,3.91064,28.94532
24.31800,2.02650,601.93110,0.03487,3.94388,28.94888
24.41800,2.03488,603.82015,0.03506,3.97737,29.03973
24.51800,2.04319,604.93560,0.03404,4.01061,29.09337
24.61800,2.05150,606.94288,0.03304,4.04385,29.18991
24.71800,2.05987,607.13869,0.03273,4.07733,29.19933
24.81800,2.06818,609.14210,0.03003,4.11058,29.29568
24.91800,2.07655,611.10221,0.02596,4.14406,29.38995
25.01800,2.08486,611.65560,0.01572,4.17730,29.41656
25.11800,2.09317,611.03026,0.00796,4.21055,29.38649
25.21800,2.10154,612.70962,0.00876,4.24403,29.46725
25.31800,2.10991,612.69416,0.00885,4.27751,29.46651
25.41800,2.11816,614.62349,0.00837,4.31051,29.55930
25.51800,2.12647,616.78709,0.00716,4.34376,29.66335
25.61800,2.13484,617.47991,0.00495,4.37724,29.69667
25.71800,2.14315,618.55642,0.00293,4.41048,29.74844
25.81800,2.15147,619.28649,0.00304,4.44372,29.78356
25.91800,2.15984,620.12328,0.00312,4.47721,29.82380
26.01800,2.16821,621.34997,0.00362,4.51069,29.88280
26.11800,2.17652,621.69987,0.00429,4.54393,29.89962
26.21800,2.18489,623.06020,0.00426,4.57741,29.96505
26.31800,2.19314,623.82501,0.00423,4.61042,30.00183
26.41800,2.20145,624.72932,0.00471,4.64366,30.04532
26.51800,2.20982,626.03904,0.00481,4.67714,30.10831
26.61800,2.21813,626.59476,0.00785,4.71038,30.13503
26.71800,2.22644,628.16413,-0.00969,4.74363,30.21051
26.81800,2.23481,628.36786,-0.14341,4.77711,30.22031
26.91800,2.24318,629.53085,-0.13916,4.81059,30.27624
27.01800,2.25149,629.74519,-0.14067,4.84384,30.28655
27.11800,2.25980,630.93095,-0.14063,4.87708,30.34358
27.21800,2.26823,631.80733,-0.14064,4.91080,30.38573
27.31800,2.27654,631.95978,-0.14064,4.94404,30.39306
27.41800,2.28486,633.13860,-0.14064,4.97729,30.44975
27.51800,2.29323,633.22578,-0.14064,5.01077,30.45394
27.61800,2.30148,633.83165,-0.14064,5.04377,30.48308
27.71800,2.30985,635.13662,-0.14064,5.07725,30.54584
27.81800,2.31822,635.82375,-0.14064,5.11074,30.57889
27.91800,2.32653,636.18184,-0.14065,5.14398,30.59611
28.01800,2.33484,636.92392,-0.14065,5.17722,30.63180
28.11800,2.34315,637.55917,-0.14065,5.21046,30.66235
28.21800,2.35146,637.96537,-0.14065,5.24371,30.68188
28.31800,2.35989,638.41012,-0.14065,5.27743,30.70328
28.41800,2.36820,638.49273,-0.14065,5.31067,30.70725
28.51800,2.37651,639.60417,-0.14065,5.34391,30.76070
28.61800,2.38482,640.00660,-0.14065,5.37716,30.78005
28.71800,2.39307,640.31617,-0.14065,5.41016,30.79494
28.81800,2.40144,640.34658,-0.14065,5.44364,30.79641
28.91800,2.40982,640.31449,-0.14066,5.47713,30.79486
29.01800,2.41813,640.96772,-0.14066,5.51037,30.82628
29.11800,2.42644,641.41857,-0.14066,5.54361,30.84796
29.21800,2.43481,641.72018,-0.14066,5.57709,30.86247
29.31800,2.44306,641.92587,-0.14066,5.61010,30.87236
29.41800,2.45149,641.47795,-0.14066,5.64382,30.85082
29.51800,2.45980,641.08470,-0.14066,5.67706,30.83190
29.61800,2.46817,641.53397,-0.14066,5.71054,30.85351
29.71800,2.47648,640.73838,-0.14066,5.74379,30.81525
29.81800,2.48479,639.72203,-0.14066,5.77703,30.76637
29.91800,2.49310,637.43191,-0.14066,5.81027,30.65623
30.01800,2.50147,102.12760,-0.14066,5.84375,4.91166
30.03200,2.50267,3.01021,-0.14066,5.84854,0.14477