File: Manufatura Aditiva/Dados/Ensaios AMR/Ensaios/Ensaios FDM/Tracao_OLABI_28_05_2018_FDM_ZX6.is_metal_RawData/Specimen_RawData_4.csv
Time,Extension,Load,Strain 1,Tensile strain,Tensile stress
(sec),(mm),(N),(mm/mm),(%),(MPa)
0.00000,0.00000,-0.56939,0.00000,-0.00023,-0.02926
0.10000,0.00371,1.07588,0.00004,0.00350,0.05528
0.20000,0.01333,4.24438,0.00021,0.02142,0.21809
0.30000,0.02326,8.75883,0.00042,0.04200,0.45006
0.40000,0.03247,11.89442,0.00061,0.06065,0.61117
0.50000,0.04137,15.32700,0.00078,0.07808,0.78755
0.60000,0.04986,18.86410,0.00094,0.09440,0.96930
0.70000,0.05823,21.97452,0.00111,0.11056,1.12912
0.80000,0.06673,25.12785,0.00127,0.12731,1.29115
0.90000,0.07510,28.86149,0.00144,0.14373,1.48300
1.00000,0.08323,31.59180,0.00159,0.15932,1.62329
1.10000,0.09166,34.99411,0.00176,0.17569,1.79811
1.20000,0.09997,38.67020,0.00191,0.19149,1.98700
1.30000,0.10828,41.61333,0.00207,0.20702,2.13823
1.40000,0.11671,44.68873,0.00223,0.22330,2.29625
1.50000,0.12508,47.57608,0.00239,0.23901,2.44461
1.60000,0.13339,50.94985,0.00255,0.25485,2.61797
1.70000,0.14164,54.40658,0.00270,0.27033,2.79559
1.80000,0.15001,56.96642,0.00285,0.28547,2.92712
1.90000,0.15832,60.29385,0.00301,0.30126,3.09809
2.00000,0.16663,62.97372,0.00316,0.31615,3.23579
2.10000,0.17494,66.97067,0.00332,0.33204,3.44117
2.20000,0.18325,70.65482,0.00348,0.34751,3.63047
2.30000,0.19157,72.99273,0.00364,0.36360,3.75060
2.40000,0.20000,76.78699,0.00379,0.37903,3.94556
2.50000,0.20837,79.61572,0.00394,0.39420,4.09091
2.60000,0.21668,82.97835,0.00410,0.40975,4.26370
2.70000,0.22499,85.96163,0.00424,0.42444,4.41699
2.80000,0.23330,89.50812,0.00440,0.44005,4.59922
2.90000,0.24161,92.41030,0.00455,0.45490,4.74834
3.00000,0.24998,95.47953,0.00470,0.47025,4.90605
3.10000,0.25841,98.72832,0.00486,0.48561,5.07298
3.20000,0.26672,102.05375,0.00501,0.50113,5.24385
3.30000,0.27503,104.76477,0.00516,0.51605,5.38315
3.40000,0.28340,108.83454,0.00531,0.53140,5.59227
3.50000,0.29165,111.88706,0.00546,0.54630,5.74912
3.60000,0.30002,114.05811,0.00561,0.56119,5.86067
3.70000,0.30839,117.64521,0.00577,0.57672,6.04499
3.80000,0.31670,120.22991,0.00592,0.59228,6.17780
3.90000,0.32508,123.82810,0.00608,0.60768,6.36269
4.00000,0.33339,126.48682,0.00623,0.62254,6.49930
4.10000,0.34164,130.35251,0.00638,0.63760,6.69793
4.20000,0.35001,132.71107,0.00652,0.65204,6.81912
4.30000,0.35832,136.41047,0.00667,0.66734,7.00921
4.40000,0.36663,139.27851,0.00683,0.68261,7.15658
4.50000,0.37500,142.79974,0.00697,0.69684,7.33751
4.60000,0.38331,145.28593,0.00712,0.71206,7.46526
4.70000,0.39162,148.25924,0.00727,0.72669,7.61804
4.80000,0.40005,151.65106,0.00742,0.74193,7.79232
4.90000,0.40836,154.51884,0.00757,0.75699,7.93968
5.00000,0.41667,158.36183,0.00772,0.77193,8.13714
5.10000,0.42510,161.02173,0.00787,0.78726,8.27382
5.20000,0.43329,163.93011,0.00802,0.80172,8.42326
5.30000,0.44155,167.06359,0.00816,0.81644,8.58427
5.40000,0.45010,170.74785,0.00831,0.83112,8.77358
5.50000,0.45829,173.29592,0.00846,0.84596,8.90450
5.60000,0.46666,176.63902,0.00861,0.86053,9.07628
5.70000,0.47509,179.64987,0.00876,0.87593,9.23099
5.80000,0.48328,182.63635,0.00891,0.89071,9.38445
5.90000,0.49159,185.86176,0.00906,0.90606,9.55018
6.00000,0.50008,189.08686,0.00921,0.92083,9.71589
6.10000,0.50827,191.99427,0.00935,0.93517,9.86529
6.20000,0.51664,195.35401,0.00950,0.94991,10.03792
6.30000,0.52507,197.58667,0.00965,0.96508,10.15264
6.40000,0.53332,200.74062,0.00979,0.97930,10.31470
6.50000,0.54169,203.62369,0.00994,0.99444,10.46284
6.60000,0.55000,206.57410,0.01010,1.00962,10.61445
6.70000,0.55825,209.87310,0.01024,1.02370,10.78396
6.80000,0.56674,212.74285,0.01039,1.03907,10.93142
6.90000,0.57506,216.64922,0.01054,1.05380,11.13214
7.00000,0.58331,218.39163,0.01068,1.06805,11.22167
7.10000,0.59174,221.54716,0.01083,1.08289,11.38381
7.20000,0.59993,225.50335,0.01097,1.09738,11.58709
7.30000,0.60824,228.11107,0.01112,1.11170,11.72109
7.40000,0.61673,231.01631,0.01127,1.12696,11.87037
7.50000,0.62498,234.81431,0.01142,1.14158,12.06552
7.60000,0.63329,237.33657,0.01156,1.15631,12.19512
7.70000,0.64166,240.04995,0.01171,1.17078,12.33454
7.80000,0.64997,243.44227,0.01186,1.18602,12.50885
7.90000,0.65828,246.39361,0.01201,1.20065,12.66050
8.00000,0.66671,249.04138,0.01215,1.21520,12.79655
8.10000,0.67496,251.96529,0.01230,1.22975,12.94679
8.20000,0.68327,254.85565,0.01244,1.24407,13.09531
8.30000,0.69170,257.67554,0.01259,1.25878,13.24020
8.40000,0.70002,260.86103,0.01273,1.27338,13.40388
8.50000,0.70839,263.37081,0.01288,1.28825,13.53284
8.60000,0.71670,266.63039,0.01303,1.30322,13.70033
8.70000,0.72501,269.84345,0.01318,1.31768,13.86543
8.80000,0.73338,272.74315,0.01332,1.33188,14.01443
8.90000,0.74169,276.00564,0.01346,1.34649,14.18206
9.00000,0.75000,278.63707,0.01361,1.36063,14.31727
9.10000,0.75837,281.61465,0.01375,1.37529,14.47027
9.20000,0.76668,284.15767,0.01390,1.38993,14.60094
9.30000,0.77493,287.48785,0.01405,1.40494,14.77206
9.40000,0.78336,290.13043,0.01420,1.41971,14.90784
9.50000,0.79167,293.77625,0.01434,1.43375,15.09517
9.60000,0.79992,296.30130,0.01449,1.44873,15.22492
9.70000,0.80835,299.08044,0.01463,1.46279,15.36772
9.80000,0.81666,301.90519,0.01477,1.47725,15.51287
9.90000,0.82492,304.91834,0.01492,1.49202,15.66769
10.00000,0.83341,307.90367,0.01507,1.50655,15.82109
10.10000,0.84172,310.73675,0.01522,1.52194,15.96666
10.20000,0.85003,313.40185,0.01535,1.53541,16.10360
10.30000,0.85840,317.02358,0.01551,1.55068,16.28970
10.40000,0.86665,319.31987,0.01565,1.56460,16.40769
10.50000,0.87502,322.13135,0.01579,1.57939,16.55215
10.60000,0.88333,324.95174,0.01594,1.59419,16.69707
10.70000,0.89164,328.09710,0.01609,1.60876,16.85869
10.80000,0.89995,330.64031,0.01623,1.62345,16.98937
10.90000,0.90832,333.59148,0.01638,1.63769,17.14101
11.00000,0.91669,336.88140,0.01653,1.65266,17.31006
11.10000,0.92506,338.91336,0.01668,1.66754,17.41446
11.20000,0.93337,342.07515,0.01682,1.68150,17.57693
11.30000,0.94168,344.81669,0.01696,1.69623,17.71780
11.40000,0.95006,347.80020,0.01711,1.71128,17.87110
11.50000,0.95825,350.23273,0.01725,1.72538,17.99609
11.60000,0.96650,354.17783,0.01740,1.73973,18.19880
11.70000,0.97505,355.68806,0.01754,1.75420,18.27640
11.80000,0.98330,358.62965,0.01769,1.76875,18.42755
11.90000,0.99161,361.75312,0.01783,1.78293,18.58805
12.00000,1.00010,363.36035,0.01798,1.79822,18.67063
12.10000,1.00829,366.79886,0.01814,1.81352,18.84731
12.20000,1.01666,369.72109,0.01828,1.82753,18.99747
12.30000,1.02509,372.37718,0.01842,1.84244,19.13395
12.40000,1.03328,375.38253,0.01857,1.85687,19.28837
12.50000,1.04159,377.72187,0.01871,1.87123,19.40857
12.60000,1.05008,380.43461,0.01886,1.88614,19.54796
12.70000,1.05827,383.01323,0.01901,1.90083,19.68046
12.80000,1.06664,385.97600,0.01916,1.91560,19.83270
12.90000,1.07502,389.21537,0.01930,1.93048,19.99915
13.00000,1.08327,391.58915,0.01945,1.94488,20.12112
13.10000,1.09170,394.51891,0.01960,1.95967,20.27166
13.20000,1.10001,397.26053,0.01974,1.97434,20.41253
13.30000,1.10832,400.22577,0.01989,1.98869,20.56490
13.40000,1.11675,402.71347,0.02004,2.00358,20.69272
13.50000,1.12506,404.93407,0.02018,2.01825,20.80682
13.60000,1.13325,407.58830,0.02033,2.03278,20.94321
13.70000,1.14168,410.33980,0.02048,2.04781,21.08459
13.80000,1.14993,412.91593,0.02063,2.06254,21.21696
13.90000,1.15824,415.69173,0.02077,2.07722,21.35959
14.00000,1.16679,417.93990,0.02092,2.09202,21.47511
14.10000,1.17492,421.23497,0.02107,2.10674,21.64442
14.20000,1.18323,424.66964,0.02122,2.12153,21.82090
14.30000,1.19178,426.79547,0.02137,2.13665,21.93013
14.40000,1.19998,428.91433,0.02151,2.15098,22.03901
14.50000,1.20841,432.17628,0.02166,2.16599,22.20662
14.60000,1.21678,434.31721,0.02181,2.18097,22.31662
14.70000,1.22497,437.77390,0.02196,2.19553,22.49424
14.80000,1.23334,439.94999,0.02210,2.21035,22.60605
14.90000,1.24171,442.81445,0.02226,2.22559,22.75324
15.00000,1.24990,445.48009,0.02240,2.24001,22.89021
15.10000,1.25827,448.26185,0.02255,2.25483,23.03314
15.20000,1.26670,451.47971,0.02270,2.26964,23.19849
15.30000,1.27495,453.03223,0.02284,2.28432,23.27826
15.40000,1.28332,455.92939,0.02299,2.29907,23.42713
15.50000,1.29169,458.82771,0.02314,2.31393,23.57605
15.60000,1.29994,461.52985,0.02329,2.32861,23.71490
15.70000,1.30831,463.87683,0.02344,2.34382,23.83549
15.80000,1.31656,466.64211,0.02359,2.35855,23.97758
15.90000,1.32494,469.59347,0.02373,2.37308,24.12923
16.00000,1.33337,471.95512,0.02388,2.38796,24.25058
16.10000,1.34156,474.77996,0.02402,2.40247,24.39573
16.20000,1.34993,476.40046,0.02417,2.41739,24.47900
16.30000,1.35842,478.94344,0.02433,2.43267,24.60966
16.40000,1.36667,481.67342,0.02447,2.44723,24.74994
16.50000,1.37498,484.25747,0.02462,2.46244,24.88272
16.60000,1.38341,486.40403,0.02476,2.47609,24.99301
16.70000,1.39166,488.81052,0.02490,2.49018,25.11667
16.80000,1.40003,490.89151,0.02505,2.50496,25.22359
16.90000,1.40840,493.34164,0.02520,2.51986,25.34949
17.00000,1.41671,495.84024,0.02535,2.53502,25.47788
17.10000,1.42502,497.97082,0.02550,2.55005,25.58735
17.20000,1.43333,500.72735,0.02565,2.56511,25.72899
17.30000,1.44164,503.15750,0.02580,2.57987,25.85386
17.40000,1.45001,505.61195,0.02595,2.59475,25.97998
17.50000,1.45833,508.32513,0.02610,2.60996,26.11939
17.60000,1.46670,510.74550,0.02625,2.62529,26.24376
17.70000,1.47507,512.54584,0.02640,2.64037,26.33626
17.80000,1.48338,515.06506,0.02655,2.65520,26.46571
17.90000,1.49163,516.90741,0.02670,2.67005,26.56038
18.00000,1.49994,520.31372,0.02685,2.68520,26.73540
18.10000,1.50825,522.85083,0.02700,2.70048,26.86577
18.20000,1.51656,524.51552,0.02716,2.71554,26.95131
18.30000,1.52505,526.66161,0.02731,2.73087,27.06158
18.40000,1.53330,529.11323,0.02746,2.74619,27.18755
18.50000,1.54161,531.61946,0.02761,2.76118,27.31633
18.60000,1.55004,533.50939,0.02777,2.77658,27.41344
18.70000,1.55829,536.17777,0.02792,2.79181,27.55055
18.80000,1.56666,538.20615,0.02806,2.80647,27.65477
18.90000,1.57503,540.85818,0.02822,2.82167,27.79104
19.00000,1.58323,543.27054,0.02837,2.83716,27.91500
19.10000,1.59160,544.56466,0.02853,2.85255,27.98149
19.20000,1.60003,547.59071,0.02868,2.86804,28.13698
19.30000,1.60828,550.14244,0.02884,2.88373,28.26810
19.40000,1.61665,551.51409,0.02899,2.89870,28.33858
19.50000,1.62502,553.56203,0.02914,2.91379,28.44381
19.60000,1.63333,555.68805,0.02929,2.92887,28.55305
19.70000,1.64176,557.76644,0.02945,2.94471,28.65985
19.80000,1.65013,560.10243,0.02960,2.96019,28.77987
19.90000,1.65838,562.55157,0.02976,2.97592,28.90572
20.00000,1.66669,564.13845,0.02991,2.99105,28.98726
20.10000,1.67500,566.47519,0.03007,3.00681,29.10733
20.20000,1.68331,568.86622,0.03022,3.02231,29.23019
20.30000,1.69168,571.56458,0.03038,3.03779,29.36884
20.40000,1.69999,572.91086,0.03053,3.05328,29.43801
20.50000,1.70831,575.41947,0.03069,3.06867,29.56692
20.60000,1.71674,577.14633,0.03085,3.08470,29.65565
20.70000,1.72499,579.43100,0.03100,3.11771,29.77304
20.80000,1.73330,581.78306,0.03116,3.15095,29.89390
20.83800,1.73647,582.13808,0.03122,3.16362,29.91214
20.93800,1.74490,584.47649,0.03138,3.19735,30.03229
21.03800,1.75315,586.54300,0.03153,3.23035,30.13848
21.13800,1.76152,588.35377,0.03169,3.26383,30.23152
21.23800,1.76983,590.39951,0.03184,3.29707,30.33664
21.33800,1.77808,592.75171,0.03200,3.33008,30.45750
21.43800,1.78651,594.75200,0.03216,3.36380,30.56028
21.53800,1.79482,596.42317,0.03232,3.39704,30.64615
21.63800,1.80319,598.32311,0.03248,3.43052,30.74378
21.73800,1.81162,600.49430,0.03264,3.46425,30.85534
21.83800,1.81987,602.47011,0.03286,3.49725,30.95686
21.93800,1.82818,604.23305,0.03306,3.53049,31.04745
22.03800,1.83661,606.56597,0.03343,3.56421,31.16732
22.13800,1.84480,606.90083,0.03144,3.59698,31.18453
22.23800,1.85312,610.57825,0.02494,3.63022,31.37349
22.33800,1.86155,610.03175,0.00378,3.66394,31.34541
22.43800,1.86986,612.24862,0.00609,3.69718,31.45932
22.53800,1.87817,613.61599,0.00626,3.73043,31.52958
22.63800,1.88654,616.27883,0.00615,3.76391,31.66640
22.73800,1.89479,617.82394,0.00553,3.79691,31.74579
22.83800,1.90310,619.64677,0.00403,3.83016,31.83946
22.93800,1.91147,621.79044,0.00311,3.86364,31.94961
23.03800,1.91978,622.85527,0.00312,3.89688,32.00432
23.13800,1.92809,625.13025,0.00317,3.93013,32.12122
23.23800,1.93640,626.98033,0.00304,3.96337,32.21628
23.33800,1.94477,628.69592,0.00316,3.99685,32.30443
23.43800,1.95308,630.85617,0.00319,4.03009,32.41543
23.53800,1.96139,631.34367,0.00329,4.06334,32.44048
23.63800,1.96976,633.95766,0.00333,4.09682,32.57479
23.73800,1.97814,635.16488,0.00350,4.13030,32.63683
23.83800,1.98645,637.01430,0.00458,4.16354,32.73186
23.93800,1.99482,639.17506,0.00637,4.19703,32.84288
24.03800,2.00325,640.85270,0.00917,4.23075,32.92908
24.13800,2.01156,641.83688,0.00228,4.26399,32.97966
24.23800,2.01987,643.48551,-0.01708,4.29723,33.06437
24.33800,2.02818,645.65362,-0.02247,4.33048,33.17577
24.43800,2.03649,646.94113,-0.02262,4.36372,33.24193
24.53800,2.04486,648.25555,-0.02363,4.39720,33.30947
24.63800,2.05317,650.27094,-0.02647,4.43044,33.41302
24.73800,2.06148,651.80995,-0.03085,4.46369,33.49210
24.83800,2.06985,653.74705,-0.03558,4.49717,33.59164
24.93800,2.07822,654.63623,-0.04339,4.53065,33.63733
25.03800,2.08659,656.41692,-0.14190,4.56413,33.72882
25.13800,2.09490,657.66047,-0.13906,4.59738,33.79272
25.23800,2.10321,659.29866,-0.13908,4.63062,33.87690
25.33800,2.11159,660.56647,-0.13908,4.66410,33.94204
25.43800,2.11984,662.26241,-0.13908,4.69710,34.02919
25.53800,2.12821,663.65679,-0.13908,4.73059,34.10083
25.63800,2.13646,664.95351,-0.13908,4.76359,34.16747
25.73800,2.14483,666.20843,-0.13909,4.79707,34.23195
25.83800,2.15314,668.15275,-0.13908,4.83032,34.33185
25.93800,2.16151,670.04994,-0.13909,4.86380,34.42934
26.03800,2.16988,670.74024,-0.13909,4.89728,34.46481
26.13800,2.17813,672.20214,-0.13909,4.93028,34.53992
26.23800,2.18650,673.17002,-0.13909,4.96377,34.58965
26.33800,2.19487,674.71783,-0.13910,4.99725,34.66919
26.43800,2.20312,675.59164,-0.13909,5.03025,34.71408
26.53800,2.21149,676.92772,-0.13909,5.06373,34.78274
26.63800,2.21980,678.30542,-0.13909,5.09698,34.85353
26.73800,2.22812,680.03740,-0.13909,5.13022,34.94252
26.83800,2.23649,680.76369,-0.13910,5.16370,34.97984
26.93800,2.24486,681.67313,-0.13909,5.19718,35.02657
27.03800,2.25317,682.93447,-0.13909,5.23043,35.09138
27.13800,2.26148,684.65611,-0.13909,5.26367,35.17985
27.23800,2.26985,685.35800,-0.13909,5.29715,35.21591
27.33800,2.27822,686.57268,-0.13910,5.33063,35.27833
27.43800,2.28653,687.82750,-0.13909,5.36388,35.34280
27.53800,2.29490,688.74615,-0.13910,5.39736,35.39001
27.63800,2.30315,689.94369,-0.13910,5.43036,35.45154
27.73800,2.31152,690.69639,-0.13909,5.46385,35.49022
27.83800,2.31983,691.63786,-0.13910,5.49709,35.53859
27.93800,2.32814,692.90847,-0.13910,5.53033,35.60388
28.03800,2.33657,693.87890,-0.13910,5.56405,35.65374
28.13800,2.34476,695.10303,-0.13910,5.59682,35.71664
28.23800,2.35314,695.87552,-0.13910,5.63030,35.75634
28.33800,2.36163,696.36162,-0.13910,5.66426,35.78131
28.43800,2.36988,697.41816,-0.13910,5.69726,35.83560
28.53800,2.37819,698.16201,-0.13910,5.73051,35.87383
28.63800,2.38650,698.67535,-0.13910,5.76375,35.90020
28.73800,2.39475,699.75103,-0.13910,5.79675,35.95547
28.83800,2.40312,700.75993,-0.13910,5.83024,36.00731
28.93800,2.41143,701.41917,-0.13910,5.86348,36.04119
29.03800,2.41980,702.01783,-0.13910,5.89696,36.07195
29.13800,2.42811,703.00843,-0.13910,5.93020,36.12285
29.23800,2.43648,703.63237,-0.13910,5.96369,36.15491
29.33800,2.44479,704.78967,-0.13910,5.99693,36.21437
29.43800,2.45310,704.58236,-0.13910,6.03017,36.20372
29.53800,2.46147,705.08495,-0.13910,6.06365,36.22955
29.63800,2.46984,706.41129,-0.13910,6.09714,36.29770
29.73800,2.47815,707.09991,-0.13910,6.13038,36.33308
29.83800,2.48647,706.91458,-0.13910,6.16362,36.32356
29.93800,2.49478,708.16302,-0.13910,6.19686,36.38771
30.03800,2.50315,708.66942,-0.13910,6.23035,36.41373
30.13800,2.51146,709.17071,-0.13910,6.26359,36.43949
30.23800,2.51983,709.10631,-0.13910,6.29707,36.43618
30.33800,2.52820,709.70561,-0.13911,6.33055,36.46697
30.43800,2.53651,710.37104,-0.13910,6.36380,36.50116
30.53800,2.54488,711.32290,-0.13910,6.39728,36.55007
30.63800,2.55313,711.46376,-0.13910,6.43028,36.55731
30.73800,2.56144,711.77236,-0.13910,6.46352,36.57317
30.83800,2.56981,711.98251,-0.13910,6.49701,36.58397
30.93800,2.57806,712.71244,-0.13910,6.53001,36.62147
31.03800,2.58649,712.41553,-0.13911,6.56373,36.60622
31.13800,2.59480,712.48715,-0.13910,6.59698,36.60990
31.23800,2.60317,713.36846,-0.13910,6.63046,36.65518
31.33800,2.61155,713.16613,-0.13910,6.66394,36.64478
31.43800,2.61986,713.72730,-0.13910,6.69718,36.67362
31.53800,2.62823,713.59263,-0.13910,6.73066,36.66670
31.63800,2.63654,714.46081,-0.13910,6.76391,36.71131
31.73800,2.64485,714.10802,-0.13910,6.79715,36.69318
31.83800,2.65316,714.09824,-0.13910,6.83039,36.69268
31.93800,2.66147,714.36870,-0.13911,6.86364,36.70658
32.03800,2.66978,714.87650,-0.13911,6.89688,36.73267
32.13800,2.67815,714.88377,-0.13910,6.93036,36.73304
32.23800,2.68646,714.47189,-0.13910,6.96360,36.71188
32.33800,2.69483,714.72474,-0.13911,6.99709,36.72487
32.43800,2.70320,714.74784,-0.13911,7.03057,36.72606
32.53800,2.71157,714.63520,-0.13911,7.06405,36.72027
32.63800,2.71988,714.80521,-0.13910,7.09729,36.72900
32.73800,2.72819,714.75552,-0.13911,7.13054,36.72645
32.83800,2.73651,714.53075,-0.13911,7.16378,36.71490
32.93800,2.74488,714.59729,-0.13910,7.19726,36.71832
33.03800,2.75319,714.00423,-0.13911,7.23051,36.68785
33.13800,2.76150,714.65718,-0.13911,7.26375,36.72140
33.23800,2.76987,714.10271,-0.13911,7.29723,36.69291
33.33800,2.77812,714.00614,-0.13911,7.33023,36.68795
33.43800,2.78643,714.26197,-0.13910,7.36348,36.70109
33.53800,2.79492,713.45628,-0.13911,7.39744,36.65969
33.63800,2.80317,713.44203,-0.13911,7.43044,36.65896
33.73800,2.81154,713.66988,-0.13911,7.46392,36.67067
33.83800,2.81991,712.91146,-0.13911,7.49740,36.63170
33.93800,2.82816,712.45190,-0.13911,7.53041,36.60809
34.03800,2.83647,712.84547,-0.13911,7.56365,36.62831
34.13800,2.84484,712.54335,-0.13911,7.59713,36.61279
34.23800,2.85303,712.96841,-0.13911,7.62990,36.63462
34.33800,2.86141,711.93813,-0.13911,7.66338,36.58168
34.43800,2.86984,711.99322,-0.13911,7.69710,36.58451
34.53800,2.87815,711.54176,-0.13911,7.73034,36.56132
34.63800,2.88646,711.24630,-0.13911,7.76359,36.54614
34.73800,2.89489,710.52308,-0.13911,7.79731,36.50898
34.83800,2.90320,709.65099,-0.13911,7.83055,36.46416
34.93800,2.91163,709.83963,-0.13911,7.86427,36.47386
35.03800,2.91982,709.37569,-0.13911,7.89704,36.45002
35.13800,2.92807,709.24368,-0.13911,7.93004,36.44324
35.23800,2.93656,709.39604,-0.13911,7.96400,36.45107
35.33800,2.94481,707.89489,-0.13911,7.99701,36.37393
35.43800,2.95318,708.12204,-0.13911,8.03049,36.38560
35.53800,2.96161,707.77913,-0.13911,8.06421,36.36798
35.63800,2.96980,706.81307,-0.13911,8.09697,36.31834
35.73800,2.97817,706.97833,-0.13911,8.13046,36.32684
35.83800,2.98660,705.40202,-0.13911,8.16418,36.24584
35.93800,2.99480,705.33399,-0.13911,8.19694,36.24234
36.03800,3.00311,704.47465,-0.13911,8.23019,36.19819
36.13800,3.01148,704.31875,-0.13911,8.26367,36.19018
36.23800,3.01973,703.89574,-0.13911,8.29667,36.16844
36.33800,3.02810,703.50310,-0.13911,8.33015,36.14827
36.43800,3.03653,702.49699,-0.13911,8.36388,36.09657
36.53800,3.04472,702.31706,-0.13911,8.39664,36.08732
36.63800,3.05315,701.66360,-0.13911,8.43036,36.05375
36.73800,3.06146,701.09982,-0.13911,8.46360,36.02478
36.83800,3.06977,700.20342,-0.13911,8.49685,35.97872
36.93800,3.07814,699.47210,-0.13911,8.53033,35.94114
37.03800,3.08645,698.87461,-0.13911,8.56357,35.91044
37.13800,3.09476,698.38800,-0.13911,8.59682,35.88544
37.23800,3.10319,697.59614,-0.13911,8.63054,35.84475
37.33800,3.11145,696.76763,-0.13911,8.66354,35.80218
37.43800,3.11982,696.52102,-0.13911,8.69702,35.78951
37.53800,3.12819,695.86043,-0.13911,8.73050,35.75556
37.63800,3.13644,695.34616,-0.13911,8.76351,35.72914
37.73800,3.14475,694.20240,-0.13911,8.79675,35.67036
37.83800,3.15318,692.71983,-0.13911,8.83047,35.59419
37.93800,3.16149,692.44429,-0.13911,8.86371,35.58003
38.03800,3.16986,691.74608,-0.13911,8.89720,35.54415
38.13800,3.17823,690.91101,-0.13911,8.93068,35.50124
38.23800,3.18654,690.39329,-0.13911,8.96392,35.47464
38.33800,3.19485,689.42099,-0.13912,8.99716,35.42468
38.43800,3.20322,688.46489,-0.13911,9.03065,35.37555
38.53800,3.21147,687.43029,-0.13911,9.06365,35.32239
38.63800,3.21978,686.42115,-0.13911,9.09689,35.27054
38.73800,3.22815,685.66618,-0.13911,9.13038,35.23175
38.83800,3.23646,684.63958,-0.13912,9.16362,35.17900
38.93800,3.24490,683.78071,-0.13911,9.19734,35.13486
39.03800,3.25321,682.48897,-0.13911,9.23058,35.06849
39.13800,3.26152,681.25464,-0.13911,9.26383,35.00507
39.23800,3.26983,679.89193,-0.13911,9.29707,34.93505
39.33800,3.27814,678.14765,-0.13912,9.33031,34.84542
39.43800,3.28645,677.19594,-0.13911,9.36355,34.79652
39.53800,3.29482,675.87458,-0.13912,9.39704,34.72862
39.63800,3.30313,673.89295,-0.13911,9.43028,34.62680
39.73800,3.31144,672.23199,-0.13911,9.46352,34.54145
39.83800,3.31987,670.59509,-0.13911,9.49724,34.45735
39.93800,3.32818,667.53067,-0.13911,9.53049,34.29988
40.03800,3.33649,665.91860,-0.13912,9.56373,34.21705
40.13800,3.34492,663.52300,-0.13911,9.59745,34.09396
40.23800,3.35317,660.30696,-0.13912,9.63046,33.92871
40.33800,3.36154,656.55392,-0.13911,9.66394,33.73587
40.43800,3.36992,652.39109,-0.13911,9.69742,33.52197
40.53800,3.37811,647.71092,-0.13911,9.73018,33.28148
40.63800,3.38648,641.29997,-0.13911,9.76367,32.95207
40.73800,3.39485,632.17254,-0.13912,9.79715,32.48307
40.83800,3.40310,619.36714,-0.13911,9.83015,31.82509
40.92400,3.41039,5.86069,-0.13911,9.85933,0.30114