File: Manufatura Aditiva/Dados/Ensaios AMR/Ensaios/Ensaios FDM/Tracao_OLABI_23_05_2018_FDM_XZ3.is_metal_RawData/Specimen_RawData_3.csv
Time,Extension,Load,Strain 1,Tensile strain,Tensile stress
(sec),(mm),(N),(mm/mm),(%),(MPa)
0.00000,0.00006,20.08850,0.00127,0.12674,0.97750
0.20000,0.01393,25.72332,0.00145,0.14531,1.25169
0.40000,0.03265,33.86839,0.00175,0.17524,1.64803
0.60000,0.04986,42.56422,0.00204,0.20361,2.07117
0.80000,0.06667,49.22669,0.00231,0.23081,2.39537
1.00000,0.08329,56.57487,0.00258,0.25754,2.75293
1.20000,0.10009,63.50648,0.00285,0.28494,3.09022
1.40000,0.11671,71.50873,0.00312,0.31235,3.47961
1.60000,0.13339,78.81143,0.00339,0.33916,3.83496
1.80000,0.14995,85.84483,0.00367,0.36697,4.17720
2.00000,0.16657,93.35423,0.00393,0.39307,4.54261
2.20000,0.18331,99.77635,0.00420,0.42033,4.85511
2.40000,0.19994,106.93063,0.00447,0.44710,5.20323
2.60000,0.21668,113.67000,0.00474,0.47402,5.53117
2.80000,0.23330,120.80413,0.00501,0.50099,5.87832
3.00000,0.24998,127.67505,0.00528,0.52759,6.21266
3.20000,0.26672,134.53937,0.00555,0.55458,6.54667
3.40000,0.28340,141.17598,0.00582,0.58151,6.86961
3.60000,0.30002,148.88457,0.00609,0.60851,7.24471
3.80000,0.31670,156.01050,0.00635,0.63488,7.59146
4.00000,0.33333,163.46679,0.00662,0.66214,7.95428
4.20000,0.35001,169.15986,0.00687,0.68699,8.23130
4.40000,0.36663,175.83052,0.00714,0.71378,8.55590
4.60000,0.38331,182.71963,0.00741,0.74086,8.89112
4.80000,0.40005,189.12476,0.00768,0.76769,9.20279
5.00000,0.41661,195.64489,0.00795,0.79467,9.52006
5.20000,0.43329,203.45584,0.00821,0.82131,9.90014
5.40000,0.45004,209.87114,0.00848,0.84812,10.21231
5.60000,0.46666,216.19978,0.00875,0.87455,10.52026
5.80000,0.48328,223.66361,0.00901,0.90114,10.88345
6.00000,0.50002,230.60362,0.00928,0.92797,11.22115
6.20000,0.51670,236.06140,0.00952,0.95207,11.48673
6.40000,0.53332,242.73365,0.00979,0.97893,11.81140
6.60000,0.54994,249.27142,0.01006,1.00583,12.12952
6.80000,0.56674,256.34090,0.01033,1.03268,12.47352
7.00000,0.58331,263.15385,0.01059,1.05911,12.80504
7.20000,0.59993,269.41889,0.01086,1.08615,13.10990
7.40000,0.61673,276.24546,0.01113,1.11264,13.44208
7.60000,0.63329,282.90616,0.01139,1.13929,13.76619
7.80000,0.64997,289.68246,0.01165,1.16541,14.09592
8.00000,0.66671,295.04027,0.01189,1.18883,14.35663
8.20000,0.68327,301.40460,0.01216,1.21577,14.66632
8.40000,0.69996,308.03690,0.01242,1.24207,14.98905
8.60000,0.71664,314.66717,0.01269,1.26891,15.31168
8.80000,0.73338,321.43905,0.01296,1.29567,15.64119
9.00000,0.75000,327.86764,0.01322,1.32199,15.95401
9.20000,0.76662,333.80587,0.01349,1.34876,16.24296
9.40000,0.78336,339.68317,0.01375,1.37533,16.52895
9.60000,0.79992,346.42392,0.01402,1.40163,16.85695
9.80000,0.81666,352.05691,0.01424,1.42403,17.13106
10.00000,0.83341,357.71851,0.01451,1.45098,17.40655
10.20000,0.84997,364.76417,0.01477,1.47716,17.74939
10.40000,0.86665,370.87738,0.01504,1.50412,18.04686
10.60000,0.88333,377.05922,0.01531,1.53124,18.34767
10.80000,0.89995,383.50881,0.01558,1.55753,18.66150
11.00000,0.91663,389.79796,0.01584,1.58389,18.96753
11.20000,0.93331,395.56576,0.01611,1.61098,19.24819
11.40000,0.95011,401.94560,0.01637,1.63749,19.55864
11.60000,0.96656,406.70102,0.01659,1.65886,19.79003
11.80000,0.98324,412.28421,0.01685,1.68483,20.06171
12.00000,1.00010,418.29022,0.01712,1.71214,20.35396
12.20000,1.01666,424.61753,0.01739,1.73875,20.66185
12.40000,1.03334,430.95546,0.01766,1.76598,20.97025
12.60000,1.05002,437.17669,0.01793,1.79267,21.27298
12.80000,1.06670,443.44510,0.01819,1.81943,21.57800
13.00000,1.08327,449.88347,0.01847,1.84675,21.89129
13.20000,1.10001,455.31509,0.01873,1.87330,22.15559
13.40000,1.11675,460.07140,0.01894,1.89358,22.38703
13.60000,1.13325,465.18100,0.01919,1.91886,22.63566
13.80000,1.14993,472.06273,0.01945,1.94521,22.97053
14.00000,1.16679,477.64191,0.01972,1.97234,23.24201
14.20000,1.18329,483.61192,0.01999,1.99900,23.53251
14.40000,1.19998,489.28340,0.02026,2.02610,23.80849
14.60000,1.21672,495.23166,0.02053,2.05340,24.09793
14.80000,1.23334,501.25243,0.02080,2.08025,24.39090
15.00000,1.24996,507.04707,0.02107,2.10709,24.67286
15.20000,1.26664,511.32729,0.02128,2.12809,24.88114
15.40000,1.28338,517.03253,0.02155,2.15454,25.15875
15.60000,1.30000,522.91262,0.02181,2.18131,25.44488
15.80000,1.31656,528.83239,0.02208,2.20818,25.73293
16.00000,1.33337,533.96565,0.02236,2.23587,25.98272
16.20000,1.34993,539.89794,0.02263,2.26288,26.27138
16.40000,1.36667,545.02045,0.02290,2.29045,26.52064
16.60000,1.38341,550.52997,0.02318,2.31757,26.78874
16.80000,1.40003,554.33530,0.02337,2.33731,26.97390
17.00000,1.41677,560.61395,0.02365,2.36450,27.27942
17.20000,1.43333,565.61241,0.02392,2.39225,27.52265
17.40000,1.45001,571.10460,0.02419,2.41921,27.78990
17.60000,1.46670,576.92025,0.02447,2.44719,28.07289
17.80000,1.48338,582.33072,0.02474,2.47433,28.33616
18.00000,1.49994,588.20196,0.02501,2.50143,28.62185
18.20000,1.51656,593.30943,0.02529,2.52927,28.87038
18.40000,1.53324,597.68013,0.02556,2.55621,29.08306
18.60000,1.55004,601.88575,0.02577,2.57653,29.28770
18.80000,1.56666,607.25901,0.02604,2.60358,29.54917
19.00000,1.58329,612.84197,0.02631,2.63149,29.82083
19.20000,1.60003,617.61504,0.02659,2.65940,30.05309
19.40000,1.61665,623.16568,0.02687,2.68736,30.32318
19.60000,1.63333,628.38020,0.02715,2.71488,30.57692
19.80000,1.65007,633.50676,0.02743,2.74305,30.82638
20.00000,1.66675,638.38614,0.02771,2.77070,31.06381
20.20000,1.68331,643.84718,0.02799,2.79856,31.32954
20.40000,1.69999,647.22248,0.02819,2.81898,31.49379
20.60000,1.71668,652.56339,0.02847,2.84679,31.75367
20.80000,1.73330,657.23499,0.02875,2.87485,31.98099
21.00000,1.74998,662.55899,0.02903,2.90322,32.24006
21.20000,1.76672,667.06575,0.02930,2.93002,32.45936
21.40000,1.78334,671.77322,0.02958,2.95815,32.68842
21.60000,1.79996,676.88539,0.02986,2.98637,32.93718
21.80000,1.81670,681.50396,0.03015,3.01476,33.16192
22.00000,1.83339,686.80015,0.03043,3.04342,33.41963
22.20000,1.85001,689.65824,0.03063,3.10991,33.55870
22.38400,1.86537,694.49069,0.03089,3.17137,33.79385
22.58400,1.88199,698.97249,0.03118,3.23786,34.01194
22.78400,1.89862,704.08131,0.03146,3.30434,34.26053
22.98400,1.91530,708.75427,0.03175,3.37107,34.48792
23.18400,1.93198,712.53222,0.03203,3.43779,34.67175
23.38400,1.94860,717.80831,0.03232,3.50428,34.92849
23.58400,1.96528,721.96350,0.03261,3.57100,35.13068
23.78400,1.98196,726.66719,0.03290,3.63773,35.35956
23.98400,1.99864,732.00339,0.03319,3.70445,35.61922
24.18400,2.01538,735.77603,0.03348,3.77142,35.80279
24.38400,2.03201,738.14811,0.03368,3.83790,35.91822
24.58400,2.04869,742.56198,0.03397,3.90463,36.13300
24.78400,2.06531,747.47787,0.03421,3.97111,36.37220
24.98400,2.08199,751.58649,0.03422,4.03784,36.57213
25.18400,2.09873,756.06978,0.03453,4.10480,36.79028
25.38400,2.11535,759.31530,0.03470,4.17129,36.94821
25.58400,2.13197,765.59372,0.02829,4.23778,37.25372
25.78400,2.14866,768.67165,0.02446,4.30450,37.40349
25.98400,2.16534,771.68164,0.00347,4.37123,37.54996
26.18400,2.18202,775.10425,0.00496,4.43795,37.71650
26.38400,2.19864,779.41557,0.00454,4.50444,37.92629
26.58400,2.21532,782.17825,0.00258,4.57116,38.06072
26.78400,2.23200,786.08198,0.00150,4.63789,38.25068
26.98400,2.24862,789.71433,0.00261,4.70437,38.42743
27.18400,2.26542,793.80441,0.00300,4.77158,38.62645
27.38400,2.28199,797.43611,0.00281,4.83782,38.80317
27.58400,2.29867,801.21793,0.00276,4.90455,38.98719
27.78400,2.31541,804.66848,0.00268,4.97151,39.15509
27.98400,2.33203,808.56429,0.00287,5.03800,39.34466
28.18400,2.34865,812.28334,0.00113,5.10448,39.52563
28.38400,2.36539,815.41641,-0.01576,5.17145,39.67809
28.58400,2.38201,819.37984,-0.14481,5.23793,39.87094
28.78400,2.39863,820.33249,-0.14173,5.30442,39.91730
28.98400,2.41526,823.90700,-0.14172,5.37091,40.09124
29.18400,2.43200,827.55769,-0.14173,5.43787,40.26888
29.38400,2.44862,831.38393,-0.14173,5.50436,40.45506
29.58400,2.46530,834.73707,-0.14173,5.57108,40.61823
29.78400,2.48204,838.40210,-0.14173,5.63805,40.79657
29.98400,2.49860,841.54252,-0.14173,5.70429,40.94938
30.18400,2.51534,844.94529,-0.14173,5.77126,41.11496
30.38400,2.53203,847.37055,-0.14173,5.83798,41.23297
30.58400,2.54871,850.35395,-0.14173,5.90471,41.37814
30.78400,2.56539,853.41102,-0.14173,5.97143,41.52690
30.98400,2.58195,856.54892,-0.14174,6.03768,41.67959
31.18400,2.59863,859.06507,-0.14174,6.10440,41.80202
31.38400,2.61537,859.98643,-0.14174,6.17137,41.84686
31.58400,2.63199,862.85220,-0.14174,6.23785,41.98631
31.78400,2.64867,865.62838,-0.14174,6.30458,42.12140
31.98400,2.66524,868.08037,-0.14174,6.37082,42.24071
32.18400,2.68198,871.35127,-0.14174,6.43779,42.39987
32.38400,2.69872,873.27762,-0.14174,6.50475,42.49361
32.58400,2.71540,876.20700,-0.14174,6.57148,42.63615
32.78400,2.73208,878.88921,-0.14174,6.63820,42.76667
32.98400,2.74864,880.74841,-0.14174,6.70445,42.85714
33.18400,2.76538,883.61930,-0.14174,6.77141,42.99683
33.38400,2.78189,886.20316,-0.14174,6.83742,43.12256
33.58400,2.79869,888.40416,-0.14174,6.90463,43.22966
33.78400,2.81549,889.26116,-0.14175,6.97183,43.27137
33.98400,2.83193,891.63426,-0.14174,7.03760,43.38684
34.18400,2.84861,893.64490,-0.14174,7.10432,43.48468
34.38400,2.86535,895.68291,-0.14174,7.17129,43.58385
34.58400,2.88197,897.32027,-0.14175,7.23777,43.66352
34.78400,2.89865,896.58340,-0.14175,7.30450,43.62766
34.98400,2.91546,898.87055,-0.14175,7.37170,43.73896
35.18400,2.93202,900.36839,-0.14175,7.43795,43.81184
35.38400,2.94864,902.49237,-0.14175,7.50443,43.91520
35.58400,2.96538,904.12572,-0.14175,7.57140,43.99467
35.78400,2.98212,905.79167,-0.14175,7.63836,44.07574
35.98400,2.99862,906.71303,-0.14175,7.70437,44.12057
36.18400,3.01518,908.19513,-0.14174,7.77062,44.19269
36.38400,3.03198,909.00306,-0.14175,7.83782,44.23200
36.58400,3.04861,910.63967,-0.14175,7.90431,44.31164
36.78400,3.06529,911.37616,-0.14175,7.97103,44.34748
36.98400,3.08197,912.50930,-0.14175,8.03776,44.40262
37.18400,3.09865,912.78683,-0.14175,8.10448,44.41612
37.38400,3.11527,914.06489,-0.14175,8.17097,44.47831
37.58400,3.13195,914.53781,-0.14175,8.23769,44.50132
37.78400,3.14869,915.52790,-0.14175,8.30466,44.54950
37.98400,3.16538,915.97755,-0.14175,8.37138,44.57138
38.18400,3.18206,916.77895,-0.14175,8.43811,44.61038
38.38400,3.19874,917.10435,-0.14175,8.50483,44.62621
38.58400,3.21530,917.48396,-0.14175,8.57108,44.64468
38.78400,3.23198,917.73607,-0.14175,8.63780,44.65695
38.98400,3.24872,917.51739,-0.14175,8.70477,44.64631
39.18400,3.26534,918.00755,-0.14175,8.77125,44.67016
39.38400,3.28196,918.29067,-0.14175,8.83774,44.68394
39.58400,3.29865,917.53965,-0.14175,8.90446,44.64739
39.78400,3.31533,917.41569,-0.14175,8.97119,44.64136
39.98400,3.33195,917.58482,-0.14175,9.03767,44.64959
40.18400,3.34869,917.49830,-0.14175,9.10464,44.64538
40.38400,3.36537,917.29816,-0.14175,9.17137,44.63564
40.58400,3.38193,916.59408,-0.14175,9.23761,44.60138
40.78400,3.39861,916.37103,-0.14175,9.30434,44.59053
40.98400,3.41547,915.65531,-0.14175,9.37178,44.55570
41.18400,3.43204,915.29852,-0.14175,9.43803,44.53834
41.38400,3.44860,914.90392,-0.14175,9.50427,44.51914
41.58400,3.46534,914.18847,-0.14175,9.57124,44.48433
41.78400,3.48196,913.10060,-0.14175,9.63772,44.43139
41.98400,3.49858,912.66073,-0.14175,9.70421,44.40998
42.18400,3.51538,911.52508,-0.14175,9.77141,44.35472
42.38400,3.53206,911.14771,-0.14175,9.83814,44.33636
42.58400,3.54857,909.80111,-0.14175,9.90414,44.27084
42.78400,3.56531,908.49884,-0.14176,9.97111,44.20747
42.98400,3.58211,907.89543,-0.14176,10.03831,44.17811
43.18400,3.59861,907.27443,-0.14175,10.10432,44.14789
43.38400,3.61523,905.69817,-0.14175,10.17081,44.07119
43.58400,3.63209,905.09700,-0.14175,10.23825,44.04193
43.78400,3.64865,903.18741,-0.14175,10.30450,43.94902
43.98400,3.66528,902.33404,-0.14175,10.37098,43.90749
44.18400,3.68208,900.70013,-0.14175,10.43819,43.82798
44.38400,3.69870,900.42129,-0.14175,10.50467,43.81441
44.58400,3.71532,898.04167,-0.14176,10.57116,43.69862
44.78400,3.73194,897.63878,-0.14175,10.63764,43.67902
44.98400,3.74868,895.60673,-0.14175,10.70461,43.58014
45.18400,3.76530,894.63899,-0.14175,10.77109,43.53305
45.38400,3.78192,893.47092,-0.14175,10.83758,43.47621
45.58400,3.79873,891.99822,-0.14175,10.90478,43.40455
45.78400,3.81529,890.46480,-0.14175,10.97103,43.32993
45.98400,3.83197,888.81208,-0.14175,11.03775,43.24951
46.18400,3.84865,887.84164,-0.14175,11.10448,43.20229
46.38400,3.86533,886.15585,-0.14175,11.17120,43.12026
46.58400,3.88201,884.71333,-0.14175,11.23793,43.05007
46.78400,3.89863,883.62982,-0.14175,11.30442,42.99734
46.98400,3.91537,883.27350,-0.14175,11.37138,42.98001
47.18400,3.93194,880.97528,-0.14176,11.43763,42.86818
47.38400,3.94862,880.23487,-0.14175,11.50435,42.83215
47.58400,3.96536,879.26593,-0.14176,11.57132,42.78500
47.78400,3.98198,877.97921,-0.14175,11.63780,42.72239
47.98400,3.99860,875.87573,-0.14176,11.70429,42.62003
48.18400,4.01534,875.52769,-0.14175,11.77125,42.60310
48.38400,4.03196,873.83967,-0.14176,11.83774,42.52096
48.58400,4.04871,872.85172,-0.14176,11.90470,42.47288
48.78400,4.06539,871.33050,-0.14176,11.97143,42.39886
48.98400,4.08207,870.60574,-0.14176,12.03815,42.36359
49.18400,4.09863,868.68471,-0.14175,12.10440,42.27011
49.38400,4.11531,868.24745,-0.14175,12.17112,42.24884
49.58400,4.13205,866.32594,-0.14176,12.23809,42.15534
49.78400,4.14867,865.46000,-0.14175,12.30457,42.11320
49.98400,4.16529,864.71774,-0.14175,12.37106,42.07708
50.18400,4.18204,863.15963,-0.14176,12.43802,42.00127
50.38400,4.19866,862.16638,-0.14175,12.50451,41.95293
50.58400,4.21534,861.26672,-0.14176,12.57123,41.90916
50.78400,4.23202,860.09046,-0.14175,12.63796,41.85192
50.98400,4.24876,858.71220,-0.14175,12.70492,41.78485
51.18400,4.26532,857.52169,-0.14175,12.77117,41.72692
51.38400,4.28200,856.47339,-0.14175,12.83790,41.67591
51.58400,4.29874,855.51506,-0.14175,12.90486,41.62928
51.78400,4.31537,854.75007,-0.14175,12.97134,41.59206
51.98400,4.33199,853.99663,-0.14175,13.03783,41.55540
52.18400,4.34861,852.40938,-0.14176,13.10432,41.47816
52.38400,4.36529,851.62930,-0.14176,13.17104,41.44020
52.58400,4.38197,850.74101,-0.14176,13.23777,41.39698
52.78400,4.39859,849.90300,-0.14176,13.30425,41.35620
52.98400,4.41533,849.06742,-0.14176,13.37122,41.31554
53.18400,4.43208,847.69325,-0.14176,13.43818,41.24867
53.38400,4.44864,846.27680,-0.14176,13.50443,41.17975
53.58400,4.46538,846.34721,-0.14176,13.57139,41.18317
53.78400,4.48200,844.79218,-0.14175,13.63788,41.10751
53.98400,4.49868,843.38207,-0.14175,13.70461,41.03889
54.18400,4.51542,843.17559,-0.14176,13.77157,41.02885
54.38400,4.53204,841.88366,-0.14175,13.83805,40.96598
54.58400,4.54861,840.99062,-0.14176,13.90430,40.92252
54.78400,4.56529,840.15019,-0.14176,13.97103,40.88163
54.98400,4.58197,838.76504,-0.14175,14.03775,40.81423
55.18400,4.59871,838.06608,-0.14175,14.10471,40.78022
55.38400,4.61533,837.46463,-0.14175,14.17120,40.75095
55.58400,4.63201,836.06364,-0.14175,14.23793,40.68278
55.78400,4.64869,835.79086,-0.14175,14.30465,40.66951
55.98400,4.66537,834.74275,-0.14175,14.37138,40.61850
56.18400,4.68206,833.64900,-0.14176,14.43810,40.56528
56.38400,4.69868,833.08555,-0.14175,14.50459,40.53786
56.58400,4.71536,831.83842,-0.14176,14.57131,40.47718
56.78400,4.73198,830.68479,-0.14175,14.63780,40.42104
56.98400,4.74860,830.02588,-0.14175,14.70429,40.38898
57.18400,4.76534,829.04855,-0.14176,14.77125,40.34142
57.38400,4.78196,828.29595,-0.14175,14.83773,40.30480
57.58400,4.79870,827.21142,-0.14176,14.90470,40.25203
57.78400,4.81527,826.84811,-0.14176,14.97094,40.23435
57.98400,4.83195,825.70985,-0.14175,15.03767,40.17896
58.18400,4.84869,825.22528,-0.14175,15.10464,40.15538
58.38400,4.86537,823.69698,-0.14175,15.17136,40.08102
58.58400,4.88199,823.14489,-0.14176,15.23785,40.05415
58.78400,4.89861,822.56505,-0.14176,15.30433,40.02594
58.98400,4.91529,821.71774,-0.14176,15.37106,39.98471
59.18400,4.93192,819.82696,-0.14176,15.43754,39.89270
59.38400,4.94872,819.86645,-0.14176,15.50475,39.89462
59.58400,4.96534,819.49178,-0.14176,15.57123,39.87639
59.78400,4.98196,817.91105,-0.14176,15.63772,39.79948
59.98400,4.99864,817.23565,-0.14175,15.70444,39.76661
60.18400,5.01532,816.09040,-0.14176,15.77117,39.71088
60.38400,5.03200,814.98073,-0.14175,15.83789,39.65689
60.58400,5.04868,814.15642,-0.14176,15.90462,39.61678
60.78400,5.06531,813.61337,-0.14175,15.97110,39.59035
60.98400,5.08199,812.74202,-0.14176,16.03783,39.54795
61.18400,5.09867,811.75203,-0.14176,16.10455,39.49978
61.38400,5.11535,810.93702,-0.14176,16.17128,39.46012
61.58400,5.13203,809.99238,-0.14176,16.23800,39.41415
61.78400,5.14871,809.46041,-0.14175,16.30473,39.38827
61.98400,5.16533,808.43968,-0.14175,16.37122,39.33860
62.18400,5.18196,807.31530,-0.14175,16.43770,39.28389
62.38400,5.19864,806.25070,-0.14175,16.50442,39.23208
62.58400,5.21532,805.48478,-0.14175,16.57115,39.19481
62.78400,5.23206,804.10205,-0.14175,16.63812,39.12753
62.98400,5.24862,803.98340,-0.14175,16.70436,39.12176
63.18400,5.26524,802.71065,-0.14175,16.77085,39.05983
63.38400,5.28198,801.53877,-0.14176,16.83781,39.00280
63.58400,5.29866,799.92404,-0.14176,16.90454,38.92423
63.78400,5.31535,799.71375,-0.14176,16.97126,38.91400
63.98400,5.33203,798.72748,-0.14175,17.03799,38.86600
64.18400,5.34865,797.18083,-0.14176,17.10447,38.79074
64.38400,5.36533,796.44267,-0.14176,17.17120,38.75483
64.58400,5.38201,795.71763,-0.14175,17.23792,38.71954
64.78400,5.39875,794.96447,-0.14176,17.30489,38.68290
64.98400,5.41537,793.48022,-0.14175,17.37137,38.61067
65.18400,5.43193,792.05073,-0.14175,17.43762,38.54111
65.38400,5.44868,790.62153,-0.14175,17.50458,38.47157
65.58400,5.46530,789.34077,-0.14176,17.57107,38.40925
65.78401,5.48204,788.81290,-0.14175,17.63804,38.38356
65.98400,5.49866,788.01988,-0.14176,17.70452,38.34497
66.18401,5.51528,787.09954,-0.14175,17.77101,38.30019
66.38400,5.53196,784.79918,-0.14176,17.83773,38.18826
66.58400,5.54864,783.87251,-0.14175,17.90446,38.14316
66.78401,5.56539,782.74552,-0.14175,17.97142,38.08832
66.98400,5.58207,781.30271,-0.14175,18.03815,38.01812
67.18401,5.59863,779.99472,-0.14176,18.10439,37.95447
67.38400,5.61531,778.52802,-0.14175,18.17112,37.88310
67.58400,5.63193,777.22380,-0.14176,18.23761,37.81964
67.78401,5.64867,775.97024,-0.14175,18.30457,37.75864
67.98400,5.66541,774.07346,-0.14175,18.37153,37.66634
68.18401,5.68197,773.01110,-0.14176,18.43778,37.61465
68.38400,5.69860,771.05495,-0.14175,18.50426,37.51946
68.58400,5.71528,769.59725,-0.14176,18.57099,37.44853
68.78401,5.73202,768.40804,-0.14175,18.63796,37.39066
68.98400,5.74870,766.93157,-0.14175,18.70468,37.31882
69.18401,5.76532,764.79358,-0.14176,18.77116,37.21478
69.38400,5.78200,763.10304,-0.14176,18.83789,37.13252
69.58400,5.79862,762.02000,-0.14176,18.90438,37.07982
69.78401,5.81537,759.95568,-0.14176,18.97134,36.97937
69.98400,5.83211,758.27981,-0.14175,19.03830,36.89782
70.18401,5.84867,756.56478,-0.14175,19.10455,36.81437
70.38400,5.86529,754.40472,-0.14175,19.17104,36.70926
70.58400,5.88197,752.70217,-0.14176,19.23776,36.62642
70.78401,5.89865,751.05331,-0.14175,19.30449,36.54618
70.98400,5.91527,749.70722,-0.14175,19.37097,36.48068
71.18401,5.93201,747.14692,-0.14175,19.43794,36.35610
71.38400,5.94876,744.92488,-0.14175,19.50490,36.24797
71.58400,5.96526,743.38061,-0.14176,19.57091,36.17283
71.78401,5.98194,740.64583,-0.14176,19.63763,36.03976
71.98400,5.99874,739.66682,-0.14176,19.70484,35.99212
72.18401,6.01536,736.44109,-0.14176,19.77133,35.83516
72.38400,6.03198,734.30375,-0.14175,19.83781,35.73115
72.58400,6.04866,732.72400,-0.14175,19.90453,35.65428
72.78401,6.06534,731.20366,-0.14175,19.97126,35.58030
72.98400,6.08191,729.13156,-0.14176,20.03751,35.47947
73.18401,6.09865,726.41685,-0.14175,20.10447,35.34737
73.38400,6.11539,724.22787,-0.14175,20.17144,35.24086
73.58401,6.13189,721.69374,-0.14176,20.23744,35.11755
73.78401,6.14857,719.80087,-0.14175,20.30417,35.02544
73.98400,6.16531,717.77767,-0.14175,20.37113,34.92699
74.18401,6.18193,715.82603,-0.14176,20.43762,34.83203
74.38400,6.19874,713.08333,-0.14176,20.50482,34.69857
74.58401,6.21536,711.87476,-0.14175,20.57131,34.63976
74.78401,6.23198,708.68842,-0.14176,20.63779,34.48471
74.98400,6.24860,706.88757,-0.14175,20.70428,34.39708
75.18401,6.26534,704.22119,-0.14175,20.77124,34.26734
75.38400,6.28202,703.10766,-0.14175,20.83797,34.21315
75.58401,6.29864,700.38489,-0.14175,20.90445,34.08066
75.78401,6.31527,698.27200,-0.14175,20.97094,33.97785
75.98400,6.33201,696.60563,-0.14175,21.03791,33.89676
76.18401,6.34863,694.32389,-0.14175,21.10439,33.78574
76.38400,6.36525,692.03721,-0.14175,21.17088,33.67447
76.58401,6.38211,691.18924,-0.14175,21.23832,33.63321
76.78401,6.39867,688.65377,-0.14175,21.30457,33.50983
76.98400,6.41529,686.78940,-0.14175,21.37105,33.41911
77.18401,6.43209,684.44726,-0.14176,21.43825,33.30514
77.38400,6.44871,683.10834,-0.14175,21.50474,33.23999
77.58401,6.46528,680.77669,-0.14176,21.57099,33.12653
77.78401,6.48202,679.40773,-0.14175,21.63795,33.05992
77.98400,6.49876,677.85443,-0.14175,21.70492,32.98433
78.18401,6.51526,676.54462,-0.14175,21.77092,32.92060
78.38400,6.53200,675.59676,-0.14175,21.83789,32.87447
78.58401,6.54880,673.02044,-0.14176,21.90509,32.74911
78.78401,6.56530,672.40549,-0.14176,21.97110,32.71919
78.98400,6.58187,670.73004,-0.14175,22.03735,32.63766
79.18401,6.59867,669.45991,-0.14175,22.10455,32.57586
79.38400,6.61535,668.57366,-0.14175,22.17127,32.53273
79.58401,6.63191,666.79907,-0.14176,22.23752,32.44638
79.78401,6.64871,665.48418,-0.14175,22.30473,32.38240
79.98400,6.66527,664.90970,-0.14175,22.37097,32.35444
80.18401,6.68195,663.61395,-0.14175,22.43769,32.29139
80.38400,6.69864,661.83689,-0.14176,22.50442,32.20492
80.58401,6.71538,660.86869,-0.14175,22.57138,32.15781
80.78401,6.73200,660.33215,-0.14175,22.63787,32.13170
80.98400,6.74868,659.17452,-0.14175,22.70460,32.07537
81.18401,6.76530,658.30741,-0.14175,22.77108,32.03318
81.38400,6.78198,657.60640,-0.14175,22.83781,31.99907
81.58401,6.79860,656.24439,-0.14175,22.90429,31.93279
81.78401,6.81528,655.46636,-0.14175,22.97102,31.89493
81.98400,6.83203,654.41588,-0.14175,23.03798,31.84381
82.18401,6.84865,654.16032,-0.14175,23.10447,31.83138
82.38400,6.86533,653.33736,-0.14175,23.17119,31.79133
82.58401,6.88201,652.36385,-0.14176,23.23792,31.74396
82.78401,6.89869,651.98699,-0.14176,23.30464,31.72563
82.98400,6.91537,651.38848,-0.14176,23.37137,31.69650
83.18401,6.93205,650.97404,-0.14175,23.43809,31.67634
83.38400,6.94862,649.98874,-0.14175,23.50434,31.62839
83.58401,6.96530,649.63759,-0.14175,23.57107,31.61130
83.78401,6.98198,649.34790,-0.14175,23.63779,31.59721
83.98400,6.99866,648.59828,-0.14175,23.70452,31.56073
84.18401,7.01534,648.24810,-0.14175,23.77124,31.54369
84.38400,7.03196,647.94687,-0.14176,23.83773,31.52903
84.58401,7.04870,647.66244,-0.14175,23.90469,31.51519
84.78401,7.06526,647.18029,-0.14175,23.97094,31.49173
84.98400,7.08201,646.61163,-0.14175,24.03790,31.46406
85.18401,7.09881,645.84566,-0.14176,24.10510,31.42679
85.38400,7.11531,645.26265,-0.14175,24.17112,31.39842
85.58401,7.13193,645.33772,-0.14176,24.23760,31.40207
85.78401,7.14873,644.81231,-0.14176,24.30480,31.37651
85.98400,7.16535,644.43015,-0.14175,24.37129,31.35791
86.18401,7.18197,644.12095,-0.14175,24.43777,31.34286
86.38400,7.19865,643.29659,-0.14176,24.50450,31.30275
86.58401,7.21534,643.28713,-0.14175,24.57123,31.30229
86.78401,7.23196,643.53892,-0.14175,24.63771,31.31454
86.98400,7.24864,643.34301,-0.14175,24.70444,31.30501
87.18401,7.26538,642.52634,-0.14175,24.77140,31.26527
87.38400,7.28200,642.34249,-0.14175,24.83789,31.25632
87.58401,7.29868,641.87516,-0.14176,24.90461,31.23359
87.78401,7.31536,641.97308,-0.14176,24.97134,31.23835
87.98400,7.33199,641.83278,-0.14175,25.03782,31.23152
88.18401,7.34873,641.37313,-0.14176,25.10479,31.20916
88.38400,7.36535,641.13964,-0.14176,25.17127,31.19779
88.58401,7.38203,641.65224,-0.14175,25.23800,31.22274
88.78401,7.39865,640.62248,-0.14175,25.30448,31.17263
88.98400,7.41527,641.30039,-0.14175,25.37097,31.20562
89.18401,7.43201,641.27375,-0.14175,25.43793,31.20432
89.38400,7.44869,641.50817,-0.14175,25.50466,31.21573
89.58401,7.46532,641.44311,-0.14175,25.57115,31.21256
89.78401,7.48200,641.57103,-0.14176,25.63787,31.21879
89.98400,7.49868,640.54159,-0.14175,25.70460,31.16869
90.18401,7.51530,640.86216,-0.14175,25.77108,31.18429
90.38400,7.53198,641.51143,-0.14175,25.83781,31.21589
90.58401,7.54872,641.27124,-0.14175,25.90477,31.20420
90.78401,7.56534,641.31808,-0.14175,25.97126,31.20648
90.98400,7.58197,641.62924,-0.14176,26.03774,31.22162
91.18401,7.59865,641.23948,-0.14175,26.10447,31.20265
91.38400,7.61527,640.92809,-0.14175,26.17095,31.18750
91.58401,7.63201,641.22495,-0.14175,26.23792,31.20195
91.78401,7.64875,640.86658,-0.14175,26.30488,31.18451
91.98400,7.66525,641.37974,-0.14176,26.37089,31.20948
92.18401,7.68193,641.41764,-0.14175,26.43761,31.21132
92.38400,7.69867,640.98663,-0.14175,26.50458,31.19035
92.58401,7.71542,641.44470,-0.14175,26.57154,31.21264
92.78401,7.73204,641.74025,-0.14175,26.63803,31.22702
92.98400,7.74866,640.97801,-0.14175,26.70451,31.18993
93.18401,7.76534,641.63096,-0.14175,26.77124,31.22170
93.38400,7.78202,641.50169,-0.14176,26.83796,31.21541
93.58401,7.79864,640.91040,-0.14175,26.90445,31.18664
93.78401,7.81538,641.36069,-0.14176,26.97141,31.20855
93.98400,7.83200,642.02435,-0.14175,27.03790,31.24084
94.18401,7.84869,641.05280,-0.14175,27.10462,31.19357
94.38400,7.86531,641.28581,-0.14175,27.17111,31.20491
94.58401,7.88199,641.48717,-0.14175,27.23784,31.21470
94.78401,7.89867,641.53695,-0.14176,27.30456,31.21713
94.98400,7.91529,642.14277,-0.14175,27.37105,31.24661
95.18401,7.93197,641.80638,-0.14175,27.43777,31.23024
95.38400,7.94859,641.66812,-0.14175,27.50426,31.22351
95.58401,7.96533,641.64624,-0.14176,27.57122,31.22245
95.78401,7.98202,642.31413,-0.14175,27.63795,31.25495
95.98400,7.99870,641.87809,-0.14175,27.70467,31.23373
96.18401,8.01538,642.01960,-0.14175,27.77140,31.24061
96.38400,8.03200,641.99613,-0.14175,27.83788,31.23947
96.58401,8.04868,641.96032,-0.14175,27.90461,31.23773
96.78401,8.06536,641.91716,-0.14176,27.97133,31.23563
96.98400,8.08204,641.91297,-0.14175,28.03806,31.23542
97.18401,8.09873,641.97383,-0.14175,28.10478,31.23839
97.38400,8.11529,641.65574,-0.14175,28.17103,31.22291
97.58401,8.13191,641.27119,-0.14175,28.23751,31.20420
97.78401,8.14871,642.14040,-0.14175,28.30472,31.24649
97.98400,8.16533,641.42160,-0.14176,28.37120,31.21152
98.18401,8.18201,641.68954,-0.14176,28.43793,31.22455
98.38400,8.19869,641.73583,-0.14176,28.50465,31.22680
98.58401,8.21531,641.26928,-0.14175,28.57114,31.20410
98.78401,8.23194,641.44498,-0.14176,28.63763,31.21265
98.98400,8.24874,640.88749,-0.14176,28.70483,31.18553
99.18401,8.26542,641.19631,-0.14175,28.77156,31.20055
99.38400,8.28198,640.26532,-0.14175,28.83781,31.15525
99.58401,8.29866,640.42183,-0.14175,28.90453,31.16287
99.78401,8.31540,640.03258,-0.14175,28.97149,31.14392
99.98400,8.33197,640.27412,-0.14175,29.03774,31.15568
100.18401,8.34865,639.29339,-0.14175,29.10446,31.10796
100.38400,8.36539,639.31067,-0.14175,29.17143,31.10880
100.58401,8.38201,638.80864,-0.14175,29.23791,31.08437
100.78401,8.39857,638.85651,-0.14175,29.30416,31.08670
100.98400,8.41543,638.16602,-0.14175,29.37160,31.05310
101.18401,8.43211,638.26391,-0.14175,29.43833,31.05786
101.38400,8.44867,637.64160,-0.14175,29.50458,31.02758
101.58401,8.46529,636.52573,-0.14176,29.57106,30.97328
101.78401,8.48198,636.34943,-0.14175,29.63779,30.96470
101.98400,8.49866,637.01770,-0.14176,29.70451,30.99722
102.18401,8.51528,636.14021,-0.14175,29.77100,30.95452
102.38400,8.53202,634.82272,-0.14175,29.83796,30.89041
102.58401,8.54852,634.83929,-0.14175,29.90397,30.89122
102.78401,8.56526,634.00692,-0.14175,29.97093,30.85072
102.98400,8.58200,633.01898,-0.14175,30.03790,30.80264
103.18401,8.59869,631.97939,-0.14175,30.10462,30.75206
103.38400,8.61537,631.52961,-0.14175,30.17135,30.73017
103.58401,8.63205,630.61630,-0.14175,30.23807,30.68573
103.78401,8.64867,629.76414,-0.14175,30.30456,30.64426
103.98400,8.66529,629.06728,-0.14175,30.37104,30.61036
104.18401,8.68197,627.86797,-0.14176,30.43777,30.55200
104.38400,8.69871,626.76463,-0.14175,30.50473,30.49831
104.58401,8.71527,625.07316,-0.14176,30.57098,30.41600
104.78401,8.73190,624.75139,-0.14175,30.63746,30.40034
104.98401,8.74864,623.37867,-0.14175,30.70443,30.33355
105.18401,8.76526,622.29666,-0.14175,30.77092,30.28090
105.38400,8.78200,620.94037,-0.14175,30.83788,30.21490
105.58401,8.79874,619.60649,-0.14175,30.90484,30.14999
105.78401,8.81530,618.04280,-0.14176,30.97109,30.07390
105.98401,8.83192,616.22271,-0.14175,31.03758,29.98534
106.18401,8.84867,614.60915,-0.14175,31.10454,29.90682
106.38400,8.86541,613.03754,-0.14175,31.17150,29.83035
106.58401,8.88203,610.48940,-0.14175,31.23799,29.70636
106.78401,8.89865,608.06284,-0.14175,31.30448,29.58828
106.98401,8.91539,604.92810,-0.14175,31.37144,29.43575
107.18401,8.93195,602.58363,-0.14175,31.43769,29.32166
107.38400,8.94863,598.78803,-0.14175,31.50441,29.13697
107.58401,8.96543,594.97920,-0.14175,31.57162,28.95163
107.78401,8.98200,590.03937,-0.14175,31.63787,28.71126
107.98401,8.99856,584.44408,-0.14175,31.70411,28.43899
108.18401,9.01536,574.69714,-0.14175,31.77131,27.96471
108.38400,9.03204,548.76371,-0.14175,31.83804,26.70279
108.58401,9.04872,501.34808,-0.14175,31.90476,24.39555
108.78401,9.06534,423.97585,-0.14176,31.97125,20.63062
108.98401,9.08202,332.95187,-0.14175,32.03798,16.20141
109.18401,9.09865,270.53098,-0.14176,32.10446,13.16401
109.38400,9.11533,227.68041,-0.14176,32.17118,11.07891
109.58401,9.13207,194.26537,-0.14175,32.23815,9.45293
109.76601,9.14719,8.50679,-0.14176,32.29866,0.41394