File: Manufatura Aditiva/Dados/Ensaios AMR/Ensaios/Ensaios FDM/Tracao_OLABI_23_05_2018_FDM_XZ3.is_metal_RawData/Specimen_RawData_1.csv
Time,Extension,Load,Strain 1,Tensile strain,Tensile stress
(sec),(mm),(N),(mm/mm),(%),(MPa)
0.00000,-0.00018,29.20297,0.00119,0.11892,1.41250
0.20000,0.01202,33.63092,0.00133,0.13339,1.62668
0.40000,0.03199,42.09660,0.00164,0.16415,2.03615
0.60000,0.04963,50.26085,0.00191,0.19146,2.43104
0.80000,0.06649,57.75300,0.00217,0.21741,2.79343
1.00000,0.08311,65.04318,0.00243,0.24298,3.14604
1.20000,0.09985,72.14511,0.00269,0.26870,3.48955
1.40000,0.11653,80.85217,0.00295,0.29468,3.91070
1.60000,0.13321,87.16140,0.00321,0.32062,4.21587
1.80000,0.14983,93.71422,0.00346,0.34552,4.53282
2.00000,0.16639,100.83826,0.00372,0.37163,4.87740
2.20000,0.18308,108.09061,0.00397,0.39658,5.22818
2.40000,0.19982,115.11879,0.00422,0.42199,5.56813
2.60000,0.21644,121.89966,0.00448,0.44814,5.89611
2.80000,0.23312,128.73327,0.00473,0.47323,6.22664
3.00000,0.24980,135.10769,0.00499,0.49858,6.53496
3.20000,0.26648,141.85614,0.00524,0.52356,6.86137
3.40000,0.28322,149.70165,0.00549,0.54928,7.24085
3.60000,0.29984,156.25281,0.00575,0.57462,7.55772
3.80000,0.31653,162.96125,0.00600,0.60016,7.88220
4.00000,0.33321,169.35794,0.00623,0.62344,8.19159
4.20000,0.34983,176.15369,0.00648,0.64825,8.52030
4.40000,0.36645,182.55165,0.00674,0.67355,8.82975
4.60000,0.38313,189.29192,0.00700,0.69956,9.15577
4.80000,0.39987,196.42466,0.00725,0.72519,9.50077
5.00000,0.41643,202.61402,0.00750,0.74998,9.80014
5.20000,0.43312,209.87533,0.00776,0.77559,10.15136
5.40000,0.44986,215.88586,0.00801,0.80089,10.44208
5.60000,0.46648,223.11118,0.00826,0.82643,10.79156
5.80000,0.48310,229.77556,0.00852,0.85219,11.11391
6.00000,0.49990,236.12105,0.00876,0.87557,11.42083
6.20000,0.51646,242.51970,0.00900,0.89950,11.73032
6.40000,0.53314,248.75714,0.00925,0.92522,12.03202
6.60000,0.54982,256.10111,0.00951,0.95148,12.38723
6.80000,0.56657,262.10512,0.00976,0.97646,12.67764
7.00000,0.58313,268.81511,0.01002,1.00178,13.00219
7.20000,0.59975,275.37025,0.01027,1.02686,13.31925
7.40000,0.61655,281.50880,0.01053,1.05254,13.61617
7.60000,0.63311,288.76003,0.01078,1.07756,13.96690
7.80000,0.64973,293.65141,0.01099,1.09868,14.20349
8.00000,0.66653,300.14231,0.01124,1.12448,14.51744
8.20000,0.68309,307.22220,0.01150,1.15026,14.85989
8.40000,0.69978,312.71661,0.01176,1.17601,15.12564
8.60000,0.71646,318.80038,0.01202,1.20201,15.41991
8.80000,0.73326,325.76129,0.01226,1.22640,15.75659
9.00000,0.74982,331.91715,0.01252,1.25212,16.05434
9.20000,0.76644,338.00201,0.01277,1.27706,16.34866
9.40000,0.78318,344.29997,0.01302,1.30212,16.65328
9.60000,0.79974,349.84658,0.01323,1.32349,16.92156
9.80000,0.81643,355.57430,0.01349,1.34912,17.19861
10.00000,0.83317,362.11158,0.01375,1.37477,17.51480
10.20000,0.84985,368.23831,0.01400,1.40000,17.81115
10.40000,0.86647,374.24976,0.01425,1.42527,18.10191
10.60000,0.88315,380.63268,0.01451,1.45101,18.41064
10.80000,0.89977,386.58124,0.01476,1.47595,18.69837
11.00000,0.91645,392.15698,0.01501,1.50070,18.96806
11.20000,0.93313,398.15037,0.01524,1.52403,19.25795
11.40000,0.94994,403.84904,0.01547,1.54694,19.53358
11.60000,0.96638,410.15893,0.01573,1.57277,19.83879
11.80000,0.98306,415.82175,0.01599,1.59873,20.11269
12.00000,0.99986,422.12959,0.01624,1.62435,20.41779
12.20000,1.01648,427.78174,0.01649,1.64903,20.69117
12.40000,1.03310,433.76642,0.01675,1.67509,20.98064
12.60000,1.04984,440.38421,0.01700,1.70026,21.30074
12.80000,1.06652,446.18547,0.01726,1.72619,21.58134
13.00000,1.08309,450.77302,0.01748,1.74761,21.80323
13.20000,1.09983,456.95063,0.01773,1.77328,22.10203
13.40000,1.11657,462.77004,0.01799,1.79901,22.38351
13.60000,1.13307,468.63989,0.01824,1.82430,22.66742
13.80000,1.14975,474.31309,0.01849,1.84866,22.94183
14.00000,1.16661,480.30680,0.01875,1.87474,23.23173
14.20000,1.18311,485.39969,0.01900,1.90000,23.47807
14.40000,1.19980,490.65226,0.01921,1.92070,23.73213
14.60000,1.21654,496.92448,0.01947,1.94658,24.03551
14.80000,1.23316,502.93417,0.01973,1.97293,24.32619
15.00000,1.24978,508.61789,0.01999,1.99898,24.60110
15.20000,1.26652,514.10017,0.02025,2.02484,24.86627
15.40000,1.28320,519.73690,0.02050,2.05003,25.13891
15.60000,1.29976,525.11715,0.02075,2.07522,25.39915
15.80000,1.31639,530.65498,0.02101,2.10078,25.66700
16.00000,1.33319,534.49832,0.02121,2.12148,25.85290
16.20000,1.34975,540.20756,0.02147,2.14737,26.12905
16.40000,1.36649,545.31153,0.02174,2.17360,26.37592
16.60000,1.38323,551.67228,0.02200,2.20006,26.68358
16.80000,1.39985,556.60182,0.02225,2.22494,26.92201
17.00000,1.41653,562.11832,0.02251,2.25125,27.18884
17.20000,1.43315,567.47450,0.02277,2.27688,27.44791
17.40000,1.44984,572.04189,0.02298,2.29756,27.66883
17.60000,1.46652,577.46531,0.02324,2.32380,27.93115
17.80000,1.48320,583.14530,0.02350,2.35019,28.20588
18.00000,1.49976,588.41347,0.02376,2.37619,28.46069
18.20000,1.51644,593.31120,0.02401,2.40078,28.69759
18.40000,1.53306,598.15035,0.02427,2.42658,28.93165
18.60000,1.54986,602.74666,0.02447,2.44710,29.15397
18.80000,1.56648,607.46274,0.02473,2.47285,29.38208
19.00000,1.58311,612.97957,0.02499,2.49940,29.64892
19.20000,1.59985,617.77085,0.02526,2.52603,29.88067
19.40000,1.61647,622.27855,0.02552,2.55180,30.09870
19.60000,1.63315,627.86522,0.02578,2.57773,30.36892
19.80000,1.64989,633.26326,0.02604,2.60386,30.63001
20.00000,1.66657,636.13309,0.02623,2.62266,30.76882
20.20000,1.68313,642.09998,0.02649,2.64895,31.05743
20.40000,1.69982,646.85415,0.02675,2.67540,31.28738
20.60000,1.71650,651.87770,0.02703,2.70252,31.53036
20.80000,1.73312,656.36402,0.02728,2.72819,31.74736
21.00000,1.74980,661.49649,0.02755,2.75457,31.99561
21.20000,1.76654,665.09773,0.02774,2.77388,32.16980
21.40000,1.78316,670.03458,0.02800,2.80049,32.40859
21.60000,1.79984,674.56076,0.02828,2.82756,32.62751
21.80000,1.81652,679.93454,0.02854,2.85441,32.88743
22.00000,1.83321,684.43012,0.02882,2.88160,33.10488
22.20000,1.84983,689.32073,0.02907,2.90658,33.34143
22.40000,1.86651,693.51001,0.02928,2.92827,33.54406
22.60000,1.88313,697.85244,0.02956,2.95557,33.75410
22.80000,1.89981,702.01298,0.02983,2.98316,33.95534
23.00000,1.91637,707.33768,0.03011,3.01060,34.21288
23.20000,1.93311,711.44076,0.03038,3.03770,34.41134
23.40000,1.94974,714.71352,0.03057,3.10419,34.56964
23.53000,1.96056,718.45469,0.03075,3.14748,34.75060
23.73000,1.97730,722.54934,0.03103,3.21444,34.94865
23.93000,1.99398,727.79511,0.03130,3.28117,35.20238
24.13000,2.01066,731.87728,0.03158,3.34789,35.39983
24.33000,2.02734,735.93734,0.03185,3.41462,35.59621
24.53000,2.04402,738.53037,0.03205,3.48134,35.72163
24.73000,2.06058,742.84105,0.03233,3.54759,35.93013
24.93000,2.07733,747.74935,0.03260,3.61455,36.16754
25.13000,2.09401,752.06375,0.03289,3.68128,36.37622
25.33000,2.11069,755.70140,0.03317,3.74800,36.55217
25.53000,2.12731,760.37203,0.03346,3.81449,36.77808
25.73000,2.14399,764.00163,0.03362,3.88121,36.95364
25.93000,2.16067,766.29026,0.03398,3.94794,37.06433
26.13000,2.17729,773.03294,0.01998,4.01442,37.39046
26.33000,2.19398,777.70860,0.01099,4.08115,37.61662
26.53000,2.21066,778.05440,0.00941,4.14788,37.63335
26.73000,2.22728,782.24456,0.00926,4.21436,37.83602
26.93000,2.24402,786.47695,0.00754,4.28133,38.04073
27.13000,2.26070,791.36910,0.00710,4.34805,38.27736
27.33000,2.27738,793.46625,0.00754,4.41478,38.37880
27.53000,2.29400,796.77962,0.00903,4.48126,38.53906
27.73000,2.31068,800.59543,0.01937,4.54799,38.72363
27.93000,2.32737,804.22340,-0.02122,4.61471,38.89911
28.13000,2.34393,808.60369,-0.10830,4.68096,39.11097
28.33000,2.36073,812.03673,-0.13373,4.74816,39.27702
28.53000,2.37735,816.03872,-0.13381,4.81465,39.47059
28.73000,2.39391,819.46366,-0.13384,4.88089,39.63625
28.93000,2.41065,822.03820,-0.13386,4.94786,39.76078
29.13000,2.42727,824.95948,-0.13384,5.01434,39.90208
29.33000,2.44390,829.24571,-0.13384,5.08083,40.10939
29.53000,2.46064,831.98333,-0.13384,5.14779,40.24181
29.73000,2.47732,834.87546,-0.13384,5.21452,40.38170
29.93000,2.49394,839.00113,-0.13384,5.28101,40.58125
30.13000,2.51062,842.33796,-0.13383,5.34773,40.74265
30.33000,2.52736,845.35293,-0.13384,5.41469,40.88848
30.53000,2.54404,847.03714,-0.13384,5.48142,40.96994
30.73000,2.56066,849.55962,-0.13384,5.54791,41.09195
30.93000,2.57729,853.65959,-0.13384,5.61439,41.29026
31.13000,2.59391,856.25267,-0.13384,5.68088,41.41568
31.33000,2.61071,859.72082,-0.13384,5.74808,41.58343
31.53000,2.62739,862.87912,-0.13384,5.81481,41.73619
31.73000,2.64401,865.61935,-0.13384,5.88129,41.86874
31.93000,2.66063,869.42194,-0.13384,5.94778,42.05266
32.13000,2.67731,869.05574,-0.13384,6.01450,42.03495
32.33000,2.69399,871.67891,-0.13384,6.08123,42.16183
32.53000,2.71074,874.98268,-0.13384,6.14819,42.32162
32.73000,2.72730,877.44333,-0.13384,6.21444,42.44064
32.93000,2.74404,880.19371,-0.13384,6.28140,42.57368
33.13000,2.76066,882.63871,-0.13384,6.34789,42.69194
33.33000,2.77722,885.95934,-0.13384,6.41414,42.85255
33.53000,2.79402,888.19480,-0.13384,6.48134,42.96067
33.73000,2.81070,890.51081,-0.13384,6.54806,43.07270
33.93000,2.82733,892.94743,-0.13384,6.61455,43.19056
34.13000,2.84401,892.37317,-0.13384,6.68128,43.16278
34.33000,2.86063,894.73240,-0.13384,6.74776,43.27689
34.53000,2.87725,897.11864,-0.13384,6.81425,43.39231
34.73000,2.89399,899.53728,-0.13384,6.88121,43.50930
34.93000,2.91073,901.38149,-0.13384,6.94818,43.59850
35.13000,2.92723,903.45191,-0.13384,7.01418,43.69864
35.33000,2.94397,906.01845,-0.13384,7.08115,43.82278
35.53000,2.96078,908.34536,-0.13384,7.14835,43.93533
35.73000,2.97734,909.68264,-0.13384,7.21460,44.00001
35.93000,2.99396,910.81178,-0.13384,7.28108,44.05463
36.13000,3.01058,912.48201,-0.13384,7.34757,44.13541
36.33000,3.02726,914.58363,-0.13384,7.41430,44.23706
36.53000,3.04388,915.83841,-0.13384,7.48078,44.29776
36.73000,3.06062,917.34007,-0.13384,7.54774,44.37039
36.93000,3.07731,915.71175,-0.13384,7.61447,44.29163
37.13000,3.09393,917.12186,-0.13384,7.68096,44.35984
37.33000,3.11061,918.94176,-0.13384,7.74768,44.44786
37.53000,3.12735,920.26163,-0.13384,7.81465,44.51170
37.73000,3.14397,921.76581,-0.13384,7.88113,44.58446
37.93000,3.16065,922.32972,-0.13384,7.94786,44.61173
38.13000,3.17739,923.24456,-0.13384,8.01482,44.65598
38.33000,3.19401,923.73313,-0.13384,8.08131,44.67962
38.53000,3.21064,924.90427,-0.13384,8.14779,44.73626
38.73000,3.22732,926.19853,-0.13384,8.21452,44.79886
38.93000,3.24406,927.11421,-0.13384,8.28148,44.84315
39.13000,3.26068,927.54345,-0.13384,8.34797,44.86391
39.33000,3.27730,928.21345,-0.13384,8.41445,44.89632
39.53000,3.29398,928.55208,-0.13384,8.48118,44.91270
39.73000,3.31060,928.86826,-0.13384,8.54766,44.92799
39.93000,3.32729,929.34044,-0.13384,8.61439,44.95083
40.13000,3.34409,928.86230,-0.13384,8.68159,44.92770
40.33000,3.36065,929.64657,-0.13384,8.74784,44.96564
40.53000,3.37727,929.98715,-0.13384,8.81432,44.98211
40.73000,3.39401,929.11730,-0.13384,8.88129,44.94004
40.93000,3.41069,929.08628,-0.13384,8.94801,44.93854
41.13000,3.42731,929.57746,-0.13384,9.01450,44.96230
41.33000,3.44399,928.62593,-0.13384,9.08123,44.91627
41.53000,3.46068,928.44032,-0.13384,9.14795,44.90729
41.73000,3.47724,927.87202,-0.13384,9.21420,44.87981
41.93000,3.49398,927.53833,-0.13384,9.28116,44.86367
42.13000,3.51078,926.73721,-0.13384,9.34836,44.82492
42.33000,3.52728,926.28486,-0.13384,9.41437,44.80304
42.53000,3.54390,926.01515,-0.13384,9.48086,44.78999
42.73000,3.56070,924.59852,-0.13385,9.54806,44.72147
42.93000,3.57738,923.62938,-0.13384,9.61479,44.67459
43.13000,3.59389,923.40885,-0.13384,9.68079,44.66393
43.33000,3.61069,922.09708,-0.13384,9.74800,44.60048
43.53000,3.62737,921.32129,-0.13384,9.81472,44.56296
43.73000,3.64399,919.71690,-0.13384,9.88121,44.48536
43.93000,3.66067,918.58860,-0.13384,9.94794,44.43078
44.13000,3.67735,917.39474,-0.13384,10.01466,44.37304
44.33000,3.69391,917.24740,-0.13384,10.08091,44.36591
44.53000,3.71066,915.91412,-0.13384,10.14787,44.30142
44.73000,3.72734,914.45995,-0.13384,10.21460,44.23108
44.93000,3.74396,913.15098,-0.13384,10.28108,44.16777
45.13000,3.76064,912.01076,-0.13384,10.34781,44.11262
45.33000,3.77732,910.61015,-0.13384,10.41453,44.04487
45.53000,3.79400,908.52026,-0.13384,10.48126,43.94379
45.73000,3.81062,907.31662,-0.13384,10.54774,43.88557
45.93000,3.82725,906.52863,-0.13384,10.61423,43.84746
46.13000,3.84399,904.84722,-0.13384,10.68119,43.76613
46.33000,3.86067,903.28557,-0.13384,10.74792,43.69059
46.53000,3.87729,902.17376,-0.13384,10.81440,43.63682
46.73000,3.89403,900.74679,-0.13384,10.88137,43.56780
46.93000,3.91065,899.07637,-0.13384,10.94785,43.48700
47.13000,3.92727,897.21195,-0.13384,11.01434,43.39682
47.33000,3.94395,895.72165,-0.13384,11.08106,43.32474
47.53000,3.96064,894.51997,-0.13384,11.14779,43.26662
47.73000,3.97726,893.07595,-0.13384,11.21428,43.19677
47.93000,3.99394,891.77843,-0.13384,11.28100,43.13401
48.13000,4.01068,890.42475,-0.13384,11.34796,43.06853
48.33000,4.02724,889.45152,-0.13384,11.41421,43.02146
48.53000,4.04398,887.06473,-0.13384,11.48118,42.90602
48.73000,4.06084,885.82579,-0.13384,11.54862,42.84609
48.93000,4.07728,884.34136,-0.13384,11.61439,42.77429
49.13000,4.09397,883.38424,-0.13384,11.68111,42.72800
49.33000,4.11071,882.11671,-0.13384,11.74808,42.66669
49.53000,4.12733,880.40913,-0.13384,11.81456,42.58410
49.73000,4.14395,878.75715,-0.13384,11.88105,42.50419
49.93000,4.16069,877.44137,-0.13384,11.94801,42.44055
50.13000,4.17737,876.12048,-0.13384,12.01474,42.37666
50.33000,4.19399,874.42622,-0.13384,12.08122,42.29471
50.53000,4.21062,874.15092,-0.13384,12.14771,42.28139
50.73000,4.22736,871.87029,-0.13384,12.21467,42.17109
50.93000,4.24404,870.78074,-0.13384,12.28140,42.11839
51.13000,4.26066,869.42818,-0.13384,12.34788,42.05296
51.33000,4.27734,867.80703,-0.13384,12.41461,41.97455
51.53000,4.29396,866.06313,-0.13384,12.48109,41.89020
51.73000,4.31058,864.56984,-0.13384,12.54758,41.81797
51.93000,4.32726,864.15764,-0.13384,12.61431,41.79803
52.13000,4.34395,862.84317,-0.13384,12.68103,41.73446
52.33000,4.36063,861.07627,-0.13384,12.74776,41.64899
52.53000,4.37725,859.30340,-0.13384,12.81424,41.56324
52.73000,4.39393,857.75312,-0.13384,12.88097,41.48826
52.93000,4.41067,856.93188,-0.13384,12.94793,41.44854
53.13000,4.42735,855.44605,-0.13384,13.01466,41.37667
53.33000,4.44403,854.21251,-0.13384,13.08138,41.31700
53.53000,4.46065,852.92617,-0.13384,13.14787,41.25478
53.73000,4.47734,851.34692,-0.13384,13.21459,41.17840
53.93000,4.49396,849.81378,-0.13384,13.28108,41.10424
54.13000,4.51076,848.58611,-0.13384,13.34828,41.04486
54.33000,4.52738,847.20375,-0.13384,13.41477,40.97800
54.53000,4.54394,845.67396,-0.13384,13.48101,40.90401
54.73000,4.56068,843.63995,-0.13384,13.54798,40.80562
54.93000,4.57730,841.89381,-0.13384,13.61447,40.72116
55.13000,4.59399,840.57469,-0.13384,13.68119,40.65736
55.33000,4.61073,839.77170,-0.13384,13.74815,40.61852
55.53000,4.62729,838.15623,-0.13384,13.81440,40.54039
55.73000,4.64397,835.91323,-0.13384,13.88113,40.43189
55.93000,4.66071,834.69814,-0.13384,13.94809,40.37312
56.13000,4.67739,832.91894,-0.13384,14.01481,40.28706
56.33000,4.69395,831.28791,-0.13384,14.08106,40.20818
56.53000,4.71063,828.96044,-0.13384,14.14779,40.09560
56.73000,4.72738,827.25454,-0.13384,14.21475,40.01308
56.93000,4.74394,825.48028,-0.13384,14.28100,39.92727
57.13000,4.76068,823.59463,-0.13384,14.34796,39.83606
57.33000,4.77736,821.53091,-0.13384,14.41469,39.73624
57.53000,4.79398,820.20201,-0.13384,14.48117,39.67197
57.73000,4.81060,817.59589,-0.13384,14.54766,39.54591
57.93000,4.82728,814.88714,-0.13384,14.61438,39.41489
58.13000,4.84397,813.46044,-0.13384,14.68111,39.34589
58.33000,4.86077,811.10392,-0.13384,14.74831,39.23190
58.53000,4.87733,808.19353,-0.13384,14.81456,39.09113
58.73000,4.89401,806.08092,-0.13384,14.88128,38.98895
58.93000,4.91057,803.61031,-0.13384,14.94753,38.86945
59.13000,4.92725,800.66100,-0.13384,15.01426,38.72680
59.33000,4.94399,798.49074,-0.13384,15.08122,38.62182
59.53000,4.96061,795.67758,-0.13384,15.14771,38.48576
59.73000,4.97730,793.29740,-0.13384,15.21443,38.37063
59.93000,4.99398,789.96271,-0.13384,15.28116,38.20934
60.13000,5.01066,787.15784,-0.13384,15.34788,38.07367
60.33000,5.02734,783.88415,-0.13384,15.41461,37.91533
60.53000,5.04402,780.50238,-0.13384,15.48133,37.75175
60.73000,5.06064,777.79088,-0.13384,15.54782,37.62060
60.93000,5.07726,774.80893,-0.13384,15.61430,37.47637
61.13000,5.09395,770.58901,-0.13384,15.68103,37.27226
61.33000,5.11069,767.56496,-0.13384,15.74799,37.12599
61.53000,5.12737,763.43981,-0.13384,15.81472,36.92646
61.73000,5.14405,759.81147,-0.13384,15.88144,36.75097
61.93000,5.16067,756.11137,-0.13384,15.94793,36.57199
62.13000,5.17729,752.66319,-0.13384,16.01442,36.40521
62.33000,5.19397,748.87513,-0.13384,16.08114,36.22199
62.53000,5.21071,744.97871,-0.13384,16.14810,36.03352
62.73000,5.22733,741.45426,-0.13384,16.21459,35.86305
62.93000,5.24396,737.40450,-0.13384,16.28108,35.66717
63.13000,5.26064,734.13993,-0.13384,16.34780,35.50927
63.33000,5.27726,729.77091,-0.13384,16.41429,35.29795
63.53000,5.29400,725.99072,-0.13384,16.48125,35.11510
63.73000,5.31068,722.10911,-0.13384,16.54798,34.92736
63.93000,5.32736,718.30531,-0.13384,16.61470,34.74337
64.13000,5.34392,714.41978,-0.13384,16.68095,34.55544
64.33000,5.36061,710.72574,-0.13384,16.74767,34.37676
64.53001,5.37741,707.12282,-0.13384,16.81488,34.20249
64.73000,5.39403,703.29728,-0.13384,16.88136,34.01746
64.93000,5.41065,700.09744,-0.13385,16.94785,33.86268
65.13000,5.42733,696.60512,-0.13384,17.01457,33.69376
65.33000,5.44395,693.22288,-0.13384,17.08106,33.53017
65.53001,5.46063,690.30784,-0.13384,17.14778,33.38918
65.73000,5.47732,687.20588,-0.13384,17.21451,33.23914
65.93000,5.49400,684.89425,-0.13384,17.28123,33.12733
66.13001,5.51056,682.08063,-0.13384,17.34748,32.99124
66.33000,5.52730,679.68504,-0.13384,17.41445,32.87537
66.53001,5.54398,677.45387,-0.13384,17.48117,32.76745
66.73000,5.56066,674.83680,-0.13384,17.54790,32.64087
66.93000,5.57734,672.77956,-0.13384,17.61462,32.54136
67.13001,5.59408,670.65684,-0.13384,17.68158,32.43869
67.33000,5.61065,669.10652,-0.13384,17.74783,32.36370
67.53001,5.62727,667.30985,-0.13384,17.81432,32.27680
67.73000,5.64395,666.42612,-0.13384,17.88104,32.23405
67.93000,5.66069,664.50452,-0.13384,17.94801,32.14111
68.13001,5.67731,662.87522,-0.13384,18.01449,32.06230
68.33000,5.69393,662.10991,-0.13384,18.08098,32.02528
68.53001,5.71067,660.90520,-0.13384,18.14794,31.96701
68.73000,5.72730,659.80447,-0.13384,18.21443,31.91377
68.93000,5.74398,659.58542,-0.13384,18.28116,31.90318
69.13001,5.76072,658.47598,-0.13384,18.34812,31.84951
69.33000,5.77728,657.37516,-0.13384,18.41436,31.79627
69.53001,5.79396,657.51257,-0.13384,18.48109,31.80292
69.73000,5.81070,656.19256,-0.13384,18.54805,31.73907
69.93000,5.82738,655.57701,-0.13384,18.61478,31.70930
70.13001,5.84400,655.18925,-0.13384,18.68127,31.69054
70.33000,5.86063,654.59977,-0.13384,18.74775,31.66203
70.53001,5.87737,653.32339,-0.13384,18.81472,31.60029
70.73000,5.89393,653.77429,-0.13384,18.88096,31.62210
70.93000,5.91061,653.12362,-0.13384,18.94769,31.59063
71.13001,5.92741,652.89531,-0.13384,19.01489,31.57959
71.33000,5.94403,653.25852,-0.13384,19.08138,31.59715
71.53001,5.96065,653.15752,-0.13384,19.14786,31.59227
71.73000,5.97733,652.61233,-0.13384,19.21459,31.56590
71.93000,5.99402,652.16050,-0.13384,19.28131,31.54404
72.13001,6.01064,652.63249,-0.13384,19.34780,31.56687
72.33000,6.02738,652.11500,-0.13384,19.41476,31.54184
72.53001,6.04400,652.65694,-0.13384,19.48125,31.56806
72.73000,6.06062,652.42639,-0.13384,19.54773,31.55691
72.93000,6.07724,652.66914,-0.13384,19.61422,31.56865
73.13001,6.09404,652.48781,-0.13384,19.68143,31.55988
73.33000,6.11067,652.49382,-0.13384,19.74791,31.56017
73.53001,6.12729,651.94876,-0.13384,19.81440,31.53380
73.73000,6.14397,652.85107,-0.13384,19.88112,31.57745
73.93000,6.16059,652.68166,-0.13384,19.94761,31.56925
74.13001,6.17727,652.92730,-0.13384,20.01433,31.58113
74.33000,6.19401,652.63566,-0.13384,20.08130,31.56703
74.53001,6.21081,652.21451,-0.13384,20.14850,31.54666
74.73000,6.22725,653.04530,-0.13384,20.21427,31.58684
74.93000,6.24394,652.88018,-0.13384,20.28099,31.57885
75.13001,6.26074,653.67548,-0.13384,20.34820,31.61732
75.33000,6.27730,653.83869,-0.13384,20.41444,31.62522
75.53001,6.29398,654.05234,-0.13384,20.48117,31.63555
75.73000,6.31072,653.73280,-0.13384,20.54813,31.62009
75.93000,6.32728,653.73299,-0.13384,20.61438,31.62010
76.13001,6.34390,654.79791,-0.13384,20.68086,31.67161
76.33000,6.36059,654.34873,-0.13384,20.74759,31.64989
76.53001,6.37733,654.43120,-0.13384,20.81456,31.65388
76.73000,6.39401,654.59572,-0.13384,20.88128,31.66183
76.93000,6.41063,654.71446,-0.13384,20.94776,31.66758
77.13001,6.42749,655.44643,-0.13384,21.01521,31.70298
77.33000,6.44393,655.38427,-0.13384,21.08098,31.69997
77.53001,6.46067,655.58199,-0.13384,21.14794,31.70954
77.73000,6.47747,655.62031,-0.13384,21.21515,31.71139
77.93000,6.49404,656.39960,-0.13384,21.28139,31.74908
78.13001,6.51060,656.60882,-0.13384,21.34764,31.75920
78.33000,6.52734,656.40635,-0.13384,21.41460,31.74941
78.53001,6.54408,656.70069,-0.13384,21.48157,31.76365
78.73000,6.56064,656.40132,-0.13384,21.54781,31.74917
78.93000,6.57726,656.72603,-0.13384,21.61430,31.76487
79.13001,6.59400,657.51751,-0.13384,21.68126,31.80316
79.33000,6.61056,657.18042,-0.13384,21.74751,31.78685
79.53001,6.62731,657.27737,-0.13384,21.81447,31.79154
79.73000,6.64405,657.22005,-0.13384,21.88144,31.78877
79.93000,6.66061,656.89138,-0.13384,21.94769,31.77287
80.13001,6.67729,657.31932,-0.13384,22.01441,31.79357
80.33000,6.69397,657.18219,-0.13384,22.08114,31.78694
80.53001,6.71065,657.65283,-0.13384,22.14786,31.80970
80.73000,6.72727,657.24594,-0.13384,22.21435,31.79002
80.93000,6.74402,657.34345,-0.13385,22.28131,31.79473
81.13001,6.76064,657.56044,-0.13384,22.34780,31.80523
81.33000,6.77726,657.52645,-0.13384,22.41428,31.80359
81.53001,6.79388,657.62284,-0.13384,22.48077,31.80825
81.73000,6.81068,658.18024,-0.13384,22.54797,31.83521
81.93000,6.82730,658.22583,-0.13384,22.61446,31.83742
82.13001,6.84398,657.34638,-0.13384,22.68118,31.79488
82.33000,6.86061,657.93218,-0.13384,22.74767,31.82321
82.53001,6.87729,658.93782,-0.13384,22.81439,31.87185
82.73000,6.89397,657.86727,-0.13384,22.88112,31.82007
82.93000,6.91071,658.60744,-0.13384,22.94808,31.85587
83.13001,6.92739,658.66695,-0.13384,23.01481,31.85875
83.33000,6.94395,658.60548,-0.13384,23.08106,31.85578
83.53001,6.96063,658.71067,-0.13384,23.14778,31.86087
83.73000,6.97731,659.37042,-0.13384,23.21450,31.89278
83.93000,6.99394,659.28153,-0.13384,23.28099,31.88848
84.13001,7.01068,659.29298,-0.13384,23.34796,31.88903
84.33000,7.02742,659.27906,-0.13384,23.41492,31.88836
84.53001,7.04398,660.02063,-0.13384,23.48116,31.92423
84.73000,7.06060,659.56754,-0.13384,23.54765,31.90231
84.93000,7.07740,659.15966,-0.13384,23.61486,31.88258
85.13001,7.09408,659.98388,-0.13384,23.68158,31.92245
85.33000,7.11064,659.58663,-0.13384,23.74783,31.90323
85.53001,7.12727,659.22691,-0.13384,23.81431,31.88584
85.73000,7.14401,659.86742,-0.13384,23.88128,31.91682
85.93000,7.16063,659.92163,-0.13384,23.94776,31.91944
86.13001,7.17725,660.07469,-0.13384,24.01425,31.92684
86.33000,7.19405,660.20400,-0.13384,24.08145,31.93310
86.53001,7.21061,660.26957,-0.13384,24.14770,31.93627
86.73000,7.22723,660.19879,-0.13384,24.21419,31.93284
86.93001,7.24398,660.09783,-0.13384,24.28115,31.92796
87.13001,7.26066,660.06859,-0.13384,24.34787,31.92655
87.33000,7.27734,660.20889,-0.13384,24.41460,31.93333
87.53001,7.29402,660.20549,-0.13384,24.48132,31.93317
87.73000,7.31064,660.29462,-0.13384,24.54781,31.93748
87.93001,7.32732,660.07124,-0.13384,24.61454,31.92668
88.13001,7.34400,660.18798,-0.13384,24.68126,31.93232
88.33000,7.36074,659.98551,-0.13384,24.74823,31.92253
88.53001,7.37737,660.34799,-0.13384,24.81471,31.94006
88.73000,7.39399,660.83926,-0.13384,24.88120,31.96382
88.93001,7.41061,660.53057,-0.13384,24.94768,31.94889
89.13001,7.42729,660.78524,-0.13384,25.01441,31.96121
89.33000,7.44403,660.39502,-0.13384,25.08137,31.94234
89.53001,7.46065,660.58855,-0.13384,25.14786,31.95170
89.73000,7.47727,660.65905,-0.13384,25.21434,31.95511
89.93001,7.49402,660.39925,-0.13384,25.28131,31.94254
90.13001,7.51058,660.97463,-0.13384,25.34755,31.97037
90.33000,7.52738,660.86240,-0.13384,25.41476,31.96494
90.53001,7.54406,660.56848,-0.13384,25.48148,31.95073
90.73000,7.56062,660.50710,-0.13384,25.54773,31.94776
90.93001,7.57736,660.78627,-0.13384,25.61469,31.96126
91.13001,7.59392,660.81667,-0.13384,25.68094,31.96273
91.33000,7.61060,660.67055,-0.13384,25.74767,31.95566
91.53001,7.62735,660.71739,-0.13384,25.81463,31.95793
91.73000,7.64403,660.42929,-0.13384,25.88136,31.94399
91.93001,7.66059,660.21383,-0.13384,25.94760,31.93357
92.13001,7.67721,661.01048,-0.13384,26.01409,31.97211
92.33000,7.69401,660.34356,-0.13384,26.08129,31.93985
92.53001,7.71069,660.49714,-0.13384,26.14802,31.94728
92.73000,7.72737,660.52340,-0.13384,26.21474,31.94855
92.93001,7.74405,660.46179,-0.13384,26.28147,31.94557
93.13001,7.76062,660.67567,-0.13384,26.34771,31.95591
93.33000,7.77736,660.36745,-0.13384,26.41468,31.94100
93.53001,7.79404,660.17518,-0.13384,26.48140,31.93170
93.73000,7.81066,660.12475,-0.13384,26.54789,31.92926
93.93001,7.82740,659.85415,-0.13384,26.61485,31.91618
94.13001,7.84396,660.42361,-0.13384,26.68110,31.94372
94.33000,7.86064,659.96526,-0.13384,26.74782,31.92155
94.53001,7.87727,659.75050,-0.13384,26.81431,31.91116
94.73000,7.89395,660.71688,-0.13384,26.88103,31.95790
94.93001,7.91069,659.85182,-0.13384,26.94800,31.91606
95.13001,7.92725,660.39488,-0.13384,27.01425,31.94233
95.33000,7.94387,659.88279,-0.13384,27.08073,31.91756
95.53001,7.96067,660.19502,-0.13384,27.14794,31.93266
95.73000,7.97735,660.08079,-0.13384,27.21466,31.92714
95.93001,7.99409,660.12200,-0.13384,27.28162,31.92913
96.13001,8.01066,660.16414,-0.13384,27.34787,31.93117
96.33000,8.02734,660.03506,-0.13384,27.41459,31.92492
96.53001,8.04402,660.00805,-0.13384,27.48132,31.92362
96.73000,8.06070,660.39925,-0.13384,27.54804,31.94254
96.93001,8.07738,659.89909,-0.13384,27.61477,31.91835
97.13001,8.09400,660.50501,-0.13384,27.68126,31.94766
97.33000,8.11062,660.39888,-0.13384,27.74774,31.94252
97.53001,8.12725,660.61793,-0.13384,27.81423,31.95312
97.73000,8.14399,660.69122,-0.13384,27.88120,31.95666
97.93001,8.16067,660.77788,-0.13384,27.94792,31.96086
98.13001,8.17729,660.49518,-0.13384,28.01440,31.94718
98.33000,8.19397,661.47665,-0.13384,28.08113,31.99465
98.53001,8.21059,661.31102,-0.13384,28.14762,31.98664
98.73000,8.22727,661.44792,-0.13384,28.21434,31.99326
98.93001,8.24407,661.17211,-0.13384,28.28154,31.97992
99.13001,8.26064,661.81961,-0.13384,28.34779,32.01124
99.33000,8.27726,661.57649,-0.13384,28.41428,31.99948
99.53001,8.29406,661.88383,-0.13384,28.48148,32.01435
99.73000,8.31062,661.93622,-0.13384,28.54773,32.01688
99.93001,8.32724,662.04779,-0.13384,28.61421,32.02228
100.13001,8.34398,662.13901,-0.13384,28.68117,32.02669
100.33000,8.36072,661.49095,-0.13384,28.74814,31.99534
100.53001,8.37728,662.15261,-0.13384,28.81439,32.02735
100.73000,8.39397,661.94795,-0.13384,28.88111,32.01745
100.93001,8.41071,662.28868,-0.13384,28.94808,32.03393
101.13001,8.42733,661.87596,-0.13384,29.01456,32.01397
101.33000,8.44401,662.32029,-0.13384,29.08129,32.03546
101.53001,8.46069,662.02017,-0.13384,29.14802,32.02094
101.73000,8.47725,662.17179,-0.13384,29.21426,32.02827
101.93001,8.49399,662.36593,-0.13384,29.28122,32.03767
102.13001,8.51068,662.27200,-0.13384,29.34795,32.03312
102.33000,8.52730,662.02688,-0.13384,29.41444,32.02127
102.53001,8.54392,662.67713,-0.13384,29.48092,32.05272
102.73000,8.56060,661.95149,-0.13384,29.54765,32.01762
102.93001,8.57734,662.20919,-0.13384,29.61461,32.03008
103.13001,8.59402,662.15554,-0.13384,29.68134,32.02749
103.33000,8.61070,662.34651,-0.13384,29.74806,32.03673
103.53001,8.62738,662.15675,-0.13384,29.81479,32.02755
103.73000,8.64395,662.50009,-0.13384,29.88103,32.04416
103.93001,8.66063,662.08858,-0.13384,29.94776,32.02425
104.13001,8.67737,661.42310,-0.13384,30.01472,31.99206
104.33000,8.69399,662.01366,-0.13384,30.08121,32.02063
104.53001,8.71061,662.16830,-0.13384,30.14770,32.02811
104.73000,8.72729,661.53458,-0.13384,30.21442,31.99746
104.93001,8.74397,662.25678,-0.13384,30.28114,32.03239
105.13001,8.76054,662.43950,-0.13384,30.34739,32.04123
105.33000,8.77734,662.21040,-0.13384,30.41459,32.03014
105.53001,8.79408,662.16826,-0.13384,30.48156,32.02810
105.73000,8.81058,661.72769,-0.13384,30.54756,32.00679
105.93001,8.82732,662.15042,-0.13384,30.61453,32.02724
106.13001,8.84406,662.20695,-0.13384,30.68150,32.02998
106.33000,8.86062,661.98697,-0.13384,30.74774,32.01934
106.53001,8.87730,662.27634,-0.13384,30.81447,32.03333
106.73000,8.89411,662.23410,-0.13384,30.88167,32.03129
106.93001,8.91061,662.27340,-0.13384,30.94768,32.03319
107.13001,8.92729,662.43215,-0.13384,31.01440,32.04087
107.33000,8.94403,663.02288,-0.13384,31.08137,32.06944
107.53001,8.96071,662.01044,-0.13384,31.14809,32.02047
107.73000,8.97727,662.67489,-0.13384,31.21434,32.05261
107.93001,8.99395,662.44276,-0.13384,31.28106,32.04138
108.13001,9.01069,662.25571,-0.13384,31.34803,32.03233
108.33000,9.02732,663.24356,-0.13384,31.41451,32.08012
108.53001,9.04394,663.01231,-0.13384,31.48100,32.06893
108.73000,9.06074,662.15382,-0.13384,31.54821,32.02740
108.93001,9.07724,662.56733,-0.13384,31.61421,32.04741
109.13001,9.09392,662.03806,-0.13384,31.68094,32.02181
109.33000,9.11066,662.69785,-0.13384,31.74790,32.05372
109.53001,9.12734,663.02982,-0.13384,31.81463,32.06978
109.73000,9.14397,662.55257,-0.13384,31.88111,32.04669
109.93001,9.16065,662.80370,-0.13384,31.94784,32.05884
110.13001,9.17733,662.68896,-0.13384,32.01456,32.05329
110.33000,9.19389,662.82409,-0.13384,32.08081,32.05983
110.53001,9.21057,663.13087,-0.13384,32.14753,32.07467
110.73000,9.22737,662.77008,-0.13384,32.21474,32.05721
110.93001,9.24399,662.73748,-0.13384,32.28122,32.05564
111.13001,9.26068,662.43485,-0.13385,32.34795,32.04100
111.33000,9.27736,662.95951,-0.13384,32.41467,32.06638
111.53001,9.29398,662.94614,-0.13384,32.48116,32.06573
111.73000,9.31066,663.16696,-0.13384,32.54789,32.07641
111.93001,9.32740,662.07373,-0.13384,32.61485,32.02353
112.13001,9.34402,662.74311,-0.13384,32.68133,32.05591
112.33000,9.36058,662.41352,-0.13384,32.74758,32.03997
112.53001,9.37726,662.50619,-0.13384,32.81431,32.04445
112.73000,9.39406,662.14511,-0.13384,32.88151,32.02699
112.93001,9.41063,662.33077,-0.13384,32.94775,32.03596
113.13001,9.42731,662.72877,-0.13384,33.01448,32.05522
113.33000,9.44405,662.18483,-0.13384,33.08144,32.02891
113.53001,9.46061,661.97515,-0.13384,33.14769,32.01876
113.73000,9.47723,662.28327,-0.13384,33.21418,32.03367
113.93001,9.49397,661.41617,-0.13384,33.28114,31.99173
114.13001,9.51077,661.78888,-0.13384,33.34835,32.00975
114.33000,9.52728,662.04993,-0.13384,33.41435,32.02238
114.53001,9.54396,661.52047,-0.13384,33.48108,31.99677
114.73000,9.56076,660.95856,-0.13384,33.54828,31.96959
114.93001,9.57726,661.04704,-0.13384,33.61429,31.97387
115.13001,9.59400,660.75874,-0.13384,33.68125,31.95993
115.33000,9.61074,660.82324,-0.13384,33.74822,31.96305
115.53001,9.62724,660.75451,-0.13384,33.81423,31.95972
115.73000,9.64393,660.11259,-0.13384,33.88095,31.92867
115.93001,9.66061,660.41066,-0.13384,33.94767,31.94309
116.13001,9.67735,660.68042,-0.13384,34.01464,31.95614
116.33000,9.69397,660.08791,-0.13384,34.08113,31.92748
116.53001,9.71053,659.81420,-0.13384,34.14737,31.91424
116.73000,9.72733,659.83357,-0.13384,34.21458,31.91518
116.93001,9.74395,659.26323,-0.13384,34.28106,31.88759
117.13001,9.76069,659.81112,-0.13384,34.34803,31.91409
117.33000,9.77744,659.27911,-0.13384,34.41499,31.88836
117.53001,9.79400,659.07268,-0.13384,34.48124,31.87838
117.73000,9.81068,658.96763,-0.13384,34.54796,31.87329
117.93001,9.82724,658.39561,-0.13384,34.61421,31.84563
118.13001,9.84392,658.61638,-0.13384,34.68093,31.85631
118.33000,9.86066,658.40795,-0.13384,34.74790,31.84622
118.53001,9.87728,657.52189,-0.13384,34.81438,31.80337
118.73000,9.89402,657.71746,-0.13384,34.88134,31.81283
118.93001,9.91059,657.39276,-0.13384,34.94760,31.79712
119.13001,9.92733,657.13916,-0.13384,35.01456,31.78485
119.33001,9.94407,657.36212,-0.13384,35.08152,31.79564
119.53001,9.96063,656.80374,-0.13384,35.14777,31.76863
119.73000,9.97737,656.59885,-0.13384,35.21473,31.75872
119.93001,9.99405,655.57733,-0.13384,35.28146,31.70931
120.13001,10.01061,655.86269,-0.13384,35.34771,31.72311
120.33001,10.02730,655.50166,-0.13384,35.41443,31.70565
120.53001,10.04404,654.83432,-0.13384,35.48139,31.67337
120.73000,10.06072,654.48480,-0.13384,35.54812,31.65647
120.93001,10.07728,654.06701,-0.13384,35.61437,31.63626
121.13001,10.09390,654.27991,-0.13384,35.68085,31.64656
121.33001,10.11064,653.50169,-0.13384,35.74781,31.60892
121.53001,10.12732,652.60287,-0.13384,35.81454,31.56544
121.73000,10.14400,652.72688,-0.13384,35.88126,31.57144
121.93001,10.16069,651.62587,-0.13384,35.94799,31.51818
122.13001,10.17725,651.60845,-0.13384,36.01424,31.51734
122.33001,10.19393,651.04673,-0.13384,36.08096,31.49017
122.53001,10.21067,650.52784,-0.13384,36.14793,31.46507
122.73000,10.22735,650.07815,-0.13384,36.21466,31.44333
122.93001,10.24397,648.77328,-0.13384,36.28114,31.38021
123.13001,10.26059,648.10133,-0.13384,36.34762,31.34771
123.33001,10.27734,647.50277,-0.13384,36.41459,31.31876
123.53001,10.29396,646.80860,-0.13384,36.48107,31.28518
123.73000,10.31070,646.22415,-0.13384,36.54804,31.25691
123.93001,10.32732,645.57353,-0.13384,36.61453,31.22544
124.13001,10.34394,644.16537,-0.13384,36.68101,31.15733
124.33001,10.36062,643.32783,-0.13384,36.74773,31.11682
124.53001,10.37730,641.84009,-0.13384,36.81446,31.04486
124.73000,10.39398,640.49773,-0.13384,36.88119,30.97993
124.93001,10.41073,639.78997,-0.13384,36.94815,30.94570
125.13001,10.42729,637.84793,-0.13384,37.01440,30.85177
125.33001,10.44391,635.65602,-0.13384,37.08088,30.74575
125.53001,10.46065,633.54434,-0.13384,37.14784,30.64361
125.73000,10.47727,632.01142,-0.13384,37.21433,30.56946
125.93001,10.49401,629.89024,-0.13384,37.28130,30.46687
126.13001,10.51063,626.55690,-0.13384,37.34778,30.30564
126.33001,10.52725,623.91777,-0.13384,37.41427,30.17798
126.53001,10.54400,619.36551,-0.13384,37.48123,29.95780
126.73000,10.56068,614.83262,-0.13384,37.54796,29.73855
126.93001,10.57730,609.04492,-0.13384,37.61445,29.45861
127.13001,10.59398,600.28229,-0.13384,37.68117,29.03477
127.33001,10.61066,578.42829,-0.13384,37.74790,27.97773
127.53001,10.62728,478.19531,-0.13384,37.81438,23.12960
127.73000,10.64396,317.72184,-0.13384,37.88111,15.36774
127.93001,10.66077,174.67687,-0.13384,37.94831,8.44886
127.97201,10.66423,8.05518,-0.13384,37.96218,0.38962