File: Manufatura Aditiva/Dados/Ensaios AMR/Ensaios/Ensaios SLS/Tracao_OLABI_08_06_2018_SLS_ZY6.is_metal_RawData/Specimen_RawData_1.csv
Time,Extension,Load,Strain 1,Tensile strain,Tensile stress
(sec),(mm),(N),(mm/mm),(%),(MPa)
0.00000,0.00006,25.59888,0.00092,0.09171,1.38178
0.10000,0.00419,27.16849,0.00095,0.09487,1.46651
0.20000,0.01381,31.09257,0.00109,0.10917,1.67832
0.30000,0.02362,36.52987,0.00125,0.12522,1.97182
0.40000,0.03270,41.82807,0.00140,0.14003,2.25780
0.50000,0.04143,46.44784,0.00154,0.15439,2.50717
0.60000,0.04986,50.59919,0.00168,0.16832,2.73125
0.70000,0.05823,54.35848,0.00182,0.18236,2.93417
0.80000,0.06673,59.08173,0.00196,0.19596,3.18913
0.90000,0.07498,62.27949,0.00210,0.20956,3.36173
1.00000,0.08329,67.00463,0.00223,0.22285,3.61679
1.10000,0.09178,70.90456,0.00236,0.23638,3.82730
1.20000,0.10003,74.96896,0.00250,0.24975,4.04669
1.30000,0.10840,79.78139,0.00263,0.26342,4.30646
1.40000,0.11683,83.73791,0.00278,0.27790,4.52002
1.50000,0.12496,87.01029,0.00291,0.29086,4.69666
1.60000,0.13333,91.08867,0.00305,0.30510,4.91680
1.70000,0.14170,95.32236,0.00319,0.31880,5.14533
1.80000,0.14989,99.27429,0.00332,0.33241,5.35865
1.90000,0.15832,103.23509,0.00346,0.34580,5.57244
2.00000,0.16663,106.84769,0.00360,0.35961,5.76745
2.10000,0.17494,110.90599,0.00373,0.37343,5.98651
2.20000,0.18331,114.65313,0.00388,0.38781,6.18877
2.30000,0.19163,118.42133,0.00402,0.40177,6.39217
2.40000,0.19994,122.14814,0.00415,0.41503,6.59334
2.50000,0.20837,126.12138,0.00428,0.42841,6.80780
2.60000,0.21668,129.94482,0.00443,0.44285,7.01419
2.70000,0.22493,133.42963,0.00456,0.45642,7.20229
2.80000,0.23336,136.84302,0.00470,0.47008,7.38654
2.90000,0.24167,140.48117,0.00484,0.48418,7.58292
3.00000,0.24992,144.24163,0.00498,0.49803,7.78590
3.10000,0.25841,147.59110,0.00511,0.51147,7.96670
3.20000,0.26666,152.43267,0.00525,0.52500,8.22804
3.30000,0.27497,155.32692,0.00539,0.53853,8.38427
3.40000,0.28346,159.76616,0.00553,0.55265,8.62389
3.50000,0.29171,162.85779,0.00567,0.56665,8.79077
3.60000,0.30002,166.49049,0.00580,0.58042,8.98686
3.70000,0.30839,170.40176,0.00594,0.59422,9.19798
3.80000,0.31665,173.85851,0.00608,0.60803,9.38457
3.90000,0.32502,176.99037,0.00622,0.62161,9.55362
4.00000,0.33333,181.01007,0.00635,0.63504,9.77060
4.10000,0.34164,184.65857,0.00649,0.64915,9.96754
4.20000,0.34995,187.83328,0.00663,0.66273,10.13890
4.30000,0.35826,192.17834,0.00677,0.67659,10.37344
4.40000,0.36657,195.65695,0.00691,0.69113,10.56121
4.50000,0.37500,198.96859,0.00706,0.70555,10.73997
4.60000,0.38337,202.38610,0.00720,0.71968,10.92444
4.70000,0.39162,206.08557,0.00733,0.73327,11.12413
4.80000,0.39999,208.93235,0.00747,0.74721,11.27779
4.90000,0.40824,212.83384,0.00761,0.76083,11.48839
5.00000,0.41667,216.45210,0.00775,0.77463,11.68369
5.10000,0.42504,220.35984,0.00789,0.78907,11.89463
5.20000,0.43335,223.17073,0.00803,0.80282,12.04635
5.30000,0.44166,226.65400,0.00817,0.81699,12.23437
5.40000,0.45010,230.50141,0.00831,0.83139,12.44205
5.50000,0.45829,233.43666,0.00845,0.84496,12.60049
5.60000,0.46666,237.25899,0.00859,0.85890,12.80681
5.70000,0.47503,240.50181,0.00873,0.87298,12.98185
5.80000,0.48334,243.76274,0.00887,0.88663,13.15787
5.90000,0.49165,247.33697,0.00901,0.90081,13.35080
6.00000,0.50002,251.18745,0.00915,0.91520,13.55865
6.10000,0.50827,254.43062,0.00929,0.92945,13.73371
6.20000,0.51664,257.58650,0.00943,0.94312,13.90405
6.30000,0.52495,259.61259,0.00953,0.95320,14.01342
6.40000,0.53326,263.35265,0.00967,0.96690,14.21530
6.50000,0.54169,266.73705,0.00981,0.98130,14.39798
6.60000,0.55000,269.93563,0.00996,0.99559,14.57064
6.70000,0.55831,273.36197,0.01009,1.00928,14.75558
6.80000,0.56674,276.49500,0.01023,1.02340,14.92470
6.90000,0.57500,280.39883,0.01038,1.03805,15.13542
7.00000,0.58331,282.59361,0.01052,1.05153,15.25389
7.10000,0.59174,286.95296,0.01066,1.06590,15.48920
7.20000,0.59993,289.45431,0.01080,1.07992,15.62422
7.30000,0.60818,293.00691,0.01094,1.09418,15.81598
7.40000,0.61673,296.20761,0.01109,1.10905,15.98875
7.50000,0.62498,299.43225,0.01124,1.12358,16.16281
7.60000,0.63329,302.40826,0.01138,1.13761,16.32345
7.70000,0.64178,306.19178,0.01152,1.15227,16.52768
7.80000,0.64997,309.30473,0.01166,1.16566,16.69571
7.90000,0.65828,312.31481,0.01180,1.17966,16.85819
8.00000,0.66671,314.84475,0.01195,1.19463,16.99475
8.10000,0.67496,318.72846,0.01209,1.20875,17.20439
8.20000,0.68333,321.61097,0.01223,1.22309,17.35998
8.30000,0.69176,324.54231,0.01238,1.23813,17.51821
8.40000,0.70002,327.19902,0.01252,1.25194,17.66161
8.50000,0.70839,330.54010,0.01266,1.26625,17.84196
8.60000,0.71664,333.20286,0.01281,1.28090,17.98569
8.70000,0.72489,336.10477,0.01294,1.29410,18.14233
8.80000,0.73344,338.86007,0.01309,1.30854,18.29105
8.90000,0.74169,342.43574,0.01323,1.32343,18.48406
9.00000,0.75000,344.94386,0.01338,1.33773,18.61945
9.10000,0.75843,348.67115,0.01353,1.35265,18.82064
9.20000,0.76668,351.20593,0.01367,1.36731,18.95746
9.30000,0.77493,354.43453,0.01381,1.38124,19.13173
9.40000,0.78336,357.38403,0.01396,1.39611,19.29094
9.50000,0.79161,359.88246,0.01411,1.41082,19.42580
9.60000,0.79992,362.81929,0.01425,1.42534,19.58433
9.70000,0.80835,365.76216,0.01440,1.43979,19.74318
9.80000,0.81660,368.95035,0.01454,1.45441,19.91527
9.90000,0.82498,371.39857,0.01469,1.46894,20.04742
10.00000,0.83341,374.84104,0.01484,1.48369,20.23324
10.10000,0.84166,376.81039,0.01498,1.49845,20.33954
10.20000,0.84991,379.45455,0.01513,1.51341,20.48227
10.30000,0.85840,381.61217,0.01526,1.52587,20.59874
10.40000,0.86665,384.07955,0.01539,1.53885,20.73192
10.50000,0.87502,386.85340,0.01553,1.55348,20.88165
10.60000,0.88333,389.10683,0.01567,1.56750,21.00328
10.70000,0.89164,392.12303,0.01583,1.58274,21.16609
10.80000,0.90007,394.48226,0.01597,1.59744,21.29344
10.90000,0.90832,397.59600,0.01612,1.61236,21.46151
11.00000,0.91669,399.84910,0.01628,1.62777,21.58313
11.10000,0.92506,403.12386,0.01642,1.64232,21.75990
11.20000,0.93331,405.61263,0.01657,1.65746,21.89424
11.30000,0.94162,407.73465,0.01672,1.67238,22.00878
11.40000,0.95000,410.72736,0.01687,1.68715,22.17032
11.50000,0.95825,413.02834,0.01702,1.70189,22.29452
11.60000,0.96656,415.96722,0.01717,1.71703,22.45316
11.70000,0.97499,417.72546,0.01732,1.73246,22.54807
11.80000,0.98336,420.65899,0.01748,1.74768,22.70641
11.90000,0.99161,422.84769,0.01763,1.76277,22.82455
12.00000,1.00010,425.64096,0.01778,1.77762,22.97533
12.10000,1.00835,427.75162,0.01793,1.79283,23.08926
12.20000,1.01666,430.85543,0.01808,1.80769,23.25680
12.30000,1.02509,433.01815,0.01823,1.82299,23.37354
12.40000,1.03328,435.40872,0.01838,1.83815,23.50257
12.50000,1.04165,437.85623,0.01854,1.85361,23.63469
12.60000,1.05002,440.86580,0.01869,1.86862,23.79714
12.70000,1.05827,442.13850,0.01884,1.88444,23.86584
12.80000,1.06658,445.02313,0.01899,1.89926,24.02154
12.90000,1.07502,446.81979,0.01914,1.91449,24.11852
13.00000,1.08333,449.54740,0.01930,1.92977,24.26576
13.10000,1.09176,451.94724,0.01946,1.94589,24.39529
13.20000,1.10001,453.95503,0.01961,1.96103,24.50367
13.30000,1.10832,456.78457,0.01976,1.97636,24.65641
13.40000,1.11675,458.58989,0.01992,1.99183,24.75385
13.50000,1.12500,460.82796,0.02007,2.00713,24.87466
13.60000,1.13325,463.08618,0.02023,2.02271,24.99656
13.70000,1.14168,465.42976,0.02038,2.03839,25.12306
13.80000,1.14993,467.38698,0.02054,2.05420,25.22870
13.90000,1.15824,469.16739,0.02067,2.06703,25.32481
14.00000,1.16673,471.46017,0.02083,2.08288,25.44857
14.10000,1.17498,473.59625,0.02098,2.09812,25.56387
14.20000,1.18329,475.39994,0.02114,2.11393,25.66123
14.30000,1.19178,477.57360,0.02130,2.12969,25.77856
14.40000,1.19998,479.80393,0.02146,2.14598,25.89895
14.50000,1.20829,482.01345,0.02162,2.16170,26.01822
14.60000,1.21672,484.25193,0.02178,2.17808,26.13904
14.70000,1.22491,484.65878,0.02189,2.18892,26.16101
14.80000,1.23334,487.22564,0.02204,2.20417,26.29956
14.90000,1.24171,489.30249,0.02221,2.22064,26.41166
15.00000,1.24996,491.46907,0.02236,2.23603,26.52861
15.10000,1.25833,493.36441,0.02252,2.25247,26.63092
15.20000,1.26670,494.91180,0.02268,2.26774,26.71445
15.30000,1.27495,497.48281,0.02284,2.28437,26.85322
15.40000,1.28338,499.04347,0.02300,2.29980,26.93747
15.50000,1.29175,500.54928,0.02316,2.31591,27.01875
15.60000,1.29994,502.52778,0.02331,2.33149,27.12554
15.70000,1.30837,504.57078,0.02348,2.34792,27.23582
15.80000,1.31662,507.02295,0.02364,2.36420,27.36818
15.90000,1.32488,508.76965,0.02380,2.38044,27.46247
16.00000,1.33343,510.24896,0.02397,2.39680,27.54232
16.10000,1.34162,510.88752,0.02413,2.41301,27.57679
16.20000,1.34993,513.47720,0.02429,2.42934,27.71657
16.30000,1.35842,515.80062,0.02446,2.44615,27.84199
16.40000,1.36667,517.33935,0.02462,2.46234,27.92504
16.50000,1.37504,519.45006,0.02479,2.47867,28.03897
16.60000,1.38341,520.70846,0.02496,2.49553,28.10690
16.70000,1.39160,523.15979,0.02511,2.51132,28.23922
16.80000,1.39997,524.57233,0.02527,2.52748,28.31547
16.90000,1.40840,525.59809,0.02544,2.54435,28.37083
17.00000,1.41659,527.93557,0.02561,2.56062,28.49701
17.10000,1.42496,529.73768,0.02578,2.57764,28.59428
17.20000,1.43333,530.69503,0.02594,2.59365,28.64596
17.30000,1.44164,532.99740,0.02610,2.61000,28.77024
17.40000,1.45001,534.56067,0.02626,2.62639,28.85462
17.50000,1.45839,536.31989,0.02644,2.64351,28.94958
17.60000,1.46664,537.13582,0.02660,2.65989,28.99362
17.70000,1.47501,539.09044,0.02677,2.67672,29.09913
17.80000,1.48320,540.30209,0.02693,2.69302,29.16453
17.90000,1.49157,542.23393,0.02710,2.70985,29.26881
18.00000,1.50000,543.71795,0.02726,2.72639,29.34891
18.10000,1.50819,545.17002,0.02743,2.74259,29.42729
18.20000,1.51656,547.27620,0.02760,2.75981,29.54098
18.30000,1.52505,548.78197,0.02777,2.77685,29.62226
18.40000,1.53336,549.69061,0.02794,2.79363,29.67131
18.50000,1.54167,551.46068,0.02811,2.81052,29.76685
18.60000,1.55004,552.92179,0.02827,2.82742,29.84572
18.70000,1.55829,554.05884,0.02844,2.84373,29.90709
18.80000,1.56666,555.77205,0.02861,2.86095,29.99957
18.90000,1.57509,556.95903,0.02878,2.87753,30.06364
19.00000,1.58335,558.81809,0.02895,2.89490,30.16399
19.10000,1.59166,559.26088,0.02911,2.91145,30.18789
19.20000,1.60009,561.21913,0.02929,2.92880,30.29359
19.30000,1.60834,562.02621,0.02946,2.94598,30.33716
19.40000,1.61665,563.73458,0.02962,2.96248,30.42937
19.50000,1.62502,565.22447,0.02980,2.97993,30.50980
19.60000,1.63333,566.17660,0.02997,2.99686,30.56119
19.70000,1.64176,568.42454,0.03014,3.01427,30.68253
19.80000,1.65001,569.67125,0.03031,3.03091,30.74982
19.90000,1.65832,570.60323,0.03048,3.04826,30.80013
20.00000,1.66663,571.97735,0.03065,3.08151,30.87430
20.10000,1.67488,573.11230,0.03082,3.11451,30.93557
20.20000,1.68325,574.43520,0.03100,3.14799,31.00697
20.21000,1.68409,574.61285,0.03101,3.15134,31.01656
20.31000,1.69252,576.37217,0.03118,3.18506,31.11153
20.41000,1.70077,576.17733,0.03130,3.21807,31.10101
20.51000,1.70914,577.14963,0.03147,3.25155,31.15349
20.61000,1.71757,578.77977,0.03164,3.28527,31.24149
20.71000,1.72582,580.05517,0.03181,3.31827,31.31033
20.81000,1.73419,581.30529,0.03199,3.35175,31.37781
20.91000,1.74256,583.34419,0.03216,3.38524,31.48787
21.01000,1.75076,583.56756,0.03233,3.41800,31.49992
21.11000,1.75913,584.92613,0.03250,3.45148,31.57326
21.21000,1.76756,586.44237,0.03268,3.48520,31.65510
21.31000,1.77581,588.30241,0.03285,3.51821,31.75550
21.41000,1.78418,588.94572,0.03302,3.55169,31.79023
21.51000,1.79249,590.10196,0.03320,3.58493,31.85264
21.61000,1.80080,591.35524,0.03337,3.61818,31.92029
21.71000,1.80923,592.51911,0.03355,3.65190,31.98311
21.81000,1.81760,593.23180,0.03372,3.68538,32.02158
21.91000,1.82585,594.69515,0.03385,3.71838,32.10057
22.01000,1.83422,595.53562,0.03428,3.75187,32.14594
22.11000,1.84253,596.97116,0.03461,3.78511,32.22342
22.21000,1.85078,597.68357,0.03190,3.81811,32.26188
22.31000,1.85921,598.65988,0.00198,3.85183,32.31458
22.41000,1.86752,600.28215,0.00115,3.88508,32.40215
22.51000,1.87578,600.83433,0.00131,3.91808,32.43195
22.61000,1.88421,602.09571,0.00128,3.95180,32.50004
22.71000,1.89252,603.16399,0.00128,3.98504,32.55770
22.81000,1.90071,604.70994,0.00168,4.01781,32.64115
22.91000,1.90920,605.25890,0.00250,4.05177,32.67078
23.01000,1.91745,606.96858,0.00289,4.08477,32.76307
23.11000,1.92576,607.84542,0.00274,4.11802,32.81040
23.21000,1.93419,609.27835,0.00334,4.15174,32.88774
23.31000,1.94244,610.35748,0.00329,4.18474,32.94600
23.41000,1.95081,611.19106,0.00374,4.21822,32.99099
23.51000,1.95918,611.93383,-0.00569,4.25171,33.03108
23.61000,1.96749,613.65780,-0.01772,4.28495,33.12414
23.71000,1.97580,613.77818,-0.01809,4.31819,33.13064
23.81000,1.98423,615.53712,-0.01888,4.35191,33.22558
23.91000,1.99260,616.04618,-0.02048,4.38539,33.25306
24.01000,2.00092,617.46300,-0.02270,4.41864,33.32954
24.11000,2.00917,618.43777,-0.02726,4.45164,33.38215
24.21000,2.01748,619.47121,-0.03477,4.48488,33.43793
24.31000,2.02585,619.37445,-0.14303,4.51837,33.43271
24.41000,2.03422,621.35118,-0.13915,4.55185,33.53941
24.51000,2.04247,622.03151,-0.13918,4.58485,33.57614
24.61000,2.05090,622.88488,-0.13918,4.61857,33.62220
24.71000,2.05915,623.89239,-0.13918,4.65158,33.67658
24.81000,2.06746,625.13929,-0.13919,4.68482,33.74389
24.91000,2.07589,625.67331,-0.13919,4.71854,33.77271
25.01000,2.08414,626.87695,-0.13919,4.75155,33.83768
25.11000,2.09245,628.05451,-0.13919,4.78479,33.90125
25.21000,2.10082,628.90174,-0.13919,4.81827,33.94698
25.31000,2.10907,629.57378,-0.13919,4.85127,33.98325
25.41000,2.11744,631.09240,-0.13919,4.88476,34.06523
25.51000,2.12576,631.77291,-0.13919,4.91800,34.10196
25.61000,2.13407,633.02196,-0.13919,4.95124,34.16938
25.71000,2.14244,633.67197,-0.13919,4.98472,34.20447
25.81000,2.15075,634.41778,-0.13919,5.01797,34.24472
25.91000,2.15924,635.48977,-0.13919,5.05193,34.30259
26.01000,2.16755,636.05416,-0.13919,5.08517,34.33305
26.11000,2.17586,636.82147,-0.13920,5.11841,34.37447
26.21000,2.18423,638.02009,-0.13920,5.15190,34.43917
26.31000,2.19254,638.87201,-0.13919,5.18514,34.48516
26.41000,2.20085,640.03495,-0.13920,5.21838,34.54793
26.51000,2.20916,641.25028,-0.13920,5.25163,34.61353
26.61000,2.21753,641.76721,-0.13920,5.28511,34.64143
26.71000,2.22584,642.28815,-0.13920,5.31835,34.66955
26.81000,2.23421,643.27028,-0.13920,5.35183,34.72257
26.91000,2.24258,643.62525,-0.13920,5.38531,34.74173
27.01000,2.25084,645.40259,-0.13919,5.41832,34.83767
27.11000,2.25915,645.25246,-0.13920,5.45156,34.82956
27.21000,2.26758,646.79193,-0.13920,5.48528,34.91266
27.31000,2.27583,647.33941,-0.13920,5.51829,34.94221
27.41000,2.28420,648.23441,-0.13920,5.55177,34.99052
27.51000,2.29251,649.26641,-0.13920,5.58501,35.04623
27.61000,2.30082,650.11317,-0.13920,5.61825,35.09193
27.71000,2.30913,650.89869,-0.13920,5.65150,35.13433
27.81000,2.31750,651.00035,-0.13920,5.68498,35.13982
27.91000,2.32587,652.62360,-0.13920,5.71846,35.22744
28.01000,2.33412,653.02285,-0.13920,5.75146,35.24899
28.11000,2.34249,653.88526,-0.13920,5.78495,35.29554
28.21000,2.35080,655.85407,-0.13920,5.81819,35.40182
28.31000,2.35911,655.72634,-0.13920,5.85143,35.39492
28.41000,2.36748,656.54996,-0.13921,5.88492,35.43938
28.51000,2.37580,656.90991,-0.13920,5.91816,35.45881
28.61000,2.38417,656.61748,-0.13920,5.95164,35.44302
28.71000,2.39248,657.86629,-0.13921,5.98488,35.51043
28.81000,2.40079,658.56525,-0.13920,6.01813,35.54816
28.91000,2.40922,659.58346,-0.13921,6.05185,35.60312
29.01000,2.41747,660.51730,-0.13920,6.08485,35.65353
29.11000,2.42584,660.99828,-0.13921,6.11833,35.67949
29.21000,2.43427,661.83363,-0.13921,6.15205,35.72458
29.31000,2.44252,662.75815,-0.13920,6.18506,35.77449
29.41000,2.45083,662.99364,-0.13920,6.21830,35.78720
29.51000,2.45926,664.72762,-0.13920,6.25202,35.88079
29.61000,2.46745,665.22644,-0.13920,6.28479,35.90772
29.71000,2.47582,666.24628,-0.13921,6.31827,35.96277
29.81000,2.48425,666.60293,-0.13920,6.35199,35.98202
29.91000,2.49250,667.72308,-0.13921,6.38499,36.04248
30.01000,2.50076,667.69128,-0.13920,6.41800,36.04077
30.11000,2.50919,668.84719,-0.13920,6.45172,36.10316
30.21000,2.51750,669.98573,-0.13921,6.48496,36.16462
30.31000,2.52587,670.09791,-0.13920,6.51845,36.17067
30.41000,2.53424,671.29550,-0.13920,6.55193,36.23532
30.51000,2.54249,672.11804,-0.13921,6.58493,36.27972
30.61000,2.55086,672.66729,-0.13921,6.61841,36.30936
30.71000,2.55905,673.32475,-0.13921,6.65118,36.34485
30.81000,2.56742,674.51023,-0.13921,6.68466,36.40884
30.91000,2.57585,674.86977,-0.13921,6.71838,36.42825
31.01000,2.58410,676.27113,-0.13921,6.75138,36.50389
31.11000,2.59247,676.56427,-0.13920,6.78487,36.51972
31.21000,2.60084,676.99137,-0.13921,6.81835,36.54277
31.31000,2.60909,677.84120,-0.13921,6.85135,36.58864
31.41000,2.61746,678.47404,-0.13921,6.88483,36.62280
31.51000,2.62583,679.40070,-0.13921,6.91832,36.67282
31.61000,2.63415,680.24262,-0.13921,6.95156,36.71827
31.71000,2.64252,680.52141,-0.13921,6.98504,36.73331
31.81000,2.65089,680.77096,-0.13921,7.01852,36.74678
31.91000,2.65914,681.79080,-0.13921,7.05153,36.80183
32.01000,2.66745,682.17996,-0.13921,7.08477,36.82284
32.11000,2.67582,682.34098,-0.13921,7.11825,36.83153
32.21000,2.68419,683.58304,-0.13921,7.15174,36.89858
32.31000,2.69250,684.64400,-0.13921,7.18498,36.95584
32.41000,2.70087,685.15376,-0.13921,7.21846,36.98336
32.51000,2.70918,685.93025,-0.13921,7.25170,37.02528
32.61000,2.71755,686.48220,-0.13921,7.28519,37.05507
32.71000,2.72586,687.17394,-0.13921,7.31843,37.09241
32.81000,2.73423,687.72053,-0.13921,7.35191,37.12191
32.91000,2.74248,688.37767,-0.13921,7.38491,37.15738
33.01000,2.75079,688.80497,-0.13921,7.41816,37.18045
33.11000,2.75917,689.81312,-0.13921,7.45164,37.23487
33.21000,2.76754,690.51655,-0.13921,7.48512,37.27283
33.31000,2.77585,691.12782,-0.13921,7.51836,37.30583
33.41000,2.78422,691.60941,-0.13921,7.55185,37.33183
33.51000,2.79259,691.77579,-0.13921,7.58533,37.34081
33.61000,2.80084,693.06265,-0.13921,7.61833,37.41027
33.71000,2.80915,693.05240,-0.13921,7.65157,37.40972
33.81000,2.81752,694.41837,-0.13921,7.68506,37.48345
33.91000,2.82577,694.61106,-0.13921,7.71806,37.49385
34.01000,2.83408,695.32376,-0.13921,7.75130,37.53232
34.11000,2.84245,695.50485,-0.13921,7.78479,37.54210
34.21000,2.85070,695.96930,-0.13921,7.81779,37.56717
34.31000,2.85913,697.10505,-0.13921,7.85151,37.62847
34.41000,2.86756,697.15893,-0.13921,7.88523,37.63138
34.51000,2.87587,698.54949,-0.13921,7.91847,37.70644
34.61000,2.88424,698.15353,-0.13921,7.95196,37.68507
34.71000,2.89256,699.42386,-0.13921,7.98520,37.75364
34.81000,2.90087,699.52281,-0.13921,8.01844,37.75898
34.91000,2.90918,700.21562,-0.13921,8.05169,37.79638
35.01000,2.91749,700.81586,-0.13921,8.08493,37.82877
35.11000,2.92580,701.42876,-0.13921,8.11817,37.86186
35.21000,2.93417,702.73639,-0.13921,8.15165,37.93244
35.31000,2.94248,702.95823,-0.13921,8.18490,37.94442
35.41000,2.95073,703.22431,-0.13921,8.21790,37.95878
35.51000,2.95922,703.87749,-0.13921,8.25186,37.99403
35.61000,2.96753,704.82274,-0.13922,8.28510,38.04506
35.71000,2.97584,705.22334,-0.13922,8.31835,38.06668
35.81000,2.98433,705.29613,-0.13921,8.35231,38.07061
35.91000,2.99246,706.07490,-0.13921,8.38483,38.11265
36.01000,3.00071,706.90038,-0.13921,8.41784,38.15720
36.11000,3.00921,706.77469,-0.13921,8.45180,38.15042
36.21000,3.01740,707.44441,-0.13921,8.48456,38.18657
36.31000,3.02577,708.68051,-0.13921,8.51805,38.25329
36.41000,3.03420,708.58826,-0.13921,8.55177,38.24831
36.51000,3.04239,709.45905,-0.13922,8.58453,38.29532
36.61000,3.05082,709.68056,-0.13922,8.61825,38.30727
36.71000,3.05925,710.55344,-0.13921,8.65197,38.35439
36.81000,3.06750,710.97896,-0.13921,8.68498,38.37736
36.91000,3.07587,710.80867,-0.13922,8.71846,38.36817
37.01000,3.08424,711.92062,-0.13921,8.75194,38.42819
37.11000,3.09243,712.05487,-0.13921,8.78471,38.43544
37.21000,3.10086,712.92482,-0.13921,8.81843,38.48240
37.31000,3.10917,713.28520,-0.13922,8.85167,38.50185
37.41000,3.11748,713.78020,-0.13921,8.88491,38.52856
37.51000,3.12591,714.49620,-0.13921,8.91863,38.56721
37.61000,3.13417,715.33606,-0.13922,8.95164,38.61255
37.71000,3.14248,715.75115,-0.13921,8.98488,38.63495
37.81000,3.15097,716.58585,-0.13921,9.01884,38.68001
37.91000,3.15916,716.63549,-0.13922,9.05161,38.68269
38.01000,3.16747,717.55308,-0.13921,9.08485,38.73222
38.11000,3.17590,718.30885,-0.13922,9.11857,38.77301
38.21000,3.18409,718.10097,-0.13922,9.15134,38.76179
38.31000,3.19246,718.61073,-0.13921,9.18482,38.78931
38.41000,3.20083,718.77004,-0.13921,9.21830,38.79791
38.51000,3.20908,719.87626,-0.13922,9.25130,38.85762
38.61000,3.21739,719.08538,-0.13922,9.28455,38.81493
38.71000,3.22588,720.60134,-0.13922,9.31851,38.89676
38.81000,3.23413,720.60865,-0.13921,9.35151,38.89715
38.91000,3.24244,722.01393,-0.13921,9.38475,38.97301
39.01000,3.25081,722.04727,-0.13922,9.41823,38.97481
39.11000,3.25918,722.39009,-0.13921,9.45172,38.99331
39.21000,3.26750,722.87959,-0.13922,9.48496,39.01973
39.31000,3.27587,722.87628,-0.13922,9.51844,39.01955
39.41000,3.28412,723.93687,-0.13922,9.55145,39.07681
39.51000,3.29249,723.72309,-0.13922,9.58493,39.06527
39.61000,3.30080,724.01199,-0.13922,9.61817,39.08086
39.71000,3.30911,724.83569,-0.13922,9.65141,39.12532
39.81000,3.31754,725.75719,-0.13922,9.68514,39.17506
39.91000,3.32579,725.65186,-0.13922,9.71814,39.16938
40.01000,3.33416,726.46784,-0.13921,9.75162,39.21342
40.11000,3.34259,725.65763,-0.13922,9.78534,39.16969
40.21000,3.35090,725.67179,-0.13922,9.81859,39.17045
40.31000,3.35915,726.43575,-0.13922,9.85159,39.21169
40.41000,3.36752,726.95897,-0.13922,9.88507,39.23993
40.51000,3.37577,727.34221,-0.13922,9.91807,39.26062
40.61000,3.38415,727.45411,-0.13922,9.95156,39.26666
40.71000,3.39252,728.13430,-0.13922,9.98504,39.30338
40.81000,3.40083,728.90655,-0.13922,10.01828,39.34506
40.91000,3.40914,729.06236,-0.13922,10.05152,39.35347
41.01000,3.41757,729.87452,-0.13922,10.08525,39.39731
41.11000,3.42588,730.26125,-0.13922,10.11849,39.41818
41.21000,3.43413,730.65371,-0.13922,10.15149,39.43937
41.31000,3.44250,730.76696,-0.13922,10.18497,39.44548
41.41000,3.45075,731.46862,-0.13921,10.21798,39.48335
41.51000,3.45912,732.25489,-0.13922,10.25146,39.52579
41.61000,3.46749,732.17596,-0.13922,10.28494,39.52153
41.71000,3.47574,732.58802,-0.13922,10.31795,39.54378
41.81000,3.48417,733.13517,-0.13922,10.35167,39.57331
41.91000,3.49248,733.60964,-0.13922,10.38491,39.59892
42.01000,3.50079,733.74636,-0.13922,10.41816,39.60630
42.11000,3.50922,734.05681,-0.13922,10.45188,39.62306
42.21000,3.51754,735.12583,-0.13922,10.48512,39.68076
42.31000,3.52585,734.96038,-0.13922,10.51836,39.67183
42.41000,3.53428,736.04588,-0.13922,10.55208,39.73043
42.51000,3.54247,735.70665,-0.13922,10.58485,39.71212
42.61000,3.55078,736.38312,-0.13922,10.61809,39.74863
42.71000,3.55927,736.54326,-0.13922,10.65205,39.75727
42.81000,3.56746,737.81814,-0.13922,10.68482,39.82609
42.91000,3.57577,738.06406,-0.13922,10.71806,39.83936
43.01000,3.58432,738.31528,-0.13922,10.75226,39.85292
43.11000,3.59245,737.88394,-0.13921,10.78478,39.82964
43.21000,3.60082,738.14704,-0.13922,10.81827,39.84384
43.31000,3.60925,739.50347,-0.13922,10.85199,39.91706
43.41000,3.61738,739.96726,-0.13922,10.88451,39.94210
43.51000,3.62581,739.79693,-0.13922,10.91823,39.93290
43.61000,3.63418,740.47549,-0.13922,10.95172,39.96953
43.71000,3.64238,741.55787,-0.13922,10.98448,40.02795
43.81000,3.65087,741.00024,-0.13922,11.01844,39.99785
43.91000,3.65924,742.24519,-0.13922,11.05192,40.06505
44.01000,3.66743,741.63680,-0.13922,11.08469,40.03222
44.11000,3.67592,741.92006,-0.13922,11.11865,40.04750
44.21000,3.68423,742.84594,-0.13922,11.15189,40.09748
44.31000,3.69242,743.19565,-0.13922,11.18466,40.11636
44.41000,3.70097,743.43700,-0.13922,11.21886,40.12939
44.51000,3.70916,743.48170,-0.13922,11.25162,40.13180
44.61000,3.71741,744.10196,-0.13922,11.28462,40.16528
44.71000,3.72596,744.00925,-0.13922,11.31882,40.16027
44.81000,3.73415,744.43854,-0.13922,11.35159,40.18345
44.91000,3.74246,745.05941,-0.13922,11.38483,40.21696
45.01000,3.75095,745.01834,-0.13922,11.41879,40.21474
45.11000,3.75914,745.02211,-0.13922,11.45156,40.21495
45.21000,3.76746,746.54929,-0.13922,11.48480,40.29738
45.31000,3.77595,746.57481,-0.13922,11.51876,40.29876
45.41000,3.78408,746.62836,-0.13922,11.55128,40.30165
45.51000,3.79245,746.36755,-0.13922,11.58477,40.28757
45.61000,3.80088,747.35000,-0.13922,11.61849,40.34060
45.71000,3.80907,747.31354,-0.13922,11.65125,40.33863
45.81000,3.81750,747.55168,-0.13922,11.68498,40.35149
45.91000,3.82587,748.40472,-0.13922,11.71846,40.39753
46.01000,3.83406,748.70475,-0.13922,11.75122,40.41373
46.11000,3.84255,749.36463,-0.13922,11.78518,40.44935
46.21000,3.85086,749.42037,-0.13922,11.81842,40.45236
46.31000,3.85911,749.62815,-0.13922,11.85143,40.46357
46.41000,3.86754,749.87216,-0.13922,11.88515,40.47675
46.51000,3.87579,749.97256,-0.13922,11.91815,40.48216
46.61000,3.88416,750.91706,-0.13922,11.95164,40.53315
46.71000,3.89254,751.05182,-0.13922,11.98512,40.54042
46.81000,3.90079,751.22537,-0.13922,12.01812,40.54979
46.91000,3.90910,751.53192,-0.13922,12.05136,40.56633
47.01000,3.91753,752.00866,-0.13922,12.08509,40.59207
47.11000,3.92578,752.25527,-0.13922,12.11809,40.60538
47.21000,3.93415,751.99176,-0.13922,12.15157,40.59116
47.31000,3.94258,752.44731,-0.13922,12.18529,40.61575
47.41000,3.95077,752.27530,-0.13922,12.21806,40.60646
47.51000,3.95914,753.09160,-0.13922,12.25154,40.65052
47.61000,3.96751,753.64425,-0.13922,12.28502,40.68036
47.71000,3.97582,753.90013,-0.13922,12.31826,40.69417
47.81000,3.98413,754.53138,-0.13922,12.35151,40.72824
47.91000,3.99244,754.31601,-0.13922,12.38475,40.71661
48.01000,4.00075,754.48095,-0.13922,12.41799,40.72552
48.11000,4.00912,754.87415,-0.13922,12.45148,40.74674
48.21000,4.01750,755.19821,-0.13922,12.48496,40.76423
48.31000,4.02581,755.43923,-0.13922,12.51820,40.77724
48.41000,4.03418,755.49860,-0.13922,12.55168,40.78045
48.51000,4.04249,756.32483,-0.13922,12.58493,40.82505
48.61000,4.05080,755.86028,-0.13922,12.61817,40.79997
48.71000,4.05923,755.71863,-0.13922,12.65189,40.79232
48.81000,4.06748,756.88558,-0.13922,12.68489,40.85532
48.91000,4.07579,756.75822,-0.13922,12.71814,40.84844
49.01000,4.08422,756.90225,-0.13922,12.75186,40.85622
49.11000,4.09241,757.58924,-0.13922,12.78462,40.89330
49.21000,4.10078,758.46142,-0.13922,12.81810,40.94038
49.31000,4.10921,757.73741,-0.13922,12.85183,40.90129
49.41000,4.11746,758.07255,-0.13922,12.88483,40.91939
49.51000,4.12583,757.89434,-0.13922,12.91831,40.90977
49.61000,4.13420,758.56755,-0.13922,12.95179,40.94611
49.71000,4.14245,759.04089,-0.13922,12.98480,40.97166
49.81000,4.15083,759.34622,-0.13922,13.01828,40.98814
49.91000,4.15920,759.74143,-0.13922,13.05176,41.00947
50.01000,4.16745,759.81445,-0.13922,13.08477,41.01341
50.11000,4.17582,760.11661,-0.13922,13.11825,41.02972
50.21000,4.18419,760.18381,-0.13922,13.15173,41.03335
50.31000,4.19238,760.62405,-0.13922,13.18450,41.05711
50.41000,4.20081,760.79951,-0.13922,13.21822,41.06658
50.51000,4.20918,761.55341,-0.13922,13.25170,41.10728
50.61000,4.21749,761.29930,-0.13922,13.28494,41.09356
50.71000,4.22598,761.76762,-0.13922,13.31890,41.11884
50.81000,4.23417,761.76347,-0.13922,13.35167,41.11861
50.91000,4.24242,762.28408,-0.13922,13.38467,41.14672
51.01000,4.25085,762.62816,-0.13922,13.41839,41.16529
51.11000,4.25910,763.02439,-0.13922,13.45139,41.18668
51.21000,4.26747,763.13331,-0.13922,13.48488,41.19256
51.31000,4.27591,762.71994,-0.13922,13.51860,41.17024
51.41000,4.28416,763.37499,-0.13922,13.55160,41.20560
51.51000,4.29247,763.13224,-0.13922,13.58484,41.19250
51.61000,4.30090,764.21052,-0.13922,13.61857,41.25070
51.71000,4.30915,763.88614,-0.13922,13.65157,41.23319
51.81000,4.31746,764.13979,-0.13922,13.68481,41.24688
51.91000,4.32595,764.82072,-0.13922,13.71877,41.28364
52.01000,4.33414,764.45634,-0.13922,13.75154,41.26397
52.11000,4.34245,765.39870,-0.13922,13.78478,41.31484
52.21000,4.35088,765.17207,-0.13922,13.81850,41.30260
52.31000,4.35913,765.35358,-0.13922,13.85151,41.31240
52.41000,4.36750,765.75987,-0.13922,13.88499,41.33434
52.51000,4.37587,765.74618,-0.13922,13.91847,41.33360
52.61000,4.38412,766.39345,-0.13922,13.95147,41.36853
52.71000,4.39255,766.47312,-0.13922,13.98520,41.37283
52.81000,4.40081,766.30209,-0.13922,14.01820,41.36360
52.91000,4.40918,766.46148,-0.13922,14.05168,41.37220
53.01000,4.41761,766.93823,-0.13922,14.08540,41.39794
53.11000,4.42580,767.00207,-0.13922,14.11817,41.40139
53.21000,4.43417,767.07928,-0.13922,14.15165,41.40555
53.31000,4.44248,767.82363,-0.13922,14.18489,41.44573
53.41000,4.45079,767.67961,-0.13922,14.21814,41.43796
53.51000,4.45916,767.46573,-0.13922,14.25162,41.42641
53.61000,4.46753,767.95509,-0.13922,14.28510,41.45283
53.71000,4.47578,768.13954,-0.13922,14.31810,41.46278
53.81000,4.48415,768.70611,-0.13922,14.35159,41.49337
53.91000,4.49258,769.18090,-0.13922,14.38531,41.51899
54.01000,4.50083,769.04916,-0.13922,14.41831,41.51188
54.11000,4.50914,768.96022,-0.13922,14.45155,41.50708
54.21000,4.51745,769.50290,-0.13922,14.48480,41.53638
54.31000,4.52577,769.94933,-0.13922,14.51804,41.56047
54.41000,4.53414,769.89662,-0.13922,14.55152,41.55763
54.51000,4.54245,770.13038,-0.13922,14.58476,41.57025
54.61000,4.55076,770.32335,-0.13922,14.61801,41.58066
54.71000,4.55913,770.00428,-0.13922,14.65149,41.56344
54.81000,4.56744,770.72675,-0.13922,14.68473,41.60244
54.91000,4.57581,770.70775,-0.13922,14.71822,41.60141
55.01000,4.58424,770.86110,-0.13922,14.75194,41.60969
55.11000,4.59255,771.30930,-0.13922,14.78518,41.63388
55.21000,4.60086,771.21090,-0.13922,14.81842,41.62857
55.31000,4.60917,771.14026,-0.13923,14.85167,41.62476
55.41000,4.61748,771.41314,-0.13923,14.88491,41.63949
55.51000,4.62585,771.63992,-0.13922,14.91839,41.65173
55.61000,4.63422,772.13882,-0.13922,14.95187,41.67866
55.71000,4.64247,772.33035,-0.13922,14.98488,41.68900
55.81000,4.65085,772.48174,-0.13922,15.01836,41.69717
55.91000,4.65922,772.75583,-0.13922,15.05184,41.71196
56.01000,4.66753,772.08527,-0.13922,15.08508,41.67577
56.11000,4.67590,773.24021,-0.13922,15.11856,41.73811
56.21000,4.68427,772.84528,-0.13923,15.15205,41.71679
56.31000,4.69252,773.38330,-0.13922,15.18505,41.74583
56.41000,4.70083,773.15778,-0.13923,15.21830,41.73366
56.51000,4.70920,773.64151,-0.13922,15.25178,41.75977
56.61000,4.71745,773.80161,-0.13922,15.28478,41.76841
56.71000,4.72582,773.83057,-0.13922,15.31826,41.76998
56.81000,4.73407,774.15402,-0.13922,15.35126,41.78743
56.91000,4.74244,774.20804,-0.13922,15.38475,41.79035
57.01000,4.75081,774.50164,-0.13922,15.41823,41.80620
57.11000,4.75918,774.64269,-0.13922,15.45171,41.81381
57.21000,4.76749,774.63640,-0.13922,15.48495,41.81347
57.31000,4.77586,775.07836,-0.13922,15.51844,41.83733
57.41000,4.78412,774.86043,-0.13923,15.55144,41.82557
57.51000,4.79243,775.23128,-0.13922,15.58468,41.84558
57.61000,4.80086,774.85531,-0.13922,15.61840,41.82529
57.71000,4.80911,775.24344,-0.13922,15.65141,41.84624
57.81000,4.81748,775.95785,-0.13922,15.68489,41.88480
57.91000,4.82591,775.94421,-0.13922,15.71861,41.88407
58.01000,4.83422,775.65699,-0.13923,15.75186,41.86856
58.11000,4.84259,775.83492,-0.13922,15.78534,41.87817
58.21000,4.85096,775.73564,-0.13922,15.81882,41.87281
58.31000,4.85915,776.53471,-0.13922,15.85159,41.91594
58.41000,4.86752,777.06869,-0.13922,15.88507,41.94476
58.51000,4.87589,777.20294,-0.13922,15.91855,41.95201
58.61000,4.88420,776.89164,-0.13922,15.95179,41.93521
58.71000,4.89245,776.71274,-0.13922,15.98480,41.92555
58.81000,4.90082,777.41486,-0.13922,16.01828,41.96345
58.91000,4.90908,776.91586,-0.13922,16.05128,41.93652
59.01000,4.91745,777.07730,-0.13923,16.08476,41.94523
59.11000,4.92588,777.58846,-0.13922,16.11848,41.97282
59.21000,4.93413,777.23297,-0.13922,16.15149,41.95363
59.31000,4.94256,777.88206,-0.13922,16.18521,41.98867
59.41000,4.95081,777.16252,-0.13922,16.21821,41.94983
59.51000,4.95912,777.66548,-0.13922,16.25146,41.97698
59.61000,4.96749,777.90511,-0.13922,16.28494,41.98991
59.71000,4.97574,778.72248,-0.13923,16.31794,42.03403
59.81000,4.98411,778.23191,-0.13922,16.35143,42.00755
59.91000,4.99254,778.71848,-0.13923,16.38515,42.03382
60.01000,5.00079,778.76551,-0.13922,16.41815,42.03635
60.11000,5.00916,778.81794,-0.13923,16.45163,42.03918
60.21000,5.01753,779.04067,-0.13923,16.48511,42.05121
60.31000,5.02585,779.09832,-0.13923,16.51836,42.05432
60.41000,5.03422,779.30042,-0.13922,16.55184,42.06523
60.51000,5.04259,779.70335,-0.13922,16.58532,42.08698
60.61000,5.05084,779.33464,-0.13922,16.61833,42.06707
60.71000,5.05915,779.69246,-0.13923,16.65157,42.08639
60.81000,5.06746,779.56324,-0.13922,16.68481,42.07941
60.91000,5.07583,780.22666,-0.13922,16.71829,42.11523
61.01000,5.08414,780.19276,-0.13923,16.75154,42.11340
61.11000,5.09251,779.84887,-0.13923,16.78502,42.09483
61.21000,5.10076,779.88426,-0.13923,16.81802,42.09674
61.31000,5.10919,780.15421,-0.13922,16.85174,42.11131
61.41000,5.11750,780.56422,-0.13923,16.88498,42.13345
61.51000,5.12581,780.29712,-0.13923,16.91823,42.11903
61.61000,5.13412,780.94373,-0.13922,16.95147,42.15393
61.71000,5.14237,780.06978,-0.13923,16.98447,42.10676
61.81000,5.15080,780.65759,-0.13922,17.01820,42.13848
61.91000,5.15918,780.74848,-0.13922,17.05168,42.14339
62.01000,5.16749,781.02946,-0.13922,17.08492,42.15856
62.11000,5.17580,780.60557,-0.13922,17.11816,42.13568
62.21000,5.18417,781.14304,-0.13922,17.15165,42.16469
62.31000,5.19242,780.99985,-0.13922,17.18465,42.15696
62.41000,5.20085,781.65997,-0.13922,17.21837,42.19259
62.51000,5.20916,782.32558,-0.13922,17.25162,42.22852
62.61000,5.21753,782.07385,-0.13922,17.28510,42.21493
62.71000,5.22584,781.24404,-0.13923,17.31834,42.17014
62.81000,5.23415,782.41574,-0.13922,17.35158,42.23339
62.91000,5.24246,781.93992,-0.13922,17.38483,42.20770
63.01000,5.25077,782.01359,-0.13922,17.41807,42.21168
63.11000,5.25914,782.06537,-0.13922,17.45155,42.21447
63.21000,5.26745,782.33527,-0.13923,17.48479,42.22905
63.31000,5.27582,782.71264,-0.13923,17.51827,42.24941
63.41000,5.28420,782.45914,-0.13922,17.55176,42.23573
63.51000,5.29251,782.70491,-0.13922,17.58500,42.24900
63.61000,5.30088,783.26715,-0.13923,17.61848,42.27935
63.71000,5.30919,782.67902,-0.13922,17.65173,42.24760
63.81000,5.31750,782.50645,-0.13923,17.68497,42.23829
63.91000,5.32587,782.63404,-0.13922,17.71845,42.24517
64.01000,5.33412,783.41961,-0.13922,17.75145,42.28757
64.11000,5.34243,783.50129,-0.13922,17.78470,42.29198
64.21001,5.35086,783.95484,-0.13922,17.81842,42.31647
64.31000,5.35911,783.48722,-0.13922,17.85142,42.29123
64.41000,5.36748,783.08722,-0.13923,17.88491,42.26963
64.51000,5.37591,783.47633,-0.13922,17.91863,42.29064
64.61000,5.38416,783.54413,-0.13922,17.95163,42.29430
64.71001,5.39241,783.12168,-0.13922,17.98463,42.27149
64.81000,5.40084,783.69742,-0.13923,18.01835,42.30257
64.91000,5.40910,783.83060,-0.13922,18.05136,42.30976
65.01000,5.41747,783.86255,-0.13922,18.08484,42.31149
65.11000,5.42590,783.98120,-0.13922,18.11856,42.31789
65.21001,5.43409,784.47461,-0.13923,18.15133,42.34452
65.31000,5.44246,784.22418,-0.13922,18.18481,42.33101
65.41000,5.45083,784.25817,-0.13922,18.21829,42.33284
65.51000,5.45914,783.67218,-0.13923,18.25153,42.30121
65.61000,5.46751,784.12825,-0.13923,18.28502,42.32582
65.71001,5.47594,784.71331,-0.13923,18.31874,42.35741
65.81001,5.48419,784.20602,-0.13922,18.35174,42.33002
65.91000,5.49256,785.02633,-0.13923,18.38522,42.37430
66.01000,5.50087,785.02018,-0.13923,18.41847,42.37397
66.11000,5.50912,783.74343,-0.13922,18.45147,42.30505
66.21001,5.51749,783.33449,-0.13923,18.48495,42.28298
66.31001,5.52580,783.45127,-0.13923,18.51820,42.28928
66.41000,5.53418,783.70171,-0.13923,18.55168,42.30280
66.51000,5.54261,783.92932,-0.13922,18.58540,42.31509
66.61000,5.55086,783.73225,-0.13923,18.61840,42.30445
66.71001,5.55917,784.36285,-0.13923,18.65165,42.33849
66.81001,5.56760,784.83028,-0.13922,18.68537,42.36372
66.91000,5.57585,784.28285,-0.13923,18.71837,42.33417
67.01000,5.58416,784.77953,-0.13923,18.75162,42.36098
67.11000,5.59253,784.51801,-0.13923,18.78510,42.34686
67.21001,5.60084,785.04793,-0.13922,18.81834,42.37547
67.31001,5.60915,785.18046,-0.13922,18.85158,42.38262
67.41000,5.61752,784.98926,-0.13923,18.88506,42.37230
67.51000,5.62583,785.29967,-0.13922,18.91831,42.38906
67.61000,5.63414,785.30395,-0.13923,18.95155,42.38929
67.71001,5.64251,785.19806,-0.13923,18.98503,42.38357
67.81001,5.65082,785.67090,-0.13923,19.01827,42.40910
67.91000,5.65914,785.68663,-0.13923,19.05152,42.40995
68.01000,5.66745,785.45129,-0.13923,19.08476,42.39724
68.11000,5.67582,786.17418,-0.13923,19.11824,42.43626
68.21001,5.68413,786.11169,-0.13922,19.15149,42.43289
68.31001,5.69244,786.36426,-0.13922,19.18473,42.44652
68.41000,5.70075,786.10014,-0.13923,19.21797,42.43227
68.51000,5.70918,785.98596,-0.13923,19.25169,42.42610
68.61000,5.71743,786.09772,-0.13922,19.28470,42.43213
68.71001,5.72574,786.50396,-0.13922,19.31794,42.45406
68.81001,5.73423,786.56264,-0.13923,19.35190,42.45723
68.91000,5.74254,786.91170,-0.13922,19.38514,42.47607
69.01000,5.75085,787.03472,-0.13922,19.41839,42.48271
69.11000,5.75922,786.70895,-0.13922,19.45187,42.46513
69.21001,5.76747,786.07779,-0.13923,19.48487,42.43106
69.31001,5.77578,786.56850,-0.13922,19.51811,42.45755
69.41000,5.78421,786.20734,-0.13923,19.55184,42.43805
69.51000,5.79247,787.01852,-0.13922,19.58484,42.48184
69.61000,5.80078,786.96432,-0.13922,19.61808,42.47891
69.71001,5.80915,787.12264,-0.13922,19.65156,42.48746
69.81001,5.81752,786.96329,-0.13923,19.68505,42.47886
69.91000,5.82589,787.27501,-0.13922,19.71853,42.49568
70.01000,5.83420,786.91607,-0.13923,19.75177,42.47631
70.11000,5.84251,787.35268,-0.13923,19.78502,42.49987
70.21001,5.85082,786.97270,-0.13923,19.81826,42.47936
70.31001,5.85919,787.14229,-0.13923,19.85174,42.48852
70.41000,5.86738,787.25033,-0.13922,19.88450,42.49435
70.51000,5.87581,787.14257,-0.13923,19.91823,42.48853
70.61000,5.88412,786.86178,-0.13923,19.95147,42.47338
70.71001,5.89243,786.90760,-0.13923,19.98471,42.47585
70.81001,5.90086,787.06155,-0.13923,20.01843,42.48416
70.91000,5.90917,786.90480,-0.13922,20.05167,42.47570
71.01000,5.91755,786.91179,-0.13923,20.08516,42.47608
71.11000,5.92592,786.96758,-0.13923,20.11864,42.47909
71.21001,5.93411,787.28646,-0.13923,20.15141,42.49630
71.31001,5.94242,786.88394,-0.13922,20.18465,42.47458
71.41000,5.95091,787.11594,-0.13923,20.21861,42.48709
71.51000,5.95916,786.79072,-0.13923,20.25161,42.46954
71.61000,5.96747,787.44069,-0.13923,20.28486,42.50462
71.71001,5.97590,786.66974,-0.13923,20.31858,42.46301
71.81001,5.98415,787.68283,-0.13922,20.35158,42.51770
71.91000,5.99252,786.82834,-0.13923,20.38506,42.47157
72.01000,6.00095,786.77908,-0.13923,20.41878,42.46891
72.11000,6.00914,786.51207,-0.13923,20.45155,42.45450
72.21001,6.01751,786.55882,-0.13922,20.48503,42.45702
72.31001,6.02588,786.41484,-0.13923,20.51851,42.44925
72.41000,6.03408,785.33525,-0.13923,20.55128,42.39098
72.51000,6.04251,785.01143,-0.13923,20.58500,42.37350
72.61000,6.05082,784.08029,-0.13922,20.61824,42.32324
72.71001,6.05913,440.15739,-0.13923,20.65148,23.75890
72.74201,6.06188,0.31311,-0.13923,20.66249,0.01690