File: Manufatura Aditiva/Dados/Ensaios AMR/Ensaios/Ensaios SLS/Tracao_OLABI_08_06_2018_SLS_ZY6.is_metal_RawData/Specimen_RawData_3.csv
Time,Extension,Load,Strain 1,Tensile strain,Tensile stress
(sec),(mm),(N),(mm/mm),(%),(MPa)
0.00000,0.00006,32.37290,0.00113,0.11296,1.74153
0.10000,0.00419,33.62777,0.00116,0.11645,1.80903
0.20000,0.01381,38.12428,0.00132,0.13160,2.05093
0.30000,0.02362,42.96277,0.00148,0.14767,2.31122
0.40000,0.03270,47.56484,0.00163,0.16325,2.55879
0.50000,0.04143,52.60702,0.00178,0.17772,2.83004
0.60000,0.04986,57.09100,0.00193,0.19296,3.07126
0.70000,0.05818,60.80178,0.00207,0.20690,3.27088
0.80000,0.06673,65.33412,0.00221,0.22118,3.51470
0.90000,0.07498,69.99185,0.00235,0.23513,3.76527
1.00000,0.08329,73.00097,0.00249,0.24947,3.92715
1.10000,0.09178,78.22939,0.00263,0.26347,4.20842
1.20000,0.10003,82.16491,0.00278,0.27758,4.42013
1.30000,0.10840,86.14091,0.00291,0.29144,4.63402
1.40000,0.11683,90.53239,0.00306,0.30597,4.87027
1.50000,0.12496,94.28375,0.00320,0.31957,5.07207
1.60000,0.13333,98.42312,0.00334,0.33430,5.29475
1.70000,0.14170,102.31698,0.00348,0.34836,5.50423
1.80000,0.14989,105.96823,0.00362,0.36208,5.70065
1.90000,0.15832,110.19398,0.00376,0.37616,5.92798
2.00000,0.16663,114.21867,0.00390,0.39043,6.14449
2.10000,0.17494,118.11191,0.00405,0.40456,6.35393
2.20000,0.18331,121.26801,0.00418,0.41844,6.52371
2.30000,0.19163,125.32824,0.00433,0.43306,6.74214
2.40000,0.19994,129.40924,0.00446,0.44636,6.96168
2.50000,0.20837,131.17840,0.00456,0.45624,7.05685
2.60000,0.21668,135.83469,0.00471,0.47058,7.30734
2.70000,0.22493,139.04574,0.00484,0.48411,7.48008
2.80000,0.23336,142.37448,0.00498,0.49808,7.65915
2.90000,0.24167,146.36429,0.00512,0.51233,7.87379
3.00000,0.24992,150.25589,0.00526,0.52610,8.08314
3.10000,0.25841,153.99010,0.00541,0.54118,8.28403
3.20000,0.26666,157.43051,0.00556,0.55557,8.46911
3.30000,0.27497,161.64520,0.00570,0.56965,8.69584
3.40000,0.28340,165.69016,0.00584,0.58381,8.91344
3.50000,0.29171,168.64581,0.00598,0.59778,9.07244
3.60000,0.30002,172.42851,0.00612,0.61240,9.27594
3.70000,0.30839,176.60599,0.00627,0.62675,9.50067
3.80000,0.31665,179.80841,0.00641,0.64063,9.67294
3.90000,0.32502,183.63923,0.00655,0.65521,9.87903
4.00000,0.33333,187.42525,0.00669,0.66935,10.08270
4.10000,0.34164,191.41258,0.00684,0.68361,10.29720
4.20000,0.34995,194.94109,0.00697,0.69728,10.48702
4.30000,0.35826,197.75932,0.00712,0.71156,10.63863
4.40000,0.36657,202.04755,0.00726,0.72580,10.86932
4.50000,0.37500,205.02058,0.00740,0.73980,11.02925
4.60000,0.38331,209.34122,0.00755,0.75478,11.26169
4.70000,0.39162,212.43617,0.00768,0.76844,11.42818
4.80000,0.39999,216.77017,0.00783,0.78298,11.66133
4.90000,0.40824,219.95602,0.00797,0.79660,11.83272
5.00000,0.41667,223.07017,0.00811,0.81068,12.00025
5.10000,0.42504,226.98848,0.00825,0.82544,12.21103
5.20000,0.43335,230.55202,0.00839,0.83937,12.40274
5.30000,0.44166,233.41491,0.00854,0.85379,12.55675
5.40000,0.45010,237.62833,0.00869,0.86934,12.78341
5.50000,0.45829,241.11068,0.00883,0.88314,12.97075
5.60000,0.46666,244.11348,0.00897,0.89728,13.13229
5.70000,0.47503,248.16764,0.00911,0.91098,13.35039
5.80000,0.48334,251.62047,0.00925,0.92524,13.53613
5.90000,0.49171,255.21335,0.00939,0.93931,13.72941
6.00000,0.50002,258.72560,0.00954,0.95441,13.91836
6.10000,0.50827,260.54487,0.00965,0.96508,14.01623
6.20000,0.51664,263.56189,0.00979,0.97924,14.17853
6.30000,0.52501,267.50786,0.00994,0.99398,14.39081
6.40000,0.53326,270.49980,0.01008,1.00814,14.55176
6.50000,0.54169,274.33191,0.01023,1.02257,14.75791
6.60000,0.55000,277.60298,0.01037,1.03711,14.93388
6.70000,0.55831,280.81755,0.01051,1.05113,15.10681
6.80000,0.56674,283.99017,0.01066,1.06566,15.27749
6.90000,0.57500,287.61437,0.01080,1.08048,15.47246
7.00000,0.58331,291.07097,0.01095,1.09456,15.65841
7.10000,0.59174,294.69235,0.01109,1.10918,15.85322
7.20000,0.59993,297.02038,0.01123,1.12346,15.97846
7.30000,0.60818,300.74199,0.01138,1.13796,16.17867
7.40000,0.61673,304.04888,0.01153,1.15277,16.35656
7.50000,0.62492,307.10301,0.01167,1.16710,16.52086
7.60000,0.63329,310.75731,0.01182,1.18174,16.71745
7.70000,0.64178,313.11307,0.01196,1.19615,16.84418
7.80000,0.64997,316.63519,0.01211,1.21074,17.03366
7.90000,0.65828,319.74341,0.01225,1.22478,17.20086
8.00000,0.66677,323.68230,0.01240,1.23981,17.41276
8.10000,0.67496,326.04649,0.01255,1.25477,17.53994
8.20000,0.68333,329.04539,0.01269,1.26949,17.70127
8.30000,0.69176,332.80412,0.01285,1.28452,17.90347
8.40000,0.70002,335.56384,0.01299,1.29895,18.05194
8.50000,0.70839,339.01818,0.01313,1.31340,18.23777
8.60000,0.71664,341.94421,0.01328,1.32820,18.39517
8.70000,0.72489,344.26912,0.01343,1.34270,18.52024
8.80000,0.73344,347.92561,0.01358,1.35761,18.71695
8.90000,0.74169,350.41261,0.01373,1.37297,18.85074
9.00000,0.75000,353.80013,0.01387,1.38749,19.03297
9.10000,0.75843,355.60401,0.01399,1.39851,19.13001
9.20000,0.76668,358.74799,0.01414,1.41353,19.29915
9.30000,0.77493,361.35486,0.01428,1.42767,19.43939
9.40000,0.78336,364.89994,0.01442,1.44247,19.63010
9.50000,0.79161,366.93453,0.01458,1.45766,19.73955
9.60000,0.79992,369.89569,0.01473,1.47271,19.89885
9.70000,0.80835,372.54111,0.01488,1.48775,20.04116
9.80000,0.81660,375.53466,0.01503,1.50269,20.20220
9.90000,0.82498,378.93190,0.01518,1.51762,20.38496
10.00000,0.83341,381.25953,0.01533,1.53272,20.51017
10.10000,0.84166,384.22020,0.01547,1.54725,20.66945
10.20000,0.84991,386.80320,0.01562,1.56229,20.80840
10.30000,0.85840,389.81831,0.01577,1.57683,20.97060
10.40000,0.86665,392.09467,0.01592,1.59193,21.09306
10.50000,0.87502,394.69618,0.01606,1.60636,21.23301
10.60000,0.88333,397.73048,0.01622,1.62187,21.39624
10.70000,0.89164,401.04673,0.01637,1.63717,21.57464
10.80000,0.90007,403.75432,0.01652,1.65219,21.72030
10.90000,0.90832,405.98102,0.01668,1.66757,21.84009
11.00000,0.91669,408.50113,0.01683,1.68261,21.97566
11.10000,0.92506,411.66283,0.01698,1.69789,22.14575
11.20000,0.93331,413.90988,0.01713,1.71308,22.26663
11.30000,0.94162,416.18706,0.01728,1.72810,22.38913
11.40000,0.95000,419.22173,0.01743,1.74336,22.55238
11.50000,0.95825,421.87558,0.01759,1.75886,22.69515
11.60000,0.96656,424.07410,0.01775,1.77462,22.81342
11.70000,0.97499,426.78774,0.01790,1.79016,22.95940
11.80000,0.98336,428.82762,0.01806,1.80592,23.06914
11.90000,0.99161,431.81051,0.01821,1.82098,23.22961
12.00000,1.00010,433.36125,0.01833,1.83340,23.31303
12.10000,1.00835,435.76593,0.01847,1.84711,23.44239
12.20000,1.01666,437.67067,0.01862,1.86235,23.54486
12.30000,1.02509,440.41635,0.01878,1.87797,23.69256
12.40000,1.03328,442.63029,0.01894,1.89407,23.81166
12.50000,1.04165,444.92511,0.01910,1.90986,23.93512
12.60000,1.05002,447.18711,0.01926,1.92553,24.05680
12.70000,1.05827,450.20976,0.01941,1.94124,24.21941
12.80000,1.06664,452.72866,0.01956,1.95627,24.35492
12.90000,1.07502,455.67551,0.01972,1.97205,24.51344
13.00000,1.08333,457.19189,0.01988,1.98797,24.59502
13.10000,1.09176,459.47852,0.02004,2.00360,24.71803
13.20000,1.10001,461.61152,0.02020,2.01958,24.83278
13.30000,1.10838,464.20898,0.02035,2.03514,24.97251
13.40000,1.11675,466.15400,0.02051,2.05113,25.07714
13.50000,1.12500,468.21325,0.02067,2.06669,25.18792
13.60000,1.13325,471.04219,0.02083,2.08293,25.34011
13.70000,1.14168,473.32649,0.02099,2.09858,25.46299
13.80000,1.14999,475.45945,0.02115,2.11470,25.57774
13.90000,1.15824,477.82836,0.02131,2.13058,25.70518
14.00000,1.16673,480.04026,0.02147,2.14678,25.82417
14.10000,1.17498,481.93526,0.02163,2.16288,25.92611
14.20000,1.18329,483.96396,0.02179,2.17881,26.03525
14.30000,1.19178,486.26787,0.02195,2.19508,26.15919
14.40000,1.19998,488.43566,0.02211,2.21107,26.27580
14.50000,1.20829,490.66450,0.02227,2.22722,26.39571
14.60000,1.21672,492.83896,0.02244,2.24392,26.51268
14.70000,1.22491,494.18309,0.02259,2.25949,26.58499
14.80000,1.23334,496.82003,0.02276,2.27602,26.72685
14.90000,1.24171,498.71379,0.02292,2.29236,26.82872
15.00000,1.24996,500.55832,0.02309,2.30923,26.92795
15.10000,1.25833,503.06595,0.02326,2.32551,27.06285
15.20000,1.26670,504.93930,0.02342,2.34184,27.16363
15.30000,1.27495,506.60567,0.02358,2.35773,27.25327
15.40000,1.28338,507.18491,0.02369,2.36899,27.28444
15.50000,1.29175,509.32867,0.02385,2.38521,27.39976
15.60000,1.29994,510.98145,0.02402,2.40186,27.48867
15.70000,1.30837,512.79780,0.02418,2.41832,27.58639
15.80000,1.31662,515.22781,0.02435,2.43540,27.71711
15.90000,1.32488,517.06843,0.02452,2.45162,27.81613
16.00000,1.33343,518.79045,0.02469,2.46859,27.90876
16.10000,1.34162,520.52801,0.02485,2.48515,28.00224
16.20000,1.34993,521.99634,0.02502,2.50170,28.08123
16.30000,1.35848,524.34038,0.02518,2.51832,28.20733
16.40000,1.36667,525.93108,0.02535,2.53531,28.29290
16.50000,1.37504,527.92751,0.02552,2.55198,28.40030
16.60000,1.38341,529.36636,0.02569,2.56923,28.47771
16.70000,1.39160,530.33638,0.02586,2.58555,28.52989
16.80000,1.39997,533.03386,0.02602,2.60209,28.67500
16.90000,1.40840,534.28747,0.02619,2.61919,28.74244
17.00000,1.41659,536.48409,0.02636,2.63612,28.86061
17.10000,1.42496,537.74873,0.02653,2.65272,28.92864
17.20000,1.43333,539.31200,0.02670,2.66976,29.01274
17.30000,1.44164,541.29711,0.02686,2.68645,29.11953
17.40000,1.45001,542.76185,0.02704,2.70352,29.19833
17.50000,1.45839,544.09034,0.02721,2.72084,29.26979
17.60000,1.46664,545.22590,0.02737,2.73743,29.33088
17.70000,1.47501,548.03146,0.02755,2.75451,29.48181
17.80000,1.48320,548.49894,0.02772,2.77153,29.50696
17.90000,1.49157,550.45388,0.02788,2.78805,29.61213
18.00000,1.50000,552.23508,0.02805,2.80502,29.70795
18.10000,1.50819,553.54675,0.02822,2.82216,29.77851
18.20000,1.51656,555.61014,0.02840,2.83960,29.88951
18.30000,1.52505,556.83772,0.02857,2.85699,29.95555
18.40000,1.53336,558.22022,0.02874,2.87353,30.02992
18.50000,1.54167,559.34712,0.02890,2.89047,30.09055
18.60000,1.55004,561.15300,0.02908,2.90785,30.18769
18.70000,1.55829,562.70370,0.02925,2.92502,30.27111
18.80000,1.56666,563.71181,0.02942,2.94223,30.32535
18.90000,1.57509,565.94792,0.02960,2.95982,30.44564
19.00000,1.58335,567.36604,0.02977,2.97733,30.52193
19.10000,1.59166,568.18612,0.02994,2.99403,30.56605
19.20000,1.60003,569.87545,0.03012,3.01153,30.65693
19.30000,1.60834,571.56463,0.03029,3.02928,30.74780
19.40000,1.61665,572.88506,0.03046,3.04608,30.81883
19.50000,1.62502,574.45010,0.03063,3.06338,30.90302
19.60000,1.63333,575.30021,0.03081,3.08103,30.94876
19.70000,1.64176,575.36610,0.03094,3.11475,30.95230
19.80000,1.65001,577.78982,0.03110,3.14776,31.08269
19.90000,1.65832,577.80202,0.03127,3.18100,31.08334
19.92400,1.66029,578.46992,0.03131,3.18889,31.11927
20.02400,1.66866,580.04200,0.03149,3.22238,31.20384
20.12400,1.67692,581.40866,0.03166,3.25538,31.27736
20.22400,1.68529,583.16709,0.03184,3.28886,31.37196
20.32400,1.69372,583.96393,0.03201,3.32258,31.41483
20.42400,1.70191,585.11728,0.03218,3.35535,31.47687
20.52400,1.71034,587.02989,0.03235,3.38907,31.57976
20.62400,1.71871,587.98022,0.03253,3.42255,31.63089
20.72400,1.72696,589.19471,0.03271,3.45555,31.69622
20.82400,1.73533,590.84818,0.03288,3.48904,31.78517
20.92400,1.74364,591.97140,0.03305,3.52228,31.84559
21.02400,1.75195,593.18957,0.03323,3.55552,31.91113
21.12400,1.76032,594.60192,0.03341,3.58900,31.98711
21.22400,1.76869,595.39736,0.03359,3.62249,32.02990
21.32400,1.77700,596.71407,0.03376,3.65573,32.10073
21.42400,1.78531,597.67519,0.03400,3.68897,32.15244
21.52400,1.79368,598.77159,0.03366,3.72245,32.21142
21.62400,1.80200,599.77635,0.03482,3.75570,32.26547
21.72400,1.81043,601.51634,0.03424,3.78942,32.35907
21.82400,1.81874,602.57805,0.02966,3.82266,32.41619
21.92400,1.82705,602.92645,0.00194,3.85590,32.43493
22.02400,1.83542,603.67906,0.00290,3.88939,32.47542
22.12400,1.84367,605.05685,0.00249,3.92239,32.54954
22.22400,1.85192,605.45187,0.00179,3.95540,32.57079
22.32400,1.86035,607.00518,0.00149,3.98912,32.65435
22.42400,1.86866,609.17009,0.00086,4.02236,32.77081
22.52400,1.87697,609.84674,-0.00058,4.05560,32.80721
22.62400,1.88540,610.80740,-0.00076,4.08932,32.85889
22.72400,1.89359,612.56015,-0.00045,4.12209,32.95318
22.82400,1.90190,613.09803,-0.00024,4.15533,32.98212
22.92400,1.91033,614.33832,0.00075,4.18905,33.04884
23.02400,1.91864,615.82793,-0.01643,4.22230,33.12898
23.12400,1.92696,616.73936,-0.14043,4.25554,33.17801
23.22400,1.93539,617.64740,-0.13893,4.28926,33.22686
23.32400,1.94364,618.46823,-0.13900,4.32226,33.27102
23.42400,1.95201,619.54707,-0.13901,4.35575,33.32905
23.52400,1.96038,620.90000,-0.13900,4.38923,33.40183
23.62400,1.96863,621.35160,-0.13901,4.42223,33.42613
23.72400,1.97700,623.32661,-0.13901,4.45571,33.53238
23.82400,1.98537,623.65760,-0.13901,4.48919,33.55018
23.92400,1.99374,625.07386,-0.13901,4.52268,33.62637
24.02400,2.00211,626.42437,-0.13901,4.55616,33.69902
24.12400,2.01030,627.59900,-0.13902,4.58892,33.76221
24.22400,2.01861,628.08534,-0.13902,4.62217,33.78838
24.32400,2.02704,628.95766,-0.13902,4.65589,33.83530
24.42400,2.03535,630.20592,-0.13901,4.68913,33.90245
24.52400,2.04366,631.05072,-0.13902,4.72237,33.94790
24.62400,2.05203,631.89692,-0.13902,4.75586,33.99342
24.72400,2.06035,633.71100,-0.13902,4.78910,34.09101
24.82400,2.06866,634.41992,-0.13902,4.82234,34.12915
24.92400,2.07703,635.11590,-0.13902,4.85582,34.16659
25.02400,2.08534,636.31623,-0.13902,4.88907,34.23116
25.12400,2.09365,637.43661,-0.13902,4.92231,34.29144
25.22400,2.10196,637.89063,-0.13902,4.95555,34.31586
25.32400,2.11027,638.96389,-0.13902,4.98880,34.37360
25.42400,2.11858,639.78429,-0.13902,5.02204,34.41773
25.52400,2.12695,640.48092,-0.13902,5.05552,34.45520
25.62400,2.13526,641.97765,-0.13902,5.08876,34.53572
25.72400,2.14357,641.66998,-0.13902,5.12201,34.51917
25.82400,2.15194,642.67777,-0.13902,5.15549,34.57339
25.92400,2.16037,643.27810,-0.13902,5.18921,34.60568
26.02400,2.16874,644.79671,-0.13903,5.22269,34.68738
26.12400,2.17700,645.49833,-0.13902,5.25570,34.72512
26.22400,2.18537,646.85200,-0.13902,5.28918,34.79794
26.32400,2.19368,647.37774,-0.13902,5.32242,34.82623
26.42400,2.20199,648.82128,-0.13902,5.35566,34.90388
26.52400,2.21036,649.81519,-0.13903,5.38915,34.95735
26.62400,2.21867,650.49324,-0.13902,5.42239,34.99383
26.72400,2.22698,651.50117,-0.13902,5.45563,35.04805
26.82400,2.23535,652.04026,-0.13903,5.48912,35.07705
26.92400,2.24372,653.25666,-0.13903,5.52260,35.14249
27.02400,2.25203,653.27594,-0.13903,5.55584,35.14352
27.12400,2.26034,654.46459,-0.13903,5.58908,35.20747
27.22400,2.26871,655.69496,-0.13903,5.62257,35.27366
27.32400,2.27702,656.73306,-0.13903,5.65581,35.32950
27.42400,2.28533,657.22791,-0.13902,5.68905,35.35612
27.52400,2.29370,659.02513,-0.13903,5.72253,35.45281
27.62400,2.30196,659.39110,-0.13903,5.75554,35.47249
27.72400,2.31033,660.88107,-0.13902,5.78902,35.55265
27.82400,2.31870,661.36122,-0.13903,5.82250,35.57848
27.92400,2.32701,661.59135,-0.13903,5.85574,35.59086
28.02400,2.33538,663.18130,-0.13903,5.88923,35.67639
28.12400,2.34363,663.86522,-0.13903,5.92223,35.71318
28.22400,2.35200,664.37176,-0.13903,5.95571,35.74043
28.32400,2.36031,665.60348,-0.13903,5.98895,35.80669
28.42400,2.36862,666.35674,-0.13903,6.02220,35.84722
28.52400,2.37693,667.31600,-0.13903,6.05544,35.89882
28.62400,2.38530,668.13380,-0.13903,6.08892,35.94281
28.72400,2.39361,669.01282,-0.13903,6.12217,35.99010
28.82400,2.40198,669.75662,-0.13903,6.15565,36.03012
28.92400,2.41035,670.27132,-0.13903,6.18913,36.05780
29.02400,2.41860,670.60860,-0.13903,6.22213,36.07595
29.12400,2.42697,671.98575,-0.13903,6.25562,36.15003
29.22400,2.43541,672.83767,-0.13903,6.28934,36.19587
29.32400,2.44372,673.81496,-0.13903,6.32258,36.24844
29.42400,2.45203,674.45030,-0.13903,6.35582,36.28262
29.52400,2.46040,674.90432,-0.13903,6.38931,36.30704
29.62400,2.46865,675.88673,-0.13903,6.42231,36.35989
29.72400,2.47702,676.34792,-0.13903,6.45579,36.38470
29.82400,2.48533,677.66439,-0.13903,6.48903,36.45552
29.92400,2.49364,678.27269,-0.13903,6.52228,36.48824
30.02400,2.50201,679.10464,-0.13903,6.55576,36.53300
30.12400,2.51032,679.51349,-0.13903,6.58900,36.55500
30.22400,2.51863,680.36783,-0.13903,6.62224,36.60096
30.32400,2.52706,681.39676,-0.13903,6.65597,36.65631
30.42400,2.53537,682.24915,-0.13903,6.68921,36.70216
30.52400,2.54368,682.85237,-0.13904,6.72245,36.73461
30.62400,2.55199,683.17079,-0.13903,6.75569,36.75174
30.72400,2.56019,683.59436,-0.13903,6.78846,36.77453
30.82400,2.56862,685.63079,-0.13903,6.82218,36.88408
30.92400,2.57699,685.15176,-0.13903,6.85566,36.85831
31.02400,2.58530,686.35987,-0.13904,6.88891,36.92330
31.12400,2.59361,686.47475,-0.13903,6.92215,36.92948
31.22400,2.60204,687.86149,-0.13903,6.95587,37.00408
31.32400,2.61029,688.67020,-0.13903,6.98887,37.04759
31.42400,2.61866,688.98327,-0.13903,7.02236,37.06443
31.52400,2.62703,690.12842,-0.13904,7.05584,37.12603
31.62400,2.63534,690.69965,-0.13903,7.08908,37.15676
31.72400,2.64365,691.71917,-0.13903,7.12233,37.21161
31.82400,2.65202,691.68871,-0.13903,7.15581,37.20997
31.92400,2.66033,692.94353,-0.13903,7.18905,37.27747
32.02400,2.66858,693.51201,-0.13904,7.22205,37.30806
32.12400,2.67695,694.61805,-0.13903,7.25554,37.36756
32.22400,2.68533,694.21502,-0.13904,7.28902,37.34587
32.32400,2.69370,695.75836,-0.13903,7.32250,37.42890
32.42400,2.70201,695.96614,-0.13903,7.35574,37.44008
32.52400,2.71032,696.60516,-0.13904,7.38899,37.47446
32.62400,2.71875,697.34692,-0.13903,7.42271,37.51436
32.72400,2.72700,697.70832,-0.13904,7.45571,37.53380
32.82400,2.73537,698.94921,-0.13903,7.48919,37.60056
32.92400,2.74368,699.53878,-0.13904,7.52244,37.63227
33.02400,2.75193,699.77012,-0.13904,7.55544,37.64472
33.12400,2.76036,700.42885,-0.13904,7.58916,37.68015
33.22400,2.76873,700.73064,-0.13904,7.62264,37.69639
33.32400,2.77698,702.04334,-0.13904,7.65565,37.76701
33.42400,2.78535,702.63236,-0.13904,7.68913,37.79869
33.52400,2.79372,702.97131,-0.13904,7.72261,37.81693
33.62400,2.80197,703.49304,-0.13904,7.75561,37.84499
33.72400,2.81035,704.79615,-0.13903,7.78910,37.91510
33.82400,2.81866,705.06921,-0.13904,7.82234,37.92979
33.92400,2.82697,705.21683,-0.13904,7.85558,37.93773
34.02400,2.83522,705.58838,-0.13903,7.88859,37.95771
34.12400,2.84365,705.43629,-0.13904,7.92231,37.94954
34.22400,2.85190,706.59039,-0.13904,7.95531,38.01162
34.32400,2.86027,706.95644,-0.13904,7.98879,38.03131
34.42400,2.86876,707.53191,-0.13904,8.02275,38.06227
34.52400,2.87707,708.61317,-0.13904,8.05600,38.12044
34.62400,2.88538,709.05783,-0.13904,8.08924,38.14436
34.72400,2.89369,709.47693,-0.13904,8.12248,38.16690
34.82400,2.90200,710.21756,-0.13904,8.15573,38.20675
34.92400,2.91037,711.28514,-0.13904,8.18921,38.26418
35.02400,2.91862,711.08718,-0.13904,8.22221,38.25353
35.12400,2.92693,712.18386,-0.13904,8.25545,38.31253
35.22400,2.93536,712.61353,-0.13904,8.28918,38.33564
35.32400,2.94362,713.26494,-0.13904,8.32218,38.37068
35.42400,2.95193,713.88218,-0.13904,8.35542,38.40389
35.52400,2.96036,715.04596,-0.13904,8.38914,38.46650
35.62400,2.96867,715.21625,-0.13904,8.42239,38.47565
35.72400,2.97704,716.19647,-0.13904,8.45587,38.52839
35.82400,2.98547,716.08182,-0.13904,8.48959,38.52222
35.92400,2.99366,717.03596,-0.13904,8.52235,38.57355
36.02400,3.00191,716.90492,-0.13904,8.55536,38.56650
36.12400,3.01040,718.01250,-0.13904,8.58932,38.62608
36.22400,3.01859,719.35984,-0.13904,8.62208,38.69856
36.32400,3.02690,718.88142,-0.13904,8.65533,38.67282
36.42400,3.03539,719.07812,-0.13904,8.68929,38.68341
36.52400,3.04358,720.70085,-0.13904,8.72205,38.77070
36.62400,3.05195,721.35134,-0.13904,8.75553,38.80570
36.72400,3.06038,720.98011,-0.13904,8.78925,38.78572
36.82400,3.06870,722.16215,-0.13904,8.82250,38.84932
36.92400,3.07707,723.16714,-0.13904,8.85598,38.90338
37.02400,3.08538,723.36146,-0.13904,8.88922,38.91383
37.12400,3.09357,723.94400,-0.13904,8.92199,38.94517
37.22400,3.10206,724.01688,-0.13904,8.95595,38.94909
37.32400,3.11031,724.71541,-0.13904,8.98895,38.98667
37.42400,3.11862,725.14545,-0.13904,9.02219,39.00980
37.52400,3.12711,725.93396,-0.13904,9.05616,39.05222
37.62400,3.13530,726.11836,-0.13904,9.08892,39.06214
37.72400,3.14367,726.89042,-0.13904,9.12240,39.10368
37.82400,3.15216,727.44801,-0.13904,9.15636,39.13367
37.92400,3.16035,727.90100,-0.13904,9.18913,39.15804
38.02400,3.16860,728.64117,-0.13904,9.22213,39.19786
38.12400,3.17703,728.81249,-0.13904,9.25585,39.20708
38.22400,3.18529,729.37575,-0.13904,9.28886,39.23738
38.32400,3.19360,729.61757,-0.13904,9.32210,39.25039
38.42400,3.20203,729.83205,-0.13904,9.35582,39.26192
38.52400,3.21028,730.76258,-0.13904,9.38882,39.31198
38.62400,3.21859,731.58331,-0.13904,9.42207,39.35614
38.72400,3.22702,732.53824,-0.13904,9.45579,39.40751
38.82400,3.23527,732.28269,-0.13904,9.48879,39.39376
38.92400,3.24364,733.34198,-0.13904,9.52227,39.45074
39.02400,3.25201,733.30980,-0.13904,9.55576,39.44901
39.12400,3.26032,734.21625,-0.13904,9.58900,39.49778
39.22400,3.26869,733.87069,-0.13904,9.62248,39.47919
39.32400,3.27700,734.40047,-0.13904,9.65573,39.50769
39.42400,3.28531,735.43377,-0.13904,9.68897,39.56327
39.52400,3.29368,735.27768,-0.13904,9.72245,39.55487
39.62400,3.30193,736.24728,-0.13904,9.75545,39.60704
39.72400,3.31030,736.65809,-0.13904,9.78894,39.62914
39.82400,3.31874,737.55607,-0.13904,9.82266,39.67744
39.92400,3.32699,737.47784,-0.13904,9.85566,39.67324
40.02400,3.33530,738.25479,-0.13904,9.88890,39.71503
40.12400,3.34379,738.92358,-0.13904,9.92286,39.75101
40.22400,3.35204,739.39231,-0.13904,9.95587,39.77623
40.32400,3.36035,738.86798,-0.13904,9.98911,39.74802
40.42400,3.36872,739.78016,-0.13904,10.02259,39.79709
40.52400,3.37697,740.07069,-0.13904,10.05560,39.81272
40.62400,3.38528,740.37788,-0.13904,10.08884,39.82925
40.72400,3.39371,741.42497,-0.13904,10.12256,39.88557
40.82400,3.40202,741.50623,-0.13904,10.15580,39.88995
40.92400,3.41033,741.48937,-0.13904,10.18905,39.88904
41.02400,3.41870,742.10796,-0.13904,10.22253,39.92232
41.12400,3.42701,743.07825,-0.13904,10.25577,39.97451
41.22400,3.43532,742.83364,-0.13904,10.28901,39.96136
41.32400,3.44364,743.54466,-0.13904,10.32226,39.99960
41.42400,3.45195,743.70741,-0.13904,10.35550,40.00836
41.52400,3.46032,744.56292,-0.13904,10.38898,40.05438
41.62400,3.46869,744.64572,-0.13904,10.42247,40.05884
41.72400,3.47694,745.31063,-0.13904,10.45547,40.09461
41.82400,3.48537,745.58323,-0.13904,10.48919,40.10927
41.92400,3.49368,746.37793,-0.13904,10.52243,40.15202
42.02400,3.50193,746.30114,-0.13905,10.55544,40.14789
42.12400,3.51042,747.20131,-0.13904,10.58940,40.19632
42.22400,3.51867,747.38883,-0.13904,10.62240,40.20641
42.32400,3.52704,747.27265,-0.13904,10.65588,40.20016
42.42400,3.53541,748.09296,-0.13904,10.68937,40.24429
42.52400,3.54360,748.53571,-0.13904,10.72213,40.26810
42.62400,3.55197,749.03150,-0.13904,10.75561,40.29477
42.72400,3.56040,749.75691,-0.13904,10.78933,40.33380
42.82400,3.56860,750.11924,-0.13904,10.82210,40.35329
42.92400,3.57697,750.72553,-0.13904,10.85558,40.38591
43.02400,3.58540,750.64753,-0.13904,10.88930,40.38171
43.12400,3.59365,751.40470,-0.13904,10.92231,40.42244
43.22400,3.60196,751.85527,-0.13904,10.95555,40.44668
43.32400,3.61045,751.68149,-0.13904,10.98951,40.43733
43.42400,3.61852,751.74957,-0.13904,11.02180,40.44099
43.52400,3.62701,752.50953,-0.13904,11.05576,40.48188
43.62400,3.63532,752.77821,-0.13904,11.08900,40.49633
43.72400,3.64351,753.15516,-0.13904,11.12176,40.51661
43.82400,3.65206,754.08258,-0.13904,11.15596,40.56650
43.92400,3.66037,754.03540,-0.13904,11.18921,40.56396
44.02400,3.66856,753.97589,-0.13905,11.22197,40.56076
44.12400,3.67711,754.43597,-0.13904,11.25617,40.58551
44.22400,3.68530,755.22419,-0.13904,11.28893,40.62791
44.32400,3.69362,755.52971,-0.13904,11.32218,40.64435
44.42400,3.70217,755.70950,-0.13904,11.35638,40.65402
44.52400,3.71030,755.82196,-0.13904,11.38890,40.66007
44.62400,3.71861,756.78076,-0.13904,11.42215,40.71165
44.72400,3.72710,756.83105,-0.13904,11.45611,40.71436
44.82400,3.73529,756.97773,-0.13904,11.48887,40.72225
44.92400,3.74366,758.06486,-0.13904,11.52235,40.78073
45.02400,3.75209,757.40311,-0.13905,11.55607,40.74513
45.12400,3.76028,758.46785,-0.13904,11.58884,40.80241
45.22400,3.76865,758.21215,-0.13904,11.62232,40.78865
45.32400,3.77714,758.75102,-0.13904,11.65628,40.81764
45.42400,3.78527,759.00299,-0.13905,11.68881,40.83120
45.52400,3.79364,759.46776,-0.13904,11.72229,40.85620
45.62400,3.80201,760.27671,-0.13904,11.75577,40.89972
45.72400,3.81026,760.48812,-0.13905,11.78878,40.91109
45.82400,3.81869,760.77222,-0.13904,11.82250,40.92638
45.92400,3.82701,760.80924,-0.13904,11.85574,40.92837
46.02400,3.83526,761.18549,-0.13904,11.88874,40.94861
46.12400,3.84375,761.70466,-0.13904,11.92270,40.97654
46.22400,3.85206,762.00683,-0.13904,11.95595,40.99279
46.32400,3.86031,761.68766,-0.13904,11.98895,40.97562
46.42400,3.86874,762.16669,-0.13904,12.02267,41.00139
46.52400,3.87699,763.10644,-0.13904,12.05568,41.05195
46.62400,3.88530,763.04986,-0.13904,12.08892,41.04890
46.72400,3.89367,763.56847,-0.13905,12.12240,41.07680
46.82400,3.90192,763.65652,-0.13904,12.15540,41.08154
46.92400,3.91029,764.28433,-0.13904,12.18889,41.11531
47.02400,3.91866,764.35343,-0.13905,12.22237,41.11903
47.12400,3.92697,765.22203,-0.13905,12.25561,41.16576
47.22400,3.93528,765.42068,-0.13904,12.28885,41.17645
47.32400,3.94371,764.72736,-0.13904,12.32258,41.13914
47.42400,3.95197,763.56046,-0.13905,12.35558,41.07637
47.52400,3.96034,764.35003,-0.13905,12.38906,41.11885
47.62400,3.96871,764.70189,-0.13905,12.42254,41.13778
47.72400,3.97696,764.40061,-0.13904,12.45555,41.12157
47.82400,3.98533,765.49561,-0.13904,12.48903,41.18047
47.92400,3.99364,765.81887,-0.13904,12.52227,41.19786
48.02400,4.00189,765.69254,-0.13905,12.55528,41.19107
48.12400,4.01038,766.97073,-0.13905,12.58924,41.25983
48.22400,4.01863,767.07657,-0.13904,12.62224,41.26553
48.32400,4.02700,767.42987,-0.13904,12.65572,41.28453
48.42400,4.03537,767.47383,-0.13904,12.68920,41.28690
48.52400,4.04362,768.62429,-0.13905,12.72221,41.34879
48.62400,4.05199,768.33256,-0.13904,12.75569,41.33309
48.72400,4.06042,768.67216,-0.13905,12.78941,41.35136
48.82400,4.06867,769.15417,-0.13904,12.82241,41.37729
48.92400,4.07693,769.39240,-0.13904,12.85542,41.39011
49.02400,4.08536,769.56474,-0.13905,12.88914,41.39938
49.12400,4.09355,770.47031,-0.13904,12.92191,41.44809
49.22400,4.10198,769.98132,-0.13904,12.95563,41.42179
49.32400,4.11041,770.62170,-0.13905,12.98935,41.45624
49.42400,4.11860,771.18766,-0.13905,13.02211,41.48668
49.52400,4.12703,770.68363,-0.13905,13.05583,41.45957
49.62400,4.13540,771.22548,-0.13905,13.08932,41.48872
49.72400,4.14365,771.95759,-0.13905,13.12232,41.52810
49.82400,4.15202,772.58926,-0.13904,13.15580,41.56208
49.92400,4.16033,772.44802,-0.13904,13.18904,41.55449
50.02400,4.16858,772.09892,-0.13905,13.22205,41.53571
50.12400,4.17701,773.10279,-0.13905,13.25577,41.58971
50.22400,4.18532,773.30265,-0.13905,13.28901,41.60046
50.32400,4.19358,773.47225,-0.13904,13.32202,41.60958
50.42400,4.20201,773.76659,-0.13905,13.35574,41.62542
50.52400,4.21032,774.01665,-0.13905,13.38898,41.63887
50.62400,4.21869,774.72408,-0.13905,13.42246,41.67693
50.72400,4.22718,774.26946,-0.13905,13.45642,41.65247
50.82400,4.23537,774.63547,-0.13905,13.48919,41.67216
50.92400,4.24362,774.72078,-0.13905,13.52219,41.67675
51.02400,4.25205,775.59836,-0.13905,13.55591,41.72396
51.12400,4.26024,775.69503,-0.13904,13.58868,41.72916
51.22400,4.26861,776.19273,-0.13904,13.62216,41.75594
51.32400,4.27710,775.89643,-0.13904,13.65612,41.73999
51.42400,4.28529,776.17555,-0.13904,13.68888,41.75501
51.52400,4.29366,776.93267,-0.13905,13.72237,41.79574
51.62400,4.30209,776.97467,-0.13905,13.75609,41.79800
51.72400,4.31028,777.33197,-0.13904,13.78885,41.81722
51.82400,4.31865,777.14222,-0.13904,13.82233,41.80701
51.92400,4.32703,777.02287,-0.13905,13.85582,41.80059
52.02400,4.33528,777.85607,-0.13905,13.88882,41.84542
52.12400,4.34365,777.81491,-0.13904,13.92230,41.84320
52.22400,4.35202,778.57040,-0.13904,13.95579,41.88384
52.32400,4.36033,778.86875,-0.13905,13.98903,41.89989
52.42400,4.36870,779.09525,-0.13904,14.02251,41.91208
52.52400,4.37701,779.29590,-0.13904,14.05575,41.92287
52.62400,4.38526,779.16034,-0.13905,14.08876,41.91558
52.72400,4.39375,779.23303,-0.13905,14.12272,41.91949
52.82400,4.40200,779.90284,-0.13905,14.15572,41.95552
52.92400,4.41031,779.94973,-0.13905,14.18896,41.95805
53.02400,4.41874,779.89306,-0.13905,14.22268,41.95500
53.12400,4.42699,780.45772,-0.13905,14.25569,41.98537
53.22400,4.43530,780.94713,-0.13905,14.28893,42.01170
53.32400,4.44367,780.74019,-0.13905,14.32241,42.00057
53.42400,4.45193,781.72423,-0.13904,14.35542,42.05351
53.52400,4.46030,781.25866,-0.13905,14.38890,42.02846
53.62400,4.46867,781.77927,-0.13904,14.42238,42.05647
53.72400,4.47698,781.83459,-0.13905,14.45562,42.05944
53.82400,4.48535,782.09722,-0.13905,14.48911,42.07357
53.92400,4.49372,781.75170,-0.13904,14.52259,42.05499
54.02400,4.50197,782.45047,-0.13905,14.55559,42.09258
54.12400,4.51028,782.47422,-0.13904,14.58884,42.09385
54.22400,4.51859,782.58123,-0.13905,14.62208,42.09961
54.32400,4.52690,782.92554,-0.13905,14.65532,42.11813
54.42400,4.53527,783.17989,-0.13905,14.68880,42.13182
54.52400,4.54358,783.98520,-0.13905,14.72205,42.17514
54.62400,4.55189,783.74017,-0.13905,14.75529,42.16196
54.72400,4.56032,784.09882,-0.13905,14.78901,42.18125
54.82400,4.56863,784.29040,-0.13905,14.82226,42.19156
54.92400,4.57701,784.11940,-0.13905,14.85574,42.18236
55.02400,4.58538,784.35224,-0.13905,14.88922,42.19488
55.12400,4.59369,784.46232,-0.13905,14.92246,42.20081
55.22400,4.60206,784.66702,-0.13905,14.95594,42.21182
55.32400,4.61037,784.97836,-0.13905,14.98919,42.22857
55.42400,4.61862,785.30442,-0.13905,15.02219,42.24611
55.52400,4.62699,785.21138,-0.13905,15.05567,42.24110
55.62400,4.63536,785.52021,-0.13905,15.08916,42.25771
55.72400,4.64367,785.84170,-0.13904,15.12240,42.27501
55.82400,4.65198,785.40696,-0.13905,15.15564,42.25162
55.92400,4.66041,785.87318,-0.13905,15.18936,42.27670
56.02400,4.66872,786.38308,-0.13905,15.22261,42.30413
56.12400,4.67709,786.24869,-0.13905,15.25609,42.29691
56.22400,4.68546,785.77809,-0.13905,15.28957,42.27159
56.32400,4.69371,787.10224,-0.13905,15.32257,42.34282
56.42400,4.70203,786.67663,-0.13905,15.35582,42.31993
56.52400,4.71034,787.05838,-0.13905,15.38906,42.34046
56.62400,4.71865,786.69684,-0.13905,15.42230,42.32101
56.72400,4.72702,787.07365,-0.13905,15.45578,42.34128
56.82400,4.73527,787.79832,-0.13905,15.48879,42.38027
56.92400,4.74364,787.16306,-0.13905,15.52227,42.34609
57.02400,4.75201,788.13769,-0.13905,15.55575,42.39853
57.12400,4.76032,787.57768,-0.13905,15.58900,42.36840
57.22400,4.76869,788.44866,-0.13905,15.62248,42.41525
57.32400,4.77706,788.44037,-0.13905,15.65596,42.41481
57.42400,4.78525,789.21635,-0.13905,15.68872,42.45655
57.52400,4.79356,788.68903,-0.13905,15.72196,42.42818
57.62400,4.80199,788.62309,-0.13905,15.75569,42.42464
57.72400,4.81030,788.99693,-0.13904,15.78893,42.44475
57.82400,4.81867,789.75307,-0.13905,15.82241,42.48542
57.92400,4.82704,789.28834,-0.13905,15.85589,42.46043
58.02400,4.83536,789.45542,-0.13905,15.88914,42.46941
58.12400,4.84373,789.64569,-0.13905,15.92262,42.47965
58.22400,4.85210,789.58999,-0.13905,15.95610,42.47665
58.32400,4.86029,790.43023,-0.13905,15.98887,42.52185
58.42400,4.86866,790.04895,-0.13905,16.02235,42.50134
58.52400,4.87709,790.37715,-0.13905,16.05607,42.51900
58.62400,4.88534,790.97170,-0.13905,16.08907,42.55098
58.72400,4.89371,790.48518,-0.13905,16.12255,42.52481
58.82400,4.90196,790.94321,-0.13905,16.15556,42.54945
58.92400,4.91027,791.20556,-0.13905,16.18880,42.56356
59.02400,4.91870,791.31294,-0.13905,16.22252,42.56934
59.12400,4.92701,791.06111,-0.13905,16.25577,42.55579
59.22400,4.93538,791.78149,-0.13904,16.28925,42.59455
59.32400,4.94375,791.66889,-0.13905,16.32273,42.58849
59.42400,4.95195,791.32160,-0.13905,16.35550,42.56981
59.52400,4.96032,792.07998,-0.13905,16.38898,42.61060
59.62400,4.96869,792.17060,-0.13905,16.42246,42.61548
59.72400,4.97694,792.35006,-0.13904,16.45546,42.62513
59.82400,4.98525,792.56343,-0.13905,16.48871,42.63661
59.92400,4.99368,792.82736,-0.13905,16.52243,42.65081
60.02400,5.00193,792.69065,-0.13905,16.55543,42.64346
60.12400,5.01030,792.70639,-0.13905,16.58891,42.64430
60.22400,5.01873,792.93018,-0.13905,16.62263,42.65634
60.32400,5.02704,793.30727,-0.13905,16.65588,42.67663
60.42400,5.03535,792.76701,-0.13905,16.68912,42.64756
60.52400,5.04372,793.22457,-0.13905,16.72260,42.67218
60.62400,5.05197,793.42006,-0.13905,16.75561,42.68269
60.72400,5.06034,793.47044,-0.13905,16.78909,42.68541
60.82400,5.06859,793.64553,-0.13905,16.82209,42.69482
60.92400,5.07702,793.78225,-0.13905,16.85581,42.70218
61.02400,5.08534,793.93480,-0.13905,16.88906,42.71038
61.12400,5.09359,793.79687,-0.13905,16.92206,42.70296
61.22400,5.10202,794.03426,-0.13905,16.95578,42.71574
61.32400,5.11033,794.15860,-0.13905,16.98903,42.72242
61.42400,5.11864,794.60610,-0.13905,17.02227,42.74650
61.52400,5.12701,794.61159,-0.13905,17.05575,42.74679
61.62400,5.13532,794.73611,-0.13905,17.08899,42.75349
61.72400,5.14357,795.13807,-0.13905,17.12200,42.77512
61.82400,5.15188,794.97667,-0.13905,17.15524,42.76643
61.92400,5.16037,795.32238,-0.13905,17.18920,42.78503
62.02400,5.16868,795.52447,-0.13905,17.22244,42.79590
62.12400,5.17699,795.13965,-0.13905,17.25568,42.77520
62.22400,5.18536,795.45025,-0.13905,17.28917,42.79191
62.32400,5.19361,795.41262,-0.13905,17.32217,42.78989
62.42400,5.20198,795.45369,-0.13905,17.35565,42.79210
62.52400,5.21036,795.83498,-0.13905,17.38914,42.81261
62.62400,5.21867,795.51851,-0.13905,17.42238,42.79558
62.72400,5.22698,795.97263,-0.13905,17.45562,42.82001
62.82400,5.23529,796.46362,-0.13905,17.48887,42.84642
62.92400,5.24360,796.34553,-0.13905,17.52211,42.84007
63.02400,5.25197,796.42320,-0.13905,17.55559,42.84425
63.12400,5.26034,796.86986,-0.13905,17.58907,42.86828
63.22400,5.26865,796.30595,-0.13905,17.62232,42.83794
63.32400,5.27702,796.72104,-0.13905,17.65580,42.86027
63.42400,5.28533,796.84881,-0.13905,17.68904,42.86715
63.52400,5.29370,796.55610,-0.13905,17.72252,42.85140
63.62400,5.30207,796.67484,-0.13905,17.75601,42.85779
63.72400,5.31032,796.86753,-0.13905,17.78901,42.86815
63.82400,5.31863,797.09040,-0.13905,17.82225,42.88014
63.92400,5.32700,797.35415,-0.13905,17.85573,42.89433
64.02400,5.33526,797.32621,-0.13905,17.88874,42.89283
64.12400,5.34363,797.23671,-0.13905,17.92222,42.88801
64.22401,5.35200,797.70824,-0.13905,17.95570,42.91338
64.32400,5.36031,797.83285,-0.13905,17.98894,42.92008
64.42400,5.36862,797.39112,-0.13905,18.02219,42.89632
64.52400,5.37711,797.54088,-0.13905,18.05615,42.90438
64.62400,5.38530,798.12435,-0.13905,18.08891,42.93576
64.72401,5.39361,798.51057,-0.13905,18.12215,42.95654
64.82400,5.40204,798.11839,-0.13905,18.15588,42.93544
64.92400,5.41029,797.99257,-0.13905,18.18888,42.92868
65.02400,5.41860,798.57456,-0.13905,18.22212,42.95998
65.12400,5.42703,798.38363,-0.13905,18.25584,42.94971
65.22401,5.43528,798.25716,-0.13905,18.28885,42.94291
65.32400,5.44359,798.77265,-0.13905,18.32209,42.97064
65.42400,5.45196,798.20873,-0.13905,18.35558,42.94030
65.52400,5.46033,798.56012,-0.13905,18.38906,42.95921
65.62400,5.46871,798.91039,-0.13905,18.42254,42.97805
65.72401,5.47708,798.74685,-0.13905,18.45602,42.96925
65.82401,5.48533,799.11835,-0.13905,18.48902,42.98924
65.92400,5.49370,799.12674,-0.13905,18.52251,42.98969
66.02400,5.50201,799.24576,-0.13905,18.55575,42.99609
66.12400,5.51032,799.00166,-0.13905,18.58899,42.98296
66.22401,5.51869,799.45382,-0.13905,18.62248,43.00729
66.32401,5.52700,799.65489,-0.13905,18.65572,43.01810
66.42400,5.53531,799.16613,-0.13905,18.68896,42.99181
66.52400,5.54374,800.10667,-0.13905,18.72268,43.04240
66.62400,5.55205,799.65340,-0.13905,18.75592,43.01802
66.72401,5.56036,799.37931,-0.13905,18.78917,43.00328
66.82401,5.56879,799.26783,-0.13905,18.82289,42.99728
66.92400,5.57698,799.22080,-0.13905,18.85565,42.99475
67.02400,5.58530,800.07613,-0.13905,18.88890,43.04076
67.12400,5.59373,799.78518,-0.13905,18.92262,43.02511
67.22401,5.60198,800.21443,-0.13905,18.95562,43.04820
67.32401,5.61029,800.23156,-0.13905,18.98886,43.04913
67.42400,5.61866,800.81103,-0.13905,19.02235,43.08030
67.52400,5.62697,800.00069,-0.13905,19.05559,43.03671
67.62400,5.63534,800.50612,-0.13905,19.08907,43.06390
67.72401,5.64365,800.30989,-0.13905,19.12232,43.05334
67.82401,5.65196,800.93900,-0.13905,19.15556,43.08718
67.92400,5.66033,800.64004,-0.13905,19.18904,43.07110
68.02400,5.66858,800.74817,-0.13905,19.22204,43.07692
68.12400,5.67695,801.06799,-0.13905,19.25552,43.09412
68.22401,5.68526,800.73914,-0.13905,19.28877,43.07643
68.32401,5.69357,801.19856,-0.13905,19.32201,43.10114
68.42400,5.70194,800.72200,-0.13905,19.35549,43.07551
68.52400,5.71031,800.89439,-0.13905,19.38898,43.08478
68.62400,5.71863,801.28638,-0.13905,19.42222,43.10587
68.72401,5.72694,801.44079,-0.13905,19.45546,43.11418
68.82401,5.73537,801.25444,-0.13905,19.48918,43.10415
68.92400,5.74374,801.39777,-0.13905,19.52266,43.11186
69.02400,5.75199,801.58180,-0.13905,19.55567,43.12176
69.12400,5.76042,801.79134,-0.13905,19.58939,43.13303
69.22401,5.76861,801.55777,-0.13905,19.62215,43.12047
69.32401,5.77698,801.82320,-0.13905,19.65564,43.13475
69.42400,5.78535,801.66860,-0.13905,19.68912,43.12643
69.52400,5.79366,801.48857,-0.13905,19.72236,43.11674
69.62400,5.80197,801.98962,-0.13905,19.75561,43.14370
69.72401,5.81028,801.96457,-0.13905,19.78885,43.14235
69.82401,5.81865,801.33518,-0.13905,19.82233,43.10849
69.92400,5.82708,802.00015,-0.13905,19.85605,43.14427
70.02400,5.83533,801.75428,-0.13905,19.88906,43.13104
70.12400,5.84371,801.42114,-0.13905,19.92254,43.11312
70.22401,5.85202,802.07149,-0.13905,19.95578,43.14811
70.32401,5.86033,802.05277,-0.13905,19.98902,43.14710
70.42400,5.86858,802.18483,-0.13905,20.02203,43.15420
70.52400,5.87701,802.20355,-0.13905,20.05575,43.15521
70.62400,5.88532,802.08629,-0.13905,20.08899,43.14890
70.72401,5.89363,801.89249,-0.13905,20.12223,43.13847
70.82401,5.90206,802.77268,-0.13905,20.15595,43.18583
70.92400,5.91037,802.00946,-0.13905,20.18920,43.14477
71.02400,5.91868,802.28597,-0.13905,20.22244,43.15964
71.12400,5.92711,802.69929,-0.13905,20.25616,43.18188
71.22401,5.93530,802.61435,-0.13905,20.28893,43.17731
71.32401,5.94361,802.84048,-0.13905,20.32217,43.18947
71.42400,5.95204,802.80658,-0.13905,20.35589,43.18765
71.52400,5.96029,803.15126,-0.13905,20.38889,43.20619
71.62400,5.96866,802.68746,-0.13905,20.42238,43.18124
71.72401,5.97704,802.43144,-0.13905,20.45586,43.16747
71.82401,5.98529,802.85473,-0.13905,20.48886,43.19024
71.92400,5.99372,802.70311,-0.13905,20.52259,43.18208
72.02400,6.00209,802.82753,-0.13905,20.55607,43.18878
72.12400,6.01028,802.97925,-0.13905,20.58883,43.19694
72.22401,6.01871,802.50017,-0.13905,20.62255,43.17117
72.32401,6.02702,802.82930,-0.13905,20.65579,43.18887
72.42400,6.03527,803.09538,-0.13905,20.68880,43.20319
72.52400,6.04370,802.85203,-0.13905,20.72252,43.19009
72.62400,6.05201,803.05506,-0.13905,20.75576,43.20102
72.72401,6.06026,803.65026,-0.13905,20.78877,43.23304
72.82401,6.06875,803.39061,-0.13905,20.82273,43.21907
72.92400,6.07700,803.49753,-0.13905,20.85573,43.22482
73.02400,6.08525,802.92262,-0.13905,20.88874,43.19389
73.12400,6.09380,803.11913,-0.13905,20.92293,43.20446
73.22401,6.10200,803.07005,-0.13905,20.95570,43.20182
73.32401,6.11031,803.37878,-0.13905,20.98894,43.21843
73.42400,6.11880,803.18544,-0.13905,21.02290,43.20803
73.52400,6.12699,803.03904,-0.13905,21.05567,43.20015
73.62400,6.13530,802.94916,-0.13905,21.08891,43.19532
73.72401,6.14373,803.45664,-0.13905,21.12263,43.22262
73.82401,6.15192,803.05571,-0.13905,21.15540,43.20105
73.92400,6.16035,803.34572,-0.13905,21.18912,43.21665
74.02400,6.16872,803.60472,-0.13905,21.22260,43.23059
74.12400,6.17697,803.86158,-0.13905,21.25560,43.24440
74.22401,6.18540,803.36453,-0.13905,21.28932,43.21767
74.32401,6.19377,804.05781,-0.13905,21.32281,43.25496
74.42400,6.20196,803.39741,-0.13905,21.35557,43.21943
74.52400,6.21033,803.68789,-0.13905,21.38905,43.23506
74.62400,6.21865,803.27103,-0.13905,21.42230,43.21264
74.72401,6.22690,803.76118,-0.13905,21.45530,43.23900
74.82401,6.23539,803.99700,-0.13905,21.48926,43.25169
74.92400,6.24364,803.47005,-0.13905,21.52226,43.22334
75.02400,6.25195,804.09572,-0.13905,21.55551,43.25700
75.12400,6.26038,803.70819,-0.13905,21.58923,43.23615
75.22401,6.26863,803.36304,-0.13905,21.62223,43.21759
75.32401,6.27700,803.44221,-0.13905,21.65572,43.22184
75.42400,6.28537,803.24188,-0.13905,21.68920,43.21107
75.52400,6.29362,803.92519,-0.13905,21.72220,43.24783
75.62400,6.30193,803.86866,-0.13905,21.75544,43.24479
75.72401,6.31030,803.14707,-0.13905,21.78892,43.20597
75.82401,6.31861,803.92696,-0.13905,21.82217,43.24792
75.92400,6.32692,804.10568,-0.13905,21.85541,43.25753
76.02400,6.33535,803.68016,-0.13905,21.88913,43.23465
76.12400,6.34361,803.86512,-0.13905,21.92214,43.24459
76.22401,6.35198,803.54288,-0.13905,21.95562,43.22726
76.32401,6.36035,803.55024,-0.13905,21.98910,43.22765
76.42400,6.36872,803.63471,-0.13905,22.02258,43.23220
76.52400,6.37715,803.62363,-0.13905,22.05631,43.23160
76.62400,6.38534,802.91303,-0.13905,22.08907,43.19337
76.72401,6.39359,803.55005,-0.13905,22.12207,43.22765
76.82401,6.40196,803.85851,-0.13905,22.15555,43.24424
76.92400,6.41027,803.56365,-0.13905,22.18880,43.22838
77.02400,6.41864,803.64142,-0.13905,22.22228,43.23256
77.12400,6.42707,803.98787,-0.13905,22.25600,43.25120
77.22401,6.43532,803.02767,-0.13905,22.28901,43.19954
77.32401,6.44363,803.37422,-0.13905,22.32225,43.21819
77.42400,6.45206,803.76333,-0.13905,22.35597,43.23912
77.52400,6.46037,803.15219,-0.13905,22.38921,43.20624
77.62400,6.46868,803.68482,-0.13905,22.42246,43.23489
77.72401,6.47712,803.00877,-0.13905,22.45618,43.19853
77.82401,6.48531,803.83569,-0.13905,22.48894,43.24301
77.92400,6.49362,803.13561,-0.13905,22.52218,43.20535
78.02400,6.50205,803.10414,-0.13905,22.55590,43.20366
78.12400,6.51024,803.39257,-0.13905,22.58867,43.21917
78.22401,6.51861,804.04123,-0.13905,22.62215,43.25407
78.32401,6.52698,802.99797,-0.13905,22.65563,43.19794
78.42400,6.53523,802.90623,-0.13905,22.68864,43.19301
78.52400,6.54372,802.82334,-0.13905,22.72260,43.18855
78.62400,6.55215,802.60914,-0.13905,22.75632,43.17703
78.72401,6.56028,802.37333,-0.13905,22.78885,43.16434
78.82401,6.56877,802.97431,-0.13905,22.82280,43.19667
78.92400,6.57702,802.60886,-0.13905,22.85581,43.17701
79.02400,6.58527,802.84243,-0.13905,22.88881,43.18958
79.12400,6.59376,802.25402,-0.13905,22.92277,43.15792
79.22401,6.60202,803.02702,-0.13905,22.95578,43.19951
79.32401,6.61027,801.72475,-0.13905,22.98878,43.12945
79.42400,6.61876,802.26352,-0.13905,23.02274,43.15844
79.52400,6.62701,802.28550,-0.13905,23.05575,43.15962
79.62400,6.63526,802.28932,-0.13905,23.08875,43.15982
79.72401,6.64375,801.97779,-0.13905,23.12271,43.14306
79.82401,6.65200,801.58459,-0.13905,23.15571,43.12191
79.92400,6.66025,800.92391,-0.13905,23.18872,43.08637
80.02400,6.66880,801.16130,-0.13905,23.22292,43.09914
80.12400,6.67693,800.58388,-0.13905,23.25544,43.06808
80.22401,6.68530,799.53363,-0.13905,23.28892,43.01158
80.32401,6.69379,798.84697,-0.13905,23.32289,42.97464
80.42400,6.70192,797.57748,-0.13905,23.35541,42.90635
80.52400,6.71035,795.45043,-0.13905,23.38913,42.79192
80.62400,6.71878,790.16481,-0.13905,23.42285,42.50758
80.72401,6.72704,31.95975,-0.13905,23.45586,1.71930
80.72801,6.72739,6.83111,-0.13905,23.45729,0.36749