File: Manufatura Aditiva/Classificação Direção/Ensaios/Ensaios FDM/Tracao_OLABI_18_03_2019_FDM_45.is_metal_RawData/Specimen_RawData_1.csv
Time,Extension,Load,Strain 1,Tensile strain,Tensile stress
(sec),(mm),(N),(mm/mm),(%),(MPa)
0.00000,0.00000,12.79770,0.00068,0.06760,0.61955
0.10000,0.00227,14.10856,0.00069,0.06893,0.68301
0.20000,0.01148,16.13247,0.00079,0.07924,0.78099
0.30000,0.02206,20.53854,0.00094,0.09376,0.99430
0.40000,0.03193,24.85322,0.00108,0.10777,1.20317
0.50000,0.04102,28.13799,0.00121,0.12075,1.36219
0.60000,0.04969,32.73585,0.00133,0.13337,1.58478
0.70000,0.05818,35.48173,0.00145,0.14538,1.71771
0.80000,0.06661,39.05598,0.00157,0.15736,1.89075
0.90000,0.07492,42.19382,0.00169,0.16922,2.04265
1.00000,0.08329,45.92809,0.00181,0.18098,2.22344
1.10000,0.09166,49.95887,0.00193,0.19311,2.41857
1.20000,0.09997,52.76329,0.00205,0.20506,2.55434
1.30000,0.10834,55.95391,0.00218,0.21763,2.70880
1.40000,0.11659,59.48282,0.00229,0.22949,2.87964
1.50000,0.12490,62.71370,0.00241,0.24139,3.03605
1.60000,0.13333,66.10728,0.00254,0.25429,3.20034
1.70000,0.14158,69.60260,0.00266,0.26580,3.36955
1.80000,0.14989,72.98410,0.00278,0.27815,3.53325
1.90000,0.15838,76.12953,0.00291,0.29093,3.68552
2.00000,0.16663,79.65786,0.00303,0.30307,3.85634
2.10000,0.17500,82.52749,0.00316,0.31623,3.99526
2.20000,0.18331,86.50924,0.00328,0.32832,4.18802
2.30000,0.19163,89.85309,0.00341,0.34073,4.34990
2.40000,0.20000,92.35282,0.00353,0.35325,4.47091
2.50000,0.20831,96.42242,0.00366,0.36611,4.66793
2.60000,0.21668,99.20851,0.00379,0.37855,4.80281
2.70000,0.22499,102.71525,0.00391,0.39104,4.97257
2.80000,0.23330,106.38569,0.00404,0.40360,5.15026
2.90000,0.24167,108.58808,0.00416,0.41609,5.25688
3.00000,0.25004,113.11840,0.00429,0.42934,5.47620
3.10000,0.25829,116.02268,0.00442,0.44178,5.61680
3.20000,0.26666,118.84915,0.00454,0.45419,5.75363
3.30000,0.27503,122.70138,0.00467,0.46731,5.94013
3.40000,0.28328,125.26760,0.00480,0.48020,6.06436
3.50000,0.29159,128.55442,0.00493,0.49262,6.22348
3.60000,0.29996,131.87405,0.00506,0.50566,6.38419
3.70000,0.30821,135.70143,0.00519,0.51861,6.56947
3.80000,0.31653,138.46508,0.00531,0.53133,6.70327
3.90000,0.32496,141.48810,0.00544,0.54437,6.84961
4.00000,0.33327,144.79851,0.00557,0.55719,7.00987
4.10000,0.34164,148.47254,0.00570,0.57030,7.18774
4.20000,0.34995,151.87908,0.00583,0.58329,7.35265
4.30000,0.35814,154.68758,0.00596,0.59606,7.48862
4.40000,0.36651,158.47653,0.00609,0.60868,7.67204
4.50000,0.37494,161.28739,0.00622,0.62177,7.80812
4.60000,0.38331,164.64917,0.00635,0.63528,7.97087
4.70000,0.39162,167.80439,0.00648,0.64806,8.12362
4.80000,0.39999,170.60342,0.00662,0.66187,8.25912
4.90000,0.40830,174.26050,0.00675,0.67479,8.43617
5.00000,0.41667,177.57354,0.00688,0.68810,8.59655
5.10000,0.42504,180.59105,0.00701,0.70142,8.74264
5.20000,0.43335,183.07959,0.00715,0.71465,8.86311
5.30000,0.44172,187.23268,0.00728,0.72792,9.06417
5.40000,0.44998,189.97955,0.00741,0.74126,9.19715
5.50000,0.45829,193.02814,0.00754,0.75419,9.34473
5.60000,0.46666,196.25255,0.00768,0.76774,9.50083
5.70000,0.47491,199.43714,0.00781,0.78060,9.65500
5.80000,0.48322,203.25037,0.00794,0.79393,9.83960
5.90000,0.49171,206.19323,0.00807,0.80739,9.98207
6.00000,0.49990,209.05109,0.00821,0.82065,10.12042
6.10000,0.50821,212.99717,0.00834,0.83419,10.31146
6.20000,0.51670,215.96025,0.00848,0.84779,10.45490
6.30000,0.52495,219.11687,0.00861,0.86065,10.60772
6.40000,0.53326,222.12253,0.00874,0.87379,10.75323
6.50000,0.54169,225.32339,0.00887,0.88729,10.90818
6.60000,0.54988,228.86908,0.00901,0.90056,11.07983
6.70000,0.55819,232.03606,0.00913,0.91348,11.23315
6.80000,0.56668,235.00118,0.00928,0.92770,11.37670
6.90000,0.57494,237.74009,0.00941,0.94085,11.50929
7.00000,0.58331,241.53835,0.00954,0.95415,11.69317
7.10000,0.59168,244.78261,0.00968,0.96759,11.85023
7.20000,0.59987,248.15933,0.00981,0.98125,12.01370
7.30000,0.60824,250.86359,0.00995,0.99490,12.14462
7.40000,0.61661,253.94964,0.01009,1.00882,12.29402
7.50000,0.62492,257.06755,0.01022,1.02214,12.44496
7.60000,0.63329,260.15958,0.01036,1.03580,12.59465
7.70000,0.64160,263.51393,0.01049,1.04946,12.75704
7.80000,0.64991,266.00757,0.01063,1.06258,12.87776
7.90000,0.65834,269.15260,0.01076,1.07590,13.03001
8.00000,0.66659,273.09409,0.01090,1.08982,13.22082
8.10000,0.67490,276.13980,0.01104,1.10374,13.36827
8.20000,0.68339,279.10906,0.01117,1.11727,13.51202
8.30000,0.69164,281.77437,0.01131,1.13075,13.64105
8.40000,0.70002,284.98671,0.01144,1.14416,13.79656
8.50000,0.70845,288.57470,0.01158,1.15816,13.97026
8.60000,0.71658,291.10452,0.01172,1.17173,14.09273
8.70000,0.72495,293.95043,0.01185,1.18503,14.23050
8.80000,0.73332,297.57402,0.01200,1.19971,14.40593
8.90000,0.74151,300.23595,0.01213,1.21257,14.53479
9.00000,0.74994,303.11593,0.01226,1.22619,14.67422
9.10000,0.75831,306.80753,0.01240,1.24017,14.85293
9.20000,0.76656,309.73481,0.01254,1.25375,14.99465
9.30000,0.77499,312.40303,0.01268,1.26759,15.12382
9.40000,0.78330,315.53914,0.01281,1.28123,15.27564
9.50000,0.79161,318.51279,0.01295,1.29469,15.41960
9.60000,0.79998,320.84268,0.01308,1.30849,15.53239
9.70000,0.80823,324.63768,0.01322,1.32234,15.71611
9.80000,0.81660,327.11567,0.01336,1.33561,15.83607
9.90000,0.82498,330.10989,0.01350,1.34959,15.98103
10.00000,0.83323,333.49185,0.01364,1.36364,16.14475
10.10000,0.84160,336.21104,0.01377,1.37721,16.27639
10.20000,0.85003,339.07418,0.01392,1.39163,16.41500
10.30000,0.85828,342.21509,0.01405,1.40450,16.56706
10.40000,0.86665,345.09059,0.01419,1.41855,16.70626
10.50000,0.87508,347.86644,0.01433,1.43251,16.84064
10.60000,0.88327,350.54404,0.01447,1.44651,16.97027
10.70000,0.89158,353.81853,0.01460,1.45987,17.12879
10.80000,0.90001,356.68414,0.01474,1.47427,17.26752
10.90000,0.90826,359.71862,0.01488,1.48787,17.41442
11.00000,0.91657,362.55356,0.01502,1.50172,17.55167
11.10000,0.92500,365.66933,0.01516,1.51580,17.70251
11.20000,0.93325,368.26625,0.01529,1.52945,17.82822
11.30000,0.94162,371.02085,0.01543,1.54339,17.96158
11.40000,0.94994,373.57963,0.01557,1.55702,18.08545
11.50000,0.95825,377.16590,0.01571,1.57054,18.25907
11.60000,0.96662,378.68510,0.01581,1.58147,18.33261
11.70000,0.97493,381.51366,0.01594,1.59408,18.46955
11.80000,0.98324,384.39296,0.01608,1.60824,18.60894
11.90000,0.99155,387.61667,0.01622,1.62201,18.76500
12.00000,0.99992,390.28279,0.01637,1.63660,18.89407
12.10000,1.00817,392.94632,0.01650,1.65034,19.02302
12.20000,1.01660,396.95553,0.01664,1.66433,19.21711
12.30000,1.02491,399.04909,0.01678,1.67809,19.31846
12.40000,1.03328,401.74555,0.01692,1.69207,19.44900
12.50000,1.04177,404.74841,0.01706,1.70599,19.59437
12.60000,1.04996,407.31863,0.01720,1.71998,19.71880
12.70000,1.05833,410.80299,0.01734,1.73355,19.88748
12.80000,1.06676,413.80194,0.01748,1.74808,20.03266
12.90000,1.07490,416.62450,0.01762,1.76223,20.16931
13.00000,1.08327,419.96907,0.01776,1.77616,20.33122
13.10000,1.09170,422.89300,0.01790,1.79020,20.47277
13.20000,1.09989,425.12924,0.01804,1.80411,20.58103
13.30000,1.10826,428.38925,0.01818,1.81841,20.73885
13.40000,1.11669,431.45623,0.01833,1.83275,20.88733
13.50000,1.12494,434.17341,0.01847,1.84684,21.01887
13.60000,1.13331,436.84263,0.01861,1.86065,21.14809
13.70000,1.14168,439.12381,0.01875,1.87510,21.25853
13.80000,1.14987,442.46996,0.01889,1.88925,21.42052
13.90000,1.15824,445.30537,0.01903,1.90325,21.55778
14.00000,1.16667,447.45416,0.01918,1.91776,21.66181
14.10000,1.17486,450.09446,0.01931,1.93136,21.78963
14.20000,1.18335,453.69612,0.01946,1.94585,21.96399
14.30000,1.19160,456.06159,0.01960,1.96022,22.07851
14.40000,1.19986,458.56540,0.01975,1.97468,22.19972
14.50000,1.20835,460.77189,0.01989,1.98921,22.30654
14.60000,1.21660,464.30221,0.02003,2.00315,22.47744
14.70000,1.22497,466.32816,0.02017,2.01716,22.57552
14.80000,1.23340,469.32134,0.02032,2.03155,22.72043
14.90000,1.24165,472.29887,0.02046,2.04585,22.86457
15.00000,1.24990,474.77633,0.02060,2.06000,22.98451
15.10000,1.25833,477.27074,0.02075,2.07453,23.10527
15.20000,1.26652,480.23141,0.02089,2.08897,23.24860
15.30000,1.27489,483.03367,0.02103,2.10301,23.38426
15.40000,1.28338,485.75075,0.02117,2.11734,23.51579
15.50000,1.29163,488.11478,0.02132,2.13192,23.63024
15.60000,1.29994,491.30409,0.02146,2.14615,23.78464
15.70000,1.30825,493.70402,0.02161,2.16113,23.90082
15.80000,1.31656,496.12657,0.02176,2.17573,24.01810
15.90000,1.32499,498.21911,0.02190,2.18982,24.11940
16.00000,1.33331,501.38957,0.02204,2.20414,24.27289
16.10000,1.34156,503.23135,0.02218,2.21791,24.36205
16.20000,1.34999,505.39039,0.02229,2.22924,24.46657
16.30000,1.35830,507.48698,0.02242,2.24238,24.56807
16.40000,1.36655,510.11071,0.02257,2.25689,24.69509
16.50000,1.37498,512.78421,0.02271,2.27091,24.82452
16.60000,1.38323,515.39708,0.02286,2.28580,24.95101
16.70000,1.39160,518.04963,0.02300,2.30008,25.07942
16.80000,1.40003,520.84522,0.02315,2.31509,25.21476
16.90000,1.40828,522.44598,0.02329,2.32934,25.29226
17.00000,1.41659,525.19715,0.02344,2.34381,25.42544
17.10000,1.42496,528.12952,0.02359,2.35861,25.56740
17.20000,1.43321,530.78984,0.02373,2.37298,25.69619
17.30000,1.44158,532.84438,0.02388,2.38785,25.79566
17.40000,1.44995,535.31001,0.02402,2.40243,25.91502
17.50000,1.45821,538.26557,0.02417,2.41675,26.05810
17.60000,1.46658,540.12383,0.02431,2.43111,26.14806
17.70000,1.47495,542.39007,0.02447,2.44669,26.25777
17.80000,1.48326,545.17207,0.02461,2.46116,26.39245
17.90000,1.49163,547.23821,0.02476,2.47593,26.49248
18.00000,1.50000,550.26361,0.02491,2.49092,26.63894
18.10000,1.50825,552.29878,0.02505,2.50543,26.73747
18.20000,1.51668,554.18988,0.02520,2.52009,26.82902
18.30000,1.52499,556.70789,0.02535,2.53472,26.95092
18.40000,1.53336,559.13278,0.02550,2.54968,27.06831
18.50000,1.54167,561.31613,0.02565,2.56476,27.17401
18.60000,1.54992,564.31605,0.02579,2.57936,27.31924
18.70000,1.55823,565.95728,0.02594,2.59408,27.39869
18.80000,1.56666,569.23283,0.02609,2.60914,27.55727
18.90000,1.57491,570.51377,0.02624,2.62405,27.61928
19.00000,1.58335,573.52120,0.02639,2.63904,27.76487
19.10000,1.59172,576.00564,0.02654,2.65435,27.88515
19.20000,1.59997,577.93963,0.02669,2.66922,27.97877
19.30000,1.60828,580.41005,0.02683,2.68343,28.09837
19.40000,1.61659,582.87247,0.02699,2.69862,28.21758
19.50000,1.62490,585.77126,0.02714,2.71378,28.35791
19.60000,1.63321,587.35004,0.02729,2.72867,28.43434
19.70000,1.64164,589.52654,0.02744,2.74378,28.53971
19.80000,1.64989,592.17731,0.02759,2.75864,28.66804
19.90000,1.65826,593.94524,0.02774,2.77397,28.75362
20.00000,1.66669,596.88422,0.02789,2.78928,28.89590
20.10000,1.67494,598.49829,0.02804,2.80386,28.97404
20.20000,1.68331,601.26074,0.02819,2.81911,29.10778
20.30000,1.69162,602.89251,0.02834,2.83449,29.18677
20.40000,1.69993,605.62850,0.02849,2.84926,29.31923
20.50000,1.70825,607.73743,0.02864,2.86432,29.42132
20.60000,1.71662,610.07082,0.02880,2.88009,29.53428
20.70000,1.72493,611.72186,0.02895,2.89485,29.61421
20.80000,1.73330,613.57096,0.02910,2.91018,29.70373
20.90000,1.74161,615.34001,0.02924,2.92425,29.78937
21.00000,1.74992,617.08051,0.02935,2.93480,29.87363
21.10000,1.75835,618.52057,0.02950,2.95026,29.94335
21.20000,1.76666,621.62699,0.02966,2.96563,30.09373
21.30000,1.77497,623.23296,0.02981,2.98090,30.17148
21.40000,1.78334,625.45720,0.02997,2.99654,30.27916
21.50000,1.79159,627.87314,0.03012,3.01221,30.39612
21.60000,1.79990,630.32513,0.03027,3.02723,30.51482
21.70000,1.80833,631.96626,0.03043,3.04266,30.59427
21.80000,1.81658,634.18760,0.03058,3.05799,30.70181
21.90000,1.82495,635.70254,0.03074,3.09147,30.77515
22.00000,1.83333,637.84313,0.03089,3.12495,30.87877
22.10000,1.84158,640.26127,0.03105,3.15796,30.99584
22.12600,1.84373,640.71096,0.03109,3.16656,31.01761
22.22600,1.85216,642.62268,0.03125,3.20029,31.11016
22.32600,1.86053,645.42075,0.03140,3.23377,31.24562
22.42600,1.86878,646.43049,0.03156,3.26677,31.29450
22.52600,1.87721,649.31158,0.03171,3.30049,31.43398
22.62600,1.88540,650.75089,0.03187,3.33326,31.50366
22.72600,1.89371,652.38955,0.03202,3.36650,31.58298
22.82600,1.90214,654.26412,0.03218,3.40022,31.67374
22.92600,1.91039,656.41310,0.03234,3.43323,31.77777
23.02600,1.91876,659.37219,0.03250,3.46671,31.92102
23.12600,1.92719,659.81140,0.03266,3.50043,31.94229
23.22600,1.93545,661.82408,0.03233,3.53343,32.03972
23.32600,1.94376,664.00943,0.03285,3.56668,32.14552
23.42600,1.95219,665.70877,0.03341,3.60040,32.22779
23.52600,1.96044,668.74321,0.02669,3.63340,32.37469
23.62600,1.96875,670.62052,0.02204,3.66664,32.46557
23.72600,1.97712,671.55403,0.00492,3.70013,32.51076
23.82600,1.98549,673.00224,0.00330,3.73361,32.58087
23.92600,1.99380,675.07760,0.00279,3.76685,32.68134
24.02600,2.00223,676.48934,0.00274,3.80057,32.74969
24.12600,2.01048,678.48517,0.00262,3.83358,32.84631
24.22600,2.01879,680.04769,0.00230,3.86682,32.92195
24.32600,2.02716,682.10177,0.00157,3.90030,33.02139
24.42600,2.03547,683.62844,0.00093,3.93354,33.09530
24.52600,2.04384,685.53621,0.00064,3.96703,33.18766
24.62600,2.05209,687.15164,0.00058,4.00003,33.26586
24.72600,2.06041,688.95449,0.00043,4.03327,33.35314
24.82600,2.06872,690.97807,0.00049,4.06652,33.45110
24.92600,2.07703,692.47154,0.00140,4.09976,33.52340
25.02600,2.08540,694.08021,0.00103,4.13324,33.60128
25.12600,2.09377,695.63859,0.00119,4.16672,33.67672
25.22600,2.10208,697.64359,0.00124,4.19997,33.77379
25.32600,2.11045,698.54553,0.00190,4.23345,33.81746
25.42600,2.11888,700.20305,0.00346,4.26717,33.89770
25.52600,2.12719,702.05717,-0.00018,4.30041,33.98746
25.62600,2.13544,704.01295,-0.00152,4.33342,34.08214
25.72600,2.14381,705.85585,-0.00331,4.36690,34.17136
25.82600,2.15212,706.73372,-0.01256,4.40014,34.21386
25.92600,2.16049,708.70016,-0.09752,4.43362,34.30905
26.02600,2.16886,710.23428,-0.06252,4.46711,34.38332
26.12600,2.17711,711.88337,-0.10438,4.50011,34.46315
26.22600,2.18549,713.09865,-0.09442,4.53359,34.52199
26.32600,2.19386,714.62351,-0.06930,4.56707,34.59581
26.42600,2.20223,716.75656,-0.05555,4.60056,34.69907
26.52600,2.21054,718.26125,-0.05605,4.63380,34.77192
26.62600,2.21879,718.73465,-0.05770,4.66680,34.79483
26.72600,2.22716,720.29592,-0.05691,4.70029,34.87042
26.82600,2.23553,721.92121,-0.05599,4.73377,34.94910
26.92600,2.24378,722.61165,-0.05691,4.76677,34.98252
27.02600,2.25203,724.23727,-0.05715,4.79978,35.06122
27.12600,2.26040,725.82476,-0.05650,4.83326,35.13807
27.22600,2.26871,726.97741,-0.05661,4.86650,35.19387
27.32600,2.27708,728.07986,-0.05705,4.89998,35.24725
27.42600,2.28545,729.90973,-0.05672,4.93346,35.33583
27.52600,2.29376,730.96864,-0.05657,4.96671,35.38710
27.62600,2.30207,732.92693,-0.05689,4.99995,35.48190
27.72600,2.31045,733.88102,-0.05683,5.03343,35.52809
27.82600,2.31870,735.26171,-0.05667,5.06644,35.59493
27.92600,2.32707,736.45762,-0.05677,5.09992,35.65282
28.02600,2.33550,737.73833,-0.05684,5.13364,35.71482
28.12600,2.34375,739.19953,-0.05683,5.16664,35.78556
28.22600,2.35212,740.65044,-0.05677,5.20012,35.85580
28.32600,2.36049,741.69463,-0.05680,5.23361,35.90636
28.42600,2.36880,743.30186,-0.05681,5.26685,35.98416
28.52600,2.37717,743.88394,-0.05675,5.30033,36.01234
28.62600,2.38554,745.50835,-0.05679,5.33381,36.09098
28.72600,2.39379,746.54738,-0.05681,5.36682,36.14128
28.82600,2.40216,747.55354,-0.05682,5.40030,36.18999
28.92600,2.41047,749.07462,-0.05681,5.43354,36.26363
29.02600,2.41878,749.25842,-0.05681,5.46679,36.27253
29.12600,2.42715,751.31380,-0.05684,5.50027,36.37203
29.22600,2.43541,751.77890,-0.05682,5.53327,36.39455
29.32600,2.44378,752.81323,-0.05680,5.56675,36.44462
29.42600,2.45215,754.63015,-0.05685,5.60024,36.53258
29.52600,2.46046,755.05995,-0.05684,5.63348,36.55339
29.62600,2.46877,756.38122,-0.05678,5.66672,36.61735
29.72600,2.47720,757.56530,-0.05687,5.70044,36.67467
29.82600,2.48545,758.22487,-0.05684,5.73345,36.70660
29.92600,2.49376,759.77547,-0.05680,5.76669,36.78167
30.02600,2.50213,760.05296,-0.05687,5.80017,36.79510
30.12600,2.51038,761.20347,-0.05685,5.83318,36.85080
30.22600,2.51875,762.42341,-0.05683,5.86666,36.90986
30.32600,2.52712,763.41713,-0.05684,5.90014,36.95797
30.42600,2.53543,763.60703,-0.05685,5.93338,36.96716
30.52600,2.54380,764.85565,-0.05687,5.96687,37.02761
30.62600,2.55211,765.35787,-0.05683,6.00011,37.05192
30.72600,2.56042,766.74409,-0.05684,6.03335,37.11903
30.82600,2.56880,767.10926,-0.05689,6.06683,37.13671
30.92600,2.57717,768.24659,-0.05685,6.10032,37.19177
31.02600,2.58554,769.17191,-0.05683,6.13380,37.23656
31.12600,2.59379,769.81336,-0.05689,6.16680,37.26762
31.22600,2.60210,769.85643,-0.05687,6.20004,37.26970
31.32600,2.61041,771.06580,-0.05684,6.23329,37.32825
31.42600,2.61878,771.55223,-0.05690,6.26677,37.35180
31.52600,2.62709,773.01646,-0.05689,6.30001,37.42268
31.62600,2.63546,773.21697,-0.05688,6.33349,37.43239
31.72600,2.64383,774.03854,-0.05690,6.36698,37.47216
31.82600,2.65208,774.73004,-0.05690,6.39998,37.50564
31.92600,2.66051,774.84213,-0.05692,6.43370,37.51107
32.02600,2.66882,776.24531,-0.05693,6.46695,37.57899
32.12600,2.67713,776.49201,-0.05690,6.50019,37.59094
32.22600,2.68545,776.95935,-0.05694,6.53343,37.61356
32.32600,2.69376,777.81281,-0.05695,6.56667,37.65488
32.42600,2.70213,778.45664,-0.05692,6.60016,37.68605
32.52600,2.71044,778.32681,-0.05694,6.63340,37.67976
32.62600,2.71875,779.27154,-0.05693,6.66664,37.72550
32.72600,2.72712,779.26908,-0.05693,6.70012,37.72538
32.82600,2.73549,779.47062,-0.05692,6.73361,37.73514
32.92600,2.74380,780.22410,-0.05694,6.76685,37.77161
33.02600,2.75217,780.97465,-0.05693,6.80033,37.80795
33.12600,2.76048,781.55184,-0.05694,6.83357,37.83589
33.22600,2.76879,781.35412,-0.05694,6.86682,37.82632
33.32600,2.77710,781.76698,-0.05690,6.90006,37.84631
33.42600,2.78541,782.33462,-0.05694,6.93330,37.87379
33.52600,2.79378,782.24568,-0.05694,6.96678,37.86948
33.62600,2.80209,783.08927,-0.05693,7.00003,37.91032
33.72600,2.81046,783.34101,-0.05695,7.03351,37.92251
33.82600,2.81884,782.93951,-0.05694,7.06699,37.90307
33.92600,2.82721,783.27321,-0.05695,7.10047,37.91922
34.02600,2.83552,784.27726,-0.05695,7.13372,37.96783
34.12600,2.84377,784.43261,-0.05694,7.16672,37.97535
34.22600,2.85208,784.45803,-0.05696,7.19996,37.97659
34.32600,2.86045,784.47554,-0.05693,7.23345,37.97743
34.42600,2.86876,784.83364,-0.05697,7.26669,37.99477
34.52600,2.87707,784.92314,-0.05697,7.29993,37.99910
34.62600,2.88544,784.60621,-0.05694,7.33341,37.98376
34.72600,2.89369,785.17292,-0.05694,7.36642,38.01119
34.82600,2.90206,784.94055,-0.05699,7.39990,37.99994
34.92600,2.91055,785.03229,-0.05694,7.43386,38.00438
35.02600,2.91880,784.72905,-0.05691,7.46686,37.98970
35.12600,2.92717,785.03592,-0.05699,7.50035,38.00456
35.22600,2.93560,784.61599,-0.05701,7.53407,37.98423
35.32600,2.94374,784.12369,-0.05697,7.56659,37.96040
35.42600,2.95217,784.86260,-0.05698,7.60031,37.99617
35.52600,2.96048,785.32947,-0.05701,7.63356,38.01877
35.62600,2.96873,784.23740,-0.05700,7.66656,37.96590
35.72600,2.97710,784.09482,-0.05695,7.70004,37.95900
35.82600,2.98541,784.67689,-0.05698,7.73329,37.98718
35.92600,2.99372,785.13455,-0.05699,7.76653,38.00933
36.02600,3.00215,784.21608,-0.05696,7.80025,37.96487
36.12600,3.01046,783.87819,-0.05695,7.83349,37.94851
36.22600,3.01883,783.94385,-0.05701,7.86698,37.95169
36.32600,3.02726,783.57393,-0.05699,7.90070,37.93378
36.42600,3.03545,783.45481,-0.05694,7.93346,37.92802
36.52600,3.04370,782.91288,-0.05700,7.96647,37.90178
36.62600,3.05219,782.96419,-0.05698,8.00043,37.90427
36.72600,3.06044,782.43846,-0.05693,8.03343,37.87881
36.82600,3.06876,782.53513,-0.05698,8.06667,37.88350
36.92600,3.07725,782.14472,-0.05697,8.10063,37.86459
37.02600,3.08538,782.06575,-0.05693,8.13316,37.86077
37.12600,3.09381,781.57019,-0.05698,8.16688,37.83678
37.22600,3.10224,781.33661,-0.05697,8.20060,37.82547
37.32600,3.11043,781.65364,-0.05695,8.23337,37.84082
37.42600,3.11880,780.75379,-0.05697,8.26685,37.79726
37.52600,3.12711,780.35817,-0.05695,8.30009,37.77810
37.62600,3.13536,780.22289,-0.05694,8.33309,37.77156
37.72600,3.14379,780.40319,-0.05698,8.36682,37.78028
37.82600,3.15210,779.47699,-0.05695,8.40006,37.73545
37.92600,3.16041,779.74782,-0.05693,8.43330,37.74856
38.02600,3.16878,778.71475,-0.05698,8.46678,37.69854
38.12600,3.17709,778.01519,-0.05698,8.50003,37.66468
38.22600,3.18540,777.65840,-0.05692,8.53327,37.64740
38.32600,3.19378,777.54315,-0.05697,8.56675,37.64183
38.42600,3.20209,777.69165,-0.05698,8.60000,37.64901
38.52600,3.21034,776.78394,-0.05694,8.63300,37.60507
38.62600,3.21883,776.17769,-0.05696,8.66696,37.57572
38.72600,3.22702,776.01434,-0.05700,8.69972,37.56781
38.82600,3.23539,775.35752,-0.05694,8.73321,37.53602
38.92600,3.24388,775.24651,-0.05696,8.76717,37.53064
39.02600,3.25207,774.89205,-0.05701,8.79993,37.51348
39.12600,3.26044,774.54816,-0.05694,8.83341,37.49683
39.22600,3.26881,773.85069,-0.05696,8.86689,37.46307
39.32600,3.27712,773.88873,-0.05700,8.90014,37.46491
39.42600,3.28549,773.40472,-0.05696,8.93362,37.44148
39.52600,3.29386,772.87266,-0.05697,8.96710,37.41572
39.62600,3.30217,771.93468,-0.05697,9.00035,37.37031
39.72600,3.31048,771.55908,-0.05696,9.03359,37.35213
39.82600,3.31880,771.24755,-0.05696,9.06683,37.33705
39.92600,3.32705,771.11614,-0.05695,9.09984,37.33069
40.02600,3.33542,771.10329,-0.05696,9.13332,37.33006
40.12600,3.34373,770.56973,-0.05699,9.16656,37.30423
40.22600,3.35210,770.22412,-0.05695,9.20004,37.28750
40.32600,3.36053,770.24987,-0.05696,9.23376,37.28875
40.42600,3.36878,769.40013,-0.05700,9.26677,37.24761
40.52600,3.37709,768.46103,-0.05697,9.30001,37.20215
40.62600,3.38546,769.02956,-0.05696,9.33349,37.22967
40.72600,3.39377,768.22024,-0.05699,9.36673,37.19049
40.82600,3.40202,767.22917,-0.05701,9.39974,37.14251
40.92600,3.41051,767.03103,-0.05696,9.43370,37.13292
41.02600,3.41876,766.91471,-0.05698,9.46670,37.12729
41.12600,3.42707,766.36001,-0.05702,9.49995,37.10044
41.22600,3.43550,766.08015,-0.05698,9.53367,37.08689
41.32600,3.44375,765.35400,-0.05699,9.56667,37.05173
41.42600,3.45213,765.03465,-0.05702,9.60015,37.03627
41.52600,3.46056,765.00340,-0.05702,9.63387,37.03476
41.62600,3.46875,764.86771,-0.05699,9.66664,37.02819
41.72600,3.47712,764.21942,-0.05700,9.70012,36.99681
41.82600,3.48549,763.92633,-0.05704,9.73360,36.98262
41.92600,3.49368,763.23310,-0.05698,9.76637,36.94906
42.02600,3.50211,763.37154,-0.05698,9.80009,36.95576
42.12600,3.51048,762.90946,-0.05704,9.83357,36.93339
42.22600,3.51873,762.81289,-0.05699,9.86658,36.92871
42.32600,3.52722,761.44841,-0.05695,9.90054,36.86266
42.42600,3.53553,761.07024,-0.05702,9.93378,36.84435
42.52600,3.54378,761.03252,-0.05701,9.96678,36.84253
42.62600,3.55227,760.99290,-0.05692,10.00074,36.84061
42.72600,3.56052,760.62437,-0.05699,10.03375,36.82277
42.82600,3.56872,760.23825,-0.05702,10.06651,36.80407
42.92600,3.57721,759.83969,-0.05697,10.10047,36.78478
43.02600,3.58534,759.03330,-0.05698,10.13300,36.74574
43.12600,3.59359,759.22115,-0.05701,10.16600,36.75484
43.22600,3.60214,758.74412,-0.05700,10.20020,36.73174
43.32600,3.61033,758.64219,-0.05698,10.23297,36.72681
43.42600,3.61870,758.42487,-0.05699,10.26645,36.71629
43.52600,3.62719,758.46082,-0.05701,10.30041,36.71803
43.62600,3.63544,757.47715,-0.05698,10.33341,36.67041
43.72600,3.64381,757.27934,-0.05698,10.36689,36.66083
43.82600,3.65224,756.77945,-0.05702,10.40062,36.63663
43.92600,3.66037,756.09488,-0.05700,10.43314,36.60349
44.02600,3.66880,756.06592,-0.05697,10.46686,36.60209
44.12600,3.67717,755.01502,-0.05704,10.50035,36.55121
44.22600,3.68542,755.48640,-0.05700,10.53335,36.57403
44.32600,3.69391,755.25572,-0.05698,10.56731,36.56286
44.42600,3.70217,754.79341,-0.05702,10.60031,36.54048
44.52600,3.71036,753.76621,-0.05701,10.63308,36.49075
44.62600,3.71891,753.69482,-0.05702,10.66728,36.48730
44.72600,3.72722,753.13719,-0.05703,10.70052,36.46030
44.82600,3.73541,753.37007,-0.05699,10.73328,36.47158
44.92600,3.74390,752.39372,-0.05703,10.76724,36.42431
45.02600,3.75209,752.13062,-0.05704,10.80001,36.41158
45.12600,3.76040,751.61760,-0.05698,10.83325,36.38674
45.22600,3.76889,751.66146,-0.05701,10.86721,36.38886
45.32600,3.77714,750.60176,-0.05702,10.90022,36.33756
45.42600,3.78539,750.94332,-0.05701,10.93322,36.35410
45.52600,3.79382,750.41926,-0.05701,10.96694,36.32872
45.62600,3.80207,750.01167,-0.05699,10.99994,36.30899
45.72600,3.81038,750.33824,-0.05704,11.03319,36.32480
45.82600,3.81887,748.90414,-0.05702,11.06715,36.25537
45.92600,3.82713,749.46093,-0.05697,11.10015,36.28233
46.02600,3.83544,748.63047,-0.05703,11.13340,36.24213
46.12600,3.84375,748.59126,-0.05702,11.16664,36.24023
46.22600,3.85206,748.61813,-0.05697,11.19988,36.24153
46.32600,3.86043,748.16151,-0.05702,11.23336,36.21943
46.42600,3.86880,747.18394,-0.05702,11.26685,36.17210
46.52600,3.87705,746.68205,-0.05696,11.29985,36.14780
46.62600,3.88548,746.59488,-0.05702,11.33357,36.14358
46.72600,3.89379,745.88787,-0.05702,11.36681,36.10936
46.82600,3.90216,745.80503,-0.05699,11.40030,36.10534
46.92600,3.91053,745.88745,-0.05701,11.43378,36.10933
47.02600,3.91878,745.06081,-0.05702,11.46678,36.06932
47.12600,3.92709,744.90868,-0.05703,11.50002,36.06195
47.22600,3.93546,744.65359,-0.05700,11.53351,36.04960
47.32600,3.94377,743.69828,-0.05702,11.56675,36.00335
47.42600,3.95209,743.87020,-0.05703,11.59999,36.01168
47.52600,3.96046,743.30745,-0.05703,11.63347,35.98443
47.62600,3.96877,743.19635,-0.05702,11.66672,35.97905
47.72600,3.97708,742.61832,-0.05703,11.69996,35.95107
47.82600,3.98551,742.39960,-0.05705,11.73368,35.94048
47.92600,3.99376,741.86800,-0.05701,11.76669,35.91475
48.02600,4.00207,741.69235,-0.05703,11.79993,35.90625
48.12600,4.01056,741.58791,-0.05705,11.83389,35.90119
48.22600,4.01881,740.58217,-0.05703,11.86689,35.85250
48.32600,4.02718,740.39111,-0.05705,11.90037,35.84325
48.42600,4.03549,740.35167,-0.05704,11.93362,35.84134
48.52600,4.04374,739.96293,-0.05702,11.96662,35.82252
48.62600,4.05217,738.44129,-0.05704,12.00034,35.74886
48.72600,4.06042,738.96041,-0.05709,12.03335,35.77399
48.82600,4.06879,738.15645,-0.05702,12.06683,35.73507
48.92600,4.07716,737.58014,-0.05705,12.10031,35.70717
49.02600,4.08548,737.49302,-0.05707,12.13355,35.70295
49.12600,4.09373,737.49390,-0.05700,12.16656,35.70299
49.22600,4.10216,736.83313,-0.05703,12.20028,35.67101
49.32600,4.11047,736.66745,-0.05708,12.23352,35.66298
49.42600,4.11872,736.21911,-0.05706,12.26653,35.64128
49.52600,4.12715,736.21683,-0.05706,12.30025,35.64117
49.62600,4.13540,735.58334,-0.05706,12.33325,35.61050
49.72600,4.14365,735.24895,-0.05707,12.36625,35.59431
49.82600,4.15214,734.63037,-0.05705,12.40022,35.56437
49.92600,4.16045,733.91213,-0.05702,12.43346,35.52959
50.02600,4.16876,733.70924,-0.05706,12.46670,35.51977
50.12600,4.17725,733.38384,-0.05706,12.50066,35.50402
50.22600,4.18544,732.52548,-0.05699,12.53343,35.46246
50.32600,4.19375,732.52483,-0.05706,12.56667,35.46243
50.42600,4.20213,731.96199,-0.05706,12.60015,35.43518
50.52600,4.21038,731.42485,-0.05699,12.63315,35.40918
50.62600,4.21875,731.10261,-0.05705,12.66664,35.39358
50.72600,4.22718,731.45102,-0.05703,12.70036,35.41045
50.82600,4.23543,730.16263,-0.05702,12.73336,35.34808
50.92600,4.24386,730.03424,-0.05705,12.76708,35.34186
51.02600,4.25217,728.88732,-0.05704,12.80033,35.28634
51.12600,4.26042,729.05463,-0.05705,12.83333,35.29444
51.22600,4.26891,728.86171,-0.05706,12.86729,35.28510
51.32600,4.27710,728.08377,-0.05707,12.90005,35.24744
51.42600,4.28541,728.01029,-0.05707,12.93330,35.24388
51.52600,4.29384,727.04670,-0.05704,12.96702,35.19723
51.62600,4.30209,726.94607,-0.05704,13.00002,35.19236
51.72600,4.31040,725.71947,-0.05705,13.03326,35.13298
51.82600,4.31889,725.52934,-0.05701,13.06723,35.12377
51.92600,4.32709,724.91006,-0.05702,13.09999,35.09379
52.02600,4.33540,724.01697,-0.05709,13.13323,35.05056
52.12600,4.34389,723.79005,-0.05703,13.16720,35.03957
52.22600,4.35214,722.99582,-0.05700,13.20020,35.00112
52.32600,4.36051,723.06637,-0.05707,13.23368,35.00454
52.42600,4.36888,722.25053,-0.05706,13.26716,34.96504
52.52600,4.37707,721.65225,-0.05703,13.29993,34.93608
52.62600,4.38544,720.88558,-0.05705,13.33341,34.89896
52.72600,4.39375,720.51585,-0.05707,13.36665,34.88107
52.82600,4.40206,720.25484,-0.05705,13.39990,34.86843
52.92600,4.41043,719.71612,-0.05702,13.43338,34.84235
53.02600,4.41880,718.91658,-0.05708,13.46686,34.80364
53.12600,4.42711,718.18647,-0.05707,13.50010,34.76830
53.22600,4.43554,717.69189,-0.05701,13.53382,34.74435
53.32600,4.44379,717.21040,-0.05710,13.56683,34.72104
53.42600,4.45210,716.60168,-0.05706,13.60007,34.69157
53.52600,4.46048,715.28894,-0.05702,13.63355,34.62802
53.62600,4.46873,714.76074,-0.05709,13.66656,34.60245
53.72600,4.47704,714.53336,-0.05706,13.69980,34.59145
53.82600,4.48547,713.02126,-0.05702,13.73352,34.51824
53.92600,4.49372,712.27499,-0.05708,13.76652,34.48211
54.02600,4.50203,712.10847,-0.05707,13.79977,34.47405
54.12600,4.51046,710.88178,-0.05704,13.83349,34.41467
54.22600,4.51877,709.30338,-0.05709,13.86673,34.33825
54.32600,4.52714,709.19660,-0.05706,13.90021,34.33308
54.42600,4.53551,708.57615,-0.05704,13.93370,34.30305
54.52600,4.54382,707.94835,-0.05710,13.96694,34.27266
54.62600,4.55213,706.25967,-0.05706,14.00018,34.19091
54.72600,4.56050,705.17352,-0.05706,14.03366,34.13832
54.82600,4.56881,704.78576,-0.05708,14.06691,34.11955
54.92600,4.57712,702.58048,-0.05706,14.10015,34.01279
55.02600,4.58544,702.05694,-0.05707,14.13339,33.98745
55.12600,4.59381,699.55201,-0.05705,14.16688,33.86618
55.22600,4.60218,698.28290,-0.05708,14.20036,33.80474
55.32600,4.61049,696.70542,-0.05709,14.23360,33.72837
55.42600,4.61886,693.24239,-0.05707,14.26708,33.56072
55.52600,4.62723,688.81400,-0.05709,14.30056,33.34634
55.62600,4.63548,683.66942,-0.05711,14.33357,33.09728
55.72600,4.64385,676.15337,-0.05708,14.36705,32.73342
55.82600,4.65216,654.19297,-0.05708,14.40029,31.67029
55.90800,4.65898,5.76289,-0.05709,14.42756,0.27899