File: Manufatura Aditiva/Classificação Direção/Ensaios/Ensaios SLS/Tracao_OLABI_08_06_2018_SLS_YZ4.is_metal_RawData/Specimen_RawData_4.csv
Time,Extension,Load,Strain 1,Tensile strain,Tensile stress
(sec),(mm),(N),(mm/mm),(%),(MPa)
0.00000,0.00006,23.07893,0.00095,0.09453,1.02186
0.20000,0.01375,29.19243,0.00112,0.11227,1.29255
0.40000,0.03270,39.44954,0.00142,0.14155,1.74670
0.60000,0.04986,46.46900,0.00164,0.16428,2.05750
0.80000,0.06673,51.92782,0.00182,0.18241,2.29920
1.00000,0.08329,59.91760,0.00207,0.20675,2.65296
1.20000,0.10003,66.87098,0.00231,0.23067,2.96083
1.40000,0.11683,74.41484,0.00254,0.25399,3.29485
1.60000,0.13333,81.12252,0.00276,0.27579,3.59184
1.80000,0.14995,86.95548,0.00295,0.29494,3.85011
2.00000,0.16663,94.16140,0.00318,0.31776,4.16916
2.20000,0.18331,99.85828,0.00338,0.33842,4.42140
2.40000,0.19994,105.25348,0.00356,0.35608,4.66029
2.60000,0.21668,111.02809,0.00375,0.37510,4.91597
2.80000,0.23336,115.41722,0.00391,0.39063,5.11030
3.00000,0.24992,120.97707,0.00408,0.40791,5.35648
3.20000,0.26666,124.50048,0.00422,0.42166,5.51248
3.40000,0.28340,129.05940,0.00437,0.43655,5.71433
3.60000,0.30002,132.33318,0.00447,0.44715,5.85929
3.80000,0.31665,135.71811,0.00457,0.45704,6.00916
4.00000,0.33333,138.65241,0.00468,0.46805,6.13908
4.20000,0.34995,141.17401,0.00476,0.47636,6.25073
4.40000,0.36663,144.42875,0.00486,0.48551,6.39484
4.60000,0.38331,146.34449,0.00493,0.49277,6.47966
4.80000,0.39999,148.79238,0.00499,0.49931,6.58805
5.00000,0.41667,150.67765,0.00506,0.50604,6.67152
5.20000,0.43335,153.04310,0.00514,0.51365,6.77626
5.40000,0.45010,155.66894,0.00521,0.52148,6.89252
5.60000,0.46666,157.86742,0.00529,0.52852,6.98986
5.80000,0.48334,160.77987,0.00534,0.53449,7.11882
6.00000,0.50002,161.95625,0.00541,0.54051,7.17090
6.20000,0.51664,163.31214,0.00546,0.54584,7.23094
6.40000,0.53326,165.65367,0.00551,0.55137,7.33461
6.60000,0.55000,167.55942,0.00557,0.55704,7.41899
6.80000,0.56674,169.18741,0.00562,0.56240,7.49107
7.00000,0.58331,170.90840,0.00567,0.56719,7.56727
7.20000,0.59993,172.68854,0.00572,0.57249,7.64609
7.40000,0.61673,174.78223,0.00579,0.57868,7.73879
7.60000,0.63329,176.62672,0.00585,0.58464,7.82046
7.80000,0.64997,178.60649,0.00590,0.59047,7.90812
8.00000,0.66671,180.78143,0.00597,0.59693,8.00442
8.20000,0.68333,182.22920,0.00603,0.60328,8.06852
8.40000,0.70002,184.08304,0.00611,0.61131,8.15061
8.60000,0.71670,187.74075,0.00621,0.62088,8.31256
8.80000,0.73344,189.62115,0.00631,0.63063,8.39581
9.00000,0.75000,192.87650,0.00641,0.64072,8.53995
9.20000,0.76662,195.54556,0.00652,0.65203,8.65813
9.40000,0.78336,198.91376,0.00663,0.66254,8.80726
9.60000,0.79992,201.85977,0.00674,0.67362,8.93770
9.80000,0.81666,204.93241,0.00685,0.68485,9.07375
10.00000,0.83341,208.62501,0.00697,0.69741,9.23724
10.20000,0.84991,212.19435,0.00710,0.70969,9.39528
10.40000,0.86665,214.96254,0.00722,0.72183,9.51785
10.60000,0.88333,218.82546,0.00734,0.73382,9.68889
10.80000,0.90007,221.92895,0.00745,0.74498,9.82630
11.00000,0.91669,224.66457,0.00757,0.75695,9.94742
11.20000,0.93331,227.95277,0.00770,0.76962,10.09302
11.40000,0.95000,231.68782,0.00783,0.78273,10.25839
11.60000,0.96656,235.29506,0.00796,0.79594,10.41811
11.80000,0.98336,239.78278,0.00810,0.81035,10.61681
12.00000,1.00010,243.01540,0.00824,0.82448,10.75994
12.20000,1.01666,246.72393,0.00839,0.83930,10.92414
12.40000,1.03328,251.20752,0.00854,0.85404,11.12266
12.60000,1.04996,254.55011,0.00869,0.86916,11.27066
12.80000,1.06664,258.73350,0.00883,0.88306,11.45589
13.00000,1.08333,262.49823,0.00898,0.89781,11.62258
13.20000,1.10001,265.39993,0.00912,0.91239,11.75105
13.40000,1.11675,269.68704,0.00928,0.92796,11.94087
13.60000,1.13325,273.53053,0.00943,0.94336,12.11105
13.80000,1.14999,277.42751,0.00959,0.95881,12.28360
14.00000,1.16673,281.17376,0.00974,0.97417,12.44947
14.20000,1.18329,285.36040,0.00990,0.98954,12.63484
14.40000,1.19998,289.83641,0.01005,1.00540,12.83302
14.60000,1.21672,293.73760,0.01021,1.02089,13.00576
14.80000,1.23334,296.77500,0.01037,1.03690,13.14024
15.00000,1.24996,300.89782,0.01053,1.05286,13.32279
15.20000,1.26670,304.83261,0.01070,1.06990,13.49701
15.40000,1.28338,308.56577,0.01086,1.08573,13.66230
15.60000,1.29994,312.18582,0.01102,1.10243,13.82258
15.80000,1.31656,316.06269,0.01119,1.11866,13.99424
16.00000,1.33343,319.94069,0.01136,1.13573,14.16594
16.20000,1.34993,324.12184,0.01152,1.15238,14.35107
16.40000,1.36667,328.04706,0.01170,1.16973,14.52487
16.60000,1.38341,331.77589,0.01187,1.18672,14.68997
16.80000,1.39997,335.93189,0.01204,1.20381,14.87398
17.00000,1.41659,339.55157,0.01221,1.22100,15.03425
17.20000,1.43339,343.82888,0.01239,1.23919,15.22364
17.40000,1.45001,347.89771,0.01257,1.25670,15.40379
17.60000,1.46664,351.50743,0.01274,1.27429,15.56362
17.80000,1.48320,355.42578,0.01292,1.29202,15.73711
18.00000,1.50000,359.44798,0.01310,1.31017,15.91520
18.20000,1.51656,364.00117,0.01328,1.32835,16.11680
18.40000,1.53336,367.32827,0.01347,1.34675,16.26411
18.60000,1.55004,371.83485,0.01366,1.36605,16.46365
18.80000,1.56666,374.50434,0.01383,1.38347,16.58185
19.00000,1.58335,378.92079,0.01402,1.40228,16.77739
19.20000,1.60003,382.70527,0.01421,1.42130,16.94496
19.40000,1.61665,386.82728,0.01440,1.44029,17.12747
19.60000,1.63333,390.85750,0.01459,1.45938,17.30591
19.80000,1.65001,394.15904,0.01479,1.47877,17.45210
20.00000,1.66663,398.79782,0.01499,1.49860,17.65748
20.20000,1.68325,402.36567,0.01518,1.51777,17.81546
20.40000,1.69993,406.45045,0.01537,1.53697,17.99632
20.60000,1.71674,410.12610,0.01557,1.55679,18.15907
20.80000,1.73330,414.15230,0.01576,1.57626,18.33733
21.00000,1.74992,418.11974,0.01597,1.59652,18.51300
21.20000,1.76672,421.87832,0.01617,1.61663,18.67941
21.40000,1.78334,424.92049,0.01637,1.63663,18.81411
21.60000,1.79996,428.38240,0.01657,1.65690,18.96739
21.80000,1.81682,432.66360,0.01678,1.67803,19.15695
22.00000,1.83339,436.40924,0.01698,1.69812,19.32280
22.20000,1.84995,439.75152,0.01718,1.71837,19.47078
22.40000,1.86669,444.39961,0.01739,1.73901,19.67659
22.60000,1.88337,447.77775,0.01760,1.76021,19.82616
22.80000,1.89993,451.52497,0.01782,1.78173,19.99207
23.00000,1.91661,455.16849,0.01803,1.80274,20.15340
23.20000,1.93335,458.76778,0.01824,1.82391,20.31276
23.40000,1.94997,462.19542,0.01845,1.84505,20.46453
23.60000,1.96666,465.73370,0.01867,1.86685,20.62119
23.80000,1.98340,469.38267,0.01888,1.88840,20.78275
24.00000,2.00008,473.09618,0.01911,1.91060,20.94718
24.20000,2.01670,476.55012,0.01932,1.93210,21.10011
24.40000,2.03338,480.13376,0.01954,1.95374,21.25878
24.60000,2.05006,482.90859,0.01975,1.97486,21.38164
24.80000,2.06662,486.40617,0.01997,1.99718,21.53650
25.00000,2.08331,489.88624,0.02020,2.01982,21.69059
25.20000,2.09999,493.13926,0.02042,2.04231,21.83462
25.40000,2.11661,497.46754,0.02065,2.06490,22.02626
25.60000,2.13323,499.77070,0.02088,2.08770,22.12824
25.80000,2.14997,503.34390,0.02110,2.11044,22.28645
26.00000,2.16671,506.63315,0.02134,2.13362,22.43209
26.20000,2.18339,509.45533,0.02157,2.15687,22.55704
26.40000,2.20001,512.62858,0.02180,2.17973,22.69754
26.60000,2.21670,515.89301,0.02203,2.20348,22.84208
26.80000,2.23338,519.25019,0.02227,2.22704,22.99073
27.00000,2.25000,522.34540,0.02251,2.25052,23.12777
27.20000,2.26674,525.23776,0.02275,2.27468,23.25584
27.40000,2.28336,528.82801,0.02299,2.29893,23.41480
27.60000,2.29998,531.95814,0.02323,2.32306,23.55339
27.80000,2.31666,534.58931,0.02347,2.34737,23.66990
28.00000,2.33334,537.74556,0.02371,2.37140,23.80964
28.20000,2.35003,540.56379,0.02396,2.39606,23.93443
28.40000,2.36665,543.69159,0.02421,2.42097,24.07291
28.60000,2.38333,546.65543,0.02445,2.44549,24.20414
28.80000,2.39995,549.50523,0.02470,2.46992,24.33032
29.00000,2.41663,552.16616,0.02495,2.49538,24.44814
29.20000,2.43337,555.14737,0.02520,2.51972,24.58014
29.40000,2.44999,557.30566,0.02545,2.54526,24.67570
29.60000,2.46668,560.45847,0.02570,2.57023,24.81530
29.80000,2.48342,563.78581,0.02596,2.59643,24.96262
30.00000,2.49998,566.76958,0.02622,2.62187,25.09473
30.20000,2.51666,569.56601,0.02648,2.64757,25.21855
30.40000,2.53334,571.32402,0.02674,2.67359,25.29639
30.60000,2.55002,574.53867,0.02700,2.69968,25.43872
30.80000,2.56658,577.28053,0.02726,2.72597,25.56013
31.00000,2.58326,579.84754,0.02752,2.75174,25.67378
31.20000,2.60001,582.43815,0.02778,2.77820,25.78849
31.40000,2.61663,584.64953,0.02805,2.80461,25.88640
31.60000,2.63331,587.17397,0.02831,2.83149,25.99817
31.80000,2.65005,589.80286,0.02858,2.85785,26.11457
32.00000,2.66661,592.15971,0.02884,2.88434,26.21893
32.20000,2.68335,595.41739,0.02912,2.91179,26.36317
32.40000,2.70003,597.89359,0.02939,2.93888,26.47281
32.60000,2.71671,599.96182,0.02966,2.96603,26.56438
32.80000,2.73340,602.52836,0.02993,2.99291,26.67802
33.00000,2.74996,605.00577,0.03021,3.02086,26.78771
33.20000,2.76670,607.03456,0.03048,3.04829,26.87754
33.40000,2.78338,609.62145,0.03076,3.11501,26.99208
33.51800,2.79325,611.20582,0.03092,3.15447,27.06223
33.71800,2.80981,612.85724,0.03120,3.22072,27.13535
33.91800,2.82649,615.82169,0.03147,3.28744,27.26660
34.11800,2.84311,617.87176,0.03175,3.35393,27.35737
34.31800,2.85979,619.90703,0.03203,3.42065,27.44749
34.51800,2.87653,622.23943,0.03231,3.48762,27.55076
34.71800,2.89321,624.74580,0.03260,3.55434,27.66173
34.91800,2.90984,626.87728,0.03288,3.62083,27.75611
35.11800,2.92646,629.18868,0.03316,3.68732,27.85845
35.31800,2.94314,630.14105,0.03342,3.75404,27.90062
35.51800,2.95988,633.01870,0.03362,3.82100,28.02803
35.71800,2.97656,634.56688,0.03434,3.88773,28.09658
35.91800,2.99312,637.18045,0.03311,3.95398,28.21230
36.11800,3.00986,636.99419,0.01279,4.02094,28.20405
36.31800,3.02642,641.39264,0.01252,4.08719,28.39880
36.51800,3.04311,643.63764,0.00890,4.15391,28.49820
36.71800,3.05991,645.42750,0.00883,4.22112,28.57745
36.91800,3.07653,647.34048,0.01085,4.28760,28.66215
37.11800,3.09309,649.97319,0.01150,4.35385,28.77872
37.31800,3.10983,651.39094,-0.03028,4.42081,28.84150
37.51800,3.12657,653.74235,-0.13377,4.48778,28.94561
37.71800,3.14313,654.94254,-0.13392,4.55402,28.99875
37.91800,3.15987,657.38219,-0.13395,4.62099,29.10677
38.11800,3.17656,660.04852,-0.13397,4.68771,29.22482
38.31800,3.19312,661.06147,-0.13396,4.75396,29.26968
38.51800,3.20974,663.30023,-0.13396,4.82045,29.36880
38.71800,3.22654,665.46639,-0.13397,4.88765,29.46471
38.91800,3.24310,666.81565,-0.13397,4.95390,29.52445
39.11800,3.25984,668.27773,-0.13397,5.02086,29.58919
39.31800,3.27652,670.30778,-0.13398,5.08759,29.67907
39.51800,3.29321,672.04111,-0.13397,5.15431,29.75582
39.71800,3.30977,673.87880,-0.13397,5.22056,29.83718
39.91800,3.32645,675.61427,-0.13398,5.28728,29.91403
40.11800,3.34325,677.30676,-0.13398,5.35449,29.98896
40.31800,3.35987,679.73202,-0.13398,5.42097,30.09635
40.51800,3.37649,680.77715,-0.13397,5.48746,30.14262
40.71800,3.39323,682.66978,-0.13398,5.55442,30.22642
40.91800,3.40979,684.43906,-0.13398,5.62067,30.30476
41.11800,3.42654,686.30581,-0.13398,5.68763,30.38741
41.31800,3.44316,687.63257,-0.13398,5.75412,30.44616
41.51800,3.45978,689.48641,-0.13398,5.82060,30.52824
41.71800,3.47640,691.30249,-0.13398,5.88709,30.60865
41.91800,3.49314,693.05701,-0.13398,5.95405,30.68633
42.11800,3.50994,694.14903,-0.13398,6.02126,30.73469
42.31800,3.52650,696.27636,-0.13398,6.08751,30.82888
42.51800,3.54313,696.08153,-0.13398,6.15399,30.82025
42.71800,3.55987,698.43000,-0.13398,6.22096,30.92423
42.91800,3.57643,699.40216,-0.13399,6.28720,30.96728
43.11800,3.59317,701.96385,-0.13398,6.35417,31.08070
43.31800,3.60991,703.77630,-0.13398,6.42113,31.16095
43.51800,3.62647,705.45217,-0.13398,6.48738,31.23515
43.71800,3.64303,706.93209,-0.13398,6.55362,31.30068
43.91800,3.65983,708.51869,-0.13398,6.62083,31.37093
44.11800,3.67658,711.17664,-0.13398,6.68779,31.48861
44.31800,3.69314,711.68472,-0.13398,6.75404,31.51111
44.51800,3.70982,714.16884,-0.13398,6.82076,31.62110
44.71800,3.72662,715.73537,-0.13398,6.88797,31.69046
44.91800,3.74312,717.12243,-0.13399,6.95397,31.75187
45.11800,3.75980,717.89585,-0.13398,7.02070,31.78612
45.31800,3.77666,720.06779,-0.13398,7.08814,31.88229
45.51800,3.79317,722.32294,-0.13398,7.15415,31.98214
45.71800,3.80973,723.03885,-0.13398,7.22040,32.01384
45.91800,3.82653,723.63978,-0.13398,7.28760,32.04044
46.11800,3.84321,726.08376,-0.13398,7.35433,32.14865
46.31800,3.85983,727.67655,-0.13398,7.42081,32.21918
46.51800,3.87645,728.94134,-0.13399,7.48730,32.27518
46.71800,3.89319,730.75346,-0.13399,7.55426,32.35541
46.91800,3.90975,731.76729,-0.13399,7.62051,32.40030
47.11800,3.92644,733.14304,-0.13398,7.68723,32.46122
47.31800,3.94318,734.58031,-0.13399,7.75420,32.52485
47.51800,3.95980,736.01040,-0.13398,7.82068,32.58817
47.71800,3.97648,736.59904,-0.13398,7.88741,32.61423
47.91800,3.99310,738.25675,-0.13399,7.95389,32.68763
48.11800,4.00984,739.82845,-0.13399,8.02086,32.75723
48.31800,4.02646,741.55596,-0.13398,8.08734,32.83371
48.51800,4.04314,742.81166,-0.13399,8.15407,32.88931
48.71800,4.05989,743.65395,-0.13398,8.22103,32.92661
48.91800,4.07645,744.74365,-0.13398,8.28728,32.97485
49.11800,4.09307,745.90836,-0.13398,8.35376,33.02642
49.31800,4.10987,747.73203,-0.13399,8.42097,33.10717
49.51800,4.12649,746.59125,-0.13399,8.48745,33.05666
49.71800,4.14317,748.02809,-0.13399,8.55418,33.12028
49.91800,4.15985,750.51910,-0.13399,8.62091,33.23057
50.11800,4.17648,751.63716,-0.13399,8.68739,33.28008
50.31800,4.19304,754.00732,-0.13398,8.75364,33.38502
50.51800,4.20984,753.57812,-0.13399,8.82084,33.36602
50.71800,4.22664,755.74289,-0.13399,8.88804,33.46186
50.91800,4.24314,757.37066,-0.13398,8.95405,33.53394
51.11800,4.25976,758.13844,-0.13399,9.02054,33.56793
51.31800,4.27656,760.35066,-0.13399,9.08774,33.66588
51.51800,4.29318,759.85291,-0.13399,9.15423,33.64384
51.71800,4.30981,761.84170,-0.13399,9.22071,33.73190
51.91800,4.32655,763.23808,-0.13399,9.28768,33.79373
52.11800,4.34317,765.51423,-0.13399,9.35416,33.89451
52.31800,4.35979,765.99400,-0.13399,9.42065,33.91575
52.51800,4.37653,766.97832,-0.13399,9.48761,33.95933
52.71800,4.39321,767.79728,-0.13399,9.55434,33.99559
52.91800,4.40983,769.86761,-0.13399,9.62083,34.08726
53.11800,4.42646,770.70296,-0.13399,9.68731,34.12425
53.31800,4.44314,772.18642,-0.13399,9.75404,34.18993
53.51800,4.45982,773.16496,-0.13399,9.82076,34.23326
53.71800,4.47650,773.17636,-0.13399,9.88749,34.23376
53.91800,4.49324,774.78089,-0.13399,9.95445,34.30481
54.11800,4.50980,776.11255,-0.13399,10.02070,34.36377
54.31800,4.52642,777.92876,-0.13399,10.08718,34.44418
54.51800,4.54310,778.86516,-0.13399,10.15391,34.48565
54.71800,4.55985,779.80403,-0.13399,10.22087,34.52721
54.91800,4.57647,780.18839,-0.13399,10.28736,34.54423
55.11800,4.59321,781.19677,-0.13399,10.35432,34.58888
55.31800,4.60983,781.69303,-0.13399,10.42081,34.61085
55.51800,4.62651,780.58578,-0.13399,10.48753,34.56183
55.71800,4.64313,782.85197,-0.13399,10.55402,34.66217
55.91800,4.65987,784.04900,-0.13399,10.62098,34.71517
56.11800,4.67655,784.88635,-0.13399,10.68771,34.75224
56.31800,4.69318,785.44971,-0.13399,10.75419,34.77719
56.51800,4.70986,786.68995,-0.13399,10.82092,34.83210
56.71800,4.72648,787.92246,-0.13400,10.88741,34.88667
56.91800,4.74310,790.01710,-0.13400,10.95389,34.97942
57.11800,4.75978,790.87876,-0.13399,11.02062,35.01757
57.31800,4.77652,791.57585,-0.13400,11.08758,35.04843
57.51800,4.79308,792.24491,-0.13400,11.15383,35.07806
57.71800,4.80977,793.61470,-0.13400,11.22055,35.13871
57.91800,4.82657,794.89052,-0.13400,11.28776,35.19519
58.11800,4.84325,796.32616,-0.13399,11.35448,35.25876
58.31800,4.85981,797.41888,-0.13400,11.42073,35.30714
58.51800,4.87655,797.75071,-0.13400,11.48769,35.32183
58.71800,4.89317,799.15542,-0.13400,11.55418,35.38403
58.91800,4.90979,799.71058,-0.13399,11.62066,35.40861
59.11800,4.92653,800.19739,-0.13400,11.68763,35.43016
59.31800,4.94322,801.47395,-0.13400,11.75435,35.48669
59.51800,4.95984,803.13580,-0.13400,11.82084,35.56027
59.71800,4.97640,803.64356,-0.13399,11.88708,35.58275
59.91800,4.99320,804.77139,-0.13400,11.95429,35.63269
60.11800,5.00982,805.47435,-0.13400,12.02077,35.66381
60.31800,5.02656,802.77398,-0.13400,12.08774,35.54425
60.51800,5.04324,805.57149,-0.13399,12.15446,35.66811
60.71800,5.05987,806.03249,-0.13400,12.22095,35.68853
60.91800,5.07655,807.66818,-0.13399,12.28767,35.76095
61.11800,5.09311,808.54297,-0.13400,12.35392,35.79968
61.31800,5.10985,809.84272,-0.13400,12.42088,35.85723
61.51800,5.12653,811.19491,-0.13399,12.48761,35.91710
61.71800,5.14303,811.05744,-0.13400,12.55362,35.91101
61.91800,5.15983,811.83063,-0.13400,12.62082,35.94525
62.11800,5.17651,812.98407,-0.13399,12.68755,35.99632
62.31800,5.19308,814.45910,-0.13399,12.75380,36.06163
62.51800,5.20988,815.19391,-0.13400,12.82100,36.09417
62.71800,5.22650,816.73972,-0.13399,12.88748,36.16261
62.91800,5.24312,816.74028,-0.13400,12.95397,36.16263
63.11800,5.25980,818.11249,-0.13399,13.02069,36.22339
63.31800,5.27648,817.60772,-0.13400,13.08742,36.20104
63.51800,5.29322,818.92768,-0.13400,13.15438,36.25948
63.71800,5.30984,820.30669,-0.13400,13.22087,36.32054
63.91800,5.32653,821.23335,-0.13399,13.28759,36.36157
64.11800,5.34309,821.47373,-0.13399,13.35384,36.37222
64.31800,5.35977,822.55257,-0.13400,13.42057,36.41998
64.51800,5.37657,823.38648,-0.13399,13.48777,36.45691
64.71800,5.39313,824.51506,-0.13399,13.55401,36.50687
64.91801,5.40981,824.41801,-0.13399,13.62074,36.50258
65.11800,5.42655,825.03790,-0.13399,13.68771,36.53003
65.31800,5.44312,826.17160,-0.13399,13.75395,36.58022
65.51800,5.45980,827.09994,-0.13399,13.82068,36.62133
65.71800,5.47660,827.81808,-0.13399,13.88788,36.65312
65.91801,5.49322,825.60880,-0.13399,13.95437,36.55530
66.11800,5.50978,826.98949,-0.13400,14.02061,36.61643
66.31800,5.52646,828.15411,-0.13400,14.08734,36.66800
66.51801,5.54326,829.72944,-0.13400,14.15454,36.73775
66.71800,5.55982,830.28469,-0.13400,14.22079,36.76234
66.91801,5.57651,829.87156,-0.13399,14.28751,36.74404
67.11800,5.59325,831.24936,-0.13399,14.35448,36.80505
67.31800,5.60981,832.25556,-0.13399,14.42072,36.84960
67.51801,5.62649,833.18092,-0.13399,14.48745,36.89057
67.71800,5.64317,833.88519,-0.13400,14.55417,36.92175
67.91801,5.65985,834.64766,-0.13400,14.62090,36.95551
68.11800,5.67647,836.22159,-0.13400,14.68739,37.02520
68.31800,5.69310,836.55454,-0.13400,14.75387,37.03994
68.51801,5.70984,837.63879,-0.13400,14.82084,37.08795
68.71800,5.72640,837.50393,-0.13399,14.88708,37.08198
68.91801,5.74326,837.02421,-0.13400,14.95453,37.06074
69.11800,5.75994,838.20289,-0.13400,15.02125,37.11293
69.31800,5.77644,839.10422,-0.13399,15.08726,37.15284
69.51801,5.79318,840.27965,-0.13399,15.15422,37.20488
69.71800,5.80981,840.47103,-0.13399,15.22071,37.21335
69.91801,5.82655,841.54857,-0.13399,15.28767,37.26106
70.11800,5.84323,841.58676,-0.13399,15.35440,37.26275
70.31800,5.85979,842.88251,-0.13399,15.42064,37.32013
70.51801,5.87647,843.17941,-0.13399,15.48737,37.33327
70.71800,5.89309,843.59786,-0.13399,15.55386,37.35180
70.91801,5.90983,844.13849,-0.13399,15.62082,37.37574
71.11800,5.92663,843.63306,-0.13400,15.68802,37.35336
71.31800,5.94313,844.92806,-0.13399,15.75403,37.41070
71.51801,5.95982,845.56034,-0.13400,15.82076,37.43869
71.71800,5.97656,846.37878,-0.13399,15.88772,37.47493
71.91801,5.99318,847.04785,-0.13399,15.95421,37.50455
72.11800,6.00980,847.80231,-0.13400,16.02069,37.53796
72.31800,6.02654,848.31817,-0.13400,16.08766,37.56080
72.51801,6.04316,846.55900,-0.13400,16.15414,37.48291
72.71800,6.05972,847.20384,-0.13400,16.22039,37.51146
72.91801,6.07647,847.88045,-0.13399,16.28735,37.54142
73.11800,6.09327,849.54193,-0.13400,16.35455,37.61498
73.31800,6.10983,849.90766,-0.13399,16.42080,37.63118
73.51801,6.12651,848.33708,-0.13399,16.48753,37.56164
73.71800,6.14319,850.17933,-0.13400,16.55425,37.64320
73.91801,6.15981,850.10901,-0.13399,16.62074,37.64009
74.11800,6.17643,851.11456,-0.13399,16.68722,37.68462
74.31800,6.19323,852.54163,-0.13399,16.75443,37.74780
74.51801,6.20986,852.80361,-0.13400,16.82092,37.75940
74.71800,6.22642,853.72524,-0.13399,16.88716,37.80021
74.91801,6.24310,854.09358,-0.13399,16.95389,37.81652
75.11800,6.25990,854.85224,-0.13399,17.02109,37.85011
75.31800,6.27652,854.96726,-0.13400,17.08757,37.85520
75.51801,6.29308,855.62179,-0.13399,17.15382,37.88418
75.71800,6.30982,856.50142,-0.13400,17.22079,37.92313
75.91801,6.32645,856.48783,-0.13399,17.28727,37.92253
76.11800,6.34313,856.32261,-0.13399,17.35400,37.91521
76.31800,6.35987,856.89742,-0.13400,17.42096,37.94066
76.51801,6.37661,857.30907,-0.13399,17.48793,37.95889
76.71800,6.39311,857.06012,-0.13400,17.55393,37.94786
76.91801,6.40979,858.50824,-0.13400,17.62066,38.01198
77.11800,6.42653,858.66498,-0.13399,17.68762,38.01892
77.31800,6.44315,859.32808,-0.13400,17.75411,38.04828
77.51801,6.45990,860.25596,-0.13400,17.82107,38.08937
77.71800,6.47658,860.07677,-0.13400,17.88780,38.08143
77.91801,6.49308,860.84306,-0.13400,17.95380,38.11536
78.11800,6.50976,861.22714,-0.13400,18.02053,38.13237
78.31800,6.52650,861.82794,-0.13399,18.08750,38.15897
78.51801,6.54318,861.47143,-0.13400,18.15422,38.14318
78.71800,6.55980,861.49275,-0.13400,18.22070,38.14413
78.91801,6.57655,861.95553,-0.13400,18.28767,38.16462
79.11800,6.59323,862.24265,-0.13400,18.35439,38.17733
79.31800,6.60973,862.67218,-0.13400,18.42040,38.19635
79.51801,6.62653,863.76946,-0.13399,18.48761,38.24493
79.71800,6.64327,864.25534,-0.13399,18.55457,38.26645
79.91801,6.65977,863.78101,-0.13399,18.62058,38.24545
80.11800,6.67645,864.35806,-0.13399,18.68730,38.27100
80.31800,6.69325,863.06101,-0.13400,18.75451,38.21357
80.51801,6.70982,863.64262,-0.13399,18.82075,38.23932
80.71800,6.72644,864.26008,-0.13399,18.88724,38.26665
80.91801,6.74318,865.74787,-0.13400,18.95420,38.33253
81.11800,6.75980,865.60277,-0.13399,19.02069,38.32611
81.31800,6.77642,866.55086,-0.13400,19.08718,38.36808
81.51801,6.79316,866.86248,-0.13400,19.15414,38.38188
81.71800,6.80990,867.01475,-0.13400,19.22110,38.38862
81.91801,6.82647,867.26891,-0.13400,19.28735,38.39988
82.11800,6.84315,866.99584,-0.13400,19.35408,38.38779
82.31800,6.85983,867.14868,-0.13400,19.42080,38.39455
82.51801,6.87645,867.98202,-0.13400,19.48729,38.43145
82.71800,6.89319,867.79697,-0.13399,19.55425,38.42326
82.91801,6.90987,868.54305,-0.13400,19.62098,38.45629
83.11800,6.92649,869.05695,-0.13400,19.68746,38.47905
83.31800,6.94311,869.50781,-0.13399,19.75395,38.49901
83.51801,6.95980,870.22344,-0.13399,19.82067,38.53069
83.71800,6.97648,870.26795,-0.13399,19.88740,38.53267
83.91801,6.99316,870.40225,-0.13399,19.95412,38.53861
84.11800,7.00984,871.00063,-0.13400,20.02085,38.56511
84.31800,7.02652,871.63178,-0.13400,20.08757,38.59305
84.51801,7.04308,871.89134,-0.13399,20.15382,38.60455
84.71800,7.05982,871.81227,-0.13400,20.22078,38.60104
84.91801,7.07662,872.81736,-0.13399,20.28799,38.64555
85.11800,7.09319,872.80804,-0.13399,20.35423,38.64513
85.31800,7.10981,872.76418,-0.13400,20.42072,38.64319
85.51801,7.12649,873.07170,-0.13400,20.48745,38.65681
85.71800,7.14317,872.19365,-0.13400,20.55417,38.61793
85.91801,7.15985,871.88417,-0.13400,20.62090,38.60423
86.11800,7.17653,872.64869,-0.13400,20.68762,38.63808
86.31800,7.19321,873.30155,-0.13400,20.75435,38.66698
86.51801,7.20972,873.40586,-0.13400,20.82035,38.67160
86.71800,7.22640,873.68554,-0.13400,20.88708,38.68399
86.91801,7.24326,874.32973,-0.13400,20.95452,38.71251
87.11800,7.25988,874.72480,-0.13400,21.02101,38.73000
87.31800,7.27650,874.88228,-0.13400,21.08749,38.73697
87.51801,7.29318,874.75106,-0.13400,21.15422,38.73116
87.71800,7.30986,875.42031,-0.13400,21.22094,38.76080
87.91801,7.32648,876.00900,-0.13400,21.28743,38.78686
88.11800,7.34311,875.69058,-0.13400,21.35391,38.77276
88.31800,7.35985,876.21454,-0.13400,21.42088,38.79596
88.51801,7.37641,876.20076,-0.13400,21.48713,38.79535
88.71800,7.39309,876.09952,-0.13400,21.55385,38.79087
88.91801,7.40989,876.54516,-0.13400,21.62105,38.81060
89.11800,7.42645,876.44868,-0.13401,21.68730,38.80633
89.31800,7.44319,877.04835,-0.13400,21.75427,38.83288
89.51801,7.45988,877.23127,-0.13400,21.82099,38.84098
89.71800,7.47650,876.72547,-0.13400,21.88748,38.81858
89.91801,7.49318,876.99965,-0.13400,21.95420,38.83072
90.11800,7.50980,876.17328,-0.13400,22.02069,38.79414
90.31800,7.52660,876.92104,-0.13401,22.08789,38.82724
90.51801,7.54316,877.24552,-0.13400,22.15414,38.84161
90.71800,7.55984,877.35783,-0.13401,22.22086,38.84658
90.91801,7.57652,877.53432,-0.13400,22.28759,38.85440
91.11800,7.59315,877.69534,-0.13400,22.35407,38.86153
91.31800,7.60983,877.40170,-0.13400,22.42080,38.84853
91.51801,7.62645,878.57991,-0.13400,22.48728,38.90069
91.71800,7.64313,878.47868,-0.13400,22.55401,38.89621
91.91801,7.65987,878.75482,-0.13400,22.62097,38.90844
92.11800,7.67643,878.71552,-0.13400,22.68722,38.90670
92.31800,7.69317,879.09987,-0.13400,22.75418,38.92371
92.51801,7.70985,880.03669,-0.13400,22.82091,38.96519
92.71800,7.72648,878.85531,-0.13400,22.88739,38.91289
92.91801,7.74322,876.94749,-0.13400,22.95436,38.82841
93.11800,7.75978,877.76612,-0.13400,23.02061,38.86466
93.31800,7.77640,878.30052,-0.13400,23.08709,38.88832
93.51801,7.79320,878.37698,-0.13400,23.15430,38.89171
93.71800,7.80982,878.88306,-0.13400,23.22078,38.91412
93.91801,7.82638,879.41149,-0.13400,23.28703,38.93751
94.11800,7.84313,879.53154,-0.13400,23.35399,38.94283
94.31800,7.85987,879.59012,-0.13400,23.42095,38.94542
94.51801,7.87649,879.86058,-0.13400,23.48744,38.95740
94.71800,7.89317,880.71022,-0.13400,23.55417,38.99501
94.91801,7.90991,880.74580,-0.13400,23.62113,38.99659
95.11800,7.92647,880.83455,-0.13400,23.68738,39.00052
95.31800,7.94321,880.61662,-0.13400,23.75434,38.99087
95.51801,7.95989,880.72009,-0.13400,23.82107,38.99545
95.71800,7.97652,879.93927,-0.13400,23.88756,38.96088
95.91801,7.99320,879.96470,-0.13400,23.95428,38.96201
96.11800,8.00982,880.54957,-0.13400,24.02076,38.98790
96.31800,8.02650,880.60601,-0.13400,24.08749,38.99040
96.51801,8.04318,881.28885,-0.13400,24.15421,39.02063
96.71800,8.05974,881.59293,-0.13400,24.22046,39.03410
96.91801,8.07648,881.62897,-0.13400,24.28742,39.03569
97.11800,8.09311,881.60569,-0.13400,24.35391,39.03466
97.31801,8.10979,881.43330,-0.13400,24.42064,39.02703
97.51801,8.12647,881.91396,-0.13400,24.48736,39.04831
97.71800,8.14315,882.18879,-0.13400,24.55409,39.06048
97.91801,8.15989,881.86404,-0.13400,24.62105,39.04610
98.11800,8.17651,882.17333,-0.13400,24.68753,39.05980
98.31801,8.19319,882.65799,-0.13400,24.75426,39.08126
98.51801,8.20981,882.86195,-0.13400,24.82075,39.09029
98.71800,8.22650,882.94931,-0.13400,24.88747,39.09415
98.91801,8.24318,883.19751,-0.13400,24.95420,39.10514
99.11800,8.25980,882.90023,-0.13400,25.02068,39.09198
99.31801,8.27648,882.47247,-0.13400,25.08741,39.07304
99.51801,8.29316,882.38753,-0.13400,25.15413,39.06928
99.71800,8.30978,883.32621,-0.13400,25.22062,39.11084
99.91801,8.32652,883.13501,-0.13400,25.28759,39.10238
100.11800,8.34326,883.07830,-0.13400,25.35455,39.09986
100.31801,8.35983,883.04086,-0.13400,25.42079,39.09821
100.51801,8.37645,883.27434,-0.13400,25.48728,39.10855
100.71800,8.39319,883.37492,-0.13400,25.55425,39.11300
100.91801,8.40987,883.46554,-0.13400,25.62097,39.11701
101.11800,8.42649,883.73814,-0.13400,25.68746,39.12908
101.31801,8.44317,883.19965,-0.13400,25.75418,39.10524
101.51801,8.45991,883.80417,-0.13400,25.82114,39.13200
101.71800,8.47648,883.69455,-0.13400,25.88739,39.12715
101.91801,8.49310,883.81693,-0.13400,25.95388,39.13257
102.11800,8.50990,883.68002,-0.13400,26.02108,39.12651
102.31801,8.52652,883.63979,-0.13400,26.08756,39.12473
102.51801,8.54308,883.89330,-0.13400,26.15381,39.13595
102.71800,8.55982,884.56683,-0.13400,26.22078,39.16578
102.91801,8.57650,882.62698,-0.13400,26.28750,39.07988
103.11800,8.59313,882.69226,-0.13400,26.35399,39.08278
103.31801,8.60981,882.55517,-0.13400,26.42072,39.07670
103.51801,8.62655,882.99755,-0.13400,26.48768,39.09629
103.71800,8.64311,882.98107,-0.13400,26.55392,39.09556
103.91801,8.65979,883.58372,-0.13400,26.62065,39.12225
104.11800,8.67653,883.62740,-0.13400,26.68761,39.12418
104.31801,8.69315,883.31802,-0.13400,26.75410,39.11048
104.51801,8.70977,883.38023,-0.13400,26.82059,39.11324
104.71800,8.72646,883.80277,-0.13400,26.88731,39.13194
104.91801,8.74314,883.59201,-0.13400,26.95404,39.12261
105.11800,8.75982,883.91677,-0.13400,27.02076,39.13699
105.31801,8.77656,884.00319,-0.13400,27.08773,39.14082
105.51801,8.79324,883.63122,-0.13400,27.15445,39.12435
105.71800,8.80986,883.61921,-0.13400,27.22094,39.12382
105.91801,8.82648,884.02638,-0.13400,27.28742,39.14185
106.11800,8.84322,884.05954,-0.13400,27.35439,39.14331
106.31801,8.85985,883.49413,-0.13400,27.42087,39.11828
106.51801,8.87647,883.76347,-0.13400,27.48736,39.13020
106.71800,8.89321,883.83369,-0.13400,27.55432,39.13331
106.91801,8.90977,884.56105,-0.13400,27.62057,39.16552
107.11800,8.92639,883.83760,-0.13400,27.68705,39.13348
107.31801,8.94319,884.19486,-0.13400,27.75426,39.14930
107.51801,8.95987,884.10750,-0.13400,27.82098,39.14544
107.71800,8.97644,884.05125,-0.13400,27.88723,39.14294
107.91801,8.99318,883.91071,-0.13400,27.95420,39.13672
108.11800,9.00992,884.10517,-0.13400,28.02116,39.14533
108.31801,9.02642,884.31137,-0.13400,28.08717,39.15446
108.51801,9.04322,883.77660,-0.13400,28.15437,39.13078
108.71800,9.06002,884.47249,-0.13400,28.22158,39.16160
108.91801,9.07640,885.00464,-0.13400,28.28710,39.18516
109.11800,9.09308,883.65385,-0.13400,28.35383,39.12535
109.31801,9.10989,884.16412,-0.13400,28.42103,39.14794
109.51801,9.12651,884.24906,-0.13400,28.48752,39.15170
109.71800,9.14313,884.55966,-0.13400,28.55400,39.16545
109.91801,9.15981,884.17875,-0.13400,28.62073,39.14859
110.11800,9.17649,884.05591,-0.13400,28.68745,39.14315
110.31801,9.19305,884.44203,-0.13400,28.75370,39.16025
110.51801,9.20985,883.82689,-0.13400,28.82091,39.13301
110.71800,9.22665,884.22680,-0.13400,28.88811,39.15072
110.91801,9.24310,883.78703,-0.13400,28.95388,39.13125
111.11800,9.25978,883.49786,-0.13400,29.02060,39.11844
111.31801,9.27652,883.45595,-0.13400,29.08756,39.11659
111.51801,9.29314,884.01651,-0.13400,29.15405,39.14141
111.71800,9.30982,883.79458,-0.13400,29.22078,39.13158
111.91801,9.32650,882.86800,-0.13400,29.28750,39.09055
112.11800,9.34312,883.41590,-0.13400,29.35399,39.11481
112.31801,9.35975,884.26117,-0.13400,29.42047,39.15224
112.51801,9.37649,883.33506,-0.13400,29.48744,39.11124
112.71800,9.39323,884.11393,-0.13400,29.55440,39.14572
112.91801,9.40979,883.24919,-0.13400,29.62065,39.10743
113.11800,9.42653,883.11555,-0.13400,29.68761,39.10152
113.31801,9.44321,883.12645,-0.13400,29.75434,39.10200
113.51801,9.45983,883.50847,-0.13400,29.82083,39.11891
113.71800,9.47651,883.39755,-0.13400,29.88755,39.11400
113.91801,9.49326,883.71411,-0.13400,29.95451,39.12802
114.11800,9.50982,883.58335,-0.13400,30.02076,39.12223
114.31801,9.52638,883.09469,-0.13400,30.08701,39.10059
114.51801,9.54318,883.05650,-0.13400,30.15421,39.09890
114.71800,9.55992,883.27713,-0.13400,30.22117,39.10867
114.91801,9.57648,883.27331,-0.13400,30.28742,39.10850
115.11800,9.59310,882.73240,-0.13400,30.35391,39.08455
115.31801,9.60990,883.16398,-0.13400,30.42111,39.10366
115.51801,9.62647,883.56351,-0.13400,30.48736,39.12135
115.71800,9.64315,881.34892,-0.13400,30.55408,39.02330
115.91801,9.65989,881.27404,-0.13400,30.62105,39.01998
116.11800,9.67651,881.49421,-0.13400,30.68753,39.02973
116.31801,9.69313,881.85742,-0.13400,30.75402,39.04581
116.51801,9.70981,881.59004,-0.13400,30.82075,39.03397
116.71800,9.72655,882.05105,-0.13400,30.88771,39.05438
116.91801,9.74312,882.17100,-0.13401,30.95395,39.05969
117.11800,9.75986,882.28984,-0.13400,31.02092,39.06496
117.31801,9.77654,882.32523,-0.13400,31.08764,39.06652
117.51801,9.79310,882.26460,-0.13400,31.15389,39.06384
117.71800,9.80978,882.15424,-0.13400,31.22061,39.05895
117.91801,9.82646,882.23005,-0.13400,31.28734,39.06231
118.11800,9.84314,881.78441,-0.13400,31.35406,39.04258
118.31801,9.85982,881.47717,-0.13400,31.42079,39.02897
118.51801,9.87645,882.28257,-0.13400,31.48728,39.06463
118.71800,9.89313,881.86106,-0.13400,31.55400,39.04597
118.91801,9.90981,882.52146,-0.13400,31.62073,39.07521
119.11800,9.92655,881.94944,-0.13400,31.68769,39.04988
119.31801,9.94329,882.17240,-0.13400,31.75465,39.05976
119.51801,9.95985,881.76997,-0.13400,31.82090,39.04194
119.71800,9.97641,881.93733,-0.13400,31.88715,39.04935
119.91801,9.99322,881.74017,-0.13400,31.95435,39.04062
120.11800,10.00978,882.19875,-0.13400,32.02060,39.06092
120.31801,10.02646,881.68839,-0.13400,32.08732,39.03833
120.51801,10.04314,881.63819,-0.13400,32.15405,39.03610
120.71800,10.05982,881.13341,-0.13400,32.22077,39.01375
120.91801,10.07644,881.51069,-0.13400,32.28726,39.03046
121.11800,10.09318,882.08551,-0.13400,32.35422,39.05591
121.31801,10.10987,881.28308,-0.13400,32.42095,39.02038
121.51801,10.12643,882.01798,-0.13400,32.48720,39.05292
121.71800,10.14311,881.32890,-0.13400,32.55392,39.02241
121.91801,10.15997,881.67991,-0.13400,32.62136,39.03795
122.11800,10.17647,881.53193,-0.13400,32.68737,39.03140
122.31801,10.19309,881.36615,-0.13400,32.75385,39.02406
122.51801,10.20989,881.66650,-0.13400,32.82106,39.03736
122.71800,10.22645,881.14040,-0.13400,32.88730,39.01406
122.91801,10.24314,881.29863,-0.13401,32.95403,39.02107
123.11800,10.25988,880.72345,-0.13400,33.02100,38.99560
123.31801,10.27650,881.01514,-0.13400,33.08748,39.00851
123.51801,10.29318,880.96987,-0.13400,33.15420,39.00651
123.71800,10.30980,880.91018,-0.13401,33.22069,39.00387
123.91801,10.32654,880.84219,-0.13400,33.28766,39.00086
124.11800,10.34310,880.80848,-0.13400,33.35390,38.99937
124.31801,10.35978,880.88401,-0.13400,33.42063,39.00271
124.51801,10.37659,880.76862,-0.13400,33.48783,38.99760
124.71800,10.39321,880.58533,-0.13400,33.55432,38.98949
124.91801,10.40983,881.13016,-0.13400,33.62080,39.01361
125.11800,10.42645,880.16950,-0.13400,33.68729,38.97107
125.31801,10.44313,880.23553,-0.13400,33.75401,38.97400
125.51801,10.45975,880.05019,-0.13400,33.82050,38.96579
125.71800,10.47649,879.75496,-0.13400,33.88747,38.95272
125.91801,10.49318,880.71898,-0.13400,33.95419,38.99540
126.11800,10.50980,879.98193,-0.13401,34.02067,38.96277
126.31801,10.52648,879.19934,-0.13400,34.08740,38.92812
126.51801,10.54322,879.78719,-0.13400,34.15436,38.95415
126.71800,10.55984,879.65196,-0.13400,34.22085,38.94816
126.91801,10.57658,879.44875,-0.13401,34.28781,38.93916
127.11800,10.59320,879.58761,-0.13400,34.35430,38.94531
127.31801,10.60982,879.80339,-0.13401,34.42078,38.95486
127.51801,10.62651,879.79203,-0.13400,34.48751,38.95436
127.71800,10.64313,878.78900,-0.13400,34.55400,38.90995
127.91801,10.65987,879.33773,-0.13400,34.62096,38.93425
128.11801,10.67649,878.96343,-0.13400,34.68745,38.91768
128.31801,10.69311,879.52651,-0.13400,34.75394,38.94260
128.51801,10.70985,879.17345,-0.13400,34.82090,38.92697
128.71800,10.72647,879.19161,-0.13400,34.88739,38.92778
128.91800,10.74316,879.02006,-0.13400,34.95411,38.92018
129.11801,10.75990,878.57712,-0.13400,35.02108,38.90057
129.31801,10.77646,878.66606,-0.13400,35.08732,38.90451
129.51801,10.79314,878.63449,-0.13400,35.15405,38.90311
129.71800,10.80976,878.05642,-0.13401,35.22053,38.87751
129.91800,10.82656,878.77484,-0.13400,35.28773,38.90932
130.11801,10.84312,878.18382,-0.13400,35.35398,38.88316
130.31801,10.85986,877.40216,-0.13401,35.42095,38.84855
130.51801,10.87654,877.81623,-0.13400,35.48767,38.86688
130.71800,10.89311,878.04561,-0.13400,35.55392,38.87704
130.91800,10.90979,877.99933,-0.13400,35.62064,38.87498
131.11802,10.92659,877.46652,-0.13400,35.68785,38.85139
131.31802,10.94309,877.52994,-0.13400,35.75386,38.85420
131.51800,10.95977,877.78205,-0.13400,35.82058,38.86536
131.71800,10.97651,877.49772,-0.13400,35.88754,38.85278
131.91800,10.99319,877.37301,-0.13400,35.95427,38.84726
132.11802,11.00982,877.17501,-0.13400,36.02075,38.83849
132.31802,11.02650,876.80575,-0.13401,36.08748,38.82214
132.51800,11.04324,877.15816,-0.13400,36.15444,38.83774
132.71800,11.05974,877.07750,-0.13400,36.22045,38.83417
132.91800,11.07642,877.12277,-0.13400,36.28717,38.83617
133.11802,11.09322,876.15615,-0.13400,36.35438,38.79338
133.31802,11.10984,876.42400,-0.13401,36.42086,38.80524
133.51800,11.12647,876.91201,-0.13400,36.48735,38.82684
133.71800,11.14315,876.38255,-0.13400,36.55408,38.80340
133.91800,11.15983,876.15354,-0.13400,36.62080,38.79326
134.11802,11.17651,876.23093,-0.13400,36.68753,38.79669
134.31802,11.19325,876.04038,-0.13400,36.75449,38.78825
134.51800,11.20987,875.72159,-0.13400,36.82098,38.77414
134.71800,11.22643,875.79926,-0.13400,36.88722,38.77757
134.91800,11.24317,875.95154,-0.13400,36.95419,38.78432
135.11802,11.25992,875.65528,-0.13400,37.02115,38.77120
135.31802,11.27654,875.18701,-0.13400,37.08764,38.75047
135.51800,11.29316,875.28080,-0.13400,37.15412,38.75462
135.71800,11.30984,875.60024,-0.13400,37.22085,38.76876
135.91800,11.32646,875.39656,-0.13400,37.28734,38.75974
136.11802,11.34308,874.40936,-0.13400,37.35382,38.71603
136.31802,11.35988,875.00671,-0.13400,37.42103,38.74248
136.51800,11.37657,874.22375,-0.13400,37.48775,38.70781
136.71800,11.39313,874.55679,-0.13400,37.55400,38.72256
136.91800,11.40981,874.57318,-0.13400,37.62072,38.72329
137.11802,11.42655,874.81942,-0.13400,37.68769,38.73419
137.31802,11.44317,874.09392,-0.13400,37.75417,38.70207
137.51800,11.45985,874.11329,-0.13400,37.82089,38.70292
137.71800,11.47659,874.29136,-0.13400,37.88786,38.71081
137.91800,11.49316,873.74831,-0.13400,37.95411,38.68676
138.11802,11.50972,873.57601,-0.13400,38.02035,38.67913
138.31802,11.52658,873.15729,-0.13400,38.08780,38.66059
138.51800,11.54326,873.80055,-0.13400,38.15452,38.68908
138.71800,11.55976,873.58411,-0.13400,38.22053,38.67949
138.91800,11.57644,873.40213,-0.13400,38.28725,38.67144
139.11802,11.59318,873.43799,-0.13400,38.35422,38.67302
139.31802,11.60980,872.60371,-0.13401,38.42070,38.63609
139.51800,11.62654,872.30308,-0.13400,38.48767,38.62278
139.71800,11.64323,872.14950,-0.13401,38.55439,38.61597
139.91800,11.65985,872.52306,-0.13400,38.62088,38.63251
140.11802,11.67641,872.36995,-0.13400,38.68712,38.62574
140.31802,11.69315,872.00236,-0.13400,38.75409,38.60946
140.51800,11.70983,871.45381,-0.13400,38.82082,38.58517
140.71800,11.72651,871.36067,-0.13400,38.88754,38.58105
140.91800,11.74313,871.55458,-0.13400,38.95403,38.58963
141.11802,11.75981,871.50326,-0.13401,39.02075,38.58736
141.31802,11.77644,871.07010,-0.13400,39.08724,38.56818
141.51800,11.79318,871.35099,-0.13400,39.15420,38.58062
141.71800,11.80992,871.31783,-0.13400,39.22117,38.57915
141.91800,11.82648,870.57771,-0.13400,39.28741,38.54638
142.11802,11.84310,870.48532,-0.13400,39.35390,38.54229
142.31802,11.85984,870.47638,-0.13400,39.42086,38.54189
142.51800,11.87646,870.86149,-0.13400,39.48735,38.55894
142.71800,11.89315,870.16858,-0.13400,39.55407,38.52827
142.91800,11.90989,869.97626,-0.13400,39.62104,38.51975
143.11802,11.92651,870.15657,-0.13400,39.68752,38.52773
143.31802,11.94313,869.49747,-0.13400,39.75401,38.49855
143.51800,11.95975,869.61137,-0.13400,39.82050,38.50359
143.71800,11.97655,869.21034,-0.13400,39.88770,38.48584
143.91800,11.99317,869.42548,-0.13400,39.95419,38.49537
144.11802,12.00980,869.58949,-0.13400,40.02067,38.50262
144.31802,12.02648,868.40196,-0.13400,40.08739,38.45005
144.51800,12.04316,869.02007,-0.13400,40.15412,38.47741
144.71800,12.05984,868.75558,-0.13400,40.22085,38.46570
144.91800,12.07652,868.34067,-0.13400,40.28757,38.44733
145.11802,12.09320,868.08186,-0.13400,40.35430,38.43587
145.31802,12.10982,868.27269,-0.13400,40.42078,38.44432
145.51800,12.12644,867.66565,-0.13401,40.48727,38.41744
145.71800,12.14324,868.13569,-0.13400,40.55447,38.43826
145.91802,12.15987,867.43888,-0.13400,40.62096,38.40740
146.11802,12.17649,867.76018,-0.13400,40.68744,38.42163
146.31802,12.19317,866.88530,-0.13400,40.75417,38.38289
146.51800,12.20979,867.46775,-0.13400,40.82066,38.40868
146.71800,12.22641,866.47691,-0.13400,40.88714,38.36481
146.91802,12.24315,866.71589,-0.13400,40.95410,38.37539
147.11802,12.25989,866.83463,-0.13400,41.02107,38.38065
147.31802,12.27652,866.19705,-0.13400,41.08755,38.35242
147.51800,12.29314,866.27277,-0.13400,41.15404,38.35577
147.71800,12.30982,865.61684,-0.13400,41.22077,38.32673
147.91802,12.32650,865.52883,-0.13400,41.28749,38.32283
148.11802,12.34318,866.05903,-0.13400,41.35422,38.34631
148.31802,12.35992,865.38289,-0.13400,41.42118,38.31637
148.51800,12.37642,865.03895,-0.13400,41.48719,38.30114
148.71800,12.39317,864.81776,-0.13400,41.55415,38.29135
148.91802,12.40985,864.83276,-0.13400,41.62087,38.29201
149.11802,12.42647,864.33254,-0.13400,41.68736,38.26986
149.31802,12.44315,864.00090,-0.13400,41.75409,38.25518
149.51800,12.45983,864.13370,-0.13400,41.82081,38.26106
149.71800,12.47651,863.83689,-0.13400,41.88754,38.24792
149.91802,12.49313,863.90832,-0.13401,41.95402,38.25108
150.11802,12.50976,863.42152,-0.13400,42.02051,38.22953
150.31802,12.52656,863.09025,-0.13400,42.08772,38.21486
150.51800,12.54318,862.79567,-0.13400,42.15420,38.20182
150.71800,12.55974,863.17798,-0.13400,42.22045,38.21874
150.91802,12.57660,862.07753,-0.13400,42.28789,38.17002
151.11802,12.59316,861.62463,-0.13400,42.35414,38.14997
151.31802,12.60984,861.99567,-0.13400,42.42086,38.16639
151.51800,12.62658,862.04605,-0.13400,42.48782,38.16862
151.71800,12.64315,860.61805,-0.13400,42.55407,38.10540
151.91802,12.65971,861.72465,-0.13400,42.62032,38.15440
152.11802,12.67645,861.19995,-0.13400,42.68728,38.13116
152.31802,12.69325,860.79342,-0.13400,42.75449,38.11316
152.51800,12.70981,860.36753,-0.13400,42.82073,38.09431
152.71800,12.72649,859.50596,-0.13400,42.88746,38.05616
152.91802,12.74317,859.80678,-0.13400,42.95419,38.06948
153.11802,12.75979,858.83476,-0.13400,43.02067,38.02644
153.31802,12.77654,858.77031,-0.13400,43.08763,38.02359
153.51800,12.79322,858.83196,-0.13400,43.15436,38.02632
153.71800,12.80984,857.79559,-0.13400,43.22084,37.98043
153.91802,12.82640,857.96528,-0.13400,43.28709,37.98794
154.11802,12.84314,857.67806,-0.13400,43.35406,37.97522
154.31802,12.85982,857.39661,-0.13400,43.42078,37.96276
154.51800,12.87644,856.31283,-0.13401,43.48727,37.91478
154.71800,12.89312,856.72671,-0.13400,43.55399,37.93310
154.91802,12.90981,856.13197,-0.13400,43.62072,37.90677
155.11802,12.92643,856.04815,-0.13400,43.68720,37.90306
155.31802,12.94317,855.14262,-0.13400,43.75417,37.86296
155.51800,12.95979,854.66625,-0.13400,43.82066,37.84187
155.71800,12.97653,854.14480,-0.13400,43.88762,37.81878
155.91802,12.99321,853.77079,-0.13400,43.95434,37.80222
156.11802,13.00983,852.97488,-0.13400,44.02083,37.76698
156.31802,13.02652,852.71187,-0.13400,44.08755,37.75534
156.51800,13.04314,851.58907,-0.13400,44.15404,37.70562
156.71800,13.05988,851.77375,-0.13400,44.22100,37.71380
156.91802,13.07656,850.92429,-0.13400,44.28773,37.67619
157.11802,13.09312,849.37243,-0.13400,44.35397,37.60748
157.31802,13.10974,849.98636,-0.13400,44.42046,37.63466
157.51800,13.12648,848.74118,-0.13400,44.48743,37.57953
157.71800,13.14317,848.16543,-0.13400,44.55415,37.55404
157.91802,13.15985,847.84273,-0.13400,44.62087,37.53975
158.11802,13.17659,846.47853,-0.13400,44.68784,37.47935
158.31802,13.19315,844.75605,-0.13400,44.75408,37.40308
158.51800,13.20983,844.26217,-0.13400,44.82081,37.38121
158.71800,13.22651,842.81992,-0.13400,44.88754,37.31736
158.91802,13.24325,841.54932,-0.13400,44.95450,37.26110
159.11802,13.25981,839.06986,-0.13400,45.02075,37.15131
159.31802,13.27644,837.94566,-0.13400,45.08724,37.10154
159.51800,13.29318,835.83621,-0.13400,45.15420,37.00814
159.71800,13.30980,834.26209,-0.13400,45.22069,36.93844
159.91802,13.32648,832.04042,-0.13400,45.28741,36.84007
160.11802,13.34322,829.59421,-0.13400,45.35438,36.73176
160.31802,13.35984,827.63573,-0.13401,45.42086,36.64505
160.51800,13.37646,825.05848,-0.13400,45.48734,36.53094
160.71800,13.39321,823.32045,-0.13400,45.55431,36.45398
160.91802,13.40983,820.88960,-0.13400,45.62079,36.34635
161.11802,13.42651,818.35808,-0.13400,45.68752,36.23426
161.31802,13.44313,815.44006,-0.13400,45.75401,36.10506
161.51800,13.45981,812.53164,-0.13400,45.82073,35.97629
161.71800,13.47643,809.55578,-0.13400,45.88722,35.84452
161.91802,13.49311,805.86150,-0.13400,45.95394,35.68095
162.11802,13.50985,802.34725,-0.13400,46.02090,35.52536
162.31802,13.52648,798.75896,-0.13400,46.08739,35.36648
162.51800,13.54316,795.01737,-0.13400,46.15412,35.20081
162.71800,13.55978,789.79991,-0.13400,46.22060,34.96980
162.91802,13.57646,783.02147,-0.13400,46.28733,34.66967
163.11802,13.59314,773.80328,-0.13400,46.35405,34.26152
163.31802,13.60982,759.67973,-0.13400,46.42078,33.63617
163.51800,13.62656,743.37139,-0.13400,46.48774,32.91409
163.71800,13.64318,724.72179,-0.13401,46.55423,32.08835
163.91802,13.65975,688.72841,-0.13400,46.62047,30.49468
164.01202,13.66776,3.93963,-0.13401,46.65252,0.17443