File: Manufatura Aditiva/Classificação Direção/Ensaios/Ensaios SLS/Tracao_OLABI_08_06_2018_SLS_YZ4.is_metal_RawData/Specimen_RawData_2.csv
Time,Extension,Load,Strain 1,Tensile strain,Tensile stress
(sec),(mm),(N),(mm/mm),(%),(MPa)
0.00000,0.00006,29.14447,0.00121,0.12123,1.33232
0.20000,0.01375,36.37711,0.00138,0.13829,1.66295
0.40000,0.03265,46.58551,0.00168,0.16811,2.12962
0.60000,0.04986,55.72909,0.00196,0.19613,2.54762
0.80000,0.06673,64.13186,0.00222,0.22236,2.93174
1.00000,0.08335,71.88150,0.00248,0.24833,3.28601
1.20000,0.10003,81.14877,0.00275,0.27499,3.70966
1.40000,0.11683,89.19091,0.00302,0.30178,4.07730
1.60000,0.13333,97.29050,0.00328,0.32826,4.44757
1.80000,0.14995,105.16553,0.00354,0.35432,4.80757
2.00000,0.16657,113.03535,0.00381,0.38109,5.16733
2.20000,0.18331,120.20356,0.00408,0.40756,5.49502
2.40000,0.19994,126.26796,0.00428,0.42754,5.77225
2.60000,0.21668,134.00095,0.00454,0.45375,6.12576
2.80000,0.23336,141.84105,0.00480,0.48024,6.48416
3.00000,0.24998,149.56448,0.00507,0.50732,6.83723
3.20000,0.26672,157.33369,0.00534,0.53406,7.19240
3.40000,0.28346,165.17548,0.00560,0.56033,7.55088
3.60000,0.30002,172.13149,0.00586,0.58636,7.86887
3.80000,0.31665,179.16840,0.00613,0.61256,8.19056
4.00000,0.33327,186.29812,0.00640,0.63952,8.51649
4.20000,0.34995,194.16909,0.00666,0.66553,8.87630
4.40000,0.36663,201.60007,0.00692,0.69174,9.21600
4.60000,0.38331,208.72641,0.00719,0.71867,9.54178
4.80000,0.39999,215.87412,0.00745,0.74479,9.86853
5.00000,0.41667,222.71962,0.00771,0.77076,10.18147
5.20000,0.43335,227.35423,0.00790,0.79026,10.39334
5.40000,0.45010,235.14763,0.00817,0.81714,10.74961
5.60000,0.46666,241.38296,0.00843,0.84323,11.03465
5.80000,0.48334,248.41018,0.00869,0.86905,11.35589
6.00000,0.50002,255.63685,0.00896,0.89559,11.68626
6.20000,0.51664,261.87499,0.00922,0.92198,11.97143
6.40000,0.53332,269.57218,0.00949,0.94876,12.32330
6.60000,0.55000,275.70478,0.00975,0.97498,12.60365
6.80000,0.56674,282.82395,0.01001,1.00119,12.92909
7.00000,0.58331,288.38099,0.01027,1.02749,13.18313
7.20000,0.59993,295.74228,0.01053,1.05337,13.51965
7.40000,0.61667,299.93409,0.01073,1.07288,13.71127
7.60000,0.63329,306.71514,0.01098,1.09837,14.02126
7.80000,0.64997,312.65584,0.01125,1.12475,14.29284
8.00000,0.66677,318.61214,0.01152,1.15160,14.56513
8.20000,0.68333,324.92101,0.01178,1.17764,14.85353
8.40000,0.70002,330.69393,0.01203,1.20336,15.11744
8.60000,0.71664,337.48578,0.01230,1.22990,15.42792
8.80000,0.73344,341.49983,0.01252,1.25191,15.61142
9.00000,0.75000,346.98935,0.01275,1.27547,15.86237
9.20000,0.76662,353.33196,0.01302,1.30226,16.15232
9.40000,0.78336,358.78955,0.01329,1.32889,16.40181
9.60000,0.79992,365.17163,0.01355,1.35460,16.69356
9.80000,0.81660,369.95476,0.01380,1.38027,16.91222
10.00000,0.83341,375.90074,0.01405,1.40492,17.18403
10.20000,0.84991,378.45697,0.01424,1.42407,17.30089
10.40000,0.86665,384.52020,0.01450,1.45032,17.57807
10.60000,0.88333,389.51538,0.01476,1.47631,17.80642
10.80000,0.90007,394.94187,0.01502,1.50214,18.05449
11.00000,0.91669,399.93143,0.01528,1.52811,18.28258
11.20000,0.93331,403.83874,0.01549,1.54907,18.46120
11.40000,0.95000,409.34193,0.01574,1.57444,18.71277
11.60000,0.96656,413.91752,0.01601,1.60059,18.92194
11.80000,0.98330,419.56189,0.01627,1.62727,19.17997
12.00000,1.00010,424.65460,0.01653,1.65342,19.41278
12.20000,1.01666,427.71781,0.01673,1.67294,19.55281
12.40000,1.03328,432.73219,0.01699,1.69929,19.78204
12.60000,1.05002,437.06610,0.01725,1.72539,19.98016
12.80000,1.06664,442.26935,0.01751,1.75146,20.21803
13.00000,1.08333,447.07991,0.01778,1.77771,20.43794
13.20000,1.10001,449.84347,0.01798,1.79759,20.56427
13.40000,1.11675,454.36160,0.01824,1.82358,20.77082
13.60000,1.13325,458.87795,0.01851,1.85052,20.97728
13.80000,1.14993,463.57578,0.01877,1.87685,21.19204
14.00000,1.16673,466.82074,0.01897,1.89693,21.34038
14.20000,1.18329,470.91530,0.01923,1.92312,21.52756
14.40000,1.19998,475.15389,0.01950,1.95029,21.72132
14.60000,1.21672,479.13291,0.01976,1.97625,21.90322
14.80000,1.23334,482.48130,0.01998,1.99820,22.05629
15.00000,1.24996,486.68752,0.02025,2.02454,22.24857
15.20000,1.26670,490.80434,0.02052,2.05161,22.43677
15.40000,1.28338,493.23048,0.02073,2.07280,22.54768
15.60000,1.29994,497.42223,0.02099,2.09949,22.73930
15.80000,1.31656,501.44419,0.02126,2.12611,22.92316
16.00000,1.33343,503.34483,0.02147,2.14734,23.01005
16.20000,1.34993,507.50677,0.02175,2.17471,23.20031
16.40000,1.36667,511.40459,0.02202,2.20233,23.37850
16.60000,1.38341,514.22394,0.02224,2.22391,23.50738
16.80000,1.39997,517.74341,0.02250,2.24993,23.66827
17.00000,1.41659,521.54087,0.02277,2.27672,23.84187
17.20000,1.43333,523.37977,0.02299,2.29918,23.92593
17.40000,1.45001,526.84839,0.02326,2.32598,24.08450
17.60000,1.46664,529.41367,0.02349,2.34945,24.20177
17.80000,1.48320,532.48848,0.02373,2.37306,24.34233
18.00000,1.50000,535.50228,0.02399,2.39937,24.48010
18.20000,1.51662,537.12707,0.02421,2.42145,24.55438
18.40000,1.53336,540.38269,0.02449,2.44901,24.70321
18.60000,1.55004,543.82295,0.02476,2.47553,24.86048
18.80000,1.56666,546.28393,0.02499,2.49850,24.97298
19.00000,1.58335,549.56409,0.02526,2.52630,25.12293
19.20000,1.60003,552.89166,0.02553,2.55281,25.27505
19.40000,1.61671,554.75910,0.02577,2.57688,25.36042
19.60000,1.63339,557.77393,0.02605,2.60475,25.49824
19.80000,1.65007,560.19947,0.02628,2.62800,25.60912
20.00000,1.66663,563.34585,0.02656,2.65584,25.75295
20.20000,1.68325,566.19183,0.02683,2.68341,25.88305
20.40000,1.69993,568.48922,0.02707,2.70721,25.98808
20.60000,1.71674,570.94074,0.02736,2.73570,26.10015
20.80000,1.73330,574.30509,0.02763,2.76259,26.25395
21.00000,1.74992,576.73021,0.02787,2.78747,26.36481
21.20000,1.76672,580.06183,0.02816,2.81569,26.51711
21.40000,1.78334,582.27601,0.02843,2.84348,26.61833
21.60000,1.79996,583.85115,0.02868,2.86847,26.69034
21.80000,1.81676,587.57709,0.02897,2.89718,26.86067
22.00000,1.83339,589.78871,0.02925,2.92531,26.96177
22.20000,1.84995,591.86765,0.02950,2.94995,27.05681
22.40000,1.86669,594.64923,0.02979,2.97871,27.18397
22.60000,1.88337,597.27151,0.03008,3.00816,27.30384
22.80000,1.89993,599.82040,0.03036,3.03609,27.42036
23.00000,1.91661,601.50060,0.03061,3.08023,27.49717
23.19600,1.93305,604.36064,0.03090,3.14600,27.62791
23.39600,1.94962,607.57785,0.03119,3.21225,27.77499
23.59600,1.96636,609.27183,0.03148,3.27921,27.85243
23.79600,1.98310,611.57243,0.03174,3.34618,27.95760
23.99600,1.99972,614.03704,0.03203,3.41266,28.07026
24.19600,2.01634,616.07333,0.03232,3.47915,28.16335
24.39600,2.03302,618.20522,0.03262,3.54587,28.26081
24.59600,2.04970,620.59467,0.03290,3.61260,28.37004
24.79600,2.06632,622.48143,0.03318,3.67908,28.45630
24.99600,2.08295,624.58618,0.03264,3.74557,28.55251
25.19600,2.09963,626.63546,-0.02505,3.81230,28.64619
25.39600,2.11625,628.85401,-0.00215,3.87878,28.74761
25.59600,2.13293,631.05393,0.00476,3.94551,28.84818
25.79600,2.14961,633.16561,0.00768,4.01223,28.94471
25.99600,2.16635,635.49788,0.00883,4.07920,29.05133
26.19600,2.18309,637.73235,0.00956,4.14616,29.15348
26.39600,2.19966,639.87686,0.00956,4.21241,29.25151
26.59600,2.21634,641.40875,0.01030,4.27913,29.32154
26.79600,2.23308,643.99047,0.01408,4.34610,29.43956
26.99600,2.24964,645.59048,-0.13293,4.41234,29.51271
27.19600,2.26638,648.30519,-0.13370,4.47931,29.63681
27.39600,2.28300,650.81385,-0.13369,4.54579,29.75149
27.59600,2.29968,651.61572,-0.13369,4.61252,29.78815
27.79600,2.31636,653.54528,-0.13369,4.67924,29.87636
27.99600,2.33299,655.69840,-0.13369,4.74573,29.97478
28.19600,2.34967,658.58085,-0.13370,4.81245,30.10655
28.39600,2.36629,659.83832,-0.13369,4.87894,30.16404
28.59600,2.38297,662.21831,-0.13369,4.94567,30.27284
28.79600,2.39965,662.87508,-0.13369,5.01239,30.30286
28.99600,2.41627,665.54048,-0.13370,5.07888,30.42471
29.19600,2.43307,667.48322,-0.13370,5.14608,30.51352
29.39600,2.44964,669.43578,-0.13370,5.21233,30.60278
29.59600,2.46632,671.96512,-0.13370,5.27905,30.71840
29.79600,2.48312,673.47544,-0.13370,5.34625,30.78745
29.99600,2.49962,674.89655,-0.13370,5.41226,30.85241
30.19600,2.51630,676.69069,-0.13370,5.47899,30.93443
30.39600,2.53304,679.40019,-0.13370,5.54595,31.05829
30.59600,2.54966,680.63736,-0.13370,5.61244,31.11485
30.79600,2.56628,682.79854,-0.13370,5.67892,31.21365
30.99600,2.58297,682.57386,-0.13370,5.74565,31.20338
31.19600,2.59971,684.87325,-0.13370,5.81261,31.30849
31.39600,2.61627,686.87340,-0.13370,5.87886,31.39993
31.59600,2.63301,688.81307,-0.13371,5.94582,31.48860
31.79600,2.64969,691.05783,-0.13371,6.01255,31.59122
31.99600,2.66625,692.74246,-0.13370,6.07880,31.66823
32.19600,2.68299,692.47568,-0.13371,6.14576,31.65603
32.39600,2.69968,694.14196,-0.13371,6.21249,31.73220
32.59600,2.71642,696.52023,-0.13371,6.27945,31.84093
32.79600,2.73304,697.58277,-0.13371,6.34594,31.88950
32.99600,2.74966,699.46581,-0.13371,6.41242,31.97558
33.19600,2.76634,701.67482,-0.13371,6.47915,32.07656
33.39600,2.78302,703.83069,-0.13371,6.54587,32.17512
33.59600,2.79964,704.68565,-0.13371,6.61236,32.21420
33.79600,2.81638,705.96435,-0.13371,6.67932,32.27266
33.99600,2.83289,707.57992,-0.13371,6.74533,32.34651
34.19600,2.84957,709.69420,-0.13371,6.81205,32.44316
34.39600,2.86637,711.36146,-0.13371,6.87926,32.51938
34.59600,2.88305,713.14825,-0.13371,6.94598,32.60106
34.79600,2.89973,715.26105,-0.13371,7.01271,32.69765
34.99600,2.91635,716.43130,-0.13371,7.07919,32.75114
35.19600,2.93303,715.81975,-0.13371,7.14592,32.72319
35.39600,2.94959,717.96142,-0.13371,7.21216,32.82109
35.59600,2.96640,719.96767,-0.13371,7.27937,32.91281
35.79600,2.98314,721.90659,-0.13371,7.34633,33.00145
35.99600,2.99958,723.89622,-0.13371,7.41210,33.09240
36.19600,3.01626,725.31719,-0.13371,7.47883,33.15736
36.39600,3.03306,726.90444,-0.13371,7.54603,33.22992
36.59600,3.04962,729.06413,-0.13371,7.61228,33.32865
36.79600,3.06636,727.98561,-0.13371,7.67924,33.27934
36.99600,3.08310,730.32132,-0.13371,7.74621,33.38612
37.19600,3.09967,731.84553,-0.13371,7.81245,33.45580
37.39600,3.11629,732.86011,-0.13371,7.87894,33.50218
37.59600,3.13303,735.00001,-0.13372,7.94590,33.60000
37.79600,3.14977,736.59467,-0.13371,8.01287,33.67290
37.99600,3.16627,738.22052,-0.13371,8.07887,33.74722
38.19600,3.18295,739.88358,-0.13372,8.14560,33.82325
38.39600,3.19963,739.16051,-0.13372,8.21232,33.79020
38.59600,3.21626,740.83498,-0.13372,8.27881,33.86674
38.79600,3.23294,741.78530,-0.13371,8.34553,33.91019
38.99600,3.24968,743.67980,-0.13371,8.41250,33.99679
39.19600,3.26636,745.74891,-0.13371,8.47922,34.09138
39.39600,3.28298,746.88243,-0.13371,8.54571,34.14320
39.59600,3.29960,748.48561,-0.13371,8.61220,34.21648
39.79600,3.31634,750.06527,-0.13372,8.67916,34.28870
39.99600,3.33303,749.46941,-0.13372,8.74589,34.26146
40.19600,3.34971,751.20456,-0.13371,8.81261,34.34078
40.39600,3.36639,752.61472,-0.13371,8.87934,34.40524
40.59600,3.38295,754.08397,-0.13372,8.94558,34.47241
40.79600,3.39963,755.55500,-0.13371,9.01231,34.53966
40.99600,3.41643,756.50401,-0.13372,9.07951,34.58304
41.19600,3.43299,758.62352,-0.13372,9.14576,34.67993
41.39600,3.44955,759.84928,-0.13372,9.21200,34.73597
41.59600,3.46630,760.84021,-0.13372,9.27897,34.78127
41.79600,3.48298,760.79760,-0.13372,9.34569,34.77932
41.99600,3.49966,762.01842,-0.13372,9.41242,34.83513
42.19600,3.51640,763.72684,-0.13372,9.47938,34.91323
42.39600,3.53308,765.18259,-0.13372,9.54611,34.97977
42.59600,3.54964,766.52877,-0.13371,9.61235,35.04132
42.79600,3.56626,767.61884,-0.13372,9.67884,35.09115
42.99600,3.58312,769.21508,-0.13372,9.74628,35.16412
43.19600,3.59963,770.70603,-0.13371,9.81229,35.23228
43.39600,3.61625,771.43633,-0.13372,9.87878,35.26566
43.59600,3.63305,771.06738,-0.13372,9.94598,35.24879
43.79600,3.64961,773.10437,-0.13372,10.01223,35.34192
43.99600,3.66629,774.46001,-0.13372,10.07895,35.40388
44.19600,3.68309,774.90360,-0.13372,10.14615,35.42416
44.39600,3.69977,776.11725,-0.13372,10.21288,35.47964
44.59600,3.71622,777.94697,-0.13372,10.27865,35.56329
44.79600,3.73296,779.56435,-0.13372,10.34561,35.63723
44.99600,3.74982,779.89525,-0.13372,10.41306,35.65236
45.19600,3.76626,781.40451,-0.13372,10.47882,35.72135
45.39600,3.78294,781.17498,-0.13372,10.54555,35.71086
45.59600,3.79968,781.76679,-0.13372,10.61251,35.73791
45.79600,3.81630,781.67515,-0.13372,10.67900,35.73372
45.99600,3.83292,782.67036,-0.13372,10.74549,35.77922
46.19600,3.84973,784.43810,-0.13372,10.81269,35.86003
46.39600,3.86641,786.13926,-0.13372,10.87941,35.93779
46.59600,3.88303,786.93870,-0.13372,10.94590,35.97434
46.79600,3.89959,788.12316,-0.13372,11.01215,36.02849
46.99600,3.91633,788.89932,-0.13372,11.07911,36.06397
47.19600,3.93295,790.34381,-0.13372,11.14560,36.13000
47.39600,3.94963,789.72103,-0.13372,11.21232,36.10153
47.59600,3.96637,791.06065,-0.13372,11.27928,36.16277
47.79600,3.98294,792.47206,-0.13372,11.34553,36.22729
47.99600,3.99962,794.06425,-0.13372,11.41226,36.30008
48.19600,4.01636,794.85197,-0.13372,11.47922,36.33609
48.39600,4.03298,795.80313,-0.13372,11.54571,36.37957
48.59600,4.04966,797.45809,-0.13372,11.61243,36.45523
48.79600,4.06628,798.14196,-0.13372,11.67892,36.48649
48.99600,4.08302,798.63863,-0.13372,11.74588,36.50919
49.19600,4.09959,800.15846,-0.13372,11.81213,36.57867
49.39600,4.11627,800.86142,-0.13372,11.87885,36.61081
49.59600,4.13307,799.97946,-0.13372,11.94606,36.57049
49.79600,4.14963,801.16764,-0.13372,12.01230,36.62481
49.99600,4.16625,802.05658,-0.13372,12.07879,36.66544
50.19600,4.18305,803.65222,-0.13372,12.14599,36.73839
50.39600,4.19961,805.19347,-0.13372,12.21224,36.80885
50.59600,4.21635,805.55361,-0.13372,12.27921,36.82531
50.79600,4.23304,806.42346,-0.13372,12.34593,36.86507
50.99600,4.24972,807.29006,-0.13372,12.41266,36.90469
51.19600,4.26628,808.48671,-0.13372,12.47890,36.95939
51.39600,4.28302,809.22144,-0.13372,12.54587,36.99298
51.59600,4.29976,810.63332,-0.13372,12.61283,37.05752
51.79600,4.31632,810.48775,-0.13372,12.67908,37.05087
51.99600,4.33294,809.80668,-0.13372,12.74556,37.01973
52.19600,4.34969,810.72142,-0.13372,12.81253,37.06155
52.39600,4.36631,811.81442,-0.13372,12.87901,37.11152
52.59600,4.38299,812.83515,-0.13372,12.94574,37.15818
52.79600,4.39967,813.95702,-0.13372,13.01246,37.20947
52.99600,4.41641,814.70171,-0.13372,13.07943,37.24351
53.19600,4.43297,815.32672,-0.13372,13.14567,37.27208
53.39600,4.44965,815.93646,-0.13372,13.21240,37.29995
53.59600,4.46639,817.34499,-0.13372,13.27936,37.36434
53.79600,4.48302,817.29731,-0.13372,13.34585,37.36216
53.99600,4.49970,818.79338,-0.13372,13.41257,37.43055
54.19600,4.51626,819.66827,-0.13372,13.47882,37.47055
54.39600,4.53294,820.27689,-0.13372,13.54555,37.49837
54.59600,4.54962,819.13313,-0.13372,13.61227,37.44609
54.79600,4.56630,820.11316,-0.13372,13.67899,37.49089
54.99600,4.58304,821.24276,-0.13372,13.74596,37.54253
55.19600,4.59973,821.38348,-0.13372,13.81269,37.54896
55.39600,4.61629,823.02699,-0.13372,13.87893,37.62409
55.59600,4.63303,824.13387,-0.13372,13.94590,37.67469
55.79600,4.64971,821.90493,-0.13372,14.01262,37.57280
55.99600,4.66633,822.00319,-0.13372,14.07911,37.57729
56.19600,4.68307,823.89964,-0.13372,14.14607,37.66398
56.39600,4.69969,824.64945,-0.13372,14.21256,37.69826
56.59600,4.71631,825.56745,-0.13372,14.27904,37.74023
56.79600,4.73294,825.92703,-0.13372,14.34553,37.75666
56.99600,4.74962,827.19959,-0.13372,14.41226,37.81484
57.19600,4.76636,828.41627,-0.13373,14.47922,37.87046
57.39600,4.78298,829.64823,-0.13372,14.54570,37.92678
57.59600,4.79966,830.34020,-0.13372,14.61243,37.95841
57.79600,4.81628,828.59136,-0.13372,14.67892,37.87846
57.99600,4.83302,829.70066,-0.13372,14.74588,37.92917
58.19600,4.84977,830.44590,-0.13372,14.81284,37.96324
58.39600,4.86633,831.20251,-0.13372,14.87909,37.99783
58.59600,4.88301,833.10846,-0.13372,14.94582,38.08496
58.79600,4.89969,833.08564,-0.13372,15.01254,38.08392
58.99600,4.91625,833.80677,-0.13372,15.07879,38.11688
59.19600,4.93299,834.62009,-0.13372,15.14575,38.15406
59.39600,4.94967,835.23998,-0.13372,15.21248,38.18240
59.59600,4.96635,836.82435,-0.13372,15.27920,38.25483
59.79600,4.98292,836.90556,-0.13372,15.34545,38.25854
59.99600,4.99960,837.75716,-0.13372,15.41217,38.29747
60.19600,5.01634,838.24927,-0.13372,15.47914,38.31997
60.39600,5.03302,838.95884,-0.13372,15.54586,38.35241
60.59600,5.04964,839.71266,-0.13372,15.61235,38.38686
60.79600,5.06632,839.93068,-0.13373,15.67907,38.39683
60.99600,5.08300,839.99680,-0.13372,15.74580,38.39985
61.19600,5.09962,840.36859,-0.13372,15.81229,38.41685
61.39600,5.11637,840.11871,-0.13372,15.87925,38.40543
61.59600,5.13299,840.71457,-0.13373,15.94573,38.43267
61.79600,5.14961,841.35588,-0.13372,16.01222,38.46198
61.99600,5.16635,842.29670,-0.13372,16.07919,38.50499
62.19600,5.18297,843.47147,-0.13372,16.14567,38.55870
62.39600,5.19965,843.78216,-0.13372,16.21240,38.57290
62.59600,5.21633,844.29011,-0.13372,16.27912,38.59612
62.79600,5.23302,844.98944,-0.13372,16.34585,38.62809
62.99600,5.24964,844.96457,-0.13372,16.41233,38.62695
63.19600,5.26632,845.70423,-0.13372,16.47906,38.66077
63.39600,5.28306,846.53161,-0.13372,16.54602,38.69859
63.59600,5.29974,846.89427,-0.13372,16.61275,38.71517
63.79600,5.31636,847.20245,-0.13372,16.67923,38.72926
63.99600,5.33298,847.89144,-0.13372,16.74572,38.76075
64.19601,5.34966,848.34769,-0.13372,16.81244,38.78161
64.39600,5.36629,847.96632,-0.13372,16.87893,38.76418
64.59600,5.38297,848.74826,-0.13372,16.94566,38.79992
64.79600,5.39971,849.52405,-0.13372,17.01262,38.83538
64.99600,5.41627,850.10445,-0.13372,17.07886,38.86192
65.19601,5.43295,850.27572,-0.13372,17.14559,38.86975
65.39600,5.44969,850.07269,-0.13373,17.21256,38.86047
65.59600,5.46631,850.15595,-0.13372,17.27904,38.86427
65.79601,5.48300,850.70860,-0.13372,17.34577,38.88953
65.99600,5.49974,850.88406,-0.13372,17.41273,38.89756
66.19601,5.51630,851.05328,-0.13373,17.47898,38.90529
66.39600,5.53298,852.21268,-0.13372,17.54570,38.95829
66.59600,5.54966,852.72631,-0.13373,17.61243,38.98177
66.79601,5.56646,852.88044,-0.13372,17.67963,38.98882
66.99600,5.58302,853.28361,-0.13373,17.74588,39.00725
67.19601,5.59964,853.99440,-0.13373,17.81236,39.03975
67.39600,5.61639,853.81540,-0.13373,17.87933,39.03156
67.59600,5.63301,854.90895,-0.13373,17.94581,39.08155
67.79601,5.64969,855.17447,-0.13373,18.01254,39.09369
67.99600,5.66631,855.73308,-0.13372,18.07902,39.11923
68.19601,5.68293,855.74389,-0.13372,18.14551,39.11972
68.39600,5.69961,856.12126,-0.13372,18.21224,39.13697
68.59600,5.71629,856.39935,-0.13373,18.27896,39.14968
68.79601,5.73303,857.22441,-0.13372,18.34593,39.18740
68.99600,5.74972,857.04317,-0.13373,18.41265,39.17912
69.19601,5.76628,857.44113,-0.13372,18.47890,39.19731
69.39600,5.78302,857.74874,-0.13372,18.54586,39.21137
69.59600,5.79958,858.53804,-0.13373,18.61211,39.24745
69.79601,5.81632,858.21636,-0.13372,18.67907,39.23275
69.99600,5.83306,855.79082,-0.13372,18.74603,39.12187
70.19601,5.84962,856.87535,-0.13372,18.81228,39.17144
70.39600,5.86631,857.25440,-0.13372,18.87901,39.18877
70.59600,5.88293,858.14642,-0.13373,18.94549,39.22955
70.79601,5.89967,858.49678,-0.13373,19.01246,39.24557
70.99600,5.91635,859.05008,-0.13373,19.07918,39.27086
71.19601,5.93297,857.47680,-0.13372,19.14567,39.19894
71.39600,5.94971,858.69497,-0.13372,19.21263,39.25463
71.59600,5.96633,859.27323,-0.13372,19.27912,39.28106
71.79601,5.98301,859.90271,-0.13372,19.34584,39.30984
71.99600,5.99976,860.46616,-0.13372,19.41281,39.33559
72.19601,6.01638,860.83449,-0.13372,19.47929,39.35243
72.39600,6.03294,861.28749,-0.13373,19.54554,39.37314
72.59600,6.04962,861.83539,-0.13372,19.61226,39.39819
72.79601,6.06636,862.45202,-0.13372,19.67923,39.42638
72.99600,6.08292,861.87702,-0.13372,19.74548,39.40009
73.19601,6.09966,863.01025,-0.13372,19.81244,39.45190
73.39600,6.11647,862.92978,-0.13373,19.87965,39.44822
73.59600,6.13291,863.69133,-0.13372,19.94541,39.48303
73.79601,6.14959,864.23820,-0.13372,20.01214,39.50803
73.99600,6.16639,864.39010,-0.13372,20.07934,39.51498
74.19601,6.18301,864.95131,-0.13373,20.14583,39.54063
74.39600,6.19963,865.06838,-0.13372,20.21231,39.54598
74.59600,6.21637,865.18927,-0.13373,20.27928,39.55151
74.79601,6.23300,865.34424,-0.13373,20.34577,39.55859
74.99600,6.24956,864.98875,-0.13373,20.41201,39.54234
75.19601,6.26636,864.91220,-0.13372,20.47921,39.53885
75.39600,6.28310,865.71379,-0.13372,20.54618,39.57549
75.59600,6.29954,865.68836,-0.13372,20.61195,39.57433
75.79601,6.31622,866.50206,-0.13372,20.67867,39.61152
75.99600,6.33302,866.64492,-0.13372,20.74588,39.61805
76.19601,6.34964,866.59649,-0.13372,20.81236,39.61584
76.39600,6.36638,866.47719,-0.13373,20.87933,39.61039
76.59600,6.38307,867.29182,-0.13373,20.94605,39.64762
76.79601,6.39957,867.66705,-0.13373,21.01206,39.66478
76.99600,6.41625,867.38728,-0.13372,21.07878,39.65199
77.19601,6.43305,868.03762,-0.13372,21.14599,39.68172
77.39600,6.44973,867.29210,-0.13373,21.21271,39.64764
77.59600,6.46635,868.23590,-0.13373,21.27920,39.69078
77.79601,6.48297,868.41648,-0.13372,21.34568,39.69904
77.99600,6.49966,868.96904,-0.13372,21.41241,39.72430
78.19601,6.51628,868.71628,-0.13372,21.47889,39.71275
78.39600,6.53290,869.20997,-0.13373,21.54538,39.73531
78.59600,6.54982,866.79943,-0.13373,21.61306,39.62512
78.79601,6.56638,867.64665,-0.13373,21.67931,39.66385
78.99600,6.58294,867.75385,-0.13373,21.74556,39.66875
79.19601,6.59974,868.90459,-0.13373,21.81276,39.72135
79.39600,6.61636,869.09356,-0.13372,21.87924,39.72999
79.59600,6.63293,869.08136,-0.13373,21.94549,39.72943
79.79601,6.64967,869.75787,-0.13373,22.01246,39.76036
79.99600,6.66641,869.63233,-0.13372,22.07942,39.75462
80.19601,6.68291,870.24281,-0.13372,22.14543,39.78253
80.39600,6.69959,870.29748,-0.13372,22.21215,39.78503
80.59600,6.71645,869.96974,-0.13373,22.27959,39.77005
80.79601,6.73295,870.49222,-0.13373,22.34560,39.79393
80.99600,6.74958,870.53571,-0.13372,22.41209,39.79592
81.19601,6.76638,871.11145,-0.13372,22.47929,39.82224
81.39600,6.78300,870.05273,-0.13372,22.54578,39.77384
81.59600,6.79962,871.29548,-0.13372,22.61226,39.83065
81.79601,6.81642,871.75379,-0.13373,22.67947,39.85160
81.99600,6.83298,872.43523,-0.13373,22.74571,39.88276
82.19601,6.84960,871.08789,-0.13373,22.81220,39.82116
82.39600,6.86629,871.88883,-0.13372,22.87893,39.85778
82.59600,6.88303,871.93772,-0.13372,22.94589,39.86001
82.79601,6.89965,872.16571,-0.13373,23.01237,39.87043
82.99600,6.91633,872.49372,-0.13373,23.07910,39.88543
83.19601,6.93301,872.26089,-0.13373,23.14582,39.87478
83.39600,6.94963,872.89205,-0.13372,23.21231,39.90364
83.59600,6.96625,873.11519,-0.13372,23.27880,39.91384
83.79601,6.98299,872.44306,-0.13372,23.34576,39.88311
83.99600,6.99968,872.76064,-0.13373,23.41249,39.89763
84.19601,7.01636,872.91766,-0.13373,23.47921,39.90481
84.39600,7.03298,872.61172,-0.13373,23.54570,39.89082
84.59600,7.04966,872.76008,-0.13373,23.61242,39.89760
84.79601,7.06634,872.69461,-0.13373,23.67915,39.89461
84.99600,7.08302,873.27128,-0.13372,23.74587,39.92097
85.19601,7.09976,873.38565,-0.13373,23.81284,39.92620
85.39600,7.11626,873.62221,-0.13373,23.87885,39.93702
85.59600,7.13301,873.89452,-0.13373,23.94581,39.94946
85.79601,7.14969,873.46798,-0.13373,24.01253,39.92997
85.99600,7.16637,873.80698,-0.13372,24.07926,39.94546
86.19601,7.18293,873.90384,-0.13373,24.14551,39.94989
86.39600,7.19961,874.27581,-0.13373,24.21223,39.96689
86.59600,7.21635,874.11134,-0.13373,24.27920,39.95937
86.79601,7.23291,874.38244,-0.13373,24.34544,39.97177
86.99600,7.24966,874.42715,-0.13373,24.41241,39.97381
87.19601,7.26646,874.29099,-0.13373,24.47961,39.96759
87.39600,7.28296,874.23567,-0.13373,24.54562,39.96506
87.59600,7.29964,874.44754,-0.13373,24.61234,39.97475
87.79601,7.31644,874.25616,-0.13372,24.67954,39.96600
87.99600,7.33306,874.73802,-0.13373,24.74603,39.98803
88.19601,7.34962,874.18258,-0.13373,24.81228,39.96263
88.39600,7.36630,874.11534,-0.13373,24.87900,39.95956
88.59600,7.38299,874.92792,-0.13373,24.94573,39.99670
88.79601,7.39961,873.90942,-0.13373,25.01221,39.95015
88.99600,7.41635,875.28368,-0.13373,25.07918,40.01297
89.19601,7.43303,874.57001,-0.13373,25.14590,39.98034
89.39600,7.44965,875.33724,-0.13373,25.21239,40.01542
89.59600,7.46639,874.52577,-0.13373,25.27936,39.97832
89.79601,7.48307,874.71493,-0.13373,25.34608,39.98697
89.99600,7.49970,874.79688,-0.13373,25.41257,39.99072
90.19601,7.51644,874.74231,-0.13373,25.47953,39.98822
90.39600,7.53300,874.73951,-0.13373,25.54578,39.98809
90.59600,7.54968,874.77667,-0.13373,25.61250,39.98979
90.79601,7.56636,875.40373,-0.13373,25.67923,40.01846
90.99600,7.58292,875.17090,-0.13373,25.74547,40.00781
91.19601,7.59966,874.44084,-0.13373,25.81244,39.97444
91.39600,7.61634,874.85518,-0.13373,25.87916,39.99338
91.59600,7.63297,874.87698,-0.13373,25.94565,39.99438
91.79601,7.64965,874.75143,-0.13373,26.01237,39.98864
91.99600,7.66633,875.12210,-0.13372,26.07910,40.00558
92.19601,7.68301,875.48047,-0.13373,26.14582,40.02197
92.39600,7.69963,875.72187,-0.13373,26.21231,40.03300
92.59600,7.71637,872.41819,-0.13373,26.27927,39.88197
92.79601,7.73299,873.58709,-0.13373,26.34576,39.93541
92.99600,7.74961,873.99185,-0.13373,26.41225,39.95391
93.19601,7.76636,874.00200,-0.13373,26.47921,39.95438
93.39600,7.78292,874.23446,-0.13373,26.54546,39.96500
93.59600,7.79966,874.41243,-0.13373,26.61242,39.97314
93.79601,7.81640,874.31651,-0.13373,26.67938,39.96875
93.99600,7.83290,874.20847,-0.13373,26.74539,39.96382
94.19601,7.84964,875.03558,-0.13373,26.81235,40.00163
94.39600,7.86638,875.13514,-0.13373,26.87932,40.00618
94.59601,7.88306,874.76186,-0.13373,26.94604,39.98911
94.79601,7.89969,875.16317,-0.13373,27.01253,40.00746
94.99600,7.91631,875.15078,-0.13373,27.07902,40.00689
95.19601,7.93305,875.67689,-0.13373,27.14598,40.03094
95.39600,7.94967,875.72411,-0.13373,27.21246,40.03310
95.59601,7.96629,874.79968,-0.13373,27.27895,39.99084
95.79601,7.98303,875.87144,-0.13373,27.34592,40.03984
95.99600,7.99965,874.96517,-0.13373,27.41240,39.99841
96.19601,8.01634,875.18319,-0.13373,27.47913,40.00837
96.39600,8.03296,875.53905,-0.13373,27.54561,40.02464
96.59601,8.04964,875.58394,-0.13373,27.61234,40.02670
96.79601,8.06632,875.39684,-0.13373,27.67906,40.01814
96.99600,8.08294,874.85118,-0.13373,27.74555,39.99320
97.19601,8.09968,875.12024,-0.13373,27.81251,40.00550
97.39600,8.11630,875.16308,-0.13373,27.87900,40.00745
97.59601,8.13299,875.21374,-0.13373,27.94573,40.00977
97.79601,8.14967,875.25751,-0.13373,28.01245,40.01177
97.99600,8.16635,875.27465,-0.13373,28.07918,40.01255
98.19601,8.18303,875.24299,-0.13373,28.14590,40.01111
98.39600,8.19965,875.53551,-0.13373,28.21238,40.02448
98.59601,8.21633,875.94055,-0.13373,28.27911,40.04300
98.79601,8.23295,875.41174,-0.13373,28.34560,40.01882
98.99600,8.24969,875.24075,-0.13373,28.41256,40.01101
99.19601,8.26638,875.23693,-0.13373,28.47929,40.01083
99.39600,8.28300,875.16513,-0.13373,28.54577,40.00755
99.59601,8.29956,875.49165,-0.13373,28.61202,40.02248
99.79601,8.31636,875.39023,-0.13373,28.67922,40.01784
99.99600,8.33304,875.09416,-0.13373,28.74595,40.00430
100.19601,8.34966,875.20937,-0.13373,28.81243,40.00957
100.39600,8.36634,875.11707,-0.13373,28.87916,40.00535
100.59601,8.38296,875.04564,-0.13373,28.94565,40.00209
100.79601,8.39965,875.21430,-0.13373,29.01237,40.00980
100.99600,8.41639,874.88322,-0.13373,29.07933,39.99466
101.19601,8.43307,875.04489,-0.13373,29.14606,40.00205
101.39600,8.44963,874.31781,-0.13373,29.21230,39.96881
101.59601,8.46631,874.84326,-0.13373,29.27903,39.99284
101.79601,8.48305,875.14427,-0.13373,29.34600,40.00660
101.99600,8.49961,875.22697,-0.13373,29.41224,40.01038
102.19601,8.51636,874.79269,-0.13373,29.47921,39.99052
102.39600,8.53304,874.92950,-0.13373,29.54593,39.99678
102.59601,8.54966,874.36782,-0.13373,29.61242,39.97110
102.79601,8.56622,874.54915,-0.13373,29.67866,39.97939
102.99600,8.58308,874.93919,-0.13373,29.74611,39.99722
103.19601,8.59970,874.42268,-0.13373,29.81259,39.97361
103.39600,8.61632,874.68103,-0.13373,29.87908,39.98542
103.59601,8.63300,874.60130,-0.13373,29.94580,39.98177
103.79601,8.64969,874.68224,-0.13373,30.01253,39.98547
103.99600,8.66631,874.24340,-0.13373,30.07901,39.96541
104.19601,8.68293,874.73467,-0.13373,30.14550,39.98787
104.39600,8.69967,874.09969,-0.13373,30.21246,39.95884
104.59601,8.71623,873.98225,-0.13373,30.27871,39.95348
104.79601,8.73291,874.42109,-0.13373,30.34544,39.97354
104.99600,8.74971,874.07324,-0.13373,30.41264,39.95763
105.19601,8.76634,873.97220,-0.13373,30.47913,39.95301
105.39600,8.78302,873.20013,-0.13373,30.54585,39.91772
105.59601,8.79970,874.14086,-0.13373,30.61258,39.96072
105.79601,8.81638,873.10178,-0.13373,30.67930,39.91322
105.99600,8.83294,873.93112,-0.13373,30.74555,39.95114
106.19601,8.84962,874.31073,-0.13373,30.81227,39.96849
106.39600,8.86642,873.06295,-0.13373,30.87948,39.91145
106.59601,8.88298,872.88301,-0.13373,30.94572,39.90322
106.79601,8.89961,873.41256,-0.13373,31.01221,39.92743
106.99600,8.91635,872.99729,-0.13373,31.07917,39.90845
107.19601,8.93291,873.32390,-0.13372,31.14542,39.92338
107.39600,8.94965,873.23235,-0.13373,31.21238,39.91919
107.59601,8.96645,873.18625,-0.13373,31.27959,39.91709
107.79601,8.98295,872.37181,-0.13373,31.34560,39.87986
107.99600,8.99957,872.90527,-0.13373,31.41208,39.90424
108.19601,9.01631,872.71295,-0.13373,31.47905,39.89545
108.39600,9.03306,872.36213,-0.13373,31.54601,39.87941
108.59601,9.04968,872.46485,-0.13373,31.61249,39.88411
108.79601,9.06636,872.91412,-0.13373,31.67922,39.90464
108.99600,9.08304,872.55444,-0.13373,31.74595,39.88820
109.19601,9.09960,872.64730,-0.13373,31.81219,39.89245
109.39600,9.11628,872.35514,-0.13373,31.87892,39.87909
109.59601,9.13314,872.56050,-0.13373,31.94636,39.88848
109.79601,9.14965,871.95337,-0.13373,32.01237,39.86073
109.99600,9.16621,872.30010,-0.13373,32.07861,39.87658
110.19601,9.18301,871.89153,-0.13373,32.14582,39.85790
110.39600,9.19969,871.21697,-0.13373,32.21254,39.82706
110.59601,9.21637,871.68012,-0.13373,32.27927,39.84823
110.79601,9.23299,871.45055,-0.13373,32.34575,39.83774
110.99600,9.24967,871.60766,-0.13373,32.41248,39.84492
111.19601,9.26629,871.75546,-0.13373,32.47896,39.85168
111.39600,9.28298,870.92957,-0.13373,32.54569,39.81392
111.59601,9.29972,871.63951,-0.13373,32.61265,39.84638
111.79601,9.31628,871.17720,-0.13373,32.67890,39.82524
111.99600,9.33302,871.00239,-0.13373,32.74587,39.81725
112.19601,9.34964,870.78828,-0.13373,32.81235,39.80746
112.39600,9.36632,870.74656,-0.13373,32.87908,39.80556
112.59601,9.38300,871.28077,-0.13373,32.94580,39.82998
112.79601,9.39969,870.37086,-0.13373,33.01252,39.78838
112.99600,9.41643,870.74703,-0.13373,33.07949,39.80558
113.19601,9.43299,870.78949,-0.13373,33.14574,39.80752
113.39600,9.44967,870.44975,-0.13373,33.21246,39.79199
113.59601,9.46641,870.21254,-0.13373,33.27943,39.78114
113.79601,9.48297,870.38428,-0.13373,33.34568,39.78899
113.99600,9.49971,870.24830,-0.13373,33.41264,39.78278
114.19601,9.51633,870.46213,-0.13373,33.47912,39.79255
114.39600,9.53296,870.73566,-0.13373,33.54561,39.80506
114.59601,9.54964,869.88537,-0.13373,33.61233,39.76619
114.79601,9.56638,869.54562,-0.13373,33.67930,39.75066
114.99600,9.58306,869.51107,-0.13373,33.74602,39.74908
115.19601,9.59962,869.06608,-0.13373,33.81227,39.72874
115.39600,9.61630,869.33225,-0.13373,33.87900,39.74090
115.59601,9.63310,869.72183,-0.13373,33.94620,39.75871
115.79601,9.64961,868.99521,-0.13373,34.01221,39.72549
115.99600,9.66635,868.87153,-0.13373,34.07917,39.71984
116.19601,9.68309,869.06124,-0.13373,34.14614,39.72852
116.39600,9.69965,869.53975,-0.13372,34.21238,39.75039
116.59601,9.71627,868.65630,-0.13373,34.27887,39.71000
116.79601,9.73301,869.07223,-0.13373,34.34583,39.72902
116.99600,9.74969,868.24885,-0.13373,34.41256,39.69138
117.19601,9.76631,868.04759,-0.13373,34.47904,39.68217
117.39600,9.78300,868.16093,-0.13373,34.54577,39.68736
117.59601,9.79968,868.10654,-0.13373,34.61249,39.68487
117.79601,9.81624,867.84177,-0.13373,34.67874,39.67277
117.99600,9.83292,868.40922,-0.13373,34.74546,39.69871
118.19601,9.84966,868.14361,-0.13373,34.81243,39.68657
118.39600,9.86634,867.41596,-0.13373,34.87915,39.65330
118.59601,9.88296,868.11995,-0.13373,34.94564,39.68548
118.79601,9.89964,867.70533,-0.13373,35.01236,39.66653
118.99600,9.91639,867.41438,-0.13373,35.07933,39.65323
119.19601,9.93307,867.63995,-0.13373,35.14605,39.66354
119.39600,9.94975,867.72935,-0.13373,35.21278,39.66763
119.59601,9.96637,867.10677,-0.13373,35.27926,39.63917
119.79601,9.98299,867.24386,-0.13373,35.34575,39.64544
119.99600,9.99961,866.67705,-0.13373,35.41224,39.61952
120.19601,10.01629,866.70546,-0.13373,35.47896,39.62082
120.39600,10.03292,866.47123,-0.13373,35.54545,39.61012
120.59601,10.04966,866.34336,-0.13373,35.61241,39.60427
120.79601,10.06634,866.47607,-0.13373,35.67913,39.61034
120.99600,10.08302,866.32418,-0.13373,35.74587,39.60339
121.19601,10.09970,866.38471,-0.13373,35.81259,39.60616
121.39600,10.11632,865.86801,-0.13373,35.87907,39.58254
121.59601,10.13300,865.45814,-0.13373,35.94580,39.56380
121.79601,10.14968,866.08008,-0.13373,36.01252,39.59223
121.99600,10.16631,865.71053,-0.13373,36.07901,39.57534
122.19601,10.18305,864.57869,-0.13373,36.14597,39.52360
122.39600,10.19961,865.18759,-0.13373,36.21222,39.55143
122.59601,10.21629,865.09809,-0.13373,36.27895,39.54734
122.79601,10.23303,864.97013,-0.13373,36.34591,39.54149
122.99600,10.24965,865.41940,-0.13373,36.41240,39.56203
123.19601,10.26627,865.18470,-0.13373,36.47888,39.55130
123.39600,10.28302,865.12463,-0.13373,36.54585,39.54855
123.59601,10.29976,864.80230,-0.13373,36.61281,39.53382
123.79601,10.31626,864.69660,-0.13373,36.67882,39.52899
123.99600,10.33300,864.37864,-0.13373,36.74578,39.51445
124.19601,10.34968,864.18893,-0.13373,36.81251,39.50578
124.39600,10.36636,863.95126,-0.13373,36.87923,39.49492
124.59601,10.38304,863.86856,-0.13373,36.94596,39.49113
124.79601,10.39972,864.20039,-0.13373,37.01268,39.50630
124.99600,10.41629,864.42493,-0.13373,37.07893,39.51657
125.19601,10.43297,863.51447,-0.13373,37.14565,39.47495
125.39600,10.44959,863.89007,-0.13373,37.21214,39.49212
125.59601,10.46633,863.44127,-0.13373,37.27911,39.47160
125.79601,10.48301,863.13039,-0.13373,37.34583,39.45739
125.99600,10.49963,863.71368,-0.13373,37.41232,39.48405
126.19601,10.51631,862.44382,-0.13373,37.47904,39.42600
126.39600,10.53299,862.91488,-0.13373,37.54576,39.44754
126.59601,10.54962,862.53127,-0.13373,37.61225,39.43000
126.79601,10.56636,862.83134,-0.13373,37.67922,39.44372
126.99601,10.58304,861.97350,-0.13373,37.74594,39.40450
127.19601,10.59966,862.01392,-0.13373,37.81243,39.40635
127.39600,10.61628,862.39958,-0.13373,37.87892,39.42398
127.59601,10.63296,861.64773,-0.13373,37.94563,39.38961
127.79601,10.64970,861.20851,-0.13373,38.01260,39.36953
127.99601,10.66633,861.43818,-0.13373,38.07909,39.38003
128.19600,10.68301,861.77262,-0.13373,38.14581,39.39532
128.39601,10.69963,860.99263,-0.13373,38.21230,39.35966
128.59601,10.71631,861.14341,-0.13373,38.27902,39.36655
128.79601,10.73305,860.70327,-0.13373,38.34599,39.34644
128.99600,10.74967,860.36129,-0.13373,38.41247,39.33080
129.19600,10.76629,860.41493,-0.13373,38.47896,39.33326
129.39601,10.78304,860.37144,-0.13373,38.54593,39.33126
129.59601,10.79960,860.29069,-0.13373,38.61217,39.32758
129.79601,10.81628,859.89870,-0.13373,38.67890,39.30965
129.99600,10.83308,859.76599,-0.13373,38.74610,39.30359
130.19600,10.84976,859.45977,-0.13373,38.81283,39.28959
130.39601,10.86632,859.23467,-0.13373,38.87907,39.27930
130.59601,10.88294,859.15951,-0.13373,38.94556,39.27586
130.79601,10.89968,858.91727,-0.13373,39.01252,39.26479
130.99600,10.91636,858.86978,-0.13373,39.07925,39.26262
131.19600,10.93293,858.18861,-0.13373,39.14549,39.23148
131.39602,10.94967,858.58926,-0.13373,39.21246,39.24979
131.59602,10.96629,858.24728,-0.13373,39.27894,39.23416
131.79600,10.98297,857.96984,-0.13373,39.34567,39.22148
131.99600,10.99971,857.81999,-0.13373,39.41264,39.21463
132.19600,11.01639,857.52029,-0.13373,39.47935,39.20093
132.39602,11.03301,857.60346,-0.13373,39.54584,39.20473
132.59602,11.04964,856.95768,-0.13373,39.61233,39.17521
132.79600,11.06638,856.36582,-0.13373,39.67929,39.14815
132.99600,11.08294,856.74534,-0.13373,39.74554,39.16550
133.19600,11.09968,856.14426,-0.13373,39.81251,39.13802
133.39602,11.11636,855.79269,-0.13373,39.87923,39.12195
133.59602,11.13292,855.66742,-0.13373,39.94548,39.11623
133.79600,11.14960,855.63296,-0.13373,40.01220,39.11465
133.99600,11.16634,854.87794,-0.13373,40.07916,39.08014
134.19600,11.18303,854.78313,-0.13373,40.14589,39.07580
134.39602,11.19977,854.42448,-0.13373,40.21285,39.05941
134.59602,11.21633,854.44683,-0.13373,40.27910,39.06042
134.79600,11.23301,853.97046,-0.13373,40.34582,39.03865
134.99600,11.24963,853.97372,-0.13373,40.41231,39.03880
135.19600,11.26631,853.90294,-0.13373,40.47904,39.03556
135.39602,11.28317,852.91546,-0.13373,40.54648,38.99042
135.59602,11.29962,852.75965,-0.13373,40.61225,38.98330
135.79600,11.31624,852.09357,-0.13373,40.67874,38.95285
135.99600,11.33304,852.09059,-0.13373,40.74593,38.95271
136.19600,11.34966,851.86651,-0.13373,40.81243,38.94247
136.39602,11.36628,851.50832,-0.13373,40.87891,38.92609
136.59602,11.38302,851.94083,-0.13373,40.94587,38.94587
136.79600,11.39970,851.31377,-0.13373,41.01260,38.91720
136.99600,11.41627,851.35484,-0.13373,41.07884,38.91908
137.19600,11.43301,850.86543,-0.13373,41.14581,38.89671
137.39602,11.44981,850.47176,-0.13373,41.21301,38.87871
137.59602,11.46631,850.46887,-0.13373,41.27902,38.87858
137.79600,11.48299,849.45820,-0.13373,41.34575,38.83237
137.99600,11.49973,849.29103,-0.13373,41.41271,38.82473
138.19600,11.51629,848.80181,-0.13373,41.47896,38.80237
138.39602,11.53297,848.55743,-0.13373,41.54568,38.79119
138.59602,11.54972,848.34266,-0.13373,41.61265,38.78138
138.79600,11.56628,847.94434,-0.13373,41.67890,38.76317
138.99600,11.58290,848.02918,-0.13373,41.74538,38.76705
139.19600,11.59964,846.57194,-0.13373,41.81234,38.70043
139.39602,11.61638,846.77991,-0.13373,41.87931,38.70994
139.59602,11.63300,846.67215,-0.13373,41.94579,38.70501
139.79600,11.64968,846.30158,-0.13373,42.01252,38.68807
139.99600,11.66636,845.25198,-0.13373,42.07924,38.64009
140.19600,11.68299,845.13621,-0.13373,42.14573,38.63480
140.39602,11.69961,844.13588,-0.13373,42.21222,38.58907
140.59602,11.71635,844.66496,-0.13373,42.27918,38.61325
140.79600,11.73297,843.46449,-0.13373,42.34566,38.55838
140.99600,11.74959,843.83702,-0.13373,42.41215,38.57541
141.19600,11.76621,842.91063,-0.13373,42.47864,38.53306
141.39602,11.78301,842.50811,-0.13373,42.54584,38.51466
141.59602,11.79963,841.92501,-0.13373,42.61232,38.48800
141.79600,11.81638,841.60343,-0.13373,42.67929,38.47330
141.99600,11.83306,841.24878,-0.13373,42.74602,38.45709
142.19600,11.84962,839.75233,-0.13373,42.81226,38.38868
142.39602,11.86630,840.06805,-0.13373,42.87899,38.40311
142.59602,11.88304,839.57426,-0.13373,42.94595,38.38054
142.79600,11.89972,839.22148,-0.13373,43.01268,38.36441
142.99600,11.91629,838.44857,-0.13373,43.07893,38.32908
143.19602,11.93297,837.86333,-0.13373,43.14565,38.30232
143.39602,11.94965,837.80829,-0.13373,43.21237,38.29981
143.59602,11.96621,836.85312,-0.13373,43.27862,38.25614
143.79600,11.98301,836.07212,-0.13373,43.34582,38.22044
143.99600,11.99975,835.69521,-0.13374,43.41279,38.20321
144.19602,12.01625,834.83420,-0.13373,43.47879,38.16385
144.39602,12.03293,834.46773,-0.13373,43.54552,38.14709
144.59602,12.04979,834.08821,-0.13373,43.61297,38.12975
144.79600,12.06642,833.12206,-0.13373,43.67945,38.08558
144.99600,12.08292,832.61682,-0.13373,43.74546,38.06248
145.19602,12.09972,831.76997,-0.13373,43.81266,38.02377
145.39602,12.11640,830.50411,-0.13373,43.87938,37.96590
145.59602,12.13296,830.22118,-0.13373,43.94563,37.95297
145.79600,12.14964,829.65037,-0.13373,44.01236,37.92687
145.99600,12.16638,828.42540,-0.13373,44.07932,37.87088
146.19602,12.18301,828.06004,-0.13373,44.14581,37.85417
146.39602,12.19963,827.15396,-0.13373,44.21229,37.81275
146.59602,12.21637,826.85249,-0.13373,44.27926,37.79897
146.79600,12.23299,825.80131,-0.13373,44.34574,37.75092
146.99600,12.24961,825.66487,-0.13373,44.41223,37.74468
147.19602,12.26641,823.90690,-0.13373,44.47944,37.66431
147.39602,12.28297,823.74541,-0.13373,44.54568,37.65693
147.59602,12.29965,821.94814,-0.13373,44.61240,37.57477
147.79600,12.31628,821.46805,-0.13373,44.67889,37.55283
147.99600,12.33302,820.52844,-0.13373,44.74585,37.50987
148.19602,12.34970,819.39548,-0.13373,44.81258,37.45808
148.39602,12.36632,818.55282,-0.13373,44.87906,37.41956
148.59602,12.38306,817.72190,-0.13373,44.94603,37.38157
148.79600,12.39962,816.50680,-0.13373,45.01228,37.32603
148.99600,12.41630,815.46372,-0.13373,45.07900,37.27834
149.19602,12.43299,814.50213,-0.13373,45.14573,37.23438
149.39602,12.44967,813.79758,-0.13373,45.21245,37.20218
149.59602,12.46629,812.70784,-0.13373,45.27894,37.15236
149.79600,12.48297,811.68106,-0.13373,45.34566,37.10542
149.99600,12.49965,811.60339,-0.13373,45.41239,37.10187
150.19602,12.51627,809.98065,-0.13373,45.47887,37.02769
150.39602,12.53301,809.05324,-0.13373,45.54584,36.98529
150.59602,12.54975,807.45341,-0.13373,45.61280,36.91216
150.79600,12.56626,806.34886,-0.13374,45.67881,36.86166
150.99600,12.58300,805.19449,-0.13373,45.74577,36.80889
151.19602,12.59974,804.36999,-0.13374,45.81274,36.77120
151.39602,12.61630,803.17967,-0.13373,45.87899,36.71679
151.59602,12.63298,801.67176,-0.13373,45.94571,36.64785
151.79600,12.64972,800.68959,-0.13373,46.01267,36.60295
151.99600,12.66628,800.02565,-0.13373,46.07892,36.57260
152.19602,12.68297,798.45395,-0.13373,46.14564,36.50075
152.39602,12.69965,797.58102,-0.13373,46.21237,36.46085
152.59602,12.71639,795.74585,-0.13373,46.27934,36.37695
152.79600,12.73295,794.91483,-0.13373,46.34558,36.33896
152.99600,12.74963,793.07184,-0.13373,46.41231,36.25471
153.19602,12.76643,792.67463,-0.13373,46.47951,36.23655
153.39602,12.78299,790.22115,-0.13373,46.54576,36.12440
153.59602,12.79973,788.73308,-0.13373,46.61272,36.05637
153.79600,12.81642,787.54090,-0.13373,46.67945,36.00187
153.99600,12.83298,786.56124,-0.13373,46.74570,35.95708
154.19602,12.84960,784.97063,-0.13373,46.81218,35.88437
154.39602,12.86628,783.60168,-0.13373,46.87890,35.82179
154.59602,12.88296,781.72032,-0.13373,46.94563,35.73579
154.79600,12.89964,779.75602,-0.13373,47.01235,35.64599
154.99600,12.91626,778.36402,-0.13373,47.07884,35.58236
155.19602,12.93301,776.54836,-0.13373,47.14581,35.49936
155.39602,12.94963,775.30774,-0.13373,47.21229,35.44264
155.59602,12.96631,773.16347,-0.13373,47.27902,35.34462
155.79600,12.98305,771.60792,-0.13373,47.34598,35.27351
155.99600,12.99973,769.90160,-0.13373,47.41271,35.19550
156.19602,13.01635,768.16482,-0.13373,47.47919,35.11611
156.39602,13.03297,765.82809,-0.13373,47.54568,35.00928
156.59602,13.04971,763.39026,-0.13373,47.61264,34.89784
156.79600,13.06640,761.57302,-0.13373,47.67936,34.81477
156.99600,13.08296,758.91525,-0.13373,47.74562,34.69327
157.19602,13.09970,757.51687,-0.13373,47.81258,34.62934
157.39602,13.11626,754.69911,-0.13373,47.87882,34.50053
157.59602,13.13294,752.03232,-0.13373,47.94555,34.37862
157.79600,13.14974,748.97194,-0.13373,48.01275,34.23872
157.99600,13.16636,746.09159,-0.13373,48.07924,34.10704
158.19602,13.18299,741.68476,-0.13373,48.14573,33.90559
158.39602,13.19973,737.07290,-0.13373,48.21269,33.69476
158.59602,13.21635,731.74317,-0.13373,48.27918,33.45111
158.79600,13.23303,724.10698,-0.13373,48.34590,33.10203
158.99600,13.24971,709.76242,-0.13373,48.41262,32.44628
159.19602,13.26645,87.24714,-0.13372,48.47959,3.98844
159.20800,13.26747,2.09583,-0.13372,48.48365,0.09581