File: Manufatura Aditiva/Classificação Direção/Ensaios/Ensaios FDM/Tracao_OLABI_23_05_2018_FDM_YX2.is_metal_RawData/Specimen_RawData_1.csv
Time,Extension,Load,Strain 1,Tensile strain,Tensile stress
(sec),(mm),(N),(mm/mm),(%),(MPa)
0.00000,0.00006,15.29409,-0.00028,-0.02759,0.77320
0.10000,0.00425,17.19148,-0.00025,-0.02487,0.86913
0.20000,0.01381,20.59026,-0.00013,-0.01326,1.04095
0.30000,0.02350,25.38004,-0.00001,-0.00062,1.28310
0.40000,0.03259,29.48473,0.00011,0.01150,1.49062
0.50000,0.04143,32.79457,0.00023,0.02306,1.65795
0.60000,0.04986,36.78281,0.00034,0.03398,1.85958
0.70000,0.05823,40.22163,0.00045,0.04492,2.03343
0.80000,0.06667,44.89108,0.00057,0.05658,2.26950
0.90000,0.07498,47.63258,0.00067,0.06710,2.40809
1.00000,0.08329,51.53319,0.00079,0.07862,2.60529
1.10000,0.09172,55.12984,0.00091,0.09056,2.78712
1.20000,0.10003,59.75553,0.00102,0.10151,3.02098
1.30000,0.10834,62.77535,0.00113,0.11276,3.17365
1.40000,0.11671,66.85894,0.00125,0.12500,3.38009
1.50000,0.12508,70.69526,0.00137,0.13650,3.57404
1.60000,0.13339,73.96608,0.00148,0.14808,3.73940
1.70000,0.14164,77.56084,0.00159,0.15925,3.92114
1.80000,0.14995,81.42351,0.00171,0.17131,4.11642
1.90000,0.15832,84.97319,0.00183,0.18315,4.29587
2.00000,0.16663,88.29536,0.00195,0.19462,4.46383
2.10000,0.17494,91.76806,0.00207,0.20703,4.63939
2.20000,0.18331,96.11330,0.00219,0.21890,4.85907
2.30000,0.19157,99.46078,0.00231,0.23076,5.02830
2.40000,0.20000,102.79814,0.00242,0.24240,5.19702
2.50000,0.20837,106.39149,0.00255,0.25527,5.37869
2.60000,0.21668,109.97880,0.00267,0.26711,5.56004
2.70000,0.22499,113.39800,0.00279,0.27896,5.73290
2.80000,0.23330,116.91445,0.00291,0.29066,5.91068
2.90000,0.24161,121.06340,0.00303,0.30327,6.12043
3.00000,0.24998,124.32191,0.00315,0.31531,6.28517
3.10000,0.25841,127.71583,0.00328,0.32788,6.45675
3.20000,0.26672,130.91218,0.00340,0.33983,6.61834
3.30000,0.27503,134.43012,0.00352,0.35235,6.79620
3.40000,0.28340,138.51670,0.00365,0.36481,7.00280
3.50000,0.29165,141.74872,0.00377,0.37654,7.16619
3.60000,0.30002,145.10434,0.00389,0.38950,7.33584
3.70000,0.30839,149.10942,0.00402,0.40183,7.53832
3.80000,0.31670,151.85492,0.00414,0.41395,7.67712
3.90000,0.32508,155.93099,0.00427,0.42698,7.88319
4.00000,0.33333,159.08807,0.00440,0.44010,8.04279
4.10000,0.34164,162.24725,0.00453,0.45256,8.20251
4.20000,0.35001,165.94901,0.00465,0.46485,8.38965
4.30000,0.35826,169.42549,0.00477,0.47748,8.56541
4.40000,0.36663,173.04941,0.00490,0.49039,8.74862
4.50000,0.37500,176.58990,0.00503,0.50307,8.92761
4.60000,0.38331,180.37804,0.00516,0.51571,9.11912
4.70000,0.39162,183.84840,0.00529,0.52860,9.29457
4.80000,0.40005,187.17288,0.00541,0.54100,9.46264
4.90000,0.40836,190.74278,0.00554,0.55397,9.64312
5.00000,0.41661,194.12204,0.00566,0.56641,9.81396
5.10000,0.42510,197.14376,0.00580,0.58000,9.96672
5.20000,0.43329,201.12989,0.00592,0.59168,10.16824
5.30000,0.44161,204.50011,0.00605,0.60455,10.33863
5.40000,0.45010,207.98172,0.00618,0.61815,10.51464
5.50000,0.45829,211.52005,0.00631,0.63064,10.69352
5.60000,0.46666,214.86923,0.00644,0.64371,10.86284
5.70000,0.47509,218.80942,0.00657,0.65666,11.06204
5.80000,0.48328,222.09990,0.00669,0.66939,11.22839
5.90000,0.49165,225.04921,0.00682,0.68209,11.37750
6.00000,0.50002,228.79788,0.00695,0.69492,11.56702
6.10000,0.50833,232.21991,0.00708,0.70772,11.74002
6.20000,0.51670,235.56331,0.00721,0.72059,11.90905
6.30000,0.52501,239.68511,0.00734,0.73425,12.11743
6.40000,0.53332,242.73263,0.00747,0.74727,12.27149
6.50000,0.54169,246.00569,0.00761,0.76064,12.43697
6.60000,0.55000,249.33701,0.00774,0.77368,12.60538
6.70000,0.55825,252.71459,0.00787,0.78660,12.77614
6.80000,0.56680,256.69469,0.00800,0.79982,12.97736
6.90000,0.57506,259.91537,0.00813,0.81251,13.14018
7.00000,0.58331,263.45721,0.00825,0.82538,13.31924
7.10000,0.59180,266.93679,0.00839,0.83897,13.49515
7.20000,0.59993,270.02981,0.00852,0.85179,13.65152
7.30000,0.60824,273.95308,0.00865,0.86518,13.84986
7.40000,0.61673,278.25022,0.00879,0.87850,14.06711
7.50000,0.62492,280.42446,0.00891,0.89143,14.17703
7.60000,0.63329,284.31339,0.00905,0.90479,14.37364
7.70000,0.64166,287.34463,0.00918,0.91760,14.52688
7.80000,0.64991,290.93870,0.00931,0.93073,14.70858
7.90000,0.65834,294.27176,0.00944,0.94397,14.87709
8.00000,0.66671,297.37253,0.00957,0.95686,15.03385
8.10000,0.67496,300.81416,0.00970,0.97029,15.20784
8.20000,0.68327,303.37074,0.00983,0.98314,15.33709
8.30000,0.69164,307.60258,0.00997,0.99665,15.55103
8.40000,0.69996,311.14458,0.01010,1.00988,15.73010
8.50000,0.70833,314.65304,0.01023,1.02340,15.90747
8.60000,0.71664,317.72105,0.01037,1.03661,16.06258
8.70000,0.72501,321.00757,0.01050,1.04962,16.22873
8.80000,0.73344,324.03199,0.01064,1.06356,16.38163
8.90000,0.74169,327.61791,0.01077,1.07658,16.56292
9.00000,0.75000,331.01586,0.01090,1.08971,16.73471
9.10000,0.75843,334.54823,0.01103,1.10336,16.91329
9.20000,0.76662,337.98972,0.01116,1.11649,17.08727
9.30000,0.77493,340.63228,0.01130,1.12969,17.22087
9.40000,0.78336,344.17387,0.01143,1.14296,17.39992
9.50000,0.79167,347.85555,0.01156,1.15647,17.58605
9.60000,0.79992,350.95669,0.01170,1.17001,17.74283
9.70000,0.80835,353.68097,0.01183,1.18341,17.88056
9.80000,0.81666,357.03143,0.01197,1.19677,18.04994
9.90000,0.82498,359.42178,0.01208,1.20762,18.17079
10.00000,0.83341,362.85843,0.01221,1.22071,18.34453
10.10000,0.84172,365.88740,0.01234,1.23441,18.49766
10.20000,0.85003,368.93985,0.01248,1.24779,18.65198
10.30000,0.85840,372.70114,0.01261,1.26128,18.84213
10.40000,0.86665,375.36744,0.01275,1.27473,18.97693
10.50000,0.87502,378.76626,0.01288,1.28804,19.14876
10.60000,0.88333,382.02156,0.01302,1.30212,19.31333
10.70000,0.89158,385.26324,0.01316,1.31578,19.47722
10.80000,0.89995,388.17895,0.01329,1.32890,19.62462
10.90000,0.90832,391.15450,0.01342,1.34216,19.77505
11.00000,0.91663,394.94596,0.01356,1.35563,19.96673
11.10000,0.92506,398.02645,0.01369,1.36930,20.12247
11.20000,0.93331,401.44608,0.01383,1.38288,20.29535
11.30000,0.94168,404.43134,0.01397,1.39652,20.44627
11.40000,0.95006,406.93679,0.01410,1.40991,20.57294
11.50000,0.95825,410.86185,0.01424,1.42355,20.77137
11.60000,0.96656,414.07300,0.01437,1.43711,20.93371
11.70000,0.97505,417.20290,0.01451,1.45071,21.09195
11.80000,0.98324,420.20651,0.01464,1.46421,21.24380
11.90000,0.99161,423.45626,0.01478,1.47781,21.40809
12.00000,1.00010,425.93726,0.01492,1.49215,21.53352
12.10000,1.00829,429.74036,0.01505,1.50545,21.72578
12.20000,1.01666,432.14918,0.01519,1.51886,21.84756
12.30000,1.02509,435.80746,0.01532,1.53245,22.03251
12.40000,1.03328,439.42770,0.01547,1.54672,22.21553
12.50000,1.04165,442.71587,0.01560,1.56014,22.38177
12.60000,1.05002,445.08399,0.01574,1.57427,22.50149
12.70000,1.05827,448.18209,0.01588,1.58752,22.65812
12.80000,1.06670,451.65354,0.01601,1.60100,22.83362
12.90000,1.07502,454.64723,0.01615,1.61516,22.98497
13.00000,1.08327,458.05685,0.01629,1.62856,23.15734
13.10000,1.09170,460.86614,0.01642,1.64241,23.29937
13.20000,1.09995,464.57732,0.01656,1.65637,23.48699
13.30000,1.10826,467.01874,0.01670,1.66950,23.61041
13.40000,1.11675,470.54403,0.01683,1.68328,23.78864
13.50000,1.12506,473.06274,0.01697,1.69693,23.91597
13.60000,1.13325,475.92111,0.01710,1.70959,24.06048
13.70000,1.14174,479.10069,0.01723,1.72293,24.22123
13.80000,1.14993,481.72246,0.01737,1.73658,24.35377
13.90000,1.15824,485.18539,0.01750,1.75027,24.52884
14.00000,1.16679,488.27450,0.01764,1.76425,24.68501
14.10000,1.17492,491.01575,0.01778,1.77809,24.82360
14.20000,1.18329,494.21657,0.01792,1.79217,24.98542
14.30000,1.19172,497.17342,0.01806,1.80586,25.13490
14.40000,1.19998,500.30015,0.01820,1.81955,25.29298
14.50000,1.20841,502.91708,0.01832,1.83153,25.42528
14.60000,1.21678,505.86788,0.01845,1.84544,25.57446
14.70000,1.22497,508.37724,0.01859,1.85883,25.70132
14.80000,1.23334,511.40334,0.01873,1.87319,25.85431
14.90000,1.24171,514.31134,0.01887,1.88710,26.00132
15.00000,1.24996,517.56073,0.01901,1.90094,26.16560
15.10000,1.25833,520.62501,0.01915,1.91503,26.32051
15.20000,1.26670,523.01548,0.01929,1.92901,26.44136
15.30000,1.27495,526.51293,0.01943,1.94256,26.61818
15.40000,1.28338,529.02065,0.01956,1.95643,26.74496
15.50000,1.29169,531.64586,0.01971,1.97067,26.87768
15.60000,1.29994,534.47299,0.01985,1.98463,27.02061
15.70000,1.30831,537.64442,0.01999,1.99878,27.18094
15.80000,1.31656,540.83425,0.02013,2.01251,27.34220
15.90000,1.32494,543.34234,0.02027,2.02665,27.46900
16.00000,1.33337,546.79471,0.02041,2.04076,27.64354
16.10000,1.34156,549.41191,0.02055,2.05469,27.77585
16.20000,1.34993,551.86148,0.02068,2.06843,27.89969
16.30000,1.35842,554.22261,0.02083,2.08283,28.01906
16.40000,1.36667,557.47237,0.02097,2.09707,28.18335
16.50000,1.37504,560.90751,0.02111,2.11079,28.35702
16.60000,1.38341,563.42990,0.02125,2.12527,28.48454
16.70000,1.39166,566.06601,0.02139,2.13909,28.61781
16.80000,1.40003,569.07027,0.02153,2.15329,28.76969
16.90000,1.40840,571.67383,0.02167,2.16735,28.90132
17.00000,1.41677,574.51674,0.02182,2.18170,29.04504
17.10000,1.42502,577.53641,0.02196,2.19620,29.19770
17.20000,1.43333,579.96064,0.02211,2.21058,29.32026
17.30000,1.44164,582.96709,0.02224,2.22438,29.47225
17.40000,1.45001,585.27440,0.02238,2.23844,29.58890
17.50000,1.45839,588.07465,0.02253,2.25270,29.73047
17.60000,1.46670,590.92804,0.02267,2.26688,29.87473
17.70000,1.47507,593.71730,0.02281,2.28139,30.01574
17.80000,1.48338,596.26610,0.02296,2.29557,30.14459
17.90000,1.49163,598.97504,0.02310,2.30968,30.28155
18.00000,1.50000,601.66507,0.02324,2.32401,30.41754
18.10000,1.50825,604.26714,0.02339,2.33855,30.54909
18.20000,1.51656,607.08993,0.02353,2.35251,30.69180
18.30000,1.52505,608.76808,0.02365,2.36501,30.77664
18.40000,1.53324,611.86450,0.02378,2.37816,30.93318
18.50000,1.54167,613.75601,0.02392,2.39226,31.02881
18.60000,1.55004,616.72120,0.02407,2.40684,31.17871
18.70000,1.55829,619.46786,0.02421,2.42124,31.31757
18.80000,1.56666,621.50713,0.02435,2.43536,31.42067
18.90000,1.57497,624.83684,0.02450,2.44982,31.58900
19.00000,1.58323,627.54340,0.02464,2.46420,31.72584
19.10000,1.59160,630.23111,0.02479,2.47918,31.86172
19.20000,1.60003,632.70265,0.02494,2.49357,31.98667
19.30000,1.60834,634.90421,0.02508,2.50805,32.09797
19.40000,1.61665,637.50329,0.02523,2.52267,32.22937
19.50000,1.62502,640.02723,0.02537,2.53746,32.35696
19.60000,1.63333,642.73481,0.02552,2.55220,32.49385
19.70000,1.64176,645.40859,0.02566,2.56639,32.62902
19.80000,1.65007,648.09863,0.02581,2.58095,32.76502
19.90000,1.65838,651.28068,0.02596,2.59578,32.92589
20.00000,1.66675,652.77629,0.02610,2.61046,33.00150
20.10000,1.67500,655.94120,0.02625,2.62503,33.16151
20.20000,1.68331,657.86117,0.02639,2.63950,33.25857
20.30000,1.69174,660.29136,0.02655,2.65473,33.38143
20.40000,1.69999,662.73427,0.02670,2.66952,33.50493
20.50000,1.70831,665.53014,0.02684,2.68377,33.64628
20.60000,1.71674,668.04546,0.02699,2.69871,33.77344
20.70000,1.72499,670.52078,0.02714,2.71351,33.89858
20.80000,1.73330,672.59595,0.02728,2.72836,34.00349
20.90000,1.74173,675.16756,0.02743,2.74322,34.13351
21.00000,1.74998,677.55878,0.02757,2.75739,34.25439
21.10000,1.75829,680.42111,0.02773,2.77258,34.39910
21.20000,1.76672,683.01223,0.02787,2.78712,34.53010
21.30000,1.77497,685.41854,0.02802,2.80228,34.65175
21.40000,1.78334,687.62735,0.02817,2.81667,34.76342
21.50000,1.79165,690.72265,0.02832,2.83225,34.91990
21.60000,1.79996,692.31428,0.02847,2.84704,35.00037
21.70000,1.80833,694.94681,0.02862,2.86207,35.13346
21.80000,1.81670,697.46505,0.02877,2.87682,35.26077
21.90000,1.82507,699.86046,0.02892,2.89190,35.38187
22.00000,1.83339,702.31296,0.02906,2.90648,35.50586
22.10000,1.84164,704.66371,0.02920,2.92048,35.62470
22.20000,1.85001,705.08192,0.02933,2.93344,35.64584
22.30000,1.85838,707.74285,0.02948,2.94829,35.78037
22.40000,1.86669,710.40052,0.02963,2.96315,35.91473
22.50000,1.87500,712.57246,0.02978,2.97805,36.02453
22.60000,1.88337,714.95147,0.02994,2.99385,36.14481
22.70000,1.89168,716.97840,0.03008,3.00820,36.24728
22.80000,1.89993,719.18224,0.03024,3.02383,36.35869
22.90000,1.90830,721.60587,0.03039,3.03904,36.48122
23.00000,1.91661,723.51573,0.03054,3.05370,36.57778
23.10000,1.92492,725.62783,0.03069,3.06928,36.68456
23.20000,1.93329,728.43013,0.03084,3.08450,36.82623
23.30000,1.94160,730.46568,0.03100,3.11774,36.92913
23.40000,1.94991,732.42513,0.03115,3.15098,37.02820
23.45800,1.95476,733.70943,0.03124,3.17036,37.09312
23.55800,1.96307,735.90628,0.03139,3.20360,37.20419
23.65800,1.97138,737.81176,0.03155,3.23684,37.30052
23.75800,1.97981,739.77918,0.03170,3.27056,37.39999
23.85800,1.98818,742.43192,0.03185,3.30405,37.53410
23.95800,1.99649,743.94182,0.03201,3.33729,37.61043
24.05800,2.00486,746.25849,0.03216,3.37077,37.72755
24.15800,2.01323,747.52602,0.03232,3.40425,37.79163
24.25800,2.02154,749.93637,0.03247,3.43750,37.91349
24.35800,2.02985,752.09811,0.03263,3.47074,38.02278
24.45800,2.03816,754.81050,0.03278,3.50398,38.15990
24.55800,2.04653,756.32008,0.03294,3.53746,38.23622
24.65800,2.05485,758.48885,0.03309,3.57071,38.34586
24.75800,2.06322,760.76370,0.03325,3.60419,38.46087
24.85800,2.07153,761.69823,0.03341,3.63743,38.50812
24.95800,2.07984,763.87315,0.03357,3.67067,38.61807
25.05800,2.08827,766.51182,0.03372,3.70440,38.75147
25.15800,2.09658,767.72817,0.03388,3.73764,38.81296
25.25800,2.10483,770.00698,0.03404,3.77064,38.92817
25.35800,2.11320,772.55261,0.03420,3.80413,39.05687
25.45800,2.12151,773.78247,0.03436,3.83737,39.11904
25.55800,2.12982,775.73014,0.03452,3.87061,39.21751
25.65800,2.13813,777.80220,0.03470,3.90385,39.32226
25.75800,2.14650,779.30312,0.03536,3.93734,39.39814
25.85800,2.15475,781.00050,0.03530,3.97034,39.48396
25.95800,2.16312,784.43838,0.02851,4.00382,39.65776
26.05800,2.17149,784.29235,0.00323,4.03730,39.65038
26.15800,2.17987,786.46531,0.00704,4.07079,39.76023
26.25800,2.18818,788.31194,0.00710,4.10403,39.85359
26.35800,2.19649,790.20392,0.00521,4.13727,39.94924
26.45800,2.20480,791.93702,0.00257,4.17051,40.03686
26.55800,2.21317,792.70564,0.00286,4.20400,40.07571
26.65800,2.22148,794.40353,0.00311,4.23724,40.16155
26.75800,2.22985,796.44099,0.00404,4.27072,40.26456
26.85800,2.23816,798.03783,0.00597,4.30396,40.34529
26.95800,2.24647,799.85205,0.00569,4.33721,40.43700
27.05800,2.25484,801.34450,0.00493,4.37069,40.51245
27.15800,2.26321,803.03354,0.00376,4.40417,40.59785
27.25800,2.27152,804.41907,0.00407,4.43742,40.66789
27.35800,2.27983,806.72288,-0.01328,4.47066,40.78436
27.45800,2.28820,808.48159,-0.02265,4.50414,40.87328
27.55800,2.29651,809.88528,-0.02666,4.53738,40.94424
27.65800,2.30483,811.72409,-0.02686,4.57063,41.03720
27.75800,2.31326,813.17099,-0.02842,4.60435,41.11035
27.85800,2.32145,814.42567,-0.03059,4.63711,41.17378
27.95800,2.32982,816.03164,-0.05224,4.67059,41.25497
28.05800,2.33825,817.74369,-0.07734,4.70432,41.34153
28.15800,2.34650,819.30682,-0.14161,4.73732,41.42055
28.25800,2.35481,820.87303,-0.14151,4.77056,41.49973
28.35800,2.36324,821.93855,-0.14150,4.80428,41.55360
28.45800,2.37149,823.46871,-0.14150,4.83729,41.63096
28.55800,2.37986,825.46035,-0.14150,4.87077,41.73165
28.65800,2.38817,827.11121,-0.14150,4.90401,41.81511
28.75800,2.39642,828.90019,-0.14151,4.93702,41.90555
28.85800,2.40479,829.84753,-0.14151,4.97050,41.95345
28.95800,2.41310,831.32200,-0.14151,5.00374,42.02799
29.05800,2.42147,832.83586,-0.14151,5.03722,42.10452
29.15800,2.42979,834.32468,-0.14151,5.07047,42.17979
29.25800,2.43810,835.13381,-0.14151,5.10371,42.22070
29.35800,2.44641,837.82859,-0.14151,5.13695,42.35693
29.45800,2.45484,838.33551,-0.14151,5.17067,42.38256
29.55800,2.46315,839.63396,-0.14151,5.20392,42.44820
29.65800,2.47152,841.17269,-0.14151,5.23740,42.52600
29.75800,2.47983,842.49945,-0.14152,5.27064,42.59307
29.85800,2.48808,843.80805,-0.14151,5.30365,42.65923
29.95800,2.49639,845.37566,-0.14151,5.33689,42.73848
30.05800,2.50482,846.17091,-0.14151,5.37061,42.77868
30.15800,2.51319,847.49963,-0.14152,5.40409,42.84586
30.25800,2.52144,848.77657,-0.14151,5.43710,42.91042
30.35800,2.52987,849.87814,-0.14151,5.47082,42.96610
30.45800,2.53818,851.71442,-0.14151,5.50406,43.05894
30.55800,2.54649,852.39839,-0.14152,5.53730,43.09352
30.65800,2.55486,853.38606,-0.14152,5.57079,43.14345
30.75800,2.56318,855.13862,-0.14152,5.60403,43.23205
30.85800,2.57143,856.22268,-0.14151,5.63703,43.28686
30.95800,2.57980,858.02013,-0.14152,5.67051,43.37773
31.05800,2.58817,858.21347,-0.14152,5.70400,43.38750
31.15800,2.59648,859.09562,-0.14152,5.73724,43.43210
31.25800,2.60479,860.85722,-0.14152,5.77048,43.52116
31.35800,2.61316,861.57899,-0.14152,5.80396,43.55765
31.45800,2.62159,863.16625,-0.14152,5.83769,43.63789
31.55800,2.62984,864.07363,-0.14152,5.87069,43.68377
31.65800,2.63821,864.75676,-0.14152,5.90417,43.71830
31.75800,2.64652,865.83160,-0.14152,5.93741,43.77264
31.85800,2.65477,867.50621,-0.14152,5.97042,43.85730
31.95800,2.66314,867.69918,-0.14152,6.00390,43.86706
32.05800,2.67145,869.06375,-0.14152,6.03714,43.93605
32.15800,2.67982,870.00802,-0.14152,6.07063,43.98378
32.25800,2.68814,870.72328,-0.14152,6.10387,44.01994
32.35800,2.69651,871.76124,-0.14152,6.13735,44.07242
32.45800,2.70488,872.88395,-0.14152,6.17083,44.12918
32.55800,2.71325,873.30844,-0.14152,6.20431,44.15064
32.65800,2.72162,874.76103,-0.14152,6.23780,44.22408
32.75800,2.72981,875.44015,-0.14152,6.27056,44.25841
32.85800,2.73818,876.37594,-0.14152,6.30404,44.30572
32.95800,2.74655,877.19327,-0.14152,6.33752,44.34704
33.05800,2.75486,877.08980,-0.14152,6.37077,44.34180
33.15800,2.76317,878.49824,-0.14152,6.40401,44.41301
33.25800,2.77148,878.25684,-0.14152,6.43725,44.40081
33.35800,2.77973,879.51478,-0.14152,6.47026,44.46440
33.45800,2.78816,880.14305,-0.14152,6.50398,44.49617
33.55800,2.79653,881.32229,-0.14152,6.53746,44.55578
33.65800,2.80484,882.04797,-0.14152,6.57070,44.59247
33.75800,2.81327,882.33808,-0.14152,6.60443,44.60714
33.85800,2.82153,883.23569,-0.14152,6.63743,44.65252
33.95800,2.82978,883.86219,-0.14153,6.67043,44.68419
34.05800,2.83821,884.81884,-0.14152,6.70415,44.73255
34.15800,2.84646,885.45354,-0.14153,6.73716,44.76464
34.25800,2.85471,886.17485,-0.14152,6.77016,44.80111
34.35800,2.86314,886.15641,-0.14152,6.80388,44.80017
34.45800,2.87145,887.08540,-0.14152,6.83713,44.84714
34.55800,2.87976,888.19368,-0.14152,6.87037,44.90317
34.65800,2.88825,888.64760,-0.14152,6.90433,44.92612
34.75800,2.89650,888.91787,-0.14152,6.93733,44.93978
34.85800,2.90481,889.52044,-0.14153,6.97058,44.97025
34.95800,2.91330,890.34000,-0.14153,7.00454,45.01168
35.05800,2.92149,890.96855,-0.14152,7.03730,45.04346
35.15800,2.92980,891.65680,-0.14152,7.07054,45.07825
35.25800,2.93823,891.72320,-0.14153,7.10426,45.08161
35.35800,2.94649,892.55366,-0.14152,7.13727,45.12359
35.45800,2.95492,893.25262,-0.14153,7.17099,45.15893
35.55800,2.96329,894.01193,-0.14153,7.20447,45.19732
35.65800,2.97148,894.08727,-0.14153,7.23724,45.20112
35.75800,2.97985,894.93897,-0.14152,7.27072,45.24418
35.85800,2.98822,894.72625,-0.14153,7.30420,45.23343
35.95800,2.99641,895.38889,-0.14152,7.33697,45.26693
36.05800,3.00484,895.76263,-0.14152,7.37069,45.28582
36.15800,3.01309,896.68529,-0.14153,7.40369,45.33247
36.25800,3.02134,897.26206,-0.14153,7.43669,45.36163
36.35800,3.02977,896.75067,-0.14153,7.47042,45.33577
36.45800,3.03814,897.88120,-0.14153,7.50390,45.39293
36.55800,3.04639,897.92339,-0.14153,7.53690,45.39506
36.65800,3.05482,897.99650,-0.14152,7.57062,45.39876
36.75800,3.06308,898.32647,-0.14153,7.60363,45.41544
36.85800,3.07139,898.76037,-0.14153,7.63687,45.43737
36.95800,3.07982,898.76056,-0.14153,7.67059,45.43739
37.05800,3.08813,898.81057,-0.14153,7.70383,45.43991
37.15800,3.09644,899.53998,-0.14153,7.73708,45.47679
37.25800,3.10481,900.01291,-0.14153,7.77056,45.50070
37.35800,3.11312,900.29072,-0.14153,7.80380,45.51474
37.45800,3.12149,900.12541,-0.14153,7.83729,45.50639
37.55800,3.12986,899.75754,-0.14153,7.87077,45.48779
37.65800,3.13817,900.84355,-0.14153,7.90401,45.54269
37.75800,3.14648,900.40797,-0.14153,7.93725,45.52067
37.85800,3.15485,901.53730,-0.14153,7.97074,45.57776
37.95800,3.16316,901.36575,-0.14153,8.00398,45.56909
38.05800,3.17153,901.30121,-0.14153,8.03746,45.56583
38.15800,3.17984,901.57343,-0.14153,8.07070,45.57959
38.25800,3.18815,901.37441,-0.14153,8.10395,45.56953
38.35800,3.19653,901.33240,-0.14153,8.13743,45.56741
38.45800,3.20484,901.77888,-0.14153,8.17067,45.58998
38.55800,3.21315,901.28919,-0.14153,8.20391,45.56522
38.65800,3.22152,901.49716,-0.14153,8.23740,45.57574
38.75800,3.22983,901.49343,-0.14153,8.27064,45.57555
38.85800,3.23814,901.97539,-0.14153,8.30388,45.59991
38.95800,3.24657,901.64756,-0.14153,8.33760,45.58334
39.05800,3.25482,901.57995,-0.14153,8.37061,45.57992
39.15800,3.26313,902.31067,-0.14153,8.40385,45.61686
39.25800,3.27156,901.76482,-0.14153,8.43757,45.58927
39.35800,3.27975,902.62955,-0.14153,8.47034,45.63298
39.45800,3.28806,902.41935,-0.14153,8.50358,45.62236
39.55800,3.29649,901.56365,-0.14153,8.53730,45.57910
39.65800,3.30480,901.90470,-0.14153,8.57054,45.59634
39.75800,3.31311,901.69189,-0.14153,8.60379,45.58558
39.85800,3.32155,901.40691,-0.14153,8.63751,45.57117
39.95800,3.32980,901.69897,-0.14153,8.67051,45.58594
40.05800,3.33823,901.60938,-0.14153,8.70423,45.58141
40.15800,3.34660,901.51066,-0.14153,8.73771,45.57642
40.25800,3.35485,901.11662,-0.14153,8.77072,45.55650
40.35800,3.36322,901.32924,-0.14153,8.80420,45.56725
40.45800,3.37153,901.37227,-0.14153,8.83744,45.56942
40.55800,3.37978,901.10870,-0.14153,8.87045,45.55610
40.65800,3.38821,901.44612,-0.14153,8.90417,45.57315
40.75800,3.39646,900.14692,-0.14153,8.93717,45.50747
40.85800,3.40477,900.48723,-0.14153,8.97042,45.52468
40.95800,3.41326,900.21361,-0.14153,9.00438,45.51085
41.05800,3.42157,900.39512,-0.14153,9.03762,45.52002
41.15800,3.42982,899.88941,-0.14153,9.07062,45.49445
41.25800,3.43831,899.68164,-0.14153,9.10458,45.48395
41.35800,3.44651,899.66198,-0.14153,9.13735,45.48296
41.45800,3.45476,899.70604,-0.14153,9.17035,45.48518
41.55800,3.46325,898.93090,-0.14153,9.20431,45.44600
41.65800,3.47138,899.49770,-0.14153,9.23684,45.47465
41.75800,3.47975,898.75469,-0.14153,9.27032,45.43709
41.85800,3.48824,898.86272,-0.14153,9.30428,45.44255
41.95800,3.49643,897.69624,-0.14153,9.33704,45.38358
42.05800,3.50480,898.12335,-0.14153,9.37053,45.40517
42.15800,3.51323,897.86351,-0.14153,9.40425,45.39203
42.25800,3.52148,897.60218,-0.14153,9.43725,45.37882
42.35800,3.52985,896.49418,-0.14153,9.47073,45.32281
42.45800,3.53822,896.95482,-0.14153,9.50422,45.34610
42.55800,3.54647,896.20622,-0.14153,9.53722,45.30825
42.65800,3.55484,896.55966,-0.14153,9.57070,45.32612
42.75800,3.56315,895.99434,-0.14153,9.60395,45.29754
42.85800,3.57147,895.53781,-0.14154,9.63719,45.27446
42.95800,3.57996,895.16789,-0.14153,9.67115,45.25576
43.05800,3.58815,894.98311,-0.14153,9.70391,45.24641
43.15800,3.59640,894.46809,-0.14153,9.73692,45.22038
43.25800,3.60489,894.66544,-0.14154,9.77088,45.23035
43.35800,3.61314,893.84774,-0.14153,9.80388,45.18901
43.45800,3.62145,894.27242,-0.14153,9.83712,45.21048
43.55800,3.62994,892.73248,-0.14153,9.87108,45.13263
43.65800,3.63813,892.89779,-0.14154,9.90385,45.14099
43.75800,3.64644,892.66105,-0.14153,9.93709,45.12902
43.85800,3.65493,892.18356,-0.14154,9.97105,45.10488
43.95800,3.66312,891.26332,-0.14154,10.00382,45.05836
44.05800,3.67143,891.78858,-0.14153,10.03706,45.08491
44.15800,3.67992,890.95850,-0.14153,10.07102,45.04295
44.25800,3.68811,891.00087,-0.14154,10.10379,45.04509
44.35800,3.69655,889.85935,-0.14154,10.13751,44.98738
44.45800,3.70486,889.47620,-0.14154,10.17075,44.96801
44.55800,3.71323,889.19476,-0.14153,10.20423,44.95378
44.65800,3.72154,888.56304,-0.14154,10.23747,44.92184
44.75800,3.72979,889.02973,-0.14154,10.27048,44.94544
44.85800,3.73810,888.28728,-0.14154,10.30372,44.90790
44.95800,3.74647,887.06389,-0.14154,10.33720,44.84605
45.05800,3.75484,887.04703,-0.14154,10.37069,44.84520
45.15800,3.76309,887.04079,-0.14153,10.40369,44.84489
45.25800,3.77152,886.44708,-0.14154,10.43741,44.81487
45.35800,3.77983,885.49862,-0.14154,10.47065,44.76692
45.45800,3.78814,885.30751,-0.14154,10.50390,44.75726
45.55800,3.79657,884.63277,-0.14153,10.53762,44.72314
45.65800,3.80476,883.99919,-0.14154,10.57038,44.69112
45.75800,3.81307,884.20110,-0.14154,10.60362,44.70132
45.85800,3.82151,883.34437,-0.14154,10.63735,44.65801
45.95800,3.82976,883.02707,-0.14154,10.67035,44.64197
46.05800,3.83813,883.03732,-0.14153,10.70383,44.64249
46.15800,3.84650,881.51898,-0.14154,10.73731,44.56573
46.25800,3.85481,881.83517,-0.14154,10.77056,44.58171
46.35800,3.86318,881.30180,-0.14154,10.80404,44.55474
46.45800,3.87155,880.64233,-0.14154,10.83752,44.52141
46.55800,3.87980,879.92232,-0.14154,10.87053,44.48501
46.65800,3.88817,879.66025,-0.14154,10.90401,44.47176
46.75800,3.89648,879.67878,-0.14154,10.93725,44.47269
46.85800,3.90485,878.47281,-0.14154,10.97073,44.41172
46.95800,3.91316,878.39160,-0.14154,11.00397,44.40762
47.05800,3.92147,877.66331,-0.14154,11.03722,44.37080
47.15800,3.92978,877.22307,-0.14154,11.07046,44.34855
47.25800,3.93815,876.49981,-0.14154,11.10394,44.31198
47.35800,3.94647,876.25021,-0.14154,11.13719,44.29936
47.45800,3.95478,875.27018,-0.14154,11.17043,44.24981
47.55800,3.96321,874.44494,-0.14154,11.20415,44.20810
47.65800,3.97146,874.27692,-0.14154,11.23715,44.19960
47.75800,3.97977,874.32293,-0.14154,11.27040,44.20193
47.85800,3.98820,873.38258,-0.14154,11.30412,44.15438
47.95800,3.99645,872.53321,-0.14154,11.33712,44.11145
48.05800,4.00482,872.36520,-0.14154,11.37061,44.10295
48.15800,4.01319,871.63625,-0.14154,11.40409,44.06610
48.25800,4.02138,871.79402,-0.14154,11.43685,44.07407
48.35800,4.02975,870.72188,-0.14154,11.47033,44.01987
48.45800,4.03824,870.50973,-0.14154,11.50429,44.00915
48.55800,4.04655,869.74939,-0.14154,11.53754,43.97071
48.65800,4.05492,869.02026,-0.14154,11.57102,43.93385
48.75800,4.06329,868.63795,-0.14154,11.60450,43.91452
48.85800,4.07148,867.81075,-0.14154,11.63726,43.87270
48.95800,4.07986,868.07143,-0.14154,11.67075,43.88588
49.05800,4.08817,867.29228,-0.14154,11.70399,43.84649
49.15800,4.09642,867.17522,-0.14154,11.73700,43.84057
49.25800,4.10485,866.73703,-0.14154,11.77072,43.81842
49.35800,4.11322,866.19537,-0.14154,11.80420,43.79103
49.45800,4.12147,864.91499,-0.14154,11.83720,43.72630
49.55800,4.12990,865.05478,-0.14154,11.87092,43.73337
49.65800,4.13815,864.19638,-0.14154,11.90393,43.68997
49.75800,4.14646,863.57556,-0.14154,11.93717,43.65858
49.85800,4.15495,863.07321,-0.14154,11.97113,43.63319
49.95800,4.16314,862.23884,-0.14154,12.00389,43.59101
50.05800,4.17145,862.03832,-0.14154,12.03714,43.58087
50.15800,4.17988,861.09033,-0.14154,12.07086,43.53294
50.25800,4.18813,860.82378,-0.14154,12.10386,43.51947
50.35800,4.19644,859.52021,-0.14154,12.13711,43.45356
50.45800,4.20494,860.14122,-0.14154,12.17107,43.48496
50.55800,4.21313,859.59565,-0.14154,12.20383,43.45738
50.65800,4.22144,859.23756,-0.14154,12.23707,43.43927
50.75800,4.22987,858.02069,-0.14154,12.27080,43.37775
50.85800,4.23818,857.48918,-0.14154,12.30404,43.35089
50.95800,4.24655,857.57654,-0.14154,12.33752,43.35530
51.05800,4.25486,856.44396,-0.14154,12.37076,43.29804
51.15800,4.26311,855.96805,-0.14154,12.40377,43.27398
51.25800,4.27148,854.81480,-0.14154,12.43725,43.21568
51.35800,4.27985,854.52050,-0.14154,12.47073,43.20080
51.45800,4.28816,854.11901,-0.14154,12.50397,43.18050
51.55800,4.29653,853.64198,-0.14154,12.53746,43.15639
51.65800,4.30478,853.50377,-0.14154,12.57046,43.14940
51.75800,4.31315,852.20905,-0.14154,12.60394,43.08395
51.85800,4.32152,852.26456,-0.14154,12.63742,43.08675
51.95800,4.32984,851.48606,-0.14154,12.67067,43.04739
52.05800,4.33809,850.93109,-0.14154,12.70367,43.01934
52.15800,4.34646,850.08238,-0.14154,12.73715,42.97643
52.25800,4.35471,849.61643,-0.14154,12.77016,42.95287
52.35800,4.36308,849.19091,-0.14154,12.80364,42.93136
52.45800,4.37151,848.11216,-0.14154,12.83736,42.87682
52.55800,4.37982,848.06923,-0.14154,12.87060,42.87465
52.65800,4.38807,847.94452,-0.14154,12.90361,42.86835
52.75800,4.39644,846.34684,-0.14154,12.93709,42.78758
52.85800,4.40481,846.19578,-0.14154,12.97057,42.77994
52.95800,4.41318,845.27107,-0.14154,13.00405,42.73319
53.05800,4.42149,845.19479,-0.14154,13.03730,42.72934
53.15800,4.42986,844.20210,-0.14154,13.07078,42.67915
53.25800,4.43817,843.29965,-0.14154,13.10402,42.63353
53.35800,4.44648,843.22467,-0.14154,13.13726,42.62973
53.45800,4.45486,842.24446,-0.14154,13.17075,42.58018
53.55800,4.46317,841.51113,-0.14154,13.20399,42.54311
53.65800,4.47148,841.04622,-0.14154,13.23723,42.51960
53.75800,4.47985,840.50111,-0.14154,13.27071,42.49204
53.85800,4.48822,839.87350,-0.14154,13.30420,42.46031
53.95800,4.49653,838.90595,-0.14154,13.33744,42.41140
54.05800,4.50490,838.59693,-0.14154,13.37092,42.39577
54.15800,4.51327,838.17123,-0.14154,13.40440,42.37426
54.25800,4.52152,837.20041,-0.14154,13.43741,42.32518
54.35800,4.52983,836.42947,-0.14154,13.47065,42.28620
54.45800,4.53826,836.21014,-0.14154,13.50437,42.27511
54.55800,4.54639,835.18783,-0.14154,13.53690,42.22343
54.65800,4.55476,834.88952,-0.14154,13.57038,42.20835
54.75800,4.56319,833.96705,-0.14154,13.60410,42.16171
54.85800,4.57144,833.17831,-0.14154,13.63710,42.12183
54.95800,4.57988,832.97603,-0.14154,13.67083,42.11161
55.05800,4.58819,831.81057,-0.14154,13.70407,42.05269
55.15800,4.59650,830.95841,-0.14154,13.73731,42.00961
55.25800,4.60487,830.63729,-0.14154,13.77079,41.99337
55.35800,4.61318,829.63360,-0.14154,13.80404,41.94263
55.45800,4.62143,829.36930,-0.14154,13.83704,41.92927
55.55800,4.62980,828.24519,-0.14154,13.87052,41.87244
55.65800,4.63817,827.77767,-0.14154,13.90401,41.84880
55.75800,4.64648,827.56532,-0.14154,13.93725,41.83807
55.85800,4.65491,826.34939,-0.14154,13.97097,41.77660
55.95800,4.66322,825.16596,-0.14154,14.00421,41.71677
56.05800,4.67153,824.71920,-0.14154,14.03746,41.69418
56.15800,4.67990,823.95161,-0.14154,14.07094,41.65537
56.25800,4.68815,823.55505,-0.14154,14.10394,41.63533
56.35800,4.69652,821.26232,-0.14154,14.13742,41.51941
56.45800,4.70489,821.93799,-0.14154,14.17091,41.55357
56.55800,4.71315,820.19689,-0.14154,14.20391,41.46555
56.65800,4.72152,819.74976,-0.14154,14.23739,41.44295
56.75800,4.72989,819.42668,-0.14154,14.27087,41.42661
56.85800,4.73808,818.22323,-0.14154,14.30364,41.36577
56.95800,4.74645,817.60054,-0.14154,14.33712,41.33429
57.05800,4.75482,816.42764,-0.14154,14.37060,41.27499
57.15800,4.76313,815.60183,-0.14154,14.40384,41.23325
57.25800,4.77150,814.69957,-0.14154,14.43733,41.18763
57.35800,4.77987,814.40127,-0.14154,14.47081,41.17255
57.45800,4.78818,812.89308,-0.14154,14.50405,41.09630
57.55800,4.79649,812.33401,-0.14154,14.53730,41.06804
57.65800,4.80474,810.91085,-0.14154,14.57030,40.99609
57.75800,4.81311,809.37473,-0.14154,14.60378,40.91843
57.85800,4.82142,808.60155,-0.14155,14.63702,40.87934
57.95800,4.82980,808.37579,-0.14154,14.67051,40.86793
58.05800,4.83811,806.76042,-0.14154,14.70375,40.78626
58.15800,4.84648,805.64981,-0.14154,14.73723,40.73011
58.25800,4.85485,804.96334,-0.14154,14.77071,40.69541
58.35800,4.86322,804.12738,-0.14155,14.80420,40.65315
58.45800,4.87159,803.17333,-0.14154,14.83768,40.60492
58.55800,4.87978,802.02390,-0.14154,14.87044,40.54680
58.65800,4.88815,801.26887,-0.14154,14.90392,40.50863
58.75800,4.89652,799.60842,-0.14154,14.93741,40.42469
58.85800,4.90477,799.43761,-0.14154,14.97041,40.41605
58.95800,4.91314,797.40565,-0.14154,15.00389,40.31333
59.05800,4.92145,796.48653,-0.14154,15.03714,40.26686
59.15800,4.92976,795.51740,-0.14154,15.07038,40.21786
59.25800,4.93819,794.02784,-0.14154,15.10410,40.14256
59.35800,4.94656,792.56538,-0.14154,15.13758,40.06862
59.45800,4.95487,791.42023,-0.14154,15.17082,40.01073
59.55800,4.96313,790.08546,-0.14155,15.20383,39.94325
59.65800,4.97150,789.21448,-0.14154,15.23731,39.89922
59.75800,4.97981,788.06458,-0.14154,15.27055,39.84108
59.85800,4.98812,787.03370,-0.14154,15.30380,39.78897
59.95800,4.99649,785.63681,-0.14155,15.33728,39.71835
60.05800,5.00486,783.86161,-0.14154,15.37076,39.62860
60.15800,5.01317,782.65164,-0.14154,15.40400,39.56743
60.25800,5.02148,781.67580,-0.14154,15.43725,39.51809
60.35800,5.02985,780.48920,-0.14154,15.47073,39.45810
60.45800,5.03822,779.29362,-0.14154,15.50421,39.39766
60.55800,5.04647,777.85845,-0.14155,15.53721,39.32510
60.65800,5.05484,776.20284,-0.14154,15.57070,39.24141
60.75800,5.06315,775.68595,-0.14154,15.60394,39.21527
60.85800,5.07146,773.45921,-0.14154,15.63718,39.10270
60.95800,5.07978,772.70358,-0.14154,15.67043,39.06450
61.05800,5.08815,771.54711,-0.14154,15.70391,39.00603
61.15800,5.09646,769.65275,-0.14155,15.73715,38.91026
61.25800,5.10483,767.99714,-0.14154,15.77063,38.82656
61.35800,5.11326,766.37613,-0.14154,15.80435,38.74461
61.45800,5.12151,765.26166,-0.14154,15.83736,38.68827
61.55800,5.12988,763.50314,-0.14154,15.87084,38.59937
61.65800,5.13825,762.15509,-0.14154,15.90432,38.53121
61.75800,5.14650,760.47271,-0.14154,15.93733,38.44616
61.85800,5.15487,759.45137,-0.14155,15.97081,38.39452
61.95800,5.16312,758.23772,-0.14155,16.00381,38.33317
62.05800,5.17143,756.42536,-0.14154,16.03705,38.24154
62.15800,5.17980,754.88193,-0.14154,16.07054,38.16351
62.25800,5.18817,753.56518,-0.14155,16.10402,38.09694
62.35800,5.19648,751.89574,-0.14154,16.13726,38.01255
62.45800,5.20479,750.78970,-0.14154,16.17050,37.95663
62.55800,5.21316,749.32775,-0.14154,16.20398,37.88272
62.65800,5.22148,747.62343,-0.14155,16.23723,37.79655
62.75800,5.22985,745.34081,-0.14154,16.27071,37.68116
62.85800,5.23816,744.47463,-0.14154,16.30395,37.63737
62.95800,5.24647,743.18731,-0.14154,16.33720,37.57228
63.05800,5.25484,741.90679,-0.14154,16.37068,37.50755
63.15800,5.26309,739.86873,-0.14155,16.40368,37.40451
63.25800,5.27140,738.88656,-0.14154,16.43693,37.35486
63.35800,5.27983,737.26540,-0.14154,16.47065,37.27290
63.45800,5.28814,735.81091,-0.14154,16.50389,37.19937
63.55800,5.29645,734.32159,-0.14154,16.53713,37.12407
63.65800,5.30494,733.15725,-0.14154,16.57109,37.06521
63.75800,5.31319,731.27504,-0.14154,16.60410,36.97005
63.85800,5.32150,729.73929,-0.14154,16.63734,36.89241
63.95800,5.32987,728.33262,-0.14154,16.67082,36.82130
64.05801,5.33813,727.55674,-0.14154,16.70383,36.78207
64.15800,5.34644,725.71849,-0.14154,16.73707,36.68914
64.25800,5.35487,724.13879,-0.14154,16.77079,36.60928
64.35800,5.36312,723.50116,-0.14154,16.80379,36.57704
64.45800,5.37149,722.14748,-0.14155,16.83728,36.50860
64.55801,5.37986,720.56218,-0.14154,16.87076,36.42846
64.65800,5.38817,719.01241,-0.14154,16.90400,36.35011
64.75800,5.39654,717.90013,-0.14155,16.93749,36.29388
64.85800,5.40491,716.61957,-0.14155,16.97097,36.22914
64.95800,5.41310,715.16922,-0.14154,17.00373,36.15582
65.05801,5.42153,713.95542,-0.14155,17.03745,36.09445
65.15800,5.42978,712.50829,-0.14154,17.07046,36.02129
65.25800,5.43809,711.84286,-0.14155,17.10370,35.98765
65.35800,5.44652,710.75265,-0.14155,17.13742,35.93253
65.45800,5.45477,709.35711,-0.14155,17.17043,35.86198
65.55801,5.46309,708.05829,-0.14155,17.20367,35.79631
65.65801,5.47158,706.90857,-0.14154,17.23763,35.73819
65.75800,5.47983,705.73268,-0.14155,17.27063,35.67875
65.85800,5.48814,705.20495,-0.14154,17.30388,35.65207
65.95800,5.49651,704.12438,-0.14155,17.33736,35.59743
66.05801,5.50476,702.61587,-0.14155,17.37036,35.52117
66.15801,5.51313,701.36003,-0.14154,17.40384,35.45768
66.25800,5.52144,700.96673,-0.14155,17.43708,35.43780
66.35800,5.52981,698.77747,-0.14155,17.47057,35.32712
66.45800,5.53812,698.43479,-0.14155,17.50381,35.30980
66.55801,5.54649,698.33621,-0.14155,17.53729,35.30481
66.65801,5.55480,696.82128,-0.14154,17.57054,35.22822
66.75800,5.56317,695.49959,-0.14154,17.60402,35.16140
66.85800,5.57154,695.09503,-0.14154,17.63750,35.14095
66.95800,5.57985,694.19360,-0.14154,17.67074,35.09538
67.05801,5.58822,692.83764,-0.14155,17.70422,35.02682
67.15801,5.59654,692.40853,-0.14154,17.73747,35.00513
67.25800,5.60485,691.52266,-0.14155,17.77071,34.96035
67.35800,5.61316,690.83353,-0.14155,17.80395,34.92551
67.45800,5.62147,689.90476,-0.14154,17.83720,34.87856
67.55801,5.62978,689.42686,-0.14155,17.87044,34.85439
67.65801,5.63821,688.60436,-0.14154,17.90416,34.81281
67.75800,5.64646,687.74950,-0.14155,17.93717,34.76959
67.85800,5.65483,687.50293,-0.14154,17.97065,34.75713
67.95800,5.66320,687.29087,-0.14155,18.00413,34.74641
68.05801,5.67151,686.02986,-0.14155,18.03737,34.68266
68.15801,5.67982,685.16773,-0.14154,18.07062,34.63907
68.25800,5.68813,684.38146,-0.14155,18.10386,34.59932
68.35800,5.69644,684.26025,-0.14154,18.13710,34.59319
68.45800,5.70475,682.90578,-0.14154,18.17034,34.52472
68.55801,5.71312,682.86490,-0.14155,18.20383,34.52265
68.65801,5.72144,682.71328,-0.14155,18.23707,34.51498
68.75800,5.72981,682.20692,-0.14154,18.27055,34.48938
68.85800,5.73818,681.26982,-0.14154,18.30403,34.44201
68.95800,5.74649,680.81920,-0.14154,18.33728,34.41923
69.05801,5.75486,680.70116,-0.14154,18.37076,34.41326
69.15801,5.76317,679.69109,-0.14155,18.40400,34.36219
69.25800,5.77142,679.41328,-0.14155,18.43701,34.34815
69.35800,5.77985,678.71027,-0.14155,18.47073,34.31261
69.45800,5.78810,678.63599,-0.14155,18.50373,34.30885
69.55801,5.79647,678.26291,-0.14155,18.53721,34.28999
69.65801,5.80490,678.12544,-0.14154,18.57093,34.28304
69.75800,5.81321,677.44418,-0.14154,18.60418,34.24860
69.85800,5.82146,676.98415,-0.14155,18.63718,34.22535
69.95800,5.82995,676.74471,-0.14155,18.67114,34.21324
70.05801,5.83815,676.24394,-0.14154,18.70391,34.18792
70.15801,5.84652,676.05176,-0.14155,18.73739,34.17821
70.25800,5.85495,675.45474,-0.14155,18.77111,34.14802
70.35800,5.86314,675.32165,-0.14155,18.80387,34.14130
70.45800,5.87145,674.98931,-0.14155,18.83712,34.12449
70.55801,5.87988,675.38237,-0.14155,18.87084,34.14436
70.65801,5.88813,674.36146,-0.14154,18.90384,34.09275
70.75800,5.89650,675.06856,-0.14155,18.93732,34.12850
70.85800,5.90487,673.42198,-0.14155,18.97081,34.04526
70.95800,5.91312,674.23843,-0.14154,19.00381,34.08653
71.05801,5.92149,674.52271,-0.14155,19.03729,34.10091
71.15801,5.92986,673.48722,-0.14155,19.07077,34.04855
71.25800,5.93811,673.41444,-0.14154,19.10378,34.04488
71.35800,5.94660,673.25924,-0.14154,19.13774,34.03703
71.45800,5.95479,673.00331,-0.14155,19.17050,34.02409
71.55801,5.96310,672.90235,-0.14154,19.20374,34.01899
71.65801,5.97154,673.11018,-0.14155,19.23747,34.02949
71.75800,5.97979,672.73374,-0.14154,19.27047,34.01046
71.85800,5.98816,672.38435,-0.14154,19.30395,33.99280
71.95800,5.99653,672.41057,-0.14154,19.33743,33.99413
72.05801,6.00478,672.27990,-0.14155,19.37044,33.98752
72.15801,6.01315,671.59538,-0.14155,19.40392,33.95291
72.25800,6.02164,671.40893,-0.14155,19.43788,33.94349
72.35800,6.02983,671.85410,-0.14154,19.47065,33.96599
72.45800,6.03808,671.44865,-0.14155,19.50365,33.94549
72.55801,6.04651,671.48670,-0.14154,19.53737,33.94742
72.65801,6.05476,671.36777,-0.14155,19.57037,33.94141
72.75800,6.06313,671.62667,-0.14154,19.60386,33.95449
72.85800,6.07150,671.12171,-0.14155,19.63734,33.92897
72.95800,6.07975,671.67911,-0.14155,19.67034,33.95715
73.05801,6.08812,671.35119,-0.14155,19.70383,33.94057
73.15801,6.09650,670.88651,-0.14155,19.73731,33.91707
73.25800,6.10487,670.87244,-0.14154,19.77079,33.91636
73.35800,6.11324,670.57065,-0.14155,19.80427,33.90110
73.45800,6.12149,670.68092,-0.14155,19.83728,33.90668
73.55801,6.12980,671.21824,-0.14154,19.87052,33.93385
73.65801,6.13811,670.22447,-0.14155,19.90376,33.88361
73.75800,6.14642,670.59211,-0.14155,19.93700,33.90219
73.85800,6.15473,670.86560,-0.14155,19.97025,33.91602
73.95800,6.16316,670.49628,-0.14155,20.00397,33.89735
74.05801,6.17141,670.30699,-0.14155,20.03697,33.88778
74.15801,6.17978,670.01204,-0.14154,20.07045,33.87286
74.25800,6.18827,670.91682,-0.14154,20.10442,33.91861
74.35800,6.19652,670.69661,-0.14155,20.13742,33.90747
74.45800,6.20489,670.05758,-0.14155,20.17090,33.87517
74.55801,6.21326,670.36897,-0.14155,20.20438,33.89091
74.65801,6.22146,669.96515,-0.14155,20.23715,33.87049
74.75800,6.22977,670.14815,-0.14154,20.27039,33.87975
74.85800,6.23820,670.20087,-0.14155,20.30411,33.88241
74.95800,6.24645,670.77633,-0.14155,20.33712,33.91150
75.05801,6.25482,670.16105,-0.14155,20.37060,33.88040
75.15801,6.26319,669.99234,-0.14155,20.40408,33.87187
75.25800,6.27150,669.76896,-0.14155,20.43732,33.86058
75.35800,6.27981,670.01716,-0.14155,20.47057,33.87312
75.45800,6.28818,669.91341,-0.14155,20.50405,33.86788
75.55801,6.29655,669.88706,-0.14155,20.53753,33.86655
75.65801,6.30486,670.52520,-0.14155,20.57077,33.89881
75.75800,6.31317,669.84389,-0.14155,20.60402,33.86436
75.85800,6.32136,669.98708,-0.14155,20.63678,33.87160
75.95800,6.32979,669.92007,-0.14155,20.67050,33.86821
76.05801,6.33810,670.10894,-0.14155,20.70374,33.87777
76.15801,6.34642,670.06187,-0.14154,20.73699,33.87539
76.25800,6.35485,669.78065,-0.14155,20.77071,33.86117
76.35800,6.36310,669.98811,-0.14155,20.80371,33.87165
76.45800,6.37141,670.35952,-0.14154,20.83695,33.89043
76.55801,6.37996,670.06331,-0.14155,20.87115,33.87546
76.65801,6.38821,669.98927,-0.14155,20.90416,33.87171
76.75800,6.39652,669.39183,-0.14155,20.93740,33.84151
76.85800,6.40501,669.99155,-0.14155,20.97136,33.87183
76.95800,6.41314,670.01544,-0.14155,21.00389,33.87304
77.05801,6.42145,669.77027,-0.14155,21.03713,33.86064
77.15801,6.42994,669.67495,-0.14155,21.07109,33.85582
77.25800,6.43813,669.79406,-0.14155,21.10386,33.86184
77.35800,6.44644,669.86168,-0.14154,21.13710,33.86526
77.45800,6.45487,669.64077,-0.14155,21.17082,33.85410
77.55801,6.46318,669.99365,-0.14155,21.20406,33.87193
77.65801,6.47155,669.76249,-0.14155,21.23754,33.86025
77.75800,6.47998,670.08599,-0.14155,21.27126,33.87660
77.85800,6.48812,670.01809,-0.14155,21.30379,33.87317
77.95800,6.49661,669.85297,-0.14155,21.33775,33.86482
78.05801,6.50486,669.75611,-0.14155,21.37076,33.85992
78.15801,6.51305,670.02224,-0.14154,21.40352,33.87338
78.25800,6.52154,669.63597,-0.14155,21.43748,33.85385
78.35800,6.52979,669.56417,-0.14155,21.47048,33.85022
78.45800,6.53810,669.61013,-0.14155,21.50373,33.85255
78.55801,6.54665,669.61404,-0.14155,21.53793,33.85275
78.65801,6.55484,670.04464,-0.14155,21.57069,33.87451
78.75800,6.56315,669.75718,-0.14155,21.60394,33.85998
78.85800,6.57158,669.52603,-0.14155,21.63766,33.84829
78.95800,6.57971,669.31969,-0.14155,21.67018,33.83786
79.05801,6.58802,669.51350,-0.14155,21.70342,33.84766
79.15801,6.59651,669.29371,-0.14155,21.73738,33.83655
79.25800,6.60477,669.88822,-0.14155,21.77039,33.86660
79.35800,6.61308,669.46787,-0.14155,21.80363,33.84535
79.45800,6.62157,668.96249,-0.14155,21.83759,33.81981
79.55801,6.62976,669.17078,-0.14155,21.87036,33.83033
79.65801,6.63813,669.33041,-0.14155,21.90384,33.83841
79.75800,6.64656,668.85804,-0.14155,21.93756,33.81452
79.85800,6.65475,668.71089,-0.14155,21.97032,33.80708
79.95800,6.66312,668.79187,-0.14155,22.00381,33.81118
80.05801,6.67155,668.87252,-0.14154,22.03753,33.81525
80.15801,6.67980,668.90833,-0.14155,22.07053,33.81707
80.25800,6.68817,668.23270,-0.14155,22.10401,33.78291
80.35800,6.69648,668.66539,-0.14155,22.13726,33.80478
80.45800,6.70479,668.34386,-0.14155,22.17050,33.78853
80.55801,6.71322,668.63727,-0.14155,22.20422,33.80336
80.65801,6.72147,667.74366,-0.14155,22.23722,33.75819
80.75800,6.72979,667.96821,-0.14155,22.27047,33.76954
80.85800,6.73822,667.62161,-0.14155,22.30419,33.75201
80.95800,6.74647,668.49012,-0.14155,22.33719,33.79592
81.05801,6.75478,667.24056,-0.14155,22.37044,33.73275
81.15801,6.76315,667.52159,-0.14155,22.40392,33.74696
81.25800,6.77146,667.53915,-0.14155,22.43716,33.74784
81.35800,6.77977,667.50548,-0.14155,22.47041,33.74614
81.45800,6.78814,666.65197,-0.14155,22.50389,33.70300
81.55801,6.79639,667.01635,-0.14155,22.53689,33.72142
81.65801,6.80476,666.23650,-0.14155,22.57037,33.68199
81.75800,6.81319,666.46626,-0.14155,22.60409,33.69361
81.85800,6.82150,665.89843,-0.14155,22.63734,33.66490
81.95800,6.82987,665.49764,-0.14155,22.67082,33.64464
82.05801,6.83824,665.26243,-0.14155,22.70430,33.63274
82.15801,6.84649,665.04758,-0.14155,22.73730,33.62188
82.25800,6.85486,664.78942,-0.14155,22.77078,33.60883
82.35800,6.86312,664.36855,-0.14155,22.80379,33.58755
82.45800,6.87143,664.42201,-0.14155,22.83703,33.59026
82.55801,6.87980,663.69451,-0.14155,22.87052,33.55348
82.65801,6.88817,663.27285,-0.14155,22.90400,33.53216
82.75800,6.89648,662.96365,-0.14155,22.93724,33.51653
82.85800,6.90491,661.99019,-0.14155,22.97096,33.46732
82.95800,6.91322,661.64630,-0.14155,23.00420,33.44993
83.05801,6.92153,661.73216,-0.14155,23.03745,33.45427
83.15801,6.92996,660.75879,-0.14155,23.07117,33.40506
83.25800,6.93815,660.47292,-0.14155,23.10393,33.39061
83.35800,6.94646,659.30020,-0.14155,23.13718,33.33132
83.45800,6.95483,658.73000,-0.14155,23.17066,33.30249
83.55801,6.96308,658.09293,-0.14155,23.20366,33.27029
83.65801,6.97145,657.07858,-0.14155,23.23714,33.21901
83.75800,6.97982,655.92197,-0.14155,23.27063,33.16053
83.85800,6.98808,654.29257,-0.14155,23.30363,33.07816
83.95800,6.99651,652.08459,-0.14155,23.33735,32.96653
84.05801,7.00494,647.57345,-0.14155,23.37107,32.73847
84.15801,7.01319,640.50504,-0.14155,23.40408,32.38112
84.25800,7.02156,623.85960,-0.14155,23.43756,31.53960
84.35800,7.02987,605.40065,-0.14155,23.47080,30.60640
84.45801,7.03812,587.21276,-0.14155,23.50381,29.68690
84.55801,7.04649,569.70422,-0.14155,23.53729,28.80174
84.65801,7.05480,549.76544,-0.14155,23.57053,27.79373
84.75800,7.06311,530.74379,-0.14155,23.60377,26.83207
84.85800,7.07154,511.46001,-0.14155,23.63749,25.85717
84.95801,7.07985,491.54251,-0.14155,23.67074,24.85023
85.05801,7.08816,474.07136,-0.14155,23.70398,23.96696
85.15801,7.09665,456.85442,-0.14155,23.73794,23.09655
85.25800,7.10485,441.62734,-0.14155,23.77071,22.32674
85.35800,7.11316,428.66669,-0.14155,23.80395,21.67150
85.45801,7.12159,415.49820,-0.14155,23.83767,21.00576
85.55801,7.12978,403.63092,-0.14154,23.87044,20.40581
85.65801,7.13815,392.43526,-0.14155,23.90392,19.83980
85.75800,7.14658,381.05836,-0.14155,23.93764,19.26464
85.85800,7.15483,370.56094,-0.14155,23.97064,18.73393
85.95801,7.16320,360.37862,-0.14155,24.00413,18.21916
86.05801,7.17157,348.74293,-0.14155,24.03761,17.63091
86.15801,7.17982,335.51496,-0.14155,24.07061,16.96216
86.25800,7.18813,315.54163,-0.14155,24.10385,15.95240
86.35800,7.19650,139.05275,-0.14155,24.13734,7.02990
86.38600,7.19883,8.18375,-0.14155,24.14666,0.41373