File: Manufatura Aditiva/Classificação Direção/Ensaios/Ensaios FDM/Tracao_OLABI_23_05_2018_FDM_YX2.is_metal_RawData/Specimen_RawData_4.csv
Time,Extension,Load,Strain 1,Tensile strain,Tensile stress
(sec),(mm),(N),(mm/mm),(%),(MPa)
0.00000,0.00006,28.45084,0.00073,0.07342,1.44511
0.20000,0.01393,33.64930,0.00088,0.08834,1.70916
0.40000,0.03265,42.71235,0.00113,0.11314,2.16950
0.60000,0.04986,50.26971,0.00136,0.13639,2.55337
0.80000,0.06667,57.51656,0.00159,0.15856,2.92146
1.00000,0.08329,64.76440,0.00182,0.18204,3.28960
1.20000,0.10003,71.84897,0.00205,0.20492,3.64945
1.40000,0.11671,79.51472,0.00229,0.22869,4.03882
1.60000,0.13339,86.14594,0.00252,0.25219,4.37564
1.80000,0.14995,93.19024,0.00276,0.27566,4.73345
2.00000,0.16663,100.48134,0.00300,0.29960,5.10379
2.20000,0.18331,108.36245,0.00324,0.32434,5.50410
2.40000,0.20000,115.18948,0.00349,0.34851,5.85086
2.60000,0.21668,122.19327,0.00373,0.37316,6.20661
2.80000,0.23330,129.18407,0.00398,0.39757,6.56170
3.00000,0.24998,135.87282,0.00422,0.42228,6.90144
3.20000,0.26672,143.45503,0.00447,0.44699,7.28657
3.40000,0.28340,150.41004,0.00472,0.47198,7.63984
3.60000,0.30002,156.70675,0.00497,0.49733,7.95967
3.80000,0.31670,163.28945,0.00522,0.52206,8.29403
4.00000,0.33333,170.72237,0.00547,0.54746,8.67157
4.20000,0.35001,177.68268,0.00572,0.57239,9.02511
4.40000,0.36663,184.87163,0.00598,0.59793,9.39026
4.60000,0.38331,191.83909,0.00624,0.62410,9.74416
4.80000,0.40005,198.20256,0.00650,0.64959,10.06738
5.00000,0.41661,205.06121,0.00675,0.67501,10.41575
5.20000,0.43329,212.14837,0.00701,0.70093,10.77573
5.40000,0.45004,219.13054,0.00727,0.72721,11.13038
5.60000,0.46666,225.51678,0.00751,0.75090,11.45476
5.80000,0.48328,231.10742,0.00776,0.77583,11.73873
6.00000,0.50002,238.78766,0.00802,0.80175,12.12884
6.20000,0.51664,246.06646,0.00828,0.82810,12.49855
6.40000,0.53332,252.69354,0.00854,0.85440,12.83516
6.60000,0.55000,259.38544,0.00881,0.88082,13.17507
6.80000,0.56680,266.78129,0.00907,0.90696,13.55073
7.00000,0.58331,272.34489,0.00931,0.93106,13.83332
7.20000,0.59993,278.92492,0.00958,0.95753,14.16754
7.40000,0.61673,285.88825,0.00984,0.98428,14.52123
7.60000,0.63329,292.69860,0.01011,1.01081,14.86716
7.80000,0.64997,299.43015,0.01037,1.03694,15.20907
8.00000,0.66671,306.37896,0.01064,1.06371,15.56203
8.20000,0.68327,312.63949,0.01090,1.08975,15.88002
8.40000,0.69996,318.93805,0.01117,1.11699,16.19995
8.60000,0.71664,325.72250,0.01143,1.14338,16.54455
8.80000,0.73338,332.98745,0.01170,1.17021,16.91356
9.00000,0.75000,338.91944,0.01197,1.19658,17.21487
9.20000,0.76662,346.04704,0.01224,1.22351,17.57690
9.40000,0.78336,351.10859,0.01251,1.25060,17.83400
9.60000,0.79992,357.88622,0.01278,1.27764,18.17826
9.80000,0.81666,364.42431,0.01305,1.30477,18.51035
10.00000,0.83341,371.19447,0.01331,1.33130,18.85423
10.20000,0.85003,376.36093,0.01356,1.35615,19.11665
10.40000,0.86665,382.52915,0.01383,1.38322,19.42995
10.60000,0.88333,388.58396,0.01411,1.41052,19.73750
10.80000,0.89995,395.23239,0.01437,1.43742,20.07519
11.00000,0.91663,401.24385,0.01465,1.46469,20.38054
11.20000,0.93331,407.59314,0.01492,1.49199,20.70304
11.40000,0.95011,414.18574,0.01519,1.51910,21.03790
11.60000,0.96656,420.54658,0.01547,1.54650,21.36099
11.80000,0.98324,426.16935,0.01574,1.57364,21.64659
12.00000,1.00010,432.45428,0.01602,1.60199,21.96582
12.20000,1.01666,438.37950,0.01629,1.62866,22.26678
12.40000,1.03328,444.97917,0.01656,1.65647,22.60200
12.60000,1.05002,450.77298,0.01684,1.68440,22.89629
12.80000,1.06670,456.95831,0.01712,1.71171,23.21046
13.00000,1.08327,463.16227,0.01739,1.73888,23.52558
13.20000,1.09995,469.26197,0.01767,1.76706,23.83541
13.40000,1.11675,474.90215,0.01795,1.79479,24.12189
13.60000,1.13325,480.92315,0.01821,1.82115,24.42772
13.80000,1.14993,486.33581,0.01847,1.84695,24.70265
14.00000,1.16679,491.88519,0.01874,1.87392,24.98452
14.20000,1.18329,498.74545,0.01902,1.90154,25.33297
14.40000,1.19998,503.98437,0.01930,1.92971,25.59908
14.60000,1.21672,510.10302,0.01958,1.95798,25.90986
14.80000,1.23334,515.73333,0.01986,1.98562,26.19585
15.00000,1.24996,521.42255,0.02014,2.01384,26.48482
15.20000,1.26664,526.93002,0.02042,2.04198,26.76456
15.40000,1.28338,532.52839,0.02070,2.07001,27.04892
15.60000,1.30000,538.14240,0.02098,2.09798,27.33408
15.80000,1.31656,544.16177,0.02126,2.12616,27.63982
16.00000,1.33337,549.12972,0.02154,2.15441,27.89216
16.20000,1.34993,554.67808,0.02183,2.18299,28.17398
16.40000,1.36667,559.96468,0.02212,2.21162,28.44251
16.60000,1.38341,565.78191,0.02240,2.24001,28.73798
16.80000,1.40003,571.11587,0.02267,2.26746,29.00891
17.00000,1.41671,575.98096,0.02293,2.29335,29.25603
17.20000,1.43333,580.89909,0.02322,2.32178,29.50584
17.40000,1.45001,585.89019,0.02350,2.35024,29.75935
17.60000,1.46670,591.72362,0.02379,2.37913,30.05565
17.80000,1.48338,597.04538,0.02408,2.40774,30.32596
18.00000,1.50000,602.11644,0.02437,2.43667,30.58354
18.20000,1.51656,607.53087,0.02465,2.46530,30.85855
18.40000,1.53324,612.58832,0.02494,2.49446,31.11544
18.60000,1.55004,617.37387,0.02523,2.52349,31.35851
18.80000,1.56666,622.89969,0.02553,2.55262,31.63919
19.00000,1.58329,627.84324,0.02582,2.58175,31.89029
19.20000,1.60003,632.89474,0.02611,2.61074,32.14687
19.40000,1.61665,637.59042,0.02640,2.63999,32.38538
19.60000,1.63333,642.80001,0.02669,2.66924,32.64999
19.80000,1.65007,647.54561,0.02698,2.69751,32.89104
20.00000,1.66675,652.65750,0.02727,2.72677,33.15069
20.20000,1.68325,656.65585,0.02753,2.75320,33.35378
20.40000,1.69999,661.35935,0.02782,2.78245,33.59269
20.60000,1.71668,666.25243,0.02812,2.81248,33.84122
20.80000,1.73330,671.22346,0.02842,2.84197,34.09372
21.00000,1.74998,675.31373,0.02872,2.87182,34.30148
21.20000,1.76672,680.86949,0.02902,2.90188,34.58367
21.40000,1.78334,685.08931,0.02932,2.93165,34.79801
21.60000,1.79996,689.97103,0.02962,2.96226,35.04597
21.80000,1.81670,695.06508,0.02992,2.99224,35.30471
22.00000,1.83339,699.88333,0.03023,3.02254,35.54945
22.20000,1.84995,703.91372,0.03053,3.05329,35.75417
22.40000,1.86669,707.97498,0.03083,3.10146,35.96045
22.60000,1.88337,712.38372,0.03114,3.16819,36.18439
22.73000,1.89413,715.29937,0.03134,3.21123,36.33248
22.93000,1.91081,719.44180,0.03165,3.27796,36.54289
23.13000,1.92743,723.32937,0.03195,3.34444,36.74035
23.33000,1.94412,728.07265,0.03227,3.41117,36.98128
23.53000,1.96074,731.47775,0.03256,3.47766,37.15424
23.73000,1.97748,735.68961,0.03284,3.54462,37.36817
23.93000,1.99416,739.59818,0.03315,3.61134,37.56670
24.13000,2.01084,743.48017,0.03346,3.67807,37.76388
24.33000,2.02752,747.71205,0.03378,3.74479,37.97883
24.53000,2.04420,750.96898,0.03409,3.81152,38.14426
24.73000,2.06082,755.46261,0.03442,3.87801,38.37251
24.93000,2.07751,758.91032,0.03538,3.94473,38.54763
25.13000,2.09425,762.65475,0.03475,4.01170,38.73782
25.33000,2.11087,766.03214,0.06674,4.07818,38.90937
25.53000,2.12749,769.25051,0.08080,4.14467,39.07284
25.73000,2.14417,774.19844,-0.01643,4.21139,39.32417
25.93000,2.16085,776.87362,-0.00040,4.27812,39.46005
26.13000,2.17747,780.79230,-0.00362,4.34460,39.65909
26.33000,2.19421,784.13133,0.00394,4.41157,39.82869
26.53000,2.21084,787.30443,0.00262,4.47805,39.98986
26.73000,2.22746,790.73440,-0.14813,4.54454,40.16408
26.93000,2.24420,794.15720,-0.14761,4.61150,40.33794
27.13000,2.26088,797.53585,-0.14800,4.67823,40.50955
27.33000,2.27750,800.08609,-0.14800,4.74471,40.63909
27.53000,2.29418,803.37133,-0.14800,4.81144,40.80595
27.73000,2.31086,806.25275,-0.14800,4.87816,40.95231
27.93000,2.32749,809.05585,-0.14800,4.94465,41.09469
28.13000,2.34411,812.66351,-0.14800,5.01114,41.27794
28.33000,2.36091,815.41110,-0.14800,5.07834,41.41750
28.53000,2.37753,818.34113,-0.14801,5.14483,41.56632
28.73000,2.39409,822.32626,-0.14801,5.21107,41.76874
28.93000,2.41083,824.21796,-0.14800,5.27804,41.86483
29.13000,2.42745,827.60500,-0.14801,5.34452,42.03687
29.33000,2.44413,830.06369,-0.14800,5.41125,42.16175
29.53000,2.46088,832.85365,-0.14801,5.47821,42.30346
29.73000,2.47744,835.83482,-0.14800,5.54446,42.45489
29.93000,2.49412,838.10994,-0.14801,5.61118,42.57045
30.13000,2.51080,840.33832,-0.14801,5.67791,42.68364
30.33000,2.52754,842.42849,-0.14801,5.74487,42.78980
30.53000,2.54422,844.93747,-0.14801,5.81160,42.91724
30.73000,2.56084,847.00836,-0.14801,5.87808,43.02243
30.93000,2.57747,849.36563,-0.14801,5.94457,43.14216
31.13000,2.59409,852.01282,-0.14801,6.01105,43.27662
31.33000,2.61089,854.49452,-0.14801,6.07826,43.40268
31.53000,2.62757,856.20247,-0.14801,6.14498,43.48943
31.73000,2.64413,858.42693,-0.14801,6.21123,43.60242
31.93000,2.66081,860.15007,-0.14801,6.27796,43.68994
32.13000,2.67749,861.84526,-0.14801,6.34468,43.77604
32.33000,2.69417,864.13622,-0.14801,6.41141,43.89241
32.53000,2.71092,865.69916,-0.14801,6.47837,43.97180
32.73000,2.72748,867.03720,-0.14801,6.54462,44.03976
32.93000,2.74422,868.81844,-0.14801,6.61158,44.13024
33.13000,2.76078,869.62245,-0.14801,6.67783,44.17107
33.33000,2.77740,871.43984,-0.14801,6.74431,44.26339
33.53000,2.79426,873.13810,-0.14802,6.81176,44.34965
33.73000,2.81088,874.99823,-0.14801,6.87824,44.44413
33.93000,2.82744,875.78455,-0.14801,6.94449,44.48407
34.13000,2.84419,877.42936,-0.14801,7.01145,44.56762
34.33000,2.86081,879.04390,-0.14801,7.07794,44.64962
34.53000,2.87743,879.64032,-0.14801,7.14443,44.67992
34.73000,2.89417,880.98347,-0.14801,7.21139,44.74814
34.93000,2.91091,882.16420,-0.14802,7.27835,44.80811
35.13000,2.92741,883.43443,-0.14801,7.34436,44.87263
35.33000,2.94415,883.87690,-0.14802,7.41132,44.89511
35.53000,2.96096,885.12721,-0.14801,7.47853,44.95861
35.73000,2.97752,886.14747,-0.14801,7.54478,45.01044
35.93000,2.99414,887.62660,-0.14802,7.61126,45.08557
36.13000,3.01082,887.85077,-0.14802,7.67799,45.09695
36.33000,3.02744,889.03243,-0.14801,7.74447,45.15697
36.53000,3.04406,889.59970,-0.14801,7.81096,45.18579
36.73000,3.06080,889.76631,-0.14801,7.87792,45.19425
36.93000,3.07748,890.98839,-0.14801,7.94465,45.25632
37.13000,3.09411,891.14122,-0.14802,8.01113,45.26409
37.33000,3.11079,891.68120,-0.14801,8.07786,45.29152
37.53000,3.12753,891.32851,-0.14801,8.14482,45.27360
37.73000,3.14415,891.94952,-0.14802,8.21131,45.30514
37.93000,3.16083,893.43041,-0.14802,8.27803,45.38036
38.13000,3.17757,892.90924,-0.14802,8.34500,45.35389
38.33000,3.19419,893.57961,-0.14802,8.41148,45.38794
38.53000,3.21076,893.22468,-0.14802,8.47773,45.36991
38.73000,3.22750,893.92690,-0.14801,8.54469,45.40558
38.93000,3.24424,893.06496,-0.14801,8.61166,45.36180
39.13000,3.26080,894.00718,-0.14801,8.67791,45.40966
39.33000,3.27742,893.66287,-0.14802,8.74439,45.39217
39.53000,3.29416,893.19227,-0.14802,8.81136,45.36827
39.73000,3.31078,894.00094,-0.14802,8.87784,45.40934
39.93000,3.32746,893.22878,-0.14802,8.94457,45.37012
40.13000,3.34427,892.98356,-0.14802,9.01177,45.35767
40.33000,3.36083,893.16834,-0.14801,9.07802,45.36705
40.53000,3.37745,892.98747,-0.14802,9.14450,45.35786
40.73000,3.39419,892.76200,-0.14802,9.21147,45.34641
40.93000,3.41087,891.71659,-0.14802,9.27819,45.29331
41.13000,3.42749,891.95091,-0.14802,9.34468,45.30521
41.33000,3.44417,891.50369,-0.14802,9.41140,45.28250
41.53000,3.46085,891.38439,-0.14802,9.47813,45.27644
41.73000,3.47742,890.82140,-0.14802,9.54437,45.24784
41.93000,3.49416,889.86084,-0.14802,9.61134,45.19905
42.13000,3.51096,889.74740,-0.14802,9.67854,45.19329
42.33000,3.52746,888.86591,-0.14802,9.74455,45.14851
42.53000,3.54408,888.80789,-0.14802,9.81104,45.14557
42.73000,3.56088,888.03153,-0.14802,9.87824,45.10614
42.93000,3.57756,887.91223,-0.14802,9.94496,45.10007
43.13000,3.59407,887.18096,-0.14802,10.01097,45.06293
43.33000,3.61087,886.36838,-0.14802,10.07818,45.02166
43.53000,3.62755,886.06812,-0.14802,10.14490,45.00640
43.73000,3.64417,884.76697,-0.14802,10.21139,44.94032
43.93000,3.66085,884.37563,-0.14802,10.27811,44.92044
44.13000,3.67753,883.72938,-0.14802,10.34484,44.88762
44.33000,3.69415,882.51280,-0.14802,10.41132,44.82582
44.53000,3.71084,881.58967,-0.14802,10.47805,44.77893
44.73000,3.72752,880.70054,-0.14802,10.54477,44.73377
44.93000,3.74414,880.77551,-0.14802,10.61126,44.73758
45.13000,3.76076,879.61126,-0.14802,10.67775,44.67844
45.33000,3.77750,878.64278,-0.14802,10.74471,44.62925
45.53000,3.79418,877.47853,-0.14802,10.81143,44.57011
45.73000,3.81080,877.07527,-0.14802,10.87792,44.54963
45.93000,3.82742,875.90404,-0.14802,10.94441,44.49014
46.13000,3.84417,875.07535,-0.14802,11.01137,44.44805
46.33000,3.86079,874.68363,-0.14801,11.07786,44.42815
46.53000,3.87747,873.33284,-0.14802,11.14458,44.35954
46.73000,3.89421,873.48800,-0.14802,11.21155,44.36742
46.93000,3.91083,871.90699,-0.14802,11.27803,44.28711
47.13000,3.92745,871.34624,-0.14802,11.34452,44.25863
47.33000,3.94413,870.37394,-0.14802,11.41124,44.20924
47.53000,3.96087,869.18138,-0.14802,11.47821,44.14867
47.73000,3.97744,868.41751,-0.14801,11.54445,44.10987
47.93000,3.99418,867.77285,-0.14802,11.61142,44.07713
48.13000,4.01086,867.38300,-0.14802,11.67814,44.05732
48.33000,4.02742,866.12226,-0.14802,11.74439,43.99329
48.53000,4.04416,864.80742,-0.14802,11.81135,43.92650
48.73000,4.06102,864.51266,-0.14802,11.87880,43.91153
48.93000,4.07746,863.46054,-0.14802,11.94456,43.85809
49.13000,4.09409,862.14403,-0.14802,12.01105,43.79122
49.33000,4.11089,861.97546,-0.14802,12.07825,43.78266
49.53000,4.12751,860.43077,-0.14802,12.14474,43.70420
49.73000,4.14413,859.71979,-0.14801,12.21123,43.66809
49.93000,4.16081,858.56598,-0.14802,12.27795,43.60948
50.13000,4.17755,857.54786,-0.14802,12.34491,43.55777
50.33000,4.19411,856.82860,-0.14802,12.41116,43.52123
50.53000,4.21079,856.31544,-0.14802,12.47789,43.49517
50.73000,4.22754,855.26118,-0.14802,12.54485,43.44162
50.93000,4.24416,854.41889,-0.14802,12.61134,43.39883
51.13000,4.26084,853.16338,-0.14802,12.67806,43.33506
51.33000,4.27752,852.57757,-0.14802,12.74479,43.30531
51.53000,4.29420,851.46269,-0.14802,12.81151,43.24868
51.73000,4.31082,850.30273,-0.14802,12.87800,43.18976
51.93000,4.32744,849.74254,-0.14802,12.94449,43.16130
52.13000,4.34412,849.28311,-0.14802,13.01121,43.13797
52.33000,4.36081,848.52073,-0.14802,13.07793,43.09925
52.53000,4.37749,847.45800,-0.14802,13.14466,43.04527
52.73000,4.39411,846.32980,-0.14802,13.21114,42.98796
52.93000,4.41085,845.84625,-0.14802,13.27811,42.96340
53.13000,4.42753,845.26064,-0.14802,13.34483,42.93365
53.33000,4.44421,844.08149,-0.14802,13.41156,42.87376
53.53000,4.46083,843.74994,-0.14802,13.47805,42.85692
53.73000,4.47752,842.84544,-0.14802,13.54477,42.81098
53.93000,4.49420,841.57772,-0.14802,13.61150,42.74659
54.13000,4.51094,840.66251,-0.14802,13.67846,42.70010
54.33000,4.52756,840.16621,-0.14802,13.74495,42.67489
54.53000,4.54412,838.63363,-0.14802,13.81119,42.59705
54.73000,4.56086,837.57211,-0.14802,13.87816,42.54313
54.93000,4.57748,837.25974,-0.14802,13.94464,42.52726
55.13000,4.59416,836.42146,-0.14802,14.01137,42.48468
55.33000,4.61091,836.07044,-0.14802,14.07833,42.46685
55.53000,4.62747,835.15728,-0.14802,14.14458,42.42047
55.73000,4.64415,833.75257,-0.14802,14.21130,42.34912
55.93000,4.66089,833.04942,-0.14802,14.27827,42.31341
56.13000,4.67757,832.59754,-0.14802,14.34499,42.29045
56.33000,4.69413,831.74957,-0.14802,14.41124,42.24738
56.53000,4.71081,830.97080,-0.14802,14.47797,42.20782
56.73000,4.72755,830.40921,-0.14802,14.54493,42.17930
56.93000,4.74412,829.46736,-0.14802,14.61118,42.13146
57.13000,4.76080,828.78619,-0.14802,14.67790,42.09686
57.33000,4.77760,828.00267,-0.14802,14.74510,42.05706
57.53000,4.79410,827.07275,-0.14802,14.81111,42.00983
57.73000,4.81078,826.20326,-0.14802,14.87784,41.96567
57.93000,4.82746,825.23096,-0.14802,14.94456,41.91628
58.13000,4.84414,824.40311,-0.14802,15.01129,41.87423
58.33000,4.86089,823.38983,-0.14802,15.07825,41.82276
58.53000,4.87751,822.71639,-0.14802,15.14474,41.78856
58.73000,4.89419,821.91760,-0.14802,15.21146,41.74798
58.93000,4.91081,821.02846,-0.14802,15.27795,41.70282
59.13000,4.92743,819.93248,-0.14802,15.34443,41.64715
59.33000,4.94417,819.45695,-0.14802,15.41140,41.62300
59.53000,4.96079,818.83194,-0.14802,15.47789,41.59125
59.73000,4.97748,817.32413,-0.14802,15.54461,41.51466
59.93000,4.99416,816.82885,-0.14802,15.61133,41.48951
60.13000,5.01084,816.43322,-0.14802,15.67806,41.46941
60.33000,5.02746,815.31769,-0.14802,15.74455,41.41275
60.53000,5.04420,814.29705,-0.14802,15.81151,41.36091
60.73000,5.06082,813.80773,-0.14802,15.87799,41.33606
60.93000,5.07744,812.42090,-0.14802,15.94448,41.26561
61.13000,5.09412,811.10764,-0.14802,16.01121,41.19891
61.33000,5.11087,810.96310,-0.14802,16.07817,41.19157
61.53000,5.12755,809.77064,-0.14802,16.14490,41.13100
61.73000,5.14423,808.79368,-0.14802,16.21162,41.08138
61.93000,5.16085,807.99116,-0.14802,16.27811,41.04061
62.13000,5.17747,806.59287,-0.14802,16.34459,40.96959
62.33000,5.19415,806.08334,-0.14802,16.41132,40.94371
62.53000,5.21089,804.49926,-0.14802,16.47828,40.86325
62.73000,5.22751,804.03360,-0.14802,16.54477,40.83960
62.93000,5.24414,802.87065,-0.14802,16.61125,40.78053
63.13000,5.26076,802.29389,-0.14802,16.67774,40.75123
63.33000,5.27744,800.84894,-0.14802,16.74446,40.67783
63.53000,5.29418,800.01475,-0.14802,16.81143,40.63546
63.73000,5.31092,798.77628,-0.14802,16.87839,40.57256
63.93000,5.32754,797.63010,-0.14802,16.94488,40.51434
64.13000,5.34410,796.94297,-0.14802,17.01113,40.47944
64.33000,5.36079,796.12201,-0.14802,17.07785,40.43774
64.53001,5.37759,794.19520,-0.14802,17.14505,40.33987
64.73000,5.39421,793.23892,-0.14802,17.21154,40.29129
64.93000,5.41083,791.98545,-0.14802,17.27803,40.22763
65.13000,5.42751,790.94265,-0.14802,17.34475,40.17466
65.33000,5.44413,789.45383,-0.14802,17.41124,40.09904
65.53001,5.46081,788.16814,-0.14802,17.47796,40.03373
65.73000,5.47749,786.91943,-0.14802,17.54469,39.97031
65.93000,5.49418,785.87690,-0.14802,17.61141,39.91735
66.13001,5.51074,784.34031,-0.14802,17.67766,39.83931
66.33000,5.52748,783.04326,-0.14802,17.74462,39.77342
66.53001,5.54422,781.26052,-0.14802,17.81159,39.68287
66.73000,5.56084,780.06657,-0.14802,17.87807,39.62223
66.93000,5.57758,778.44812,-0.14802,17.94504,39.54002
67.13001,5.59420,776.94273,-0.14802,18.01152,39.46356
67.33000,5.61083,774.80469,-0.14802,18.07801,39.35496
67.53001,5.62745,773.58843,-0.14802,18.14450,39.29318
67.73000,5.64413,771.87358,-0.14802,18.21122,39.20608
67.93000,5.66087,770.06612,-0.14802,18.27819,39.11427
68.13001,5.67749,768.36962,-0.14802,18.34467,39.02810
68.33000,5.69411,766.49673,-0.14802,18.41116,38.93297
68.53001,5.71085,765.02636,-0.14802,18.47812,38.85828
68.73000,5.72747,763.03435,-0.14802,18.54461,38.75710
68.93000,5.74416,760.97068,-0.14802,18.61133,38.65228
69.13001,5.76090,758.85509,-0.14802,18.67830,38.54483
69.33000,5.77746,756.74294,-0.14802,18.74454,38.43754
69.53001,5.79414,754.18567,-0.14802,18.81127,38.30765
69.73000,5.81088,752.59837,-0.14802,18.87823,38.22702
69.93000,5.82756,750.48176,-0.14802,18.94496,38.11951
70.13001,5.84418,747.15829,-0.14802,19.01144,37.95070
70.33000,5.86080,744.97741,-0.14802,19.07793,37.83993
70.53001,5.87761,743.02647,-0.14802,19.14513,37.74084
70.73000,5.89411,741.02278,-0.14802,19.21114,37.63906
70.93000,5.91079,738.62271,-0.14802,19.27786,37.51715
71.13001,5.92759,736.16998,-0.14802,19.34507,37.39257
71.33000,5.94415,733.13736,-0.14802,19.41132,37.23853
71.53001,5.96077,731.19621,-0.14802,19.47780,37.13993
71.73000,5.97751,728.96462,-0.14802,19.54477,37.02658
71.93000,5.99420,726.40055,-0.14802,19.61149,36.89635
72.13001,6.01082,723.62325,-0.14802,19.67797,36.75528
72.33000,6.02750,721.80256,-0.14802,19.74470,36.66280
72.53001,6.04418,718.80952,-0.14802,19.81143,36.51077
72.73000,6.06074,716.92714,-0.14802,19.87767,36.41516
72.93000,6.07742,714.75771,-0.14802,19.94440,36.30497
73.13001,6.09422,712.58578,-0.14802,20.01160,36.19465
73.33000,6.11084,709.77118,-0.14802,20.07809,36.05169
73.53001,6.12747,707.39696,-0.14802,20.14457,35.93109
73.73000,6.14415,705.69385,-0.14802,20.21130,35.84459
73.93000,6.16077,704.05276,-0.14802,20.27778,35.76123
74.13001,6.17745,702.21843,-0.14802,20.34451,35.66806
74.33000,6.19419,699.34516,-0.14802,20.41148,35.52211
74.53001,6.21093,697.88867,-0.14802,20.47844,35.44813
74.73000,6.22737,696.31366,-0.14802,20.54421,35.36813
74.93000,6.24412,694.24035,-0.14802,20.61117,35.26282
75.13001,6.26092,692.52071,-0.14802,20.67837,35.17548
75.33000,6.27748,690.88163,-0.14802,20.74462,35.09222
75.53001,6.29416,689.24148,-0.14802,20.81135,35.00891
75.73000,6.31084,687.25338,-0.14802,20.87807,34.90793
75.93000,6.32746,686.50641,-0.14802,20.94456,34.86999
76.13001,6.34408,685.16275,-0.14802,21.01104,34.80174
76.33000,6.36082,683.68646,-0.14802,21.07801,34.72675
76.53001,6.37757,682.23081,-0.14802,21.14497,34.65282
76.73000,6.39413,681.16747,-0.14802,21.21122,34.59881
76.93000,6.41081,680.32835,-0.14802,21.27794,34.55619
77.13001,6.42767,678.96284,-0.14802,21.34539,34.48683
77.33000,6.44411,677.91743,-0.14802,21.41116,34.43373
77.53001,6.46085,676.55495,-0.14802,21.47812,34.36452
77.73000,6.47765,675.99090,-0.14802,21.54532,34.33587
77.93000,6.49421,674.95098,-0.14802,21.61157,34.28305
78.13001,6.51078,674.46982,-0.14802,21.67782,34.25861
78.33000,6.52752,673.38212,-0.14802,21.74478,34.20336
78.53001,6.54420,673.35819,-0.14802,21.81150,34.20215
78.73000,6.56082,672.41951,-0.14802,21.87799,34.15447
78.93000,6.57744,671.77787,-0.14802,21.94448,34.12188
79.13001,6.59418,671.58299,-0.14802,22.01144,34.11198
79.33000,6.61074,671.06956,-0.14802,22.07769,34.08590
79.53001,6.62749,670.44492,-0.14802,22.14465,34.05417
79.73000,6.64423,670.33069,-0.14802,22.21162,34.04837
79.93000,6.66079,669.33432,-0.14802,22.27786,33.99776
80.13001,6.67747,669.31825,-0.14802,22.34459,33.99694
80.33000,6.69415,669.54824,-0.14802,22.41131,34.00863
80.53001,6.71083,668.56192,-0.14802,22.47804,33.95853
80.73000,6.72745,668.78265,-0.14802,22.54452,33.96974
80.93000,6.74420,668.66521,-0.14802,22.61149,33.96378
81.13001,6.76082,668.73487,-0.14802,22.67797,33.96731
81.33000,6.77744,668.64053,-0.14802,22.74446,33.96252
81.53001,6.79406,668.87420,-0.14802,22.81095,33.97439
81.73000,6.81086,668.32174,-0.14802,22.87815,33.94633
81.93000,6.82754,668.73222,-0.14802,22.94488,33.96718
82.13001,6.84416,668.57194,-0.14802,23.01136,33.95904
82.33000,6.86078,667.89393,-0.14802,23.07785,33.92460
82.53001,6.87747,668.05142,-0.14802,23.14457,33.93260
82.73000,6.89415,668.10055,-0.14802,23.21130,33.93509
82.93000,6.91089,667.88113,-0.14802,23.27826,33.92395
83.13001,6.92757,667.83330,-0.14802,23.34498,33.92152
83.33000,6.94413,668.02809,-0.14802,23.41123,33.93141
83.53001,6.96081,668.01771,-0.14802,23.47796,33.93089
83.73000,6.97755,667.74404,-0.14802,23.54492,33.91698
83.93000,6.99411,667.61789,-0.14802,23.61117,33.91058
84.13001,7.01086,667.91028,-0.14802,23.67813,33.92543
84.33000,7.02760,668.14004,-0.14802,23.74510,33.93710
84.53001,7.04416,668.09827,-0.14802,23.81134,33.93498
84.73000,7.06078,667.77579,-0.14802,23.87783,33.91860
84.93000,7.07752,667.97798,-0.14802,23.94479,33.92887
85.13001,7.09426,667.89971,-0.14802,24.01176,33.92489
85.33000,7.11082,668.04718,-0.14802,24.07801,33.93238
85.53001,7.12745,667.74595,-0.14802,24.14449,33.91708
85.73000,7.14425,667.76327,-0.14802,24.21170,33.91796
85.93000,7.16081,667.16229,-0.14802,24.27794,33.88744
86.13001,7.17743,667.25663,-0.14802,24.34443,33.89223
86.33000,7.19423,667.33155,-0.14802,24.41163,33.89603
86.53001,7.21079,666.71288,-0.14802,24.47788,33.86461
86.73000,7.22741,666.85667,-0.14802,24.54436,33.87191
86.93001,7.24415,666.96056,-0.14802,24.61133,33.87719
87.13001,7.26084,666.19865,-0.14802,24.67805,33.83849
87.33000,7.27752,666.57318,-0.14802,24.74478,33.85751
87.53001,7.29420,666.00465,-0.14802,24.81150,33.82864
87.73000,7.31082,665.71971,-0.14802,24.87799,33.81416
87.93001,7.32750,664.89945,-0.14802,24.94471,33.77250
88.13001,7.34412,665.07142,-0.14802,25.01120,33.78123
88.33000,7.36092,665.09400,-0.14802,25.07840,33.78238
88.53001,7.37755,664.08664,-0.14802,25.14489,33.73121
88.73000,7.39417,664.19803,-0.14802,25.21137,33.73687
88.93001,7.41079,663.66671,-0.14802,25.27786,33.70988
89.13001,7.42747,663.48240,-0.14802,25.34459,33.70052
89.33000,7.44427,663.63723,-0.14802,25.41179,33.70839
89.53001,7.46083,663.19737,-0.14802,25.47804,33.68604
89.73000,7.47745,662.84006,-0.14802,25.54452,33.66790
89.93001,7.49413,662.50102,-0.14802,25.61125,33.65067
90.13001,7.51076,662.49561,-0.14802,25.67773,33.65040
90.33000,7.52756,661.78567,-0.14802,25.74494,33.61434
90.53001,7.54424,661.79577,-0.14802,25.81166,33.61485
90.73000,7.56080,661.04298,-0.14802,25.87791,33.57661
90.93001,7.57754,661.72010,-0.14802,25.94487,33.61101
91.13001,7.59410,661.17449,-0.14802,26.01112,33.58329
91.33000,7.61078,661.21174,-0.14802,26.07785,33.58519
91.53001,7.62752,660.29700,-0.14802,26.14481,33.53872
91.73000,7.64421,659.38798,-0.14802,26.21153,33.49255
91.93001,7.66077,660.17411,-0.14802,26.27778,33.53248
92.13001,7.67739,659.99930,-0.14802,26.34427,33.52361
92.33000,7.69419,658.93484,-0.14802,26.41147,33.46954
92.53001,7.71087,659.08441,-0.14802,26.47820,33.47713
92.73000,7.72749,658.97391,-0.14802,26.54468,33.47152
92.93001,7.74423,658.58457,-0.14802,26.61164,33.45174
93.13001,7.76080,657.65758,-0.14802,26.67789,33.40466
93.33000,7.77754,658.19295,-0.14802,26.74485,33.43185
93.53001,7.79422,657.82513,-0.14802,26.81158,33.41317
93.73000,7.81084,656.74819,-0.14802,26.87807,33.35847
93.93001,7.82752,656.57962,-0.14802,26.94479,33.34991
94.13001,7.84414,656.42092,-0.14802,27.01128,33.34185
94.33000,7.86082,655.89952,-0.14802,27.07800,33.31536
94.53001,7.87744,655.22641,-0.14802,27.14449,33.28117
94.73000,7.89413,654.65034,-0.14802,27.21121,33.25191
94.93001,7.91087,653.96144,-0.14802,27.27818,33.21692
95.13001,7.92743,653.71678,-0.14802,27.34442,33.20449
95.33000,7.94411,653.73043,-0.14802,27.41115,33.20518
95.53001,7.96085,652.81712,-0.14802,27.47812,33.15880
95.73000,7.97747,652.13591,-0.14802,27.54460,33.12420
95.93001,7.99427,651.23942,-0.14802,27.61180,33.07866
96.13001,8.01083,650.69608,-0.14802,27.67805,33.05106
96.33000,8.02752,649.73347,-0.14802,27.74477,33.00217
96.53001,8.04414,649.02105,-0.14802,27.81126,32.96598
96.73000,8.06082,648.34352,-0.14802,27.87798,32.93157
96.93001,8.07756,647.00162,-0.14801,27.94495,32.86341
97.13001,8.09418,647.06830,-0.14802,28.01144,32.86679
97.33000,8.11080,644.97432,-0.14802,28.07792,32.76043
97.53001,8.12748,643.81589,-0.14802,28.14465,32.70160
97.73000,8.14417,643.23917,-0.14802,28.21137,32.67230
97.93001,8.16085,641.98337,-0.14802,28.27809,32.60851
98.13001,8.17753,640.83454,-0.14802,28.34482,32.55016
98.33000,8.19415,638.81739,-0.14802,28.41131,32.44770
98.53001,8.21077,637.32220,-0.14802,28.47779,32.37176
98.73000,8.22751,636.22943,-0.14802,28.54476,32.31625
98.93001,8.24425,634.19342,-0.14802,28.61172,32.21284
99.13001,8.26081,631.79671,-0.14802,28.67797,32.09110
99.33000,8.27744,630.52736,-0.14802,28.74446,32.02662
99.53001,8.29424,628.53885,-0.14802,28.81166,31.92562
99.73000,8.31086,626.85264,-0.14802,28.87814,31.83997
99.93001,8.32748,625.33724,-0.14802,28.94463,31.76300
100.13001,8.34422,622.36455,-0.14802,29.01160,31.61201
100.33000,8.36090,620.10204,-0.14802,29.07832,31.49709
100.53001,8.37746,618.14450,-0.14802,29.14457,31.39766
100.73000,8.39415,615.85940,-0.14802,29.21129,31.28159
100.93001,8.41089,614.00044,-0.14802,29.27826,31.18717
101.13001,8.42751,611.39753,-0.14802,29.34474,31.05495
101.33000,8.44419,609.26084,-0.14802,29.41147,30.94642
101.53001,8.46087,606.25770,-0.14802,29.47819,30.79389
101.73000,8.47743,604.22518,-0.14802,29.54444,30.69065
101.93001,8.49417,601.17980,-0.14802,29.61140,30.53596
102.13001,8.51085,597.75030,-0.14802,29.67812,30.36177
102.33000,8.52748,595.19140,-0.14801,29.74462,30.23179
102.53001,8.54404,591.93773,-0.14802,29.81086,30.06653
102.73000,8.56078,587.39968,-0.14802,29.87782,29.83602
102.93001,8.57752,583.20113,-0.14802,29.94479,29.62276
103.13001,8.59420,577.13501,-0.14802,30.01151,29.31465
103.33000,8.61088,570.37831,-0.14802,30.07824,28.97145
103.53001,8.62756,559.36594,-0.14802,30.14497,28.41209
103.73000,8.64413,544.28237,-0.14802,30.21121,27.64595
103.93001,8.66081,471.67283,-0.14802,30.27793,23.95786
103.97601,8.66469,9.13340,-0.14802,30.29348,0.46392