File: Manufatura Aditiva/Dados/Ensaios AMR/Ensaios/Ensaios SLS/Tracao_OLABI_07_06_2018_SLS_XZ2.is_metal_RawData/Specimen_RawData_4.csv
Time,Extension,Load,Strain 1,Tensile strain,Tensile stress
(sec),(mm),(N),(mm/mm),(%),(MPa)
0.00000,0.00006,28.68708,0.00117,0.11742,1.38953
0.20000,0.01381,35.04823,0.00136,0.13598,1.69765
0.40000,0.03270,45.34171,0.00167,0.16749,2.19625
0.60000,0.04986,54.70726,0.00197,0.19715,2.64989
0.80000,0.06673,62.17309,0.00225,0.22503,3.01152
1.00000,0.08335,70.73746,0.00253,0.25274,3.42636
1.20000,0.10003,78.53807,0.00281,0.28117,3.80420
1.40000,0.11683,87.29962,0.00309,0.30913,4.22859
1.60000,0.13339,95.16456,0.00337,0.33676,4.60955
1.80000,0.14995,102.67816,0.00365,0.36457,4.97349
2.00000,0.16657,110.96683,0.00393,0.39289,5.37497
2.20000,0.18331,118.34523,0.00421,0.42116,5.73236
2.40000,0.19994,125.82825,0.00448,0.44848,6.09482
2.60000,0.21668,133.05896,0.00477,0.47702,6.44506
2.80000,0.23336,140.90292,0.00505,0.50517,6.82501
3.00000,0.24998,149.00268,0.00533,0.53308,7.21734
3.20000,0.26672,156.19205,0.00560,0.56044,7.56558
3.40000,0.28340,163.40642,0.00589,0.58880,7.91502
3.60000,0.30008,170.44947,0.00617,0.61730,8.25617
3.80000,0.31665,177.82919,0.00645,0.64467,8.61363
4.00000,0.33327,185.32487,0.00672,0.67227,8.97670
4.20000,0.34995,192.69636,0.00700,0.69970,9.33376
4.40000,0.36663,199.62599,0.00728,0.72789,9.66941
4.60000,0.38331,206.49717,0.00755,0.75544,10.00224
4.80000,0.39999,213.79839,0.00783,0.78319,10.35589
5.00000,0.41661,220.45195,0.00811,0.81089,10.67817
5.20000,0.43335,227.88169,0.00839,0.83888,11.03805
5.40000,0.45004,235.35648,0.00867,0.86697,11.40011
5.60000,0.46666,241.39280,0.00895,0.89452,11.69250
5.80000,0.48334,248.09472,0.00922,0.92214,12.01712
6.00000,0.50002,255.59701,0.00950,0.95046,12.38052
6.20000,0.51664,262.31899,0.00978,0.97783,12.70611
6.40000,0.53326,269.25262,0.01006,1.00638,13.04196
6.60000,0.55000,275.85279,0.01035,1.03459,13.36166
6.80000,0.56674,282.55556,0.01062,1.06228,13.68633
7.00000,0.58331,287.42107,0.01084,1.08425,13.92200
7.20000,0.59993,293.32985,0.01112,1.11236,14.20821
7.40000,0.61673,300.45328,0.01141,1.14086,14.55325
7.60000,0.63329,307.21435,0.01169,1.16908,14.88074
7.80000,0.64997,313.54846,0.01197,1.19659,15.18755
8.00000,0.66671,319.67377,0.01225,1.22538,15.48424
8.20000,0.68333,325.63445,0.01253,1.25346,15.77297
8.40000,0.70002,332.21215,0.01282,1.28195,16.09157
8.60000,0.71664,338.35163,0.01311,1.31059,16.38896
8.80000,0.73344,343.85992,0.01339,1.33916,16.65576
9.00000,0.75000,350.75608,0.01367,1.36738,16.98980
9.20000,0.76662,356.75408,0.01396,1.39606,17.28033
9.40000,0.78336,362.94372,0.01425,1.42492,17.58014
9.60000,0.79992,368.63096,0.01454,1.45378,17.85562
9.80000,0.81660,373.93973,0.01482,1.48197,18.11276
10.00000,0.83341,379.89111,0.01511,1.51090,18.40103
10.20000,0.84991,385.69553,0.01540,1.54035,18.68218
10.40000,0.86671,391.15907,0.01570,1.57005,18.94682
10.60000,0.88333,396.39245,0.01598,1.59848,19.20032
10.80000,0.90007,402.13317,0.01628,1.62761,19.47838
11.00000,0.91669,407.14373,0.01657,1.65681,19.72108
11.20000,0.93331,412.62042,0.01686,1.68637,19.98636
11.40000,0.95000,416.24783,0.01709,1.70939,20.16206
11.60000,0.96656,421.16079,0.01738,1.73804,20.40004
11.80000,0.98330,426.16120,0.01768,1.76781,20.64224
12.00000,1.00010,431.16133,0.01798,1.79764,20.88444
12.20000,1.01666,435.99936,0.01827,1.82696,21.11878
12.40000,1.03328,441.37198,0.01857,1.85716,21.37902
12.60000,1.04996,445.90984,0.01887,1.88652,21.59882
12.80000,1.06664,451.04749,0.01916,1.91562,21.84768
13.00000,1.08333,455.81125,0.01946,1.94565,22.07842
13.20000,1.10001,460.40649,0.01976,1.97588,22.30101
13.40000,1.11675,464.92261,0.02006,2.00628,22.51976
13.60000,1.13325,469.72642,0.02036,2.03649,22.75244
13.80000,1.14993,474.22280,0.02068,2.06771,22.97024
14.00000,1.16673,478.89748,0.02099,2.09869,23.19666
14.20000,1.18329,483.33011,0.02129,2.12890,23.41137
14.40000,1.19998,487.34015,0.02160,2.15979,23.60561
14.60000,1.21672,491.43895,0.02192,2.19170,23.80414
14.80000,1.23334,495.90762,0.02222,2.22216,24.02060
15.00000,1.24996,499.61428,0.02254,2.25363,24.20014
15.20000,1.26670,504.00509,0.02285,2.28512,24.41282
15.40000,1.28344,508.57677,0.02317,2.31663,24.63426
15.60000,1.29994,512.67692,0.02348,2.34794,24.83286
15.80000,1.31656,515.87652,0.02380,2.37997,24.98784
16.00000,1.33343,518.32478,0.02404,2.40423,25.10643
16.20000,1.34993,521.84737,0.02436,2.43578,25.27706
16.40000,1.36667,525.55664,0.02469,2.46856,25.45673
16.60000,1.38341,529.79719,0.02501,2.50088,25.66213
16.80000,1.39997,532.86334,0.02532,2.53200,25.81064
17.00000,1.41659,536.00469,0.02565,2.56467,25.96280
17.20000,1.43333,539.80900,0.02597,2.59744,26.14708
17.40000,1.45001,543.23906,0.02630,2.62964,26.31322
17.60000,1.46664,546.79429,0.02662,2.66217,26.48543
17.80000,1.48320,549.54165,0.02695,2.69492,26.61850
18.00000,1.50000,552.84579,0.02728,2.72778,26.77855
18.20000,1.51656,556.35981,0.02761,2.76068,26.94876
18.40000,1.53330,559.55714,0.02793,2.79344,27.10363
18.60000,1.55004,562.37821,0.02827,2.82677,27.24027
18.80000,1.56666,565.53585,0.02860,2.85950,27.39322
19.00000,1.58341,568.41210,0.02893,2.89334,27.53254
19.20000,1.60003,571.62559,0.02926,2.92649,27.68820
19.40000,1.61671,574.28232,0.02960,2.95965,27.81688
19.60000,1.63333,577.32668,0.02994,2.99389,27.96434
19.80000,1.65007,580.42095,0.03028,3.02768,28.11422
20.00000,1.66663,582.73389,0.03061,3.06067,28.22626
20.20000,1.68325,586.56088,0.03094,3.11046,28.41163
20.35000,1.69581,586.90235,0.03120,3.16069,28.42817
20.55000,1.71249,590.25371,0.03154,3.22741,28.59050
20.75000,1.72917,593.14668,0.03187,3.29414,28.73063
20.95000,1.74579,595.90731,0.03221,3.36062,28.86435
21.15000,1.76253,598.32246,0.03256,3.42759,28.98133
21.35000,1.77910,598.52265,0.03282,3.49383,28.99103
21.55000,1.79578,601.24220,0.03317,3.56056,29.12276
21.75000,1.81264,604.09973,0.03350,3.62800,29.26117
21.95000,1.82920,606.09826,0.03385,3.69425,29.35797
22.15000,1.84582,608.88305,0.03419,3.76073,29.49286
22.35000,1.86250,611.22403,0.03454,3.82746,29.60625
22.55000,1.87912,613.92048,0.03488,3.89394,29.73686
22.75000,1.89575,616.32702,0.03523,3.96043,29.85343
22.95000,1.91249,618.30310,0.03557,4.02739,29.94915
23.15000,1.92917,620.66219,0.03584,4.09412,30.06341
23.35000,1.94573,623.04633,0.03608,4.16037,30.17890
23.55000,1.96247,623.10705,0.02601,4.22733,30.18184
23.75000,1.97927,621.82271,0.01274,4.29453,30.11963
23.95000,1.99589,626.72491,0.01394,4.36102,30.35708
24.15000,2.01251,630.94664,0.01245,4.42751,30.56157
24.35000,2.02920,632.24980,0.00956,4.49423,30.62469
24.55000,2.04582,635.10891,0.00940,4.56072,30.76318
24.75000,2.06250,637.18054,0.01165,4.62744,30.86352
24.95000,2.07918,639.25935,0.01234,4.69417,30.96422
25.15000,2.09580,641.88186,-0.00051,4.76065,31.09125
25.35000,2.11242,643.76364,0.01824,4.82714,31.18239
25.55000,2.12904,645.16678,0.00456,4.89362,31.25036
25.75000,2.14578,648.20703,-0.00890,4.96059,31.39762
25.95000,2.16253,649.64602,-0.01316,5.02755,31.46732
26.15000,2.17921,650.87420,-0.09580,5.09428,31.52681
26.35000,2.19583,652.90756,-0.13176,5.16076,31.62530
26.55000,2.21251,655.01942,-0.13176,5.22749,31.72760
26.75000,2.22919,656.94228,-0.13176,5.29421,31.82074
26.95000,2.24587,659.30332,-0.13176,5.36094,31.93510
27.15000,2.26255,660.81383,-0.13177,5.42766,32.00827
27.35000,2.27924,662.81175,-0.13177,5.49439,32.10504
27.55000,2.29580,664.27593,-0.13177,5.56064,32.17596
27.75000,2.31248,666.65225,-0.13178,5.62736,32.29107
27.95000,2.32916,666.33481,-0.13177,5.69409,32.27569
28.15000,2.34584,668.41547,-0.13178,5.76081,32.37647
28.35000,2.36246,670.11234,-0.13178,5.82730,32.45866
28.55000,2.37908,672.40042,-0.13178,5.89378,32.56949
28.75000,2.39576,673.59880,-0.13177,5.96051,32.62754
28.95000,2.41251,676.19029,-0.13178,6.02747,32.75306
29.15000,2.42919,677.03081,-0.13178,6.09420,32.79378
29.35000,2.44587,678.87986,-0.13178,6.16092,32.88334
29.55000,2.46255,680.43065,-0.13178,6.22765,32.95846
29.75000,2.47923,682.66406,-0.13178,6.29437,33.06664
29.95000,2.49585,683.82751,-0.13178,6.36086,33.12299
30.15000,2.51247,685.66138,-0.13178,6.42734,33.21182
30.35000,2.52927,687.41865,-0.13178,6.49455,33.29694
30.55000,2.54584,688.96939,-0.13179,6.56080,33.37206
30.75000,2.56240,691.25998,-0.13179,6.62704,33.48301
30.95000,2.57914,692.52667,-0.13179,6.69401,33.54436
31.15000,2.59582,693.68132,-0.13179,6.76073,33.60029
31.35000,2.61244,695.33181,-0.13179,6.82722,33.68023
31.55000,2.62918,696.87529,-0.13179,6.89418,33.75500
31.75000,2.64580,698.73468,-0.13179,6.96067,33.84506
31.95000,2.66243,700.10251,-0.13179,7.02715,33.91132
32.15000,2.67911,701.67645,-0.13179,7.09388,33.98755
32.35000,2.69591,702.74025,-0.13179,7.16108,34.03908
32.55000,2.71259,704.83754,-0.13179,7.22781,34.14067
32.75000,2.72915,705.82605,-0.13179,7.29405,34.18855
32.95000,2.74583,707.32073,-0.13179,7.36078,34.26095
33.15000,2.76251,708.46342,-0.13179,7.42750,34.31630
33.35000,2.77919,710.41025,-0.13179,7.49423,34.41060
33.55000,2.79588,711.49594,-0.13179,7.56095,34.46319
33.75000,2.81250,712.71188,-0.13179,7.62744,34.52208
33.95000,2.82912,713.98611,-0.13179,7.69392,34.58381
34.15000,2.84574,715.46095,-0.13179,7.76041,34.65524
34.35000,2.86248,716.70217,-0.13179,7.82738,34.71537
34.55000,2.87922,718.67006,-0.13179,7.89434,34.81068
34.75000,2.89584,719.93726,-0.13179,7.96083,34.87207
34.95000,2.91253,720.38583,-0.13179,8.02755,34.89379
35.15000,2.92915,720.59110,-0.13179,8.09404,34.90374
35.35000,2.94577,721.97691,-0.13179,8.16052,34.97086
35.55000,2.96257,723.41817,-0.13179,8.22773,35.04067
35.75000,2.97919,724.99793,-0.13179,8.29421,35.11719
35.95000,2.99575,725.79435,-0.13179,8.36046,35.15577
36.15000,3.01249,727.32456,-0.13179,8.42742,35.22989
36.35000,3.02917,727.87497,-0.13179,8.49415,35.25655
36.55000,3.04580,729.99317,-0.13179,8.56063,35.35915
36.75000,3.06254,730.97814,-0.13179,8.62760,35.40686
36.95000,3.07928,731.89456,-0.13179,8.69456,35.45125
37.15000,3.09572,733.97579,-0.13179,8.76033,35.55206
37.35000,3.11246,734.53328,-0.13179,8.82729,35.57906
37.55000,3.12926,735.83857,-0.13179,8.89450,35.64229
37.75000,3.14582,736.90615,-0.13179,8.96074,35.69400
37.95000,3.16245,738.21764,-0.13179,9.02723,35.75752
38.15000,3.17919,739.96643,-0.13179,9.09420,35.84223
38.35000,3.19581,740.78250,-0.13179,9.16068,35.88176
38.55000,3.21243,741.67186,-0.13179,9.22717,35.92484
38.75000,3.22911,742.83145,-0.13179,9.29389,35.98101
38.95000,3.24585,743.88245,-0.13179,9.36086,36.03191
39.15000,3.26241,745.13583,-0.13179,9.42710,36.09262
39.35000,3.27915,746.45341,-0.13179,9.49407,36.15644
39.55000,3.29590,747.12313,-0.13180,9.56103,36.18888
39.75000,3.31246,748.25846,-0.13179,9.62728,36.24388
39.95000,3.32920,748.92649,-0.13179,9.69424,36.27623
40.15000,3.34588,749.74694,-0.13179,9.76097,36.31598
40.35000,3.36256,750.99361,-0.13179,9.82769,36.37636
40.55000,3.37912,751.82714,-0.13180,9.89394,36.41674
40.75000,3.39580,752.82380,-0.13180,9.96066,36.46501
40.95000,3.41255,754.08714,-0.13180,10.02763,36.52620
41.15000,3.42917,755.03900,-0.13180,10.09411,36.57231
41.35000,3.44579,755.98457,-0.13179,10.16060,36.61811
41.55000,3.46253,756.80418,-0.13179,10.22756,36.65781
41.75000,3.47915,758.62068,-0.13180,10.29405,36.74580
41.95000,3.49583,758.88033,-0.13180,10.36078,36.75837
42.15000,3.51257,759.66590,-0.13179,10.42774,36.79642
42.35000,3.52919,760.67699,-0.13180,10.49423,36.84540
42.55000,3.54582,761.29520,-0.13180,10.56071,36.87535
42.75000,3.56250,762.14769,-0.13180,10.62744,36.91664
42.95000,3.57924,762.85643,-0.13180,10.69440,36.95097
43.15000,3.59574,764.14691,-0.13180,10.76041,37.01348
43.35000,3.61248,763.73732,-0.13180,10.82737,36.99364
43.55000,3.62922,764.52945,-0.13180,10.89434,37.03201
43.75000,3.64572,765.52085,-0.13179,10.96034,37.08002
43.95000,3.66252,766.65888,-0.13180,11.02755,37.13515
44.15000,3.67927,767.63262,-0.13179,11.09451,37.18232
44.35000,3.69583,768.57372,-0.13180,11.16076,37.22790
44.55000,3.71245,769.68223,-0.13180,11.22724,37.28159
44.75000,3.72919,770.07720,-0.13180,11.29421,37.30072
44.95000,3.74593,771.36843,-0.13180,11.36117,37.36327
45.15000,3.76237,772.71122,-0.13180,11.42694,37.42831
45.35000,3.77923,773.56277,-0.13180,11.49438,37.46956
45.55000,3.79586,773.70666,-0.13180,11.56087,37.47653
45.75000,3.81248,775.24744,-0.13180,11.62736,37.55116
45.95000,3.82916,775.41196,-0.13180,11.69408,37.55913
46.15000,3.84590,776.09187,-0.13180,11.76105,37.59206
46.35000,3.86246,777.17951,-0.13180,11.82729,37.64474
46.55000,3.87920,777.80960,-0.13180,11.89426,37.67527
46.75000,3.89582,778.38805,-0.13180,11.96074,37.70328
46.95000,3.91244,779.59956,-0.13180,12.02723,37.76197
47.15000,3.92913,780.13912,-0.13180,12.09395,37.78810
47.35000,3.94581,780.75584,-0.13180,12.16068,37.81797
47.55000,3.96255,781.12460,-0.13180,12.22764,37.83583
47.75000,3.97911,782.59008,-0.13180,12.29389,37.90682
47.95000,3.99579,782.73918,-0.13180,12.36061,37.91404
48.15000,4.01247,783.27190,-0.13180,12.42734,37.93985
48.35000,4.02915,783.63419,-0.13180,12.49406,37.95739
48.55000,4.04578,785.30591,-0.13180,12.56055,38.03837
48.75000,4.06258,785.45958,-0.13180,12.62775,38.04581
48.95000,4.07914,786.65875,-0.13180,12.69400,38.10390
49.15000,4.09576,786.92064,-0.13180,12.76049,38.11658
49.35000,4.11244,787.85298,-0.13180,12.82721,38.16174
49.55000,4.12918,788.41485,-0.13180,12.89417,38.18896
49.75000,4.14580,789.05132,-0.13180,12.96066,38.21979
49.95000,4.16248,790.08937,-0.13180,13.02739,38.27007
50.15000,4.17917,790.21361,-0.13180,13.09411,38.27608
50.35000,4.19573,791.41269,-0.13180,13.16036,38.33417
50.55000,4.21247,791.47508,-0.13180,13.22732,38.33719
50.75000,4.22933,792.38387,-0.13180,13.29477,38.38121
50.95000,4.24583,792.88175,-0.13180,13.36077,38.40532
51.15000,4.26245,793.20390,-0.13180,13.42726,38.42093
51.35000,4.27925,793.86067,-0.13180,13.49446,38.45274
51.55000,4.29582,794.39506,-0.13180,13.56071,38.47863
51.75000,4.31244,795.04680,-0.13180,13.62720,38.51019
51.95000,4.32918,795.70273,-0.13180,13.69416,38.54197
52.15000,4.34586,796.08345,-0.13180,13.76089,38.56041
52.35000,4.36248,797.53445,-0.13180,13.82737,38.63069
52.55000,4.37910,797.73124,-0.13180,13.89386,38.64022
52.75000,4.39584,798.05804,-0.13180,13.96082,38.65605
52.95000,4.41252,798.46280,-0.13180,14.02754,38.67566
53.15000,4.42915,798.80515,-0.13180,14.09403,38.69224
53.35000,4.44583,799.57983,-0.13180,14.16076,38.72976
53.55000,4.46251,800.52568,-0.13180,14.22748,38.77558
53.75000,4.47913,801.09378,-0.13180,14.29397,38.80310
53.95000,4.49581,800.90798,-0.13180,14.36069,38.79409
54.15000,4.51249,801.05998,-0.13180,14.42742,38.80146
54.35000,4.52911,802.30311,-0.13180,14.49391,38.86167
54.55000,4.54579,800.98510,-0.13180,14.56063,38.79783
54.75000,4.56248,802.29668,-0.13180,14.62735,38.86136
54.95000,4.57922,802.29454,-0.13180,14.69432,38.86126
55.15000,4.59590,802.97207,-0.13180,14.76104,38.89407
55.35000,4.61252,804.08007,-0.13180,14.82753,38.94774
55.55000,4.62914,804.08612,-0.13180,14.89402,38.94804
55.75000,4.64582,804.54247,-0.13180,14.96074,38.97014
55.95000,4.66250,805.27011,-0.13180,15.02746,39.00539
56.15000,4.67931,806.51371,-0.13180,15.09467,39.06562
56.35000,4.69587,806.43846,-0.13180,15.16092,39.06198
56.55000,4.71243,806.89341,-0.13180,15.22716,39.08401
56.75000,4.72917,807.66696,-0.13180,15.29413,39.12148
56.95000,4.74573,807.10435,-0.13180,15.36037,39.09423
57.15000,4.76247,808.64225,-0.13180,15.42734,39.16872
57.35000,4.77921,808.84527,-0.13180,15.49430,39.17856
57.55000,4.79577,809.32993,-0.13180,15.56055,39.20203
57.75000,4.81246,809.54172,-0.13180,15.62727,39.21229
57.95000,4.82920,809.91238,-0.13180,15.69424,39.23025
58.15000,4.84594,810.31080,-0.13180,15.76120,39.24955
58.35000,4.86250,810.60557,-0.13180,15.82745,39.26382
58.55000,4.87912,810.96906,-0.13180,15.89393,39.28143
58.75000,4.89586,811.88111,-0.13180,15.96090,39.32561
58.95000,4.91242,811.97526,-0.13180,16.02715,39.33017
59.15000,4.92917,812.43962,-0.13180,16.09411,39.35266
59.35000,4.94591,812.96731,-0.13180,16.16107,39.37822
59.55000,4.96247,813.30407,-0.13180,16.22732,39.39453
59.75000,4.97909,812.88330,-0.13180,16.29381,39.37415
59.95000,4.99583,813.59213,-0.13180,16.36077,39.40849
60.15000,5.01251,814.01663,-0.13180,16.42749,39.42905
60.35000,5.02925,814.58073,-0.13180,16.49446,39.45637
60.55000,5.04581,815.38139,-0.13180,16.56071,39.49515
60.75000,5.06256,815.29766,-0.13180,16.62767,39.49110
60.95000,5.07912,815.26814,-0.13180,16.69392,39.48967
61.15000,5.09580,816.29632,-0.13180,16.76064,39.53947
61.35000,5.11254,816.53632,-0.13180,16.82761,39.55109
61.55000,5.12910,816.76329,-0.13180,16.89385,39.56209
61.75000,5.14578,817.47137,-0.13180,16.96058,39.59639
61.95000,5.16246,817.14215,-0.13180,17.02730,39.58044
62.15000,5.17914,817.56087,-0.13180,17.09403,39.60072
62.35000,5.19583,817.46941,-0.13180,17.16075,39.59629
62.55000,5.21251,818.48493,-0.13180,17.22748,39.64548
62.75000,5.22913,818.94845,-0.13180,17.29396,39.66793
62.95000,5.24575,819.23632,-0.13180,17.36045,39.68188
63.15000,5.26249,819.40051,-0.13180,17.42742,39.68983
63.35000,5.27923,820.21086,-0.13180,17.49438,39.72908
63.55000,5.29585,819.79278,-0.13180,17.56086,39.70883
63.75000,5.31254,819.77025,-0.13180,17.62759,39.70774
63.95000,5.32916,820.68015,-0.13180,17.69407,39.75181
64.15000,5.34578,820.85235,-0.13180,17.76056,39.76015
64.35001,5.36246,820.98516,-0.13180,17.82729,39.76659
64.55000,5.37920,821.45873,-0.13180,17.89425,39.78952
64.75000,5.39582,821.29110,-0.13180,17.96074,39.78141
64.95000,5.41250,821.71261,-0.13180,18.02746,39.80182
65.15000,5.42912,822.42973,-0.13180,18.09395,39.83656
65.35001,5.44581,822.10805,-0.13180,18.16067,39.82098
65.55000,5.46249,822.00095,-0.13180,18.22740,39.81579
65.75000,5.47923,822.99914,-0.13180,18.29436,39.86414
65.95001,5.49591,823.05474,-0.13180,18.36109,39.86683
66.15000,5.51241,823.35463,-0.13180,18.42709,39.88136
66.35001,5.52915,824.04772,-0.13180,18.49406,39.91493
66.55000,5.54589,823.90029,-0.13180,18.56102,39.90779
66.75000,5.56257,823.90932,-0.13180,18.62775,39.90823
66.95001,5.57914,824.39007,-0.13180,18.69400,39.93151
67.15000,5.59582,824.69778,-0.13180,18.76072,39.94642
67.35001,5.61250,824.35776,-0.13180,18.82745,39.92995
67.55000,5.62918,824.51981,-0.13180,18.89417,39.93780
67.75000,5.64580,825.33592,-0.13180,18.96066,39.97733
67.95001,5.66248,824.84894,-0.13180,19.02738,39.95374
68.15000,5.67910,825.43427,-0.13180,19.09387,39.98209
68.35001,5.69579,826.04829,-0.13180,19.16059,40.01183
68.55000,5.71253,826.12867,-0.13180,19.22756,40.01572
68.75000,5.72915,826.68578,-0.13180,19.29404,40.04271
68.95001,5.74589,826.28978,-0.13180,19.36101,40.02353
69.15000,5.76251,826.14115,-0.13180,19.42749,40.01633
69.35001,5.77919,826.13677,-0.13180,19.49422,40.01612
69.55000,5.79581,826.50408,-0.13180,19.56071,40.03391
69.75000,5.81250,827.34926,-0.13180,19.62743,40.07485
69.95001,5.82924,827.61198,-0.13180,19.69439,40.08757
70.15000,5.84580,826.85659,-0.13180,19.76064,40.05098
70.35001,5.86242,827.76686,-0.13180,19.82713,40.09508
70.55000,5.87916,827.61580,-0.13180,19.89409,40.08776
70.75000,5.89584,827.90703,-0.13180,19.96082,40.10186
70.95001,5.91252,828.25748,-0.13180,20.02754,40.11884
71.15000,5.92920,827.97902,-0.13181,20.09427,40.10535
71.35001,5.94583,828.77548,-0.13180,20.16075,40.14393
71.55000,5.96245,828.45874,-0.13181,20.22724,40.12859
71.75000,5.97919,828.41422,-0.13180,20.29420,40.12643
71.95001,5.99593,829.31006,-0.13180,20.36117,40.16983
72.15000,6.01249,828.90205,-0.13180,20.42741,40.15006
72.35001,6.02911,828.96203,-0.13180,20.49390,40.15297
72.55000,6.04591,829.19719,-0.13180,20.56110,40.16436
72.75000,6.06247,829.25698,-0.13180,20.62735,40.16726
72.95001,6.07910,829.26312,-0.13180,20.69383,40.16755
73.15000,6.09584,830.14872,-0.13180,20.76080,40.21045
73.35001,6.11252,830.14732,-0.13180,20.82753,40.21038
73.55000,6.12914,829.77982,-0.13181,20.89401,40.19258
73.75000,6.14582,830.45550,-0.13180,20.96073,40.22531
73.95001,6.16250,830.36469,-0.13180,21.02746,40.22091
74.15000,6.17912,830.64819,-0.13180,21.09395,40.23464
74.35001,6.19581,830.77066,-0.13180,21.16067,40.24057
74.55000,6.21255,830.32353,-0.13180,21.22764,40.21891
74.75000,6.22905,830.90561,-0.13180,21.29364,40.24711
74.95001,6.24579,830.74532,-0.13180,21.36060,40.23935
75.15000,6.26253,831.23622,-0.13180,21.42757,40.26312
75.35001,6.27915,831.32014,-0.13180,21.49406,40.26719
75.55000,6.29577,830.89387,-0.13180,21.56054,40.24654
75.75000,6.31245,831.28372,-0.13180,21.62727,40.26543
75.95001,6.32914,831.53173,-0.13180,21.69399,40.27744
76.15000,6.34582,831.50864,-0.13180,21.76072,40.27632
76.35001,6.36256,831.08954,-0.13180,21.82768,40.25602
76.55000,6.37930,831.97867,-0.13180,21.89465,40.29909
76.75000,6.39574,832.35539,-0.13180,21.96041,40.31733
76.95001,6.41242,832.15972,-0.13180,22.02714,40.30786
77.15000,6.42922,831.97346,-0.13180,22.09434,40.29884
77.35001,6.44579,832.15209,-0.13180,22.16059,40.30749
77.55000,6.46253,832.27279,-0.13180,22.22755,40.31333
77.75000,6.47921,831.96815,-0.13180,22.29428,40.29858
77.95001,6.49583,832.56382,-0.13180,22.36077,40.32743
78.15000,6.51245,832.63600,-0.13180,22.42725,40.33092
78.35001,6.52913,832.33239,-0.13180,22.49398,40.31622
78.55000,6.54593,832.27120,-0.13180,22.56118,40.31326
78.75000,6.56249,832.27409,-0.13181,22.62743,40.31340
78.95001,6.57912,832.50124,-0.13180,22.69391,40.32440
79.15000,6.59598,833.22311,-0.13180,22.76136,40.35936
79.35001,6.61242,833.27396,-0.13180,22.82712,40.36183
79.55000,6.62916,833.12253,-0.13181,22.89409,40.35449
79.75000,6.64596,833.09989,-0.13180,22.96129,40.35340
79.95001,6.66252,833.06180,-0.13180,23.02754,40.35155
80.15000,6.67908,832.92201,-0.13180,23.09379,40.34478
80.35001,6.69583,833.16620,-0.13180,23.16075,40.35661
80.55000,6.71257,832.82515,-0.13181,23.22771,40.34009
80.75001,6.72913,833.13044,-0.13180,23.29396,40.35488
80.95001,6.74581,832.95675,-0.13180,23.36069,40.34646
81.15000,6.76255,833.41552,-0.13180,23.42765,40.36868
81.35001,6.77905,833.03489,-0.13180,23.49366,40.35025
81.55000,6.79579,833.12904,-0.13180,23.56062,40.35481
81.75001,6.81259,833.44048,-0.13180,23.62783,40.36989
81.95001,6.82916,832.90981,-0.13180,23.69407,40.34419
82.15000,6.84578,831.76997,-0.13180,23.76056,40.28898
82.35001,6.86246,831.83441,-0.13180,23.82728,40.29210
82.55000,6.87920,832.56885,-0.13180,23.89425,40.32767
82.75001,6.89582,832.33817,-0.13180,23.96073,40.31650
82.95001,6.91250,833.43377,-0.13180,24.02746,40.36957
83.15000,6.92918,832.79815,-0.13180,24.09418,40.33878
83.35001,6.94575,832.87572,-0.13180,24.16043,40.34254
83.55000,6.96237,833.07931,-0.13180,24.22692,40.35240
83.75001,6.97917,833.19172,-0.13180,24.29412,40.35785
83.95001,6.99585,833.70777,-0.13180,24.36084,40.38284
84.15000,7.01253,833.54600,-0.13181,24.42757,40.37500
84.35001,7.02915,833.11908,-0.13180,24.49406,40.35432
84.55000,7.04577,833.00043,-0.13180,24.56054,40.34858
84.75001,7.06251,833.63988,-0.13180,24.62751,40.37955
84.95001,7.07926,833.23177,-0.13180,24.69447,40.35978
85.15000,7.09594,833.67582,-0.13180,24.76119,40.38129
85.35001,7.11244,833.84579,-0.13181,24.82720,40.38953
85.55000,7.12912,833.61184,-0.13180,24.89393,40.37819
85.75001,7.14586,834.19448,-0.13180,24.96089,40.40641
85.95001,7.16248,833.57776,-0.13180,25.02738,40.37654
86.15000,7.17916,833.43713,-0.13181,25.09410,40.36973
86.35001,7.19584,833.84244,-0.13180,25.16083,40.38936
86.55000,7.21247,834.45171,-0.13180,25.22731,40.41887
86.75001,7.22909,834.28463,-0.13180,25.29380,40.41078
86.95001,7.24589,833.67145,-0.13181,25.36100,40.38108
87.15000,7.26263,833.98772,-0.13181,25.42797,40.39640
87.35001,7.27913,833.84989,-0.13180,25.49397,40.38972
87.55000,7.29581,833.69864,-0.13180,25.56070,40.38240
87.75001,7.31255,834.32849,-0.13180,25.62766,40.41291
87.95001,7.32918,833.74055,-0.13181,25.69415,40.38443
88.15000,7.34580,833.41738,-0.13180,25.76064,40.36877
88.35001,7.36254,833.14134,-0.13181,25.82760,40.35540
88.55000,7.37910,833.52346,-0.13181,25.89385,40.37391
88.75001,7.39578,833.54358,-0.13181,25.96057,40.37489
88.95001,7.41246,833.10371,-0.13180,26.02730,40.35358
89.15000,7.42920,833.44635,-0.13181,26.09426,40.37018
89.35001,7.44582,833.34316,-0.13180,26.16075,40.36518
89.55000,7.46251,833.04541,-0.13181,26.22747,40.35076
89.75001,7.47919,833.54535,-0.13180,26.29420,40.37497
89.95001,7.49587,833.64453,-0.13180,26.36092,40.37978
90.15000,7.51255,833.38208,-0.13181,26.42765,40.36707
90.35001,7.52923,832.88494,-0.13180,26.49437,40.34298
90.55000,7.54585,833.34511,-0.13181,26.56086,40.36527
90.75001,7.56253,833.65543,-0.13181,26.62758,40.38031
90.95001,7.57910,833.13622,-0.13180,26.69383,40.35516
91.15000,7.59584,833.11331,-0.13180,26.76080,40.35405
91.35001,7.61258,833.31401,-0.13180,26.82776,40.36377
91.55000,7.62914,833.10483,-0.13181,26.89400,40.35363
91.75001,7.64576,832.98739,-0.13180,26.96049,40.34795
91.95001,7.66250,832.29076,-0.13180,27.02745,40.31421
92.15000,7.67912,833.32919,-0.13180,27.09394,40.36450
92.35001,7.69586,832.32196,-0.13181,27.16091,40.31572
92.55000,7.71255,833.02092,-0.13180,27.22763,40.34957
92.75001,7.72917,833.11712,-0.13180,27.29412,40.35423
92.95001,7.74585,832.32662,-0.13180,27.36084,40.31594
93.15000,7.76247,832.96513,-0.13180,27.42733,40.34687
93.35001,7.77915,832.77673,-0.13180,27.49405,40.33774
93.55000,7.79583,832.56066,-0.13181,27.56078,40.32728
93.75001,7.81251,833.07587,-0.13180,27.62750,40.35223
93.95001,7.82907,832.48243,-0.13181,27.69375,40.32349
94.15000,7.84576,832.61132,-0.13181,27.76047,40.32973
94.35001,7.86256,832.56392,-0.13180,27.82768,40.32743
94.55000,7.87918,832.51540,-0.13180,27.89416,40.32508
94.75001,7.89586,832.15777,-0.13180,27.96089,40.30776
94.95001,7.91254,832.00708,-0.13180,28.02761,40.30046
95.15000,7.92910,832.64392,-0.13180,28.09386,40.33131
95.35001,7.94584,832.00904,-0.13181,28.16083,40.30056
95.55000,7.96253,831.41848,-0.13181,28.22755,40.27195
95.75001,7.97915,832.09584,-0.13181,28.29403,40.30476
95.95001,7.99583,831.80647,-0.13180,28.36076,40.29074
96.15000,8.01245,831.36847,-0.13180,28.42725,40.26953
96.35001,8.02919,831.71260,-0.13181,28.49421,40.28620
96.55000,8.04581,831.81001,-0.13180,28.56070,40.29092
96.75001,8.06243,831.34323,-0.13180,28.62718,40.26831
96.95001,8.07911,831.30859,-0.13180,28.69391,40.26663
97.15000,8.09580,831.23855,-0.13180,28.76063,40.26324
97.35001,8.11242,831.67674,-0.13180,28.82712,40.28446
97.55000,8.12916,830.59920,-0.13181,28.89408,40.23227
97.75001,8.14584,830.61736,-0.13181,28.96081,40.23315
97.95001,8.16258,830.60674,-0.13181,29.02777,40.23263
98.15000,8.17914,830.55906,-0.13180,29.09402,40.23032
98.35001,8.19582,830.44283,-0.13180,29.16075,40.22469
98.55000,8.21250,829.77898,-0.13180,29.22747,40.19254
98.75001,8.22913,830.79142,-0.13180,29.29395,40.24158
98.95001,8.24587,831.06449,-0.13181,29.36092,40.25481
99.15000,8.26249,829.79612,-0.13180,29.42740,40.19337
99.35001,8.27911,830.42812,-0.13180,29.49389,40.22398
99.55000,8.29579,830.65955,-0.13180,29.56061,40.23519
99.75001,8.31247,830.15179,-0.13181,29.62734,40.21060
99.95001,8.32921,829.90248,-0.13181,29.69430,40.19852
100.15000,8.34584,829.99403,-0.13180,29.76079,40.20295
100.35001,8.36252,830.07654,-0.13180,29.82752,40.20695
100.55000,8.37908,829.88227,-0.13181,29.89376,40.19754
100.75001,8.39582,829.73130,-0.13180,29.96073,40.19023
100.95001,8.41262,829.22084,-0.13180,30.02793,40.16550
101.15000,8.42912,829.78569,-0.13180,30.09394,40.19286
101.35001,8.44580,829.84138,-0.13180,30.16066,40.19556
101.55000,8.46254,829.19933,-0.13181,30.22763,40.16446
101.75001,8.47917,829.57689,-0.13180,30.29411,40.18275
101.95001,8.49573,829.36464,-0.13181,30.36036,40.17247
102.15000,8.51253,828.92384,-0.13180,30.42756,40.15112
102.35001,8.52921,828.91807,-0.13180,30.49429,40.15084
102.55000,8.54577,828.53753,-0.13180,30.56053,40.13240
102.75001,8.56245,828.83332,-0.13180,30.62726,40.14673
102.95001,8.57925,828.33804,-0.13180,30.69447,40.12274
103.15000,8.59582,828.68049,-0.13181,30.76071,40.13933
103.35001,8.61256,828.25311,-0.13181,30.82767,40.11863
103.55000,8.62924,828.37343,-0.13180,30.89440,40.12446
103.75001,8.64580,828.20570,-0.13180,30.96065,40.11633
103.95001,8.66248,828.14097,-0.13180,31.02737,40.11320
104.15000,8.67916,828.22023,-0.13180,31.09410,40.11703
104.35001,8.69584,828.22423,-0.13180,31.16083,40.11723
104.55000,8.71241,828.05874,-0.13180,31.22707,40.10921
104.75001,8.72909,827.48849,-0.13180,31.29379,40.08159
104.95001,8.74589,827.19019,-0.13180,31.36100,40.06714
105.15000,8.76251,827.29515,-0.13180,31.42748,40.07223
105.35001,8.77919,827.48318,-0.13180,31.49421,40.08134
105.55000,8.79593,826.75871,-0.13181,31.56117,40.04624
105.75001,8.81249,826.89328,-0.13181,31.62742,40.05276
105.95001,8.82917,826.55922,-0.13180,31.69414,40.03658
106.15000,8.84586,826.77407,-0.13180,31.76087,40.04699
106.35001,8.86254,826.59535,-0.13180,31.82760,40.03833
106.55000,8.87916,826.00294,-0.13180,31.89408,40.00964
106.75001,8.89584,826.91601,-0.13180,31.96080,40.05386
106.95001,8.91252,826.22636,-0.13180,32.02753,40.02046
107.15000,8.92902,826.42501,-0.13181,32.09354,40.03008
107.35001,8.94582,826.03274,-0.13181,32.16074,40.01108
107.55000,8.96256,826.24881,-0.13181,32.22770,40.02155
107.75001,8.97907,825.54659,-0.13181,32.29372,39.98753
107.95001,8.99581,825.59716,-0.13181,32.36068,39.98998
108.15000,9.01255,825.45783,-0.13181,32.42764,39.98323
108.35001,9.02911,825.46342,-0.13180,32.49389,39.98350
108.55000,9.04579,825.73295,-0.13181,32.56061,39.99656
108.75001,9.06265,825.03632,-0.13181,32.62806,39.96281
108.95001,9.07915,825.94091,-0.13181,32.69406,40.00663
109.15000,9.09578,825.20479,-0.13180,32.76055,39.97097
109.35001,9.11252,825.06407,-0.13180,32.82751,39.96416
109.55000,9.12926,824.44428,-0.13181,32.89448,39.93414
109.75001,9.14576,824.71212,-0.13181,32.96049,39.94711
109.95001,9.16244,825.05578,-0.13181,33.02721,39.96376
110.15000,9.17918,824.47436,-0.13181,33.09418,39.93560
110.35001,9.19580,824.07277,-0.13181,33.16066,39.91614
110.55000,9.21248,824.53992,-0.13181,33.22739,39.93877
110.75001,9.22929,823.68804,-0.13181,33.29459,39.89751
110.95001,9.24579,824.56600,-0.13180,33.36060,39.94003
111.15000,9.26247,823.05167,-0.13180,33.42732,39.86668
111.35001,9.27915,823.71980,-0.13180,33.49405,39.89905
111.55000,9.29583,823.14452,-0.13181,33.56077,39.87118
111.75001,9.31245,823.69568,-0.13181,33.62726,39.89788
111.95001,9.32919,822.96347,-0.13181,33.69422,39.86241
112.15000,9.34587,822.95043,-0.13180,33.76095,39.86178
112.35001,9.36244,822.84082,-0.13180,33.82719,39.85647
112.55000,9.37912,822.62391,-0.13181,33.89392,39.84596
112.75001,9.39586,822.16924,-0.13181,33.96088,39.82394
112.95001,9.41254,821.92551,-0.13181,34.02761,39.81213
113.15001,9.42916,821.42968,-0.13180,34.09410,39.78812
113.35001,9.44590,821.88752,-0.13180,34.16106,39.81030
113.55000,9.46252,821.65543,-0.13181,34.22755,39.79905
113.75001,9.47915,821.26902,-0.13181,34.29403,39.78034
113.95001,9.49589,821.40947,-0.13181,34.36099,39.78714
114.15001,9.51257,821.16667,-0.13180,34.42772,39.77538
114.35001,9.52907,820.97342,-0.13181,34.49373,39.76602
114.55000,9.54575,820.75372,-0.13181,34.56045,39.75537
114.75001,9.56255,820.63889,-0.13181,34.62766,39.74981
114.95001,9.57917,820.17370,-0.13181,34.69414,39.72728
115.15001,9.59579,820.21868,-0.13180,34.76063,39.72946
115.35001,9.61254,820.02701,-0.13181,34.82759,39.72018
115.55000,9.62916,819.57309,-0.13180,34.89408,39.69819
115.75001,9.64578,819.57672,-0.13180,34.96056,39.69836
115.95001,9.66252,819.72321,-0.13181,35.02753,39.70546
116.15001,9.67926,819.43870,-0.13181,35.09449,39.69168
116.35001,9.69576,818.93615,-0.13181,35.16050,39.66734
116.55000,9.71244,818.70090,-0.13181,35.22722,39.65594
116.75001,9.72924,818.39124,-0.13180,35.29443,39.64094
116.95001,9.74581,818.26421,-0.13181,35.36067,39.63479
117.15001,9.76255,818.47645,-0.13181,35.42764,39.64507
117.35001,9.77923,818.17014,-0.13181,35.49436,39.63023
117.55000,9.79579,818.73462,-0.13181,35.56061,39.65758
117.75001,9.81241,817.73810,-0.13180,35.62709,39.60931
117.95001,9.82909,817.16999,-0.13181,35.69382,39.58179
118.15001,9.84583,817.56031,-0.13181,35.76078,39.60070
118.35001,9.86252,816.02177,-0.13181,35.82751,39.52617
118.55000,9.87908,816.83286,-0.13181,35.89376,39.56546
118.75001,9.89588,816.24864,-0.13181,35.96096,39.53716
118.95001,9.91250,816.13101,-0.13181,36.02745,39.53146
119.15001,9.92918,816.05567,-0.13181,36.09417,39.52781
119.35001,9.94592,815.60798,-0.13181,36.16114,39.50613
119.55000,9.96254,815.99141,-0.13181,36.22762,39.52470
119.75001,9.97916,815.56737,-0.13181,36.29411,39.50416
119.95001,9.99579,814.94339,-0.13181,36.36059,39.47394
120.15001,10.01247,814.48480,-0.13180,36.42732,39.45173
120.35001,10.02915,814.74073,-0.13181,36.49404,39.46412
120.55000,10.04577,814.02976,-0.13181,36.56053,39.42968
120.75001,10.06251,814.21472,-0.13181,36.62750,39.43864
120.95001,10.07913,813.71870,-0.13181,36.69398,39.41462
121.15001,10.09581,813.22882,-0.13181,36.76070,39.39089
121.35001,10.11261,813.27092,-0.13180,36.82791,39.39293
121.55000,10.12918,813.01890,-0.13181,36.89416,39.38072
121.75001,10.14586,812.84251,-0.13181,36.96088,39.37218
121.95001,10.16254,812.26919,-0.13181,37.02761,39.34441
122.15001,10.17916,811.99659,-0.13180,37.09410,39.33120
122.35001,10.19578,811.73079,-0.13180,37.16058,39.31833
122.55000,10.21252,812.13126,-0.13181,37.22754,39.33772
122.75001,10.22920,811.35528,-0.13181,37.29427,39.30014
122.95001,10.24577,811.24017,-0.13181,37.36051,39.29456
123.15001,10.26245,810.42973,-0.13181,37.42724,39.25531
123.35001,10.27925,809.98614,-0.13181,37.49444,39.23382
123.55000,10.29587,809.85166,-0.13181,37.56093,39.22731
123.75001,10.31249,809.24323,-0.13181,37.62741,39.19783
123.95001,10.32917,809.37147,-0.13181,37.69414,39.20405
124.15001,10.34579,809.04644,-0.13180,37.76062,39.18830
124.35001,10.36247,809.15866,-0.13181,37.82735,39.19374
124.55000,10.37922,808.26664,-0.13181,37.89431,39.15053
124.75001,10.39590,808.10562,-0.13181,37.96104,39.14273
124.95001,10.41246,807.39399,-0.13181,38.02728,39.10826
125.15001,10.42908,807.58762,-0.13181,38.09377,39.11764
125.35001,10.44582,806.93588,-0.13181,38.16074,39.08607
125.55000,10.46244,806.53457,-0.13181,38.22722,39.06664
125.75001,10.47918,806.45001,-0.13181,38.29419,39.06254
125.95001,10.49581,805.61368,-0.13181,38.36067,39.02203
126.15001,10.51249,805.70141,-0.13181,38.42739,39.02628
126.35001,10.52917,805.01502,-0.13181,38.49412,38.99303
126.55000,10.54579,805.10695,-0.13180,38.56061,38.99748
126.75001,10.56253,804.09469,-0.13181,38.62757,38.94845
126.95001,10.57921,803.98573,-0.13180,38.69430,38.94317
127.15001,10.59577,803.54325,-0.13181,38.76055,38.92174
127.35001,10.61245,803.05813,-0.13180,38.82727,38.89824
127.55000,10.62914,802.97720,-0.13181,38.89399,38.89433
127.75001,10.64582,802.61808,-0.13181,38.96072,38.87693
127.95001,10.66256,802.20532,-0.13180,39.02769,38.85693
128.15001,10.67912,801.96047,-0.13180,39.09393,38.84508
128.35001,10.69574,801.14547,-0.13181,39.16042,38.80560
128.55000,10.71248,800.57029,-0.13181,39.22738,38.77774
128.75000,10.72922,800.19692,-0.13181,39.29434,38.75965
128.95002,10.74585,799.71654,-0.13181,39.36083,38.73639
129.15001,10.76253,798.97186,-0.13181,39.42755,38.70031
129.35001,10.77915,799.10560,-0.13181,39.49404,38.70679
129.55000,10.79577,798.24049,-0.13181,39.56053,38.66489
129.75000,10.81245,797.90140,-0.13181,39.62725,38.64846
129.95002,10.82925,797.22125,-0.13181,39.69446,38.61552
130.15001,10.84587,796.27801,-0.13181,39.76094,38.56983
130.35001,10.86249,796.80514,-0.13181,39.82743,38.59536
130.55000,10.87924,796.14017,-0.13181,39.89440,38.56315
130.75000,10.89586,795.11302,-0.13181,39.96088,38.51340
130.95002,10.91248,794.41108,-0.13181,40.02737,38.47940
131.15002,10.92916,793.86299,-0.13181,40.09409,38.45285
131.35000,10.94578,793.97615,-0.13181,40.16058,38.45833
131.55000,10.96240,792.44943,-0.13181,40.22706,38.38438
131.75000,10.97914,791.78531,-0.13181,40.29402,38.35221
131.95002,10.99588,791.37478,-0.13181,40.36099,38.33233
132.15002,11.01251,790.84141,-0.13181,40.42747,38.30650
132.35000,11.02913,790.43526,-0.13181,40.49396,38.28682
132.55000,11.04587,789.43726,-0.13181,40.56093,38.23848
132.75000,11.06249,788.90575,-0.13181,40.62741,38.21273
132.95002,11.07911,788.07836,-0.13181,40.69390,38.17266
133.15002,11.09585,787.34607,-0.13181,40.76086,38.13719
133.35000,11.11253,786.52259,-0.13181,40.82758,38.09730
133.55000,11.12904,785.35378,-0.13181,40.89359,38.04069
133.75000,11.14578,784.76770,-0.13181,40.96056,38.01230
133.95002,11.16252,784.32020,-0.13181,41.02752,37.99062
134.15002,11.17920,782.94780,-0.13181,41.09425,37.92415
134.35000,11.19588,782.29085,-0.13181,41.16097,37.89233
134.55000,11.21256,781.95045,-0.13181,41.22770,37.87584
134.75000,11.22912,781.24534,-0.13181,41.29394,37.84168
134.95002,11.24581,780.42252,-0.13181,41.36067,37.80183
135.15002,11.26255,779.06395,-0.13181,41.42763,37.73602
135.35000,11.27923,778.16439,-0.13181,41.49436,37.69245
135.55000,11.29579,776.62752,-0.13181,41.56061,37.61801
135.75000,11.31247,776.11418,-0.13181,41.62733,37.59314
135.95002,11.32921,775.46649,-0.13181,41.69430,37.56177
136.15002,11.34583,774.62443,-0.13181,41.76078,37.52098
136.35000,11.36251,773.43257,-0.13181,41.82750,37.46325
136.55000,11.37926,772.24239,-0.13181,41.89447,37.40560
136.75000,11.39582,771.43740,-0.13181,41.96072,37.36661
136.95002,11.41238,770.40135,-0.13181,42.02696,37.31643
137.15002,11.42924,769.38835,-0.13181,42.09441,37.26736
137.35000,11.44586,767.94224,-0.13181,42.16089,37.19731
137.55000,11.46254,766.54307,-0.13180,42.22762,37.12954
137.75000,11.47916,765.86371,-0.13181,42.29410,37.09663
137.95002,11.49590,764.31646,-0.13181,42.36107,37.02169
138.15002,11.51247,763.43711,-0.13181,42.42731,36.97910
138.35000,11.52915,761.87341,-0.13181,42.49404,36.90335
138.55000,11.54589,760.19978,-0.13181,42.56100,36.82228
138.75000,11.56245,758.76154,-0.13181,42.62725,36.75262
138.95002,11.57907,756.97922,-0.13181,42.69374,36.66629
139.15002,11.59587,754.21561,-0.13181,42.76094,36.53243
139.35000,11.61243,752.64880,-0.13181,42.82719,36.45654
139.55000,11.62917,749.74424,-0.13180,42.89415,36.31585
139.75000,11.64586,746.50324,-0.13181,42.96088,36.15886
139.95002,11.66254,742.31024,-0.13180,43.02760,35.95576
140.15002,11.67916,737.29507,-0.13181,43.09408,35.71284
140.35000,11.69578,729.32770,-0.13181,43.16058,35.32692
140.55000,11.71252,718.53870,-0.13181,43.22754,34.80432
140.75000,11.72914,695.77773,-0.13180,43.29402,33.70184
140.81402,11.73464,4.84002,-0.13180,43.31603,0.23444