File: Manufatura Aditiva/Dados/Ensaios AMR/Ensaios/Ensaios SLS/Tracao_OLABI_07_06_2018_SLS_XZ2.is_metal_RawData/Specimen_RawData_1.csv
Time,Extension,Load,Strain 1,Tensile strain,Tensile stress
(sec),(mm),(N),(mm/mm),(%),(MPa)
0.00000,0.00006,13.34519,0.00048,0.04804,0.67362
0.20000,0.01208,18.89449,0.00063,0.06257,0.95373
0.40000,0.03229,28.96887,0.00095,0.09473,1.46225
0.60000,0.04980,37.74062,0.00123,0.12313,1.90501
0.80000,0.06667,45.87830,0.00150,0.14975,2.31578
1.00000,0.08335,54.41919,0.00176,0.17633,2.74689
1.20000,0.10009,62.42301,0.00203,0.20307,3.15089
1.40000,0.11677,69.26406,0.00225,0.22540,3.49621
1.60000,0.13339,77.54025,0.00251,0.25142,3.91396
1.80000,0.14995,84.22903,0.00278,0.27797,4.25159
2.00000,0.16657,92.25302,0.00305,0.30516,4.65661
2.20000,0.18331,99.97487,0.00332,0.33246,5.04638
2.40000,0.19994,107.57605,0.00359,0.35856,5.43006
2.60000,0.21668,115.16649,0.00385,0.38522,5.81320
2.80000,0.23336,122.84396,0.00412,0.41216,6.20073
3.00000,0.24998,128.93063,0.00436,0.43611,6.50797
3.20000,0.26672,135.71028,0.00463,0.46276,6.85018
3.40000,0.28340,143.42356,0.00490,0.48951,7.23952
3.60000,0.30002,150.71405,0.00517,0.51708,7.60752
3.80000,0.31665,157.92863,0.00544,0.54363,7.97168
4.00000,0.33327,164.32753,0.00570,0.57042,8.29468
4.20000,0.34995,171.29933,0.00594,0.59408,8.64659
4.40000,0.36663,177.77610,0.00621,0.62129,8.97352
4.60000,0.38331,184.19264,0.00648,0.64802,9.29740
4.80000,0.39999,191.74416,0.00674,0.67425,9.67857
5.00000,0.41667,198.13669,0.00701,0.70114,10.00125
5.20000,0.43335,204.77688,0.00727,0.72697,10.33642
5.40000,0.45010,210.52614,0.00751,0.75137,10.62662
5.60000,0.46672,216.63706,0.00777,0.77728,10.93508
5.80000,0.48334,223.60070,0.00803,0.80325,11.28658
6.00000,0.50002,230.16473,0.00830,0.83044,11.61791
6.20000,0.51664,235.77535,0.00853,0.85344,11.90111
6.40000,0.53332,242.52583,0.00879,0.87925,12.24185
6.60000,0.55000,248.89943,0.00906,0.90595,12.56357
6.80000,0.56674,254.77973,0.00932,0.93246,12.86039
7.00000,0.58331,260.26755,0.00955,0.95471,13.13739
7.20000,0.59993,266.46934,0.00980,0.98045,13.45044
7.40000,0.61667,272.04226,0.01006,1.00648,13.73174
7.60000,0.63329,276.80076,0.01029,1.02880,13.97193
7.80000,0.64997,283.32304,0.01054,1.05449,14.30116
8.00000,0.66671,289.35021,0.01081,1.08058,14.60539
8.20000,0.68333,293.20573,0.01102,1.10223,14.80000
8.40000,0.70002,299.54149,0.01129,1.12862,15.11981
8.60000,0.71664,305.47900,0.01154,1.15444,15.41951
8.80000,0.73344,309.59197,0.01176,1.17614,15.62712
9.00000,0.75000,314.94237,0.01201,1.20134,15.89719
9.20000,0.76662,320.08945,0.01226,1.22618,16.15699
9.40000,0.78336,324.82354,0.01250,1.24967,16.39595
9.60000,0.79992,330.96860,0.01275,1.27467,16.70614
9.80000,0.81666,334.61333,0.01296,1.29623,16.89011
10.00000,0.83341,339.73216,0.01321,1.32132,17.14849
10.20000,0.84997,343.67698,0.01343,1.34296,17.34761
10.40000,0.86671,348.45439,0.01368,1.36816,17.58876
10.60000,0.88333,353.27577,0.01390,1.38955,17.83212
10.80000,0.90007,357.39604,0.01412,1.41249,18.04010
11.00000,0.91669,361.36056,0.01435,1.43492,18.24022
11.20000,0.93331,364.99358,0.01456,1.45583,18.42360
11.40000,0.95000,370.03276,0.01480,1.48039,18.67796
11.60000,0.96656,373.22545,0.01501,1.50093,18.83911
11.80000,0.98330,377.73957,0.01524,1.52364,19.06697
12.00000,1.00004,381.41685,0.01546,1.54595,19.25259
12.20000,1.01666,384.02649,0.01566,1.56634,19.38431
12.40000,1.03334,390.13098,0.01591,1.59124,19.69245
12.60000,1.05002,393.25948,0.01612,1.61225,19.85036
12.80000,1.06664,397.12754,0.01635,1.63545,20.04561
13.00000,1.08333,401.08124,0.01659,1.65875,20.24518
13.20000,1.10001,404.72019,0.01680,1.67954,20.42886
13.40000,1.11675,409.11348,0.01705,1.70465,20.65062
13.60000,1.13325,412.60952,0.01726,1.72603,20.82708
13.80000,1.14993,416.38822,0.01752,1.75158,21.01782
14.00000,1.16673,419.91337,0.01774,1.77421,21.19576
14.20000,1.18329,423.43200,0.01796,1.79629,21.37337
14.40000,1.19998,427.60754,0.01822,1.82155,21.58413
14.60000,1.21672,430.70950,0.01844,1.84398,21.74071
14.80000,1.23334,435.53947,0.01870,1.87044,21.98451
15.00000,1.24996,438.52092,0.01893,1.89309,22.13500
15.20000,1.26664,442.50921,0.01919,1.91917,22.33632
15.40000,1.28338,445.80288,0.01941,1.94123,22.50257
15.60000,1.29994,449.47071,0.01966,1.96632,22.68771
15.80000,1.31656,452.79153,0.01992,1.99155,22.85533
16.00000,1.33343,456.57712,0.02015,2.01545,23.04641
16.20000,1.34993,460.32993,0.02041,2.04143,23.23584
16.40000,1.36667,463.67268,0.02065,2.06535,23.40457
16.60000,1.38341,467.18195,0.02093,2.09262,23.58171
16.80000,1.39997,470.89667,0.02116,2.11645,23.76921
17.00000,1.41659,474.41907,0.02143,2.14309,23.94701
17.20000,1.43333,477.20154,0.02168,2.16766,24.08746
17.40000,1.45001,481.27468,0.02195,2.19461,24.29306
17.60000,1.46664,484.26078,0.02219,2.21916,24.44379
17.80000,1.48326,487.49777,0.02245,2.24533,24.60718
18.00000,1.50000,490.71321,0.02273,2.27263,24.76949
18.20000,1.51662,494.05079,0.02298,2.29792,24.93795
18.40000,1.53330,497.58330,0.02325,2.32492,25.11626
18.60000,1.55004,499.89354,0.02350,2.35031,25.23288
18.80000,1.56666,503.83387,0.02378,2.37801,25.43177
19.00000,1.58341,506.84665,0.02405,2.40510,25.58384
19.20000,1.60003,509.64491,0.02432,2.43238,25.72509
19.40000,1.61665,513.04814,0.02459,2.45900,25.89687
19.60000,1.63339,515.78623,0.02486,2.48601,26.03508
19.80000,1.65001,518.58486,0.02514,2.51385,26.17635
20.00000,1.66663,522.13240,0.02542,2.54160,26.35542
20.20000,1.68325,524.21060,0.02569,2.56909,26.46032
20.40000,1.69993,527.43186,0.02597,2.59702,26.62291
20.60000,1.71668,530.18350,0.02625,2.62496,26.76181
20.80000,1.73336,532.57826,0.02653,2.65262,26.88268
21.00000,1.74992,535.62149,0.02681,2.68064,27.03630
21.20000,1.76672,537.43087,0.02709,2.70865,27.12763
21.40000,1.78334,539.88239,0.02736,2.73629,27.25137
21.60000,1.80002,542.46038,0.02763,2.76306,27.38150
21.80000,1.81682,545.65533,0.02792,2.79183,27.54277
22.00000,1.83339,548.19304,0.02819,2.81906,27.67087
22.20000,1.84995,550.53392,0.02848,2.84784,27.78902
22.40000,1.86669,552.70866,0.02877,2.87698,27.89880
22.60000,1.88337,555.24549,0.02904,2.90393,28.02685
22.80000,1.89987,558.20653,0.02934,2.93411,28.17631
23.00000,1.91661,560.18145,0.02963,2.96253,28.27600
23.20000,1.93335,562.36396,0.02991,2.99095,28.38616
23.40000,1.94997,565.68477,0.03022,3.02187,28.55379
23.60000,1.96666,567.16306,0.03049,3.04904,28.62840
23.80000,1.98340,569.42641,0.03079,3.11600,28.74265
23.99000,1.99924,572.99733,0.03109,3.17938,28.92290
24.19000,2.01586,574.19804,0.03138,3.24586,28.98351
24.39000,2.03248,576.42846,0.03167,3.31235,29.09609
24.59000,2.04923,579.27384,0.03199,3.37931,29.23972
24.79000,2.06585,581.85477,0.03229,3.44580,29.36999
24.99000,2.08247,583.53357,0.03257,3.51229,29.45473
25.19000,2.09915,586.76167,0.03289,3.57901,29.61767
25.39000,2.11577,588.37729,0.03321,3.64550,29.69922
25.59000,2.13245,589.95569,0.03349,3.71222,29.77890
25.79000,2.14913,592.94924,0.03381,3.77895,29.93000
25.99000,2.16587,594.90926,0.03436,3.84591,30.02894
26.19000,2.18262,595.63289,0.03401,3.91288,30.06546
26.39000,2.19918,597.08403,0.00125,3.97912,30.13871
26.59000,2.21586,600.75140,0.00480,4.04585,30.32383
26.79000,2.23254,603.08562,0.00077,4.11257,30.44165
26.99000,2.24916,604.20283,-0.00035,4.17906,30.49804
27.19000,2.26590,606.26711,0.00133,4.24602,30.60224
27.39000,2.28252,608.70033,0.00189,4.31251,30.72506
27.59000,2.29915,609.62518,0.00171,4.37900,30.77174
27.79000,2.31583,612.35256,0.00119,4.44572,30.90941
27.99000,2.33251,613.98633,0.00055,4.51245,30.99188
28.19000,2.34919,616.64120,-0.01843,4.57917,31.12589
28.39000,2.36581,617.60815,-0.13635,4.64566,31.17470
28.59000,2.38249,619.34944,-0.12810,4.71238,31.26259
28.79000,2.39917,621.53726,-0.12808,4.77911,31.37302
28.99000,2.41579,624.34757,-0.12788,4.84559,31.51488
29.19000,2.43254,624.75749,-0.12797,4.91256,31.53557
29.39000,2.44916,626.92692,-0.12807,4.97904,31.64507
29.59000,2.46584,629.01550,-0.12815,5.04577,31.75050
29.79000,2.48258,630.93808,-0.12821,5.11273,31.84754
29.99000,2.49914,631.89985,-0.12826,5.17898,31.89609
30.19000,2.51582,634.28842,-0.12829,5.24570,32.01666
30.39000,2.53256,636.30389,-0.12831,5.31267,32.11839
30.59000,2.54918,637.62022,-0.12834,5.37915,32.18484
30.79000,2.56581,639.63789,-0.12835,5.44564,32.28668
30.99000,2.58243,640.41442,-0.12836,5.51213,32.32588
31.19000,2.59917,642.56308,-0.12836,5.57909,32.43433
31.39000,2.61579,644.98368,-0.12838,5.64558,32.55652
31.59000,2.63247,646.19244,-0.12839,5.71230,32.61753
31.79000,2.64921,647.07436,-0.12840,5.77926,32.66205
31.99000,2.66577,648.98166,-0.12840,5.84551,32.75832
32.19000,2.68252,651.15117,-0.12842,5.91248,32.86783
32.39000,2.69920,653.21722,-0.12841,5.97920,32.97212
32.59000,2.71588,654.54026,-0.12841,6.04593,33.03890
32.79000,2.73256,655.03889,-0.12842,6.11265,33.06407
32.99000,2.74912,657.57148,-0.12841,6.17890,33.19191
33.19000,2.76586,659.34537,-0.12842,6.24586,33.28144
33.39000,2.78254,661.09006,-0.12840,6.31259,33.36951
33.59000,2.79916,662.58274,-0.12840,6.37907,33.44485
33.79000,2.81585,662.20094,-0.12839,6.44580,33.42558
33.99000,2.83241,664.78769,-0.12840,6.51204,33.55616
34.19000,2.84903,666.64694,-0.12839,6.57853,33.65000
34.39000,2.86583,668.13077,-0.12840,6.64573,33.72490
34.59000,2.88257,669.87984,-0.12840,6.71270,33.81319
34.79000,2.89919,671.14267,-0.12839,6.77918,33.87693
34.99000,2.91587,671.27137,-0.12839,6.84591,33.88343
35.19000,2.93249,673.25099,-0.12838,6.91239,33.98335
35.39000,2.94912,675.34568,-0.12839,6.97888,34.08908
35.59000,2.96592,676.86946,-0.12839,7.04608,34.16600
35.79000,2.98260,678.07930,-0.12839,7.11281,34.22707
35.99000,2.99910,678.41345,-0.12837,7.17882,34.24393
36.19000,3.01572,679.78082,-0.12837,7.24530,34.31295
36.39000,3.03252,681.71099,-0.12839,7.31251,34.41039
36.59000,3.04908,683.02574,-0.12837,7.37875,34.47675
36.79000,3.06583,684.19157,-0.12837,7.44572,34.53559
36.99000,3.08263,685.94278,-0.12837,7.51292,34.62399
37.19000,3.09913,688.11313,-0.12837,7.57893,34.73354
37.39000,3.11581,687.61986,-0.12836,7.64565,34.70864
37.59000,3.13255,689.27407,-0.12836,7.71262,34.79214
37.79000,3.14923,690.66202,-0.12835,7.77934,34.86220
37.99000,3.16579,692.68108,-0.12834,7.84559,34.96412
38.19000,3.18248,693.69692,-0.12834,7.91231,35.01539
38.39000,3.19916,694.95472,-0.12834,7.97904,35.07888
38.59000,3.21578,694.61353,-0.12835,8.04553,35.06166
38.79000,3.23246,696.81127,-0.12834,8.11225,35.17259
38.99000,3.24914,698.19852,-0.12833,8.17898,35.24261
39.19000,3.26582,699.70414,-0.12833,8.24570,35.31861
39.39000,3.28250,700.88371,-0.12833,8.31243,35.37815
39.59000,3.29912,702.54551,-0.12834,8.37891,35.46204
39.79000,3.31581,703.74245,-0.12833,8.44564,35.52245
39.99000,3.33255,703.11124,-0.12833,8.51260,35.49059
40.19000,3.34923,704.98884,-0.12832,8.57933,35.58537
40.39000,3.36585,705.89185,-0.12832,8.64581,35.63095
40.59000,3.38247,708.12604,-0.12832,8.71230,35.74372
40.79000,3.39915,709.16484,-0.12831,8.77902,35.79616
40.99000,3.41595,709.93146,-0.12831,8.84623,35.83485
41.19000,3.43251,711.45580,-0.12831,8.91247,35.91180
41.39000,3.44908,713.26750,-0.12830,8.97872,36.00325
41.59000,3.46582,712.28696,-0.12830,9.04568,35.95375
41.79000,3.48250,714.21587,-0.12831,9.11241,36.05112
41.99000,3.49918,714.83757,-0.12830,9.17913,36.08250
42.19000,3.51586,716.60918,-0.12829,9.24586,36.17192
42.39000,3.53260,717.73557,-0.12829,9.31282,36.22878
42.59000,3.54910,719.03560,-0.12829,9.37883,36.29440
42.79000,3.56573,720.12618,-0.12829,9.44532,36.34945
42.99000,3.58259,721.27855,-0.12828,9.51276,36.40762
43.19000,3.59909,720.75855,-0.12827,9.57877,36.38137
43.39000,3.61571,722.00648,-0.12828,9.64525,36.44436
43.59000,3.63251,723.22935,-0.12827,9.71246,36.50608
43.79000,3.64913,724.63052,-0.12827,9.77894,36.57681
43.99000,3.66575,725.91635,-0.12828,9.84543,36.64172
44.19000,3.68255,727.02006,-0.12827,9.91263,36.69743
44.39000,3.69930,728.19381,-0.12827,9.97960,36.75667
44.59000,3.71574,729.05892,-0.12827,10.04536,36.80034
44.79000,3.73248,730.26395,-0.12827,10.11233,36.86117
44.99000,3.74928,730.38666,-0.12827,10.17953,36.86736
45.19000,3.76578,730.75374,-0.12826,10.24554,36.88589
45.39000,3.78246,732.09326,-0.12826,10.31227,36.95350
45.59000,3.79920,733.05997,-0.12825,10.37923,37.00230
45.79000,3.81583,733.77155,-0.12826,10.44572,37.03822
45.99000,3.83245,735.15824,-0.12826,10.51220,37.10822
46.19000,3.84925,736.45692,-0.12826,10.57940,37.17377
46.39000,3.86587,736.73120,-0.12823,10.64589,37.18761
46.59000,3.88249,738.01666,-0.12825,10.71238,37.25249
46.79000,3.89911,738.54900,-0.12825,10.77886,37.27937
46.99000,3.91585,739.28987,-0.12824,10.84583,37.31676
47.19000,3.93247,739.11222,-0.12823,10.91231,37.30780
47.39000,3.94910,739.97988,-0.12823,10.97880,37.35159
47.59000,3.96590,741.02059,-0.12823,11.04600,37.40413
47.79000,3.98246,742.25897,-0.12823,11.11225,37.46663
47.99000,3.99914,742.83592,-0.12823,11.17897,37.49575
48.19000,4.01582,744.16678,-0.12823,11.24570,37.56293
48.39000,4.03250,744.70835,-0.12822,11.31242,37.59027
48.59000,4.04918,746.05714,-0.12821,11.37915,37.65835
48.79000,4.06580,746.89058,-0.12822,11.44563,37.70042
48.99000,4.08255,747.82381,-0.12822,11.51260,37.74753
49.19000,4.09911,748.65702,-0.12821,11.57885,37.78959
49.39000,4.11579,748.22535,-0.12821,11.64557,37.76780
49.59000,4.13259,748.24952,-0.12821,11.71277,37.76902
49.79000,4.14915,749.54089,-0.12820,11.77902,37.83420
49.99000,4.16577,750.70937,-0.12822,11.84551,37.89318
50.19000,4.18257,751.82505,-0.12822,11.91271,37.94950
50.39000,4.19908,752.97211,-0.12819,11.97872,38.00740
50.59000,4.21588,752.98906,-0.12819,12.04592,38.00825
50.79000,4.23256,754.13333,-0.12819,12.11265,38.06601
50.99000,4.24918,755.07150,-0.12820,12.17913,38.11337
51.19000,4.26580,755.82843,-0.12819,12.24562,38.15157
51.39000,4.28254,756.07914,-0.12819,12.31258,38.16423
51.59000,4.29922,757.12539,-0.12818,12.37931,38.21704
51.79000,4.31578,757.79282,-0.12819,12.44555,38.25073
51.99000,4.33241,758.83297,-0.12818,12.51204,38.30323
52.19000,4.34921,757.88731,-0.12818,12.57924,38.25550
52.39000,4.36583,758.43297,-0.12818,12.64573,38.28304
52.59000,4.38251,759.89761,-0.12818,12.71245,38.35697
52.79000,4.39913,760.25971,-0.12817,12.77894,38.37525
52.99000,4.41587,760.95322,-0.12817,12.84591,38.41026
53.19000,4.43249,761.92459,-0.12817,12.91239,38.45929
53.39000,4.44918,762.68003,-0.12817,12.97912,38.49742
53.59000,4.46592,763.08870,-0.12816,13.04608,38.51804
53.79000,4.48254,764.13471,-0.12817,13.11257,38.57084
53.99000,4.49916,764.44228,-0.12816,13.17905,38.58637
54.19000,4.51578,764.64433,-0.12816,13.24554,38.59657
54.39000,4.53246,766.15587,-0.12816,13.31226,38.67287
54.59000,4.54914,765.84788,-0.12816,13.37899,38.65732
54.79000,4.56576,767.17199,-0.12815,13.44547,38.72416
54.99000,4.58257,767.50219,-0.12816,13.51268,38.74082
55.19000,4.59925,766.58600,-0.12816,13.57940,38.69458
55.39000,4.61581,767.61241,-0.12815,13.64565,38.74639
55.59000,4.63249,768.38471,-0.12814,13.71237,38.78537
55.79000,4.64917,769.44204,-0.12814,13.77910,38.83874
55.99000,4.66585,769.80977,-0.12815,13.84582,38.85730
56.19000,4.68259,770.53867,-0.12815,13.91279,38.89409
56.39000,4.69916,771.44285,-0.12814,13.97904,38.93973
56.59000,4.71578,772.07219,-0.12813,14.04552,38.97150
56.79000,4.73246,772.78148,-0.12813,14.11225,39.00730
56.99000,4.74914,772.97655,-0.12814,14.17897,39.01715
57.19000,4.76582,773.55066,-0.12813,14.24570,39.04613
57.39000,4.78244,773.58875,-0.12813,14.31218,39.04805
57.59000,4.79912,774.45274,-0.12813,14.37891,39.09166
57.79000,4.81580,775.20842,-0.12812,14.44563,39.12981
57.99000,4.83255,775.97736,-0.12812,14.51260,39.16862
58.19000,4.84929,776.31245,-0.12813,14.57956,39.18554
58.39000,4.86585,776.67870,-0.12812,14.64581,39.20402
58.59000,4.88253,776.73192,-0.12812,14.71253,39.20671
58.79000,4.89915,777.91871,-0.12812,14.77902,39.26661
58.99000,4.91577,776.29872,-0.12811,14.84551,39.18484
59.19000,4.93245,777.33747,-0.12810,14.91223,39.23727
59.39000,4.94919,778.54032,-0.12811,14.97919,39.29799
59.59000,4.96582,778.17859,-0.12811,15.04568,39.27973
59.79000,4.98244,779.61688,-0.12810,15.11216,39.35233
59.99000,4.99912,779.25147,-0.12810,15.17889,39.33389
60.19000,5.01586,780.57824,-0.12811,15.24585,39.40086
60.39000,5.03254,780.76939,-0.12811,15.31258,39.41050
60.59000,5.04916,780.86532,-0.12811,15.37906,39.41535
60.79000,5.06584,782.26728,-0.12810,15.44579,39.48611
60.99000,5.08247,782.20125,-0.12810,15.51228,39.48278
61.19000,5.09909,782.88345,-0.12810,15.57876,39.51722
61.39000,5.11583,783.65896,-0.12811,15.64573,39.55636
61.59000,5.13245,783.69202,-0.12810,15.71221,39.55803
61.79000,5.14913,784.06902,-0.12808,15.77894,39.57706
61.99000,5.16581,784.52248,-0.12808,15.84566,39.59995
62.19000,5.18249,785.23811,-0.12809,15.91239,39.63607
62.39000,5.19917,785.29045,-0.12809,15.97911,39.63871
62.59000,5.21586,786.57037,-0.12809,16.04584,39.70332
62.79000,5.23248,786.36818,-0.12808,16.11232,39.69311
62.99000,5.24916,786.58685,-0.12807,16.17905,39.70415
63.19000,5.26578,786.72944,-0.12807,16.24554,39.71135
63.39000,5.28258,787.05922,-0.12807,16.31274,39.72799
63.59000,5.29920,787.65955,-0.12808,16.37923,39.75830
63.79000,5.31588,786.22047,-0.12807,16.44595,39.68566
63.99000,5.33245,787.07784,-0.12806,16.51220,39.72894
64.19000,5.34913,787.70425,-0.12806,16.57892,39.76055
64.39000,5.36581,787.98803,-0.12808,16.64565,39.77488
64.59000,5.38249,788.37844,-0.12807,16.71237,39.79458
64.79000,5.39923,788.41858,-0.12806,16.77934,39.79661
64.99000,5.41579,788.84969,-0.12806,16.84558,39.81837
65.19000,5.43241,789.87954,-0.12805,16.91207,39.87035
65.39000,5.44915,790.11749,-0.12807,16.97903,39.88236
65.59001,5.46578,790.77957,-0.12806,17.04552,39.91578
65.79000,5.48252,790.47354,-0.12806,17.11248,39.90034
65.99001,5.49926,791.12574,-0.12805,17.17945,39.93326
66.19000,5.51582,791.79639,-0.12805,17.24569,39.96711
66.39000,5.53250,792.39663,-0.12805,17.31242,39.99741
66.59001,5.54918,792.33516,-0.12806,17.37914,39.99430
66.79000,5.56592,792.83332,-0.12806,17.44611,40.01945
66.99001,5.58254,793.32860,-0.12805,17.51259,40.04445
67.19000,5.59917,793.47100,-0.12805,17.57908,40.05164
67.39000,5.61585,793.24450,-0.12805,17.64581,40.04020
67.59001,5.63247,793.66500,-0.12806,17.71229,40.06143
67.79000,5.64921,794.61886,-0.12806,17.77925,40.10958
67.99001,5.66583,794.95627,-0.12805,17.84574,40.12661
68.19000,5.68245,794.49695,-0.12804,17.91223,40.10342
68.39001,5.69913,795.11730,-0.12804,17.97895,40.13474
68.59001,5.71576,795.47353,-0.12805,18.04544,40.15272
68.79000,5.73250,795.34249,-0.12805,18.11240,40.14610
68.99001,5.74924,795.39306,-0.12804,18.17937,40.14865
69.19000,5.76580,796.49389,-0.12804,18.24562,40.20422
69.39001,5.78254,795.74948,-0.12804,18.31258,40.16665
69.59001,5.79910,796.46399,-0.12804,18.37882,40.20271
69.79000,5.81584,796.59866,-0.12804,18.44579,40.20951
69.99001,5.83252,796.99801,-0.12804,18.51251,40.22967
70.19000,5.84915,797.18027,-0.12803,18.57900,40.23887
70.39001,5.86577,796.90507,-0.12803,18.64548,40.22498
70.59001,5.88245,795.91749,-0.12804,18.71221,40.17513
70.79000,5.89919,795.85807,-0.12804,18.77917,40.17213
70.99001,5.91587,796.96542,-0.12804,18.84590,40.22802
71.19000,5.93249,797.02167,-0.12803,18.91238,40.23086
71.39001,5.94923,797.64780,-0.12802,18.97935,40.26247
71.59001,5.96586,797.57534,-0.12803,19.04584,40.25881
71.79000,5.98254,798.29637,-0.12803,19.11256,40.29520
71.99001,5.99928,798.51067,-0.12802,19.17952,40.30602
72.19000,6.01584,798.52985,-0.12801,19.24577,40.30699
72.39001,6.03246,799.21382,-0.12801,19.31226,40.34151
72.59001,6.04914,799.52041,-0.12800,19.37898,40.35699
72.79000,6.06582,799.20739,-0.12800,19.44571,40.34119
72.99001,6.08244,799.66132,-0.12800,19.51219,40.36410
73.19000,6.09919,800.31445,-0.12800,19.57916,40.39707
73.39001,6.11593,800.29564,-0.12800,19.64612,40.39612
73.59001,6.13243,800.52307,-0.12800,19.71213,40.40760
73.79000,6.14911,801.11874,-0.12801,19.77886,40.43767
73.99001,6.16591,800.47874,-0.12801,19.84606,40.40536
74.19000,6.18253,801.37923,-0.12801,19.91254,40.45082
74.39001,6.19915,801.10785,-0.12801,19.97903,40.43712
74.59001,6.21584,801.71395,-0.12801,20.04576,40.46771
74.79000,6.23246,801.58859,-0.12801,20.11224,40.46138
74.99001,6.24908,801.87209,-0.12800,20.17873,40.47570
75.19000,6.26582,802.39419,-0.12801,20.24569,40.50205
75.39001,6.28256,802.02995,-0.12800,20.31265,40.48366
75.59001,6.29906,801.56662,-0.12800,20.37866,40.46028
75.79000,6.31574,802.80090,-0.12801,20.44539,40.52258
75.99001,6.33248,802.36103,-0.12801,20.51235,40.50037
76.19000,6.34911,803.25892,-0.12799,20.57884,40.54570
76.39001,6.36591,802.21128,-0.12800,20.64604,40.49282
76.59001,6.38259,803.32542,-0.12800,20.71277,40.54905
76.79000,6.39909,803.81054,-0.12800,20.77877,40.57354
76.99001,6.41577,803.38847,-0.12800,20.84550,40.55224
77.19000,6.43251,803.30297,-0.12800,20.91246,40.54792
77.39001,6.44919,803.50144,-0.12799,20.97919,40.55794
77.59001,6.46587,803.89716,-0.12799,21.04591,40.57792
77.79000,6.48244,803.46670,-0.12800,21.11216,40.55619
77.99001,6.49918,803.94167,-0.12799,21.17912,40.58016
78.19000,6.51580,804.01553,-0.12799,21.24561,40.58389
78.39001,6.53242,803.71527,-0.12799,21.31210,40.56873
78.59001,6.54934,803.94251,-0.12799,21.37978,40.58020
78.79000,6.56584,804.41805,-0.12799,21.44579,40.60421
78.99001,6.58240,804.52748,-0.12799,21.51203,40.60973
79.19000,6.59921,804.17944,-0.12799,21.57923,40.59216
79.39001,6.61583,804.90271,-0.12798,21.64572,40.62867
79.59001,6.63239,804.50149,-0.12798,21.71197,40.60842
79.79000,6.64919,804.84720,-0.12798,21.77917,40.62587
79.99001,6.66593,804.82485,-0.12799,21.84614,40.62474
80.19000,6.68243,805.19654,-0.12798,21.91215,40.64350
80.39001,6.69911,805.18061,-0.12797,21.97887,40.64270
80.59001,6.71597,805.88823,-0.12797,22.04631,40.67842
80.79000,6.73248,804.50960,-0.12798,22.11232,40.60883
80.99001,6.74910,805.59738,-0.12798,22.17880,40.66373
81.19000,6.76590,805.54150,-0.12797,22.24601,40.66092
81.39001,6.78252,804.99779,-0.12796,22.31249,40.63347
81.59001,6.79914,805.25810,-0.12795,22.37898,40.64661
81.79000,6.81588,805.54448,-0.12796,22.44595,40.66106
81.99001,6.83244,803.21431,-0.12797,22.51219,40.54345
82.19000,6.84913,803.62028,-0.12797,22.57892,40.56394
82.39001,6.86581,804.47029,-0.12796,22.64564,40.60684
82.59001,6.88255,804.21334,-0.12796,22.71261,40.59387
82.79000,6.89917,804.59490,-0.12796,22.77909,40.61313
82.99001,6.91585,805.04529,-0.12796,22.84582,40.63587
83.19000,6.93247,804.78629,-0.12796,22.91230,40.62280
83.39001,6.94915,805.21889,-0.12796,22.97903,40.64463
83.59001,6.96577,805.91673,-0.12794,23.04551,40.67986
83.79000,6.98252,805.75235,-0.12794,23.11248,40.67156
83.99001,6.99920,805.66071,-0.12795,23.17920,40.66693
84.19000,7.01588,805.84325,-0.12796,23.24593,40.67614
84.39001,7.03250,805.97512,-0.12795,23.31242,40.68280
84.59001,7.04918,806.04572,-0.12794,23.37914,40.68637
84.79000,7.06586,805.63081,-0.12794,23.44586,40.66542
84.99001,7.08254,806.21177,-0.12793,23.51259,40.69475
85.19000,7.09928,806.17378,-0.12794,23.57955,40.69283
85.39001,7.11579,806.22034,-0.12794,23.64556,40.69518
85.59001,7.13247,806.35566,-0.12794,23.71229,40.70201
85.79000,7.14921,806.52442,-0.12793,23.77925,40.71053
85.99001,7.16583,806.33424,-0.12794,23.84574,40.70093
86.19000,7.18245,806.22351,-0.12795,23.91222,40.69534
86.39001,7.19907,807.26240,-0.12794,23.97871,40.74778
86.59001,7.21581,806.99064,-0.12794,24.04567,40.73406
86.79000,7.23244,806.58616,-0.12794,24.11216,40.71365
86.99001,7.24918,806.62472,-0.12794,24.17912,40.71559
87.19000,7.26598,806.94957,-0.12794,24.24633,40.73199
87.39001,7.28248,807.15809,-0.12794,24.31233,40.74252
87.59001,7.29916,807.25169,-0.12794,24.37906,40.74724
87.79000,7.31590,806.73713,-0.12793,24.44602,40.72126
87.99001,7.33252,807.16899,-0.12793,24.51251,40.74306
88.19000,7.34915,807.44419,-0.12794,24.57899,40.75695
88.39001,7.36577,807.09392,-0.12795,24.64548,40.73927
88.59001,7.38251,807.04065,-0.12794,24.71245,40.73659
88.79000,7.39913,807.08954,-0.12793,24.77893,40.73906
88.99001,7.41581,806.94417,-0.12793,24.84566,40.73172
89.19000,7.43249,806.90598,-0.12794,24.91238,40.72979
89.39001,7.44917,806.78230,-0.12793,24.97911,40.72355
89.59001,7.46585,807.31893,-0.12792,25.04583,40.75063
89.79000,7.48254,807.58743,-0.12792,25.11256,40.76419
89.99001,7.49916,807.16079,-0.12791,25.17904,40.74265
90.19000,7.51590,807.29425,-0.12792,25.24601,40.74939
90.39001,7.53252,807.76885,-0.12793,25.31249,40.77334
90.59001,7.54920,806.92247,-0.12792,25.37922,40.73062
90.79000,7.56588,807.19218,-0.12792,25.44594,40.74424
90.99001,7.58244,807.14868,-0.12792,25.51219,40.74204
91.19000,7.59912,807.18827,-0.12791,25.57891,40.74404
91.39001,7.61587,807.38226,-0.12792,25.64588,40.75383
91.59001,7.63243,806.68982,-0.12792,25.71213,40.71888
91.79000,7.64917,806.95329,-0.12791,25.77909,40.73218
91.99001,7.66585,807.47074,-0.12790,25.84581,40.75830
92.19000,7.68247,807.00712,-0.12790,25.91230,40.73489
92.39001,7.69915,806.67427,-0.12791,25.97903,40.71809
92.59001,7.71589,806.51147,-0.12792,26.04599,40.70987
92.79000,7.73252,807.31353,-0.12790,26.11248,40.75036
92.99001,7.74914,806.90943,-0.12790,26.17896,40.72996
93.19000,7.76582,807.32433,-0.12790,26.24569,40.75090
93.39001,7.78244,807.86692,-0.12791,26.31217,40.77829
93.59001,7.79918,806.95255,-0.12791,26.37914,40.73214
93.79000,7.81586,806.97862,-0.12790,26.44586,40.73346
93.99001,7.83242,806.85662,-0.12789,26.51211,40.72729
94.19000,7.84910,807.04931,-0.12789,26.57883,40.73702
94.39001,7.86585,806.74645,-0.12790,26.64579,40.72174
94.59001,7.88259,806.94826,-0.12790,26.71276,40.73192
94.79000,7.89921,806.72894,-0.12790,26.77925,40.72085
94.99001,7.91583,807.31027,-0.12790,26.84573,40.75019
95.19000,7.93251,807.01010,-0.12789,26.91246,40.73504
95.39001,7.94913,806.33182,-0.12789,26.97895,40.70081
95.59001,7.96581,806.76675,-0.12789,27.04567,40.72276
95.79000,7.98249,806.89592,-0.12788,27.11239,40.72928
95.99001,7.99918,806.95171,-0.12787,27.17912,40.73210
96.19000,8.01586,806.49843,-0.12786,27.24584,40.70922
96.39001,8.03248,806.08306,-0.12787,27.31233,40.68825
96.59001,8.04916,807.20466,-0.12789,27.37906,40.74487
96.79000,8.06584,807.18417,-0.12788,27.44578,40.74383
96.99001,8.08240,806.84246,-0.12787,27.51203,40.72658
97.19000,8.09914,807.42761,-0.12787,27.57899,40.75612
97.39001,8.11577,806.82831,-0.12787,27.64548,40.72587
97.59001,8.13245,806.68144,-0.12788,27.71220,40.71845
97.79000,8.14919,806.50970,-0.12788,27.77917,40.70979
97.99001,8.16587,806.05028,-0.12787,27.84589,40.68660
98.19000,8.18255,806.09992,-0.12787,27.91262,40.68910
98.39001,8.19917,806.28386,-0.12787,27.97911,40.69839
98.59001,8.21585,806.28507,-0.12788,28.04583,40.69845
98.79000,8.23247,805.93424,-0.12787,28.11231,40.68074
98.99001,8.24916,806.13624,-0.12786,28.17904,40.69093
99.19000,8.26590,805.67161,-0.12786,28.24600,40.66748
99.39001,8.28252,806.12134,-0.12785,28.31249,40.69018
99.59001,8.29902,805.56311,-0.12785,28.37850,40.66201
99.79001,8.31588,805.29153,-0.12785,28.44594,40.64830
99.99001,8.33256,805.67813,-0.12786,28.51267,40.66781
100.19000,8.34918,806.00660,-0.12785,28.57915,40.68439
100.39001,8.36587,806.21662,-0.12786,28.64588,40.69499
100.59001,8.38243,805.87771,-0.12785,28.71212,40.67788
100.79001,8.39911,805.26732,-0.12785,28.77885,40.64708
100.99001,8.41591,805.57661,-0.12786,28.84605,40.66269
101.19000,8.43259,804.83891,-0.12786,28.91278,40.62545
101.39001,8.44915,805.37675,-0.12786,28.97902,40.65260
101.59001,8.46583,805.51030,-0.12785,29.04575,40.65934
101.79001,8.48257,805.95892,-0.12786,29.11271,40.68198
101.99001,8.49914,805.43794,-0.12785,29.17896,40.65569
102.19000,8.51582,805.18806,-0.12784,29.24568,40.64307
102.39001,8.53250,805.02275,-0.12785,29.31241,40.63473
102.59001,8.54918,805.19011,-0.12786,29.37913,40.64318
102.79001,8.56574,804.89935,-0.12786,29.44538,40.62850
102.99001,8.58260,805.02257,-0.12786,29.51283,40.63472
103.19000,8.59922,804.84506,-0.12785,29.57931,40.62576
103.39001,8.61584,804.54135,-0.12784,29.64579,40.61043
103.59001,8.63253,804.84338,-0.12784,29.71252,40.62568
103.79001,8.64915,804.31337,-0.12785,29.77901,40.59892
103.99001,8.66583,804.57553,-0.12785,29.84573,40.61216
104.19000,8.68245,804.36133,-0.12785,29.91222,40.60134
104.39001,8.69919,804.56575,-0.12783,29.97918,40.61166
104.59001,8.71575,804.66596,-0.12784,30.04543,40.61672
104.79001,8.73243,804.90084,-0.12785,30.11215,40.62857
104.99001,8.74918,803.98694,-0.12784,30.17912,40.58244
105.19000,8.76586,804.25041,-0.12785,30.24584,40.59575
105.39001,8.78254,804.32044,-0.12785,30.31256,40.59928
105.59001,8.79922,804.00091,-0.12784,30.37929,40.58315
105.79001,8.81584,804.30014,-0.12784,30.44578,40.59826
105.99001,8.83246,803.86782,-0.12785,30.51226,40.57643
106.19000,8.84914,803.93720,-0.12784,30.57899,40.57993
106.39001,8.86588,803.49157,-0.12784,30.64595,40.55744
106.59001,8.88251,803.32160,-0.12784,30.71244,40.54886
106.79001,8.89907,803.58777,-0.12784,30.77869,40.56230
106.99001,8.91581,803.90377,-0.12784,30.84565,40.57825
107.19000,8.93243,803.85124,-0.12784,30.91214,40.57560
107.39001,8.94917,802.92141,-0.12784,30.97910,40.52866
107.59001,8.96591,803.84957,-0.12783,31.04606,40.57551
107.79001,8.98247,803.46502,-0.12783,31.11231,40.55610
107.99001,8.99910,803.01352,-0.12785,31.17880,40.53331
108.19000,9.01584,802.98325,-0.12784,31.24576,40.53178
108.39001,9.03252,803.06651,-0.12783,31.31248,40.53598
108.59001,9.04920,802.84150,-0.12783,31.37921,40.52463
108.79001,9.06582,802.58306,-0.12783,31.44570,40.51158
108.99001,9.08256,802.24266,-0.12783,31.51266,40.49440
109.19000,9.09906,803.08514,-0.12783,31.57867,40.53693
109.39001,9.11581,802.38935,-0.12784,31.64563,40.50180
109.59001,9.13261,802.41933,-0.12783,31.71284,40.50332
109.79001,9.14911,802.55773,-0.12783,31.77885,40.51030
109.99001,9.16573,802.53053,-0.12784,31.84533,40.50893
110.19000,9.18253,802.48127,-0.12783,31.91253,40.50644
110.39001,9.19921,802.67955,-0.12781,31.97926,40.51645
110.59001,9.21589,801.77654,-0.12781,32.04598,40.47087
110.79001,9.23251,801.80774,-0.12780,32.11247,40.47245
110.99001,9.24920,801.88885,-0.12780,32.17920,40.47654
111.19000,9.26576,801.61188,-0.12782,32.24545,40.46256
111.39001,9.28250,801.41556,-0.12782,32.31241,40.45265
111.59001,9.29924,801.16391,-0.12782,32.37937,40.43995
111.79001,9.31580,801.16475,-0.12781,32.44562,40.43999
111.99001,9.33248,800.94123,-0.12781,32.51234,40.42871
112.19000,9.34916,801.19595,-0.12782,32.57906,40.44157
112.39001,9.36578,800.59748,-0.12782,32.64555,40.41136
112.59001,9.38247,800.52102,-0.12780,32.71228,40.40750
112.79001,9.39915,800.91143,-0.12781,32.77900,40.42720
112.99001,9.41589,801.03083,-0.12781,32.84597,40.43323
113.19000,9.43251,800.72135,-0.12782,32.91245,40.41761
113.39001,9.44919,800.61173,-0.12781,32.97918,40.41208
113.59001,9.46587,800.50454,-0.12781,33.04591,40.40667
113.79001,9.48249,800.36391,-0.12780,33.11239,40.39957
113.99001,9.49917,799.56995,-0.12780,33.17911,40.35949
114.19000,9.51580,799.89042,-0.12781,33.24560,40.37567
114.39001,9.53248,800.15007,-0.12782,33.31233,40.38877
114.59001,9.54916,798.12100,-0.12781,33.37905,40.28635
114.79001,9.56590,798.16561,-0.12780,33.44601,40.28860
114.99001,9.58258,797.45352,-0.12781,33.51274,40.25266
115.19000,9.59914,796.79806,-0.12782,33.57899,40.21957
115.39001,9.61576,797.37147,-0.12782,33.64547,40.24852
115.59001,9.63257,797.09692,-0.12781,33.71268,40.23466
115.79001,9.64907,796.59633,-0.12780,33.77868,40.20939
115.99001,9.66587,797.03843,-0.12780,33.84589,40.23171
116.19000,9.68255,797.21147,-0.12781,33.91261,40.24044
116.39001,9.69917,796.88495,-0.12781,33.97910,40.22396
116.59001,9.71579,796.79061,-0.12780,34.04559,40.21920
116.79001,9.73253,796.09053,-0.12780,34.11255,40.18386
116.99001,9.74921,796.63238,-0.12780,34.17927,40.21121
117.19000,9.76584,797.02996,-0.12781,34.24576,40.23128
117.39001,9.78246,796.63405,-0.12781,34.31225,40.21130
117.59001,9.79914,796.52509,-0.12780,34.37897,40.20580
117.79001,9.81576,796.36099,-0.12780,34.44545,40.19751
117.99001,9.83244,796.25649,-0.12779,34.51218,40.19224
118.19000,9.84918,796.21430,-0.12780,34.57914,40.19011
118.39001,9.86580,795.80480,-0.12780,34.64563,40.16944
118.59001,9.88249,796.29887,-0.12780,34.71235,40.19438
118.79001,9.89917,795.88527,-0.12779,34.77908,40.17350
118.99001,9.91585,795.75367,-0.12779,34.84581,40.16686
119.19000,9.93253,795.99293,-0.12780,34.91253,40.17894
119.39001,9.94921,794.92684,-0.12781,34.97925,40.12512
119.59001,9.96589,794.31385,-0.12779,35.04598,40.09418
119.79001,9.98245,794.82971,-0.12780,35.11223,40.12022
119.99001,9.99913,794.77318,-0.12779,35.17895,40.11737
120.19000,10.01582,794.51511,-0.12780,35.24568,40.10434
120.39001,10.03244,794.44507,-0.12780,35.31216,40.10080
120.59001,10.04912,794.43622,-0.12780,35.37889,40.10036
120.79001,10.06580,793.90351,-0.12780,35.44561,40.07347
120.99001,10.08248,793.90509,-0.12779,35.51234,40.07355
121.19000,10.09916,793.91180,-0.12779,35.57906,40.07389
121.39001,10.11584,793.76176,-0.12778,35.64579,40.06631
121.59001,10.13253,793.19431,-0.12779,35.71252,40.03767
121.79001,10.14921,793.83636,-0.12778,35.77923,40.07008
121.99001,10.16583,793.70746,-0.12778,35.84573,40.06357
122.19000,10.18251,793.16702,-0.12778,35.91245,40.03629
122.39001,10.19913,792.85726,-0.12779,35.97893,40.02066
122.59001,10.21581,793.04967,-0.12779,36.04566,40.03037
122.79001,10.23249,792.72082,-0.12779,36.11239,40.01377
122.99001,10.24911,792.26373,-0.12778,36.17887,39.99070
123.19000,10.26574,792.74653,-0.12779,36.24536,40.01507
123.39001,10.28254,792.48706,-0.12779,36.31256,40.00197
123.59001,10.29922,792.08342,-0.12779,36.37929,39.98160
123.79001,10.31578,792.29502,-0.12779,36.44553,39.99228
123.99001,10.33252,791.75653,-0.12778,36.51250,39.96510
124.19000,10.34920,791.25194,-0.12778,36.57922,39.93963
124.39001,10.36582,791.78503,-0.12778,36.64570,39.96653
124.59001,10.38251,791.66424,-0.12779,36.71243,39.96044
124.79001,10.39925,791.81818,-0.12780,36.77940,39.96821
124.99001,10.41575,791.33799,-0.12778,36.84540,39.94397
125.19000,10.43243,790.55429,-0.12778,36.91213,39.90441
125.39001,10.44911,790.83033,-0.12778,36.97885,39.91835
125.59001,10.46579,790.36821,-0.12778,37.04558,39.89502
125.79001,10.48247,790.53454,-0.12778,37.11231,39.90342
125.99001,10.49915,790.57524,-0.12778,37.17903,39.90547
126.19000,10.51583,790.82176,-0.12778,37.24575,39.91791
126.39001,10.53252,790.35945,-0.12778,37.31248,39.89458
126.59001,10.54914,790.19777,-0.12778,37.37897,39.88642
126.79001,10.56588,789.63684,-0.12779,37.44593,39.85810
126.99001,10.58256,789.57658,-0.12778,37.51265,39.85506
127.19000,10.59912,789.30343,-0.12777,37.57890,39.84127
127.39001,10.61580,789.60089,-0.12777,37.64563,39.85629
127.59001,10.63243,789.07404,-0.12778,37.71212,39.82969
127.79001,10.64917,789.34850,-0.12777,37.77908,39.84355
127.99001,10.66585,788.90417,-0.12777,37.84580,39.82112
128.19000,10.68253,789.52452,-0.12776,37.91253,39.85243
128.39000,10.69915,788.70365,-0.12777,37.97902,39.81100
128.59001,10.71577,788.84317,-0.12777,38.04550,39.81804
128.79001,10.73257,788.72107,-0.12778,38.11270,39.81188
128.99001,10.74913,788.48014,-0.12778,38.17895,39.79972
129.19000,10.76575,787.75007,-0.12777,38.24543,39.76287
129.39000,10.78250,788.62533,-0.12777,38.31240,39.80704
129.59001,10.79912,787.55291,-0.12777,38.37889,39.75291
129.79001,10.81580,787.22583,-0.12777,38.44561,39.73640
129.99001,10.83254,787.25116,-0.12776,38.51258,39.73768
130.19000,10.84928,787.31775,-0.12776,38.57954,39.74104
130.39000,10.86584,787.47123,-0.12776,38.64579,39.74879
130.59001,10.88246,786.75319,-0.12776,38.71227,39.71255
130.79001,10.89921,786.42033,-0.12777,38.77923,39.69574
130.99001,10.91583,787.22965,-0.12776,38.84572,39.73660
131.19000,10.93245,786.87193,-0.12775,38.91221,39.71854
131.39000,10.94919,786.07658,-0.12776,38.97917,39.67839
131.59002,10.96575,786.29665,-0.12776,39.04542,39.68950
131.79002,10.98249,785.88137,-0.12776,39.11238,39.66854
131.99000,10.99917,785.56621,-0.12776,39.17911,39.65263
132.19000,11.01585,784.65557,-0.12775,39.24583,39.60667
132.39000,11.03248,785.39969,-0.12775,39.31232,39.64423
132.59002,11.04916,784.89827,-0.12775,39.37905,39.61892
132.79002,11.06584,784.44034,-0.12776,39.44577,39.59580
132.99000,11.08246,784.71527,-0.12776,39.51226,39.60968
133.19000,11.09920,784.63499,-0.12775,39.57922,39.60563
133.39000,11.11582,783.44336,-0.12774,39.64570,39.54548
133.59002,11.13238,783.92513,-0.12775,39.71195,39.56979
133.79002,11.14913,782.80745,-0.12776,39.77892,39.51338
133.99000,11.16587,782.99064,-0.12776,39.84588,39.52262
134.19000,11.18255,783.61398,-0.12775,39.91261,39.55409
134.39000,11.19929,783.16974,-0.12774,39.97957,39.53167
134.59002,11.21579,782.90692,-0.12774,40.04558,39.51840
134.79002,11.23247,782.39990,-0.12774,40.11231,39.49281
134.99000,11.24915,782.28740,-0.12775,40.17903,39.48713
135.19000,11.26583,782.80205,-0.12775,40.24575,39.51311
135.39000,11.28264,782.20638,-0.12774,40.31295,39.48304
135.59002,11.29914,781.57373,-0.12774,40.37896,39.45110
135.79002,11.31576,781.04236,-0.12774,40.44545,39.42428
135.99000,11.33256,780.99933,-0.12775,40.51265,39.42211
136.19000,11.34912,780.53540,-0.12775,40.57890,39.39869
136.39000,11.36574,780.71314,-0.12774,40.64539,39.40767
136.59002,11.38248,780.06438,-0.12774,40.71235,39.37492
136.79002,11.39917,778.83229,-0.12774,40.77908,39.31273
136.99000,11.41573,779.21487,-0.12775,40.84532,39.33204
137.19000,11.43247,779.04863,-0.12775,40.91229,39.32365
137.39000,11.44933,779.12463,-0.12774,40.97973,39.32748
137.59002,11.46583,778.51466,-0.12773,41.04573,39.29669
137.79002,11.48245,777.65682,-0.12774,41.11222,39.25339
137.99000,11.49919,777.79754,-0.12774,41.17919,39.26049
138.19000,11.51581,777.21407,-0.12774,41.24567,39.23104
138.39000,11.53250,776.31637,-0.12774,41.31240,39.18573
138.59002,11.54924,775.92684,-0.12773,41.37936,39.16607
138.79002,11.56580,774.89987,-0.12774,41.44561,39.11423
138.99000,11.58236,774.24450,-0.12774,41.51186,39.08115
139.19000,11.59916,773.76389,-0.12774,41.57906,39.05689
139.39000,11.61590,772.57524,-0.12774,41.64602,38.99689
139.59002,11.63252,771.58650,-0.12773,41.71251,38.94698
139.79002,11.64915,769.93001,-0.12773,41.77900,38.86337
139.99000,11.66589,769.33135,-0.12773,41.84596,38.83315
140.19000,11.68251,767.95262,-0.12773,41.91245,38.76356
140.39000,11.69913,765.23880,-0.12773,41.97893,38.62658
140.59002,11.71587,762.15058,-0.12773,42.04590,38.47069
140.79002,11.73249,758.99507,-0.12773,42.11238,38.31141
140.99000,11.74911,753.24816,-0.12773,42.17887,38.02133
141.19000,11.76573,745.49881,-0.12773,42.24535,37.63017
141.39000,11.78254,192.53652,-0.12775,42.31256,9.71857
141.40800,11.78415,9.71316,-0.12771,42.31901,0.49029