File: Manufatura Aditiva/Dados/Ensaios AMR/Ensaios/Ensaios FDM/Tracao_OLABI_23_05_2018_FDM_YX2.is_metal_RawData/Specimen_RawData_5.csv
Time,Extension,Load,Strain 1,Tensile strain,Tensile stress
(sec),(mm),(N),(mm/mm),(%),(MPa)
0.00000,0.00006,31.68807,-0.00031,-0.03141,1.59783
0.20000,0.01387,36.54644,-0.00016,-0.01641,1.84280
0.40000,0.03259,45.64000,0.00009,0.00914,2.30133
0.60000,0.04986,53.51150,0.00033,0.03337,2.69824
0.80000,0.06667,60.20398,0.00057,0.05671,3.03570
1.00000,0.08329,67.90591,0.00080,0.07996,3.42406
1.20000,0.10003,74.43075,0.00104,0.10352,3.75306
1.40000,0.11671,82.05664,0.00127,0.12691,4.13759
1.60000,0.13339,88.18046,0.00149,0.14932,4.44637
1.80000,0.14995,94.39951,0.00170,0.17026,4.75996
2.00000,0.16657,101.41076,0.00195,0.19516,5.11349
2.20000,0.18331,108.56504,0.00219,0.21908,5.47424
2.40000,0.20000,115.54805,0.00243,0.24321,5.82634
2.60000,0.21668,122.47164,0.00268,0.26825,6.17546
2.80000,0.23330,129.01907,0.00292,0.29235,6.50560
3.00000,0.24998,135.49539,0.00317,0.31702,6.83216
3.20000,0.26672,142.47209,0.00342,0.34195,7.18395
3.40000,0.28340,149.84197,0.00367,0.36695,7.55557
3.60000,0.30002,155.80509,0.00392,0.39168,7.85625
3.80000,0.31670,162.68941,0.00417,0.41658,8.20338
4.00000,0.33333,170.03326,0.00442,0.44208,8.57368
4.20000,0.35001,176.67689,0.00467,0.46728,8.90868
4.40000,0.36663,183.02983,0.00492,0.49233,9.22902
4.60000,0.38331,189.85032,0.00518,0.51826,9.57293
4.80000,0.40005,196.26906,0.00543,0.54339,9.89658
5.00000,0.41661,202.21910,0.00565,0.56501,10.19661
5.20000,0.43329,209.02436,0.00591,0.59061,10.53975
5.40000,0.45010,215.49389,0.00616,0.61613,10.86597
5.60000,0.46666,222.29908,0.00641,0.64126,11.20911
5.80000,0.48328,227.97766,0.00667,0.66693,11.49545
6.00000,0.50002,235.89807,0.00693,0.69309,11.89482
6.20000,0.51670,242.21872,0.00719,0.71857,12.21353
6.40000,0.53332,248.76643,0.00744,0.74449,12.54369
6.60000,0.55000,254.84338,0.00770,0.77035,12.85011
6.80000,0.56680,261.67918,0.00797,0.79675,13.19479
7.00000,0.58331,268.97062,0.00823,0.82256,13.56246
7.20000,0.59993,275.02202,0.00849,0.84901,13.86759
7.40000,0.61673,282.12564,0.00875,0.87509,14.22578
7.60000,0.63329,288.41700,0.00901,0.90106,14.54301
7.80000,0.64997,293.72659,0.00923,0.92275,14.81074
8.00000,0.66671,300.06319,0.00948,0.94834,15.13025
8.20000,0.68327,306.42843,0.00975,0.97488,15.45121
8.40000,0.69996,313.35091,0.01001,1.00132,15.80027
8.60000,0.71664,319.28050,0.01027,1.02712,16.09926
8.80000,0.73338,325.78774,0.01053,1.05289,16.42738
9.00000,0.74994,331.90611,0.01079,1.07928,16.73589
9.20000,0.76662,338.54875,0.01106,1.10649,17.07083
9.40000,0.78336,344.80586,0.01133,1.13265,17.38634
9.60000,0.79992,350.68274,0.01157,1.15724,17.68267
9.80000,0.81666,356.83415,0.01184,1.18355,17.99285
10.00000,0.83341,363.09694,0.01210,1.21031,18.30864
10.20000,0.85003,368.80821,0.01237,1.23673,18.59662
10.40000,0.86665,373.23355,0.01259,1.25856,18.81976
10.60000,0.88333,379.77863,0.01285,1.28537,19.14979
10.80000,0.89995,385.17276,0.01311,1.31147,19.42178
11.00000,0.91663,391.70678,0.01338,1.33816,19.75125
11.20000,0.93331,397.76447,0.01365,1.36463,20.05670
11.40000,0.95011,404.29821,0.01392,1.39161,20.38615
11.60000,0.96656,410.34683,0.01418,1.41821,20.69115
11.80000,0.98324,416.41230,0.01445,1.44489,20.99699
12.00000,1.00010,421.86817,0.01472,1.47156,21.27209
12.20000,1.01666,427.27529,0.01498,1.49845,21.54474
12.40000,1.03328,433.53178,0.01526,1.52552,21.86021
12.60000,1.05002,439.80903,0.01552,1.55206,22.17674
12.80000,1.06670,444.53191,0.01574,1.57394,22.41488
13.00000,1.08327,451.47599,0.01601,1.60102,22.76503
13.20000,1.09995,456.36175,0.01628,1.62788,23.01138
13.40000,1.11675,462.02643,0.01655,1.65522,23.29702
13.60000,1.13325,468.86383,0.01682,1.68172,23.64178
13.80000,1.14993,474.31360,0.01709,1.70858,23.91658
14.00000,1.16679,480.53204,0.01736,1.73615,24.23013
14.20000,1.18329,485.47224,0.01763,1.76297,24.47924
14.40000,1.19998,491.69376,0.01791,1.79050,24.79295
14.60000,1.21672,497.92700,0.01818,1.81756,25.10725
14.80000,1.23334,501.75143,0.01839,1.83891,25.30009
15.00000,1.24996,507.37467,0.01865,1.86499,25.58364
15.20000,1.26664,512.79506,0.01892,1.89216,25.85695
15.40000,1.28338,518.24846,0.01920,1.91972,26.13193
15.60000,1.29994,523.76469,0.01947,1.94663,26.41008
15.80000,1.31656,529.89828,0.01974,1.97386,26.71936
16.00000,1.33337,534.89967,0.02001,2.00131,26.97154
16.20000,1.34993,540.26688,0.02029,2.02867,27.24218
16.40000,1.36667,545.30953,0.02056,2.05649,27.49645
16.60000,1.38341,550.66044,0.02083,2.08347,27.76626
16.80000,1.40003,555.05289,0.02106,2.10574,27.98774
17.00000,1.41671,560.54443,0.02133,2.13319,28.26464
17.20000,1.43333,565.63062,0.02161,2.16079,28.52111
17.40000,1.45001,570.72821,0.02189,2.18877,28.77815
17.60000,1.46670,576.18809,0.02216,2.21604,29.05345
17.80000,1.48338,580.75855,0.02244,2.24408,29.28391
18.00000,1.49994,586.59124,0.02272,2.27164,29.57802
18.20000,1.51656,591.70648,0.02299,2.29948,29.83595
18.40000,1.53324,596.51476,0.02327,2.32711,30.07840
18.60000,1.55004,600.20532,0.02349,2.34864,30.26449
18.80000,1.56666,604.81313,0.02377,2.37685,30.49683
19.00000,1.58329,610.07994,0.02405,2.40484,30.76240
19.20000,1.60003,615.64222,0.02433,2.43275,31.04287
19.40000,1.61665,620.81628,0.02461,2.46109,31.30377
19.60000,1.63333,624.93789,0.02488,2.48801,31.51159
19.80000,1.65013,629.99986,0.02517,2.51666,31.76683
20.00000,1.66675,634.86989,0.02545,2.54480,32.01240
20.20000,1.68331,640.10955,0.02574,2.57360,32.27660
20.40000,1.69999,643.81342,0.02602,2.60179,32.46336
20.60000,1.71668,647.72395,0.02624,2.62415,32.66055
20.80000,1.73330,651.91058,0.02652,2.65232,32.87165
21.00000,1.74998,657.64785,0.02681,2.68138,33.16095
21.20000,1.76672,662.53035,0.02710,2.71027,33.40714
21.40000,1.78334,667.40392,0.02739,2.73895,33.65288
21.60000,1.79996,671.60260,0.02768,2.76795,33.86459
21.80000,1.81670,676.36915,0.02797,2.79706,34.10494
22.00000,1.83339,680.34604,0.02826,2.82611,34.30547
22.20000,1.84995,685.36294,0.02855,2.85536,34.55844
22.40000,1.86669,688.79803,0.02879,2.87943,34.73165
22.60000,1.88337,692.71857,0.02907,2.90661,34.92934
22.80000,1.89993,697.65174,0.02936,2.93606,35.17808
23.00000,1.91661,701.98211,0.02966,2.96574,35.39643
23.20000,1.93329,706.22079,0.02995,2.99465,35.61016
23.40000,1.94997,710.27484,0.03025,3.02467,35.81458
23.60000,1.96660,714.87562,0.03054,3.05404,36.04657
23.80000,1.98328,718.84585,0.03084,3.12077,36.24677
23.93600,1.99470,721.39516,0.03103,3.16645,36.37531
24.13600,2.01138,725.03281,0.03132,3.23317,36.55873
24.33600,2.02800,729.81296,0.03162,3.29966,36.79977
24.53600,2.04468,731.93558,0.03185,3.36638,36.90680
24.73600,2.06130,736.74708,0.03216,3.43287,37.14941
24.93600,2.07804,740.10082,0.03246,3.49983,37.31852
25.13600,2.09472,743.50322,0.03276,3.56656,37.49008
25.33600,2.11135,748.17850,0.03307,3.63304,37.72582
25.53600,2.12797,752.16121,0.03338,3.69953,37.92664
25.73600,2.14465,755.56939,0.03369,3.76625,38.09850
25.93600,2.16133,759.87270,0.03400,3.83298,38.31549
26.13600,2.17801,763.33298,0.03431,3.89970,38.48996
26.33600,2.19469,766.19079,0.03501,3.96643,38.63407
26.53600,2.21131,768.98499,0.03557,4.03292,38.77496
26.73600,2.22794,773.21110,0.01055,4.09940,38.98806
26.93600,2.24468,776.16577,-0.05189,4.16637,39.13704
27.13600,2.26136,779.46214,-0.08264,4.23309,39.30325
27.33600,2.27804,782.62640,0.02330,4.29982,39.46281
27.53600,2.29466,786.37311,0.01162,4.36630,39.65173
27.73600,2.31134,789.24904,0.03861,4.43303,39.79675
27.93600,2.32802,792.91295,0.01744,4.49975,39.98149
28.13600,2.34464,795.92448,-0.00935,4.56624,40.13334
28.33600,2.36139,799.18150,-0.13964,4.63320,40.29757
28.53600,2.37801,802.35535,-0.13927,4.69969,40.45761
28.73600,2.39457,804.24836,-0.13927,4.76593,40.55306
28.93600,2.41131,807.32154,-0.13927,4.83290,40.70802
29.13600,2.42793,810.78876,-0.13927,4.89938,40.88285
29.33600,2.44461,814.04820,-0.13927,4.96611,41.04721
29.53600,2.46135,816.31634,-0.13927,5.03307,41.16158
29.73600,2.47798,819.24526,-0.13927,5.09956,41.30926
29.93600,2.49460,821.97338,-0.13928,5.16604,41.44682
30.13600,2.51128,824.67645,-0.13927,5.23277,41.58312
30.33600,2.52802,827.57305,-0.13928,5.29974,41.72918
30.53600,2.54476,830.17992,-0.13928,5.36670,41.86063
30.73600,2.56132,832.58562,-0.13928,5.43295,41.98193
30.93600,2.57794,835.05837,-0.13928,5.49943,42.10661
31.13600,2.59462,836.60521,-0.13928,5.56616,42.18461
31.33600,2.61137,839.21039,-0.13928,5.63312,42.31598
31.53600,2.62805,841.65642,-0.13928,5.69985,42.43931
31.73600,2.64467,844.48429,-0.13928,5.76633,42.58190
31.93600,2.66129,846.99281,-0.13928,5.83282,42.70839
32.13600,2.67797,848.34853,-0.13928,5.89954,42.77675
32.33600,2.69465,850.47167,-0.13928,5.96627,42.88381
32.53600,2.71145,853.33660,-0.13928,6.03347,43.02827
32.73600,2.72802,855.11068,-0.13928,6.09972,43.11772
32.93600,2.74470,857.18231,-0.13928,6.16644,43.22218
33.13600,2.76132,858.72458,-0.13928,6.23293,43.29995
33.33600,2.77794,861.14788,-0.13928,6.29942,43.42214
33.53600,2.79474,863.08010,-0.13929,6.36662,43.51957
33.73600,2.81136,864.86889,-0.13928,6.43310,43.60977
33.93600,2.82792,866.28115,-0.13929,6.49935,43.68098
34.13600,2.84466,867.90659,-0.13928,6.56632,43.76294
34.33600,2.86129,868.54594,-0.13928,6.63280,43.79518
34.53600,2.87797,870.35187,-0.13929,6.69953,43.88624
34.73600,2.89471,871.49851,-0.13929,6.76649,43.94406
34.93600,2.91145,873.09498,-0.13929,6.83346,44.02456
35.13600,2.92789,874.22533,-0.13928,6.89922,44.08155
35.33600,2.94469,876.04420,-0.13929,6.96643,44.17327
35.53600,2.96149,877.69013,-0.13929,7.03363,44.25626
35.73600,2.97799,879.22625,-0.13929,7.09964,44.33372
35.93600,2.99456,880.08279,-0.13929,7.16588,44.37691
36.13600,3.01130,881.32825,-0.13928,7.23285,44.43970
36.33600,3.02798,882.53357,-0.13929,7.29957,44.50048
36.53600,3.04460,883.06218,-0.13929,7.36606,44.52714
36.73600,3.06128,884.33754,-0.13929,7.43278,44.59145
36.93600,3.07802,885.23859,-0.13929,7.49975,44.63688
37.13600,3.09458,886.14626,-0.13929,7.56600,44.68265
37.33600,3.11127,887.36732,-0.13929,7.63272,44.74422
37.53600,3.12807,887.90702,-0.13929,7.69992,44.77143
37.73600,3.14463,888.74185,-0.13929,7.76617,44.81353
37.93600,3.16131,889.27085,-0.13929,7.83290,44.84020
38.13600,3.17805,889.62773,-0.13929,7.89986,44.85820
38.33600,3.19473,890.66336,-0.13929,7.96659,44.91042
38.53600,3.21129,890.76972,-0.13929,8.03283,44.91578
38.73600,3.22797,890.69875,-0.13929,8.09956,44.91220
38.93600,3.24472,891.30662,-0.13929,8.16652,44.94285
39.13600,3.26134,892.35604,-0.13929,8.23301,44.99577
39.33600,3.27796,892.68424,-0.13929,8.29949,45.01231
39.53600,3.29470,892.77253,-0.13929,8.36646,45.01677
39.73600,3.31126,892.78696,-0.13929,8.43270,45.01749
39.93600,3.32800,893.21909,-0.13929,8.49967,45.03928
40.13600,3.34474,893.20308,-0.13929,8.56663,45.03848
40.33600,3.36137,893.43498,-0.13929,8.63312,45.05017
40.53600,3.37793,893.33812,-0.13929,8.69936,45.04529
40.73600,3.39467,893.88499,-0.13929,8.76633,45.07286
40.93600,3.41141,893.87707,-0.13929,8.83329,45.07246
41.13600,3.42797,893.47865,-0.13929,8.89954,45.05237
41.33600,3.44471,892.93132,-0.13929,8.96651,45.02477
41.53600,3.46139,893.36922,-0.13929,9.03323,45.04686
41.73600,3.47789,893.28103,-0.13929,9.09924,45.04241
41.93600,3.49464,892.24400,-0.13929,9.16620,44.99012
42.13600,3.51150,892.39292,-0.13929,9.23364,44.99763
42.33600,3.52800,892.31376,-0.13929,9.29965,44.99363
42.53600,3.54462,892.16447,-0.13929,9.36614,44.98611
42.73600,3.56136,891.31352,-0.13929,9.43310,44.94320
42.93600,3.57810,890.41516,-0.13929,9.50007,44.89790
43.13600,3.59454,890.84310,-0.13929,9.56583,44.91948
43.33600,3.61135,889.52575,-0.13929,9.63304,44.85305
43.53600,3.62809,889.11960,-0.13929,9.70000,44.83257
43.73600,3.64465,889.19699,-0.13929,9.76625,44.83648
43.93600,3.66133,888.32350,-0.13929,9.83297,44.79243
44.13600,3.67807,888.16416,-0.13929,9.89994,44.78440
44.33600,3.69463,887.37709,-0.13929,9.96619,44.74471
44.53600,3.71137,886.46840,-0.13930,10.03315,44.69889
44.73600,3.72799,885.91073,-0.13929,10.09964,44.67077
44.93600,3.74462,885.80819,-0.13929,10.16612,44.66560
45.13600,3.76130,884.53544,-0.13929,10.23285,44.60143
45.33600,3.77798,883.57758,-0.13929,10.29957,44.55312
45.53600,3.79472,882.80272,-0.13929,10.36654,44.51405
45.73600,3.81128,882.23843,-0.13929,10.43278,44.48560
45.93600,3.82796,881.35004,-0.13929,10.49951,44.44080
46.13600,3.84464,880.42682,-0.13929,10.56623,44.39425
46.33600,3.86127,879.80404,-0.13929,10.63272,44.36285
46.53600,3.87795,878.42429,-0.13929,10.69944,44.29328
46.73600,3.89475,878.22955,-0.13930,10.76665,44.28346
46.93600,3.91137,876.98027,-0.13929,10.83313,44.22047
47.13600,3.92793,876.02241,-0.13929,10.89938,44.17216
47.33600,3.94467,875.37775,-0.13930,10.96634,44.13966
47.53600,3.96135,873.80251,-0.13930,11.03307,44.06023
47.73600,3.97797,873.31580,-0.13929,11.09955,44.03569
47.93600,3.99466,873.23459,-0.13930,11.16628,44.03159
48.13600,4.01134,871.74056,-0.13929,11.23300,43.95626
48.33600,4.02790,871.07671,-0.13929,11.29925,43.92279
48.53600,4.04470,869.94572,-0.13930,11.36645,43.86576
48.73600,4.06150,868.45616,-0.13930,11.43366,43.79065
48.93600,4.07800,867.66649,-0.13929,11.49966,43.75083
49.13600,4.09462,867.25056,-0.13929,11.56615,43.72986
49.33600,4.11136,865.64282,-0.13929,11.63312,43.64879
49.53600,4.12799,864.82288,-0.13930,11.69960,43.60745
49.73600,4.14461,863.84295,-0.13930,11.76609,43.55803
49.93600,4.16135,862.66138,-0.13930,11.83305,43.49846
50.13600,4.17803,861.18933,-0.13930,11.89978,43.42423
50.33600,4.19459,860.96777,-0.13929,11.96602,43.41306
50.53600,4.21127,859.65674,-0.13930,12.03275,43.34695
50.73600,4.22807,858.94959,-0.13929,12.09995,43.31129
50.93600,4.24470,857.83461,-0.13930,12.16644,43.25507
51.13600,4.26132,856.14081,-0.13930,12.23292,43.16967
51.33600,4.27806,855.20083,-0.13929,12.29989,43.12227
51.53600,4.29468,854.38751,-0.13930,12.36637,43.08126
51.73600,4.31130,853.09669,-0.13930,12.43286,43.01617
51.93600,4.32798,852.08034,-0.13929,12.49959,42.96492
52.13600,4.34466,851.53366,-0.13929,12.56631,42.93736
52.33600,4.36128,850.03367,-0.13929,12.63279,42.86172
52.53600,4.37797,849.26086,-0.13930,12.69952,42.82275
52.73600,4.39465,847.88399,-0.13929,12.76625,42.75333
52.93600,4.41133,846.49837,-0.13930,12.83297,42.68346
53.13600,4.42801,845.44681,-0.13930,12.89970,42.63044
53.33600,4.44469,844.24149,-0.13930,12.96642,42.56966
53.53600,4.46131,843.37145,-0.13930,13.03291,42.52579
53.73600,4.47799,842.01610,-0.13930,13.09963,42.45745
53.93600,4.49468,840.40314,-0.13929,13.16636,42.37612
54.13600,4.51148,839.94297,-0.13930,13.23356,42.35291
54.33600,4.52804,838.19283,-0.13929,13.29981,42.26466
54.53600,4.54460,837.51455,-0.13930,13.36605,42.23046
54.73600,4.56134,835.76618,-0.13930,13.43302,42.14230
54.93600,4.57796,834.22922,-0.13930,13.49951,42.06480
55.13600,4.59470,833.23978,-0.13930,13.56647,42.01492
55.33600,4.61138,831.78468,-0.13929,13.63319,41.94154
55.53600,4.62795,829.77694,-0.13930,13.69944,41.84031
55.73600,4.64463,829.14960,-0.13930,13.76617,41.80867
55.93600,4.66137,827.32458,-0.13929,13.83313,41.71665
56.13600,4.67811,825.50850,-0.13930,13.90010,41.62508
56.33600,4.69467,824.40088,-0.13930,13.96634,41.56923
56.53600,4.71129,822.56151,-0.13930,14.03283,41.47648
56.73600,4.72803,821.18856,-0.13930,14.09979,41.40725
56.93600,4.74459,819.67600,-0.13929,14.16604,41.33098
57.13600,4.76134,817.34918,-0.13930,14.23300,41.21365
57.33600,4.77808,815.63368,-0.13930,14.29997,41.12715
57.53600,4.79464,814.09458,-0.13930,14.36622,41.04955
57.73600,4.81126,812.05005,-0.13929,14.43270,40.94645
57.93600,4.82800,809.76114,-0.13930,14.49966,40.83104
58.13600,4.84462,808.12387,-0.13930,14.56615,40.74848
58.33600,4.86142,806.05922,-0.13930,14.63335,40.64437
58.53600,4.87799,804.01162,-0.13930,14.69960,40.54113
58.73600,4.89467,801.55861,-0.13929,14.76632,40.41744
58.93600,4.91129,799.46807,-0.13930,14.83281,40.31202
59.13600,4.92797,796.56420,-0.13930,14.89954,40.16560
59.33600,4.94471,794.51827,-0.13930,14.96650,40.06244
59.53600,4.96127,792.34820,-0.13930,15.03275,39.95301
59.73600,4.97795,789.90171,-0.13930,15.09947,39.82965
59.93600,4.99463,787.22928,-0.13930,15.16620,39.69490
60.13600,5.01138,784.42525,-0.13930,15.23316,39.55351
60.33600,5.02800,781.95957,-0.13930,15.29965,39.42918
60.53600,5.04468,779.49502,-0.13930,15.36637,39.30491
60.73600,5.06130,775.76488,-0.13930,15.43286,39.11683
60.93600,5.07792,773.35886,-0.13929,15.49934,38.99551
61.13600,5.09466,770.15720,-0.13930,15.56631,38.83406
61.33600,5.11140,766.95536,-0.13930,15.63327,38.67262
61.53600,5.12803,764.27916,-0.13930,15.69976,38.53767
61.73600,5.14471,761.17702,-0.13930,15.76648,38.38125
61.93600,5.16133,758.12996,-0.13930,15.83297,38.22761
62.13600,5.17795,754.82703,-0.13930,15.89945,38.06107
62.33600,5.19463,751.69969,-0.13930,15.96618,37.90337
62.53600,5.21137,748.67927,-0.13930,16.03314,37.75107
62.73600,5.22799,745.38579,-0.13930,16.09963,37.58500
62.93600,5.24467,741.92979,-0.13930,16.16636,37.41074
63.13600,5.26130,739.23022,-0.13930,16.23284,37.27462
63.33600,5.27798,736.99849,-0.13930,16.29957,37.16209
63.53600,5.29466,733.53187,-0.13930,16.36629,36.98729
63.73600,5.31140,730.76882,-0.13930,16.43326,36.84797
63.93600,5.32802,727.51441,-0.13930,16.49974,36.68386
64.13600,5.34458,725.01972,-0.13930,16.56599,36.55807
64.33601,5.36132,722.21649,-0.13930,16.63295,36.41673
64.53600,5.37806,719.79435,-0.13930,16.69992,36.29459
64.73600,5.39475,717.61422,-0.13930,16.76664,36.18466
64.93600,5.41131,714.35622,-0.13930,16.83289,36.02038
65.13600,5.42799,712.77455,-0.13930,16.89961,35.94063
65.33601,5.44467,710.17887,-0.13930,16.96634,35.80975
65.53600,5.46129,707.67445,-0.13930,17.03283,35.68346
65.73600,5.47797,705.50316,-0.13930,17.09955,35.57398
65.93601,5.49465,703.58166,-0.13930,17.16627,35.47709
66.13600,5.51128,701.46387,-0.13930,17.23276,35.37030
66.33601,5.52802,699.80216,-0.13930,17.29973,35.28651
66.53600,5.54470,697.95088,-0.13930,17.36645,35.19316
66.73600,5.56132,696.22383,-0.13930,17.43294,35.10608
66.93601,5.57806,693.94186,-0.13930,17.49990,34.99102
67.13600,5.59468,693.23005,-0.13930,17.56638,34.95512
67.33601,5.61130,691.62319,-0.13930,17.63287,34.87410
67.53600,5.62799,690.12213,-0.13930,17.69960,34.79841
67.73600,5.64467,688.82033,-0.13930,17.76632,34.73277
67.93601,5.66141,687.46605,-0.13930,17.83329,34.66449
68.13600,5.67797,686.59293,-0.13930,17.89953,34.62046
68.33601,5.69459,684.71269,-0.13930,17.96602,34.52565
68.53600,5.71133,683.74141,-0.13930,18.03298,34.47667
68.73600,5.72795,682.71379,-0.13930,18.09947,34.42486
68.93601,5.74463,681.30302,-0.13930,18.16619,34.35372
69.13600,5.76138,680.69734,-0.13930,18.23316,34.32318
69.33601,5.77800,679.89011,-0.13930,18.29965,34.28248
69.53600,5.79462,679.25737,-0.13930,18.36613,34.25057
69.73600,5.81136,677.77908,-0.13930,18.43309,34.17603
69.93601,5.82810,677.95678,-0.13930,18.50006,34.18499
70.13600,5.84466,676.68450,-0.13930,18.56631,34.12084
70.33601,5.86128,675.69460,-0.13930,18.63279,34.07093
70.53600,5.87808,676.10284,-0.13930,18.69999,34.09151
70.73600,5.89465,675.18228,-0.13930,18.76624,34.04509
70.93601,5.91127,674.27200,-0.13930,18.83273,33.99920
71.13600,5.92807,673.20522,-0.13930,18.89993,33.94540
71.33601,5.94469,674.01747,-0.13930,18.96642,33.98636
71.53600,5.96131,672.84955,-0.13930,19.03290,33.92747
71.73600,5.97799,672.90594,-0.13930,19.09963,33.93031
71.93601,5.99467,672.28745,-0.13930,19.16635,33.89912
72.13600,6.01130,672.04689,-0.13930,19.23284,33.88699
72.33601,6.02804,671.80297,-0.13930,19.29980,33.87469
72.53600,6.04472,670.89722,-0.13930,19.36653,33.82903
72.73600,6.06128,670.97149,-0.13930,19.43277,33.83277
72.93601,6.07790,670.75440,-0.13930,19.49926,33.82182
73.13600,6.09470,670.12594,-0.13930,19.56646,33.79013
73.33601,6.11132,670.22396,-0.13930,19.63295,33.79508
73.53600,6.12794,669.58615,-0.13930,19.69943,33.76292
73.73600,6.14463,669.17739,-0.13930,19.76616,33.74231
73.93601,6.16131,669.54228,-0.13930,19.83289,33.76070
74.13600,6.17793,669.58102,-0.13930,19.89937,33.76266
74.33601,6.19467,669.09380,-0.13930,19.96634,33.73809
74.53600,6.21147,669.05995,-0.13930,20.03354,33.73638
74.73600,6.22791,669.07844,-0.13930,20.09931,33.73732
74.93601,6.24459,668.92309,-0.13930,20.16603,33.72948
75.13600,6.26139,668.87327,-0.13930,20.23324,33.72697
75.33601,6.27796,668.58931,-0.13930,20.29948,33.71265
75.53600,6.29470,668.00700,-0.13930,20.36645,33.68329
75.73600,6.31138,668.27140,-0.13930,20.43317,33.69662
75.93601,6.32794,668.47634,-0.13930,20.49942,33.70695
76.13600,6.34462,667.97012,-0.13930,20.56614,33.68143
76.33601,6.36130,668.65575,-0.13930,20.63287,33.71600
76.53600,6.37804,667.91307,-0.13930,20.69983,33.67855
76.73600,6.39467,667.94707,-0.13930,20.76632,33.68027
76.93601,6.41135,667.62511,-0.13930,20.83305,33.66403
77.13600,6.42815,668.42157,-0.13930,20.90025,33.70419
77.33601,6.44459,668.54986,-0.13930,20.96601,33.71066
77.53600,6.46133,668.61915,-0.13930,21.03298,33.71416
77.73600,6.47813,668.71177,-0.13930,21.10018,33.71883
77.93601,6.49469,668.80835,-0.13930,21.16643,33.72370
78.13600,6.51126,669.04533,-0.13930,21.23268,33.73565
78.33601,6.52800,669.05734,-0.13930,21.29964,33.73625
78.53600,6.54474,668.90437,-0.13930,21.36661,33.72854
78.73600,6.56130,669.37604,-0.13930,21.43285,33.75232
78.93601,6.57798,669.42670,-0.13930,21.49958,33.75488
79.13600,6.59472,669.76473,-0.13930,21.56654,33.77192
79.33601,6.61122,670.19076,-0.13930,21.63255,33.79340
79.53600,6.62796,669.89670,-0.13930,21.69951,33.77858
79.73600,6.64470,670.19477,-0.13930,21.76648,33.79361
79.93601,6.66127,670.10731,-0.13930,21.83272,33.78920
80.13600,6.67795,670.59230,-0.13930,21.89945,33.81365
80.33601,6.69463,669.90010,-0.13930,21.96618,33.77875
80.53600,6.71137,670.75668,-0.13930,22.03314,33.82194
80.73600,6.72793,670.87044,-0.13930,22.09939,33.82767
80.93601,6.74467,671.13070,-0.13930,22.16635,33.84080
81.13600,6.76135,671.28409,-0.13930,22.23308,33.84853
81.33601,6.77792,671.32232,-0.13930,22.29932,33.85046
81.53600,6.79454,671.49769,-0.13930,22.36581,33.85930
81.73601,6.81134,671.41964,-0.13930,22.43301,33.85537
81.93601,6.82802,671.77112,-0.13930,22.49974,33.87309
82.13600,6.84470,672.12936,-0.13930,22.56646,33.89116
82.33601,6.86126,672.38673,-0.13930,22.63271,33.90413
82.53600,6.87794,672.59385,-0.13930,22.69943,33.91457
82.73601,6.89469,672.22812,-0.13930,22.76640,33.89613
82.93601,6.91137,672.57700,-0.13930,22.83312,33.91373
83.13600,6.92811,672.78361,-0.13930,22.90009,33.92414
83.33601,6.94461,673.07921,-0.13930,22.96610,33.93905
83.53600,6.96129,672.80363,-0.13930,23.03282,33.92515
83.73601,6.97803,673.26650,-0.13930,23.09978,33.94849
83.93601,6.99459,673.56965,-0.13930,23.16603,33.96378
84.13600,7.01133,673.29067,-0.13930,23.23299,33.94971
84.33601,7.02808,673.29388,-0.13930,23.29996,33.94987
84.53600,7.04464,673.48126,-0.13930,23.36621,33.95932
84.73601,7.06126,673.58757,-0.13930,23.43269,33.96468
84.93601,7.07806,673.21928,-0.13930,23.49989,33.94611
85.13600,7.09474,674.16048,-0.13930,23.56662,33.99357
85.33601,7.11130,673.56941,-0.13930,23.63287,33.96377
85.53600,7.12798,673.93775,-0.13930,23.69959,33.98234
85.73601,7.14472,674.23894,-0.13930,23.76656,33.99753
85.93601,7.16129,674.25701,-0.13930,23.83280,33.99844
86.13600,7.17797,674.61398,-0.13930,23.89953,34.01644
86.33601,7.19471,674.35279,-0.13930,23.96649,34.00327
86.53600,7.21127,674.49240,-0.13930,24.03274,34.01031
86.73601,7.22795,674.74199,-0.13930,24.09947,34.02289
86.93601,7.24463,674.25333,-0.13930,24.16619,33.99825
87.13600,7.26131,673.72979,-0.13930,24.23292,33.97185
87.33601,7.27800,673.96173,-0.13930,24.29964,33.98355
87.53600,7.29468,674.45314,-0.13930,24.36637,34.00833
87.73601,7.31130,674.46441,-0.13930,24.43285,34.00890
87.93601,7.32798,674.27699,-0.13930,24.49958,33.99944
88.13600,7.34466,673.90045,-0.13930,24.56630,33.98046
88.33601,7.36140,674.33636,-0.13930,24.63326,34.00244
88.53600,7.37802,673.90604,-0.13930,24.69975,33.98074
88.73601,7.39470,674.18991,-0.13930,24.76648,33.99505
88.93601,7.41133,673.82292,-0.13930,24.83296,33.97655
89.13600,7.42801,674.05854,-0.13930,24.89969,33.98843
89.33601,7.44475,674.05119,-0.13930,24.96665,33.98806
89.53600,7.46137,674.09030,-0.13930,25.03314,33.99003
89.73601,7.47799,673.61174,-0.13930,25.09963,33.96590
89.93601,7.49467,673.83898,-0.13930,25.16635,33.97736
90.13600,7.51129,674.01598,-0.13930,25.23283,33.98628
90.33601,7.52809,674.08136,-0.13930,25.30003,33.98958
90.53600,7.54472,674.31647,-0.13930,25.36652,34.00143
90.73601,7.56128,674.28476,-0.13930,25.43277,33.99984
90.93601,7.57802,674.27973,-0.13930,25.49973,33.99958
91.13600,7.59464,674.30772,-0.13930,25.56622,34.00100
91.33601,7.61132,674.49370,-0.13930,25.63295,34.01037
91.53600,7.62800,674.03358,-0.13930,25.69967,33.98717
91.73601,7.64468,674.33272,-0.13930,25.76640,34.00225
91.93601,7.66125,674.87895,-0.13930,25.83264,34.02980
92.13600,7.67793,674.19666,-0.13930,25.89937,33.99540
92.33601,7.69473,674.30739,-0.13930,25.96657,34.00098
92.53600,7.71135,674.97347,-0.13930,26.03306,34.03456
92.73601,7.72803,674.22315,-0.13930,26.09978,33.99673
92.93601,7.74471,674.95201,-0.13930,26.16651,34.03348
93.13600,7.76127,674.36239,-0.13930,26.23276,34.00375
93.33601,7.77801,674.15689,-0.13930,26.29972,33.99339
93.53600,7.79470,674.45710,-0.13930,26.36644,34.00853
93.73601,7.81132,674.38576,-0.13930,26.43293,34.00493
93.93601,7.82800,674.54726,-0.13930,26.49965,34.01307
94.13600,7.84462,674.11615,-0.13930,26.56614,33.99133
94.33601,7.86136,674.37328,-0.13930,26.63310,34.00430
94.53600,7.87798,674.51154,-0.13930,26.69959,34.01127
94.73601,7.89460,675.20845,-0.13930,26.76608,34.04641
94.93601,7.91134,674.06157,-0.13930,26.83304,33.98858
95.13600,7.92791,673.72862,-0.13930,26.89928,33.97179
95.33601,7.94459,674.56239,-0.13930,26.96601,34.01384
95.53600,7.96133,673.90013,-0.13930,27.03297,33.98044
95.73601,7.97801,673.95205,-0.13930,27.09970,33.98306
95.93601,7.99475,673.60057,-0.13930,27.16666,33.96534
96.13600,8.01131,673.99195,-0.13930,27.23291,33.98507
96.33601,8.02805,673.44466,-0.13930,27.29988,33.95748
96.53600,8.04468,673.11940,-0.13930,27.36636,33.94107
96.73601,8.06136,673.59577,-0.13930,27.43309,33.96510
96.93601,8.07804,673.32336,-0.13930,27.49981,33.95136
97.13600,8.09466,673.14380,-0.13930,27.56630,33.94231
97.33601,8.11128,672.61402,-0.13930,27.63278,33.91559
97.53600,8.12796,672.73933,-0.13930,27.69951,33.92191
97.73601,8.14464,673.04568,-0.13930,27.76623,33.93736
97.93601,8.16138,672.55078,-0.13930,27.83320,33.91240
98.13600,8.17801,672.89895,-0.13930,27.89968,33.92996
98.33601,8.19469,672.68410,-0.13930,27.96641,33.91912
98.53600,8.21125,672.72582,-0.13930,28.03265,33.92123
98.73601,8.22799,672.81658,-0.13930,28.09962,33.92580
98.93601,8.24479,672.70193,-0.13930,28.16682,33.92002
99.13600,8.26129,672.28856,-0.13930,28.23283,33.89918
99.33601,8.27797,672.56079,-0.13930,28.29956,33.91291
99.53600,8.29472,672.95879,-0.13930,28.36652,33.93298
99.73601,8.31134,672.14989,-0.13930,28.43300,33.89219
99.93601,8.32796,671.73736,-0.13930,28.49949,33.87139
100.13600,8.34470,671.61638,-0.13930,28.56646,33.86529
100.33601,8.36138,671.84744,-0.13930,28.63318,33.87694
100.53600,8.37800,671.79357,-0.13930,28.69967,33.87422
100.73601,8.39468,671.87920,-0.13930,28.76639,33.87854
100.93601,8.41142,671.69354,-0.13930,28.83336,33.86918
101.13600,8.42799,671.83110,-0.13930,28.89960,33.87611
101.33601,8.44467,671.11701,-0.13930,28.96633,33.84011
101.53600,8.46141,671.28981,-0.13930,29.03329,33.84882
101.73601,8.47797,670.57535,-0.13930,29.09954,33.81279
101.93601,8.49465,670.75696,-0.13930,29.16627,33.82195
102.13600,8.51133,670.90550,-0.13930,29.23299,33.82944
102.33601,8.52795,670.43938,-0.13929,29.29947,33.80594
102.53600,8.54458,670.97521,-0.13930,29.36596,33.83296
102.73601,8.56126,671.01321,-0.13930,29.43269,33.83487
102.93601,8.57806,670.37856,-0.13930,29.49989,33.80287
103.13600,8.59468,670.18969,-0.13930,29.56638,33.79335
103.33601,8.61136,670.35989,-0.13930,29.63310,33.80193
103.53600,8.62804,669.88678,-0.13930,29.69983,33.77808
103.73601,8.64466,670.00319,-0.13930,29.76631,33.78394
103.93601,8.66129,670.06927,-0.13930,29.83280,33.78728
104.13600,8.67803,669.99430,-0.13930,29.89976,33.78350
104.33601,8.69465,669.32575,-0.13930,29.96625,33.74979
104.53600,8.71127,670.20138,-0.13930,30.03274,33.79394
104.73601,8.72801,670.25167,-0.13930,30.09970,33.79647
104.93601,8.74469,669.10326,-0.13930,30.16642,33.73857
105.13600,8.76119,669.95807,-0.13930,30.23243,33.78167
105.33601,8.77799,669.78182,-0.13930,30.29963,33.77278
105.53600,8.79480,669.63816,-0.13930,30.36684,33.76554
105.73601,8.81124,669.17255,-0.13930,30.43261,33.74206
105.93601,8.82798,669.66028,-0.13930,30.49957,33.76665
106.13600,8.84478,669.09972,-0.13930,30.56678,33.73839
106.33601,8.86128,669.86778,-0.13930,30.63278,33.77711
106.53600,8.87796,670.06270,-0.13930,30.69951,33.78695
106.73601,8.89476,669.60501,-0.13930,30.76671,33.76387
106.93601,8.91132,669.53083,-0.13930,30.83296,33.76013
107.13600,8.92795,669.68827,-0.13930,30.89944,33.76807
107.33601,8.94469,669.78624,-0.13930,30.96641,33.77301
107.53600,8.96143,669.76957,-0.13930,31.03337,33.77216
107.73601,8.97793,669.70144,-0.13930,31.09938,33.76873
107.93601,8.99461,669.33180,-0.13930,31.16610,33.75009
108.13600,9.01135,669.82387,-0.13930,31.23307,33.77490
108.33601,9.02797,669.68873,-0.13930,31.29955,33.76809
108.53600,9.04466,669.11774,-0.13930,31.36628,33.73930
108.73601,9.06146,668.52970,-0.13930,31.43348,33.70964
108.93601,9.07796,668.52681,-0.13930,31.49949,33.70950
109.13600,9.09464,668.71722,-0.13930,31.56621,33.71910
109.33601,9.11132,668.23415,-0.13929,31.63294,33.69474
109.53600,9.12800,667.55917,-0.13930,31.69966,33.66071
109.73601,9.14462,667.61193,-0.13930,31.76615,33.66337
109.93601,9.16130,667.07712,-0.13930,31.83288,33.63640
110.13600,9.17805,666.09625,-0.13930,31.89984,33.58694
110.33601,9.19461,665.52684,-0.13930,31.96609,33.55823
110.53600,9.21129,664.22950,-0.13930,32.03281,33.49281
110.73601,9.22803,663.61963,-0.13930,32.09978,33.46206
110.93601,9.24471,662.60286,-0.13930,32.16650,33.41079
111.13600,9.26133,661.90101,-0.13930,32.23299,33.37540
111.33601,9.27807,661.29710,-0.13930,32.29995,33.34495
111.53600,9.29463,659.57755,-0.13930,32.36620,33.25825
111.73601,9.31132,657.86103,-0.13930,32.43292,33.17169
111.93601,9.32806,657.18545,-0.13930,32.49989,33.13763
112.13600,9.34474,656.03242,-0.13930,32.56661,33.07949
112.33601,9.36124,654.76419,-0.13929,32.63262,33.01554
112.53600,9.37792,652.88129,-0.13930,32.69935,32.92060
112.73601,9.39472,650.24314,-0.13930,32.76655,32.78757
112.93601,9.41128,646.71901,-0.13929,32.83280,32.60987
113.13600,9.42797,641.66836,-0.13930,32.89952,32.35520
113.33601,9.44471,634.52832,-0.13930,32.96649,31.99518
113.53600,9.46133,604.19864,-0.13930,33.03297,30.46585
113.73601,9.47795,522.56640,-0.13930,33.09946,26.34966
113.84200,9.48698,5.89423,-0.13930,33.13557,0.29721