File: Manufatura Aditiva/Dados/Ensaios AMR/Ensaios/Ensaios FDM/Tracao_OLABI_23_05_2018_FDM_YX2.is_metal_RawData/Specimen_RawData_2.csv
Time,Extension,Load,Strain 1,Tensile strain,Tensile stress
(sec),(mm),(N),(mm/mm),(%),(MPa)
0.00000,0.00006,20.89292,0.00054,0.05395,1.05665
0.20000,0.01387,25.72712,0.00068,0.06833,1.30114
0.40000,0.03265,34.52484,0.00093,0.09297,1.74608
0.60000,0.04986,41.95318,0.00116,0.11629,2.12176
0.80000,0.06667,49.34678,0.00139,0.13895,2.49569
1.00000,0.08329,55.96551,0.00161,0.16137,2.83043
1.20000,0.10003,63.50321,0.00184,0.18389,3.21164
1.40000,0.11671,71.27156,0.00208,0.20754,3.60453
1.60000,0.13339,77.79509,0.00230,0.23048,3.93445
1.80000,0.14995,84.47117,0.00253,0.25337,4.27209
2.00000,0.16657,91.78755,0.00276,0.27602,4.64211
2.20000,0.18331,98.00835,0.00297,0.29712,4.95673
2.40000,0.19994,105.21103,0.00321,0.32073,5.32100
2.60000,0.21662,112.06847,0.00345,0.34503,5.66781
2.80000,0.23330,119.10367,0.00369,0.36885,6.02361
3.00000,0.24998,125.18190,0.00393,0.39253,6.33102
3.20000,0.26672,133.43018,0.00417,0.41653,6.74817
3.40000,0.28340,139.48366,0.00441,0.44129,7.05432
3.60000,0.30002,145.84388,0.00466,0.46551,7.37599
3.80000,0.31670,153.05913,0.00490,0.48954,7.74089
4.00000,0.33333,160.23826,0.00514,0.51447,8.10397
4.20000,0.35001,166.60324,0.00539,0.53866,8.42588
4.40000,0.36663,173.08397,0.00563,0.56336,8.75364
4.60000,0.38331,178.79962,0.00584,0.58383,9.04271
4.80000,0.40005,185.76981,0.00609,0.60890,9.39522
5.00000,0.41661,192.28167,0.00634,0.63364,9.72456
5.20000,0.43329,199.81267,0.00659,0.65878,10.10543
5.40000,0.45004,206.32115,0.00684,0.68396,10.43459
5.60000,0.46666,212.95452,0.00709,0.70862,10.77007
5.80000,0.48328,219.12898,0.00733,0.73339,11.08234
6.00000,0.50002,226.41874,0.00759,0.75900,11.45102
6.20000,0.51670,233.00708,0.00784,0.78410,11.78422
6.40000,0.53332,239.41032,0.00809,0.80901,12.10806
6.60000,0.54994,245.60462,0.00832,0.83209,12.42134
6.80000,0.56680,251.67447,0.00856,0.85572,12.72832
7.00000,0.58331,258.16748,0.00882,0.88171,13.05670
7.20000,0.59993,265.32407,0.00907,0.90735,13.41864
7.40000,0.61673,271.90472,0.00933,0.93290,13.75145
7.60000,0.63329,278.19499,0.00958,0.95830,14.06958
7.80000,0.64991,284.85451,0.00984,0.98379,14.40638
8.00000,0.66671,291.69649,0.01009,1.00915,14.75241
8.20000,0.68327,298.06169,0.01035,1.03457,15.07433
8.40000,0.69996,304.43417,0.01061,1.06052,15.39661
8.60000,0.71664,310.23244,0.01081,1.08091,15.68986
8.80000,0.73338,315.98376,0.01107,1.10705,15.98073
9.00000,0.75000,322.78378,0.01132,1.13224,16.32464
9.20000,0.76662,329.24823,0.01158,1.15828,16.65157
9.40000,0.78336,334.92884,0.01185,1.18470,16.93887
9.60000,0.79992,341.97024,0.01211,1.21099,17.29498
9.80000,0.81666,348.42293,0.01236,1.23638,17.62132
10.00000,0.83341,353.64579,0.01262,1.26234,17.88547
10.20000,0.85003,360.83970,0.01288,1.28843,18.24930
10.40000,0.86665,365.08392,0.01309,1.30903,18.46395
10.60000,0.88333,371.02331,0.01335,1.33507,18.76433
10.80000,0.89995,377.14359,0.01361,1.36064,19.07386
11.00000,0.91663,383.15784,0.01387,1.38715,19.37803
11.20000,0.93331,389.23291,0.01413,1.41311,19.68527
11.40000,0.95006,395.27426,0.01439,1.43912,19.99081
11.60000,0.96656,401.85773,0.01466,1.46593,20.32376
11.80000,0.98324,407.72893,0.01492,1.49208,20.62070
12.00000,1.00010,411.57282,0.01510,1.50958,20.81510
12.20000,1.01666,417.35731,0.01535,1.53493,21.10765
12.40000,1.03328,423.21677,0.01562,1.56175,21.40399
12.60000,1.05002,429.13435,0.01588,1.58840,21.70327
12.80000,1.06670,435.24751,0.01615,1.61477,22.01244
13.00000,1.08327,440.68932,0.01641,1.64114,22.28765
13.20000,1.10001,446.96610,0.01668,1.66771,22.60510
13.40000,1.11675,453.22147,0.01694,1.69400,22.92146
13.60000,1.13325,458.66789,0.01719,1.71883,23.19691
13.80000,1.14993,463.36972,0.01741,1.74064,23.43470
14.00000,1.16679,469.54174,0.01767,1.76713,23.74685
14.20000,1.18323,475.30006,0.01794,1.79382,24.03807
14.40000,1.19998,481.07640,0.01821,1.82103,24.33021
14.60000,1.21672,486.92296,0.01848,1.84817,24.62590
14.80000,1.23334,492.78252,0.01874,1.87426,24.92224
15.00000,1.24996,499.38317,0.01901,1.90110,25.25607
15.20000,1.26670,504.01092,0.01928,1.92805,25.49011
15.40000,1.28338,508.52327,0.01948,1.94800,25.71832
15.60000,1.29994,513.91535,0.01975,1.97466,25.99103
15.80000,1.31656,519.99097,0.02002,2.00163,26.29830
16.00000,1.33337,525.45518,0.02029,2.02850,26.57465
16.20000,1.34993,530.44343,0.02055,2.05504,26.82693
16.40000,1.36667,535.69782,0.02082,2.08216,27.09266
16.60000,1.38341,541.34135,0.02110,2.10963,27.37808
16.80000,1.40003,546.23154,0.02135,2.13545,27.62540
17.00000,1.41671,550.20493,0.02157,2.15680,27.82635
17.20000,1.43333,555.30942,0.02184,2.18387,28.08451
17.40000,1.45001,561.13517,0.02211,2.21137,28.37914
17.60000,1.46670,566.32962,0.02239,2.23854,28.64185
17.80000,1.48338,571.49353,0.02266,2.26557,28.90302
18.00000,1.49994,577.17529,0.02293,2.29303,29.19037
18.20000,1.51656,581.54748,0.02320,2.32037,29.41149
18.40000,1.53324,585.12157,0.02341,2.34088,29.59225
18.60000,1.55004,590.82084,0.02368,2.36820,29.88048
18.80000,1.56666,595.55122,0.02396,2.39561,30.11972
19.00000,1.58329,601.01794,0.02423,2.42318,30.39620
19.20000,1.60003,605.18002,0.02451,2.45075,30.60669
19.40000,1.61665,610.40400,0.02479,2.47863,30.87089
19.60000,1.63333,615.32878,0.02506,2.50632,31.11996
19.80000,1.65007,620.79998,0.02534,2.53430,31.39667
20.00000,1.66675,624.57742,0.02555,2.55455,31.58771
20.20000,1.68325,628.61126,0.02582,2.58231,31.79172
20.40000,1.69999,633.85833,0.02611,2.61111,32.05708
20.60000,1.71674,638.20034,0.02639,2.63929,32.27668
20.80000,1.73330,643.30404,0.02667,2.66707,32.53480
21.00000,1.74998,648.28997,0.02695,2.69495,32.78696
21.20000,1.76672,653.20143,0.02723,2.72324,33.03535
21.40000,1.78334,657.06312,0.02751,2.75075,33.23066
21.60000,1.79996,660.36447,0.02771,2.77109,33.39762
21.80000,1.81670,664.95808,0.02800,2.79991,33.62994
22.00000,1.83339,669.96594,0.02828,2.82841,33.88321
22.20000,1.85001,674.36285,0.02857,2.85690,34.10558
22.40000,1.86669,679.07628,0.02886,2.88597,34.34396
22.60000,1.88337,683.84083,0.02914,2.91417,34.58493
22.80000,1.89993,688.23243,0.02943,2.94301,34.80703
23.00000,1.91661,692.92621,0.02972,2.97189,35.04441
23.20000,1.93329,694.92105,0.02993,2.99310,35.14530
23.40000,1.94991,699.79266,0.03022,3.02249,35.39168
23.60000,1.96660,704.25076,0.03052,3.05175,35.61715
23.80000,1.98328,708.09359,0.03081,3.11847,35.81150
23.96600,1.99715,711.82791,0.03105,3.17396,36.00036
24.16600,2.01389,715.56871,0.03134,3.24092,36.18955
24.36600,2.03051,719.96767,0.03164,3.30741,36.41203
24.56600,2.04719,724.45408,0.03194,3.37413,36.63892
24.76600,2.06387,726.31207,0.03215,3.44086,36.73289
24.96600,2.08049,730.60663,0.03244,3.50734,36.95008
25.16600,2.09724,734.59903,0.03274,3.57431,37.15200
25.36600,2.11386,738.70746,0.03305,3.64079,37.35978
25.56600,2.13048,742.48132,0.03334,3.70728,37.55064
25.76600,2.14716,746.98390,0.03364,3.77400,37.77836
25.96600,2.16378,749.71095,0.03394,3.84049,37.91628
26.16600,2.18052,753.34236,0.03465,3.90745,38.09993
26.36600,2.19714,755.22694,0.03398,3.97394,38.19524
26.56600,2.21383,758.80811,0.00885,4.04066,38.37636
26.76600,2.23051,762.76124,0.00850,4.10739,38.57629
26.96600,2.24713,766.68500,0.00797,4.17387,38.77473
27.16600,2.26387,770.12340,0.00872,4.24084,38.94863
27.36600,2.28049,773.46950,0.00916,4.30733,39.11786
27.56600,2.29717,776.97220,0.01238,4.37405,39.29500
27.76600,2.31391,780.53456,0.01318,4.44101,39.47517
27.96600,2.33047,783.61519,-0.00945,4.50726,39.63097
28.16600,2.34716,785.05548,-0.01637,4.57399,39.70381
28.36600,2.36390,787.96744,-0.01764,4.64095,39.85108
28.56600,2.38052,791.28528,-0.01903,4.70744,40.01888
28.76600,2.39714,795.33607,-0.02144,4.77392,40.22374
28.96600,2.41382,797.90689,-0.02454,4.84065,40.35376
29.16600,2.43044,800.72675,-0.02876,4.90713,40.49638
29.36600,2.44706,803.96440,-0.03765,4.97362,40.66012
29.56600,2.46381,807.03376,-0.13838,5.04058,40.81535
29.76600,2.48049,810.75756,-0.13839,5.10731,41.00368
29.96600,2.49705,812.77099,-0.13839,5.17356,41.10551
30.16600,2.51379,814.08294,-0.13839,5.24052,41.17186
30.36600,2.53053,816.82652,-0.13840,5.30748,41.31062
30.56600,2.54721,819.46002,-0.13840,5.37421,41.44380
30.76600,2.56383,822.77022,-0.13840,5.44070,41.61121
30.96600,2.58045,825.45336,-0.13840,5.50718,41.74691
31.16600,2.59720,827.51699,-0.13840,5.57415,41.85128
31.36600,2.61388,829.95016,-0.13841,5.64087,41.97433
31.56600,2.63050,833.63298,-0.13840,5.70736,42.16059
31.76600,2.64718,835.66410,-0.13841,5.77408,42.26332
31.96600,2.66374,838.33775,-0.13841,5.84033,42.39853
32.16600,2.68048,840.73609,-0.13841,5.90729,42.51983
32.36600,2.69722,841.06261,-0.13841,5.97426,42.53634
32.56600,2.71390,843.52605,-0.13841,6.04098,42.66093
32.76600,2.73053,846.22102,-0.13841,6.10747,42.79723
32.96600,2.74721,847.41479,-0.13841,6.17419,42.85760
33.16600,2.76383,850.03031,-0.13841,6.24068,42.98988
33.36600,2.78039,852.77688,-0.13841,6.30692,43.12879
33.56600,2.79719,854.22723,-0.13842,6.37413,43.20214
33.76600,2.81393,856.60899,-0.13841,6.44109,43.32259
33.96600,2.83043,858.29766,-0.13842,6.50710,43.40800
34.16600,2.84712,859.95551,-0.13841,6.57382,43.49184
34.36600,2.86386,861.14425,-0.13842,6.64079,43.55196
34.56600,2.88042,862.90520,-0.13842,6.70704,43.64102
34.76600,2.89716,864.51219,-0.13842,6.77400,43.72229
34.96600,2.91396,866.29651,-0.13842,6.84120,43.81253
35.16600,2.93046,867.69108,-0.13842,6.90721,43.88306
35.36600,2.94714,868.86063,-0.13842,6.97394,43.94221
35.56600,2.96394,870.25296,-0.13842,7.04114,44.01263
35.76600,2.98057,871.77344,-0.13842,7.10763,44.08953
35.96600,2.99707,872.66164,-0.13842,7.17363,44.13445
36.16600,3.01381,873.83157,-0.13842,7.24060,44.19362
36.36600,3.03049,875.37076,-0.13842,7.30732,44.27146
36.56600,3.04705,876.61380,-0.13842,7.37357,44.33433
36.76600,3.06379,878.44832,-0.13842,7.44053,44.42711
36.96600,3.08053,878.58196,-0.13842,7.50750,44.43387
37.16600,3.09716,879.87185,-0.13842,7.57398,44.49910
37.36600,3.11378,880.93262,-0.13842,7.64047,44.55275
37.56600,3.13052,881.92364,-0.13842,7.70743,44.60287
37.76600,3.14714,882.51755,-0.13842,7.77392,44.63291
37.96600,3.16382,883.39550,-0.13842,7.84064,44.67731
38.16600,3.18056,884.22643,-0.13842,7.90761,44.71933
38.36600,3.19724,884.80348,-0.13842,7.97433,44.74852
38.56600,3.21380,885.97136,-0.13842,8.04058,44.80758
38.76600,3.23043,886.19255,-0.13842,8.10707,44.81877
38.96600,3.24723,886.76969,-0.13842,8.17427,44.84796
39.16600,3.26379,887.29998,-0.13842,8.24052,44.87477
39.36600,3.28041,887.39293,-0.13842,8.30700,44.87948
39.56600,3.29715,886.57513,-0.13842,8.37397,44.83812
39.76600,3.31377,886.97700,-0.13842,8.44045,44.85844
39.96600,3.33045,887.45067,-0.13843,8.50718,44.88240
40.16600,3.34725,887.76471,-0.13843,8.57438,44.89828
40.36600,3.36388,888.56397,-0.13842,8.64087,44.93870
40.56600,3.38044,888.71615,-0.13842,8.70711,44.94640
40.76600,3.39712,889.06288,-0.13842,8.77384,44.96394
40.96600,3.41392,888.87196,-0.13842,8.84104,44.95428
41.16600,3.43048,888.97170,-0.13843,8.90729,44.95932
41.36600,3.44716,889.03615,-0.13843,8.97401,44.96258
41.56600,3.46390,889.51671,-0.13842,9.04098,44.98689
41.76600,3.48041,889.71108,-0.13843,9.10699,44.99672
41.96600,3.49709,889.17864,-0.13843,9.17371,44.96979
42.16600,3.51389,888.16760,-0.13843,9.24091,44.91866
42.36600,3.53057,888.40527,-0.13843,9.30764,44.93068
42.56600,3.54713,888.67340,-0.13843,9.37389,44.94424
42.76600,3.56381,888.09598,-0.13843,9.44061,44.91504
42.96600,3.58061,887.96839,-0.13843,9.50782,44.90858
43.16600,3.59706,888.65524,-0.13842,9.57358,44.94332
43.36600,3.61380,887.23628,-0.13843,9.64055,44.87156
43.56600,3.63060,887.16466,-0.13842,9.70775,44.86793
43.76600,3.64716,886.32246,-0.13843,9.77400,44.82534
43.96600,3.66378,885.84339,-0.13843,9.84048,44.80111
44.16600,3.68058,885.04292,-0.13843,9.90769,44.76063
44.36600,3.69720,885.15282,-0.13843,9.97417,44.76619
44.56600,3.71382,883.79448,-0.13843,10.04066,44.69749
44.76600,3.73045,883.16035,-0.13843,10.10715,44.66542
44.96600,3.74713,882.89538,-0.13843,10.17387,44.65202
45.16600,3.76375,882.29589,-0.13843,10.24036,44.62170
45.36600,3.78043,881.28382,-0.13843,10.30708,44.57051
45.56600,3.79723,881.50417,-0.13843,10.37428,44.58166
45.76600,3.81379,880.52480,-0.13843,10.44053,44.53212
45.96600,3.83047,879.36614,-0.13843,10.50726,44.47353
46.16600,3.84716,878.74411,-0.13843,10.57398,44.44207
46.36600,3.86384,877.64934,-0.13843,10.64071,44.38670
46.56600,3.88052,876.69967,-0.13843,10.70743,44.33867
46.76600,3.89714,876.12355,-0.13843,10.77392,44.30953
46.96600,3.91382,874.72014,-0.13843,10.84064,44.23856
47.16600,3.93044,874.80536,-0.13843,10.90713,44.24287
47.36600,3.94712,873.40148,-0.13843,10.97385,44.17187
47.56600,3.96392,872.19384,-0.13843,11.04106,44.11079
47.76600,3.98043,871.52394,-0.13843,11.10707,44.07691
47.96600,3.99711,870.31843,-0.13843,11.17379,44.01594
48.16600,4.01391,869.30860,-0.13843,11.24099,43.96487
48.36600,4.03047,869.06264,-0.13843,11.30724,43.95243
48.56600,4.04721,867.75376,-0.13843,11.37420,43.88623
48.76600,4.06395,866.45484,-0.13843,11.44117,43.82055
48.96600,4.08051,865.68501,-0.13843,11.50741,43.78161
49.16600,4.09707,864.14665,-0.13843,11.57366,43.70381
49.36600,4.11388,863.54678,-0.13843,11.64087,43.67347
49.56600,4.13062,862.03199,-0.13843,11.70783,43.59686
49.76600,4.14712,861.37205,-0.13843,11.77384,43.56348
49.96600,4.16374,860.25018,-0.13843,11.84032,43.50674
50.16600,4.18054,858.55005,-0.13843,11.90753,43.42076
50.36600,4.19710,857.77137,-0.13843,11.97377,43.38138
50.56600,4.21378,856.69123,-0.13843,12.04050,43.32675
50.76600,4.23052,855.45070,-0.13843,12.10746,43.26402
50.96600,4.24721,854.13530,-0.13843,12.17419,43.19749
51.16600,4.26383,853.41837,-0.13843,12.24067,43.16123
51.36600,4.28051,851.83699,-0.13843,12.30740,43.08125
51.56600,4.29719,851.09575,-0.13843,12.37412,43.04377
51.76600,4.31387,849.80410,-0.13843,12.44085,42.97844
51.96600,4.33049,848.82872,-0.13843,12.50733,42.92911
52.16600,4.34711,847.02736,-0.13843,12.57382,42.83801
52.36600,4.36374,846.29254,-0.13843,12.64031,42.80085
52.56600,4.38048,844.50543,-0.13843,12.70727,42.71046
52.76600,4.39710,843.51469,-0.13843,12.77376,42.66035
52.96600,4.41384,842.14555,-0.13843,12.84072,42.59111
53.16600,4.43052,840.78042,-0.13843,12.90745,42.52207
53.36600,4.44714,839.51587,-0.13844,12.97393,42.45812
53.56600,4.46382,837.94808,-0.13844,13.04066,42.37883
53.76600,4.48051,836.61946,-0.13843,13.10738,42.31163
53.96600,4.49719,836.05936,-0.13843,13.17411,42.28331
54.16600,4.51393,834.06307,-0.13843,13.24107,42.18235
54.36600,4.53049,832.93095,-0.13843,13.30732,42.12509
54.56600,4.54711,831.19310,-0.13843,13.37380,42.03720
54.76600,4.56385,830.21279,-0.13843,13.44077,41.98762
54.96600,4.58053,828.69008,-0.13844,13.50749,41.91061
55.16600,4.59721,826.95019,-0.13844,13.57422,41.82261
55.36600,4.61384,825.34971,-0.13843,13.64070,41.74167
55.56600,4.63046,824.52875,-0.13844,13.70719,41.70015
55.76600,4.64720,822.57744,-0.13844,13.77416,41.60146
55.96600,4.66388,820.69524,-0.13843,13.84088,41.50627
56.16600,4.68056,819.45416,-0.13843,13.90760,41.44350
56.36600,4.69718,817.77927,-0.13843,13.97409,41.35880
56.56600,4.71380,816.87588,-0.13843,14.04058,41.31311
56.76600,4.73054,813.96364,-0.13843,14.10754,41.16582
56.96600,4.74711,812.74789,-0.13843,14.17379,41.10434
57.16600,4.76379,810.56980,-0.13843,14.24051,40.99418
57.36600,4.78053,808.85179,-0.13843,14.30748,40.90730
57.56600,4.79715,807.16293,-0.13843,14.37396,40.82188
57.76600,4.81377,805.49270,-0.13843,14.44045,40.73741
57.96600,4.83045,803.12667,-0.13843,14.50717,40.61775
58.16600,4.84719,801.60229,-0.13843,14.57414,40.54066
58.36600,4.86387,799.49396,-0.13843,14.64086,40.43403
58.56600,4.88050,797.19275,-0.13843,14.70735,40.31765
58.76600,4.89718,795.94329,-0.13844,14.77407,40.25446
58.96600,4.91380,792.99426,-0.13844,14.84056,40.10531
59.16600,4.93042,790.77026,-0.13844,14.90704,39.99283
59.36600,4.94722,788.03059,-0.13843,14.97425,39.85427
59.56600,4.96378,786.31323,-0.13843,15.04050,39.76742
59.76600,4.98046,783.52764,-0.13844,15.10722,39.62654
59.96600,4.99715,781.03831,-0.13843,15.17394,39.50064
60.16600,5.01383,779.03373,-0.13844,15.24067,39.39926
60.36600,5.03045,775.63263,-0.13843,15.30716,39.22725
60.56600,5.04713,773.14442,-0.13844,15.37388,39.10141
60.76600,5.06381,770.36112,-0.13844,15.44061,38.96065
60.96600,5.08049,768.03085,-0.13843,15.50733,38.84280
61.16600,5.09711,764.80834,-0.13844,15.57382,38.67982
61.36600,5.11391,762.59170,-0.13844,15.64102,38.56771
61.56600,5.13054,759.38655,-0.13843,15.70751,38.40562
61.76600,5.14722,756.61968,-0.13843,15.77423,38.26568
61.96600,5.16384,753.43903,-0.13843,15.84072,38.10482
62.16600,5.18052,750.42285,-0.13844,15.90744,37.95228
62.36600,5.19714,747.82460,-0.13844,15.97393,37.82087
62.56600,5.21382,745.03333,-0.13844,16.04065,37.67971
62.76600,5.23050,741.67890,-0.13844,16.10738,37.51006
62.96600,5.24713,738.86542,-0.13843,16.17386,37.36777
63.16600,5.26375,735.58497,-0.13843,16.24035,37.20186
63.36600,5.28049,733.01517,-0.13844,16.30731,37.07190
63.56600,5.29711,729.94209,-0.13844,16.37380,36.91648
63.76600,5.31385,726.81266,-0.13844,16.44077,36.75821
63.96600,5.33053,723.95876,-0.13843,16.50749,36.61387
64.16600,5.34715,721.74068,-0.13844,16.57398,36.50169
64.36600,5.36377,718.29809,-0.13844,16.64046,36.32759
64.56600,5.38052,715.73467,-0.13844,16.70743,36.19794
64.76601,5.39726,713.38951,-0.13844,16.77439,36.07934
64.96600,5.41382,710.25155,-0.13844,16.84064,35.92064
65.16600,5.43044,707.92008,-0.13844,16.90712,35.80272
65.36600,5.44718,705.48831,-0.13844,16.97409,35.67974
65.56600,5.46380,703.59213,-0.13844,17.04057,35.58384
65.76601,5.48048,701.66159,-0.13844,17.10730,35.48620
65.96600,5.49717,699.19992,-0.13844,17.17402,35.36171
66.16600,5.51379,697.93561,-0.13844,17.24051,35.29776
66.36601,5.53053,695.44353,-0.13844,17.30747,35.17173
66.56600,5.54715,693.52733,-0.13844,17.37396,35.07482
66.76601,5.56383,691.76829,-0.13844,17.44069,34.98586
66.96600,5.58057,689.57875,-0.13844,17.50765,34.87512
67.16600,5.59719,688.46862,-0.13844,17.57414,34.81897
67.36601,5.61387,687.85595,-0.13843,17.64086,34.78799
67.56600,5.63044,685.79270,-0.13844,17.70711,34.68364
67.76601,5.64712,684.45383,-0.13844,17.77383,34.61593
67.96600,5.66386,682.84841,-0.13844,17.84080,34.53474
68.16600,5.68048,682.03104,-0.13844,17.90728,34.49340
68.36601,5.69710,680.54381,-0.13844,17.97377,34.41818
68.56600,5.71378,679.83903,-0.13844,18.04049,34.38254
68.76601,5.73046,678.47781,-0.13844,18.10722,34.31369
68.96600,5.74715,677.31226,-0.13844,18.17394,34.25475
69.16600,5.76383,676.62122,-0.13844,18.24067,34.21980
69.36601,5.78057,675.52510,-0.13844,18.30763,34.16436
69.56600,5.79713,674.91918,-0.13844,18.37388,34.13372
69.76601,5.81387,674.79420,-0.13844,18.44084,34.12740
69.96600,5.83061,673.99936,-0.13844,18.50781,34.08720
70.16600,5.84717,672.98994,-0.13844,18.57405,34.03615
70.36601,5.86379,672.49760,-0.13844,18.64054,34.01125
70.56600,5.88054,671.94975,-0.13844,18.70750,33.98354
70.76601,5.89716,671.59804,-0.13844,18.77399,33.96575
70.96600,5.91378,671.00404,-0.13844,18.84048,33.93571
71.16600,5.93052,670.72595,-0.13844,18.90744,33.92165
71.36601,5.94726,670.02326,-0.13843,18.97441,33.88611
71.56600,5.96376,669.41096,-0.13844,19.04041,33.85514
71.76601,5.98044,669.05846,-0.13843,19.10714,33.83731
71.96600,5.99724,668.57231,-0.13844,19.17434,33.81273
72.16600,6.01387,668.56132,-0.13844,19.24083,33.81217
72.36601,6.03049,667.80192,-0.13844,19.30731,33.77377
72.56600,6.04723,668.56495,-0.13844,19.37428,33.81236
72.76601,6.06379,667.76262,-0.13843,19.44052,33.77178
72.96600,6.08041,667.57635,-0.13844,19.50701,33.76236
73.16600,6.09715,667.71088,-0.13844,19.57397,33.76916
73.36601,6.11389,667.23223,-0.13844,19.64094,33.74495
73.56600,6.13046,666.97346,-0.13844,19.70719,33.73187
73.76601,6.14708,666.99679,-0.13844,19.77367,33.73305
73.96600,6.16382,666.37495,-0.13844,19.84064,33.70160
74.16600,6.18044,666.18449,-0.13844,19.90712,33.69197
74.36601,6.19724,666.37099,-0.13844,19.97432,33.70140
74.56600,6.21392,666.41816,-0.13844,20.04105,33.70378
74.76601,6.23042,666.36633,-0.13844,20.10706,33.70116
74.96600,6.24710,666.09462,-0.13844,20.17378,33.68742
75.16600,6.26385,665.19291,-0.13844,20.24074,33.64182
75.36601,6.28047,665.85364,-0.13844,20.30723,33.67523
75.56600,6.29721,665.61452,-0.13844,20.37420,33.66314
75.76601,6.31383,665.30476,-0.13844,20.44068,33.64747
75.96600,6.33051,665.22746,-0.13844,20.50741,33.64356
76.16600,6.34707,664.85363,-0.13844,20.57365,33.62466
76.36601,6.36375,665.85648,-0.13844,20.64038,33.67538
76.56600,6.38061,665.46542,-0.13844,20.70782,33.65560
76.76601,6.39718,664.70979,-0.13844,20.77407,33.61738
76.96600,6.41380,665.53499,-0.13844,20.84055,33.65912
77.16600,6.43060,664.69312,-0.13844,20.90776,33.61654
77.36601,6.44710,664.81312,-0.13844,20.97377,33.62261
77.56600,6.46378,664.58015,-0.13844,21.04049,33.61082
77.76601,6.48058,664.28198,-0.13844,21.10769,33.59575
77.96600,6.49726,664.20585,-0.13844,21.17442,33.59190
78.16600,6.51377,664.55011,-0.13844,21.24043,33.60931
78.36601,6.53045,663.98242,-0.13844,21.30715,33.58060
78.56600,6.54731,662.89236,-0.13844,21.37459,33.52547
78.76601,6.56381,662.58823,-0.13844,21.44060,33.51009
78.96600,6.58037,662.66698,-0.13844,21.50685,33.51407
79.16600,6.59717,661.76276,-0.13844,21.57405,33.46834
79.36601,6.61379,661.40704,-0.13844,21.64054,33.45035
79.56600,6.63042,661.14431,-0.13844,21.70702,33.43706
79.76601,6.64728,660.49583,-0.13844,21.77447,33.40426
79.96600,6.66378,660.08866,-0.13844,21.84048,33.38367
80.16600,6.68040,659.55720,-0.13844,21.90696,33.35679
80.36601,6.69714,658.70080,-0.13844,21.97392,33.31348
80.56600,6.71388,658.92157,-0.13844,22.04089,33.32465
80.76601,6.73050,658.28143,-0.13844,22.10737,33.29227
80.96600,6.74718,657.99011,-0.13844,22.17410,33.27754
81.16600,6.76381,657.11779,-0.13844,22.24059,33.23342
81.36601,6.78043,657.08086,-0.13844,22.30707,33.23155
81.56600,6.79711,656.60663,-0.13844,22.37380,33.20757
81.76601,6.81385,655.86721,-0.13844,22.44076,33.17017
81.96600,6.83053,655.38017,-0.13844,22.50749,33.14554
82.16600,6.84715,655.47084,-0.13844,22.57397,33.15013
82.36601,6.86377,655.06417,-0.13844,22.64046,33.12956
82.56600,6.88052,655.21924,-0.13844,22.70742,33.13740
82.76601,6.89720,654.20782,-0.13844,22.77415,33.08625
82.96600,6.91388,653.97555,-0.13844,22.84087,33.07450
83.16600,6.93062,653.79189,-0.13844,22.90784,33.06522
83.36601,6.94712,653.49005,-0.13844,22.97384,33.04995
83.56600,6.96380,653.39291,-0.13844,23.04057,33.04504
83.76601,6.98054,653.46379,-0.13844,23.10753,33.04862
83.96600,6.99716,652.36301,-0.13844,23.17402,32.99295
84.16600,7.01385,652.59007,-0.13844,23.24075,33.00443
84.36601,7.03053,652.29181,-0.13844,23.30747,32.98935
84.56600,7.04721,651.79593,-0.13844,23.37419,32.96427
84.76601,7.06377,652.05670,-0.13844,23.44044,32.97746
84.96600,7.08045,651.02717,-0.13844,23.50717,32.92539
85.16600,7.09731,651.00016,-0.13844,23.57461,32.92403
85.36601,7.11381,650.98731,-0.13844,23.64062,32.92337
85.56600,7.13043,650.83336,-0.13844,23.70710,32.91559
85.76601,7.14724,650.18665,-0.13844,23.77431,32.88288
85.96600,7.16386,650.43066,-0.13844,23.84079,32.89522
86.16600,7.18042,649.78427,-0.13844,23.90704,32.86253
86.36601,7.19716,649.77743,-0.13844,23.97400,32.86219
86.56600,7.21378,649.79652,-0.13844,24.04049,32.86315
86.76601,7.23040,650.00197,-0.13844,24.10697,32.87354
86.96600,7.24714,649.55242,-0.13844,24.17394,32.85081
87.16600,7.26389,648.78743,-0.13844,24.24090,32.81212
87.36601,7.28051,649.12746,-0.13844,24.30739,32.82932
87.56600,7.29719,648.47521,-0.13844,24.37411,32.79633
87.76601,7.31381,648.18934,-0.13844,24.44060,32.78187
87.96600,7.33049,648.21267,-0.13844,24.50732,32.78305
88.16601,7.34723,648.43395,-0.13844,24.57429,32.79424
88.36601,7.36385,648.05066,-0.13844,24.64078,32.77486
88.56600,7.38053,647.52433,-0.13844,24.70750,32.74824
88.76601,7.39716,647.01252,-0.13844,24.77399,32.72235
88.96600,7.41384,646.73359,-0.13844,24.84071,32.70824
89.16601,7.43052,646.67752,-0.13844,24.90744,32.70541
89.36601,7.44720,646.21517,-0.13844,24.97416,32.68203
89.56600,7.46382,645.88087,-0.13844,25.04065,32.66512
89.76601,7.48050,645.93279,-0.13844,25.10737,32.66774
89.96600,7.49718,644.75159,-0.13844,25.17410,32.60801
90.16601,7.51381,644.35042,-0.13844,25.24058,32.58772
90.36601,7.53055,644.09846,-0.13844,25.30755,32.57497
90.56600,7.54723,643.84402,-0.13844,25.37427,32.56211
90.76601,7.56379,642.89155,-0.13844,25.44052,32.51394
90.96600,7.58047,641.90002,-0.13844,25.50724,32.46379
91.16601,7.59715,641.93965,-0.13844,25.57397,32.46579
91.36601,7.61377,640.13647,-0.13844,25.64045,32.37460
91.56600,7.63051,640.36138,-0.13844,25.70742,32.38597
91.76601,7.64720,638.78875,-0.13844,25.77415,32.30644
91.96600,7.66376,638.00612,-0.13844,25.84039,32.26686
92.16601,7.68044,637.11158,-0.13844,25.90712,32.22161
92.36601,7.69724,635.94771,-0.13844,25.97432,32.16275
92.56600,7.71386,634.16697,-0.13844,26.04080,32.07269
92.76601,7.73048,632.50456,-0.13844,26.10729,31.98862
92.96600,7.74722,630.53374,-0.13844,26.17425,31.88894
93.16601,7.76384,628.29554,-0.13844,26.24074,31.77575
93.36601,7.78047,625.04085,-0.13844,26.30723,31.61115
93.56600,7.79715,621.29237,-0.13844,26.37395,31.42157
93.76601,7.81389,617.63832,-0.13844,26.44092,31.23676
93.96600,7.83051,612.32569,-0.13844,26.50740,30.96808
94.16601,7.84713,604.56377,-0.13844,26.57389,30.57553
94.36601,7.86381,591.98164,-0.13844,26.64061,29.93919
94.56600,7.88043,561.51971,-0.13844,26.70710,28.39859
94.65201,7.88773,4.11079,-0.13844,26.73628,0.20790