File: Manufatura Aditiva/Dados/Ensaios AMR/Ensaios/Ensaios FDM/Tracao_OLABI_22_05_2018_FDM_XY1.is_metal_RawData/Specimen_RawData_4.csv
Time,Extension,Load,Strain 1,Tensile strain,Tensile stress
(sec),(mm),(N),(mm/mm),(%),(MPa)
0.00000,0.00006,19.70009,0.00086,0.08593,0.98210
0.10000,0.00419,21.60866,0.00089,0.08899,1.07724
0.20000,0.01375,24.64270,0.00103,0.10260,1.22850
0.30000,0.02356,29.94342,0.00116,0.11617,1.49275
0.40000,0.03270,33.48781,0.00130,0.12969,1.66945
0.50000,0.04143,37.91635,0.00143,0.14297,1.89022
0.60000,0.04992,41.97562,0.00156,0.15558,2.09259
0.70000,0.05835,45.61698,0.00168,0.16796,2.27412
0.80000,0.06673,48.64419,0.00180,0.18027,2.42503
0.90000,0.07498,52.94369,0.00193,0.19252,2.63937
1.00000,0.08323,56.59636,0.00205,0.20483,2.82147
1.10000,0.09172,60.36475,0.00218,0.21790,3.00933
1.20000,0.09997,64.09973,0.00230,0.22997,3.19553
1.30000,0.10834,68.02903,0.00242,0.24232,3.39141
1.40000,0.11677,72.05418,0.00255,0.25523,3.59208
1.50000,0.12502,75.11223,0.00268,0.26791,3.74453
1.60000,0.13339,78.95561,0.00281,0.28071,3.93613
1.70000,0.14182,82.88577,0.00293,0.29324,4.13206
1.80000,0.15001,85.74488,0.00305,0.30532,4.27459
1.90000,0.15832,89.56952,0.00318,0.31801,4.46526
2.00000,0.16669,93.61987,0.00331,0.33126,4.66718
2.10000,0.17494,96.29825,0.00343,0.34346,4.80070
2.20000,0.18337,100.77823,0.00356,0.35592,5.02404
2.30000,0.19163,103.75204,0.00369,0.36876,5.17229
2.40000,0.20000,107.81529,0.00382,0.38182,5.37486
2.50000,0.20831,111.17880,0.00394,0.39448,5.54253
2.60000,0.21656,115.27782,0.00407,0.40736,5.74688
2.70000,0.22493,118.93198,0.00420,0.41977,5.92905
2.80000,0.23336,121.52322,0.00433,0.43268,6.05823
2.90000,0.24167,125.46119,0.00446,0.44555,6.25455
3.00000,0.24992,128.83135,0.00458,0.45810,6.42256
3.10000,0.25835,132.26155,0.00471,0.47138,6.59356
3.20000,0.26666,135.84949,0.00485,0.48458,6.77243
3.30000,0.27497,138.91263,0.00497,0.49673,6.92513
3.40000,0.28340,142.99172,0.00510,0.50988,7.12849
3.50000,0.29165,146.33422,0.00523,0.52268,7.29512
3.60000,0.29996,150.10746,0.00536,0.53613,7.48322
3.70000,0.30839,153.49219,0.00549,0.54877,7.65196
3.80000,0.31676,156.75903,0.00562,0.56168,7.81482
3.90000,0.32502,160.47757,0.00574,0.57443,8.00020
4.00000,0.33339,163.42821,0.00588,0.58751,8.14729
4.10000,0.34164,167.51183,0.00601,0.60060,8.35087
4.20000,0.35001,170.91404,0.00613,0.61333,8.52048
4.30000,0.35832,174.38994,0.00626,0.62579,8.69376
4.40000,0.36663,178.17924,0.00639,0.63924,8.88267
4.50000,0.37494,180.76599,0.00651,0.65128,9.01163
4.60000,0.38325,185.08394,0.00665,0.66488,9.22688
4.70000,0.39162,188.34760,0.00677,0.67725,9.38959
4.80000,0.39999,191.44134,0.00690,0.69016,9.54382
4.90000,0.40836,195.05403,0.00703,0.70316,9.72392
5.00000,0.41667,197.69680,0.00716,0.71598,9.85567
5.10000,0.42498,201.36519,0.00729,0.72925,10.03855
5.20000,0.43329,205.54084,0.00742,0.74222,10.24671
5.30000,0.44161,208.06484,0.00755,0.75515,10.37254
5.40000,0.45004,211.14512,0.00768,0.76796,10.52610
5.50000,0.45835,215.04678,0.00781,0.78127,10.72061
5.60000,0.46666,218.78558,0.00795,0.79467,10.90699
5.70000,0.47503,222.03324,0.00807,0.80749,11.06890
5.80000,0.48328,225.20986,0.00820,0.82034,11.22726
5.90000,0.49165,228.81310,0.00834,0.83361,11.40689
6.00000,0.50002,232.23876,0.00847,0.84723,11.57767
6.10000,0.50833,236.77980,0.00860,0.86049,11.80405
6.20000,0.51670,238.75705,0.00874,0.87355,11.90262
6.30000,0.52501,243.17834,0.00886,0.88642,12.12303
6.40000,0.53332,246.90768,0.00900,0.89978,12.30895
6.50000,0.54163,248.77589,0.00913,0.91271,12.40208
6.60000,0.55000,253.17345,0.00926,0.92605,12.62131
6.70000,0.55831,256.07673,0.00939,0.93887,12.76605
6.80000,0.56668,259.99595,0.00952,0.95232,12.96143
6.90000,0.57500,262.94156,0.00965,0.96544,13.10828
7.00000,0.58331,266.70198,0.00978,0.97839,13.29574
7.10000,0.59174,270.22527,0.00992,0.99224,13.47139
7.20000,0.59999,273.18820,0.01005,1.00542,13.61910
7.30000,0.60830,277.15224,0.01018,1.01796,13.81671
7.40000,0.61673,280.24586,0.01031,1.03134,13.97094
7.50000,0.62492,283.39776,0.01044,1.04445,14.12807
7.60000,0.63323,287.07411,0.01058,1.05767,14.31134
7.70000,0.64172,290.79283,0.01071,1.07116,14.49673
7.80000,0.64997,293.83481,0.01085,1.08452,14.64838
7.90000,0.65828,297.07470,0.01098,1.09759,14.80990
8.00000,0.66677,300.18373,0.01110,1.11017,14.96489
8.10000,0.67496,302.92687,0.01121,1.12146,15.10164
8.20000,0.68327,306.03784,0.01134,1.13392,15.25673
8.30000,0.69176,310.20483,0.01148,1.14783,15.46447
8.40000,0.69996,312.74837,0.01161,1.16051,15.59127
8.50000,0.70833,316.47866,0.01174,1.17382,15.77723
8.60000,0.71676,319.15649,0.01188,1.18773,15.91073
8.70000,0.72495,323.01575,0.01201,1.20080,16.10312
8.80000,0.73338,325.49426,0.01214,1.21423,16.22668
8.90000,0.74163,329.31683,0.01228,1.22757,16.41725
9.00000,0.74988,333.13897,0.01241,1.24068,16.60779
9.10000,0.75843,335.80163,0.01254,1.25440,16.74053
9.20000,0.76674,339.22996,0.01267,1.26733,16.91144
9.30000,0.77499,342.54205,0.01281,1.28054,17.07656
9.40000,0.78348,346.05353,0.01294,1.29412,17.25161
9.50000,0.79161,349.37691,0.01308,1.30756,17.41729
9.60000,0.79992,352.57030,0.01321,1.32080,17.57649
9.70000,0.80841,355.33102,0.01334,1.33371,17.71412
9.80000,0.81666,358.58767,0.01347,1.34711,17.87647
9.90000,0.82492,361.47693,0.01360,1.36036,18.02051
10.00000,0.83335,364.39237,0.01374,1.37392,18.16585
10.10000,0.84160,368.66497,0.01388,1.38793,18.37885
10.20000,0.84997,370.86478,0.01400,1.40009,18.48851
10.30000,0.85840,374.07510,0.01414,1.41384,18.64856
10.40000,0.86665,377.69305,0.01427,1.42702,18.82892
10.50000,0.87496,380.05577,0.01440,1.44003,18.94671
10.60000,0.88333,384.49971,0.01454,1.45385,19.16825
10.70000,0.89164,387.20511,0.01467,1.46724,19.30312
10.80000,0.90001,390.33170,0.01481,1.48065,19.45899
10.90000,0.90832,393.12723,0.01494,1.49408,19.59835
11.00000,0.91663,395.86513,0.01507,1.50745,19.73484
11.10000,0.92506,399.10511,0.01521,1.52101,19.89636
11.20000,0.93331,402.87906,0.01535,1.53460,20.08450
11.30000,0.94168,405.77697,0.01548,1.54755,20.22897
11.40000,0.95006,408.74439,0.01561,1.56105,20.37690
11.50000,0.95825,411.95359,0.01574,1.57425,20.53689
11.60000,0.96662,415.18398,0.01588,1.58780,20.69793
11.70000,0.97499,417.51973,0.01601,1.60149,20.81438
11.80000,0.98330,421.05466,0.01615,1.61484,20.99060
11.90000,0.99161,424.95690,0.01628,1.62834,21.18514
12.00000,1.00004,427.52284,0.01642,1.64177,21.31306
12.10000,1.00835,429.97343,0.01653,1.65268,21.43522
12.20000,1.01660,432.45619,0.01665,1.66520,21.55899
12.30000,1.02509,435.34865,0.01679,1.67863,21.70319
12.40000,1.03334,439.00413,0.01692,1.69210,21.88543
12.50000,1.04165,441.53016,0.01706,1.70602,22.01135
12.60000,1.05008,444.87854,0.01720,1.71950,22.17828
12.70000,1.05833,447.98292,0.01733,1.73297,22.33304
12.80000,1.06664,450.70038,0.01746,1.74605,22.46851
12.90000,1.07496,453.49509,0.01757,1.75712,22.60784
13.00000,1.08327,455.86359,0.01771,1.77086,22.72591
13.10000,1.09164,459.26403,0.01784,1.78372,22.89543
13.20000,1.10001,462.11383,0.01797,1.79738,23.03750
13.30000,1.10832,465.26883,0.01811,1.81073,23.19478
13.40000,1.11675,467.96249,0.01824,1.82438,23.32907
13.50000,1.12500,470.94557,0.01838,1.83780,23.47778
13.60000,1.13337,474.17614,0.01852,1.85161,23.63884
13.70000,1.14174,477.45081,0.01865,1.86509,23.80209
13.80000,1.14999,480.21628,0.01879,1.87870,23.93995
13.90000,1.15818,483.16806,0.01892,1.89173,24.08710
14.00000,1.16667,486.38661,0.01906,1.90596,24.24756
14.10000,1.17492,488.44805,0.01919,1.91933,24.35032
14.20000,1.18323,492.32617,0.01933,1.93261,24.54366
14.30000,1.19172,495.57639,0.01947,1.94650,24.70569
14.40000,1.19998,498.65912,0.01960,1.95991,24.85937
14.50000,1.20829,501.27138,0.01974,1.97356,24.98960
14.60000,1.21678,503.93203,0.01987,1.98748,25.12224
14.70000,1.22497,507.25448,0.02001,2.00113,25.28787
14.80000,1.23328,509.84449,0.02014,2.01434,25.41699
14.90000,1.24171,512.94286,0.02028,2.02827,25.57145
15.00000,1.24996,515.49068,0.02042,2.04227,25.69847
15.10000,1.25833,517.91952,0.02055,2.05543,25.81955
15.20000,1.26670,521.45440,0.02069,2.06929,25.99577
15.30000,1.27489,524.38243,0.02083,2.08330,26.14174
15.40000,1.28332,526.35102,0.02097,2.09667,26.23988
15.50000,1.29169,530.03035,0.02110,2.11040,26.42330
15.60000,1.29994,532.51502,0.02121,2.12124,26.54717
15.70000,1.30837,535.13385,0.02134,2.13420,26.67773
15.80000,1.31668,537.49545,0.02148,2.14791,26.79546
15.90000,1.32494,540.25333,0.02162,2.16159,26.93295
16.00000,1.33337,543.36102,0.02176,2.17568,27.08787
16.10000,1.34162,545.55745,0.02189,2.18926,27.19737
16.20000,1.34993,548.73386,0.02203,2.20285,27.35572
16.30000,1.35848,552.11727,0.02217,2.21687,27.52439
16.40000,1.36661,554.35132,0.02231,2.23059,27.63577
16.50000,1.37492,557.38613,0.02244,2.24424,27.78706
16.60000,1.38347,560.59905,0.02258,2.25839,27.94723
16.70000,1.39166,562.83432,0.02272,2.27200,28.05866
16.80000,1.40003,565.38563,0.02286,2.28563,28.18585
16.90000,1.40840,568.41467,0.02300,2.30021,28.33686
17.00000,1.41665,571.36584,0.02314,2.31374,28.48398
17.10000,1.42496,573.62490,0.02328,2.32771,28.59660
17.20000,1.43339,576.29244,0.02341,2.34122,28.72958
17.30000,1.44158,579.32939,0.02355,2.35487,28.88098
17.40000,1.44995,582.34059,0.02369,2.36893,29.03110
17.50000,1.45833,584.14447,0.02383,2.38309,29.12103
17.60000,1.46664,587.46757,0.02397,2.39656,29.28669
17.70000,1.47501,590.17735,0.02410,2.41046,29.42178
17.80000,1.48338,592.66486,0.02425,2.42488,29.54579
17.90000,1.49163,594.93994,0.02439,2.43871,29.65921
18.00000,1.50000,597.70537,0.02452,2.45249,29.79707
18.10000,1.50825,600.61333,0.02466,2.46611,29.94204
18.20000,1.51662,603.08664,0.02480,2.48006,30.06534
18.30000,1.52499,605.75465,0.02494,2.49401,30.19835
18.40000,1.53318,608.19779,0.02508,2.50787,30.32014
18.50000,1.54155,610.76898,0.02522,2.52210,30.44832
18.60000,1.55004,613.29794,0.02537,2.53655,30.57440
18.70000,1.55829,615.50150,0.02550,2.55029,30.68425
18.80000,1.56660,618.57291,0.02564,2.56419,30.83737
18.90000,1.57509,621.25847,0.02578,2.57816,30.97125
19.00000,1.58335,623.30109,0.02589,2.58935,31.07308
19.10000,1.59166,625.00294,0.02602,2.60195,31.15792
19.20000,1.60009,627.68413,0.02616,2.61610,31.29158
19.30000,1.60834,630.43102,0.02630,2.63010,31.42852
19.40000,1.61665,633.15765,0.02644,2.64441,31.56445
19.50000,1.62502,635.17848,0.02659,2.65853,31.66520
19.60000,1.63333,638.00970,0.02672,2.67241,31.80634
19.70000,1.64170,640.87049,0.02687,2.68654,31.94896
19.80000,1.65007,643.12601,0.02701,2.70071,32.06140
19.90000,1.65838,646.08324,0.02715,2.71514,32.20882
20.00000,1.66675,648.17895,0.02729,2.72911,32.31330
20.10000,1.67500,651.10554,0.02744,2.74365,32.45920
20.20000,1.68331,653.47366,0.02757,2.75732,32.57726
20.30000,1.69162,655.14464,0.02772,2.77167,32.66056
20.40000,1.69987,658.74201,0.02786,2.78567,32.83989
20.50000,1.70825,660.39744,0.02800,2.80010,32.92242
20.60000,1.71668,662.61562,0.02813,2.81317,33.03300
20.70000,1.72493,665.30090,0.02828,2.82751,33.16687
20.80000,1.73330,667.40098,0.02842,2.84151,33.27156
20.90000,1.74173,669.91812,0.02856,2.85619,33.39705
21.00000,1.74998,672.52400,0.02870,2.87014,33.52696
21.10000,1.75829,675.04160,0.02884,2.88435,33.65247
21.20000,1.76672,677.81312,0.02899,2.89851,33.79063
21.30000,1.77491,680.03116,0.02913,2.91273,33.90121
21.40000,1.78328,682.44515,0.02927,2.92735,34.02155
21.50000,1.79171,685.27451,0.02942,2.94213,34.16261
21.60000,1.79996,686.78576,0.02956,2.95643,34.23795
21.70000,1.80833,689.74206,0.02971,2.97080,34.38532
21.80000,1.81670,691.71134,0.02986,2.98559,34.48350
21.90000,1.82501,693.95574,0.03000,2.99981,34.59538
22.00000,1.83339,696.87860,0.03014,3.01434,34.74110
22.10000,1.84176,699.05324,0.03029,3.02924,34.84951
22.20000,1.85007,701.47314,0.03043,3.04333,34.97015
22.30000,1.85838,703.55777,0.03058,3.05806,35.07407
22.40000,1.86669,705.50451,0.03073,3.09130,35.17112
22.50000,1.87494,708.17326,0.03087,3.12431,35.30416
22.54400,1.87859,708.31641,0.03090,3.13889,35.31130
22.64400,1.88702,710.55116,0.03104,3.17262,35.42271
22.74400,1.89533,712.36398,0.03119,3.20586,35.51308
22.84400,1.90358,715.26696,0.03133,3.23886,35.65780
22.94400,1.91201,717.55233,0.03148,3.27258,35.77173
23.04400,1.92026,718.68608,0.03163,3.30559,35.82825
23.14400,1.92869,721.60559,0.03178,3.33931,35.97380
23.24400,1.93706,723.38013,0.03192,3.37279,36.06226
23.34400,1.94531,726.22565,0.03207,3.40579,36.20412
23.44400,1.95368,728.55479,0.03222,3.43928,36.32023
23.54400,1.96193,730.01911,0.03237,3.47228,36.39323
23.64400,1.97024,732.09899,0.03251,3.50552,36.49692
23.74400,1.97867,734.78259,0.03266,3.53924,36.63070
23.84400,1.98698,736.87634,0.03281,3.57249,36.73508
23.94400,1.99529,738.33899,0.03296,3.60573,36.80800
24.04400,2.00373,741.14208,0.03311,3.63945,36.94774
24.14400,2.01204,742.70945,0.03326,3.67269,37.02588
24.24400,2.02035,745.28721,0.03341,3.70594,37.15438
24.34400,2.02878,746.74352,0.03356,3.73966,37.22699
24.44400,2.03703,749.05152,0.03371,3.77266,37.34204
24.54400,2.04528,750.68763,0.03386,3.80567,37.42361
24.64400,2.05365,752.86468,0.03396,3.83915,37.53214
24.74400,2.06202,754.97827,0.03453,3.87263,37.63751
24.84400,2.07033,757.61667,0.03349,3.90587,37.76904
24.94400,2.07870,759.80192,0.03303,3.93936,37.87798
25.04400,2.08701,762.44660,0.02593,3.97260,38.00982
25.14400,2.09532,765.90511,0.01974,4.00584,38.18224
25.24400,2.10369,766.25417,0.00939,4.03932,38.19964
25.34400,2.11194,766.07885,0.01090,4.07233,38.19090
25.44400,2.12025,768.27551,0.01094,4.10557,38.30041
25.54400,2.12863,770.79018,0.01083,4.13905,38.42577
25.64400,2.13694,772.50213,0.01069,4.17230,38.51111
25.74400,2.14525,774.00100,0.01054,4.20554,38.58583
25.84400,2.15356,775.74705,0.01048,4.23878,38.67288
25.94400,2.16193,777.26822,0.00965,4.27226,38.74871
26.04400,2.17030,779.64654,0.00941,4.30575,38.86728
26.14400,2.17861,781.32097,0.00821,4.33899,38.95075
26.24400,2.18698,783.39884,0.00892,4.37247,39.05434
26.34400,2.19541,784.25752,0.00853,4.40619,39.09715
26.44400,2.20372,786.22364,0.00824,4.43944,39.19516
26.54400,2.21203,788.64181,0.00877,4.47268,39.31572
26.64400,2.22034,789.74376,0.00838,4.50592,39.37065
26.74400,2.22865,791.44519,0.00744,4.53916,39.45547
26.84400,2.23702,793.56031,0.00729,4.57265,39.56092
26.94400,2.24533,795.24852,0.00730,4.60589,39.64508
27.04400,2.25365,796.29784,0.00687,4.63913,39.69739
27.14400,2.26202,798.33986,0.00335,4.67261,39.79919
27.24400,2.27033,800.15622,-0.00979,4.70586,39.88974
27.34400,2.27876,801.42831,-0.01564,4.73958,39.95316
27.44400,2.28707,802.94879,-0.08401,4.77282,40.02895
27.54400,2.29538,805.00748,-0.13708,4.80606,40.13158
27.64400,2.30375,807.30505,-0.13708,4.83955,40.24612
27.74400,2.31200,808.56811,-0.13707,4.87255,40.30909
27.84400,2.32031,809.83536,-0.13707,4.90579,40.37226
27.94400,2.32862,812.16069,-0.13707,4.93904,40.48819
28.04400,2.33699,813.29327,-0.13708,4.97252,40.54465
28.14400,2.34530,814.94106,-0.13708,5.00576,40.62680
28.24400,2.35367,817.08618,-0.13708,5.03924,40.73374
28.34400,2.36204,818.04004,-0.13708,5.07273,40.78129
28.44400,2.37029,820.01882,-0.13708,5.10573,40.87994
28.54400,2.37861,821.11610,-0.13708,5.13897,40.93464
28.64400,2.38704,823.21092,-0.13708,5.17269,41.03907
28.74400,2.39523,824.62644,-0.13708,5.20546,41.10964
28.84400,2.40366,826.34659,-0.13708,5.23918,41.19539
28.94400,2.41203,827.37915,-0.13708,5.27266,41.24687
29.04400,2.42028,829.14652,-0.13709,5.30566,41.33498
29.14400,2.42865,830.77494,-0.13709,5.33915,41.41616
29.24400,2.43702,831.75888,-0.13708,5.37263,41.46521
29.34400,2.44533,832.84853,-0.13709,5.40587,41.51953
29.44400,2.45370,834.44668,-0.13709,5.43935,41.59920
29.54400,2.46207,835.84804,-0.13709,5.47284,41.66906
29.64400,2.47038,837.25275,-0.13709,5.50608,41.73909
29.74400,2.47869,838.43246,-0.13709,5.53932,41.79790
29.84400,2.48700,840.27583,-0.13709,5.57256,41.88980
29.94400,2.49531,841.33903,-0.13709,5.60581,41.94280
30.04400,2.50368,842.52125,-0.13709,5.63929,42.00174
30.14400,2.51200,843.52335,-0.13709,5.67253,42.05169
30.24400,2.52031,845.24229,-0.13709,5.70578,42.13739
30.34400,2.52874,846.59345,-0.13709,5.73950,42.20475
30.44400,2.53699,847.86285,-0.13709,5.77250,42.26803
30.54400,2.54530,849.15487,-0.13709,5.80574,42.33244
30.64400,2.55373,850.59321,-0.13709,5.83947,42.40414
30.74400,2.56198,851.53738,-0.13709,5.87247,42.45121
30.84400,2.57035,852.97311,-0.13709,5.90595,42.52279
30.94400,2.57872,853.93274,-0.13709,5.93943,42.57063
31.04400,2.58691,854.77447,-0.13709,5.97220,42.61259
31.14400,2.59528,855.63269,-0.13710,6.00568,42.65537
31.24400,2.60365,856.87246,-0.13709,6.03916,42.71718
31.34400,2.61202,858.48086,-0.13709,6.07265,42.79736
31.44400,2.62027,859.13651,-0.13709,6.10565,42.83005
31.54400,2.62864,860.40832,-0.13709,6.13913,42.89345
31.64400,2.63696,861.25527,-0.13709,6.17237,42.93567
31.74400,2.64527,862.39232,-0.13710,6.20562,42.99236
31.84400,2.65370,864.03005,-0.13709,6.23934,43.07401
31.94400,2.66201,865.13218,-0.13710,6.27258,43.12895
32.04400,2.67032,865.67532,-0.13710,6.30582,43.15602
32.14400,2.67863,866.93903,-0.13709,6.33907,43.21902
32.24400,2.68694,867.75785,-0.13710,6.37231,43.25984
32.34400,2.69531,868.91623,-0.13709,6.40579,43.31759
32.44400,2.70362,869.95540,-0.13710,6.43903,43.36940
32.54400,2.71199,871.31131,-0.13710,6.47252,43.43699
32.64400,2.72036,872.39807,-0.13709,6.50600,43.49117
32.74400,2.72867,872.56730,-0.13709,6.53924,43.49961
32.84400,2.73704,873.57778,-0.13710,6.57272,43.54998
32.94400,2.74535,875.02282,-0.13710,6.60597,43.62202
33.04400,2.75366,875.87368,-0.13710,6.63921,43.66444
33.14400,2.76198,876.38414,-0.13710,6.67245,43.68988
33.24400,2.77029,877.74917,-0.13710,6.70570,43.75793
33.34400,2.77866,877.71015,-0.13710,6.73918,43.75599
33.44400,2.78697,878.93801,-0.13710,6.77242,43.81720
33.54400,2.79534,879.44334,-0.13710,6.80590,43.84239
33.64400,2.80371,881.28205,-0.13710,6.83938,43.93406
33.74400,2.81202,881.49840,-0.13710,6.87263,43.94484
33.84400,2.82039,881.96862,-0.13710,6.90611,43.96828
33.94400,2.82870,882.88235,-0.13710,6.93935,44.01384
34.04400,2.83701,883.89814,-0.13710,6.97260,44.06448
34.14400,2.84532,884.45898,-0.13710,7.00584,44.09243
34.24400,2.85363,885.24092,-0.13710,7.03908,44.13142
34.34400,2.86194,886.00433,-0.13710,7.07233,44.16948
34.44400,2.87031,886.68745,-0.13710,7.10581,44.20353
34.54400,2.87862,887.77188,-0.13710,7.13905,44.25759
34.64400,2.88700,888.37231,-0.13710,7.17253,44.28753
34.74400,2.89543,888.85929,-0.13710,7.20625,44.31180
34.84400,2.90374,889.19830,-0.13710,7.23950,44.32870
34.94400,2.91205,889.31639,-0.13710,7.27274,44.33459
35.04400,2.92036,890.75547,-0.13710,7.30598,44.40633
35.14400,2.92867,891.31380,-0.13710,7.33923,44.43417
35.24400,2.93704,891.49391,-0.13710,7.37271,44.44315
35.34400,2.94535,892.11361,-0.13710,7.40595,44.47404
35.44400,2.95366,893.03963,-0.13710,7.43919,44.52020
35.54400,2.96203,893.23483,-0.13710,7.47267,44.52993
35.64400,2.97022,893.86785,-0.13710,7.50544,44.56149
35.74400,2.97859,894.23666,-0.13710,7.53892,44.57988
35.84400,2.98708,894.80113,-0.13710,7.57288,44.60802
35.94400,2.99533,895.06712,-0.13710,7.60589,44.62128
36.04400,3.00370,895.52198,-0.13710,7.63937,44.64395
36.14400,3.01213,895.60319,-0.13710,7.67309,44.64800
36.24400,3.02033,896.48729,-0.13710,7.70585,44.69208
36.34400,3.02864,896.54848,-0.13710,7.73910,44.69513
36.44400,3.03707,897.39934,-0.13710,7.77282,44.73755
36.54400,3.04526,897.32874,-0.13710,7.80558,44.73402
36.64400,3.05363,897.92088,-0.13710,7.83907,44.76354
36.74400,3.06200,897.85112,-0.13710,7.87255,44.76007
36.84400,3.07025,898.29378,-0.13710,7.90555,44.78214
36.94400,3.07868,898.29760,-0.13710,7.93927,44.78233
37.04400,3.08705,899.16773,-0.13710,7.97275,44.82570
37.14400,3.09536,899.31553,-0.13710,8.00600,44.83307
37.24400,3.10379,899.87861,-0.13710,8.03972,44.86114
37.34400,3.11204,899.85337,-0.13710,8.07272,44.85988
37.44400,3.12023,899.50236,-0.13710,8.10549,44.84238
37.54400,3.12872,900.33887,-0.13710,8.13945,44.88409
37.64400,3.13697,900.61184,-0.13710,8.17245,44.89769
37.74400,3.14535,900.49375,-0.13710,8.20593,44.89181
37.84400,3.15378,900.86916,-0.13711,8.23966,44.91052
37.94400,3.16197,900.98884,-0.13710,8.27242,44.91649
38.04400,3.17034,901.01408,-0.13710,8.30590,44.91775
38.14400,3.17877,901.11662,-0.13710,8.33962,44.92286
38.24400,3.18696,900.95736,-0.13710,8.37239,44.91492
38.34400,3.19533,901.13552,-0.13710,8.40587,44.92380
38.44400,3.20370,901.14353,-0.13710,8.43935,44.92420
38.54400,3.21189,901.16942,-0.13710,8.47212,44.92549
38.64400,3.22032,900.97822,-0.13710,8.50584,44.91596
38.74400,3.22869,901.22772,-0.13710,8.53932,44.92840
38.84400,3.23688,900.94013,-0.13710,8.57209,44.91406
38.94400,3.24531,901.88533,-0.13710,8.60581,44.96118
39.04400,3.25362,901.25119,-0.13710,8.63905,44.92957
39.14400,3.26194,901.20044,-0.13710,8.67229,44.92704
39.24400,3.27037,901.47890,-0.13710,8.70601,44.94092
39.34400,3.27862,901.14865,-0.13711,8.73902,44.92446
39.44400,3.28693,901.34926,-0.13711,8.77226,44.93446
39.54400,3.29536,901.24076,-0.13710,8.80598,44.92905
39.64400,3.30361,901.01538,-0.13710,8.83898,44.91781
39.74400,3.31198,900.56453,-0.13710,8.87247,44.89534
39.84400,3.32041,900.53184,-0.13710,8.90619,44.89371
39.94400,3.32860,900.37417,-0.13710,8.93895,44.88585
40.04400,3.33697,900.60253,-0.13710,8.97243,44.89723
40.14400,3.34534,900.56248,-0.13711,9.00592,44.89523
40.24400,3.35365,900.01803,-0.13710,9.03916,44.86809
40.34400,3.36202,899.65798,-0.13710,9.07264,44.85014
40.44400,3.37039,899.71805,-0.13710,9.10612,44.85314
40.54400,3.37870,899.40075,-0.13710,9.13937,44.83732
40.64400,3.38702,899.18403,-0.13710,9.17261,44.82652
40.74400,3.39539,898.88936,-0.13710,9.20609,44.81182
40.84400,3.40364,899.08997,-0.13710,9.23910,44.82183
40.94400,3.41201,898.54775,-0.13711,9.27258,44.79480
41.04400,3.42032,898.16358,-0.13711,9.30582,44.77564
41.14400,3.42863,897.82635,-0.13711,9.33906,44.75883
41.24400,3.43706,898.07902,-0.13710,9.37279,44.77143
41.34400,3.44531,898.03459,-0.13711,9.40579,44.76921
41.44400,3.45362,897.31654,-0.13710,9.43903,44.73342
41.54400,3.46199,896.97707,-0.13711,9.47251,44.71649
41.64400,3.47030,896.84324,-0.13710,9.50576,44.70982
41.74400,3.47855,896.46000,-0.13711,9.53876,44.69072
41.84400,3.48698,895.78358,-0.13711,9.57248,44.65699
41.94400,3.49529,895.69949,-0.13711,9.60573,44.65280
42.04400,3.50360,895.31280,-0.13711,9.63897,44.63353
42.14400,3.51203,894.96756,-0.13711,9.67269,44.61631
42.24400,3.52035,895.05697,-0.13710,9.70593,44.62077
42.34400,3.52866,893.71577,-0.13711,9.73918,44.55391
42.44400,3.53709,894.19959,-0.13710,9.77290,44.57803
42.54400,3.54534,893.84448,-0.13711,9.80590,44.56033
42.64400,3.55371,892.83269,-0.13711,9.83938,44.50988
42.74400,3.56208,892.66011,-0.13711,9.87286,44.50128
42.84400,3.57027,892.53280,-0.13710,9.90563,44.49493
42.94400,3.57864,891.63678,-0.13711,9.93911,44.45027
43.04400,3.58701,891.94998,-0.13710,9.97259,44.46588
43.14400,3.59526,890.65852,-0.13711,10.00560,44.40150
43.24400,3.60369,890.67696,-0.13710,10.03932,44.40242
43.34400,3.61206,889.55956,-0.13711,10.07280,44.34671
43.44400,3.62031,889.97325,-0.13711,10.10581,44.36734
43.54400,3.62880,889.16281,-0.13710,10.13976,44.32693
43.64400,3.63705,888.21165,-0.13711,10.17277,44.27951
43.74400,3.64525,888.06963,-0.13710,10.20553,44.27243
43.84400,3.65374,887.72299,-0.13711,10.23949,44.25515
43.94400,3.66193,887.31237,-0.13711,10.27226,44.23468
44.04400,3.67024,886.80871,-0.13711,10.30550,44.20958
44.14400,3.67873,885.86733,-0.13711,10.33946,44.16264
44.24400,3.68698,885.65657,-0.13711,10.37247,44.15214
44.34400,3.69523,884.51020,-0.13711,10.40547,44.09499
44.44400,3.70378,884.25977,-0.13711,10.43967,44.08250
44.54400,3.71197,883.53837,-0.13710,10.47243,44.04654
44.64400,3.72028,883.46796,-0.13711,10.50568,44.04303
44.74400,3.72883,882.59568,-0.13711,10.53988,43.99955
44.84400,3.73690,882.21515,-0.13711,10.57216,43.98058
44.94400,3.74527,881.85314,-0.13711,10.60565,43.96253
45.04400,3.75370,881.92709,-0.13710,10.63937,43.96621
45.14400,3.76196,881.22329,-0.13711,10.67237,43.93113
45.24400,3.77044,880.88140,-0.13711,10.70633,43.91409
45.34400,3.77870,880.37560,-0.13711,10.73933,43.88887
45.44400,3.78695,879.81950,-0.13711,10.77234,43.86115
45.54400,3.79538,878.71635,-0.13711,10.80606,43.80615
45.64400,3.80369,878.15551,-0.13711,10.83930,43.77819
45.74400,3.81194,877.69926,-0.13711,10.87231,43.75545
45.84400,3.82037,876.93138,-0.13711,10.90603,43.71717
45.94400,3.82868,876.63066,-0.13711,10.93927,43.70218
46.04400,3.83699,876.12215,-0.13711,10.97251,43.67682
46.14400,3.84542,875.38678,-0.13711,11.00623,43.64016
46.24400,3.85367,874.80573,-0.13711,11.03924,43.61120
46.34400,3.86192,873.76526,-0.13711,11.07224,43.55933
46.44400,3.87041,874.04242,-0.13711,11.10620,43.57314
46.54400,3.87866,872.50313,-0.13711,11.13921,43.49641
46.64400,3.88697,872.45367,-0.13711,11.17245,43.49394
46.74400,3.89546,871.26838,-0.13711,11.20641,43.43485
46.84400,3.90366,871.27779,-0.13711,11.23917,43.43532
46.94400,3.91197,870.74814,-0.13711,11.27242,43.40892
47.04400,3.92034,869.90045,-0.13711,11.30590,43.36666
47.14400,3.92859,868.61914,-0.13711,11.33890,43.30278
47.24400,3.93696,869.02902,-0.13711,11.37239,43.32322
47.34400,3.94533,868.10663,-0.13711,11.40587,43.27723
47.44400,3.95364,867.56218,-0.13711,11.43911,43.25009
47.54400,3.96201,866.75743,-0.13711,11.47259,43.20997
47.64400,3.97038,865.75570,-0.13711,11.50607,43.16003
47.74400,3.97869,865.65707,-0.13711,11.53932,43.15511
47.84400,3.98706,865.29739,-0.13711,11.57280,43.13718
47.94400,3.99531,864.54516,-0.13711,11.60580,43.09968
48.04400,4.00362,863.49715,-0.13711,11.63905,43.04744
48.14400,4.01199,862.96294,-0.13711,11.67253,43.02081
48.24400,4.02031,862.54254,-0.13711,11.70577,42.99985
48.34400,4.02862,861.68973,-0.13711,11.73901,42.95733
48.44400,4.03699,861.79869,-0.13711,11.77250,42.96276
48.54400,4.04530,861.19520,-0.13711,11.80574,42.93268
48.64400,4.05367,860.32012,-0.13711,11.83922,42.88905
48.74400,4.06204,859.50317,-0.13711,11.87270,42.84833
48.84400,4.07029,858.85813,-0.13711,11.90571,42.81617
48.94400,4.07860,857.99247,-0.13711,11.93895,42.77301
49.04400,4.08709,857.43098,-0.13711,11.97291,42.74502
49.14400,4.09534,857.29137,-0.13711,12.00592,42.73806
49.24400,4.10365,856.32764,-0.13711,12.03916,42.69002
49.34400,4.11202,855.79380,-0.13711,12.07264,42.66341
49.44400,4.12027,855.26770,-0.13710,12.10564,42.63718
49.54400,4.12864,854.90597,-0.13711,12.13913,42.61914
49.64400,4.13701,853.80515,-0.13711,12.17261,42.56427
49.74400,4.14532,853.03318,-0.13711,12.20585,42.52578
49.84400,4.15370,852.30479,-0.13711,12.23933,42.48947
49.94400,4.16201,852.07094,-0.13711,12.27258,42.47781
50.04400,4.17032,851.19912,-0.13711,12.30582,42.43435
50.14400,4.17869,850.42752,-0.13711,12.33930,42.39589
50.24400,4.18700,849.69103,-0.13711,12.37254,42.35917
50.34400,4.19525,848.94747,-0.13711,12.40555,42.32210
50.44400,4.20368,848.34592,-0.13711,12.43927,42.29211
50.54400,4.21193,847.96166,-0.13711,12.47227,42.27296
50.64400,4.22024,847.52310,-0.13711,12.50552,42.25109
50.74400,4.22873,846.42721,-0.13711,12.53948,42.19646
50.84400,4.23704,845.69994,-0.13711,12.57272,42.16020
50.94400,4.24541,845.55540,-0.13711,12.60620,42.15300
51.04400,4.25384,844.46548,-0.13711,12.63992,42.09866
51.14400,4.26203,844.08121,-0.13711,12.67269,42.07951
51.24400,4.27028,842.82011,-0.13711,12.70569,42.01664
51.34400,4.27866,842.81880,-0.13711,12.73917,42.01657
51.44400,4.28697,841.97856,-0.13711,12.77242,41.97468
51.54400,4.29528,841.07649,-0.13711,12.80566,41.92971
51.64400,4.30377,839.96756,-0.13711,12.83962,41.87443
51.74400,4.31196,839.78120,-0.13711,12.87238,41.86514
51.84400,4.32033,839.34693,-0.13711,12.90587,41.84349
51.94400,4.32870,838.24703,-0.13711,12.93935,41.78866
52.04400,4.33695,837.99027,-0.13711,12.97235,41.77586
52.14400,4.34538,837.18998,-0.13711,13.00607,41.73596
52.24400,4.35369,836.06280,-0.13711,13.03932,41.67977
52.34400,4.36194,835.46359,-0.13711,13.07232,41.64989
52.44400,4.37037,834.90210,-0.13711,13.10604,41.62190
52.54400,4.37862,834.17082,-0.13711,13.13904,41.58545
52.64400,4.38699,833.74735,-0.13711,13.17253,41.56434
52.74400,4.39536,832.19651,-0.13711,13.20601,41.48702
52.84400,4.40362,832.29169,-0.13711,13.23901,41.49177
52.94400,4.41193,830.77336,-0.13711,13.27226,41.41608
53.04400,4.42036,830.17107,-0.13711,13.30598,41.38605
53.14400,4.42873,830.40083,-0.13711,13.33946,41.39750
53.24400,4.43704,828.71886,-0.13711,13.37270,41.31366
53.34400,4.44541,828.01124,-0.13711,13.40618,41.27838
53.44400,4.45366,827.56560,-0.13711,13.43919,41.25616
53.54400,4.46197,826.44112,-0.13711,13.47243,41.20010
53.64400,4.47034,826.46655,-0.13711,13.50591,41.20137
53.74400,4.47859,825.00586,-0.13711,13.53892,41.12855
53.84400,4.48702,824.68232,-0.13711,13.57264,41.11242
53.94400,4.49539,823.29782,-0.13711,13.60612,41.04340
54.04400,4.50364,823.00045,-0.13711,13.63912,41.02858
54.14400,4.51207,821.69715,-0.13711,13.67285,40.96360
54.24400,4.52032,820.25090,-0.13711,13.70585,40.89151
54.34400,4.52864,820.55060,-0.13711,13.73909,40.90645
54.44400,4.53701,819.44438,-0.13711,13.77258,40.85130
54.54400,4.54520,818.25312,-0.13711,13.80534,40.79191
54.64400,4.55363,817.14671,-0.13711,13.83906,40.73676
54.74400,4.56200,816.64883,-0.13711,13.87254,40.71193
54.84400,4.57031,815.08122,-0.13711,13.90579,40.63379
54.94400,4.57862,814.46199,-0.13711,13.93903,40.60291
55.04400,4.58699,813.39031,-0.13711,13.97251,40.54949
55.14400,4.59530,812.77015,-0.13711,14.00575,40.51857
55.24400,4.60367,811.78909,-0.13711,14.03924,40.46967
55.34400,4.61204,811.04767,-0.13711,14.07272,40.43270
55.44400,4.62035,810.11895,-0.13711,14.10596,40.38640
55.54400,4.62866,809.30889,-0.13711,14.13921,40.34602
55.64400,4.63703,807.82389,-0.13711,14.17269,40.27199
55.74400,4.64534,806.56009,-0.13711,14.20593,40.20898
55.84400,4.65366,805.70923,-0.13711,14.23917,40.16657
55.94400,4.66203,805.33475,-0.13711,14.27265,40.14790
56.04400,4.67034,803.97176,-0.13711,14.30590,40.07995
56.14400,4.67871,802.93110,-0.13711,14.33938,40.02807
56.24400,4.68702,801.71032,-0.13711,14.37262,39.96721
56.34400,4.69539,800.49327,-0.13711,14.40610,39.90654
56.44400,4.70382,799.61829,-0.13711,14.43983,39.86292
56.54400,4.71207,798.42787,-0.13711,14.47283,39.80357
56.64400,4.72038,797.41739,-0.13711,14.50607,39.75320
56.74400,4.72869,795.94962,-0.13711,14.53931,39.68003
56.84400,4.73694,794.84489,-0.13711,14.57232,39.62495
56.94400,4.74531,793.64022,-0.13711,14.60580,39.56490
57.04400,4.75368,792.35714,-0.13711,14.63928,39.50093
57.14400,4.76193,791.30232,-0.13711,14.67229,39.44835
57.24400,4.77030,790.57813,-0.13711,14.70577,39.41225
57.34400,4.77873,789.71433,-0.13711,14.73949,39.36918
57.44400,4.78699,787.18280,-0.13711,14.77250,39.24298
57.54400,4.79536,785.92300,-0.13711,14.80598,39.18018
57.64400,4.80373,784.71098,-0.13711,14.83946,39.11975
57.74400,4.81192,783.78702,-0.13711,14.87222,39.07369
57.84400,4.82029,782.41546,-0.13711,14.90571,39.00532
57.94400,4.82872,781.20255,-0.13711,14.93943,38.94485
58.04400,4.83697,779.49255,-0.13711,14.97243,38.85960
58.14400,4.84540,778.45138,-0.13711,15.00615,38.80770
58.24400,4.85371,777.14669,-0.13711,15.03939,38.74266
58.34400,4.86202,775.35654,-0.13711,15.07264,38.65341
58.44400,4.87039,774.29060,-0.13711,15.10612,38.60027
58.54400,4.87870,772.71415,-0.13711,15.13936,38.52168
58.64400,4.88701,770.88783,-0.13711,15.17260,38.43064
58.74400,4.89538,770.25485,-0.13711,15.20609,38.39908
58.84400,4.90364,768.30420,-0.13711,15.23909,38.30184
58.94400,4.91201,767.00281,-0.13711,15.27257,38.23696
59.04400,4.92038,765.69077,-0.13711,15.30605,38.17155
59.14400,4.92863,763.98347,-0.13711,15.33906,38.08644
59.24400,4.93694,762.32008,-0.13711,15.37230,38.00351
59.34400,4.94537,761.18079,-0.13711,15.40602,37.94672
59.44400,4.95368,759.71950,-0.13711,15.43926,37.87387
59.54400,4.96199,758.17583,-0.13711,15.47251,37.79691
59.64400,4.97042,755.97828,-0.13711,15.50623,37.68736
59.74400,4.97861,754.38432,-0.13711,15.53900,37.60790
59.84400,4.98698,752.97151,-0.13711,15.57248,37.53746
59.94400,4.99529,751.49438,-0.13711,15.60572,37.46383
60.04400,5.00360,749.42377,-0.13711,15.63896,37.36060
60.14400,5.01197,748.27326,-0.13711,15.67245,37.30325
60.24400,5.02034,746.18356,-0.13711,15.70593,37.19907
60.34400,5.02865,744.56395,-0.13711,15.73917,37.11833
60.44400,5.03697,743.30182,-0.13711,15.77241,37.05541
60.54400,5.04534,741.81706,-0.13711,15.80589,36.98139
60.64400,5.05377,740.24280,-0.13711,15.83962,36.90291
60.74400,5.06208,738.57387,-0.13711,15.87286,36.81971
60.84400,5.07033,736.58931,-0.13711,15.90586,36.72077
60.94400,5.07864,735.23703,-0.13711,15.93911,36.65336
61.04400,5.08701,734.21593,-0.13711,15.97259,36.60245
61.14400,5.09526,732.00874,-0.13711,16.00559,36.49242
61.24400,5.10363,730.66182,-0.13711,16.03907,36.42527
61.34400,5.11200,728.87694,-0.13711,16.07256,36.33629
61.44400,5.12025,727.51516,-0.13711,16.10556,36.26840
61.54400,5.12868,725.93447,-0.13711,16.13928,36.18960
61.64400,5.13705,724.58973,-0.13711,16.17276,36.12256
61.74400,5.14536,722.99419,-0.13711,16.20601,36.04302
61.84400,5.15361,722.10962,-0.13711,16.23901,35.99892
61.94400,5.16199,720.19347,-0.13711,16.27249,35.90340
62.04400,5.17030,719.27407,-0.13711,16.30574,35.85757
62.14400,5.17861,717.40448,-0.13711,16.33898,35.76436
62.24400,5.18698,715.79954,-0.13711,16.37246,35.68435
62.34400,5.19535,714.44912,-0.13711,16.40594,35.61703
62.44400,5.20366,712.97837,-0.13711,16.43918,35.54371
62.54400,5.21197,712.04095,-0.13711,16.47243,35.49697
62.64400,5.22034,710.44248,-0.13711,16.50591,35.41729
62.74400,5.22865,708.92335,-0.13711,16.53915,35.34156
62.84400,5.23702,708.05773,-0.13711,16.57264,35.29840
62.94400,5.24533,706.76147,-0.13711,16.60588,35.23378
63.04400,5.25364,705.33385,-0.13711,16.63912,35.16261
63.14400,5.26195,703.96103,-0.13711,16.67236,35.09417
63.24400,5.27026,702.81369,-0.13711,16.70561,35.03698
63.34400,5.27863,701.73084,-0.13711,16.73909,34.98299
63.44400,5.28701,700.41064,-0.13711,16.77257,34.91718
63.54400,5.29538,699.24728,-0.13711,16.80605,34.85918
63.64400,5.30369,697.94389,-0.13711,16.83930,34.79420
63.74400,5.31200,696.93779,-0.13711,16.87254,34.74405
63.84400,5.32037,696.25005,-0.13711,16.90602,34.70976
63.94400,5.32874,695.05638,-0.13711,16.93950,34.65025
64.04401,5.33705,693.80542,-0.13711,16.97275,34.58789
64.14400,5.34530,692.78926,-0.13711,17.00575,34.53723
64.24400,5.35367,691.61896,-0.13711,17.03923,34.47889
64.34400,5.36192,691.09579,-0.13711,17.07224,34.45281
64.44400,5.37029,689.77722,-0.13711,17.10572,34.38707
64.54401,5.37872,689.29549,-0.13711,17.13944,34.36306
64.64400,5.38697,687.69911,-0.13711,17.17244,34.28348
64.74400,5.39528,687.50037,-0.13711,17.20569,34.27357
64.84400,5.40371,686.59703,-0.13712,17.23941,34.22853
64.94400,5.41196,685.73244,-0.13711,17.27241,34.18543
65.04401,5.42034,684.54323,-0.13711,17.30589,34.12615
65.14400,5.42871,683.99357,-0.13711,17.33938,34.09875
65.24400,5.43696,683.18443,-0.13711,17.37238,34.05841
65.34400,5.44533,682.43644,-0.13711,17.40586,34.02112
65.44400,5.45364,681.56430,-0.13711,17.43911,33.97764
65.54401,5.46201,680.31279,-0.13711,17.47259,33.91525
65.64401,5.47032,679.32233,-0.13711,17.50583,33.86588
65.74400,5.47863,679.42189,-0.13711,17.53907,33.87084
65.84400,5.48700,678.88875,-0.13711,17.57255,33.84426
65.94400,5.49543,677.93992,-0.13711,17.60628,33.79696
66.04401,5.50374,677.88237,-0.13711,17.63952,33.79409
66.14401,5.51199,676.83822,-0.13711,17.67252,33.74203
66.24400,5.52036,675.49138,-0.13712,17.70601,33.67489
66.34400,5.52861,675.24468,-0.13711,17.73901,33.66259
66.44400,5.53693,674.54996,-0.13711,17.77225,33.62796
66.54401,5.54536,674.02641,-0.13711,17.80597,33.60186
66.64401,5.55361,673.51838,-0.13711,17.83898,33.57653
66.74400,5.56198,672.92713,-0.13711,17.87246,33.54706
66.84400,5.57041,672.09885,-0.13711,17.90618,33.50576
66.94400,5.57866,671.71422,-0.13711,17.93918,33.48659
67.04401,5.58709,671.12581,-0.13711,17.97290,33.45726
67.14401,5.59546,670.97526,-0.13711,18.00639,33.44975
67.24400,5.60365,670.40212,-0.13711,18.03915,33.42118
67.34400,5.61202,669.42731,-0.13711,18.07263,33.37258
67.44400,5.62033,668.71983,-0.13711,18.10588,33.33731
67.54401,5.62864,668.23568,-0.13711,18.13912,33.31318
67.64401,5.63695,668.06222,-0.13711,18.17236,33.30453
67.74400,5.64532,667.78427,-0.13711,18.20585,33.29067
67.84400,5.65363,667.57994,-0.13711,18.23909,33.28049
67.94400,5.66200,666.79991,-0.13711,18.27257,33.24160
68.04401,5.67038,666.63641,-0.13711,18.30605,33.23345
68.14401,5.67863,666.07031,-0.13711,18.33906,33.20523
68.24400,5.68700,665.27063,-0.13711,18.37254,33.16536
68.34400,5.69525,664.73172,-0.13711,18.40554,33.13850
68.44400,5.70356,664.10946,-0.13711,18.43878,33.10748
68.54401,5.71199,664.03011,-0.13711,18.47251,33.10352
68.64401,5.72030,663.79793,-0.13711,18.50575,33.09195
68.74400,5.72861,663.37911,-0.13712,18.53899,33.07106
68.84400,5.73704,663.17311,-0.13711,18.57271,33.06079
68.94400,5.74529,662.94768,-0.13711,18.60572,33.04956
69.04401,5.75366,661.81826,-0.13711,18.63920,32.99325
69.14401,5.76203,660.86072,-0.13712,18.67268,32.94552
69.24400,5.77040,660.83972,-0.13711,18.70616,32.94447
69.34400,5.77871,660.59595,-0.13711,18.73941,32.93232
69.44400,5.78708,660.19264,-0.13711,18.77289,32.91221
69.54401,5.79534,659.67496,-0.13711,18.80589,32.88641
69.64401,5.80365,658.52837,-0.13711,18.83914,32.82924
69.74400,5.81196,658.98150,-0.13711,18.87238,32.85183
69.84400,5.82027,657.88073,-0.13711,18.90562,32.79696
69.94400,5.82864,657.21655,-0.13711,18.93911,32.76385
70.04401,5.83701,656.18390,-0.13711,18.97259,32.71237
70.14401,5.84532,655.86925,-0.13711,19.00583,32.69668
70.24400,5.85369,655.42939,-0.13711,19.03931,32.67475
70.34400,5.86206,654.84731,-0.13711,19.07279,32.64573
70.44400,5.87031,653.42402,-0.13711,19.10580,32.57478
70.54401,5.87874,653.04041,-0.13711,19.13952,32.55566
70.64401,5.88693,652.36981,-0.13711,19.17228,32.52222
70.74400,5.89524,651.79812,-0.13711,19.20553,32.49372
70.84400,5.90367,651.55406,-0.13712,19.23925,32.48156
70.94400,5.91193,649.49812,-0.13711,19.27225,32.37906
71.04401,5.92030,649.58422,-0.13711,19.30573,32.38336
71.14401,5.92873,648.59786,-0.13711,19.33945,32.33418
71.24400,5.93698,647.52181,-0.13711,19.37246,32.28054
71.34400,5.94535,646.28688,-0.13711,19.40594,32.21898
71.44400,5.95372,644.90871,-0.13711,19.43942,32.15027
71.54401,5.96197,644.08812,-0.13711,19.47242,32.10936
71.64401,5.97028,642.14929,-0.13712,19.50567,32.01271
71.74400,5.97865,640.52325,-0.13711,19.53915,31.93164
71.84400,5.98696,639.20808,-0.13711,19.57239,31.86608
71.94400,5.99539,637.52006,-0.13711,19.60612,31.78193
72.04401,6.00370,635.76982,-0.13711,19.63936,31.69468
72.14401,6.01195,634.10448,-0.13711,19.67236,31.61165
72.24400,6.02038,631.94786,-0.13711,19.70609,31.50414
72.34400,6.02869,629.21820,-0.13711,19.73933,31.36806
72.44400,6.03700,627.56878,-0.13711,19.77257,31.28583
72.54401,6.04543,624.87549,-0.13711,19.80629,31.15157
72.64401,6.05363,622.59934,-0.13711,19.83906,31.03809
72.74400,6.06194,620.30037,-0.13711,19.87230,30.92348
72.84400,6.07043,617.96196,-0.13711,19.90626,30.80691
72.94400,6.07862,614.56272,-0.13711,19.93902,30.63745
73.04401,6.08693,611.69122,-0.13711,19.97227,30.49430
73.14401,6.09542,608.47723,-0.13711,20.00623,30.33407
73.24400,6.10361,605.87563,-0.13711,20.03899,30.20438
73.34400,6.11192,601.77408,-0.13711,20.07223,29.99990
73.44400,6.12041,598.52763,-0.13711,20.10619,29.83806
73.54401,6.12860,593.98403,-0.13711,20.13896,29.61155
73.64401,6.13697,589.16206,-0.13711,20.17244,29.37116
73.74400,6.14540,581.44857,-0.13712,20.20616,28.98663
73.84400,6.15365,567.11272,-0.13711,20.23917,28.27195
73.94400,6.16202,547.31024,-0.13711,20.27265,27.28475
74.04401,6.17040,523.50881,-0.13711,20.30613,26.09819
74.14401,6.17859,489.74757,-0.13711,20.33889,24.41511
74.24400,6.18708,443.23346,-0.13711,20.37286,22.09627
74.34400,6.19539,359.66223,-0.13711,20.40610,17.93004
74.39001,6.19915,9.69329,-0.13711,20.42117,0.48323