File: Manufatura Aditiva/Dados/Ensaios AMR/Ensaios/Ensaios FDM/Tracao_OLABI_22_05_2018_FDM_XY1.is_metal_RawData/Specimen_RawData_3.csv
Time,Extension,Load,Strain 1,Tensile strain,Tensile stress
(sec),(mm),(N),(mm/mm),(%),(MPa)
0.00000,0.00149,20.15616,-0.00353,-0.35305,1.01085
0.10000,0.00532,21.88359,-0.00350,-0.35013,1.09748
0.20000,0.01489,25.77280,-0.00337,-0.33694,1.29253
0.30000,0.02469,30.22978,-0.00323,-0.32287,1.51605
0.40000,0.03396,34.68017,-0.00309,-0.30924,1.73924
0.50000,0.04287,38.22336,-0.00296,-0.29626,1.91694
0.60000,0.05124,42.95132,-0.00283,-0.28322,2.15405
0.70000,0.05973,46.26350,-0.00271,-0.27075,2.32016
0.80000,0.06810,49.85906,-0.00259,-0.25873,2.50048
0.90000,0.07635,53.65502,-0.00246,-0.24581,2.69085
1.00000,0.08472,57.70572,-0.00234,-0.23371,2.89400
1.10000,0.09315,61.48635,-0.00221,-0.22067,3.08360
1.20000,0.10140,64.58457,-0.00209,-0.20869,3.23898
1.30000,0.10977,68.54725,-0.00196,-0.19573,3.43771
1.40000,0.11820,72.53689,-0.00183,-0.18285,3.63779
1.50000,0.12645,76.35487,-0.00171,-0.17074,3.82927
1.60000,0.13477,80.09019,-0.00157,-0.15694,4.01660
1.70000,0.14320,83.95519,-0.00145,-0.14455,4.21043
1.80000,0.15139,86.82536,-0.00133,-0.13259,4.35437
1.90000,0.15976,90.50567,-0.00120,-0.11978,4.53895
2.00000,0.16813,94.16710,-0.00107,-0.10681,4.72257
2.10000,0.17638,97.91763,-0.00094,-0.09391,4.91066
2.20000,0.18481,102.08882,-0.00081,-0.08079,5.11985
2.30000,0.19312,105.46270,-0.00069,-0.06852,5.28905
2.40000,0.20137,108.39031,-0.00055,-0.05499,5.43588
2.50000,0.20974,112.56112,-0.00043,-0.04279,5.64505
2.60000,0.21799,116.53446,-0.00030,-0.02979,5.84431
2.70000,0.22636,119.61700,-0.00017,-0.01707,5.99891
2.80000,0.23479,123.30504,-0.00004,-0.00419,6.18387
2.90000,0.24310,126.66958,0.00009,0.00871,6.35260
3.00000,0.25141,130.44038,0.00021,0.02142,6.54171
3.10000,0.25979,134.45761,0.00035,0.03484,6.74318
3.20000,0.26810,136.90256,0.00047,0.04738,6.86579
3.30000,0.27641,140.53462,0.00060,0.06002,7.04795
3.40000,0.28478,144.12911,0.00073,0.07278,7.22821
3.50000,0.29309,148.18246,0.00086,0.08620,7.43149
3.60000,0.30140,151.36274,0.00099,0.09935,7.59099
3.70000,0.30977,154.42468,0.00112,0.11237,7.74454
3.80000,0.31820,157.85286,0.00125,0.12486,7.91647
3.90000,0.32651,161.64939,0.00139,0.13859,8.10687
4.00000,0.33476,164.62880,0.00151,0.15117,8.25629
4.10000,0.34307,168.15718,0.00164,0.16439,8.43324
4.20000,0.35144,171.60850,0.00177,0.17733,8.60633
4.30000,0.35969,175.58713,0.00190,0.19018,8.80586
4.40000,0.36806,179.22034,0.00203,0.20312,8.98807
4.50000,0.37637,182.80457,0.00216,0.21627,9.16782
4.60000,0.38469,185.97973,0.00230,0.22952,9.32706
4.70000,0.39306,189.91993,0.00242,0.24246,9.52467
4.80000,0.40143,192.61262,0.00256,0.25583,9.65971
4.90000,0.40980,196.09875,0.00268,0.26848,9.83454
5.00000,0.41811,199.61176,0.00282,0.28152,10.01072
5.10000,0.42642,203.11556,0.00295,0.29520,10.18644
5.20000,0.43467,207.10293,0.00308,0.30778,10.38641
5.30000,0.44310,209.81138,0.00321,0.32109,10.52224
5.40000,0.45147,213.46926,0.00334,0.33410,10.70569
5.50000,0.45978,216.62037,0.00347,0.34721,10.86372
5.60000,0.46809,220.69730,0.00361,0.36068,11.06818
5.70000,0.47646,223.29697,0.00373,0.37316,11.19856
5.80000,0.48471,228.33231,0.00386,0.38640,11.45108
5.90000,0.49308,230.89622,0.00399,0.39949,11.57967
6.00000,0.50145,234.39615,0.00412,0.41243,11.75519
6.10000,0.50977,237.65690,0.00426,0.42576,11.91872
6.20000,0.51814,240.72591,0.00439,0.43865,12.07263
6.30000,0.52645,245.18685,0.00452,0.45203,12.29635
6.40000,0.53476,248.71558,0.00465,0.46488,12.47332
6.50000,0.54307,251.22545,0.00478,0.47808,12.59920
6.60000,0.55138,255.24502,0.00491,0.49148,12.80078
6.70000,0.55975,258.73173,0.00505,0.50458,12.97564
6.80000,0.56812,261.63955,0.00518,0.51761,13.12147
6.90000,0.57643,264.96535,0.00531,0.53118,13.28827
7.00000,0.58468,268.76829,0.00544,0.54443,13.47899
7.10000,0.59317,273.02583,0.00558,0.55824,13.69251
7.20000,0.60142,276.20124,0.00571,0.57116,13.85176
7.30000,0.60967,279.16650,0.00584,0.58445,14.00047
7.40000,0.61816,282.94711,0.00598,0.59766,14.19007
7.50000,0.62635,285.97380,0.00611,0.61068,14.34186
7.60000,0.63467,289.34723,0.00624,0.62408,14.51104
7.70000,0.64316,292.48972,0.00638,0.63754,14.66864
7.80000,0.65141,296.31443,0.00650,0.65043,14.86045
7.90000,0.65978,298.99725,0.00664,0.66400,14.99500
8.00000,0.66821,303.00973,0.00678,0.67814,15.19623
8.10000,0.67640,306.48627,0.00691,0.69077,15.37058
8.20000,0.68477,309.35132,0.00704,0.70368,15.51426
8.30000,0.69314,312.82883,0.00717,0.71719,15.68866
8.40000,0.70145,315.95654,0.00730,0.73026,15.84552
8.50000,0.70982,319.37873,0.00744,0.74377,16.01715
8.60000,0.71813,323.20421,0.00757,0.75740,16.20900
8.70000,0.72638,326.85066,0.00770,0.77015,16.39187
8.80000,0.73481,328.71671,0.00784,0.78373,16.48546
8.90000,0.74306,333.11672,0.00797,0.79699,16.70612
9.00000,0.75137,336.45839,0.00810,0.81011,16.87371
9.10000,0.75992,339.52233,0.00824,0.82370,17.02737
9.20000,0.76812,342.65495,0.00837,0.83719,17.18447
9.30000,0.77643,345.66903,0.00850,0.85018,17.33563
9.40000,0.78492,349.67859,0.00864,0.86420,17.53671
9.50000,0.79305,352.48024,0.00877,0.87734,17.67722
9.60000,0.80136,355.38012,0.00891,0.89095,17.82265
9.70000,0.80985,359.18511,0.00904,0.90390,18.01348
9.80000,0.81804,361.65968,0.00917,0.91724,18.13758
9.90000,0.82641,365.12027,0.00931,0.93052,18.31113
10.00000,0.83478,367.99081,0.00943,0.94343,18.45509
10.10000,0.84303,371.11919,0.00954,0.95446,18.61198
10.20000,0.85140,374.39154,0.00968,0.96813,18.77609
10.30000,0.85977,377.26113,0.00981,0.98140,18.92001
10.40000,0.86808,379.95684,0.00995,0.99465,19.05520
10.50000,0.87639,383.14767,0.01007,1.00746,19.21522
10.60000,0.88471,386.34429,0.01021,1.02149,19.37553
10.70000,0.89308,389.61919,0.01035,1.03478,19.53977
10.80000,0.90145,392.64783,0.01048,1.04819,19.69166
10.90000,0.90976,395.94728,0.01061,1.06135,19.85713
11.00000,0.91813,399.19033,0.01075,1.07496,20.01978
11.10000,0.92650,402.26486,0.01089,1.08896,20.17397
11.20000,0.93475,405.29687,0.01102,1.10172,20.32603
11.30000,0.94306,408.51641,0.01115,1.11527,20.48749
11.40000,0.95149,412.26172,0.01129,1.12854,20.67532
11.50000,0.95968,415.05061,0.01142,1.14185,20.81518
11.60000,0.96799,418.30679,0.01155,1.15546,20.97849
11.70000,0.97648,420.95543,0.01169,1.16917,21.11132
11.80000,0.98473,424.48216,0.01183,1.18280,21.28819
11.90000,0.99304,427.51725,0.01196,1.19587,21.44040
12.00000,1.00147,430.41823,0.01210,1.20969,21.58588
12.10000,1.00972,433.66230,0.01223,1.22324,21.74858
12.20000,1.01810,436.49329,0.01236,1.23635,21.89055
12.30000,1.02647,439.46505,0.01250,1.24962,22.03959
12.40000,1.03478,442.89995,0.01263,1.26341,22.21185
12.50000,1.04315,445.75068,0.01277,1.27696,22.35482
12.60000,1.05152,448.74069,0.01290,1.29034,22.50477
12.70000,1.05977,451.65508,0.01304,1.30356,22.65093
12.80000,1.06808,454.55857,0.01317,1.31727,22.79655
12.90000,1.07639,457.51282,0.01331,1.33086,22.94470
13.00000,1.08470,460.97813,0.01345,1.34453,23.11849
13.10000,1.09307,463.91105,0.01358,1.35807,23.26558
13.20000,1.10144,466.59037,0.01372,1.37184,23.39995
13.30000,1.10975,469.86123,0.01385,1.38515,23.56399
13.40000,1.11818,473.26786,0.01399,1.39861,23.73483
13.50000,1.12643,476.27590,0.01412,1.41199,23.88569
13.60000,1.13474,479.38484,0.01426,1.42571,24.04161
13.70000,1.14323,482.33774,0.01439,1.43907,24.18970
13.80000,1.15143,485.22339,0.01453,1.45292,24.33442
13.90000,1.15968,488.17527,0.01466,1.46636,24.48246
14.00000,1.16817,490.99014,0.01480,1.48029,24.62362
14.10000,1.17636,494.23967,0.01494,1.49404,24.78659
14.20000,1.18473,497.42991,0.01507,1.50718,24.94658
14.30000,1.19316,500.00809,0.01521,1.52094,25.07588
14.40000,1.20135,503.20663,0.01534,1.53439,25.23629
14.50000,1.20972,506.32078,0.01548,1.54820,25.39247
14.60000,1.21815,509.05915,0.01562,1.56215,25.52980
14.70000,1.22640,512.32995,0.01576,1.57573,25.69384
14.80000,1.23471,514.54138,0.01589,1.58911,25.80474
14.90000,1.24314,517.59300,0.01603,1.60334,25.95778
15.00000,1.25133,520.60680,0.01617,1.61690,26.10893
15.10000,1.25982,523.68264,0.01630,1.63022,26.26318
15.20000,1.26808,525.29722,0.01642,1.64160,26.34416
15.30000,1.27639,528.38507,0.01655,1.65529,26.49902
15.40000,1.28482,531.84913,0.01669,1.66895,26.67274
15.50000,1.29307,534.62284,0.01680,1.68033,26.81185
15.60000,1.30138,536.88972,0.01694,1.69409,26.92553
15.70000,1.30987,539.28178,0.01708,1.70804,27.04550
15.80000,1.31812,541.88017,0.01722,1.72159,27.17581
15.90000,1.32637,545.75708,0.01735,1.73500,27.37024
16.00000,1.33480,548.13195,0.01749,1.74916,27.48934
16.10000,1.34299,550.88815,0.01763,1.76313,27.62757
16.20000,1.35136,553.30954,0.01777,1.77667,27.74900
16.30000,1.35985,556.48983,0.01791,1.79075,27.90849
16.40000,1.36804,559.50098,0.01804,1.80424,28.05951
16.50000,1.37635,562.17927,0.01818,1.81825,28.19383
16.60000,1.38484,565.17045,0.01832,1.83234,28.34384
16.70000,1.39310,567.50979,0.01846,1.84576,28.46116
16.80000,1.40147,570.76598,0.01860,1.85983,28.62446
16.90000,1.40984,573.42290,0.01873,1.87349,28.75771
17.00000,1.41803,576.40905,0.01888,1.88781,28.90746
17.10000,1.42646,578.71556,0.01902,1.90166,29.02314
17.20000,1.43477,581.28759,0.01916,1.91563,29.15213
17.30000,1.44302,584.12389,0.01929,1.92904,29.29437
17.40000,1.45145,586.65969,0.01943,1.94295,29.42154
17.50000,1.45976,589.61315,0.01957,1.95698,29.56966
17.60000,1.46807,592.00996,0.01971,1.97116,29.68987
17.70000,1.47650,595.13273,0.01985,1.98524,29.84647
17.80000,1.48481,598.04581,0.01999,1.99945,29.99257
17.90000,1.49306,600.37193,0.02013,2.01309,30.10922
18.00000,1.50143,603.35002,0.02027,2.02716,30.25858
18.10000,1.50968,605.81467,0.02041,2.04088,30.38218
18.20000,1.51806,608.55225,0.02055,2.05455,30.51948
18.30000,1.52649,611.02011,0.02069,2.06862,30.64324
18.40000,1.53468,613.66917,0.02082,2.08243,30.77609
18.50000,1.54305,616.28236,0.02097,2.09657,30.90715
18.60000,1.55148,618.87633,0.02111,2.11067,31.03724
18.70000,1.55973,621.76953,0.02125,2.12499,31.18233
18.80000,1.56810,623.73448,0.02138,2.13848,31.28088
18.90000,1.57647,626.21739,0.02153,2.15291,31.40540
19.00000,1.58478,628.96870,0.02167,2.16708,31.54338
19.10000,1.59315,631.45314,0.02181,2.18096,31.66798
19.20000,1.60146,634.46150,0.02195,2.19521,31.81885
19.30000,1.60983,637.10432,0.02208,2.20816,31.95139
19.40000,1.61808,638.59518,0.02220,2.22014,32.02616
19.50000,1.62639,641.00982,0.02234,2.23444,32.14725
19.60000,1.63476,643.98921,0.02249,2.24862,32.29667
19.70000,1.64313,646.30527,0.02263,2.26296,32.41283
19.80000,1.65145,648.55134,0.02277,2.27682,32.52547
19.90000,1.65982,651.24147,0.02291,2.29149,32.66038
20.00000,1.66819,654.20861,0.02306,2.30569,32.80919
20.10000,1.67644,656.95429,0.02320,2.32006,32.94688
20.20000,1.68469,659.11496,0.02334,2.33392,33.05524
20.30000,1.69306,661.37938,0.02348,2.34811,33.16881
20.40000,1.70131,663.81334,0.02362,2.36223,33.29087
20.50000,1.70968,666.65872,0.02377,2.37663,33.43357
20.60000,1.71817,669.17371,0.02391,2.39108,33.55970
20.70000,1.72636,671.70435,0.02405,2.40501,33.68661
20.80000,1.73473,673.93370,0.02420,2.41963,33.79842
20.90000,1.74316,676.32040,0.02434,2.43422,33.91811
21.00000,1.75135,679.23260,0.02448,2.44833,34.06416
21.10000,1.75978,681.33445,0.02463,2.46250,34.16957
21.20000,1.76809,683.93019,0.02477,2.47665,34.29975
21.30000,1.77635,686.15233,0.02491,2.49112,34.41119
21.40000,1.78472,688.91235,0.02506,2.50573,34.54961
21.50000,1.79315,691.73048,0.02520,2.52031,34.69094
21.60000,1.80140,693.90833,0.02535,2.53473,34.80017
21.70000,1.80977,695.43286,0.02549,2.54911,34.87662
21.80000,1.81814,698.41975,0.02564,2.56363,35.02642
21.90000,1.82645,700.23574,0.02578,2.57761,35.11749
22.00000,1.83482,703.33420,0.02593,2.59279,35.27288
22.10000,1.84319,705.76575,0.02608,2.60758,35.39482
22.20000,1.85144,707.55156,0.02622,2.62212,35.48439
22.30000,1.85987,709.80266,0.02637,2.63664,35.59728
22.40000,1.86806,712.07485,0.02652,2.65188,35.71124
22.50000,1.87637,714.75785,0.02666,2.66632,35.84579
22.60000,1.88480,716.92364,0.02681,2.68082,35.95441
22.70000,1.89311,719.01977,0.02696,2.69560,36.05953
22.80000,1.90137,721.10593,0.02710,2.71024,36.16415
22.90000,1.90980,723.68081,0.02725,2.72513,36.29328
23.00000,1.91805,725.71277,0.02740,2.73978,36.39519
23.10000,1.92636,728.14035,0.02755,2.75459,36.51693
23.20000,1.93485,730.01273,0.02769,2.76925,36.61084
23.30000,1.94310,732.57294,0.02784,2.78390,36.73923
23.40000,1.95141,734.16103,0.02799,2.79854,36.81887
23.50000,1.95978,736.57120,0.02814,2.81378,36.93975
23.60000,1.96803,738.31892,0.02828,2.82794,37.02740
23.70000,1.97646,739.46072,0.02840,2.83961,37.08466
23.80000,1.98477,741.82590,0.02854,2.85432,37.20328
23.90000,1.99308,744.30201,0.02869,2.86916,37.32746
24.00000,2.00145,746.34869,0.02884,2.88396,37.43010
24.10000,2.00982,748.43829,0.02900,2.89952,37.53489
24.20000,2.01819,751.13880,0.02914,2.91398,37.67033
24.30000,2.02656,752.70301,0.02929,2.92931,37.74878
24.40000,2.03476,754.68207,0.02944,2.94390,37.84803
24.50000,2.04307,756.67845,0.02957,2.95698,37.94815
24.60000,2.05150,758.66021,0.02972,2.97214,38.04753
24.70000,2.05981,760.66502,0.02987,2.98727,38.14808
24.80000,2.06812,763.06160,0.03002,3.00222,38.26827
24.90000,2.07649,764.61118,0.03018,3.01773,38.34598
25.00000,2.08474,766.95480,0.03033,3.03302,38.46352
25.10000,2.09311,768.41014,0.03048,3.04798,38.53650
25.20000,2.10148,770.58286,0.03063,3.08146,38.64547
25.30000,2.10973,772.77548,0.03078,3.11447,38.75543
25.40000,2.11810,774.89153,0.03093,3.14795,38.86155
25.43400,2.12091,775.45028,0.03098,3.15919,38.88957
25.53400,2.12922,776.91562,0.03113,3.19243,38.96306
25.63400,2.13753,778.90917,0.03129,3.22567,39.06304
25.73400,2.14584,781.18490,0.03145,3.25892,39.17717
25.83400,2.15416,782.91176,0.03160,3.29216,39.26377
25.93400,2.16253,783.80797,0.03175,3.32564,39.30872
26.03400,2.17090,786.50974,0.03191,3.35912,39.44421
26.13400,2.17927,788.19552,0.03206,3.39261,39.52876
26.23400,2.18758,790.02930,0.03221,3.42585,39.62072
26.33400,2.19601,792.30582,0.03237,3.45957,39.73489
26.43400,2.20432,793.88097,0.03253,3.49281,39.81389
26.53400,2.21263,795.72629,0.03268,3.52606,39.90643
26.63400,2.22094,797.21976,0.03284,3.55930,39.98133
26.73400,2.22925,798.90070,0.03299,3.59254,40.06563
26.83400,2.23762,800.51003,0.03315,3.62602,40.14634
26.93400,2.24593,802.77519,0.03331,3.65927,40.25994
27.03400,2.25424,804.33246,0.03346,3.69251,40.33804
27.13400,2.26261,806.66905,0.03392,3.72599,40.45522
27.23400,2.27098,807.78170,0.03378,3.75947,40.51102
27.33400,2.27935,809.53725,0.03482,3.79296,40.59906
27.43400,2.28767,812.56013,0.03018,3.82620,40.75067
27.53400,2.29598,812.73289,0.00237,3.85944,40.75933
27.63400,2.30429,813.96988,0.00329,3.89269,40.82137
27.73400,2.31266,816.12999,0.00278,3.92617,40.92970
27.83400,2.32091,817.82872,0.00286,3.95917,41.01489
27.93400,2.32922,819.23492,0.00282,3.99241,41.08541
28.03400,2.33759,821.24779,0.00185,4.02590,41.18636
28.13400,2.34590,822.51308,0.00105,4.05914,41.24982
28.23400,2.35427,824.10984,0.00027,4.09262,41.32990
28.33400,2.36264,826.00191,0.00080,4.12610,41.42479
28.43400,2.37089,827.18153,0.00050,4.15911,41.48394
28.53400,2.37920,828.49404,0.00572,4.19235,41.54977
28.63400,2.38763,830.20097,0.00551,4.22607,41.63537
28.73400,2.39588,831.61900,0.00480,4.25908,41.70649
28.83400,2.40426,832.69207,0.00440,4.29256,41.76030
28.93400,2.41263,833.50698,0.00337,4.32604,41.80117
29.03400,2.42088,835.45949,-0.00075,4.35904,41.89909
29.13400,2.42925,836.99860,-0.01890,4.39253,41.97628
29.23400,2.43762,838.47605,-0.02599,4.42601,42.05037
29.33400,2.44593,839.73221,-0.13542,4.45925,42.11337
29.43400,2.45430,841.43225,-0.13846,4.49273,42.19863
29.53400,2.46261,842.56073,-0.13863,4.52598,42.25523
29.63400,2.47098,843.95083,-0.13863,4.55946,42.32494
29.73400,2.47929,845.81459,-0.13863,4.59270,42.41841
29.83400,2.48760,847.12440,-0.13863,4.62594,42.48410
29.93400,2.49591,847.89954,-0.13863,4.65919,42.52297
30.03400,2.50428,850.04885,-0.13863,4.69267,42.63076
30.13400,2.51259,851.26152,-0.13863,4.72591,42.69158
30.23400,2.52090,852.49599,-0.13863,4.75915,42.75349
30.33400,2.52933,853.19066,-0.13863,4.79288,42.78833
30.43400,2.53759,854.53484,-0.13863,4.82588,42.85574
30.53400,2.54590,856.11036,-0.13863,4.85912,42.93475
30.63400,2.55433,857.41729,-0.13863,4.89284,43.00029
30.73400,2.56264,859.01665,-0.13863,4.92609,43.08051
30.83400,2.57095,860.00971,-0.13863,4.95933,43.13031
30.93400,2.57932,861.04870,-0.13863,4.99281,43.18242
31.03400,2.58751,862.46971,-0.13863,5.02558,43.25368
31.13400,2.59588,863.48215,-0.13863,5.05906,43.30445
31.23400,2.60431,865.01930,-0.13863,5.09278,43.38154
31.33400,2.61256,866.00045,-0.13863,5.12578,43.43075
31.43400,2.62093,867.24944,-0.13863,5.15927,43.49339
31.53400,2.62924,868.05737,-0.13863,5.19251,43.53391
31.63400,2.63755,869.49542,-0.13863,5.22575,43.60603
31.73400,2.64592,870.76798,-0.13863,5.25923,43.66985
31.83400,2.65429,871.68077,-0.13863,5.29272,43.71562
31.93400,2.66261,872.74825,-0.13863,5.32596,43.76916
32.03400,2.67092,873.70407,-0.13863,5.35920,43.81709
32.13400,2.67923,874.91320,-0.13863,5.39244,43.87773
32.23400,2.68754,875.87880,-0.13863,5.42569,43.92616
32.33400,2.69591,876.93725,-0.13864,5.45917,43.97924
32.43400,2.70422,877.66387,-0.13863,5.49241,44.01568
32.53400,2.71259,879.12576,-0.13863,5.52590,44.08900
32.63400,2.72096,879.89885,-0.13863,5.55938,44.12777
32.73400,2.72927,880.99176,-0.13863,5.59262,44.18258
32.83400,2.73764,881.81058,-0.13863,5.62610,44.22364
32.93400,2.74595,883.02512,-0.13863,5.65935,44.28455
33.03400,2.75426,883.32286,-0.13863,5.69259,44.29948
33.13400,2.76257,884.51933,-0.13863,5.72583,44.35949
33.23400,2.77088,884.75570,-0.13864,5.75907,44.37134
33.33400,2.77925,886.12074,-0.13864,5.79256,44.43980
33.43400,2.78751,887.14361,-0.13864,5.82556,44.49110
33.53400,2.79594,888.00788,-0.13864,5.85928,44.53444
33.63400,2.80431,888.54199,-0.13863,5.89276,44.56123
33.73400,2.81262,889.43867,-0.13864,5.92601,44.60620
33.83400,2.82099,889.89977,-0.13864,5.95949,44.62932
33.93400,2.82930,890.69279,-0.13864,5.99273,44.66909
34.03400,2.83761,891.72125,-0.13864,6.02597,44.72067
34.13400,2.84592,892.48316,-0.13864,6.05922,44.75888
34.23400,2.85423,893.23791,-0.13864,6.09246,44.79673
34.33400,2.86254,894.19577,-0.13864,6.12570,44.84477
34.43400,2.87091,894.69748,-0.13864,6.15919,44.86993
34.53400,2.87922,895.25776,-0.13864,6.19243,44.89803
34.63400,2.88759,896.28669,-0.13864,6.22591,44.94963
34.73400,2.89602,896.27877,-0.13864,6.25963,44.94923
34.83400,2.90433,896.88227,-0.13864,6.29288,44.97950
34.93400,2.91265,897.20534,-0.13864,6.32612,44.99570
35.03400,2.92096,898.23510,-0.13864,6.35936,45.04735
35.13400,2.92927,898.75702,-0.13864,6.39260,45.07352
35.23400,2.93770,899.00522,-0.13864,6.42632,45.08597
35.33400,2.94595,899.86390,-0.13864,6.45933,45.12903
35.43400,2.95420,900.60178,-0.13864,6.49233,45.16604
35.53400,2.96263,901.33715,-0.13864,6.52605,45.20292
35.63400,2.97082,901.88179,-0.13864,6.55882,45.23023
35.73400,2.97919,901.43019,-0.13864,6.59230,45.20758
35.83400,2.98768,902.21222,-0.13864,6.62626,45.24680
35.93400,2.99593,902.78806,-0.13864,6.65927,45.27568
36.03400,3.00430,902.94462,-0.13864,6.69275,45.28354
36.13400,3.01273,903.91599,-0.13864,6.72647,45.33225
36.23400,3.02086,904.46305,-0.13864,6.75899,45.35968
36.33400,3.02929,904.19147,-0.13864,6.79272,45.34607
36.43400,3.03761,904.72652,-0.13864,6.82596,45.37290
36.53400,3.04586,905.34454,-0.13864,6.85896,45.40389
36.63400,3.05423,905.84531,-0.13864,6.89244,45.42901
36.73400,3.06254,906.01873,-0.13864,6.92569,45.43770
36.83400,3.07085,906.08578,-0.13864,6.95893,45.44107
36.93400,3.07928,906.21309,-0.13864,6.99265,45.44745
37.03400,3.08759,907.10316,-0.13864,7.02589,45.49209
37.13400,3.09596,907.08947,-0.13864,7.05938,45.49140
37.23400,3.10439,907.09683,-0.13864,7.09310,45.49177
37.33400,3.11258,907.28747,-0.13864,7.12586,45.50133
37.43400,3.12083,907.72817,-0.13864,7.15887,45.52343
37.53400,3.12932,908.36864,-0.13864,7.19283,45.55555
37.63400,3.13757,908.06279,-0.13864,7.22583,45.54021
37.73400,3.14588,908.39909,-0.13864,7.25907,45.55708
37.83400,3.15437,908.20389,-0.13865,7.29303,45.54729
37.93400,3.16257,908.59756,-0.13864,7.32580,45.56704
38.03400,3.17094,908.84808,-0.13865,7.35928,45.57960
38.13400,3.17943,908.80645,-0.13864,7.39324,45.57751
38.23400,3.18756,909.20981,-0.13865,7.42577,45.59774
38.33400,3.19593,908.69870,-0.13865,7.45925,45.57211
38.43400,3.20424,909.07635,-0.13864,7.49249,45.59105
38.53400,3.21249,909.35305,-0.13864,7.52549,45.60492
38.63400,3.22092,909.49470,-0.13865,7.55922,45.61203
38.73400,3.22929,909.19342,-0.13864,7.59270,45.59692
38.83400,3.23754,909.24343,-0.13864,7.62570,45.59943
38.93400,3.24591,908.88031,-0.13864,7.65918,45.58121
39.03400,3.25422,909.25824,-0.13864,7.69243,45.60017
39.13400,3.26253,909.13652,-0.13865,7.72567,45.59406
39.23400,3.27096,909.26588,-0.13864,7.75939,45.60055
39.33400,3.27921,909.53223,-0.13865,7.79240,45.61391
39.43400,3.28753,908.93107,-0.13865,7.82564,45.58376
39.53400,3.29596,909.24045,-0.13865,7.85936,45.59928
39.63400,3.30421,909.00986,-0.13864,7.89236,45.58771
39.73400,3.31258,908.61544,-0.13864,7.92585,45.56793
39.83400,3.32101,909.01963,-0.13865,7.95957,45.58820
39.93400,3.32926,908.56934,-0.13865,7.99257,45.56562
40.03400,3.33757,907.97441,-0.13864,8.02581,45.53578
40.13400,3.34600,908.48245,-0.13865,8.05954,45.56126
40.23400,3.35425,908.25753,-0.13865,8.09254,45.54998
40.33400,3.36262,908.08114,-0.13865,8.12602,45.54114
40.43400,3.37099,908.23099,-0.13865,8.15950,45.54865
40.53400,3.37930,907.75667,-0.13864,8.19275,45.52486
40.63400,3.38767,907.50344,-0.13865,8.22623,45.51217
40.73400,3.39598,907.44002,-0.13865,8.25947,45.50898
40.83400,3.40423,906.75000,-0.13865,8.29247,45.47438
40.93400,3.41260,906.83121,-0.13865,8.32596,45.47845
41.03400,3.42092,906.00764,-0.13864,8.35920,45.43715
41.13400,3.42923,906.60304,-0.13865,8.39244,45.46701
41.23400,3.43766,905.91051,-0.13865,8.42616,45.43228
41.33400,3.44597,906.34990,-0.13865,8.45941,45.45431
41.43400,3.45422,905.86673,-0.13865,8.49241,45.43008
41.53400,3.46259,905.69304,-0.13865,8.52589,45.42137
41.63400,3.47090,904.57946,-0.13865,8.55914,45.36552
41.73400,3.47915,904.37075,-0.13865,8.59214,45.35506
41.83400,3.48764,904.00726,-0.13865,8.62610,45.33683
41.93400,3.49589,903.51366,-0.13865,8.65910,45.31207
42.03400,3.50420,903.61619,-0.13865,8.69235,45.31721
42.13400,3.51269,903.13898,-0.13865,8.72631,45.29328
42.23400,3.52088,902.90187,-0.13865,8.75907,45.28139
42.33400,3.52925,902.01376,-0.13865,8.79255,45.23685
42.43400,3.53768,901.43103,-0.13865,8.82628,45.20763
42.53400,3.54594,902.12952,-0.13865,8.85928,45.24266
42.63400,3.55431,901.26693,-0.13865,8.89276,45.19940
42.73400,3.56268,901.39424,-0.13865,8.92624,45.20578
42.83400,3.57087,900.28271,-0.13865,8.95901,45.15004
42.93400,3.57924,899.81835,-0.13865,8.99249,45.12675
43.03400,3.58761,900.41328,-0.13865,9.02597,45.15659
43.13400,3.59586,898.58780,-0.13865,9.05898,45.06504
43.23400,3.60435,898.91162,-0.13864,9.09294,45.08128
43.33400,3.61266,898.21015,-0.13865,9.12618,45.04610
43.43400,3.62091,897.47207,-0.13865,9.15918,45.00908
43.53400,3.62940,897.94835,-0.13865,9.19314,45.03297
43.63400,3.63759,896.93135,-0.13865,9.22591,44.98196
43.73400,3.64584,896.55006,-0.13865,9.25891,44.96284
43.83400,3.65433,895.79597,-0.13865,9.29287,44.92502
43.93400,3.66247,896.28361,-0.13865,9.32540,44.94948
44.03400,3.67084,895.56053,-0.13865,9.35888,44.91322
44.13400,3.67939,895.06106,-0.13865,9.39308,44.88817
44.23400,3.68758,894.48579,-0.13865,9.42584,44.85931
44.33400,3.69583,893.24275,-0.13865,9.45885,44.79698
44.43400,3.70438,892.91437,-0.13865,9.49305,44.78051
44.53400,3.71257,892.70482,-0.13865,9.52581,44.77000
44.63400,3.72094,891.48916,-0.13865,9.55929,44.70903
44.73400,3.72937,891.68381,-0.13865,9.59302,44.71880
44.83400,3.73750,891.68772,-0.13865,9.62554,44.71899
44.93400,3.74593,890.01134,-0.13865,9.65926,44.63492
45.03400,3.75430,890.36832,-0.13865,9.69274,44.65282
45.13400,3.76255,889.50507,-0.13865,9.72575,44.60953
45.23400,3.77104,889.26675,-0.13865,9.75971,44.59758
45.33400,3.77929,888.84365,-0.13865,9.79271,44.57636
45.43400,3.78749,888.31140,-0.13865,9.82548,44.54966
45.53400,3.79603,887.98944,-0.13865,9.85968,44.53352
45.63400,3.80429,886.91972,-0.13865,9.89268,44.47987
45.73400,3.81254,886.20177,-0.13865,9.92568,44.44386
45.83400,3.82097,885.39096,-0.13865,9.95941,44.40320
45.93400,3.82928,885.48586,-0.13865,9.99265,44.40796
46.03400,3.83759,883.90484,-0.13865,10.02589,44.32867
46.13400,3.84602,884.03262,-0.13865,10.05961,44.33508
46.23400,3.85427,883.20663,-0.13865,10.09262,44.29366
46.33400,3.86252,882.97464,-0.13865,10.12562,44.28202
46.43400,3.87101,882.68435,-0.13865,10.15958,44.26746
46.53400,3.87926,881.01281,-0.13865,10.19258,44.18363
46.63400,3.88757,880.64186,-0.13865,10.22583,44.16503
46.73400,3.89606,880.35688,-0.13865,10.25979,44.15074
46.83400,3.90425,880.08605,-0.13865,10.29255,44.13715
46.93400,3.91256,879.44847,-0.13865,10.32580,44.10518
47.03400,3.92094,878.77233,-0.13865,10.35928,44.07127
47.13400,3.92919,878.42559,-0.13865,10.39228,44.05388
47.23400,3.93756,877.97092,-0.13865,10.42576,44.03108
47.33400,3.94593,876.74111,-0.13865,10.45925,43.96940
47.43400,3.95424,876.80323,-0.13865,10.49249,43.97252
47.53400,3.96261,876.26474,-0.13865,10.52597,43.94551
47.63400,3.97092,875.35512,-0.13865,10.55921,43.89989
47.73400,3.97929,874.89607,-0.13865,10.59270,43.87687
47.83400,3.98766,874.57718,-0.13865,10.62618,43.86088
47.93400,3.99591,874.03813,-0.13865,10.65918,43.83385
48.03400,4.00422,873.48837,-0.13865,10.69243,43.80627
48.13400,4.01259,872.79417,-0.13865,10.72591,43.77146
48.23400,4.02090,871.62396,-0.13865,10.75915,43.71277
48.33400,4.02921,871.43555,-0.13865,10.79239,43.70332
48.43400,4.03758,871.02931,-0.13865,10.82587,43.68295
48.53400,4.04589,869.85053,-0.13865,10.85912,43.62383
48.63400,4.05421,869.25039,-0.13865,10.89236,43.59374
48.73400,4.06264,869.21696,-0.13865,10.92608,43.59206
48.83400,4.07089,868.31376,-0.13865,10.95909,43.54676
48.93400,4.07920,867.24209,-0.13865,10.99233,43.49302
49.03400,4.08769,867.16805,-0.13865,11.02629,43.48930
49.13400,4.09594,867.01550,-0.13865,11.05929,43.48166
49.23400,4.10431,865.91160,-0.13865,11.09277,43.42629
49.33400,4.11262,865.25492,-0.13865,11.12602,43.39336
49.43400,4.12087,864.60132,-0.13865,11.15902,43.36058
49.53400,4.12924,864.28178,-0.13865,11.19251,43.34455
49.63400,4.13761,863.17658,-0.13865,11.22599,43.28913
49.73400,4.14592,863.03484,-0.13865,11.25923,43.28202
49.83400,4.15429,862.67227,-0.13865,11.29271,43.26384
49.93400,4.16260,861.65443,-0.13865,11.32595,43.21279
50.03400,4.17091,861.19846,-0.13865,11.35920,43.18993
50.13400,4.17929,860.36175,-0.13865,11.39268,43.14796
50.23400,4.18760,859.45716,-0.13866,11.42592,43.10260
50.33400,4.19585,859.68999,-0.13865,11.45893,43.11427
50.43400,4.20428,859.06582,-0.13865,11.49265,43.08297
50.53400,4.21259,857.85640,-0.13865,11.52589,43.02232
50.63400,4.22084,857.53137,-0.13865,11.55889,43.00602
50.73400,4.22933,857.26958,-0.13865,11.59285,42.99289
50.83400,4.23764,855.82342,-0.13865,11.62610,42.92036
50.93400,4.24601,855.84093,-0.13865,11.65958,42.92124
51.03400,4.25444,855.36251,-0.13865,11.69330,42.89725
51.13400,4.26263,854.32176,-0.13866,11.72606,42.84505
51.23400,4.27088,853.75980,-0.13865,11.75907,42.81687
51.33400,4.27925,853.31956,-0.13865,11.79255,42.79479
51.43400,4.28750,852.60458,-0.13865,11.82555,42.75893
51.53400,4.29593,852.66344,-0.13865,11.85928,42.76189
51.63400,4.30431,851.43531,-0.13865,11.89276,42.70029
51.73400,4.31256,851.11214,-0.13865,11.92576,42.68409
51.83400,4.32093,850.53071,-0.13865,11.95924,42.65493
51.93400,4.32930,849.64437,-0.13866,11.99273,42.61048
52.03400,4.33755,848.63342,-0.13865,12.02573,42.55978
52.13400,4.34604,848.80358,-0.13865,12.05969,42.56831
52.23400,4.35429,848.12064,-0.13866,12.09269,42.53406
52.33400,4.36254,847.50317,-0.13866,12.12570,42.50309
52.43400,4.37097,846.63266,-0.13865,12.15942,42.45943
52.53400,4.37922,845.84840,-0.13865,12.19242,42.42010
52.63400,4.38753,845.50772,-0.13866,12.22567,42.40302
52.73400,4.39602,844.63907,-0.13865,12.25963,42.35946
52.83400,4.40421,844.30277,-0.13865,12.29239,42.34259
52.93400,4.41252,843.16768,-0.13865,12.32563,42.28566
53.03400,4.42101,843.27552,-0.13865,12.35960,42.29107
53.13400,4.42933,842.37419,-0.13866,12.39284,42.24587
53.23400,4.43764,841.55751,-0.13865,12.42608,42.20491
53.33400,4.44601,840.96147,-0.13865,12.45956,42.17502
53.43400,4.45426,839.98879,-0.13865,12.49257,42.12624
53.53400,4.46257,839.54716,-0.13865,12.52581,42.10409
53.63400,4.47094,839.47545,-0.13865,12.55929,42.10049
53.73400,4.47919,838.50669,-0.13865,12.59230,42.05191
53.83400,4.48762,837.86463,-0.13865,12.62602,42.01971
53.93400,4.49593,837.28544,-0.13865,12.65926,41.99067
54.03400,4.50424,836.75189,-0.13865,12.69250,41.96391
54.13400,4.51267,836.36986,-0.13865,12.72622,41.94475
54.23400,4.52092,835.14871,-0.13865,12.75923,41.88351
54.33400,4.52923,834.38512,-0.13865,12.79247,41.84521
54.43400,4.53760,834.37674,-0.13865,12.82595,41.84479
54.53400,4.54579,833.41869,-0.13865,12.85872,41.79674
54.63400,4.55417,832.56857,-0.13865,12.89220,41.75411
54.73400,4.56260,832.11344,-0.13865,12.92592,41.73128
54.83400,4.57091,830.97890,-0.13865,12.95916,41.67439
54.93400,4.57916,830.85047,-0.13865,12.99217,41.66795
55.03400,4.58759,830.54658,-0.13865,13.02589,41.65270
55.13400,4.59590,829.48701,-0.13865,13.05913,41.59956
55.23400,4.60427,829.17409,-0.13865,13.09261,41.58387
55.33400,4.61264,828.07122,-0.13865,13.12610,41.52856
55.43400,4.62095,827.94800,-0.13865,13.15934,41.52238
55.53400,4.62926,827.36425,-0.13865,13.19258,41.49311
55.63400,4.63763,826.18948,-0.13865,13.22607,41.43419
55.73400,4.64594,825.74822,-0.13865,13.25931,41.41206
55.83400,4.65425,824.89382,-0.13865,13.29255,41.36921
55.93400,4.66256,824.54002,-0.13865,13.32579,41.35147
56.03400,4.67093,823.76227,-0.13865,13.35928,41.31247
56.13400,4.67931,823.63430,-0.13865,13.39276,41.30605
56.23400,4.68762,822.33986,-0.13865,13.42600,41.24113
56.33400,4.69599,822.05506,-0.13865,13.45948,41.22684
56.43400,4.70442,821.09375,-0.13866,13.49320,41.17863
56.53400,4.71261,820.65137,-0.13865,13.52597,41.15645
56.63400,4.72098,819.79074,-0.13865,13.55945,41.11329
56.73400,4.72929,819.25923,-0.13865,13.59269,41.08663
56.83400,4.73754,819.00721,-0.13865,13.62570,41.07399
56.93400,4.74591,817.96739,-0.13865,13.65918,41.02185
57.03400,4.75428,817.42303,-0.13865,13.69266,40.99454
57.13400,4.76253,817.28892,-0.13865,13.72567,40.98782
57.23400,4.77090,815.64365,-0.13866,13.75915,40.90531
57.33400,4.77933,815.65445,-0.13865,13.79287,40.90585
57.43400,4.78764,814.49198,-0.13865,13.82611,40.84755
57.53400,4.79595,814.18622,-0.13865,13.85935,40.83221
57.63400,4.80432,813.31637,-0.13866,13.89284,40.78859
57.73400,4.81252,812.06039,-0.13865,13.92560,40.72561
57.83400,4.82089,811.42373,-0.13865,13.95908,40.69368
57.93400,4.82926,811.47114,-0.13865,13.99256,40.69605
58.03400,4.83757,810.32692,-0.13865,14.02581,40.63867
58.13400,4.84600,810.24403,-0.13865,14.05953,40.63451
58.23400,4.85431,809.06367,-0.13865,14.09277,40.57531
58.33400,4.86262,808.56187,-0.13865,14.12602,40.55015
58.43400,4.87099,808.21048,-0.13865,14.15950,40.53253
58.53400,4.87930,807.37434,-0.13866,14.19274,40.49059
58.63400,4.88761,806.11259,-0.13865,14.22599,40.42731
58.73400,4.89598,806.16968,-0.13865,14.25947,40.43018
58.83400,4.90423,804.84701,-0.13866,14.29247,40.36385
58.93400,4.91260,804.82522,-0.13866,14.32595,40.36275
59.03400,4.92097,803.80170,-0.13865,14.35943,40.31142
59.13400,4.92922,802.52923,-0.13866,14.39244,40.24761
59.23400,4.93754,802.02129,-0.13865,14.42568,40.22213
59.33400,4.94597,801.74971,-0.13866,14.45940,40.20852
59.43400,4.95428,800.77508,-0.13865,14.49264,40.15963
59.53400,4.96259,799.72288,-0.13865,14.52589,40.10686
59.63400,4.97102,798.94373,-0.13865,14.55961,40.06779
59.73400,4.97921,798.02526,-0.13865,14.59237,40.02173
59.83400,4.98758,797.99984,-0.13866,14.62586,40.02045
59.93400,4.99595,796.91876,-0.13865,14.65934,39.96624
60.03400,5.00420,796.51130,-0.13865,14.69234,39.94580
60.13400,5.01257,794.82971,-0.13865,14.72582,39.86147
60.23400,5.02094,794.47124,-0.13865,14.75931,39.84349
60.33400,5.02919,793.67915,-0.13865,14.79231,39.80377
60.43400,5.03756,793.24031,-0.13865,14.82579,39.78176
60.53400,5.04593,792.08817,-0.13866,14.85927,39.72398
60.63400,5.05436,791.32868,-0.13866,14.89300,39.68589
60.73400,5.06267,790.56444,-0.13865,14.92624,39.64756
60.83400,5.07093,789.44890,-0.13866,14.95924,39.59162
60.93400,5.07924,789.69831,-0.13865,14.99248,39.60412
61.03400,5.08761,788.26584,-0.13866,15.02597,39.53228
61.13400,5.09586,787.15133,-0.13865,15.05897,39.47639
61.23400,5.10423,786.93600,-0.13865,15.09245,39.46559
61.33400,5.11260,785.87858,-0.13865,15.12594,39.41256
61.43400,5.12091,784.87685,-0.13866,15.15918,39.36232
61.53400,5.12928,784.07396,-0.13866,15.19266,39.32206
61.63400,5.13765,783.17877,-0.13865,15.22614,39.27716
61.73400,5.14596,782.09909,-0.13866,15.25939,39.22301
61.83400,5.15427,781.60437,-0.13865,15.29263,39.19820
61.93400,5.16258,780.59621,-0.13865,15.32587,39.14764
62.03400,5.17089,779.31914,-0.13865,15.35912,39.08360
62.13400,5.17920,778.39498,-0.13866,15.39236,39.03725
62.23400,5.18758,777.33137,-0.13865,15.42584,38.98391
62.33400,5.19595,776.21723,-0.13866,15.45932,38.92804
62.43400,5.20426,775.84521,-0.13865,15.49256,38.90938
62.53400,5.21257,773.93730,-0.13865,15.52581,38.81369
62.63400,5.22094,773.16514,-0.13865,15.55929,38.77497
62.73400,5.22925,772.24961,-0.13866,15.59253,38.72905
62.83400,5.23762,770.82589,-0.13866,15.62601,38.65765
62.93400,5.24593,769.52809,-0.13865,15.65926,38.59257
63.03400,5.25424,768.49791,-0.13866,15.69250,38.54090
63.13400,5.26255,767.15341,-0.13866,15.72574,38.47348
63.23400,5.27086,765.74446,-0.13866,15.75899,38.40282
63.33400,5.27923,764.87795,-0.13866,15.79247,38.35936
63.43400,5.28760,763.67380,-0.13866,15.82595,38.29897
63.53400,5.29591,762.65624,-0.13865,15.85919,38.24794
63.63400,5.30434,761.06577,-0.13866,15.89291,38.16817
63.73400,5.31260,759.08154,-0.13866,15.92592,38.06866
63.83400,5.32097,758.18393,-0.13866,15.95940,38.02365
63.93400,5.32940,756.47603,-0.13866,15.99312,37.93800
64.03400,5.33765,754.74819,-0.13865,16.02613,37.85134
64.13400,5.34590,753.17072,-0.13865,16.05913,37.77223
64.23400,5.35427,752.00335,-0.13865,16.09261,37.71368
64.33400,5.36252,749.79956,-0.13866,16.12561,37.60316
64.43400,5.37089,747.79810,-0.13865,16.15910,37.50279
64.53400,5.37932,746.13625,-0.13866,16.19282,37.41945
64.63400,5.38757,744.24902,-0.13865,16.22582,37.32480
64.73400,5.39588,742.44877,-0.13866,16.25906,37.23452
64.83400,5.40431,739.89523,-0.13866,16.29279,37.10645
64.93400,5.41256,738.04129,-0.13865,16.32579,37.01347
65.03400,5.42093,736.36030,-0.13865,16.35927,36.92917
65.13400,5.42930,733.66733,-0.13866,16.39275,36.79412
65.23400,5.43756,731.81950,-0.13866,16.42576,36.70145
65.33400,5.44593,728.97850,-0.13866,16.45924,36.55897
65.43400,5.45424,726.72749,-0.13866,16.49248,36.44608
65.53400,5.46255,723.26697,-0.13866,16.52573,36.27253
65.63400,5.47092,720.83902,-0.13866,16.55921,36.15076
65.73400,5.47923,718.16621,-0.13866,16.59245,36.01672
65.83400,5.48760,714.97313,-0.13865,16.62593,35.85659
65.93401,5.49603,711.10083,-0.13866,16.65965,35.66238
66.03401,5.50434,706.35406,-0.13866,16.69290,35.42433
66.13400,5.51259,701.12795,-0.13865,16.72590,35.16224
66.23400,5.52096,694.15537,-0.13865,16.75939,34.81255
66.33400,5.52921,687.82968,-0.13866,16.79239,34.49532
66.43401,5.53752,679.50385,-0.13866,16.82563,34.07777
66.53401,5.54595,670.52282,-0.13865,16.85935,33.62736
66.63400,5.55420,661.80937,-0.13866,16.89236,33.19037
66.73400,5.56257,651.15942,-0.13866,16.92584,32.65627
66.83400,5.57101,640.67170,-0.13866,16.95956,32.13030
66.93401,5.57926,629.65336,-0.13865,16.99256,31.57772
67.03401,5.58769,617.50943,-0.13866,17.02629,30.96869
67.13400,5.59606,606.07223,-0.13866,17.05977,30.39510
67.23400,5.60425,593.65840,-0.13866,17.09253,29.77254
67.33400,5.61262,582.81114,-0.13866,17.12601,29.22853
67.43401,5.62093,571.06200,-0.13866,17.15926,28.63930
67.53401,5.62924,559.80850,-0.13866,17.19250,28.07493
67.63400,5.63761,547.53618,-0.13866,17.22598,27.45946
67.73400,5.64592,535.92972,-0.13865,17.25923,26.87739
67.83400,5.65423,522.95667,-0.13866,17.29247,26.22678
67.93401,5.66266,507.83018,-0.13866,17.32619,25.46817
68.03401,5.67091,490.17663,-0.13866,17.35919,24.58283
68.13400,5.67922,450.77372,-0.13866,17.39243,22.60673
68.23400,5.68766,69.56213,-0.13866,17.42616,3.48861
68.24800,5.68885,5.55300,-0.13866,17.43094,0.27849