File: Manufatura Aditiva/Classificação Direção/Ensaios/Ensaios FDM/Tracao_OLABI_22_05_2018_FDM_XY1.is_metal_RawData/Specimen_RawData_1.csv
Time,Extension,Load,Strain 1,Tensile strain,Tensile stress
(sec),(mm),(N),(mm/mm),(%),(MPa)
0.00000,65.00170,19.11209,-0.00521,-0.52141,0.94715
0.10000,65.00379,20.24031,-0.00521,-0.52054,1.00306
0.20000,65.01324,23.75719,-0.00509,-0.50852,1.17735
0.30000,65.02400,28.78209,-0.00493,-0.49344,1.42637
0.40000,65.03368,32.88950,-0.00479,-0.47890,1.62992
0.50000,65.04283,37.50479,-0.00465,-0.46535,1.85864
0.60000,65.05156,42.06330,-0.00452,-0.45210,2.08455
0.70000,65.05993,45.04909,-0.00440,-0.44033,2.23252
0.80000,65.06837,48.54127,-0.00427,-0.42743,2.40558
0.90000,65.07661,52.99676,-0.00415,-0.41514,2.62638
1.00000,65.08487,56.16772,-0.00403,-0.40300,2.78353
1.10000,65.09335,60.47013,-0.00390,-0.38998,2.99675
1.20000,65.10167,64.00086,-0.00378,-0.37762,3.17172
1.30000,65.10998,67.43101,-0.00365,-0.36550,3.34171
1.40000,65.11841,71.60155,-0.00353,-0.35257,3.54839
1.50000,65.12666,75.35389,-0.00340,-0.33993,3.73435
1.60000,65.13503,79.20809,-0.00328,-0.32759,3.92535
1.70000,65.14346,82.80961,-0.00315,-0.31476,4.10383
1.80000,65.15165,85.98710,-0.00302,-0.30245,4.26130
1.90000,65.15996,89.00058,-0.00290,-0.28978,4.41064
2.00000,65.16839,93.66727,-0.00277,-0.27690,4.64191
2.10000,65.17658,96.62315,-0.00265,-0.26454,4.78840
2.20000,65.18495,100.00458,-0.00252,-0.25168,4.95597
2.30000,65.19339,104.23439,-0.00239,-0.23871,5.16559
2.40000,65.20157,107.39052,-0.00227,-0.22686,5.32200
2.50000,65.20995,110.98332,-0.00213,-0.21343,5.50005
2.60000,65.21826,114.72236,-0.00200,-0.20039,5.68535
2.70000,65.22650,118.07281,-0.00188,-0.18788,5.85139
2.80000,65.23500,121.77455,-0.00176,-0.17555,6.03484
2.90000,65.24330,125.10453,-0.00163,-0.16260,6.19986
3.00000,65.25162,128.73573,-0.00150,-0.15001,6.37981
3.10000,65.25998,132.71917,-0.00136,-0.13649,6.57722
3.20000,65.26830,135.94603,-0.00124,-0.12413,6.73714
3.30000,65.27661,139.31806,-0.00111,-0.11111,6.90425
3.40000,65.28498,142.54702,-0.00098,-0.09784,7.06427
3.50000,65.29329,146.01276,-0.00086,-0.08562,7.23602
3.60000,65.30161,149.58777,-0.00072,-0.07227,7.41319
3.70000,65.31003,152.93361,-0.00060,-0.05979,7.57900
3.80000,65.31835,156.68767,-0.00047,-0.04696,7.76504
3.90000,65.32665,160.63716,-0.00034,-0.03384,7.96077
4.00000,65.33503,163.73588,-0.00021,-0.02053,8.11433
4.10000,65.34334,166.96762,-0.00008,-0.00786,8.27449
4.20000,65.35158,170.34238,0.00005,0.00479,8.44173
4.30000,65.36002,173.73175,0.00018,0.01782,8.60970
4.40000,65.36826,177.48337,0.00031,0.03102,8.79562
4.50000,65.37658,181.25285,0.00044,0.04399,8.98243
4.60000,65.38495,183.95957,0.00057,0.05738,9.11657
4.70000,65.39320,188.16346,0.00070,0.07017,9.32490
4.80000,65.40163,191.24130,0.00083,0.08264,9.47743
4.90000,65.41000,194.33834,0.00096,0.09607,9.63091
5.00000,65.41831,197.33559,0.00109,0.10908,9.77945
5.10000,65.42669,201.54039,0.00122,0.12233,9.98783
5.20000,65.43493,204.51578,0.00135,0.13504,10.13528
5.30000,65.44330,207.85448,0.00148,0.14808,10.30074
5.40000,65.45167,211.66732,0.00161,0.16095,10.48969
5.50000,65.45998,214.60946,0.00174,0.17403,10.63550
5.60000,65.46830,218.84474,0.00187,0.18740,10.84539
5.70000,65.47672,222.24702,0.00200,0.20042,11.01400
5.80000,65.48492,225.01908,0.00213,0.21343,11.15137
5.90000,65.49323,228.79844,0.00227,0.22655,11.33867
6.00000,65.50172,231.84866,0.00240,0.23954,11.48983
6.10000,65.50997,235.30093,0.00252,0.25247,11.66091
6.20000,65.51834,239.05525,0.00266,0.26572,11.84697
6.30000,65.52677,242.51200,0.00279,0.27914,12.01828
6.40000,65.53490,245.78234,0.00292,0.29199,12.18035
6.50000,65.54327,249.43233,0.00305,0.30504,12.36123
6.60000,65.55170,253.27858,0.00319,0.31911,12.55184
6.70000,65.55995,255.93117,0.00332,0.33191,12.68330
6.80000,65.56832,259.80202,0.00345,0.34466,12.87513
6.90000,65.57663,263.21770,0.00358,0.35769,13.04440
7.00000,65.58494,265.65716,0.00371,0.37084,13.16529
7.10000,65.59338,269.37183,0.00384,0.38432,13.34938
7.20000,65.60163,273.78607,0.00398,0.39784,13.56814
7.30000,65.60994,277.42062,0.00411,0.41110,13.74826
7.40000,65.61831,280.20437,0.00425,0.42460,13.88621
7.50000,65.62662,283.19228,0.00438,0.43755,14.03429
7.60000,65.63487,287.33858,0.00451,0.45070,14.23977
7.70000,65.64335,288.98835,0.00462,0.46236,14.32153
7.80000,65.65161,293.33895,0.00476,0.47555,14.53713
7.90000,65.65992,296.48494,0.00489,0.48879,14.69304
8.00000,65.66841,299.46140,0.00502,0.50233,14.84054
8.10000,65.67666,303.60487,0.00516,0.51569,15.04588
8.20000,65.68491,305.47685,0.00528,0.52850,15.13865
8.30000,65.69340,309.46094,0.00542,0.54231,15.33610
8.40000,65.70160,312.81037,0.00555,0.55530,15.50208
8.50000,65.70996,316.29358,0.00569,0.56854,15.67470
8.60000,65.71846,319.84542,0.00582,0.58215,15.85072
8.70000,65.72665,322.47873,0.00595,0.59522,15.98122
8.80000,65.73495,326.53857,0.00608,0.60838,16.18242
8.90000,65.74333,329.47096,0.00622,0.62243,16.32774
9.00000,65.75157,333.80080,0.00635,0.63542,16.54232
9.10000,65.76001,336.16093,0.00649,0.64925,16.65928
9.20000,65.76844,339.76557,0.00662,0.66245,16.83792
9.30000,65.77663,342.17383,0.00675,0.67510,16.95726
9.40000,65.78506,346.10610,0.00689,0.68875,17.15214
9.50000,65.79332,349.16999,0.00703,0.70256,17.30398
9.60000,65.80156,352.58289,0.00716,0.71595,17.47311
9.70000,65.81000,355.43495,0.00729,0.72916,17.61445
9.80000,65.81830,357.67527,0.00743,0.74264,17.72548
9.90000,65.82655,361.51842,0.00755,0.75546,17.91593
10.00000,65.83498,364.64769,0.00769,0.76890,18.07101
10.10000,65.84329,368.01496,0.00783,0.78265,18.23788
10.20000,65.85161,371.61517,0.00796,0.79600,18.41630
10.30000,65.86004,374.32795,0.00809,0.80931,18.55074
10.40000,65.86829,377.47074,0.00823,0.82309,18.70649
10.50000,65.87659,379.79283,0.00836,0.83628,18.82157
10.60000,65.88503,383.52306,0.00850,0.85003,19.00643
10.70000,65.89328,386.62106,0.00863,0.86330,19.15995
10.80000,65.90159,389.51403,0.00876,0.87618,19.30332
10.90000,65.91002,392.80946,0.00889,0.88882,19.46664
11.00000,65.91828,395.64776,0.00902,0.90197,19.60729
11.10000,65.92670,398.57170,0.00915,0.91542,19.75220
11.20000,65.93501,402.07091,0.00929,0.92908,19.92561
11.30000,65.94326,405.44961,0.00942,0.94224,20.09305
11.40000,65.95163,407.68236,0.00956,0.95583,20.20370
11.50000,65.95995,411.18469,0.00969,0.96922,20.37727
11.60000,65.96826,414.12693,0.00982,0.98248,20.52308
11.70000,65.97669,417.53221,0.00996,0.99575,20.69183
11.80000,65.98494,420.32781,0.01009,1.00944,20.83038
11.90000,65.99325,423.51065,0.01023,1.02287,20.98811
12.00000,66.00168,426.13596,0.01037,1.03673,21.11821
12.10000,66.00999,429.76812,0.01050,1.05027,21.29821
12.20000,66.01830,432.90206,0.01064,1.06375,21.45352
12.30000,66.02667,435.66604,0.01077,1.07733,21.59050
12.40000,66.03498,438.73838,0.01091,1.09090,21.74276
12.50000,66.04335,441.78604,0.01104,1.10447,21.89379
12.60000,66.05172,444.60921,0.01118,1.11820,22.03370
12.70000,66.05997,447.76644,0.01131,1.13141,22.19016
12.80000,66.06822,450.23388,0.01144,1.14445,22.31244
12.90000,66.07665,453.92630,0.01159,1.15857,22.49543
13.00000,66.08491,456.51007,0.01172,1.17196,22.62348
13.10000,66.09322,459.61491,0.01185,1.18532,22.77734
13.20000,66.10165,462.33349,0.01199,1.19889,22.91207
13.30000,66.10996,465.33593,0.01212,1.21238,23.06086
13.40000,66.11833,468.29921,0.01226,1.22576,23.20772
13.50000,66.12670,471.78362,0.01238,1.23807,23.38039
13.60000,66.13500,474.18643,0.01252,1.25150,23.49947
13.70000,66.14344,476.63702,0.01265,1.26487,23.62092
13.80000,66.15163,480.75393,0.01279,1.27863,23.82494
13.90000,66.15988,483.25388,0.01292,1.29174,23.94883
14.00000,66.16831,486.39369,0.01306,1.30586,24.10443
14.10000,66.17656,489.14226,0.01319,1.31942,24.24064
14.20000,66.18493,491.97068,0.01333,1.33307,24.38081
14.30000,66.19337,495.15306,0.01347,1.34682,24.53852
14.40000,66.20161,498.16840,0.01361,1.36069,24.68796
14.50000,66.20999,501.18887,0.01374,1.37434,24.83764
14.60000,66.21841,504.11397,0.01388,1.38813,24.98260
14.70000,66.22667,506.62970,0.01401,1.40145,25.10728
14.80000,66.23486,509.59336,0.01415,1.41478,25.25415
14.90000,66.24334,512.87105,0.01429,1.42921,25.41658
15.00000,66.25160,515.65082,0.01443,1.44277,25.55434
15.10000,66.25991,518.11705,0.01457,1.45673,25.67656
15.20000,66.26840,521.44798,0.01471,1.47068,25.84163
15.30000,66.27653,523.52613,0.01484,1.48415,25.94462
15.40000,66.28496,527.01808,0.01498,1.49792,26.11767
15.50000,66.29339,529.12338,0.01511,1.51146,26.22201
15.60000,66.30159,532.87256,0.01525,1.52538,26.40781
15.70000,66.31001,535.79588,0.01539,1.53899,26.55268
15.80000,66.31839,538.56652,0.01552,1.55249,26.68999
15.90000,66.32663,540.80035,0.01565,1.56505,26.80069
16.00000,66.33500,544.33891,0.01578,1.57822,26.97605
16.10000,66.34326,546.80323,0.01592,1.59198,27.09818
16.20000,66.35156,548.97028,0.01606,1.60572,27.20557
16.30000,66.36006,551.98981,0.01620,1.61974,27.35521
16.40000,66.36824,554.72390,0.01633,1.63346,27.49070
16.50000,66.37662,557.67661,0.01647,1.64743,27.63703
16.60000,66.38505,560.44920,0.01661,1.66140,27.77444
16.70000,66.39330,563.27903,0.01675,1.67524,27.91467
16.80000,66.40161,566.27253,0.01689,1.68882,28.06302
16.90000,66.41010,568.50845,0.01703,1.70307,28.17383
17.00000,66.41829,571.42135,0.01717,1.71698,28.31819
17.10000,66.42660,573.74435,0.01731,1.73084,28.43331
17.20000,66.43503,577.18046,0.01745,1.74472,28.60359
17.30000,66.44322,579.62686,0.01758,1.75827,28.72483
17.40000,66.45159,582.02581,0.01772,1.77233,28.84372
17.50000,66.46002,584.81256,0.01787,1.78664,28.98182
17.60000,66.46828,587.89183,0.01800,1.79994,29.13442
17.70000,66.47670,589.93422,0.01814,1.81411,29.23564
17.80000,66.48502,593.08796,0.01828,1.82810,29.39193
17.90000,66.49327,594.82120,0.01842,1.84168,29.47782
18.00000,66.50164,597.77754,0.01856,1.85634,29.62433
18.10000,66.50989,600.69300,0.01870,1.86966,29.76881
18.20000,66.51826,603.34788,0.01883,1.88292,29.90038
18.30000,66.52663,605.72843,0.01896,1.89551,30.01836
18.40000,66.53488,607.99783,0.01909,1.90923,30.13082
18.50000,66.54325,610.75445,0.01923,1.92304,30.26744
18.60000,66.55168,613.05980,0.01937,1.93713,30.38168
18.70000,66.55993,616.33866,0.01951,1.95111,30.54417
18.80000,66.56824,618.99880,0.01965,1.96514,30.67600
18.90000,66.57667,621.14941,0.01980,1.97953,30.78258
19.00000,66.58498,623.76717,0.01994,1.99372,30.91231
19.10000,66.59330,626.64212,0.02007,2.00732,31.05479
19.20000,66.60172,629.46361,0.02021,2.02134,31.19461
19.30000,66.60998,632.19722,0.02036,2.03588,31.33008
19.40000,66.61829,634.46392,0.02050,2.04970,31.44242
19.50000,66.62672,636.74124,0.02064,2.06407,31.55527
19.60000,66.63491,639.52091,0.02078,2.07787,31.69303
19.70000,66.64328,641.73546,0.02092,2.09224,31.80277
19.80000,66.65171,644.06344,0.02106,2.10608,31.91814
19.90000,66.66002,647.21564,0.02121,2.12067,32.07436
20.00000,66.66839,649.99377,0.02135,2.13479,32.21204
20.10000,66.67670,652.20282,0.02149,2.14904,32.32151
20.20000,66.68495,654.64126,0.02163,2.16314,32.44235
20.30000,66.69326,657.46182,0.02177,2.17722,32.58213
20.40000,66.70158,660.01168,0.02192,2.19187,32.70850
20.50000,66.70989,661.72234,0.02205,2.20523,32.79327
20.60000,66.71832,664.14936,0.02218,2.21760,32.91355
20.70000,66.72663,666.79716,0.02232,2.23154,33.04477
20.80000,66.73493,669.04998,0.02246,2.24566,33.15641
20.90000,66.74331,671.67301,0.02260,2.26010,33.28640
21.00000,66.75161,673.89775,0.02274,2.27400,33.39666
21.10000,66.75993,676.18233,0.02288,2.28847,33.50987
21.20000,66.76835,679.61127,0.02303,2.30296,33.67980
21.30000,66.77655,681.89939,0.02317,2.31703,33.79320
21.40000,66.78486,684.44675,0.02331,2.33103,33.91944
21.50000,66.79335,686.16979,0.02346,2.34585,34.00483
21.60000,66.80166,689.00040,0.02360,2.35997,34.14510
21.70000,66.80998,691.11716,0.02375,2.37462,34.25000
21.80000,66.81840,693.86703,0.02390,2.38952,34.38628
21.90000,66.82659,696.28800,0.02404,2.40374,34.50626
22.00000,66.83496,699.03028,0.02418,2.41787,34.64216
22.10000,66.84345,701.37060,0.02432,2.43249,34.75814
22.20000,66.85165,703.75451,0.02447,2.44677,34.87628
22.30000,66.85995,705.90349,0.02461,2.46117,34.98278
22.40000,66.86839,707.70886,0.02476,2.47587,35.07225
22.50000,66.87657,710.74418,0.02491,2.49064,35.22267
22.60000,66.88501,713.10787,0.02505,2.50512,35.33981
22.70000,66.89332,715.09061,0.02520,2.51994,35.43807
22.80000,66.90157,717.43592,0.02534,2.53439,35.55429
22.90000,66.91000,719.58560,0.02549,2.54860,35.66083
23.00000,66.91832,721.80675,0.02561,2.56080,35.77090
23.10000,66.92662,723.37850,0.02575,2.57515,35.84880
23.20000,66.93505,725.75789,0.02590,2.59012,35.96671
23.30000,66.94330,728.23376,0.02604,2.60445,36.08941
23.40000,66.95161,730.31224,0.02619,2.61928,36.19241
23.50000,66.96004,732.93285,0.02634,2.63379,36.32228
23.60000,66.96824,735.27293,0.02648,2.64838,36.43825
23.70000,66.97655,737.23998,0.02663,2.66301,36.53574
23.80000,66.98504,739.60461,0.02678,2.67842,36.65292
23.90000,66.99329,741.36718,0.02693,2.69307,36.74027
24.00000,67.00160,744.01340,0.02708,2.70760,36.87141
24.10000,67.01009,745.97797,0.02723,2.72305,36.96877
24.20000,67.01834,748.04006,0.02738,2.73755,37.07096
24.30000,67.02671,749.49688,0.02752,2.75208,37.14315
24.40000,67.03508,752.16936,0.02767,2.76725,37.27560
24.50000,67.04327,754.20225,0.02782,2.78178,37.37634
24.60000,67.05164,755.94750,0.02797,2.79658,37.46283
24.70000,67.06001,759.16722,0.02812,2.81181,37.62239
24.80000,67.06826,760.95206,0.02827,2.82668,37.71085
24.90000,67.07669,762.75119,0.02842,2.84177,37.80001
25.00000,67.08500,764.75493,0.02857,2.85683,37.89931
25.10000,67.09331,767.13734,0.02872,2.87153,38.01737
25.20000,67.10163,769.36809,0.02887,2.88669,38.12792
25.30000,67.10994,771.14035,0.02902,2.90161,38.21575
25.40000,67.11831,773.35997,0.02916,2.91648,38.32575
25.50000,67.12662,774.42238,0.02929,2.92935,38.37840
25.60000,67.13492,776.93621,0.02944,2.94430,38.50298
25.70000,67.14318,778.59908,0.02959,2.95894,38.58539
25.80000,67.15161,780.77139,0.02975,2.97459,38.69304
25.90000,67.15992,782.42775,0.02989,2.98950,38.77513
26.00000,67.16823,784.50488,0.03005,3.00513,38.87806
26.10000,67.17667,786.36846,0.03021,3.02057,38.97042
26.20000,67.18497,788.09662,0.03036,3.03597,39.05606
26.30000,67.19328,789.96066,0.03051,3.05085,39.14844
26.40000,67.20165,791.97502,0.03066,3.06616,39.24826
26.50000,67.21003,793.90192,0.03081,3.09965,39.34376
26.60000,67.21833,795.19851,0.03097,3.13288,39.40801
26.70000,67.22664,798.12361,0.03112,3.16611,39.55297
26.72800,67.22897,798.12743,0.03117,3.17545,39.55316
26.82800,67.23729,799.68059,0.03130,3.20871,39.63013
26.92800,67.24566,802.20904,0.03144,3.24218,39.75544
27.02800,67.25397,802.88500,0.03160,3.27543,39.78893
27.12800,67.26228,804.83286,0.03175,3.30866,39.88547
27.22800,67.27071,806.62379,0.03191,3.34239,39.97422
27.32800,67.27896,808.49193,0.03207,3.37540,40.06680
27.42800,67.28733,810.07015,0.03222,3.40889,40.14501
27.52800,67.29570,811.67808,0.03237,3.44236,40.22470
27.62800,67.30401,813.91269,0.03254,3.47561,40.33544
27.72800,67.31232,815.04267,0.03269,3.50884,40.39144
27.82800,67.32063,817.43030,0.03285,3.54207,40.50976
27.92800,67.32895,818.97220,0.03300,3.57534,40.58617
28.02800,67.33731,821.01338,0.03316,3.60881,40.68733
28.12800,67.34563,821.85166,0.03332,3.64206,40.72887
28.22800,67.35399,823.06648,0.03346,3.67553,40.78908
28.32800,67.36231,824.81280,0.03361,3.70880,40.87562
28.42800,67.37062,826.36662,0.03377,3.74203,40.95263
28.52800,67.37899,827.94921,0.03393,3.77552,41.03105
28.62800,67.38730,829.68082,0.03409,3.80874,41.11687
28.72800,67.39567,831.12065,0.03425,3.84225,41.18822
28.82800,67.40392,832.69533,0.03456,3.87524,41.26626
28.92800,67.41229,834.43690,0.03365,3.90873,41.35257
29.02800,67.42060,835.86797,0.03416,3.94196,41.42349
29.12800,67.42891,837.80019,0.01061,3.97519,41.51924
29.22800,67.43734,838.68168,0.00100,4.00892,41.56293
29.32800,67.44559,839.80644,0.00144,4.04193,41.61867
29.42800,67.45397,841.64599,0.00142,4.07542,41.70983
29.52800,67.46239,843.60186,0.00133,4.10913,41.80676
29.62800,67.47065,844.87544,0.00157,4.14214,41.86987
29.72800,67.47895,845.96602,0.00168,4.17537,41.92392
29.82800,67.48739,847.45623,0.00166,4.20912,41.99777
29.92800,67.49558,848.81485,0.00286,4.24187,42.06510
30.02800,67.50395,850.44783,0.00073,4.27536,42.14603
30.12800,67.51238,852.13063,0.00038,4.30907,42.22942
30.22800,67.52063,853.19281,0.00075,4.34206,42.28206
30.32800,67.52894,855.22821,0.00070,4.37532,42.38293
30.42800,67.53737,855.83720,-0.00033,4.40902,42.41311
30.52800,67.54562,857.17440,-0.00077,4.44204,42.47938
30.62800,67.55399,858.84258,-0.00292,4.47552,42.56205
30.72800,67.56236,860.27374,-0.01486,4.50901,42.63298
30.82800,67.57061,860.83785,0.02255,4.54201,42.66093
30.92800,67.57899,861.94277,0.02697,4.57550,42.71569
31.02800,67.58723,863.43456,-0.00106,4.60849,42.78962
31.12800,67.59561,864.59154,-0.08644,4.64200,42.84695
31.22800,67.60404,865.83048,-0.12875,4.67569,42.90835
31.32800,67.61223,867.34314,-0.13634,4.70846,42.98331
31.42800,67.62060,868.25425,-0.11379,4.74195,43.02847
31.52800,67.62903,869.17672,-0.13702,4.77566,43.07418
31.62800,67.63722,870.14465,-0.14025,4.80845,43.12215
31.72800,67.64559,871.48249,-0.14029,4.84190,43.18845
31.82800,67.65402,872.66276,-0.14032,4.87565,43.24694
31.92800,67.66227,873.03817,-0.14033,4.90864,43.26555
32.02800,67.67058,874.59590,-0.14033,4.94189,43.34274
32.12800,67.67901,875.73333,-0.14033,4.97560,43.39911
32.22800,67.68727,877.16738,-0.14033,5.00862,43.47018
32.32800,67.69557,877.71434,-0.14033,5.04185,43.49729
32.42800,67.70395,878.56352,-0.14033,5.07534,43.53937
32.52800,67.71232,879.98640,-0.14033,5.10882,43.60988
32.62800,67.72062,881.23698,-0.14033,5.14205,43.67186
32.72800,67.72900,881.78189,-0.14033,5.17554,43.69886
32.82800,67.73730,882.45114,-0.14033,5.20876,43.73203
32.92800,67.74568,884.15574,-0.14033,5.24227,43.81651
33.02800,67.75399,884.90769,-0.14033,5.27550,43.85377
33.12800,67.76230,885.77177,-0.14033,5.30875,43.89659
33.22800,67.77061,886.88666,-0.14033,5.34198,43.95184
33.32800,67.77892,887.33966,-0.14033,5.37525,43.97429
33.42800,67.78723,888.20625,-0.14033,5.40848,44.01724
33.52800,67.79566,889.22465,-0.14034,5.44221,44.06771
33.62800,67.80397,890.28096,-0.14033,5.47544,44.12006
33.72800,67.81235,890.73954,-0.14033,5.50895,44.14278
33.82800,67.82071,892.13708,-0.14034,5.54240,44.21204
33.92800,67.82896,892.22286,-0.14034,5.57541,44.21629
34.02800,67.83728,892.59306,-0.14034,5.60866,44.23464
34.12800,67.84564,893.81598,-0.14033,5.64213,44.29524
34.22800,67.85390,895.15075,-0.14034,5.67515,44.36139
34.32800,67.86221,895.12561,-0.14034,5.70838,44.36015
34.42800,67.87064,896.03281,-0.14034,5.74211,44.40510
34.52800,67.87895,896.80972,-0.14034,5.77534,44.44360
34.62800,67.88732,897.32530,-0.14034,5.80883,44.46915
34.72800,67.89575,898.09215,-0.14034,5.84255,44.50716
34.82800,67.90407,898.26547,-0.14034,5.87582,44.51575
34.92800,67.91237,899.44005,-0.14034,5.90905,44.57396
35.02800,67.92068,899.66450,-0.14034,5.94227,44.58508
35.12800,67.92905,900.85929,-0.14034,5.97576,44.64429
35.22800,67.93736,901.35224,-0.14034,6.00899,44.66872
35.32800,67.94562,901.50563,-0.14034,6.04202,44.67632
35.42800,67.95392,902.50503,-0.14034,6.07525,44.72585
35.52800,67.96236,902.71840,-0.14034,6.10898,44.73642
35.62800,67.97060,902.89311,-0.14034,6.14197,44.74508
35.72800,67.97886,903.25540,-0.14034,6.17499,44.76303
35.82800,67.98734,903.89494,-0.14034,6.20893,44.79473
35.92800,67.99566,904.42523,-0.14034,6.24220,44.82101
36.02800,68.00397,904.50272,-0.14034,6.27543,44.82485
36.12800,68.01246,904.96624,-0.14034,6.30940,44.84782
36.22800,68.02065,904.86007,-0.14034,6.34215,44.84256
36.32800,68.02890,905.94394,-0.14034,6.37515,44.89627
36.42800,68.03739,906.12592,-0.14034,6.40913,44.90529
36.52800,68.04558,906.72057,-0.14034,6.44187,44.93476
36.62800,68.05390,906.88458,-0.14034,6.47514,44.94289
36.72800,68.06232,906.85692,-0.14034,6.50884,44.94152
36.82800,68.07052,907.81813,-0.14034,6.54162,44.98915
36.92800,68.07894,907.29557,-0.14034,6.57533,44.96326
37.02800,68.08738,907.69790,-0.14034,6.60906,44.98320
37.12800,68.09562,907.92896,-0.14034,6.64205,44.99464
37.22800,68.10400,908.21069,-0.14035,6.67556,45.00861
37.32800,68.11236,908.56999,-0.14034,6.70901,45.02641
37.42800,68.12056,908.67924,-0.14034,6.74178,45.03183
37.52800,68.12899,907.62870,-0.14034,6.77551,44.97977
37.62800,68.13730,908.60901,-0.14034,6.80874,45.02835
37.72800,68.14561,909.55254,-0.14034,6.84201,45.07511
37.82800,68.15410,909.42308,-0.14034,6.87594,45.06869
37.92800,68.16229,908.78289,-0.14034,6.90873,45.03696
38.02800,68.17060,909.06108,-0.14035,6.94196,45.05075
38.12800,68.17909,909.54211,-0.14034,6.97593,45.07459
38.22800,68.18734,909.73396,-0.14035,7.00892,45.08410
38.32800,68.19560,909.88595,-0.14034,7.04194,45.09163
38.42800,68.20403,910.44214,-0.14034,7.07566,45.11919
38.52800,68.21221,909.98504,-0.14035,7.10840,45.09654
38.62800,68.22058,909.76087,-0.14034,7.14189,45.08543
38.72800,68.22901,909.69494,-0.14034,7.17561,45.08216
38.82800,68.23721,909.78006,-0.14035,7.20839,45.08638
38.92800,68.24558,909.43836,-0.14035,7.24186,45.06945
39.02800,68.25401,909.55766,-0.14035,7.27559,45.07536
39.12800,68.26226,909.39961,-0.14035,7.30858,45.06753
39.22800,68.27057,909.02010,-0.14035,7.34185,45.04872
39.32800,68.27900,909.40604,-0.14035,7.37554,45.06784
39.42800,68.28725,908.99002,-0.14034,7.40857,45.04723
39.52800,68.29562,909.19491,-0.14035,7.44204,45.05738
39.62800,68.30399,908.81782,-0.14035,7.47553,45.03870
39.72800,68.31225,908.73949,-0.14034,7.50854,45.03481
39.82800,68.32067,908.65567,-0.14035,7.54223,45.03066
39.92800,68.32893,908.36454,-0.14035,7.57526,45.01623
40.02800,68.33723,908.38457,-0.14035,7.60849,45.01722
40.12800,68.34573,907.77995,-0.14035,7.64246,44.98726
40.22800,68.35391,907.78293,-0.14035,7.67521,44.98741
40.32800,68.36229,907.32006,-0.14034,7.70871,44.96447
40.42800,68.37071,907.82000,-0.14035,7.74241,44.98925
40.52800,68.37903,906.89678,-0.14035,7.77568,44.94349
40.62800,68.38728,906.95592,-0.14035,7.80866,44.94642
40.72800,68.39571,906.41100,-0.14035,7.84240,44.91942
40.82800,68.40396,906.17537,-0.14035,7.87540,44.90774
40.92800,68.41227,906.13086,-0.14035,7.90863,44.90554
41.02800,68.42070,905.38552,-0.14035,7.94236,44.86860
41.12800,68.42895,905.19395,-0.14035,7.97535,44.85910
41.22800,68.43727,905.03832,-0.14035,8.00862,44.85139
41.32800,68.44569,904.15273,-0.14035,8.04231,44.80751
41.42800,68.45395,903.52017,-0.14035,8.07534,44.77616
41.52800,68.46225,903.82891,-0.14035,8.10857,44.79146
41.62800,68.47063,903.37358,-0.14035,8.14206,44.76889
41.72800,68.47893,902.88455,-0.14035,8.17529,44.74466
41.82800,68.48725,902.46042,-0.14035,8.20855,44.72364
41.92800,68.49568,901.86549,-0.14035,8.24227,44.69416
42.02800,68.50387,901.79294,-0.14035,8.27501,44.69056
42.12800,68.51236,901.38540,-0.14035,8.30899,44.67036
42.22800,68.52061,901.10116,-0.14035,8.34198,44.65628
42.32800,68.52892,900.29575,-0.14035,8.37524,44.61636
42.42800,68.53741,900.00136,-0.14035,8.40918,44.60177
42.52800,68.54566,899.19390,-0.14035,8.44221,44.56176
42.62800,68.55397,898.98538,-0.14035,8.47543,44.55143
42.72800,68.56240,898.52810,-0.14035,8.50917,44.52876
42.82800,68.57059,898.55278,-0.14035,8.54193,44.52999
42.92800,68.57891,897.11277,-0.14036,8.57518,44.45862
43.02800,68.58740,896.61125,-0.14035,8.60914,44.43377
43.12800,68.59559,896.21730,-0.14035,8.64192,44.41425
43.22800,68.60390,895.70675,-0.14035,8.67515,44.38894
43.32800,68.61245,894.32606,-0.14035,8.70935,44.32052
43.42800,68.62064,894.65287,-0.14035,8.74211,44.33672
43.52800,68.62901,894.25566,-0.14035,8.77558,44.31703
43.62800,68.63744,893.64760,-0.14035,8.80931,44.28690
43.72800,68.64557,893.01048,-0.14035,8.84182,44.25533
43.82800,68.65394,892.48950,-0.14035,8.87533,44.22950
43.92800,68.66231,891.13023,-0.14035,8.90880,44.16214
44.02800,68.67051,891.18378,-0.14035,8.94158,44.16480
44.12800,68.67899,890.06200,-0.14035,8.97552,44.10920
44.22800,68.68731,889.58479,-0.14035,9.00878,44.08556
44.32800,68.69555,889.24672,-0.14035,9.04177,44.06880
44.42800,68.70405,887.68722,-0.14035,9.07575,43.99152
44.52800,68.71230,887.66972,-0.14035,9.10873,43.99065
44.62800,68.72060,886.48358,-0.14036,9.14196,43.93187
44.72800,68.72910,885.77466,-0.14035,9.17594,43.89674
44.82800,68.73728,885.49573,-0.14035,9.20868,43.88291
44.92800,68.74554,884.62858,-0.14035,9.24171,43.83994
45.02800,68.75408,884.04864,-0.14036,9.27589,43.81120
45.12800,68.76228,883.12672,-0.14035,9.30867,43.76551
45.22800,68.77059,882.35801,-0.14035,9.34190,43.72741
45.32800,68.77914,881.76187,-0.14036,9.37612,43.69787
45.42800,68.78727,880.57639,-0.14035,9.40864,43.63912
45.52800,68.79558,879.94533,-0.14035,9.44189,43.60785
45.62800,68.80407,879.31892,-0.14035,9.47584,43.57681
45.72800,68.81220,878.57451,-0.14036,9.50835,43.53991
45.82800,68.82064,877.06111,-0.14035,9.54210,43.46491
45.92800,68.82906,876.79662,-0.14035,9.57579,43.45181
46.02800,68.83726,875.80169,-0.14035,9.60857,43.40250
46.12800,68.84568,875.22333,-0.14035,9.64229,43.37384
46.22800,68.85406,874.29844,-0.14035,9.67578,43.32800
46.32800,68.86225,873.04255,-0.14036,9.70854,43.26576
46.42800,68.87068,871.86033,-0.14035,9.74228,43.20718
46.52800,68.87905,871.76142,-0.14035,9.77575,43.20227
46.62800,68.88724,870.14763,-0.14035,9.80853,43.12230
46.72800,68.89573,869.60997,-0.14036,9.84247,43.09565
46.82800,68.90398,868.34608,-0.14036,9.87549,43.03302
46.92800,68.91229,866.95030,-0.14036,9.90872,42.96385
47.02800,68.92072,865.95286,-0.14035,9.94242,42.91442
47.12800,68.92891,864.86870,-0.14036,9.97520,42.86069
47.22800,68.93722,863.61654,-0.14035,10.00843,42.79863
47.32800,68.94571,862.75004,-0.14036,10.04240,42.75570
47.42800,68.95396,861.32437,-0.14036,10.07541,42.68504
47.52800,68.96228,860.63389,-0.14036,10.10866,42.65082
47.62800,68.97070,859.31802,-0.14035,10.14237,42.58561
47.72800,68.97890,858.77739,-0.14036,10.17515,42.55882
47.82800,68.98732,857.40620,-0.14035,10.20885,42.49087
47.92800,68.99570,855.84903,-0.14036,10.24236,42.41370
48.02800,69.00395,854.50448,-0.14036,10.27535,42.34706
48.12800,69.01226,853.21134,-0.14036,10.30858,42.28298
48.22800,69.02063,852.15028,-0.14035,10.34207,42.23040
48.32800,69.02888,850.86590,-0.14036,10.37507,42.16674
48.42800,69.03731,849.08400,-0.14035,10.40880,42.07844
48.52800,69.04568,847.76962,-0.14036,10.44228,42.01330
48.62800,69.05393,846.83662,-0.14036,10.47528,41.96706
48.72800,69.06236,845.42260,-0.14035,10.50900,41.89699
48.82800,69.07062,844.48410,-0.14036,10.54202,41.85048
48.92800,69.07892,842.74756,-0.14036,10.57525,41.76442
49.02800,69.08736,840.87234,-0.14036,10.60898,41.67149
49.12800,69.09560,839.38083,-0.14036,10.64197,41.59758
49.22800,69.10391,837.81825,-0.14036,10.67520,41.52014
49.32800,69.11241,836.56739,-0.14035,10.70917,41.45815
49.42800,69.12054,834.72161,-0.14036,10.74170,41.36668
49.52800,69.12897,833.23019,-0.14036,10.77543,41.29277
49.62800,69.13740,832.50850,-0.14036,10.80914,41.25700
49.72800,69.14559,830.10476,-0.14035,10.84193,41.13788
49.82800,69.15396,828.56212,-0.14036,10.87538,41.06143
49.92800,69.16239,826.55642,-0.14036,10.90913,40.96203
50.02800,69.17064,825.07664,-0.14035,10.94212,40.88869
50.12800,69.17895,823.45931,-0.14036,10.97537,40.80854
50.22800,69.18732,822.10982,-0.14036,11.00884,40.74167
50.32800,69.19558,820.04396,-0.14036,11.04186,40.63929
50.42800,69.20401,817.92865,-0.14036,11.07558,40.53446
50.52800,69.21237,816.32016,-0.14036,11.10903,40.45475
50.62800,69.22056,814.59023,-0.14036,11.14181,40.36901
50.72800,69.22899,812.21387,-0.14036,11.17553,40.25125
50.82800,69.23731,810.59178,-0.14036,11.20879,40.17086
50.92800,69.24567,808.86567,-0.14036,11.24225,40.08532
51.02800,69.25417,806.57583,-0.14036,11.27622,39.97184
51.12800,69.26236,804.27183,-0.14036,11.30898,39.85766
51.22800,69.27061,802.29212,-0.14036,11.34201,39.75955
51.32800,69.27904,800.84540,-0.14036,11.37570,39.68786
51.42800,69.28723,798.26089,-0.14036,11.40849,39.55978
51.52800,69.29560,796.92611,-0.14036,11.44196,39.49363
51.62800,69.30403,794.42160,-0.14036,11.47569,39.36951
51.72800,69.31228,792.06908,-0.14036,11.50868,39.25293
51.82800,69.32059,790.27042,-0.14036,11.54191,39.16379
51.92800,69.32903,787.70760,-0.14036,11.57566,39.03678
52.02800,69.33733,785.68775,-0.14036,11.60889,38.93668
52.12800,69.34565,784.19680,-0.14036,11.64214,38.86280
52.22800,69.35407,781.78504,-0.14036,11.67585,38.74327
52.32800,69.36227,779.55890,-0.14036,11.70863,38.63295
52.42800,69.37064,776.98533,-0.14036,11.74210,38.50541
52.52800,69.37901,774.93032,-0.14036,11.77559,38.40357
52.62800,69.38726,772.87750,-0.14036,11.80858,38.30184
52.72800,69.39563,771.03265,-0.14036,11.84209,38.21041
52.82800,69.40400,768.92092,-0.14036,11.87554,38.10576
52.92800,69.41225,766.86228,-0.14036,11.90855,38.00374
53.02800,69.42068,764.58142,-0.14036,11.94228,37.89071
53.12800,69.42899,762.11151,-0.14036,11.97551,37.76830
53.22800,69.43730,760.70880,-0.14036,12.00876,37.69879
53.32800,69.44573,757.49322,-0.14036,12.04247,37.53943
53.42800,69.45399,756.27984,-0.14036,12.07550,37.47930
53.52800,69.46229,754.26796,-0.14036,12.10873,37.37960
53.62800,69.47061,752.11315,-0.14036,12.14198,37.27281
53.72800,69.47891,749.92036,-0.14036,12.17521,37.16414
53.82800,69.48735,747.67587,-0.14036,12.20896,37.05291
53.92800,69.49566,746.07800,-0.14036,12.24219,36.97372
54.02800,69.50397,744.00636,-0.14036,12.27542,36.87106
54.12800,69.51228,741.13808,-0.14036,12.30867,36.72892
54.22800,69.52071,739.28507,-0.14036,12.34238,36.63708
54.32800,69.52896,737.47816,-0.14036,12.37540,36.54754
54.42800,69.53727,735.33379,-0.14036,12.40863,36.44127
54.52800,69.54558,733.23390,-0.14037,12.44188,36.33720
54.62800,69.55389,731.74885,-0.14036,12.47511,36.26361
54.72800,69.56227,730.11704,-0.14036,12.50862,36.18274
54.82800,69.57057,728.08480,-0.14036,12.54185,36.08203
54.92800,69.57889,726.65974,-0.14036,12.57510,36.01141
55.02800,69.58731,723.52611,-0.14036,12.60881,35.85611
55.12800,69.59557,722.97566,-0.14036,12.64184,35.82883
55.22800,69.60393,720.81671,-0.14036,12.67529,35.72184
55.32800,69.61236,718.88571,-0.14036,12.70900,35.62614
55.42800,69.62068,717.70735,-0.14036,12.74227,35.56775
55.52800,69.62899,715.40028,-0.14036,12.77550,35.45341
55.62800,69.63736,714.08739,-0.14036,12.80899,35.38835
55.72800,69.64561,711.98326,-0.14036,12.84198,35.28408
55.82800,69.65398,710.62492,-0.14036,12.87549,35.21676
55.92800,69.66235,709.14165,-0.14036,12.90894,35.14325
56.02800,69.67060,707.42574,-0.14036,12.94197,35.05822
56.12800,69.67897,705.44058,-0.14036,12.97544,34.95984
56.22800,69.68734,704.17929,-0.14036,13.00893,34.89733
56.32800,69.69571,701.99072,-0.14036,13.04240,34.78887
56.42800,69.70409,700.76091,-0.14036,13.07591,34.72792
56.52800,69.71240,699.54367,-0.14036,13.10914,34.66760
56.62800,69.72070,697.27707,-0.14036,13.14237,34.55527
56.72800,69.72902,695.99696,-0.14036,13.17562,34.49184
56.82800,69.73732,694.49148,-0.14036,13.20885,34.41723
56.92800,69.74558,693.32984,-0.14036,13.24187,34.35966
57.02800,69.75395,691.06426,-0.14036,13.27534,34.24738
57.12800,69.76226,690.19622,-0.14036,13.30859,34.20436
57.22800,69.77063,687.92654,-0.14036,13.34206,34.09189
57.32800,69.77900,686.63135,-0.14036,13.37557,34.02770
57.42800,69.78731,684.57490,-0.14036,13.40880,33.92579
57.52800,69.79568,683.26946,-0.14036,13.44229,33.86110
57.62800,69.80405,680.94400,-0.14036,13.47576,33.74585
57.72800,69.81224,679.84625,-0.14036,13.50851,33.69145
57.82800,69.82062,677.30588,-0.14036,13.54202,33.56555
57.92800,69.82898,674.87080,-0.14036,13.57547,33.44488
58.02800,69.83730,673.28690,-0.14036,13.60874,33.36638
58.12800,69.84560,671.68330,-0.14036,13.64197,33.28691
58.22800,69.85404,669.32961,-0.14036,13.67570,33.17027
58.32800,69.86234,666.80801,-0.14036,13.70893,33.04531
58.42800,69.87072,664.41474,-0.14036,13.74244,32.92670
58.52800,69.87908,662.18786,-0.14036,13.77589,32.81634
58.62800,69.88728,659.84540,-0.14036,13.80867,32.70026
58.72800,69.89565,656.97278,-0.14036,13.84214,32.55790
58.82800,69.90402,654.20750,-0.14036,13.87565,32.42086
58.92800,69.91233,650.98698,-0.14036,13.90888,32.26126
59.02800,69.92064,646.92157,-0.14036,13.94211,32.05978
59.12800,69.92895,642.16782,-0.14036,13.97536,31.82420
59.22800,69.93726,633.46955,-0.14036,14.00859,31.39314
59.32800,69.94564,622.88288,-0.14036,14.04210,30.86849
59.42800,69.95400,608.88473,-0.14036,14.07555,30.17478
59.52800,69.96232,584.47593,-0.14036,14.10882,28.96514
59.62800,69.97068,542.08678,-0.14036,14.14229,26.86444
59.72800,69.97894,481.11035,-0.14036,14.17532,23.84260
59.82800,69.98730,406.45716,-0.14036,14.20877,20.14298
59.92800,69.99574,55.60910,-0.14036,14.24252,2.75585
59.94000,69.99669,7.46436,-0.14036,14.24632,0.36991