File: Manufatura Aditiva/Classificação Orientação/Ensaios/Ensaios FDM/Tracao_OLABI_22_05_2018_FDM_XY1.is_metal_RawData/Specimen_RawData_5.csv
Time,Extension,Load,Strain 1,Tensile strain,Tensile stress
(sec),(mm),(N),(mm/mm),(%),(MPa)
0.00000,0.00006,19.11425,0.00096,0.09610,0.94567
0.10000,0.00419,20.79924,0.00099,0.09902,1.02903
0.20000,0.01381,24.65095,0.00112,0.11200,1.21960
0.30000,0.02356,28.99022,0.00126,0.12584,1.43428
0.40000,0.03270,32.89950,0.00139,0.13924,1.62769
0.50000,0.04143,37.39968,0.00152,0.15199,1.85033
0.60000,0.04992,41.27281,0.00165,0.16462,2.04195
0.70000,0.05835,44.82630,0.00176,0.17636,2.21776
0.80000,0.06673,47.97204,0.00189,0.18885,2.37340
0.90000,0.07498,52.58447,0.00201,0.20106,2.60159
1.00000,0.08323,56.17749,0.00213,0.21336,2.77936
1.10000,0.09172,59.55576,0.00226,0.22596,2.94650
1.20000,0.09997,63.05311,0.00238,0.23787,3.11953
1.30000,0.10834,67.34544,0.00250,0.24987,3.33189
1.40000,0.11677,70.60377,0.00263,0.26312,3.49309
1.50000,0.12502,74.16441,0.00276,0.27555,3.66925
1.60000,0.13339,78.30022,0.00288,0.28802,3.87387
1.70000,0.14182,81.59429,0.00301,0.30093,4.03684
1.80000,0.14995,84.77559,0.00313,0.31269,4.19424
1.90000,0.15832,88.42442,0.00325,0.32534,4.37476
2.00000,0.16669,91.58801,0.00338,0.33767,4.53128
2.10000,0.17494,95.66935,0.00350,0.35032,4.73320
2.20000,0.18337,99.04559,0.00363,0.36275,4.90024
2.30000,0.19169,102.88303,0.00376,0.37561,5.09009
2.40000,0.19994,106.08733,0.00388,0.38793,5.24863
2.50000,0.20831,110.30243,0.00401,0.40113,5.45717
2.60000,0.21662,113.96587,0.00414,0.41403,5.63841
2.70000,0.22493,117.31038,0.00426,0.42630,5.80388
2.80000,0.23336,119.92916,0.00439,0.43852,5.93344
2.90000,0.24167,124.33734,0.00451,0.45124,6.15154
3.00000,0.24992,127.67578,0.00464,0.46370,6.31671
3.10000,0.25835,131.05402,0.00477,0.47730,6.48384
3.20000,0.26666,133.97500,0.00490,0.48977,6.62836
3.30000,0.27497,137.25545,0.00503,0.50275,6.79066
3.40000,0.28340,141.16978,0.00515,0.51543,6.98432
3.50000,0.29165,144.57892,0.00528,0.52788,7.15298
3.60000,0.29996,148.00482,0.00539,0.53873,7.32248
3.70000,0.30839,150.63620,0.00551,0.55057,7.45266
3.80000,0.31676,154.35152,0.00564,0.56399,7.63648
3.90000,0.32502,157.13798,0.00576,0.57618,7.77434
4.00000,0.33339,161.75255,0.00589,0.58921,8.00264
4.10000,0.34164,164.79265,0.00602,0.60233,8.15305
4.20000,0.35001,167.16737,0.00615,0.61459,8.27054
4.30000,0.35832,171.20063,0.00628,0.62795,8.47008
4.40000,0.36663,174.25785,0.00641,0.64065,8.62133
4.50000,0.37494,178.57937,0.00653,0.65326,8.83514
4.60000,0.38325,182.06306,0.00667,0.66652,9.00749
4.70000,0.39162,185.74293,0.00679,0.67940,9.18955
4.80000,0.39999,188.56155,0.00692,0.69208,9.32900
4.90000,0.40836,191.62395,0.00705,0.70537,9.48051
5.00000,0.41667,195.31476,0.00718,0.71793,9.66312
5.10000,0.42498,198.75679,0.00732,0.73166,9.83341
5.20000,0.43329,201.97956,0.00744,0.74360,9.99285
5.30000,0.44161,205.49668,0.00756,0.75644,10.16686
5.40000,0.45004,209.04497,0.00770,0.76974,10.34241
5.50000,0.45835,212.36257,0.00782,0.78247,10.50655
5.60000,0.46666,216.06449,0.00796,0.79621,10.68970
5.70000,0.47503,218.52287,0.00808,0.80845,10.81133
5.80000,0.48328,222.80400,0.00821,0.82146,11.02313
5.90000,0.49165,226.01364,0.00834,0.83443,11.18193
6.00000,0.50002,228.71981,0.00847,0.84703,11.31582
6.10000,0.50833,232.88887,0.00861,0.86073,11.52208
6.20000,0.51670,235.36303,0.00873,0.87346,11.64449
6.30000,0.52501,239.86164,0.00887,0.88657,11.86705
6.40000,0.53326,243.07203,0.00899,0.89931,12.02589
6.50000,0.54163,246.83746,0.00913,0.91259,12.21218
6.60000,0.55000,249.68146,0.00926,0.92621,12.35289
6.70000,0.55831,252.95352,0.00939,0.93862,12.51477
6.80000,0.56668,255.98169,0.00952,0.95189,12.66459
6.90000,0.57494,260.11348,0.00965,0.96524,12.86901
7.00000,0.58331,263.11078,0.00978,0.97783,13.01730
7.10000,0.59174,267.01009,0.00991,0.99117,13.21021
7.20000,0.59999,270.15379,0.01004,1.00431,13.36575
7.30000,0.60830,273.75093,0.01017,1.01744,13.54371
7.40000,0.61673,276.85494,0.01031,1.03066,13.69728
7.50000,0.62492,279.98313,0.01044,1.04408,13.85205
7.60000,0.63323,284.02521,0.01057,1.05693,14.05203
7.70000,0.64172,286.68109,0.01070,1.07019,14.18343
7.80000,0.64997,290.38547,0.01083,1.08282,14.36670
7.90000,0.65828,293.81765,0.01096,1.09599,14.53650
8.00000,0.66677,297.42743,0.01109,1.10944,14.71510
8.10000,0.67496,301.06283,0.01123,1.12273,14.89496
8.20000,0.68327,303.21591,0.01135,1.13520,15.00148
8.30000,0.69176,307.56388,0.01149,1.14883,15.21659
8.40000,0.69996,309.23458,0.01159,1.15886,15.29925
8.50000,0.70833,312.68429,0.01172,1.17207,15.46992
8.60000,0.71676,315.99284,0.01185,1.18512,15.63361
8.70000,0.72495,318.64920,0.01198,1.19829,15.76504
8.80000,0.73338,322.51379,0.01211,1.21143,15.95623
8.90000,0.74163,325.17167,0.01225,1.22470,16.08773
9.00000,0.74988,328.99322,0.01238,1.23768,16.27680
9.10000,0.75837,332.20083,0.01252,1.25152,16.43550
9.20000,0.76674,335.83429,0.01264,1.26438,16.61526
9.30000,0.77499,338.03608,0.01277,1.27695,16.72419
9.40000,0.78348,341.82495,0.01291,1.29059,16.91165
9.50000,0.79161,345.05574,0.01304,1.30432,17.07149
9.60000,0.79992,348.81132,0.01318,1.31755,17.25729
9.70000,0.80841,351.30989,0.01331,1.33071,17.38091
9.80000,0.81666,354.49383,0.01344,1.34380,17.53843
9.90000,0.82492,357.40039,0.01356,1.35595,17.68223
10.00000,0.83335,359.85711,0.01368,1.36818,17.80378
10.10000,0.84166,363.74286,0.01382,1.38152,17.99603
10.20000,0.84997,365.82183,0.01394,1.39445,18.09888
10.30000,0.85840,369.47785,0.01408,1.40780,18.27976
10.40000,0.86665,372.50074,0.01421,1.42099,18.42932
10.50000,0.87496,376.16421,0.01434,1.43419,18.61057
10.60000,0.88333,378.95020,0.01448,1.44781,18.74840
10.70000,0.89164,381.94729,0.01461,1.46107,18.89668
10.80000,0.90001,384.79054,0.01474,1.47378,19.03735
10.90000,0.90832,388.11758,0.01487,1.48734,19.20195
11.00000,0.91663,391.61439,0.01500,1.50040,19.37496
11.10000,0.92506,394.29204,0.01514,1.51406,19.50743
11.20000,0.93331,397.99544,0.01527,1.52655,19.69066
11.30000,0.94168,400.53334,0.01540,1.54048,19.81622
11.40000,0.95006,404.09155,0.01554,1.55400,19.99226
11.50000,0.95825,406.93167,0.01567,1.56725,20.13277
11.60000,0.96662,410.45411,0.01580,1.58030,20.30704
11.70000,0.97499,413.01250,0.01594,1.59397,20.43362
11.80000,0.98330,416.18068,0.01607,1.60705,20.59036
11.90000,0.99155,419.34294,0.01620,1.62023,20.74681
12.00000,1.00004,422.48671,0.01634,1.63376,20.90235
12.10000,1.00835,425.06903,0.01647,1.64687,21.03011
12.20000,1.01660,428.16047,0.01660,1.66019,21.18306
12.30000,1.02509,431.15537,0.01672,1.67169,21.33123
12.40000,1.03334,433.58449,0.01684,1.68359,21.45141
12.50000,1.04165,436.43024,0.01697,1.69660,21.59220
12.60000,1.05008,439.90589,0.01710,1.71040,21.76416
12.70000,1.05833,442.58651,0.01724,1.72363,21.89678
12.80000,1.06664,445.35217,0.01737,1.73705,22.03361
12.90000,1.07496,448.21142,0.01751,1.75080,22.17507
13.00000,1.08327,451.18597,0.01764,1.76365,22.32224
13.10000,1.09164,454.37110,0.01777,1.77718,22.47982
13.20000,1.10001,457.25517,0.01790,1.79048,22.62251
13.30000,1.10832,460.43675,0.01804,1.80370,22.77991
13.40000,1.11675,463.17913,0.01817,1.81727,22.91559
13.50000,1.12500,465.84411,0.01831,1.83087,23.04744
13.60000,1.13331,468.88632,0.01844,1.84437,23.19795
13.70000,1.14174,471.89598,0.01858,1.85793,23.34686
13.80000,1.14999,475.62891,0.01871,1.87127,23.53154
13.90000,1.15818,477.95661,0.01885,1.88487,23.64670
14.00000,1.16667,481.49219,0.01898,1.89801,23.82162
14.10000,1.17492,484.36671,0.01912,1.91177,23.96384
14.20000,1.18323,487.53289,0.01925,1.92507,24.12049
14.30000,1.19172,489.72601,0.01939,1.93903,24.22899
14.40000,1.19998,493.39361,0.01953,1.95279,24.41044
14.50000,1.20829,495.33644,0.01966,1.96638,24.50656
14.60000,1.21678,498.82885,0.01980,1.97976,24.67935
14.70000,1.22497,501.35716,0.01993,1.99341,24.80444
14.80000,1.23328,504.60612,0.02006,2.00632,24.96518
14.90000,1.24171,507.13862,0.02020,2.02013,25.09047
15.00000,1.24996,510.02540,0.02034,2.03397,25.23329
15.10000,1.25833,513.13578,0.02048,2.04775,25.38718
15.20000,1.26670,515.76751,0.02061,2.06119,25.51738
15.30000,1.27495,518.73480,0.02075,2.07456,25.66419
15.40000,1.28332,521.97766,0.02089,2.08865,25.82463
15.50000,1.29169,524.25922,0.02102,2.10182,25.93750
15.60000,1.29994,527.09067,0.02115,2.11536,26.07759
15.70000,1.30837,530.12036,0.02129,2.12897,26.22748
15.80000,1.31668,532.91093,0.02143,2.14259,26.36554
15.90000,1.32494,535.85176,0.02155,2.15469,26.51104
16.00000,1.33337,537.94589,0.02167,2.16655,26.61465
16.10000,1.34162,540.89320,0.02180,2.17995,26.76046
16.20000,1.34993,543.02956,0.02193,2.19341,26.86616
16.30000,1.35842,545.95149,0.02208,2.20762,27.01072
16.40000,1.36661,549.42467,0.02221,2.22096,27.18255
16.50000,1.37492,551.84141,0.02235,2.23487,27.30212
16.60000,1.38347,554.39197,0.02249,2.24867,27.42831
16.70000,1.39166,557.25160,0.02263,2.26260,27.56979
16.80000,1.40003,560.22741,0.02276,2.27605,27.71702
16.90000,1.40840,562.66352,0.02290,2.29010,27.83754
17.00000,1.41665,565.76100,0.02304,2.30363,27.99079
17.10000,1.42496,567.68474,0.02318,2.31751,28.08596
17.20000,1.43339,570.88761,0.02331,2.33143,28.24442
17.30000,1.44158,573.24772,0.02345,2.34514,28.36119
17.40000,1.44995,575.55083,0.02357,2.35711,28.47514
17.50000,1.45833,578.60049,0.02371,2.37121,28.62602
17.60000,1.46664,581.14715,0.02385,2.38511,28.75201
17.70000,1.47501,584.26978,0.02399,2.39904,28.90650
17.80000,1.48338,586.07324,0.02413,2.41259,28.99573
17.90000,1.49163,589.51466,0.02426,2.42608,29.16599
18.00000,1.50000,592.16358,0.02440,2.43981,29.29704
18.10000,1.50825,594.36942,0.02454,2.45353,29.40618
18.20000,1.51662,596.79612,0.02467,2.46747,29.52624
18.30000,1.52499,599.32913,0.02482,2.48157,29.65156
18.40000,1.53318,602.36664,0.02495,2.49528,29.80184
18.50000,1.54161,604.51129,0.02509,2.50920,29.90794
18.60000,1.55004,607.30046,0.02523,2.52335,30.04593
18.70000,1.55835,610.07584,0.02537,2.53701,30.18325
18.80000,1.56666,612.62427,0.02551,2.55118,30.30933
18.90000,1.57509,614.80636,0.02565,2.56487,30.41729
19.00000,1.58335,617.19045,0.02579,2.57931,30.53524
19.10000,1.59166,619.65776,0.02593,2.59330,30.65731
19.20000,1.60009,622.44432,0.02607,2.60714,30.79517
19.30000,1.60834,625.08923,0.02622,2.62151,30.92603
19.40000,1.61665,627.65232,0.02635,2.63510,31.05284
19.50000,1.62502,629.36540,0.02646,2.64577,31.13759
19.60000,1.63333,631.62851,0.02660,2.65974,31.24956
19.70000,1.64170,634.18662,0.02674,2.67358,31.37612
19.80000,1.65007,636.59693,0.02688,2.68755,31.49537
19.90000,1.65838,638.93343,0.02702,2.70201,31.61096
20.00000,1.66675,642.06123,0.02716,2.71596,31.76571
20.10000,1.67506,643.95107,0.02730,2.73017,31.85921
20.20000,1.68331,646.85154,0.02744,2.74407,32.00271
20.30000,1.69162,648.99488,0.02758,2.75820,32.10875
20.40000,1.69987,651.64873,0.02772,2.77231,32.24005
20.50000,1.70825,654.13243,0.02787,2.78669,32.36293
20.60000,1.71668,656.27098,0.02801,2.80086,32.46873
20.70000,1.72493,658.99915,0.02815,2.81475,32.60371
20.80000,1.73330,661.46669,0.02828,2.82850,32.72579
20.90000,1.74173,663.68850,0.02843,2.84305,32.83571
21.00000,1.74998,666.75600,0.02857,2.85684,32.98747
21.10000,1.75829,668.59289,0.02871,2.87136,33.07835
21.20000,1.76672,671.31454,0.02886,2.88565,33.21301
21.30000,1.77491,673.39451,0.02900,2.90008,33.31591
21.40000,1.78328,675.79979,0.02914,2.91428,33.43491
21.50000,1.79171,678.91390,0.02929,2.92873,33.58898
21.60000,1.79996,680.78074,0.02943,2.94341,33.68134
21.70000,1.80833,683.44865,0.02957,2.95724,33.81334
21.80000,1.81670,685.90809,0.02971,2.97145,33.93501
21.90000,1.82501,688.32585,0.02986,2.98631,34.05463
22.00000,1.83339,690.32572,0.03001,3.00088,34.15358
22.10000,1.84176,692.32793,0.03016,3.01587,34.25263
22.20000,1.85007,695.20692,0.03030,3.03005,34.39507
22.30000,1.85838,697.49127,0.03045,3.06329,34.50809
22.40000,1.86669,699.56719,0.03059,3.09654,34.61079
22.50000,1.87494,701.94984,0.03073,3.12954,34.72867
22.50200,1.87512,701.98937,0.03074,3.13026,34.73063
22.60200,1.88355,704.05053,0.03089,3.16398,34.83260
22.70200,1.89186,706.37013,0.03103,3.19722,34.94736
22.80200,1.90011,708.40488,0.03118,3.23023,35.04803
22.90200,1.90854,710.92616,0.03133,3.26395,35.17277
23.00200,1.91679,712.28952,0.03147,3.29695,35.24023
23.10200,1.92510,714.73829,0.03160,3.33019,35.36138
23.20200,1.93359,715.97355,0.03172,3.36415,35.42249
23.30200,1.94184,718.17590,0.03185,3.39716,35.53145
23.40200,1.95009,719.77833,0.03200,3.43016,35.61073
23.50200,1.95858,722.51810,0.03215,3.46412,35.74628
23.60200,1.96678,724.40100,0.03229,3.49689,35.83944
23.70200,1.97515,726.70449,0.03244,3.53037,35.95340
23.80200,1.98352,728.78576,0.03259,3.56385,36.05637
23.90200,1.99183,731.62494,0.03274,3.59709,36.19684
24.00200,2.00020,733.51692,0.03289,3.63058,36.29044
24.10200,2.00857,735.26679,0.03303,3.66406,36.37701
24.20200,2.01694,737.14415,0.03319,3.69754,36.46990
24.30200,2.02519,739.05527,0.03333,3.73054,36.56445
24.40200,2.03350,741.67452,0.03348,3.76379,36.69403
24.50200,2.04181,743.26824,0.03363,3.79703,36.77288
24.60200,2.05018,745.28228,0.03378,3.83051,36.87253
24.70200,2.05849,747.90097,0.03393,3.86375,37.00209
24.80200,2.06680,749.64645,0.03408,3.89700,37.08844
24.90200,2.07517,751.64279,0.03423,3.93048,37.18721
25.00200,2.08348,753.93431,0.03439,3.96372,37.30058
25.10200,2.09180,755.71514,0.03453,3.99696,37.38869
25.20200,2.10023,757.43422,0.03469,4.03069,37.47374
25.30200,2.10842,759.66902,0.03484,4.06345,37.58430
25.40200,2.11679,760.84351,0.03499,4.09693,37.64241
25.50200,2.12516,763.75213,0.03514,4.13041,37.78632
25.60200,2.13341,764.73700,0.03529,4.16342,37.83504
25.70200,2.14178,766.65324,0.03554,4.19690,37.92985
25.80200,2.15009,768.31570,0.03558,4.23014,38.01210
25.90200,2.15840,770.81900,0.03547,4.26339,38.13595
26.00200,2.16677,772.46623,0.03578,4.29687,38.21744
26.10200,2.17514,774.91947,0.03676,4.33035,38.33881
26.20200,2.18351,776.47422,0.03685,4.36383,38.41574
26.30200,2.19182,777.84890,0.03664,4.39708,38.48375
26.40200,2.20019,779.80398,0.02804,4.43056,38.58047
26.50200,2.20856,781.23398,-0.00165,4.46404,38.65122
26.60200,2.21687,782.32381,-0.00153,4.49728,38.70514
26.70200,2.22519,784.61161,-0.00065,4.53053,38.81833
26.80200,2.23350,786.79686,0.00064,4.56377,38.92645
26.90200,2.24187,788.02090,0.00105,4.59725,38.98700
27.00200,2.25018,790.51238,0.00107,4.63050,39.11027
27.10200,2.25849,791.77264,0.00088,4.66374,39.17262
27.20200,2.26692,793.91170,0.00085,4.69746,39.27845
27.30200,2.27517,794.50998,0.00181,4.73046,39.30805
27.40200,2.28354,796.03773,0.00256,4.76395,39.38363
27.50200,2.29191,797.99043,0.00039,4.79743,39.48024
27.60200,2.30022,799.89200,0.00090,4.83067,39.57432
27.70200,2.30853,801.28480,0.00149,4.86391,39.64323
27.80200,2.31684,802.72723,0.00291,4.89716,39.71459
27.90200,2.32515,804.90252,0.00355,4.93040,39.82221
28.00200,2.33352,806.53410,0.00368,4.96388,39.90294
28.10200,2.34183,808.16839,0.00358,4.99712,39.98379
28.20200,2.35015,809.59648,0.00335,5.03037,40.05445
28.30200,2.35846,811.65330,0.00339,5.06361,40.15621
28.40200,2.36683,812.60139,0.00333,5.09709,40.20311
28.50200,2.37520,813.78249,0.00277,5.13057,40.26155
28.60200,2.38345,816.38973,0.00221,5.16358,40.39054
28.70200,2.39182,817.23286,-0.01320,5.19706,40.43225
28.80200,2.40013,818.91222,-0.02782,5.23030,40.51534
28.90200,2.40850,820.42757,-0.03011,5.26379,40.59031
29.00200,2.41681,822.22382,-0.03012,5.29703,40.67918
29.10200,2.42512,823.13651,-0.03117,5.33027,40.72433
29.20200,2.43349,824.78747,-0.03309,5.36375,40.80602
29.30200,2.44180,825.92275,-0.04307,5.39700,40.86218
29.40200,2.45017,827.56924,-0.04863,5.43048,40.94364
29.50200,2.45860,828.34950,-0.13754,5.46420,40.98224
29.60200,2.46685,829.79640,-0.13473,5.49720,41.05383
29.70200,2.47517,831.39064,-0.13482,5.53045,41.13270
29.80200,2.48354,832.55107,-0.13483,5.56393,41.19011
29.90200,2.49179,834.33753,-0.13483,5.59693,41.27850
30.00200,2.50010,835.67193,-0.13483,5.63017,41.34452
30.10200,2.50859,836.44614,-0.13483,5.66413,41.38282
30.20200,2.51684,838.21807,-0.13483,5.69714,41.47049
30.30200,2.52515,838.99312,-0.13483,5.73038,41.50883
30.40200,2.53352,840.82289,-0.13483,5.76386,41.59936
30.50200,2.54183,842.28395,-0.13483,5.79711,41.67165
30.60200,2.55020,843.58444,-0.13483,5.83059,41.73598
30.70200,2.55857,844.24019,-0.13483,5.86407,41.76843
30.80200,2.56682,845.78097,-0.13484,5.89707,41.84466
30.90200,2.57519,847.36301,-0.13484,5.93056,41.92293
31.00200,2.58344,848.44194,-0.13483,5.96356,41.97631
31.10200,2.59181,849.26831,-0.13483,5.99704,42.01719
31.20200,2.60019,851.43168,-0.13484,6.03053,42.12423
31.30200,2.60844,851.27810,-0.13484,6.06353,42.11663
31.40200,2.61681,852.24519,-0.13484,6.09701,42.16447
31.50200,2.62518,853.92771,-0.13484,6.13049,42.24771
31.60200,2.63343,854.83864,-0.13484,6.16350,42.29278
31.70200,2.64174,856.05765,-0.13484,6.19674,42.35309
31.80200,2.65017,857.00182,-0.13484,6.23046,42.39981
31.90200,2.65848,858.57715,-0.13484,6.26370,42.47775
32.00200,2.66679,859.56715,-0.13484,6.29695,42.52672
32.10200,2.67516,860.39146,-0.13484,6.33043,42.56750
32.20200,2.68341,861.33610,-0.13484,6.36343,42.61424
32.30200,2.69172,862.10789,-0.13484,6.39668,42.65243
32.40200,2.70015,863.42460,-0.13484,6.43040,42.71757
32.50200,2.70852,864.53380,-0.13484,6.46388,42.77245
32.60200,2.71683,865.84846,-0.13484,6.49712,42.83749
32.70200,2.72520,866.97396,-0.13484,6.53060,42.89317
32.80200,2.73352,867.44428,-0.13484,6.56385,42.91644
32.90200,2.74189,868.28312,-0.13484,6.59733,42.95794
33.00200,2.75020,869.37658,-0.13484,6.63057,43.01204
33.10200,2.75857,869.49244,-0.13484,6.66405,43.01777
33.20200,2.76682,870.37487,-0.13485,6.69706,43.06143
33.30200,2.77513,871.66429,-0.13484,6.73030,43.12523
33.40200,2.78350,871.59574,-0.13484,6.76378,43.12183
33.50200,2.79181,872.66304,-0.13485,6.79703,43.17464
33.60200,2.80018,873.56661,-0.13484,6.83051,43.21934
33.70200,2.80849,874.09336,-0.13484,6.86375,43.24540
33.80200,2.81692,875.60695,-0.13485,6.89747,43.32029
33.90200,2.82517,875.40261,-0.13485,6.93048,43.31018
34.00200,2.83348,876.92132,-0.13484,6.96372,43.38531
34.10200,2.84185,877.70550,-0.13484,6.99720,43.42411
34.20200,2.85011,877.96850,-0.13485,7.03021,43.43712
34.30200,2.85842,879.21983,-0.13485,7.06345,43.49903
34.40200,2.86685,880.45718,-0.13485,7.09717,43.56025
34.50200,2.87516,880.26635,-0.13485,7.13041,43.55081
34.60200,2.88353,881.52280,-0.13485,7.16389,43.61297
34.70200,2.89190,881.17756,-0.13485,7.19738,43.59589
34.80200,2.90021,882.46642,-0.13485,7.23062,43.65966
34.90200,2.90858,883.06554,-0.13485,7.26410,43.68930
35.00200,2.91689,883.56473,-0.13485,7.29735,43.71399
35.10200,2.92520,884.05199,-0.13485,7.33059,43.73810
35.20200,2.93351,884.68231,-0.13485,7.36383,43.76929
35.30200,2.94182,885.18439,-0.13485,7.39707,43.79412
35.40200,2.95019,885.94500,-0.13485,7.43056,43.83176
35.50200,2.95850,886.21899,-0.13485,7.46380,43.84531
35.60200,2.96681,887.11716,-0.13485,7.49704,43.88975
35.70200,2.97501,887.11130,-0.13485,7.52981,43.88946
35.80200,2.98350,887.96690,-0.13485,7.56377,43.93179
35.90200,2.99187,888.34120,-0.13485,7.59725,43.95031
36.00200,3.00018,888.97226,-0.13485,7.63049,43.98153
36.10200,3.00867,889.01846,-0.13485,7.66445,43.98381
36.20200,3.01680,889.85041,-0.13485,7.69698,44.02497
36.30200,3.02511,889.90163,-0.13485,7.73022,44.02751
36.40200,3.03360,890.36012,-0.13485,7.76418,44.05019
36.50200,3.04179,890.49973,-0.13485,7.79695,44.05710
36.60200,3.05010,890.98252,-0.13485,7.83019,44.08099
36.70200,3.05853,891.15705,-0.13485,7.86391,44.08962
36.80200,3.06672,891.73606,-0.13485,7.89668,44.11827
36.90200,3.07509,891.87836,-0.13485,7.93016,44.12531
37.00200,3.08358,892.19129,-0.13485,7.96412,44.14079
37.10200,3.09183,892.49238,-0.13485,7.99712,44.15569
37.20200,3.10020,892.71246,-0.13485,8.03060,44.16657
37.30200,3.10858,892.57983,-0.13485,8.06409,44.16001
37.40200,3.11677,893.64564,-0.13485,8.09685,44.21274
37.50200,3.12514,893.28783,-0.13485,8.13033,44.19504
37.60200,3.13351,894.05132,-0.13485,8.16381,44.23281
37.70200,3.14182,893.80378,-0.13486,8.19706,44.22057
37.80200,3.15025,894.26646,-0.13485,8.23078,44.24346
37.90200,3.15856,893.91107,-0.13486,8.26402,44.22588
38.00200,3.16681,894.02664,-0.13485,8.29703,44.23159
38.10200,3.17530,894.72160,-0.13485,8.33099,44.26598
38.20200,3.18355,894.13887,-0.13486,8.36399,44.23714
38.30200,3.19180,894.69282,-0.13486,8.39699,44.26455
38.40200,3.20023,894.79182,-0.13485,8.43071,44.26945
38.50200,3.20842,894.40094,-0.13485,8.46348,44.25011
38.60200,3.21679,894.22511,-0.13486,8.49696,44.24141
38.70200,3.22516,895.05808,-0.13486,8.53044,44.28262
38.80200,3.23342,894.76751,-0.13485,8.56345,44.26825
38.90200,3.24179,894.71843,-0.13486,8.59693,44.26582
39.00200,3.25022,894.76118,-0.13485,8.63065,44.26793
39.10200,3.25847,894.41529,-0.13486,8.66366,44.25082
39.20200,3.26678,894.72439,-0.13486,8.69690,44.26611
39.30200,3.27521,894.61766,-0.13486,8.73062,44.26083
39.40200,3.28346,894.73128,-0.13485,8.76362,44.26645
39.50200,3.29183,894.56551,-0.13485,8.79711,44.25825
39.60200,3.30014,893.90939,-0.13486,8.83035,44.22579
39.70200,3.30845,894.20881,-0.13485,8.86359,44.24060
39.80200,3.31682,894.52211,-0.13486,8.89707,44.25611
39.90200,3.32513,894.13458,-0.13485,8.93032,44.23693
40.00200,3.33350,893.69165,-0.13486,8.96380,44.21502
40.10200,3.34187,893.52140,-0.13486,8.99728,44.20660
40.20200,3.35012,893.59600,-0.13485,9.03028,44.21029
40.30200,3.35850,893.75060,-0.13486,9.06377,44.21793
40.40200,3.36693,893.21453,-0.13486,9.09749,44.19141
40.50200,3.37518,893.22524,-0.13486,9.13049,44.19194
40.60200,3.38349,892.78128,-0.13486,9.16373,44.16998
40.70200,3.39186,892.75530,-0.13486,9.19722,44.16869
40.80200,3.40011,892.31590,-0.13486,9.23022,44.14695
40.90200,3.40848,891.95743,-0.13486,9.26370,44.12922
41.00200,3.41685,891.93387,-0.13486,9.29718,44.12805
41.10200,3.42516,891.77005,-0.13485,9.33043,44.11995
41.20200,3.43347,891.51924,-0.13486,9.36367,44.10754
41.30200,3.44190,891.24925,-0.13486,9.39739,44.09418
41.40200,3.45015,890.62275,-0.13486,9.43040,44.06319
41.50200,3.45846,889.96133,-0.13486,9.46364,44.03046
41.60200,3.46683,889.52761,-0.13486,9.49712,44.00901
41.70200,3.47508,889.70223,-0.13486,9.53012,44.01764
41.80200,3.48346,888.90716,-0.13486,9.56361,43.97831
41.90200,3.49183,888.94796,-0.13486,9.59709,43.98033
42.00200,3.50014,888.54479,-0.13486,9.63033,43.96038
42.10200,3.50851,887.91698,-0.13486,9.66381,43.92932
42.20200,3.51682,887.74525,-0.13486,9.69706,43.92082
42.30200,3.52513,887.69682,-0.13486,9.73030,43.91843
42.40200,3.53356,887.23637,-0.13486,9.76402,43.89565
42.50200,3.54187,886.63548,-0.13486,9.79726,43.86592
42.60200,3.55018,886.25001,-0.13486,9.83051,43.84685
42.70200,3.55855,886.02621,-0.13486,9.86399,43.83577
42.80200,3.56680,885.78500,-0.13486,9.89699,43.82384
42.90200,3.57505,884.70262,-0.13486,9.93000,43.77029
43.00200,3.58360,884.87240,-0.13486,9.96420,43.77869
43.10200,3.59173,883.78154,-0.13486,9.99672,43.72472
43.20200,3.60010,883.18912,-0.13486,10.03020,43.69541
43.30200,3.60859,882.91792,-0.13486,10.06416,43.68199
43.40200,3.61685,882.64402,-0.13486,10.09717,43.66844
43.50200,3.62516,882.30679,-0.13486,10.13041,43.65176
43.60200,3.63365,881.85417,-0.13486,10.16437,43.62936
43.70200,3.64178,880.86585,-0.13486,10.19690,43.58047
43.80200,3.65015,880.46612,-0.13486,10.23038,43.56069
43.90200,3.65852,879.84614,-0.13486,10.26386,43.53002
44.00200,3.66671,879.60055,-0.13486,10.29663,43.51787
44.10200,3.67514,879.41755,-0.13486,10.33035,43.50881
44.20200,3.68351,878.04049,-0.13486,10.36383,43.44069
44.30200,3.69176,877.36044,-0.13486,10.39683,43.40704
44.40200,3.70019,877.63481,-0.13486,10.43055,43.42061
44.50200,3.70856,876.53752,-0.13486,10.46404,43.36633
44.60200,3.71675,876.28514,-0.13486,10.49680,43.35384
44.70200,3.72524,875.84797,-0.13486,10.53076,43.33221
44.80200,3.73350,875.08354,-0.13486,10.56377,43.29439
44.90200,3.74175,874.45350,-0.13486,10.59677,43.26322
45.00200,3.75030,874.51180,-0.13486,10.63097,43.26611
45.10200,3.75849,873.23710,-0.13486,10.66373,43.20304
45.20200,3.76680,872.04063,-0.13486,10.69698,43.14384
45.30200,3.77535,871.73358,-0.13486,10.73118,43.12865
45.40200,3.78348,871.26885,-0.13486,10.76370,43.10566
45.50200,3.79179,870.83671,-0.13486,10.79694,43.08428
45.60200,3.80028,869.74278,-0.13486,10.83090,43.03016
45.70200,3.80835,869.47829,-0.13486,10.86319,43.01707
45.80200,3.81684,868.74701,-0.13486,10.89715,42.98089
45.90200,3.82527,867.61666,-0.13486,10.93087,42.92497
46.00200,3.83346,867.35878,-0.13486,10.96364,42.91221
46.10200,3.84183,866.72772,-0.13486,10.99712,42.88099
46.20200,3.85020,866.55058,-0.13486,11.03060,42.87223
46.30200,3.85846,865.30745,-0.13486,11.06361,42.81072
46.40200,3.86683,864.94107,-0.13486,11.09709,42.79259
46.50200,3.87526,863.91894,-0.13486,11.13081,42.74203
46.60200,3.88345,863.20043,-0.13486,11.16357,42.70648
46.70200,3.89188,862.13378,-0.13486,11.19729,42.65371
46.80200,3.90019,862.30831,-0.13486,11.23054,42.66234
46.90200,3.90844,861.21857,-0.13486,11.26354,42.60843
47.00200,3.91687,861.34747,-0.13486,11.29726,42.61480
47.10200,3.92512,859.36319,-0.13486,11.33027,42.51663
47.20200,3.93343,858.64179,-0.13486,11.36351,42.48094
47.30200,3.94186,858.12118,-0.13486,11.39723,42.45518
47.40200,3.95011,857.75210,-0.13486,11.43023,42.43692
47.50200,3.95848,856.34673,-0.13487,11.46372,42.36739
47.60200,3.96685,856.52778,-0.13486,11.49720,42.37635
47.70200,3.97510,854.64632,-0.13486,11.53020,42.28327
47.80200,3.98347,854.06713,-0.13486,11.56368,42.25461
47.90200,3.99191,853.19998,-0.13486,11.59741,42.21171
48.00200,4.00016,852.35285,-0.13486,11.63041,42.16980
48.10200,4.00847,851.39628,-0.13486,11.66365,42.12247
48.20200,4.01684,850.81663,-0.13486,11.69713,42.09380
48.30200,4.02515,850.14040,-0.13486,11.73038,42.06034
48.40200,4.03352,849.52321,-0.13486,11.76386,42.02980
48.50200,4.04189,848.27533,-0.13486,11.79734,41.96807
48.60200,4.05014,847.37753,-0.13486,11.83034,41.92365
48.70200,4.05851,845.97114,-0.13486,11.86383,41.85407
48.80200,4.06682,845.27349,-0.13486,11.89707,41.81955
48.90200,4.07513,844.61337,-0.13487,11.93031,41.78689
49.00200,4.08356,843.27301,-0.13486,11.96403,41.72058
49.10200,4.09181,842.95161,-0.13486,11.99704,41.70468
49.20200,4.10012,841.69721,-0.13486,12.03028,41.64262
49.30200,4.10855,840.84887,-0.13486,12.06400,41.60064
49.40200,4.11675,839.93757,-0.13486,12.09677,41.55556
49.50200,4.12512,838.39390,-0.13487,12.13025,41.47919
49.60200,4.13355,837.94985,-0.13487,12.16397,41.45722
49.70200,4.14180,836.59887,-0.13487,12.19697,41.39038
49.80200,4.15017,835.36133,-0.13486,12.23046,41.32915
49.90200,4.15860,834.40319,-0.13486,12.26418,41.28175
50.00200,4.16679,833.40248,-0.13486,12.29694,41.23224
50.10200,4.17516,831.84671,-0.13487,12.33042,41.15527
50.20200,4.18359,831.22440,-0.13487,12.36415,41.12448
50.30200,4.19178,830.31906,-0.13486,12.39691,41.07969
50.40200,4.20015,828.81395,-0.13486,12.43039,41.00522
50.50200,4.20852,828.05092,-0.13487,12.46387,40.96747
50.60200,4.21671,826.75032,-0.13487,12.49664,40.90313
50.70200,4.22514,825.25155,-0.13486,12.53036,40.82897
50.80200,4.23357,824.63287,-0.13487,12.56408,40.79837
50.90200,4.24189,822.74368,-0.13486,12.59733,40.70490
51.00200,4.25031,822.09148,-0.13486,12.63105,40.67263
51.10200,4.25857,820.56923,-0.13486,12.66405,40.59732
51.20200,4.26676,819.49923,-0.13486,12.69681,40.54438
51.30200,4.27525,818.22565,-0.13486,12.73078,40.48137
51.40200,4.28344,817.01269,-0.13487,12.76354,40.42136
51.50200,4.29175,815.32747,-0.13487,12.79678,40.33798
51.60200,4.30024,813.90860,-0.13487,12.83074,40.26778
51.70200,4.30849,812.32777,-0.13486,12.86375,40.18958
51.80200,4.31680,810.61544,-0.13487,12.89699,40.10486
51.90200,4.32523,809.49552,-0.13486,12.93071,40.04945
52.00200,4.33348,807.38971,-0.13487,12.96372,39.94527
52.10200,4.34179,806.18877,-0.13487,12.99696,39.88585
52.20200,4.35028,804.28701,-0.13487,13.03092,39.79176
52.30200,4.35847,801.85058,-0.13487,13.06368,39.67122
52.40200,4.36679,801.11315,-0.13487,13.09693,39.63474
52.50200,4.37522,799.76283,-0.13486,13.13065,39.56793
52.60200,4.38347,797.94060,-0.13486,13.16365,39.47778
52.70200,4.39184,796.20378,-0.13487,13.19713,39.39185
52.80200,4.40021,794.49704,-0.13487,13.23062,39.30741
52.90200,4.40846,793.19887,-0.13487,13.26362,39.24318
53.00200,4.41683,790.95289,-0.13487,13.29710,39.13206
53.10200,4.42520,789.30333,-0.13487,13.33058,39.05045
53.20200,4.43351,787.55859,-0.13486,13.36383,38.96413
53.30200,4.44194,785.43918,-0.13487,13.39755,38.85927
53.40200,4.45019,783.43879,-0.13486,13.43055,38.76030
53.50200,4.45844,781.85908,-0.13486,13.46355,38.68215
53.60200,4.46681,779.36305,-0.13486,13.49704,38.55866
53.70200,4.47512,777.53658,-0.13487,13.53028,38.46830
53.80200,4.48349,776.21839,-0.13487,13.56376,38.40308
53.90200,4.49186,774.28748,-0.13486,13.59724,38.30755
54.00200,4.50012,772.17985,-0.13486,13.63025,38.20327
54.10200,4.50849,769.71594,-0.13487,13.66373,38.08137
54.20200,4.51692,767.78056,-0.13487,13.69745,37.98562
54.30200,4.52517,766.14297,-0.13487,13.73045,37.90460
54.40200,4.53348,764.09923,-0.13486,13.76370,37.80349
54.50200,4.54179,762.07658,-0.13487,13.79694,37.70342
54.60200,4.55010,759.36797,-0.13487,13.83018,37.56941
54.70200,4.55847,757.70058,-0.13487,13.86366,37.48692
54.80200,4.56678,755.96198,-0.13487,13.89691,37.40090
54.90200,4.57515,753.08210,-0.13487,13.93039,37.25842
55.00200,4.58346,751.42523,-0.13487,13.96363,37.17645
55.10200,4.59177,748.65962,-0.13486,13.99688,37.03962
55.20200,4.60014,747.04336,-0.13486,14.03036,36.95966
55.30200,4.60851,745.13908,-0.13487,14.06384,36.86544
55.40200,4.61688,743.13064,-0.13487,14.09732,36.76608
55.50200,4.62520,740.99549,-0.13487,14.13057,36.66044
55.60200,4.63351,738.70048,-0.13487,14.16381,36.54689
55.70200,4.64182,736.45944,-0.13487,14.19705,36.43602
55.80200,4.65019,735.08355,-0.13487,14.23053,36.36795
55.90200,4.65856,732.34071,-0.13487,14.26402,36.23225
56.00200,4.66681,730.65879,-0.13487,14.29702,36.14904
56.10200,4.67518,728.46557,-0.13487,14.33050,36.04053
56.20200,4.68355,726.08120,-0.13487,14.36398,35.92256
56.30200,4.69186,724.46368,-0.13487,14.39723,35.84254
56.40200,4.70023,722.64364,-0.13487,14.43071,35.75249
56.50200,4.70860,720.35799,-0.13487,14.46419,35.63941
56.60200,4.71685,719.13074,-0.13487,14.49720,35.57869
56.70200,4.72522,716.87917,-0.13487,14.53068,35.46730
56.80200,4.73353,714.37061,-0.13487,14.56392,35.34319
56.90200,4.74179,713.23863,-0.13487,14.59693,35.28718
57.00200,4.75010,711.04243,-0.13487,14.63017,35.17852
57.10200,4.75841,710.01793,-0.13487,14.66341,35.12784
57.20200,4.76684,707.77969,-0.13487,14.69713,35.01710
57.30200,4.77515,705.95257,-0.13487,14.73037,34.92671
57.40200,4.78352,704.23093,-0.13487,14.76386,34.84153
57.50200,4.79189,702.28511,-0.13487,14.79734,34.74526
57.60200,4.80020,700.97772,-0.13487,14.83058,34.68058
57.70200,4.80851,699.06041,-0.13487,14.86382,34.58572
57.80200,4.81676,697.46724,-0.13487,14.89683,34.50690
57.90200,4.82519,696.60204,-0.13487,14.93055,34.46409
58.00200,4.83344,694.97065,-0.13487,14.96355,34.38338
58.10200,4.84181,692.78753,-0.13487,14.99704,34.27537
58.20200,4.85024,692.01840,-0.13487,15.03076,34.23732
58.30200,4.85849,690.22635,-0.13487,15.06376,34.14866
58.40200,4.86686,688.83086,-0.13487,15.09724,34.07962
58.50200,4.87524,687.23038,-0.13487,15.13073,34.00043
58.60200,4.88349,686.07358,-0.13487,15.16373,33.94320
58.70200,4.89186,685.04908,-0.13487,15.19721,33.89252
58.80200,4.90023,683.25051,-0.13487,15.23069,33.80353
58.90200,4.90854,682.26121,-0.13487,15.26394,33.75459
59.00200,4.91679,680.85575,-0.13487,15.29694,33.68505
59.10200,4.92516,679.38827,-0.13487,15.33042,33.61245
59.20200,4.93347,678.37490,-0.13487,15.36366,33.56231
59.30200,4.94178,677.16711,-0.13487,15.39691,33.50256
59.40200,4.95021,675.90661,-0.13487,15.43063,33.44020
59.50200,4.95846,674.40961,-0.13487,15.46363,33.36613
59.60200,4.96689,673.59898,-0.13487,15.49735,33.32603
59.70200,4.97514,671.98062,-0.13487,15.53036,33.24596
59.80200,4.98345,670.99091,-0.13487,15.56360,33.19699
59.90200,4.99188,669.79062,-0.13487,15.59732,33.13761
60.00200,5.00008,668.67126,-0.13487,15.63009,33.08223
60.10200,5.00845,666.63739,-0.13487,15.66357,32.98161
60.20200,5.01682,666.23245,-0.13487,15.69705,32.96157
60.30200,5.02507,664.64646,-0.13486,15.73005,32.88311
60.40200,5.03344,663.20319,-0.13487,15.76354,32.81170
60.50200,5.04187,661.96416,-0.13487,15.79726,32.75040
60.60200,5.05018,660.73174,-0.13487,15.83050,32.68943
60.70200,5.05855,659.11356,-0.13487,15.86398,32.60937
60.80200,5.06692,658.15095,-0.13487,15.89746,32.56174
60.90200,5.07517,656.45101,-0.13487,15.93047,32.47764
61.00200,5.08348,654.92652,-0.13487,15.96371,32.40221
61.10200,5.09179,653.12968,-0.13487,15.99696,32.31332
61.20200,5.10016,651.93851,-0.13487,16.03044,32.25438
61.30200,5.10847,650.25464,-0.13487,16.06368,32.17107
61.40200,5.11684,648.39353,-0.13487,16.09716,32.07900
61.50200,5.12510,646.66634,-0.13487,16.13017,31.99355
61.60200,5.13353,645.77851,-0.13487,16.16389,31.94962
61.70200,5.14190,643.78129,-0.13487,16.19737,31.85081
61.80200,5.15021,641.90677,-0.13487,16.23061,31.75807
61.90200,5.15852,640.28567,-0.13487,16.26386,31.67786
62.00200,5.16677,638.98703,-0.13487,16.29686,31.61362
62.10200,5.17514,637.33691,-0.13487,16.33034,31.53198
62.20200,5.18351,635.88503,-0.13487,16.36382,31.46014
62.30200,5.19182,634.46388,-0.13487,16.39707,31.38983
62.40200,5.20013,632.59834,-0.13487,16.43031,31.29754
62.50200,5.20850,632.01082,-0.13487,16.46379,31.26847
62.60200,5.21675,629.96163,-0.13487,16.49680,31.16709
62.70200,5.22512,628.17796,-0.13487,16.53028,31.07884
62.80200,5.23349,627.63263,-0.13487,16.56376,31.05186
62.90200,5.24180,625.96505,-0.13487,16.59700,30.96936
63.00200,5.25018,624.39716,-0.13487,16.63049,30.89179
63.10200,5.25849,623.29257,-0.13487,16.66373,30.83714
63.20200,5.26674,621.84352,-0.13487,16.69673,30.76545
63.30200,5.27511,620.81795,-0.13487,16.73021,30.71471
63.40200,5.28348,619.24178,-0.13487,16.76369,30.63673
63.50200,5.29179,618.02962,-0.13487,16.79694,30.57676
63.60200,5.30016,617.29457,-0.13487,16.83042,30.54039
63.70200,5.30853,615.81433,-0.13487,16.86390,30.46716
63.80200,5.31690,614.37790,-0.13487,16.89739,30.39609
63.90200,5.32521,613.63382,-0.13487,16.93063,30.35928
64.00201,5.33352,611.96284,-0.13487,16.96387,30.27660
64.10200,5.34183,611.18151,-0.13487,16.99711,30.23795
64.20200,5.35020,609.75067,-0.13487,17.03060,30.16716
64.30200,5.35845,608.77833,-0.13487,17.06360,30.11905
64.40200,5.36676,608.82769,-0.13487,17.09684,30.12149
64.50201,5.37519,606.55940,-0.13487,17.13056,30.00927
64.60200,5.38345,605.53155,-0.13487,17.16357,29.95842
64.70200,5.39182,604.32171,-0.13487,17.19705,29.89856
64.80200,5.40019,603.55365,-0.13487,17.23053,29.86056
64.90200,5.40850,602.11876,-0.13487,17.26377,29.78957
65.00201,5.41681,600.85040,-0.13487,17.29702,29.72682
65.10200,5.42524,600.19195,-0.13487,17.33074,29.69424
65.20200,5.43343,598.97364,-0.13487,17.36350,29.63397
65.30200,5.44180,597.70509,-0.13487,17.39698,29.57121
65.40200,5.45017,596.91002,-0.13487,17.43047,29.53187
65.50201,5.45842,594.64234,-0.13487,17.46347,29.41968
65.60201,5.46679,593.83633,-0.13487,17.49695,29.37980
65.70200,5.47516,592.76852,-0.13487,17.53044,29.32697
65.80200,5.48347,591.43752,-0.13487,17.56368,29.26112
65.90200,5.49184,589.84570,-0.13487,17.59716,29.18237
66.00201,5.50027,588.66870,-0.13487,17.63088,29.12414
66.10201,5.50853,587.76112,-0.13487,17.66389,29.07924
66.20200,5.51684,585.83473,-0.13487,17.69713,28.98393
66.30200,5.52521,584.36636,-0.13487,17.73061,28.91128
66.40200,5.53340,582.55428,-0.13487,17.76338,28.82163
66.50201,5.54183,580.91292,-0.13487,17.79710,28.74042
66.60201,5.55014,579.54630,-0.13487,17.83034,28.67281
66.70200,5.55845,577.25399,-0.13487,17.86358,28.55940
66.80200,5.56694,575.99833,-0.13487,17.89754,28.49728
66.90200,5.57519,573.92074,-0.13487,17.93055,28.39449
67.00201,5.58350,570.74521,-0.13487,17.96379,28.23738
67.10201,5.59193,568.66542,-0.13487,17.99751,28.13448
67.20200,5.60018,565.53078,-0.13487,18.03052,27.97940
67.30200,5.60849,561.40418,-0.13487,18.06376,27.77524
67.40200,5.61686,557.63014,-0.13487,18.09724,27.58852
67.50201,5.62511,553.20938,-0.13487,18.13024,27.36980
67.60201,5.63343,547.52394,-0.13487,18.16349,27.08852
67.70200,5.64186,541.90778,-0.13487,18.19721,26.81066
67.80200,5.65017,535.02559,-0.13487,18.23045,26.47017
67.90200,5.65848,527.15298,-0.13487,18.26369,26.08067
68.00201,5.66685,517.44729,-0.13487,18.29718,25.60049
68.10201,5.67516,505.32231,-0.13487,18.33042,25.00061
68.20200,5.68347,486.84026,-0.13487,18.36366,24.08622
68.30200,5.69184,450.47980,-0.13487,18.39714,22.28730
68.37600,5.69800,4.24006,-0.13487,18.42178,0.20978