File: Manufatura Aditiva/Dados/Ensaios AMR/Ensaios/Ensaios FDM/Tracao_OLABI_25_05_2018_FDM_YZ5.is_metal_RawData/Specimen_RawData_3.csv
Time,Extension,Load,Strain 1,Tensile strain,Tensile stress
(sec),(mm),(N),(mm/mm),(%),(MPa)
0.00000,0.00006,16.61922,0.00061,0.06125,0.83181
0.60000,0.04986,37.45093,0.00139,0.13924,1.87445
1.20000,0.10003,59.25595,0.00221,0.22091,2.96581
1.80000,0.15001,81.56621,0.00302,0.30199,4.08245
2.40000,0.20000,103.11616,0.00384,0.38377,5.16105
3.00000,0.24998,124.62940,0.00466,0.46572,6.23780
3.60000,0.30002,145.85231,0.00549,0.54851,7.30002
4.20000,0.34995,166.95881,0.00630,0.62984,8.35642
4.80000,0.40005,188.76118,0.00713,0.71270,9.44765
5.40000,0.45010,209.03733,0.00795,0.79544,10.46249
6.00000,0.50002,230.33477,0.00878,0.87790,11.52844
6.60000,0.55000,250.85816,0.00960,0.95966,12.55565
7.20000,0.59993,270.96865,0.01042,1.04199,13.56220
7.80000,0.64997,291.71954,0.01124,1.12444,14.60080
8.40000,0.70002,311.61176,0.01207,1.20729,15.59642
9.00000,0.75000,331.41542,0.01290,1.28980,16.58761
9.60000,0.79992,351.35511,0.01373,1.37281,17.58561
10.20000,0.85003,370.87330,0.01455,1.45547,18.56251
10.80000,0.89995,389.66341,0.01535,1.53511,19.50297
11.40000,0.95006,408.36707,0.01618,1.61847,20.43910
12.00000,1.00010,427.94165,0.01702,1.70175,21.41882
12.60000,1.05008,448.11796,0.01786,1.78614,22.42866
13.20000,1.10001,466.57822,0.01869,1.86940,23.35261
13.80000,1.14993,485.12802,0.01953,1.95332,24.28105
14.40000,1.19998,502.84909,0.02038,2.03801,25.16800
15.00000,1.24990,519.93141,0.02119,2.11917,26.02298
15.60000,1.30000,538.10435,0.02204,2.20357,26.93255
16.20000,1.34993,554.68604,0.02288,2.28761,27.76248
16.80000,1.40003,571.95597,0.02373,2.37322,28.62686
17.40000,1.45001,588.56718,0.02459,2.45901,29.45826
18.00000,1.49994,605.38081,0.02544,2.54407,30.29980
18.60000,1.55004,621.12384,0.02630,2.63013,31.08775
19.20000,1.60003,636.61155,0.02714,2.71426,31.86292
19.80000,1.65013,652.49456,0.02801,2.80105,32.65788
20.40000,1.69999,668.11088,0.02889,2.88907,33.43948
21.00000,1.74998,682.63942,0.02977,2.97683,34.16665
21.60000,1.79996,697.24554,0.03066,3.10244,34.89770
22.11800,1.84313,709.55735,0.03143,3.27511,35.51391
22.71800,1.89317,723.49994,0.03232,3.47529,36.21175
23.31800,1.94310,737.28147,0.03322,3.67499,36.90153
23.91800,1.99320,750.11486,0.03414,3.87540,37.54385
24.51800,2.04319,763.20781,0.03505,4.07534,38.19916
25.11800,2.09317,774.83901,0.03598,4.27527,38.78131
25.71800,2.14315,786.21805,0.03738,4.47521,39.35085
26.31800,2.19314,798.73493,0.03051,4.67514,39.97732
26.91800,2.24324,807.45425,0.00815,4.87556,40.41373
27.51800,2.29323,817.67999,0.03797,5.07549,40.92554
28.11800,2.34315,827.53943,0.04483,5.27519,41.41901
28.71800,2.39307,836.27393,-0.14032,5.47489,41.85618
29.31800,2.44306,845.63503,-0.13993,5.67482,42.32471
29.91800,2.49310,853.65921,-0.13995,5.87500,42.72633
30.51800,2.54321,861.59958,-0.13996,6.07541,43.12375
31.11800,2.59313,868.73239,-0.13996,6.27511,43.48075
31.71800,2.64317,874.88350,-0.13997,6.47529,43.78862
32.31800,2.69316,879.98006,-0.13997,6.67522,44.04371
32.91800,2.74320,884.19886,-0.13997,6.87540,44.25486
33.51800,2.79319,888.88779,-0.13997,7.07533,44.48955
34.11800,2.84323,892.49955,-0.13998,7.27551,44.67032
34.71800,2.89321,895.73804,-0.13998,7.47544,44.83241
35.31800,2.94314,897.69494,-0.13997,7.67514,44.93035
35.91800,2.99318,899.36787,-0.13998,7.87532,45.01408
36.51800,3.04311,900.48416,-0.13998,8.07501,45.06995
37.11800,3.09309,901.21776,-0.13997,8.27495,45.10667
37.71800,3.14307,900.98912,-0.13998,8.47489,45.09523
38.31800,3.19318,899.64941,-0.13998,8.67530,45.02818
38.91800,3.24316,898.84726,-0.13998,8.87524,44.98803
39.51800,3.29315,897.33629,-0.13998,9.07517,44.91240
40.11800,3.34325,895.03285,-0.13998,9.27559,44.79711
40.71800,3.39317,892.39562,-0.13998,9.47528,44.66512
41.31800,3.44328,889.18153,-0.13998,9.67570,44.50425
41.91800,3.49314,886.40722,-0.13998,9.87516,44.36539
42.51800,3.54313,883.23103,-0.13998,10.07509,44.20642
43.11800,3.59311,880.17061,-0.13998,10.27503,44.05325
43.71800,3.64309,876.15587,-0.13998,10.47496,43.85230
44.31800,3.69314,873.21112,-0.13998,10.67514,43.70492
44.91800,3.74312,869.36541,-0.13998,10.87507,43.51244
45.51800,3.79317,864.94060,-0.13998,11.07525,43.29097
46.11800,3.84321,862.33048,-0.13998,11.27543,43.16033
46.71800,3.89319,858.31247,-0.13998,11.47536,42.95923
47.31800,3.94318,854.66877,-0.13998,11.67530,42.77686
47.91800,3.99316,851.69878,-0.13998,11.87523,42.62821
48.51800,4.04314,848.98993,-0.13998,12.07517,42.49263
49.11800,4.09313,845.72071,-0.13998,12.27511,42.32900
49.71800,4.14317,842.19752,-0.13998,12.47528,42.15266
50.31800,4.19316,839.13971,-0.13998,12.67522,41.99961
50.91800,4.24314,835.83845,-0.13998,12.87515,41.83438
51.51800,4.29318,833.81729,-0.13998,13.07533,41.73322
52.11800,4.34311,830.39040,-0.13998,13.27503,41.56171
52.71800,4.39315,828.16649,-0.13998,13.47520,41.45040
53.31800,4.44320,824.99161,-0.13998,13.67538,41.29149
53.91800,4.49318,822.67653,-0.13998,13.87531,41.17562
54.51800,4.54310,820.04173,-0.13998,14.07501,41.04375
55.11800,4.59315,817.52799,-0.13998,14.27518,40.91793
55.71800,4.64313,815.21012,-0.13998,14.47512,40.80192
56.31800,4.69318,813.03688,-0.13998,14.67530,40.69315
56.91800,4.74304,810.68603,-0.13998,14.87475,40.57549
57.51800,4.79314,808.14539,-0.13998,15.07517,40.44833
58.11800,4.84313,805.70010,-0.13998,15.27510,40.32594
58.71800,4.89317,803.25380,-0.13998,15.47528,40.20350
59.31800,4.94316,801.17434,-0.13998,15.67521,40.09942
59.91800,4.99314,798.55993,-0.13998,15.87515,39.96856
60.51800,5.04318,796.12769,-0.13998,16.07533,39.84683
61.11800,5.09317,792.88734,-0.13998,16.27526,39.68465
61.71800,5.14321,790.09952,-0.13998,16.47544,39.54511
62.31800,5.19314,787.26113,-0.13998,16.67513,39.40305
62.91800,5.24312,784.06511,-0.13998,16.87507,39.24309
63.51800,5.29316,780.92301,-0.13998,17.07524,39.08582
64.11800,5.34315,777.80355,-0.13998,17.27518,38.92969
64.71800,5.39319,774.03202,-0.13998,17.47536,38.74092
65.31800,5.44312,769.90696,-0.13998,17.67505,38.53446
65.91801,5.49316,764.88703,-0.13998,17.87523,38.28321
66.51801,5.54320,760.76100,-0.13997,18.07541,38.07670
67.11800,5.59325,755.39080,-0.13998,18.27558,37.80791
67.71800,5.64311,749.62913,-0.13998,18.47504,37.51954
68.31800,5.69310,742.21473,-0.13998,18.67497,37.14844
68.91801,5.74314,735.74372,-0.13997,18.87515,36.82456
69.51801,5.79312,728.32596,-0.13998,19.07508,36.45330
70.11800,5.84317,719.73181,-0.13998,19.27526,36.02316
70.71800,5.89309,710.89799,-0.13998,19.47496,35.58101
71.31800,5.94313,701.19468,-0.13998,19.67513,35.09536
71.91801,5.99318,693.09189,-0.13998,19.87531,34.68980
72.51801,6.04316,684.35241,-0.13998,20.07524,34.25239
73.11800,6.09321,676.56855,-0.13998,20.27542,33.86280
73.71800,6.14313,669.62917,-0.13998,20.47511,33.51548
74.31800,6.19317,664.24357,-0.13998,20.67529,33.24592
74.91801,6.24310,659.03608,-0.13997,20.87499,32.98528
75.51801,6.29320,654.82925,-0.13998,21.07540,32.77473
76.11800,6.34307,652.24729,-0.13997,21.27486,32.64550
76.71800,6.39317,649.44113,-0.13998,21.47527,32.50505
77.31800,6.44309,648.45192,-0.13997,21.67497,32.45554
77.91801,6.49314,646.08497,-0.13998,21.87515,32.33707
78.51801,6.54324,645.32091,-0.13998,22.07556,32.29883
79.11800,6.59317,645.49008,-0.13997,22.27526,32.30730
79.71800,6.64321,645.16319,-0.13998,22.47543,32.29094
80.31800,6.69319,644.84235,-0.13998,22.67537,32.27488
80.91801,6.74318,645.14000,-0.13997,22.87530,32.28978
81.51801,6.79310,644.95434,-0.13998,23.07500,32.28048
82.11800,6.84321,645.68711,-0.13998,23.27542,32.31716
82.71800,6.89319,645.84678,-0.13998,23.47535,32.32515
83.31800,6.94311,646.87831,-0.13997,23.67505,32.37678
83.91801,6.99316,646.49032,-0.13998,23.87522,32.35736
84.51801,7.04314,647.79171,-0.13997,24.07516,32.42249
85.11800,7.09319,647.34784,-0.13998,24.27534,32.40028
85.71800,7.14323,647.71832,-0.13998,24.47551,32.41882
86.31800,7.19321,648.24149,-0.13998,24.67545,32.44501
86.91801,7.24320,648.11637,-0.13998,24.87538,32.43874
87.51801,7.29318,648.22668,-0.13998,25.07532,32.44426
88.11800,7.34317,649.29551,-0.13998,25.27525,32.49776
88.71800,7.39321,648.95349,-0.13997,25.47543,32.48064
89.31800,7.44325,649.18096,-0.13998,25.67560,32.49203
89.91801,7.49324,649.17752,-0.13998,25.87554,32.49186
90.51801,7.54322,650.11703,-0.13997,26.07548,32.53888
91.11800,7.59315,650.28034,-0.13998,26.27517,32.54705
91.71800,7.64319,650.07764,-0.13997,26.47535,32.53691
92.31800,7.69317,650.10861,-0.13998,26.67529,32.53846
92.91801,7.74328,650.13850,-0.13997,26.87570,32.53995
93.51801,7.79320,650.65823,-0.13998,27.07540,32.56597
94.11800,7.84313,650.29776,-0.13998,27.27509,32.54792
94.71800,7.89311,650.76258,-0.13998,27.47503,32.57119
95.31800,7.94309,650.86139,-0.13998,27.67496,32.57613
95.91801,7.99320,650.89278,-0.13997,27.87538,32.57771
96.51801,8.04318,651.89530,-0.13997,28.07532,32.62788
97.11800,8.09317,651.13483,-0.13997,28.27525,32.58982
97.71800,8.14315,651.39225,-0.13997,28.47519,32.60270
98.31801,8.19319,651.90215,-0.13997,28.67537,32.62822
98.91801,8.24324,651.53274,-0.13997,28.87554,32.60974
99.51801,8.29322,652.08608,-0.13997,29.07547,32.63743
100.11800,8.34320,652.55081,-0.13997,29.27541,32.66069
100.71800,8.39319,652.80665,-0.13997,29.47535,32.67350
101.31801,8.44317,652.95207,-0.13997,29.67528,32.68077
101.91801,8.49310,652.82835,-0.13997,29.87498,32.67458
102.51801,8.54308,653.78523,-0.13997,30.07491,32.72247
103.11800,8.59318,653.97555,-0.13997,30.27533,32.73200
103.71800,8.64317,653.94994,-0.13997,30.47526,32.73072
104.31801,8.69315,653.73797,-0.13997,30.67520,32.72011
104.91801,8.74314,654.44848,-0.13997,30.87514,32.75567
105.51801,8.79324,654.54231,-0.13998,31.07555,32.76037
106.11800,8.84322,653.82905,-0.13997,31.27549,32.72467
106.71800,8.89333,654.52172,-0.13998,31.47590,32.75934
107.31801,8.94325,654.86575,-0.13997,31.67560,32.77655
107.91801,8.99318,654.54585,-0.13997,31.87530,32.76054
108.51801,9.04316,655.24722,-0.13997,32.07524,32.79565
109.11800,9.09314,654.98939,-0.13997,32.27517,32.78275
109.71800,9.14319,654.51665,-0.13997,32.47535,32.75908
110.31801,9.19305,654.60815,-0.13998,32.67480,32.76366
110.91801,9.24316,655.70292,-0.13997,32.87522,32.81846
111.51801,9.29320,655.37798,-0.13997,33.07539,32.80219
112.11800,9.34318,655.55810,-0.13997,33.27533,32.81121
112.71800,9.39323,655.87168,-0.13997,33.47550,32.82690
113.31801,9.44321,655.46776,-0.13997,33.67544,32.80669
113.91801,9.49326,655.97808,-0.13997,33.87561,32.83223
114.51801,9.54318,655.35516,-0.13997,34.07531,32.80105
115.11800,9.59316,656.20290,-0.13997,34.27525,32.84348
115.71800,9.64315,655.81282,-0.13997,34.47518,32.82396
116.31801,9.69319,655.77966,-0.13998,34.67536,32.82230
116.91801,9.74318,656.23717,-0.13997,34.87529,32.84520
117.51801,9.79322,656.44225,-0.13997,35.07547,32.85546
118.11800,9.84308,655.83438,-0.13997,35.27493,32.82504
118.71800,9.89319,656.67811,-0.13997,35.47534,32.86726
119.31801,9.94323,656.76058,-0.13997,35.67552,32.87140
119.91801,9.99328,657.08058,-0.13998,35.87569,32.88741
120.51801,10.04326,656.75713,-0.13998,36.07563,32.87122
121.11800,10.09312,657.06014,-0.13997,36.27509,32.88639
121.71800,10.14317,656.55038,-0.13997,36.47526,32.86087
122.31801,10.19315,657.43756,-0.13997,36.67519,32.90528
122.91801,10.24314,656.96649,-0.13997,36.87513,32.88170
123.51801,10.29312,657.07606,-0.13997,37.07507,32.88718
124.11800,10.34310,657.77367,-0.13997,37.27500,32.92210
124.71800,10.39315,657.39052,-0.13997,37.47518,32.90292
125.31801,10.44313,658.00594,-0.13997,37.67511,32.93372
125.91801,10.49323,657.78531,-0.13997,37.87553,32.92268
126.51801,10.54316,657.87090,-0.13997,38.07523,32.92697
127.11800,10.59326,658.56087,-0.13997,38.27564,32.96150
127.71800,10.64313,658.99948,-0.13997,38.47510,32.98345
128.31801,10.69317,658.77503,-0.13997,38.67528,32.97222
128.91800,10.74316,659.34276,-0.13997,38.87521,33.00063
129.51801,10.79308,659.88554,-0.13997,39.07491,33.02780
130.11801,10.84318,659.45433,-0.13997,39.27532,33.00622
130.71800,10.89311,659.16828,-0.13997,39.47502,32.99190
131.31802,10.94315,659.45517,-0.13997,39.67519,33.00626
131.91800,10.99319,659.34975,-0.13997,39.87537,33.00098
132.51800,11.04324,659.13456,-0.13997,40.07554,32.99021
133.11802,11.09322,659.32991,-0.13997,40.27548,32.99999
133.71800,11.14315,659.06229,-0.13997,40.47518,32.98660
134.31802,11.19319,659.32148,-0.13997,40.67535,32.99957
134.91800,11.24311,659.56567,-0.13997,40.87505,33.01179
135.51800,11.29322,659.41350,-0.13997,41.07547,33.00417
136.11802,11.34308,659.58914,-0.13997,41.27492,33.01297
136.71800,11.39307,660.26482,-0.13997,41.47486,33.04678
137.31802,11.44311,660.80512,-0.13997,41.67503,33.07383
137.91800,11.49321,661.31619,-0.13997,41.87545,33.09941
138.51800,11.54320,660.92764,-0.13997,42.07538,33.07996
139.11802,11.59312,660.29308,-0.13997,42.27508,33.04820
139.71800,11.64323,661.11749,-0.13997,42.47549,33.08946
140.31802,11.69321,661.20429,-0.13998,42.67543,33.09380
140.91800,11.74319,660.12344,-0.13997,42.87537,33.03971
141.51800,11.79312,660.59777,-0.13997,43.07507,33.06345
142.11802,11.84310,660.79781,-0.13997,43.27500,33.07346
142.71800,11.89315,660.93416,-0.13997,43.47518,33.08028
143.31802,11.94313,660.14286,-0.13997,43.67511,33.04068
143.91800,11.99317,660.75786,-0.13997,43.87529,33.07146
144.51800,12.04310,660.77039,-0.13997,44.07499,33.07209
145.11802,12.09326,660.84326,-0.13997,44.27564,33.07573
145.71800,12.14319,660.66161,-0.13997,44.47533,33.06664
146.31802,12.19329,660.93993,-0.13997,44.67575,33.08057
146.91802,12.24315,660.55553,-0.13997,44.87520,33.06133
147.51800,12.29314,660.16242,-0.13997,45.07514,33.04166
148.11802,12.34306,660.60019,-0.13997,45.27484,33.06357
148.71800,12.39311,660.24750,-0.13997,45.47502,33.04592
149.31802,12.44315,659.54942,-0.13997,45.67519,33.01098
149.91802,12.49307,660.19786,-0.13997,45.87488,33.04343
150.51800,12.54312,659.82346,-0.13997,46.07506,33.02469
151.11802,12.59310,659.59790,-0.13997,46.27500,33.01340
151.71800,12.64321,660.45495,-0.13997,46.47541,33.05630
152.31802,12.69313,660.11394,-0.13997,46.67511,33.03923
152.91802,12.74317,659.87762,-0.13997,46.87529,33.02740
153.51800,12.79316,660.22901,-0.13998,47.07522,33.04499
154.11802,12.84314,659.91734,-0.13997,47.27516,33.02939
154.71800,12.89324,660.28186,-0.13997,47.47557,33.04764
155.31802,12.94311,660.85355,-0.13997,47.67503,33.07625
155.91802,12.99321,660.57118,-0.13997,47.87544,33.06212
156.51800,13.04314,660.84997,-0.13997,48.07514,33.07607
157.11802,13.09318,660.85667,-0.13997,48.27532,33.07640
157.71800,13.14310,660.53723,-0.13997,48.47501,33.06042
158.31802,13.19315,660.95227,-0.13997,48.67518,33.08119
158.91802,13.24319,660.30589,-0.13997,48.87536,33.04884
159.51800,13.29312,660.30789,-0.13997,49.07506,33.04894
160.11802,13.34316,660.29904,-0.13997,49.27523,33.04850
160.71800,13.39308,660.38878,-0.13997,49.47493,33.05299
161.31802,13.44319,659.84470,-0.13997,49.67535,33.02576
161.91802,13.49305,659.72712,-0.13997,49.87480,33.01987
162.51800,13.54310,660.33960,-0.13997,50.07498,33.05053
163.11802,13.59314,660.71148,-0.13997,50.27515,33.06914
163.71800,13.64307,660.73122,-0.13997,50.47485,33.07013
164.31802,13.69317,661.11824,-0.13997,50.67526,33.08950
164.91802,13.74315,660.61416,-0.13997,50.87520,33.06427
165.51800,13.79320,661.27265,-0.13997,51.07538,33.09723
166.11802,13.84318,661.01588,-0.13997,51.27531,33.08437
166.71800,13.89322,660.82003,-0.13997,51.47549,33.07457
167.31802,13.94315,661.35614,-0.13997,51.67518,33.10141
167.91802,13.99313,660.20400,-0.13997,51.87512,33.04374
168.51800,14.04318,661.40713,-0.13997,52.07529,33.10396
169.11802,14.09310,660.01117,-0.13997,52.27499,33.03409
169.71800,14.14314,660.50314,-0.13997,52.47517,33.05871
170.31802,14.19307,661.31051,-0.13997,52.67487,33.09912
170.91802,14.24311,660.86305,-0.13997,52.87504,33.07673
171.51800,14.29322,660.37392,-0.13997,53.07546,33.05224
172.11802,14.34326,659.92968,-0.13997,53.27563,33.03001
172.71800,14.39324,659.57913,-0.13997,53.47557,33.01246
173.31802,14.44317,659.44563,-0.13997,53.67526,33.00578
173.91802,14.49315,660.36847,-0.13997,53.87520,33.05197
174.51800,14.54314,659.28046,-0.13997,54.07513,32.99752
175.11802,14.59318,660.32829,-0.13997,54.27531,33.04996
175.71800,14.64310,660.73001,-0.13997,54.47501,33.07007
176.31802,14.69315,659.95860,-0.13997,54.67518,33.03146
176.91802,14.74307,659.46397,-0.13997,54.87488,33.00670
177.51800,14.79312,659.60279,-0.13997,55.07506,33.01365
178.11802,14.84322,659.50081,-0.13997,55.27546,33.00854
178.71800,14.89320,660.37220,-0.13997,55.47540,33.05216
179.31802,14.94331,660.00042,-0.13997,55.67582,33.03355
179.91802,14.99317,659.64516,-0.13997,55.87528,33.01577
180.51800,15.04322,659.25005,-0.13997,56.07545,32.99599
181.11802,15.09308,659.56754,-0.13997,56.27491,33.01188
181.71800,15.14318,659.68996,-0.13997,56.47533,33.01801
182.31802,15.19317,659.34728,-0.13997,56.67526,33.00086
182.91802,15.24321,659.15263,-0.13997,56.87544,32.99112
183.51800,15.29320,659.15105,-0.13997,57.07538,32.99104
184.11802,15.34312,659.39813,-0.13997,57.27507,33.00341
184.71800,15.39316,659.11692,-0.13997,57.47524,32.98933
185.31802,15.44321,659.19845,-0.13997,57.67542,32.99341
185.91802,15.49325,659.52088,-0.13997,57.87559,33.00955
186.51800,15.54312,659.83525,-0.13997,58.07505,33.02528
187.11802,15.59316,659.66123,-0.13997,58.27523,33.01657
187.71800,15.64314,660.33625,-0.13997,58.47516,33.05036
188.31802,15.69313,660.60699,-0.13997,58.67510,33.06391
188.91802,15.74317,660.46640,-0.13997,58.87527,33.05687
189.51800,15.79315,660.46827,-0.13997,59.07521,33.05696
190.11802,15.84320,660.71711,-0.13997,59.27538,33.06942
190.71800,15.89318,660.84513,-0.13997,59.47531,33.07583
191.31802,15.94323,660.73453,-0.13997,59.67550,33.07029
191.91802,15.99315,660.55786,-0.13997,59.87519,33.06145
192.51800,16.04325,660.36405,-0.13997,60.07560,33.05175
193.11802,16.09318,660.48801,-0.13997,60.27530,33.05795
193.71800,16.14316,660.50631,-0.13997,60.47524,33.05887
194.31802,16.19315,660.45811,-0.13997,60.67518,33.05646
194.91802,16.24313,660.67320,-0.13997,60.87511,33.06722
195.51800,16.29323,660.43744,-0.13997,61.07553,33.05542
196.11802,16.34310,659.86933,-0.13997,61.27499,33.02699
196.71800,16.39314,660.35199,-0.13997,61.47516,33.05115
197.31802,16.44313,660.68168,-0.13997,61.67510,33.06765
197.91802,16.49323,660.44405,-0.13997,61.87551,33.05576
198.51800,16.54321,660.23241,-0.13997,62.07544,33.04516
199.11802,16.59320,660.23050,-0.13997,62.27538,33.04507
199.71800,16.64318,659.83688,-0.13997,62.47532,33.02536
200.31802,16.69311,659.75604,-0.13997,62.67502,33.02132
200.91802,16.74315,659.45927,-0.13997,62.87519,33.00647
201.51800,16.79307,659.62360,-0.13997,63.07489,33.01469
202.11802,16.84312,659.83022,-0.13997,63.27506,33.02503
202.71800,16.89310,659.01261,-0.13997,63.47500,32.98411
203.31802,16.94309,659.91147,-0.13997,63.67493,33.02910
203.91802,16.99313,659.81201,-0.13997,63.87511,33.02412
204.51800,17.04311,660.29872,-0.13997,64.07505,33.04848
205.11802,17.09322,660.49681,-0.13997,64.27546,33.05840
205.71800,17.14326,660.26868,-0.13997,64.47563,33.04698
206.31802,17.19330,660.34282,-0.13997,64.67581,33.05069
206.91802,17.24323,660.55064,-0.13997,64.87551,33.06109
207.51800,17.29309,660.25481,-0.13998,65.07497,33.04628
208.11802,17.34308,660.71698,-0.13997,65.27491,33.06942
208.71800,17.39312,661.10813,-0.13997,65.47508,33.08899
209.31802,17.44317,660.52857,-0.13997,65.67525,33.05999
209.91802,17.49309,660.79665,-0.13997,65.87495,33.07340
210.51800,17.54313,660.71437,-0.13997,66.07512,33.06928
211.11802,17.59312,661.07688,-0.13997,66.27506,33.08743
211.71802,17.64322,660.75232,-0.13997,66.47547,33.07118
212.31802,17.69320,660.32624,-0.13997,66.67541,33.04986
212.91802,17.74319,660.91781,-0.13997,66.87534,33.07947
213.51800,17.79317,661.65598,-0.13997,67.07528,33.11641
214.11802,17.84316,661.50385,-0.13997,67.27522,33.10880
214.71802,17.89314,661.20122,-0.13997,67.47515,33.09365
215.31802,17.94307,661.89552,-0.13997,67.67485,33.12840
215.91802,17.99317,661.15260,-0.13997,67.87527,33.09122
216.51800,18.04309,660.79334,-0.13997,68.07497,33.07324
217.11802,18.09320,660.83646,-0.13997,68.27538,33.07539
217.71802,18.14312,661.43726,-0.13997,68.47508,33.10546
218.31802,18.19317,660.70165,-0.13997,68.67525,33.06865
218.91802,18.24321,660.81625,-0.13997,68.87543,33.07438
219.51800,18.29313,659.91450,-0.13997,69.07513,33.02925
220.11802,18.34318,660.27832,-0.13997,69.27530,33.04746
220.71802,18.39310,660.41620,-0.13997,69.47500,33.05436
221.31802,18.44315,660.45527,-0.13997,69.67517,33.05632
221.91802,18.49313,660.27218,-0.13997,69.87511,33.04715
222.51800,18.54317,660.23357,-0.13997,70.07528,33.04522
223.11802,18.59310,660.64028,-0.13997,70.27498,33.06557
223.71802,18.64308,660.20470,-0.13997,70.47492,33.04377
224.31802,18.69318,659.94556,-0.13997,70.67533,33.03080
224.91802,18.74317,659.94384,-0.13997,70.87526,33.03072
225.51800,18.79327,660.11231,-0.13997,71.07568,33.03915
226.11802,18.84314,659.96586,-0.13997,71.27514,33.03182
226.71802,18.89318,660.54529,-0.13997,71.47532,33.06082
227.31802,18.94305,660.73798,-0.13997,71.67477,33.07047
227.91802,18.99309,660.54948,-0.13997,71.87495,33.06103
228.51800,19.04313,660.99362,-0.13997,72.07512,33.08326
229.11802,19.09306,660.25457,-0.13997,72.27482,33.04627
229.71802,19.14322,660.67236,-0.13997,72.47547,33.06718
230.31802,19.19314,660.29602,-0.13997,72.67517,33.04834
230.91802,19.24319,659.99455,-0.13997,72.87534,33.03326
231.51800,19.29317,660.39329,-0.13997,73.07528,33.05322
232.11802,19.34322,660.08815,-0.13997,73.27545,33.03794
232.71802,19.39326,659.75846,-0.13997,73.47563,33.02144
233.31802,19.44312,659.66472,-0.13997,73.67509,33.01675
233.91802,19.49311,659.03338,-0.13997,73.87503,32.98515
234.51800,19.54309,658.69316,-0.13997,74.07496,32.96812
235.11802,19.59314,658.74816,-0.13997,74.27514,32.97087
235.71802,19.64312,659.22756,-0.13997,74.47507,32.99487
236.31802,19.69310,658.92236,-0.13997,74.67501,32.97959
236.91802,19.74315,659.59785,-0.13997,74.87518,33.01340
237.51800,19.79319,659.14956,-0.13997,75.07536,32.99096
238.11802,19.84324,658.65763,-0.13997,75.27553,32.96634
238.71802,19.89310,658.24972,-0.13997,75.47499,32.94593
239.31802,19.94320,658.06410,-0.13997,75.67541,32.93663
239.91802,19.99313,657.99309,-0.13997,75.87510,32.93308
240.51800,20.04317,657.47877,-0.13997,76.07528,32.90734
241.11802,20.09316,657.93106,-0.13997,76.27522,32.92998
241.71802,20.14314,658.18974,-0.13997,76.47516,32.94292
242.31802,20.19306,658.73694,-0.13997,76.67484,32.97031
242.91802,20.24311,658.46108,-0.13997,76.87503,32.95650
243.51800,20.29315,658.27155,-0.13997,77.07520,32.94702
244.11802,20.34314,658.50667,-0.13997,77.27513,32.95879
244.71802,20.39318,658.40543,-0.13997,77.47531,32.95372
245.31802,20.44316,658.34294,-0.13997,77.67525,32.95059
245.91802,20.49321,658.48688,-0.13997,77.87542,32.95779
246.51800,20.54319,657.96264,-0.13997,78.07535,32.93156
247.11802,20.59317,658.04911,-0.13997,78.27529,32.93589
247.71802,20.64316,657.91556,-0.13997,78.47522,32.92920
248.31802,20.69320,657.35159,-0.13997,78.67540,32.90097
248.91802,20.74325,658.24096,-0.13997,78.87558,32.94549
249.51800,20.79311,657.62596,-0.13997,79.07503,32.91471
250.11802,20.84316,657.19467,-0.13997,79.27521,32.89312
250.71802,20.89314,658.37074,-0.13997,79.47515,32.95198
251.31802,20.94324,657.73414,-0.13997,79.67556,32.92012
251.91802,20.99317,657.66559,-0.13997,79.87526,32.91669
252.51800,21.04321,657.84375,-0.13997,80.07543,32.92561
253.11802,21.09313,657.61651,-0.13997,80.27512,32.91423
253.71802,21.14312,658.61559,-0.13997,80.47506,32.96424
254.31802,21.19316,658.70374,-0.13997,80.67524,32.96865
254.91802,21.24314,658.34778,-0.13997,80.87517,32.95084
255.51800,21.29319,658.40129,-0.13997,81.07536,32.95351
256.11802,21.34311,657.61763,-0.13997,81.27504,32.91429
256.71802,21.39316,657.80059,-0.13997,81.47522,32.92345
257.31803,21.44314,658.16231,-0.13997,81.67515,32.94155
257.91800,21.49319,657.91672,-0.13997,81.87534,32.92926
258.51800,21.54317,657.49455,-0.13997,82.07527,32.90813
259.11802,21.59315,657.40310,-0.13997,82.27521,32.90355
259.71802,21.64326,657.66359,-0.13997,82.47563,32.91659
260.31803,21.69312,657.34186,-0.13997,82.67508,32.90049
260.91800,21.74323,657.43686,-0.13997,82.87550,32.90524
261.51800,21.79309,658.00049,-0.13997,83.07495,32.93345
262.11802,21.84320,657.97521,-0.13997,83.27537,32.93219
262.71803,21.89318,658.33195,-0.13997,83.47530,32.95004
263.31803,21.94310,658.48557,-0.13997,83.67499,32.95773
263.91800,21.99321,658.00627,-0.13997,83.87541,32.93374
264.51800,22.04319,658.34555,-0.13997,84.07534,32.95072
265.11800,22.09329,657.68189,-0.13997,84.27576,32.91751
265.71803,22.14322,657.88394,-0.13997,84.47546,32.92762
266.31803,22.19320,657.96226,-0.13997,84.67539,32.93154
266.91800,22.24312,657.48719,-0.13997,84.87509,32.90776
267.51800,22.29311,657.09762,-0.13997,85.07502,32.88826
268.11800,22.34309,657.29613,-0.13997,85.27496,32.89820
268.71803,22.39314,657.46219,-0.13997,85.47513,32.90651
269.31803,22.44318,657.34778,-0.13997,85.67532,32.90078
269.91800,22.49310,657.85721,-0.13997,85.87501,32.92628
270.51800,22.54321,657.42335,-0.13997,86.07542,32.90456
271.11800,22.59325,657.62219,-0.13997,86.27561,32.91452
271.71803,22.64330,657.25669,-0.13997,86.47578,32.89622
272.31803,22.69322,657.44920,-0.13997,86.67547,32.90586
272.91800,22.74314,656.85138,-0.13997,86.87516,32.87594
273.51800,22.79313,657.33739,-0.13997,87.07510,32.90026
274.11800,22.84311,657.14745,-0.13997,87.27504,32.89075
274.71803,22.89316,656.98884,-0.13997,87.47522,32.88282
275.31803,22.94320,656.31871,-0.13997,87.67539,32.84928
275.91800,22.99318,656.14558,-0.13997,87.87532,32.84061
276.51800,23.04311,655.78483,-0.13998,88.07503,32.82256
277.11800,23.09321,655.40909,-0.13997,88.27544,32.80375
277.71803,23.14320,655.52113,-0.13997,88.47538,32.80936
278.31803,23.19318,654.74007,-0.13997,88.67531,32.77026
278.91800,23.24322,655.86655,-0.13997,88.87549,32.82664
279.51800,23.29321,654.83311,-0.13997,89.07543,32.77492
280.11800,23.34319,654.95721,-0.13997,89.27536,32.78113
280.71803,23.39318,655.22892,-0.13997,89.47530,32.79473
281.31803,23.44316,654.64894,-0.13997,89.67522,32.76571
281.91800,23.49308,655.30450,-0.13997,89.87493,32.79852
282.51800,23.54319,654.83018,-0.13997,90.07534,32.77478
283.11800,23.59317,654.74412,-0.13997,90.27528,32.77047
283.71803,23.64316,655.09919,-0.13997,90.47521,32.78824
284.31803,23.69320,654.90939,-0.13997,90.67539,32.77874
284.91800,23.74318,654.72745,-0.13997,90.87533,32.76963
285.51800,23.79329,654.97500,-0.13997,91.07574,32.78202
286.11800,23.84315,654.33844,-0.13997,91.27520,32.75016
286.71803,23.89319,654.75693,-0.13997,91.47537,32.77111
287.31803,23.94318,654.84918,-0.13997,91.67531,32.77573
287.91800,23.99316,654.46170,-0.13997,91.87524,32.75633
288.51800,24.04315,654.49644,-0.13997,92.07518,32.75807
289.11800,24.09307,654.57770,-0.13997,92.27488,32.76214
289.71803,24.14323,654.66873,-0.13997,92.47553,32.76669
290.31803,24.19310,654.25313,-0.13997,92.67499,32.74590
290.91800,24.24326,654.23003,-0.13997,92.87564,32.74474
291.51800,24.29319,654.02645,-0.13997,93.07534,32.73455
292.11800,24.34323,653.38081,-0.13997,93.27551,32.70223
292.71803,24.39321,654.17970,-0.13997,93.47545,32.74222
293.31803,24.44314,653.18425,-0.13997,93.67514,32.69239
293.91800,24.49312,652.74565,-0.13997,93.87508,32.67044
294.51800,24.54305,653.43287,-0.13997,94.07479,32.70484
295.11800,24.59315,653.30896,-0.13997,94.27519,32.69864
295.71803,24.64307,652.88544,-0.13997,94.47489,32.67744
296.31803,24.69312,652.99543,-0.13997,94.67507,32.68295
296.91800,24.74316,652.40911,-0.13997,94.87525,32.65360
297.51800,24.79315,651.76543,-0.13997,95.07518,32.62138
298.11800,24.84331,651.59239,-0.13997,95.27583,32.61272
298.71803,24.89323,651.86098,-0.13997,95.47553,32.62616
299.31803,24.94322,652.27970,-0.13997,95.67547,32.64712
299.91800,24.99314,652.07519,-0.13997,95.87516,32.63689
300.51800,25.04313,651.43444,-0.13997,96.07510,32.60482
301.11800,25.09311,651.26591,-0.13997,96.27503,32.59638
301.71803,25.14304,652.25707,-0.13997,96.47474,32.64599
302.31803,25.19314,652.01810,-0.13997,96.67515,32.63403
302.91800,25.24312,652.28986,-0.13997,96.87508,32.64763
303.51800,25.29317,651.98285,-0.13997,97.07525,32.63226
304.11800,25.34321,652.39714,-0.13997,97.27543,32.65300
304.71803,25.39319,651.56673,-0.13997,97.47537,32.61144
305.31803,25.44318,652.53931,-0.13997,97.67531,32.66011
305.91803,25.49322,652.64935,-0.13997,97.87548,32.66562
306.51800,25.54321,652.59649,-0.13997,98.07542,32.66298
307.11800,25.59307,651.79300,-0.13997,98.27487,32.62276
307.71803,25.64311,652.07826,-0.13997,98.47505,32.63704
308.31803,25.69310,652.15216,-0.13997,98.67499,32.64074
308.91803,25.74314,651.70447,-0.13997,98.87516,32.61833
309.51800,25.79313,651.41646,-0.13997,99.07510,32.60392
310.11800,25.84317,651.22065,-0.13997,99.27527,32.59412
310.71803,25.89310,650.67345,-0.13997,99.47497,32.56673
311.31803,25.94326,650.36048,-0.13997,99.67562,32.55106
311.91803,25.99318,650.66535,-0.13997,99.87532,32.56632
312.51800,26.04317,650.10148,-0.13997,100.07526,32.53810
313.11800,26.09309,649.72644,-0.13997,100.27496,32.51933
313.71803,26.14314,649.69659,-0.13997,100.47513,32.51783
314.31803,26.19318,649.76537,-0.13997,100.67530,32.52128
314.91803,26.24316,649.47372,-0.13997,100.87523,32.50668
315.51800,26.29321,649.71359,-0.13997,101.07541,32.51868
316.11800,26.34313,649.35237,-0.13997,101.27511,32.50061
316.71803,26.39323,648.81924,-0.13997,101.47552,32.47392
317.31803,26.44322,648.90501,-0.13997,101.67546,32.47821
317.91803,26.49314,648.97798,-0.13997,101.87516,32.48187
318.51800,26.54313,647.90230,-0.13997,102.07510,32.42803
319.11800,26.59317,648.16959,-0.13997,102.27528,32.44141
319.71803,26.64321,647.57811,-0.13997,102.47544,32.41180
320.31803,26.69308,648.62911,-0.13997,102.67490,32.46441
320.91803,26.74312,647.66239,-0.13997,102.87509,32.41602
321.51800,26.79317,647.93448,-0.13997,103.07525,32.42964
322.11800,26.84315,648.10300,-0.13997,103.27519,32.43808
322.71803,26.89319,648.42361,-0.13997,103.47537,32.45412
323.31803,26.94312,649.04243,-0.13997,103.67507,32.48509
323.91803,26.99322,648.88960,-0.13997,103.87547,32.47744
324.51800,27.04315,648.48023,-0.13997,104.07518,32.45695
325.11800,27.09325,648.92503,-0.13997,104.27558,32.47922
325.71803,27.14317,649.35219,-0.13997,104.47528,32.50060
326.31803,27.19316,648.96718,-0.13997,104.67522,32.48133
326.91803,27.24314,649.69454,-0.13997,104.87516,32.51773
327.51800,27.29307,648.80219,-0.13997,105.07486,32.47307
328.11800,27.34317,649.72034,-0.13997,105.27527,32.51902
328.71803,27.39304,650.51480,-0.13997,105.47473,32.55879
329.31803,27.44320,649.99396,-0.13997,105.67539,32.53272
329.91803,27.49312,650.76835,-0.13997,105.87507,32.57148
330.51800,27.54322,650.41105,-0.13997,106.07549,32.55359
331.11800,27.59321,651.03304,-0.13997,106.27543,32.58472
331.71803,27.64319,651.05446,-0.13997,106.47537,32.58580
332.31803,27.69318,650.64477,-0.13997,106.67530,32.56529
332.91803,27.74310,650.51401,-0.13997,106.87500,32.55875
333.51800,27.79315,650.32537,-0.13997,107.07517,32.54930
334.11800,27.84307,650.59504,-0.13997,107.27488,32.56280
334.71803,27.89311,650.38642,-0.13997,107.47504,32.55236
335.31803,27.94310,650.27121,-0.13997,107.67498,32.54660
335.91803,27.99314,650.60817,-0.13997,107.87516,32.56346
336.51800,28.04313,650.17077,-0.13997,108.07509,32.54157
337.11800,28.09323,650.05864,-0.13997,108.27551,32.53596
337.71803,28.14321,649.94157,-0.13997,108.47545,32.53010
338.31803,28.19320,650.06707,-0.13997,108.67538,32.53638
338.91803,28.24318,649.39950,-0.13997,108.87531,32.50296
339.51800,28.29317,649.74087,-0.13997,109.07525,32.52005
340.11800,28.34321,649.21454,-0.13997,109.27544,32.49371
340.71803,28.39319,649.51200,-0.13997,109.47536,32.50859
341.31803,28.44318,649.66027,-0.13997,109.67530,32.51602
341.91803,28.49310,649.73230,-0.13997,109.87500,32.51962
342.51800,28.54315,650.25901,-0.13997,110.07518,32.54599
343.11800,28.59313,650.63760,-0.13997,110.27511,32.56493
343.71803,28.64317,650.97045,-0.13997,110.47528,32.58159
344.31803,28.69328,650.84877,-0.13997,110.67569,32.57550
344.91803,28.74314,650.62619,-0.13997,110.87515,32.56436
345.51800,28.79324,651.34019,-0.13997,111.07557,32.60010
346.11800,28.84311,650.76491,-0.13997,111.27502,32.57130
346.71803,28.89315,651.20035,-0.13997,111.47521,32.59310
347.31803,28.94307,651.60603,-0.13997,111.67489,32.61340
347.91803,28.99312,650.51401,-0.13997,111.87507,32.55875
348.51800,29.04316,651.30270,-0.13997,112.07525,32.59822
349.11800,29.09315,651.48626,-0.13997,112.27518,32.60741
349.71803,29.14313,652.00790,-0.13997,112.47512,32.63352
350.31803,29.19312,651.62792,-0.13997,112.67506,32.61450
350.91803,29.24328,651.25041,-0.13997,112.87571,32.59560
351.51800,29.29321,651.72161,-0.13997,113.07541,32.61919
352.11800,29.34319,652.03849,-0.13997,113.27535,32.63505
352.71803,29.39311,651.92208,-0.13997,113.47504,32.62922
353.31803,29.44309,651.71542,-0.13997,113.67497,32.61888
353.91803,29.49320,651.74000,-0.13997,113.87539,32.62011
354.51800,29.54318,652.11728,-0.13997,114.07533,32.63899
355.11800,29.59317,651.57674,-0.13997,114.27525,32.61194
355.71803,29.64315,651.90117,-0.13997,114.47519,32.62818
356.31803,29.69320,652.30033,-0.13997,114.67538,32.64816
356.91803,29.74318,653.14900,-0.13997,114.87532,32.69063
357.51800,29.79322,652.67254,-0.13998,115.07548,32.66678
358.11800,29.84321,652.68585,-0.13997,115.27542,32.66745
358.71803,29.89313,653.57601,-0.13997,115.47512,32.71200
359.31803,29.94318,652.90364,-0.13997,115.67529,32.67835
359.91803,29.99310,653.03356,-0.13997,115.87498,32.68485
360.51800,30.04314,652.69591,-0.13997,116.07517,32.66795
361.11800,30.09313,652.98388,-0.13997,116.27511,32.68237
361.71803,30.14317,651.93968,-0.13997,116.47527,32.63010
362.31803,30.19310,651.97139,-0.13997,116.67497,32.63169
362.91803,30.24314,652.48515,-0.13997,116.87515,32.65741
363.51800,30.29324,652.77028,-0.13997,117.07556,32.67168
364.11800,30.34323,652.54681,-0.13997,117.27550,32.66049
364.71803,30.39327,652.15402,-0.13997,117.47568,32.64083
365.31803,30.44319,652.26029,-0.13997,117.67536,32.64615
365.91803,30.49318,652.19915,-0.13997,117.87530,32.64309
366.51800,30.54316,652.05353,-0.13997,118.07524,32.63580
367.11800,30.59315,652.21251,-0.13997,118.27518,32.64376
367.71803,30.64313,652.51892,-0.13997,118.47512,32.65910
368.31803,30.69306,652.26681,-0.13997,118.67481,32.64648
368.91803,30.74316,652.57801,-0.13997,118.87523,32.66205
369.51800,30.79314,653.17540,-0.13997,119.07516,32.69195
370.11800,30.84319,652.69265,-0.13997,119.27534,32.66779
370.71803,30.89317,653.48106,-0.13997,119.47528,32.70725
371.31803,30.94328,652.85619,-0.13997,119.67570,32.67598
371.91803,30.99326,652.76781,-0.13997,119.87562,32.67155
372.51800,31.04312,652.62858,-0.13997,120.07508,32.66459
373.11800,31.09311,652.47519,-0.13997,120.27502,32.65691
373.71803,31.14309,652.40422,-0.13997,120.47496,32.65335
374.31803,31.19313,652.54187,-0.13997,120.67512,32.66024
374.91803,31.24312,652.57312,-0.13997,120.87506,32.66181
375.51800,31.29310,651.85130,-0.13997,121.07500,32.62568
376.11800,31.34314,652.36175,-0.13997,121.27516,32.65123
376.71803,31.39319,652.76083,-0.13997,121.47535,32.67120
377.31803,31.44317,652.14331,-0.13997,121.67528,32.64030
377.91803,31.49322,652.00687,-0.13997,121.87546,32.63346
378.51800,31.54320,652.36068,-0.13998,122.07539,32.65118
379.11800,31.59313,652.52269,-0.13997,122.27509,32.65928
379.71803,31.64317,652.74462,-0.13997,122.47527,32.67039
380.31803,31.69315,652.68064,-0.13997,122.67520,32.66719
380.91803,31.74320,652.99240,-0.13997,122.87538,32.68279
381.51800,31.79312,652.96437,-0.13998,123.07508,32.68139
382.11800,31.84310,653.01894,-0.13997,123.27501,32.68412
382.71803,31.89321,653.00805,-0.13997,123.47543,32.68357
383.31803,31.94319,652.55826,-0.13997,123.67536,32.66106
383.91803,31.99318,652.02359,-0.13997,123.87530,32.63430
384.51800,32.04316,652.69466,-0.13997,124.07522,32.66789
385.11800,32.09326,652.11235,-0.13998,124.27565,32.63874
385.71803,32.14313,651.31965,-0.13997,124.47510,32.59907
386.31803,32.19311,651.68524,-0.13997,124.67505,32.61737
386.91803,32.24310,651.91444,-0.13997,124.87497,32.62884
387.51800,32.29308,652.10653,-0.13997,125.07492,32.63845
388.11800,32.34318,651.54005,-0.13997,125.27531,32.61010
388.71803,32.39311,651.57954,-0.13997,125.47504,32.61208
389.31803,32.44315,651.72175,-0.13997,125.67519,32.61920
389.91803,32.49320,652.50131,-0.13997,125.87538,32.65821
390.51800,32.54330,651.99598,-0.13997,126.07578,32.63292
391.11800,32.59322,652.09558,-0.13997,126.27548,32.63791
391.71803,32.64321,651.94708,-0.13997,126.47542,32.63047
392.31803,32.69319,652.98765,-0.13997,126.67536,32.68256
392.91803,32.74305,652.23859,-0.13997,126.87480,32.64507
393.51800,32.79310,652.60017,-0.13997,127.07499,32.66316
394.11800,32.84308,652.30452,-0.13997,127.27493,32.64837
394.71803,32.89313,653.25340,-0.13997,127.47511,32.69586
395.31803,32.94311,653.02355,-0.13997,127.67504,32.68435
395.91803,32.99322,653.44456,-0.13997,127.87546,32.70543
396.51800,33.04320,653.06537,-0.13997,128.07539,32.68644
397.11800,33.09319,653.53676,-0.13997,128.27533,32.71004
397.71803,33.14317,654.62287,-0.13997,128.47526,32.76440
398.31803,33.19309,654.23893,-0.13997,128.67496,32.74518
398.91803,33.24314,654.24205,-0.13998,128.87514,32.74534
399.51800,33.29312,655.12741,-0.13997,129.07507,32.78965
400.11800,33.34316,654.24233,-0.13997,129.27524,32.74535
400.71803,33.39315,654.30612,-0.13997,129.47519,32.74855
401.31803,33.44313,654.82864,-0.13997,129.67511,32.77470
401.91803,33.49312,655.11819,-0.13997,129.87505,32.78919
402.51800,33.54316,654.36387,-0.13997,130.07523,32.75143
403.11800,33.59320,654.93868,-0.13997,130.27540,32.78020
403.71803,33.64325,654.56545,-0.13997,130.47557,32.76152
404.31803,33.69317,654.94669,-0.13997,130.67528,32.78061
404.91803,33.74310,655.16820,-0.13997,130.87497,32.79169
405.51800,33.79314,656.06292,-0.13997,131.07514,32.83648
406.11800,33.84318,655.66651,-0.13997,131.27532,32.81664
406.71803,33.89317,656.02348,-0.13997,131.47527,32.83450
407.31803,33.94315,655.86660,-0.13997,131.67520,32.82665
407.91803,33.99314,656.06730,-0.13997,131.87513,32.83669
408.51800,34.04312,655.83833,-0.13997,132.07506,32.82523
409.11800,34.09310,655.90166,-0.13997,132.27501,32.82840
409.71803,34.14315,656.10996,-0.13997,132.47517,32.83883
410.31803,34.19313,655.81263,-0.13997,132.67512,32.82395
410.91803,34.24317,656.14479,-0.13997,132.87529,32.84057
411.51800,34.29310,656.01273,-0.13997,133.07500,32.83396
412.11800,34.34320,655.46120,-0.13997,133.27540,32.80636
412.71803,34.39307,654.94119,-0.13997,133.47487,32.78033
413.31803,34.44311,654.77765,-0.13997,133.67503,32.77215
413.91803,34.49321,654.87195,-0.13997,133.87545,32.77687
414.51800,34.54314,654.98520,-0.13998,134.07514,32.78254
415.11800,34.59318,654.92340,-0.13997,134.27532,32.77944
415.71803,34.64311,654.97374,-0.13997,134.47502,32.78196
416.31803,34.69321,654.69015,-0.13997,134.67544,32.76777
416.91803,34.74319,654.63958,-0.13997,134.87537,32.76524
417.51800,34.79324,654.44270,-0.13997,135.07556,32.75538
418.11800,34.84316,654.30664,-0.13997,135.27523,32.74857
418.71803,34.89315,654.21946,-0.13997,135.47518,32.74421
419.31803,34.94319,654.50002,-0.13997,135.67535,32.75825
419.91803,34.99318,654.54282,-0.13997,135.87530,32.76039
420.51800,35.04310,654.73719,-0.13998,136.07498,32.77012
421.11800,35.09314,653.86044,-0.13997,136.27517,32.72624
421.71803,35.14313,653.86426,-0.13997,136.47510,32.72643
422.31803,35.19317,653.79012,-0.13998,136.67527,32.72272
422.91803,35.24321,654.70440,-0.13997,136.87545,32.76848
423.51800,35.29326,654.86738,-0.13997,137.07563,32.77664
424.11800,35.34318,654.85304,-0.13997,137.27531,32.77592
424.71803,35.39323,654.36522,-0.13997,137.47549,32.75150
425.31803,35.44315,654.76294,-0.13997,137.67519,32.77141
425.91803,35.49314,655.13644,-0.13997,137.87514,32.79010
426.51800,35.54318,655.40788,-0.13997,138.07530,32.80369
427.11800,35.59310,655.74390,-0.13997,138.27500,32.82051
427.71803,35.64309,656.12816,-0.13997,138.47494,32.83974
428.31803,35.69307,654.98715,-0.13998,138.67488,32.78263
428.91803,35.74312,655.87154,-0.13997,138.87506,32.82690
429.51800,35.79322,655.64765,-0.13997,139.07547,32.81569
430.11800,35.84332,655.38520,-0.13997,139.27587,32.80256
430.71803,35.89325,655.84201,-0.13998,139.47557,32.82542
431.31803,35.94329,656.03419,-0.13997,139.67575,32.83504
431.91803,35.99316,655.15768,-0.13997,139.87522,32.79117
432.51800,36.04314,655.60732,-0.13997,140.07515,32.81367
433.11800,36.09318,655.23633,-0.13997,140.27532,32.79510
433.71803,36.14311,654.86692,-0.13997,140.47501,32.77662
434.31803,36.19315,654.94226,-0.13997,140.67520,32.78038
434.91803,36.24319,654.99838,-0.13997,140.87536,32.78320
435.51803,36.29318,654.48852,-0.13997,141.07531,32.75768
436.11800,36.34316,653.74444,-0.13997,141.27524,32.72043
436.71803,36.39327,654.15241,-0.13997,141.47565,32.74085
437.31803,36.44325,653.88642,-0.13997,141.67558,32.72754
437.91803,36.49330,653.70146,-0.13997,141.87577,32.71828
438.51803,36.54316,653.89182,-0.13997,142.07523,32.72781
439.11800,36.59302,653.92717,-0.13997,142.27468,32.72958
439.71803,36.64313,654.24833,-0.13997,142.47509,32.74566
440.31803,36.69317,653.77783,-0.13997,142.67528,32.72210
440.91803,36.74321,653.41075,-0.13997,142.87544,32.70373
441.51803,36.79308,654.20042,-0.13997,143.07489,32.74326
442.11800,36.84318,654.02095,-0.13997,143.27532,32.73427
442.71803,36.89317,655.11796,-0.13997,143.47526,32.78918
443.31803,36.94321,654.68126,-0.13997,143.67542,32.76732
443.91803,36.99319,655.07246,-0.13997,143.87537,32.78690
444.51803,37.04318,655.08555,-0.13997,144.07530,32.78756
445.11800,37.09316,655.63070,-0.13997,144.27524,32.81484
445.71803,37.14314,656.39596,-0.13997,144.47516,32.85315
446.31803,37.19319,656.82149,-0.13997,144.67535,32.87444
446.91803,37.24311,657.53572,-0.13997,144.87504,32.91019
447.51803,37.29316,657.26726,-0.13997,145.07523,32.89676
448.11800,37.34320,657.67989,-0.13997,145.27540,32.91740
448.71803,37.39319,657.26461,-0.13997,145.47533,32.89662
449.31803,37.44323,658.21828,-0.13997,145.67550,32.94435
449.91803,37.49315,658.41754,-0.13997,145.87519,32.95433
450.51803,37.54326,657.75099,-0.13997,146.07562,32.92096
451.11800,37.59324,658.36366,-0.13997,146.27557,32.95163
451.71803,37.64328,658.41023,-0.13998,146.47572,32.95396
452.31803,37.69315,658.94630,-0.13997,146.67517,32.98079
452.91803,37.74313,658.54257,-0.13997,146.87512,32.96058
453.51803,37.79318,658.25675,-0.13997,147.07531,32.94628
454.11800,37.84316,658.00808,-0.13997,147.27523,32.93383
454.71803,37.89314,658.73484,-0.13997,147.47516,32.97021
455.31803,37.94313,658.75477,-0.13997,147.67511,32.97120
455.91803,37.99323,658.46788,-0.13997,147.87552,32.95684
456.51803,38.04322,658.30508,-0.13997,148.07546,32.94870
457.11800,38.09326,658.30965,-0.13997,148.27564,32.94893
457.71803,38.14325,657.67020,-0.13997,148.47558,32.91692
458.31803,38.19323,657.68692,-0.13997,148.67550,32.91776
458.91803,38.24315,657.97786,-0.13997,148.87520,32.93232
459.51803,38.29308,657.93945,-0.13997,149.07490,32.93040
460.11800,38.34312,658.05721,-0.13997,149.27508,32.93629
460.71803,38.39316,657.70000,-0.13997,149.47524,32.91841
461.31803,38.44315,658.01493,-0.13997,149.67519,32.93417
461.91803,38.49313,657.56845,-0.13997,149.87512,32.91183
462.51803,38.54318,658.09749,-0.13997,150.07529,32.93831
463.11800,38.59322,658.08268,-0.13997,150.27547,32.93756
463.71803,38.64320,658.08627,-0.13997,150.47541,32.93774
464.31803,38.69331,658.25237,-0.13997,150.67583,32.94606
464.91803,38.74317,658.44436,-0.13997,150.87528,32.95567
465.51803,38.79315,657.58727,-0.13997,151.07521,32.91277
466.11800,38.84308,658.41875,-0.13998,151.27491,32.95439
466.71803,38.89306,658.37167,-0.13997,151.47483,32.95203
467.31803,38.94311,657.42377,-0.13997,151.67502,32.90459
467.91803,38.99309,657.51462,-0.13997,151.87496,32.90913
468.51803,39.04308,657.81497,-0.13997,152.07490,32.92417
469.11800,39.09318,657.33059,-0.13997,152.27530,32.89992
469.71803,39.14322,657.13855,-0.13997,152.47548,32.89031
470.31803,39.19321,657.35155,-0.13997,152.67541,32.90097
470.91803,39.24319,656.81036,-0.13997,152.87535,32.87389
471.51803,39.29323,657.30549,-0.13997,153.07552,32.89867
472.11800,39.34316,656.57427,-0.13997,153.27523,32.86207
472.71803,39.39314,657.32463,-0.13997,153.47517,32.89962
473.31803,39.44307,656.98121,-0.13997,153.67485,32.88243
473.91803,39.49311,656.47098,-0.13997,153.87503,32.85690
474.51803,39.54316,656.44090,-0.13997,154.07522,32.85539
475.11800,39.59320,656.50265,-0.13997,154.27537,32.85848
475.71803,39.64306,656.88374,-0.13997,154.47484,32.87756
476.31803,39.69322,656.00397,-0.13997,154.67548,32.83352
476.91803,39.74315,656.67974,-0.13997,154.87520,32.86735
477.51803,39.79325,657.14531,-0.13998,155.07560,32.89065
478.11800,39.84306,656.95001,-0.13997,155.27483,32.88087
478.71803,39.89310,656.77967,-0.13997,155.47500,32.87235
479.31803,39.94314,657.37660,-0.13997,155.67517,32.90223
479.91803,39.99313,656.83909,-0.13997,155.87511,32.87532
480.51803,40.04317,656.78363,-0.13997,156.07529,32.87255
481.11800,40.09310,656.78232,-0.13997,156.27497,32.87248
481.71803,40.14314,657.21809,-0.13998,156.47516,32.89429
482.31803,40.19319,656.86950,-0.13997,156.67534,32.87685
482.91803,40.24317,656.81147,-0.13997,156.87528,32.87394
483.51803,40.29321,656.60221,-0.13997,157.07543,32.86347
484.11800,40.34314,656.63089,-0.13997,157.27514,32.86490
484.71803,40.39318,656.26767,-0.13997,157.47530,32.84672
485.31803,40.44311,656.60356,-0.13997,157.67502,32.86353
485.91803,40.49321,656.08067,-0.13997,157.87542,32.83736
486.51803,40.54307,656.07778,-0.13997,158.07489,32.83722
487.11800,40.59311,656.47438,-0.13997,158.27504,32.85707
487.71803,40.64316,656.18451,-0.13997,158.47524,32.84256
488.31803,40.69314,656.32029,-0.13997,158.67517,32.84936
488.91803,40.74319,656.43163,-0.13997,158.87535,32.85493
489.51803,40.79317,656.88412,-0.13998,159.07528,32.87757
490.11800,40.84322,656.72928,-0.13997,159.27546,32.86983
490.71803,40.89320,656.56225,-0.13997,159.47540,32.86147
491.31803,40.94318,656.99886,-0.13997,159.67534,32.88332
491.91803,40.99311,656.94470,-0.13997,159.87502,32.88061
492.51803,41.04309,656.89231,-0.13997,160.07496,32.87799
493.11800,41.09308,656.43238,-0.13997,160.27490,32.85497
493.71803,41.14306,656.69208,-0.13997,160.47484,32.86797
494.31803,41.19311,656.35247,-0.13997,160.67501,32.85097
494.91803,41.24315,656.98950,-0.13997,160.87519,32.88285
495.51803,41.29319,656.41156,-0.13997,161.07535,32.85392
496.11800,41.34318,656.75178,-0.13997,161.27530,32.87095
496.71803,41.39322,656.43732,-0.13997,161.47547,32.85521
497.31803,41.44321,656.13557,-0.13997,161.67542,32.84011
497.91803,41.49319,656.33794,-0.13997,161.87534,32.85024
498.51803,41.54318,656.07768,-0.13997,162.07529,32.83722
499.11800,41.59315,656.34167,-0.13997,162.27521,32.85043
499.71803,41.64308,656.30921,-0.13997,162.47492,32.84880
500.31803,41.69312,655.54250,-0.13997,162.67508,32.81043
500.91803,41.74311,654.95889,-0.13997,162.87503,32.78122
501.51803,41.79309,653.90323,-0.13997,163.07496,32.72838
502.11800,41.84320,651.83584,-0.13997,163.27537,32.62490
502.71803,41.89312,648.70915,-0.13997,163.47507,32.46841
503.31803,41.94323,644.35592,-0.13997,163.67549,32.25053
503.91803,41.99321,635.61662,-0.13997,163.87542,31.81312
504.51803,42.04307,612.38199,-0.13998,164.07487,30.65021
504.65603,42.05467,7.96767,-0.13997,164.12128,0.39879