File: Manufatura Aditiva/Dados/Ensaios AMR/Ensaios/Ensaios FDM/Tracao_OLABI_25_05_2018_FDM_YZ5.is_metal_RawData/Specimen_RawData_4.csv
Time,Extension,Load,Strain 1,Tensile strain,Tensile stress
(sec),(mm),(N),(mm/mm),(%),(MPa)
0.00000,0.00000,11.04531,0.00080,0.08049,0.53962
0.60000,0.04986,32.89432,0.00169,0.16929,1.60707
1.20000,0.10003,55.01454,0.00263,0.26306,2.68777
1.80000,0.14995,77.15878,0.00357,0.35740,3.76964
2.40000,0.20000,99.47882,0.00452,0.45176,4.86009
3.00000,0.24998,120.83008,0.00547,0.54656,5.90322
3.60000,0.30002,142.58990,0.00641,0.64105,6.96631
4.20000,0.35001,164.75191,0.00736,0.73624,8.04905
4.80000,0.40005,186.30009,0.00832,0.83198,9.10180
5.40000,0.45010,207.37734,0.00927,0.92732,10.13154
6.00000,0.50002,228.77522,0.01022,1.02246,11.17694
6.60000,0.55000,249.81091,0.01118,1.11824,12.20465
7.20000,0.59993,270.91580,0.01215,1.21464,13.23574
7.80000,0.64997,291.76471,0.01310,1.31007,14.25433
8.40000,0.70002,312.27788,0.01406,1.40602,15.25651
9.00000,0.75000,332.89385,0.01502,1.50156,16.26372
9.60000,0.79992,352.29637,0.01598,1.59800,17.21164
10.20000,0.85003,372.47594,0.01694,1.69396,18.19752
10.80000,0.89995,391.63916,0.01786,1.78626,19.13375
11.40000,0.95006,410.77333,0.01883,1.88277,20.06856
12.00000,1.00010,431.05986,0.01979,1.97928,21.05967
12.60000,1.05008,450.81144,0.02075,2.07505,22.02464
13.20000,1.10001,469.20106,0.02172,2.17206,22.92308
13.80000,1.14993,488.93699,0.02269,2.26949,23.88729
14.40000,1.19998,506.90915,0.02368,2.36756,24.76533
15.00000,1.24996,525.70542,0.02466,2.46553,25.68363
15.60000,1.29994,542.40450,0.02563,2.56287,26.49948
16.20000,1.34993,559.34866,0.02659,2.65931,27.32729
16.80000,1.40003,577.16509,0.02758,2.75815,28.19772
17.40000,1.45001,594.73910,0.02857,2.85719,29.05631
18.00000,1.49994,611.36689,0.02957,2.95673,29.86867
18.60000,1.55004,627.30596,0.03057,3.05682,30.64738
19.12000,1.59327,640.85457,0.03143,3.21306,31.30931
19.72000,1.64343,657.06740,0.03245,3.41371,32.10139
20.32000,1.69336,673.00675,0.03346,3.61341,32.88012
20.92000,1.74340,687.40593,0.03446,3.81359,33.58360
21.52000,1.79333,701.30685,0.03304,4.01328,34.26274
22.12000,1.84331,716.35060,0.03161,4.21322,34.99771
22.72000,1.89329,729.54623,0.03060,4.41316,35.64239
23.32000,1.94328,743.69540,0.02525,4.61309,36.33365
23.92000,1.99332,756.39454,-0.12378,4.81327,36.95408
24.52000,2.04337,769.73443,-0.11661,5.01344,37.60580
25.12000,2.09335,781.59366,-0.28565,5.21338,38.18520
25.72000,2.14333,793.13600,-0.28573,5.41331,38.74910
26.32000,2.19332,804.40752,-0.28574,5.61325,39.29978
26.92000,2.24336,815.06753,-0.28575,5.81343,39.82058
27.52000,2.29341,825.70249,-0.28576,6.01360,40.34016
28.12000,2.34333,835.99016,-0.28576,6.21330,40.84277
28.72000,2.39319,844.68666,-0.28577,6.41275,41.26764
29.32000,2.44324,855.06914,-0.28577,6.61293,41.77488
29.92000,2.49328,862.31539,-0.28578,6.81311,42.12890
30.52000,2.54339,869.84718,-0.28578,7.01352,42.49687
31.12000,2.59331,875.88634,-0.28578,7.21322,42.79192
31.72000,2.64335,881.95540,-0.28579,7.41339,43.08842
32.32000,2.69334,887.18813,-0.28579,7.61333,43.34407
32.92000,2.74338,892.53280,-0.28579,7.81350,43.60519
33.52000,2.79336,897.18392,-0.28579,8.01344,43.83242
34.12000,2.84335,900.76067,-0.28579,8.21338,44.00716
34.72000,2.89339,903.36036,-0.28579,8.41355,44.13417
35.32000,2.94332,904.42896,-0.28580,8.61325,44.18638
35.92000,2.99330,906.79331,-0.28580,8.81318,44.30190
36.52000,3.04323,907.84067,-0.28579,9.01288,44.35306
37.12000,3.09327,907.82968,-0.28580,9.21306,44.35253
37.72000,3.14325,907.63234,-0.28580,9.41299,44.34288
38.32000,3.19336,906.25612,-0.28580,9.61341,44.27565
38.92000,3.24334,905.12233,-0.28580,9.81334,44.22026
39.52000,3.29332,902.82084,-0.28580,10.01328,44.10781
40.12000,3.34343,901.21543,-0.28581,10.21369,44.02938
40.72000,3.39335,898.25839,-0.28581,10.41339,43.88491
41.32000,3.44340,894.94120,-0.28581,10.61357,43.72285
41.92000,3.49332,892.59399,-0.28581,10.81326,43.60818
42.52000,3.54324,888.18893,-0.28581,11.01296,43.39297
43.12000,3.59323,884.54802,-0.28581,11.21289,43.21509
43.72000,3.64327,881.13835,-0.28581,11.41307,43.04851
44.32000,3.69332,877.50824,-0.28581,11.61325,42.87115
44.92000,3.74324,874.01941,-0.28581,11.81294,42.70071
45.52000,3.79334,869.64406,-0.28581,12.01336,42.48695
46.12000,3.84333,866.22331,-0.28581,12.21329,42.31982
46.72000,3.89337,862.34976,-0.28581,12.41347,42.13058
47.32000,3.94336,858.62884,-0.28581,12.61340,41.94879
47.92000,3.99334,854.73359,-0.28582,12.81334,41.75849
48.52000,4.04332,851.08615,-0.28581,13.01327,41.58029
49.12000,4.09331,847.93642,-0.28582,13.21321,41.42641
49.72000,4.14329,844.57286,-0.28581,13.41315,41.26208
50.32000,4.19334,840.68011,-0.28582,13.61332,41.07190
50.92000,4.24332,836.81177,-0.28582,13.81326,40.88291
51.52000,4.29330,832.70390,-0.28582,14.01320,40.68221
52.12000,4.34329,829.50955,-0.28582,14.21313,40.52615
52.72000,4.39327,825.06984,-0.28582,14.41307,40.30925
53.32000,4.44338,821.15009,-0.28582,14.61348,40.11775
53.92000,4.49336,817.24748,-0.28582,14.81342,39.92708
54.52000,4.54328,813.00326,-0.28582,15.01312,39.71973
55.12000,4.59333,808.96793,-0.28582,15.21329,39.52258
55.72000,4.64331,803.93841,-0.28582,15.41323,39.27686
56.32000,4.69330,799.25861,-0.28582,15.61316,39.04823
56.92000,4.74322,794.17313,-0.28582,15.81286,38.79977
57.52000,4.79332,787.86528,-0.28582,16.01327,38.49160
58.12000,4.84331,782.57667,-0.28582,16.21321,38.23322
58.72000,4.89335,775.16660,-0.28582,16.41338,37.87120
59.32000,4.94334,767.80282,-0.28583,16.61332,37.51144
59.92000,4.99332,760.50996,-0.28582,16.81326,37.15514
60.52000,5.04336,752.55106,-0.28583,17.01343,36.76630
61.12000,5.09329,743.83607,-0.28582,17.21313,36.34053
61.72000,5.14333,734.82813,-0.28583,17.41330,35.90044
62.32000,5.19326,725.45200,-0.28583,17.61300,35.44236
62.92000,5.24330,716.48592,-0.28583,17.81317,35.00432
63.52000,5.29334,706.75025,-0.28583,18.01335,34.52868
64.12000,5.34327,697.96625,-0.28583,18.21305,34.09953
64.72000,5.39337,689.62323,-0.28583,18.41346,33.69193
65.32000,5.44329,681.86275,-0.28583,18.61316,33.31279
65.92001,5.49334,675.23415,-0.28583,18.81334,32.98894
66.52001,5.54338,668.93990,-0.28583,19.01351,32.68143
67.12000,5.59343,664.10271,-0.28583,19.21368,32.44511
67.72000,5.64329,659.87408,-0.28583,19.41314,32.23852
68.32000,5.69328,656.47857,-0.28583,19.61308,32.07263
68.92001,5.74332,653.65341,-0.28583,19.81325,31.93460
69.52001,5.79330,651.49381,-0.28583,20.01319,31.82909
70.12000,5.84335,649.78744,-0.28583,20.21337,31.74573
70.72000,5.89327,647.49480,-0.28583,20.41306,31.63372
71.32000,5.94331,646.71063,-0.28583,20.61324,31.59541
71.92001,5.99336,645.97731,-0.28583,20.81341,31.55958
72.52001,6.04334,645.48417,-0.28583,21.01335,31.53549
73.12000,6.09339,644.53394,-0.28583,21.21352,31.48907
73.72000,6.14331,645.03462,-0.28583,21.41322,31.51353
74.32001,6.19335,645.19322,-0.28583,21.61340,31.52127
74.92001,6.24328,644.51168,-0.28583,21.81309,31.48798
75.52001,6.29338,645.52897,-0.28583,22.01351,31.53768
76.12000,6.34325,645.93744,-0.28583,22.21297,31.55763
76.72000,6.39329,645.64990,-0.28583,22.41314,31.54359
77.32001,6.44327,646.30075,-0.28583,22.61308,31.57538
77.92001,6.49332,646.16096,-0.28583,22.81325,31.56855
78.52001,6.54342,646.62211,-0.28583,23.01367,31.59108
79.12000,6.59335,647.65103,-0.28583,23.21336,31.64135
79.72000,6.64339,647.23860,-0.28583,23.41354,31.62120
80.32001,6.69337,648.31837,-0.28583,23.61347,31.67396
80.92001,6.74336,648.30012,-0.28583,23.81341,31.67307
81.52001,6.79328,648.90441,-0.28583,24.01311,31.70259
82.12000,6.84333,649.38576,-0.28583,24.21328,31.72610
82.72000,6.89331,649.66371,-0.28584,24.41322,31.73968
83.32001,6.94329,649.64988,-0.28584,24.61315,31.73901
83.92001,6.99328,650.44598,-0.28583,24.81309,31.77790
84.52001,7.04326,650.79518,-0.28584,25.01303,31.79496
85.12000,7.09337,650.51778,-0.28584,25.21344,31.78141
85.72000,7.14341,650.07834,-0.28584,25.41362,31.75994
86.32001,7.19339,650.28430,-0.28584,25.61355,31.77000
86.92001,7.24338,650.12230,-0.28583,25.81349,31.76209
87.52001,7.29336,650.13422,-0.28584,26.01342,31.76267
88.12000,7.34335,650.41417,-0.28584,26.21336,31.77635
88.72000,7.39339,649.91517,-0.28584,26.41354,31.75197
89.32001,7.44337,650.23606,-0.28584,26.61347,31.76764
89.92001,7.49336,650.89315,-0.28584,26.81341,31.79975
90.52001,7.54334,650.76011,-0.28584,27.01334,31.79325
91.12000,7.59327,650.77399,-0.28584,27.21304,31.79393
91.72000,7.64337,650.87005,-0.28584,27.41345,31.79862
92.32001,7.69335,651.18498,-0.28584,27.61339,31.81401
92.92001,7.74346,651.34219,-0.28584,27.81380,31.82169
93.52001,7.79338,651.31960,-0.28584,28.01350,31.82058
94.12000,7.84330,651.83076,-0.28584,28.21320,31.84556
94.72000,7.89329,652.08892,-0.28584,28.41313,31.85817
95.32001,7.94327,652.12403,-0.28584,28.61307,31.85988
95.92001,7.99338,651.76440,-0.28584,28.81349,31.84231
96.52001,8.04336,652.81149,-0.28584,29.01342,31.89347
97.12000,8.09334,651.92254,-0.28584,29.21335,31.85004
97.72000,8.14327,651.62564,-0.28584,29.41305,31.83554
98.32001,8.19331,652.11332,-0.28584,29.61323,31.85936
98.92001,8.24342,652.42909,-0.28584,29.81365,31.87479
99.52001,8.29340,652.71822,-0.28584,30.01358,31.88891
100.12000,8.34338,653.26174,-0.28584,30.21351,31.91547
100.72000,8.39331,653.23911,-0.28584,30.41321,31.91436
101.32001,8.44335,653.72670,-0.28584,30.61339,31.93818
101.92001,8.49328,654.54114,-0.28584,30.81309,31.97797
102.52001,8.54326,654.29085,-0.28584,31.01302,31.96574
103.12000,8.59330,655.00857,-0.28584,31.21319,32.00081
103.72000,8.64329,654.81379,-0.28584,31.41313,31.99129
104.32001,8.69333,654.82710,-0.28584,31.61331,31.99194
104.92001,8.74326,655.45696,-0.28584,31.81300,32.02272
105.52001,8.79342,656.34688,-0.28584,32.01365,32.06619
106.12000,8.84340,656.22125,-0.28584,32.21359,32.06005
106.72001,8.89351,655.99075,-0.28585,32.41401,32.04879
107.32001,8.94343,656.80742,-0.28584,32.61370,32.08869
107.92001,8.99330,657.74415,-0.28584,32.81316,32.13446
108.52001,9.04334,656.87248,-0.28584,33.01334,32.09187
109.12000,9.09332,656.57976,-0.28584,33.21327,32.07757
109.72001,9.14331,657.13315,-0.28584,33.41321,32.10461
110.32001,9.19323,656.95704,-0.28584,33.61291,32.09600
110.92001,9.24334,657.46885,-0.28584,33.81332,32.12101
111.52001,9.29332,657.97823,-0.28584,34.01326,32.14589
112.12000,9.34336,657.69795,-0.28584,34.21343,32.13220
112.72001,9.39341,658.32729,-0.28584,34.41361,32.16295
113.32001,9.44339,658.02261,-0.28584,34.61354,32.14806
113.92001,9.49338,658.00431,-0.28585,34.81348,32.14717
114.52001,9.54330,657.71402,-0.28584,35.01318,32.13298
115.12000,9.59334,657.60007,-0.28584,35.21335,32.12742
115.72001,9.64327,657.28752,-0.28585,35.41305,32.11215
116.32001,9.69331,657.98280,-0.28584,35.61323,32.14612
116.92001,9.74330,656.89785,-0.28584,35.81316,32.09311
117.52001,9.79340,656.29855,-0.28584,36.01357,32.06383
118.12000,9.84326,656.53091,-0.28584,36.21303,32.07518
118.72001,9.89337,656.61250,-0.28585,36.41344,32.07917
119.32001,9.94341,656.11759,-0.28584,36.61362,32.05499
119.92001,9.99345,655.77170,-0.28584,36.81380,32.03809
120.52001,10.04338,656.76225,-0.28584,37.01349,32.08649
121.12000,10.09330,656.68742,-0.28584,37.21319,32.08283
121.72001,10.14329,656.83662,-0.28584,37.41313,32.09012
122.32001,10.19327,657.18577,-0.28585,37.61306,32.10718
122.92001,10.24332,656.75932,-0.28584,37.81324,32.08634
123.52001,10.29330,656.68835,-0.28585,38.01318,32.08288
124.12000,10.34328,657.40612,-0.28585,38.21311,32.11794
124.72001,10.39333,656.91867,-0.28584,38.41329,32.09413
125.32001,10.44331,657.55318,-0.28584,38.61322,32.12513
125.92001,10.49341,658.21884,-0.28585,38.81364,32.15765
126.52001,10.54334,658.32278,-0.28584,39.01334,32.16273
127.12000,10.59344,658.20795,-0.28584,39.21375,32.15712
127.72001,10.64331,658.15770,-0.28584,39.41321,32.15466
128.32001,10.69329,658.25502,-0.28584,39.61314,32.15942
128.92002,10.74333,658.00571,-0.28585,39.81332,32.14724
129.52001,10.79326,659.23454,-0.28584,40.01301,32.20727
130.12001,10.84336,658.95943,-0.28585,40.21343,32.19383
130.72000,10.89323,658.56106,-0.28585,40.41288,32.17437
131.32000,10.94333,659.17736,-0.28585,40.61330,32.20448
131.92002,10.99337,659.48986,-0.28585,40.81348,32.21975
132.52000,11.04342,659.70435,-0.28585,41.01365,32.23022
133.12002,11.09340,659.35077,-0.28585,41.21359,32.21295
133.72000,11.14333,660.11078,-0.28585,41.41329,32.25008
134.32000,11.19337,660.30626,-0.28585,41.61346,32.25963
134.92002,11.24329,659.81606,-0.28585,41.81316,32.23568
135.52000,11.29334,660.10389,-0.28585,42.01333,32.24974
136.12002,11.34320,660.81248,-0.28585,42.21279,32.28436
136.72000,11.39325,660.50044,-0.28585,42.41296,32.26912
137.32000,11.44329,660.29048,-0.28585,42.61314,32.25886
137.92002,11.49333,659.92698,-0.28585,42.81332,32.24110
138.52000,11.54338,660.43697,-0.28585,43.01349,32.26602
139.12002,11.59330,659.59059,-0.28585,43.21319,32.22467
139.72000,11.64341,659.75087,-0.28585,43.41360,32.23250
140.32000,11.69333,659.85564,-0.28585,43.61329,32.23762
140.92002,11.74337,659.71003,-0.28585,43.81347,32.23050
141.52000,11.79330,660.00763,-0.28585,44.01317,32.24504
142.12002,11.84328,660.09662,-0.28585,44.21310,32.24939
142.72000,11.89332,659.52982,-0.28585,44.41328,32.22170
143.32000,11.94331,659.79413,-0.28585,44.61321,32.23461
143.92002,11.99335,660.13746,-0.28585,44.81339,32.25138
144.52000,12.04328,660.12447,-0.28585,45.01309,32.25075
145.12002,12.09344,660.00605,-0.28585,45.21374,32.24496
145.72000,12.14336,659.13843,-0.28585,45.41344,32.20258
146.32000,12.19341,659.71180,-0.28585,45.61362,32.23059
146.92002,12.24333,659.62519,-0.28585,45.81331,32.22636
147.52000,12.29326,659.95539,-0.28585,46.01301,32.24249
148.12002,12.34324,660.18542,-0.28585,46.21295,32.25373
148.72000,12.39329,658.96162,-0.28585,46.41312,32.19394
149.32000,12.44333,659.55957,-0.28585,46.61329,32.22315
149.92002,12.49325,659.69429,-0.28585,46.81299,32.22973
150.52000,12.54330,659.32111,-0.28585,47.01317,32.21150
151.12002,12.59328,659.24171,-0.28585,47.21310,32.20762
151.72000,12.64338,658.80837,-0.28585,47.41351,32.18645
152.32000,12.69331,659.64679,-0.28585,47.61321,32.22741
152.92002,12.74335,659.97387,-0.28585,47.81339,32.24339
153.52000,12.79328,659.57601,-0.28585,48.01309,32.22395
154.12002,12.84332,659.84074,-0.28585,48.21326,32.23689
154.72000,12.89336,659.72009,-0.28585,48.41344,32.23100
155.32000,12.94323,660.33201,-0.28585,48.61290,32.26089
155.92002,12.99339,660.05611,-0.28585,48.81355,32.24741
156.52000,13.04332,660.58547,-0.28585,49.01325,32.27327
157.12002,13.09336,660.75055,-0.28585,49.21342,32.28134
157.72000,13.14329,660.88820,-0.28585,49.41312,32.28806
158.32000,13.19333,660.34882,-0.28585,49.61329,32.26171
158.92002,13.24337,660.46878,-0.28586,49.81347,32.26757
159.52000,13.29330,661.29868,-0.28585,50.01317,32.30812
160.12002,13.34334,661.15856,-0.28586,50.21334,32.30127
160.72000,13.39326,660.74752,-0.28586,50.41304,32.28119
161.32000,13.44337,661.51908,-0.28585,50.61345,32.31889
161.92002,13.49323,661.01537,-0.28585,50.81291,32.29427
162.52000,13.54322,661.26878,-0.28585,51.01285,32.30666
163.12002,13.59326,660.86422,-0.28585,51.21302,32.28689
163.72000,13.64324,660.97751,-0.28585,51.41296,32.29243
164.32000,13.69335,660.76103,-0.28585,51.61337,32.28185
164.92002,13.74333,661.32084,-0.28586,51.81330,32.30920
165.52000,13.79338,661.12019,-0.28585,52.01349,32.29940
166.12002,13.84336,660.56722,-0.28585,52.21342,32.27238
166.72000,13.89340,659.89611,-0.28585,52.41359,32.23959
167.32000,13.94333,660.32419,-0.28585,52.61329,32.26051
167.92002,13.99331,660.24247,-0.28586,52.81323,32.25652
168.52000,14.04330,659.49545,-0.28585,53.01316,32.22002
169.12002,14.09328,659.65350,-0.28586,53.21310,32.22774
169.72000,14.14332,659.15324,-0.28586,53.41328,32.20330
170.32000,14.19325,659.02048,-0.28586,53.61298,32.19681
170.92002,14.24329,659.26281,-0.28585,53.81315,32.20865
171.52000,14.29340,658.93685,-0.28585,54.01356,32.19273
172.12002,14.34344,658.60311,-0.28586,54.21373,32.17642
172.72000,14.39342,659.19254,-0.28585,54.41367,32.20522
173.32000,14.44335,658.51994,-0.28585,54.61337,32.17236
173.92002,14.49333,658.31067,-0.28586,54.81331,32.16214
174.52000,14.54332,658.78276,-0.28585,55.01324,32.18520
175.12002,14.59336,658.70392,-0.28585,55.21342,32.18135
175.72000,14.64328,659.23482,-0.28586,55.41312,32.20729
176.32000,14.69327,658.66825,-0.28586,55.61305,32.17960
176.92002,14.74325,659.02038,-0.28586,55.81298,32.19681
177.52000,14.79330,658.70532,-0.28585,56.01316,32.18142
178.12002,14.84340,659.47222,-0.28586,56.21358,32.21888
178.72000,14.89338,659.21713,-0.28585,56.41351,32.20642
179.32000,14.94349,659.28986,-0.28586,56.61392,32.20998
179.92002,14.99335,659.19617,-0.28585,56.81338,32.20540
180.52000,15.04340,659.57531,-0.28586,57.01356,32.22392
181.12002,15.09326,659.23533,-0.28585,57.21301,32.20731
181.72000,15.14330,658.84315,-0.28585,57.41320,32.18815
182.32000,15.19335,659.09601,-0.28585,57.61337,32.20050
182.92002,15.24339,659.07515,-0.28586,57.81354,32.19949
183.52000,15.29332,660.07627,-0.28585,58.01324,32.24839
184.12002,15.34330,659.13084,-0.28585,58.21317,32.20221
184.72000,15.39334,659.96023,-0.28586,58.41335,32.24273
185.32000,15.44339,660.22044,-0.28585,58.61353,32.25544
185.92002,15.49343,660.42854,-0.28586,58.81370,32.26561
186.52000,15.54329,660.78533,-0.28585,59.01316,32.28304
187.12002,15.59334,660.22319,-0.28586,59.21333,32.25557
187.72002,15.64332,660.92727,-0.28586,59.41327,32.28997
188.32000,15.69325,660.89467,-0.28586,59.61296,32.28838
188.92002,15.74329,661.55554,-0.28586,59.81314,32.32066
189.52000,15.79327,660.80871,-0.28585,60.01307,32.28418
190.12002,15.84338,660.89928,-0.28586,60.21349,32.28860
190.72002,15.89330,660.62706,-0.28586,60.41319,32.27530
191.32000,15.94341,660.27418,-0.28586,60.61361,32.25806
191.92002,15.99333,660.57327,-0.28586,60.81330,32.27267
192.52000,16.04343,661.28913,-0.28586,61.01372,32.30765
193.12002,16.09336,660.46845,-0.28586,61.21340,32.26756
193.72002,16.14334,660.22584,-0.28586,61.41334,32.25570
194.32000,16.19332,659.76912,-0.28586,61.61328,32.23339
194.92002,16.24331,660.17271,-0.28586,61.81321,32.25311
195.52000,16.29335,658.95244,-0.28586,62.01339,32.19349
196.12002,16.34328,660.17918,-0.28586,62.21309,32.25342
196.72002,16.39326,659.34048,-0.28586,62.41302,32.21245
197.32000,16.44325,659.94207,-0.28586,62.61296,32.24184
197.92002,16.49335,659.43077,-0.28586,62.81338,32.21686
198.52000,16.54339,660.25439,-0.28586,63.01355,32.25710
199.12002,16.59338,660.11711,-0.28586,63.21349,32.25039
199.72002,16.64336,660.22696,-0.28586,63.41342,32.25576
200.32000,16.69329,660.48671,-0.28586,63.61312,32.26845
200.92002,16.74333,661.47912,-0.28586,63.81329,32.31693
201.52000,16.79325,661.22166,-0.28586,64.01299,32.30435
202.12002,16.84330,661.73123,-0.28586,64.21317,32.32925
202.72002,16.89328,660.84275,-0.28586,64.41311,32.28584
203.32000,16.94327,661.22357,-0.28586,64.61304,32.30445
203.92002,16.99331,661.55251,-0.28586,64.81321,32.32052
204.52000,17.04329,661.43260,-0.28586,65.01315,32.31466
205.12002,17.09334,660.95134,-0.28586,65.21332,32.29115
205.72002,17.14344,660.95982,-0.28586,65.41374,32.29156
206.32000,17.19348,660.78687,-0.28586,65.61392,32.28311
206.92002,17.24341,660.45276,-0.28586,65.81361,32.26679
207.52000,17.29327,660.18938,-0.28586,66.01307,32.25392
208.12002,17.34326,661.36853,-0.28586,66.21301,32.31153
208.72002,17.39324,660.84615,-0.28586,66.41294,32.28601
209.32000,17.44334,661.08354,-0.28586,66.61336,32.29761
209.92002,17.49327,660.69532,-0.28586,66.81305,32.27864
210.52000,17.54331,661.48499,-0.28586,67.01323,32.31722
211.12002,17.59330,661.56671,-0.28586,67.21317,32.32121
211.72002,17.64340,662.00825,-0.28587,67.41358,32.34278
212.32000,17.69338,661.35991,-0.28586,67.61351,32.31111
212.92002,17.74337,661.44997,-0.28586,67.81345,32.31551
213.52000,17.79335,661.93077,-0.28586,68.01339,32.33900
214.12002,17.84334,662.90046,-0.28586,68.21333,32.38637
214.72002,17.89332,662.73762,-0.28587,68.41326,32.37842
215.32000,17.94324,663.04109,-0.28586,68.61296,32.39324
215.92002,17.99329,662.50409,-0.28586,68.81313,32.36701
216.52000,18.04327,662.07256,-0.28586,69.01307,32.34592
217.12002,18.09338,662.09668,-0.28586,69.21348,32.34710
217.72002,18.14330,662.15508,-0.28586,69.41318,32.34996
218.32000,18.19334,661.91819,-0.28586,69.61336,32.33838
218.92002,18.24339,661.51195,-0.28586,69.81353,32.31853
219.52000,18.29331,661.81705,-0.28586,70.01323,32.33344
220.12002,18.34336,661.42464,-0.28586,70.21340,32.31427
220.72002,18.39328,662.21743,-0.28586,70.41310,32.35300
221.32000,18.44332,661.65677,-0.28586,70.61328,32.32561
221.92002,18.49331,661.36918,-0.28586,70.81321,32.31156
222.52000,18.54335,661.65230,-0.28586,71.01339,32.32539
223.12002,18.59328,660.96550,-0.28587,71.21308,32.29184
223.72002,18.64326,661.26655,-0.28586,71.41302,32.30655
224.32000,18.69336,661.38729,-0.28587,71.61343,32.31245
224.92002,18.74329,660.86943,-0.28586,71.81313,32.28714
225.52000,18.79345,660.98091,-0.28586,72.01378,32.29259
226.12002,18.84332,661.51703,-0.28586,72.21324,32.31878
226.72002,18.89330,661.48671,-0.28586,72.41318,32.31730
227.32000,18.94322,662.06492,-0.28586,72.61288,32.34555
227.92002,18.99327,661.18198,-0.28586,72.81305,32.30241
228.52000,19.04331,661.87009,-0.28586,73.01322,32.33603
229.12002,19.09324,662.21543,-0.28587,73.21292,32.35291
229.72002,19.14340,662.19619,-0.28586,73.41357,32.35197
230.32000,19.19332,662.68630,-0.28587,73.61327,32.37591
230.92002,19.24337,662.57790,-0.28587,73.81345,32.37061
231.52000,19.29335,663.32864,-0.28586,74.01339,32.40729
232.12002,19.34340,662.66805,-0.28587,74.21356,32.37502
232.72002,19.39338,662.91015,-0.28586,74.41350,32.38684
233.32000,19.44330,662.23419,-0.28586,74.61320,32.35382
233.92002,19.49329,662.83112,-0.28586,74.81313,32.38298
234.52000,19.54327,662.42418,-0.28587,75.01307,32.36310
235.12002,19.59332,662.68756,-0.28586,75.21324,32.37597
235.72002,19.64324,663.11131,-0.28587,75.41294,32.39668
236.32000,19.69322,663.65483,-0.28587,75.61287,32.42323
236.92002,19.74333,663.29353,-0.28587,75.81328,32.40557
237.52000,19.79337,663.47709,-0.28587,76.01346,32.41454
238.12002,19.84341,663.71164,-0.28586,76.21363,32.42600
238.72002,19.89328,664.37894,-0.28586,76.41309,32.45860
239.32000,19.94338,664.25167,-0.28587,76.61350,32.45238
239.92002,19.99331,664.30685,-0.28587,76.81321,32.45508
240.52000,20.04335,664.09782,-0.28587,77.01338,32.44487
241.12002,20.09328,664.06447,-0.28587,77.21308,32.44324
241.72002,20.14332,664.26829,-0.28586,77.41325,32.45320
242.32000,20.19324,664.33884,-0.28587,77.61295,32.45665
242.92002,20.24329,663.96855,-0.28586,77.81312,32.43855
243.52000,20.29333,664.21628,-0.28586,78.01330,32.45066
244.12002,20.34331,664.27006,-0.28587,78.21324,32.45329
244.72002,20.39336,664.84287,-0.28587,78.41341,32.48127
245.32000,20.44334,664.53787,-0.28587,78.61335,32.46637
245.92002,20.49339,664.59510,-0.28586,78.81352,32.46917
246.52000,20.54331,665.10495,-0.28587,79.01322,32.49407
247.12002,20.59330,665.08804,-0.28587,79.21316,32.49325
247.72002,20.64328,664.56129,-0.28587,79.41310,32.46751
248.32000,20.69332,665.07701,-0.28587,79.61327,32.49271
248.92002,20.74342,665.11324,-0.28586,79.81368,32.49448
249.52000,20.79329,664.57102,-0.28587,80.01314,32.46799
250.12002,20.84327,664.58434,-0.28587,80.21308,32.46864
250.72002,20.89332,664.77256,-0.28587,80.41325,32.47783
251.32000,20.94342,664.62522,-0.28587,80.61367,32.47064
251.92002,20.99334,664.24659,-0.28587,80.81336,32.45214
252.52002,21.04333,664.85186,-0.28587,81.01330,32.48171
253.12002,21.09331,664.52157,-0.28587,81.21323,32.46557
253.72002,21.14330,664.04804,-0.28587,81.41317,32.44244
254.32000,21.19334,664.06508,-0.28587,81.61334,32.44327
254.92002,21.24327,663.79402,-0.28587,81.81304,32.43003
255.52002,21.29337,663.64896,-0.28587,82.01346,32.42294
256.12003,21.34329,663.41595,-0.28587,82.21316,32.41156
256.72000,21.39334,663.26642,-0.28587,82.41333,32.40425
257.32000,21.44332,663.55439,-0.28587,82.61327,32.41832
257.92002,21.49337,663.97539,-0.28587,82.81344,32.43889
258.52002,21.54335,663.75285,-0.28587,83.01337,32.42802
259.12003,21.59333,663.77479,-0.28587,83.21331,32.42909
259.72000,21.64338,663.97078,-0.28587,83.41349,32.43866
260.32000,21.69330,664.73670,-0.28587,83.61319,32.47608
260.92002,21.74340,664.41596,-0.28587,83.81360,32.46041
261.52002,21.79327,663.95169,-0.28587,84.01306,32.43773
262.12003,21.84331,663.93362,-0.28587,84.21323,32.43685
262.72000,21.89330,663.21800,-0.28587,84.41317,32.40189
263.32000,21.94328,663.85074,-0.28587,84.61311,32.43280
263.92000,21.99339,662.87392,-0.28587,84.81352,32.38507
264.52003,22.04337,663.07154,-0.28587,85.01346,32.39473
265.12003,22.09341,663.15397,-0.28587,85.21364,32.39876
265.72000,22.14334,662.71671,-0.28587,85.41333,32.37740
266.32000,22.19338,662.76570,-0.28587,85.61351,32.37979
266.92000,22.24331,663.05040,-0.28587,85.81320,32.39370
267.52003,22.29329,662.84100,-0.28587,86.01314,32.38347
268.12003,22.34327,663.11075,-0.28587,86.21308,32.39664
268.72000,22.39326,663.12030,-0.28587,86.41301,32.39711
269.32000,22.44336,662.93618,-0.28587,86.61342,32.38812
269.92000,22.49329,662.71839,-0.28587,86.81313,32.37748
270.52003,22.54333,662.87112,-0.28586,87.01329,32.38494
271.12003,22.59343,663.25204,-0.28587,87.21371,32.40355
271.72000,22.64348,663.67202,-0.28587,87.41388,32.42407
272.32000,22.69340,663.71378,-0.28587,87.61358,32.42611
272.92000,22.74327,663.25176,-0.28587,87.81304,32.40353
273.52003,22.79331,663.77837,-0.28587,88.01322,32.42926
274.12003,22.84329,664.63263,-0.28587,88.21315,32.47100
274.72000,22.89334,664.09912,-0.28587,88.41332,32.44493
275.32000,22.94338,664.13563,-0.28587,88.61350,32.44672
275.92000,22.99330,664.37260,-0.28587,88.81320,32.45829
276.52003,23.04329,664.90360,-0.28587,89.01314,32.48424
277.12003,23.09339,664.04617,-0.28587,89.21356,32.44235
277.72000,23.14338,664.26471,-0.28587,89.41349,32.45302
278.32000,23.19336,663.84138,-0.28587,89.61343,32.43234
278.92000,23.24340,664.02461,-0.28587,89.81360,32.44129
279.52003,23.29333,662.85585,-0.28587,90.01330,32.38419
280.12003,23.34337,662.81604,-0.28587,90.21347,32.38225
280.72000,23.39330,662.84086,-0.28587,90.41316,32.38346
281.32000,23.44328,662.32937,-0.28587,90.61310,32.35847
281.92000,23.49326,661.68369,-0.28587,90.81303,32.32693
282.52003,23.54331,660.68075,-0.28587,91.01321,32.27793
283.12003,23.59335,661.70073,-0.28587,91.21339,32.32776
283.72000,23.64334,660.87544,-0.28587,91.41333,32.28744
284.32000,23.69338,660.82519,-0.28587,91.61350,32.28498
284.92000,23.74336,661.50385,-0.28587,91.81343,32.31814
285.52003,23.79341,662.07843,-0.28587,92.01361,32.34621
286.12003,23.84333,662.89580,-0.28587,92.21330,32.38615
286.72000,23.89331,663.29734,-0.28587,92.41323,32.40576
287.32000,23.94330,664.20264,-0.28587,92.61317,32.44999
287.92000,23.99334,664.59267,-0.28587,92.81335,32.46905
288.52003,24.04333,665.28171,-0.28587,93.01329,32.50271
289.12003,24.09325,665.59296,-0.28587,93.21298,32.51792
289.72000,24.14335,665.34891,-0.28587,93.41340,32.50599
290.32000,24.19328,665.74039,-0.28587,93.61309,32.52512
290.92000,24.24344,665.66067,-0.28587,93.81375,32.52122
291.52003,24.29337,666.24139,-0.28587,94.01344,32.54959
292.12003,24.34341,666.13164,-0.28587,94.21363,32.54423
292.72000,24.39340,666.14444,-0.28587,94.41357,32.54486
293.32000,24.44332,666.33457,-0.28587,94.61325,32.55415
293.92000,24.49330,666.38789,-0.28587,94.81319,32.55675
294.52003,24.54323,666.39688,-0.28587,95.01289,32.55719
295.12003,24.59333,666.29359,-0.28587,95.21330,32.55215
295.72000,24.64320,667.29323,-0.28587,95.41276,32.60098
296.32000,24.69330,667.68527,-0.28587,95.61318,32.62014
296.92000,24.74328,667.23372,-0.28587,95.81311,32.59808
297.52003,24.79332,667.62706,-0.28587,96.01328,32.61729
298.12003,24.84343,667.62082,-0.28587,96.21370,32.61699
298.72000,24.89335,668.47247,-0.28587,96.41339,32.65860
299.32000,24.94340,668.63541,-0.28587,96.61357,32.66656
299.92000,24.99326,669.05855,-0.28587,96.81302,32.68723
300.52003,25.04331,669.04821,-0.28587,97.01321,32.68673
301.12003,25.09329,669.67793,-0.28587,97.21314,32.71749
301.72000,25.14321,668.98479,-0.28587,97.41283,32.68362
302.32000,25.19326,669.39346,-0.28587,97.61301,32.70359
302.92000,25.24330,669.04267,-0.28587,97.81319,32.68645
303.52003,25.29335,669.67094,-0.28587,98.01336,32.71715
304.12003,25.34339,669.04519,-0.28587,98.21354,32.68658
304.72000,25.39337,668.36127,-0.28587,98.41347,32.65316
305.32000,25.44336,668.33859,-0.28587,98.61341,32.65205
305.92000,25.49340,668.69818,-0.28588,98.81358,32.66962
306.52003,25.54333,668.59587,-0.28587,99.01328,32.66462
307.12003,25.59325,668.29277,-0.28587,99.21298,32.64982
307.72000,25.64329,668.13664,-0.28587,99.41316,32.64219
308.32000,25.69328,667.87787,-0.28587,99.61309,32.62955
308.92000,25.74332,667.60797,-0.28587,99.81326,32.61636
309.52003,25.79330,667.97878,-0.28587,100.01320,32.63448
310.12003,25.84335,667.04471,-0.28587,100.21337,32.58884
310.72000,25.89327,667.02417,-0.28587,100.41307,32.58784
311.32000,25.94344,666.86645,-0.28587,100.61373,32.58013
311.92000,25.99336,667.24932,-0.28587,100.81342,32.59884
312.52003,26.04335,666.40335,-0.28587,101.01336,32.55751
313.12003,26.09327,666.71991,-0.28587,101.21306,32.57298
313.72000,26.14331,666.48195,-0.28587,101.41324,32.56135
314.32000,26.19336,666.44340,-0.28587,101.61340,32.55946
314.92000,26.24334,667.33351,-0.28587,101.81334,32.60295
315.52003,26.29339,666.87274,-0.28587,102.01352,32.58044
316.12003,26.34331,667.18212,-0.28587,102.21322,32.59555
316.72000,26.39335,667.60248,-0.28587,102.41339,32.61609
317.32000,26.44340,667.90152,-0.28587,102.61356,32.63070
317.92000,26.49332,667.87875,-0.28587,102.81327,32.62959
318.52003,26.54331,667.85663,-0.28587,103.01321,32.62851
319.12003,26.59329,668.62521,-0.28587,103.21314,32.66606
319.72000,26.64333,668.16355,-0.28587,103.41331,32.64351
320.32000,26.69320,668.28378,-0.28587,103.61277,32.64938
320.92000,26.74330,668.71191,-0.28587,103.81318,32.67030
321.52003,26.79328,668.31363,-0.28587,104.01312,32.65084
322.12003,26.84327,667.59125,-0.28587,104.21305,32.61554
322.72000,26.89337,668.07219,-0.28587,104.41347,32.63904
323.32000,26.94324,667.74776,-0.28587,104.61292,32.62319
323.92000,26.99340,667.94236,-0.28587,104.81358,32.63270
324.52003,27.04333,668.12760,-0.28587,105.01329,32.64175
325.12003,27.09343,667.20406,-0.28587,105.21369,32.59663
325.72000,27.14329,667.77710,-0.28587,105.41315,32.62462
326.32000,27.19334,667.26971,-0.28587,105.61333,32.59983
326.92000,27.24332,667.27181,-0.28587,105.81326,32.59994
327.52003,27.29325,667.64015,-0.28587,106.01296,32.61793
328.12003,27.34329,666.80079,-0.28587,106.21313,32.57692
328.72000,27.39321,666.58994,-0.28587,106.41284,32.56662
329.32000,27.44338,666.48074,-0.28587,106.61348,32.56129
329.92000,27.49330,666.68168,-0.28587,106.81318,32.57111
330.52003,27.54340,666.84680,-0.28587,107.01360,32.57917
331.12003,27.59339,666.38561,-0.28587,107.21353,32.55664
331.72000,27.64337,666.07180,-0.28587,107.41347,32.54131
332.32000,27.69336,667.14673,-0.28587,107.61341,32.59383
332.92000,27.74328,666.06174,-0.28587,107.81310,32.54082
333.52003,27.79332,666.10058,-0.28587,108.01327,32.54272
334.12003,27.84325,666.15012,-0.28587,108.21297,32.54514
334.72000,27.89323,665.77089,-0.28587,108.41291,32.52661
335.32000,27.94328,666.28852,-0.28588,108.61309,32.55190
335.92000,27.99326,666.27795,-0.28587,108.81302,32.55138
336.52003,28.04331,666.17518,-0.28587,109.01320,32.54636
337.12003,28.09341,665.60199,-0.28587,109.21361,32.51836
337.72000,28.14339,665.65527,-0.28587,109.41355,32.52096
338.32000,28.19338,665.60800,-0.28587,109.61349,32.51865
338.92000,28.24336,665.65140,-0.28587,109.81342,32.52077
339.52003,28.29328,666.38286,-0.28587,110.01312,32.55651
340.12003,28.34333,665.82281,-0.28587,110.21329,32.52914
340.72000,28.39331,666.22929,-0.28587,110.41323,32.54900
341.32000,28.44330,666.07306,-0.28587,110.61317,32.54137
341.92000,28.49328,666.88256,-0.28587,110.81311,32.58092
342.52003,28.54332,667.11088,-0.28587,111.01327,32.59208
343.12003,28.59331,667.13435,-0.28587,111.21321,32.59322
343.72000,28.64335,667.91833,-0.28588,111.41338,32.63152
344.32000,28.69340,668.10013,-0.28587,111.61356,32.64040
344.92000,28.74332,668.13012,-0.28587,111.81326,32.64187
345.52003,28.79342,667.87708,-0.28588,112.01367,32.62951
346.12003,28.84329,668.01133,-0.28587,112.21313,32.63607
346.72000,28.89333,668.49389,-0.28587,112.41331,32.65964
347.32000,28.94326,667.85705,-0.28587,112.61301,32.62853
347.92000,28.99330,667.91517,-0.28588,112.81319,32.63137
348.52003,29.04334,668.39941,-0.28587,113.01335,32.65503
349.12003,29.09333,668.04942,-0.28587,113.21329,32.63793
349.72003,29.14331,668.39554,-0.28587,113.41323,32.65484
350.32000,29.19330,668.45911,-0.28587,113.61316,32.65794
350.92000,29.24346,667.89538,-0.28587,113.81382,32.63040
351.52003,29.29338,668.42460,-0.28587,114.01350,32.65626
352.12003,29.34331,668.34167,-0.28587,114.21322,32.65221
352.72003,29.39329,667.69891,-0.28587,114.41315,32.62080
353.32000,29.44328,668.14558,-0.28587,114.61308,32.64262
353.92000,29.49332,668.05636,-0.28587,114.81326,32.63827
354.52003,29.54336,667.03339,-0.28587,115.01343,32.58829
355.12003,29.59329,667.49970,-0.28587,115.21313,32.61107
355.72003,29.64333,668.27834,-0.28587,115.41331,32.64911
356.32000,29.69338,667.58273,-0.28587,115.61348,32.61513
356.92000,29.74336,668.31494,-0.28587,115.81342,32.65090
357.52003,29.79340,667.41924,-0.28588,116.01359,32.60714
358.12003,29.84339,667.58795,-0.28587,116.21352,32.61538
358.72003,29.89331,667.58581,-0.28588,116.41322,32.61528
359.32000,29.94335,666.82366,-0.28588,116.61340,32.57804
359.92000,29.99328,666.57909,-0.28587,116.81310,32.56609
360.52003,30.04332,666.86701,-0.28587,117.01328,32.58016
361.12003,30.09331,667.15474,-0.28588,117.21321,32.59422
361.72003,30.14335,666.76075,-0.28587,117.41339,32.57497
362.32000,30.19328,667.13849,-0.28588,117.61308,32.59342
362.92000,30.24332,666.77537,-0.28587,117.81325,32.57568
363.52003,30.29336,667.15376,-0.28587,118.01343,32.59417
364.12003,30.34341,666.75302,-0.28587,118.21361,32.57459
364.72003,30.39345,666.56140,-0.28588,118.41378,32.56523
365.32000,30.44337,667.01239,-0.28587,118.61348,32.58726
365.92000,30.49336,667.55284,-0.28588,118.81342,32.61367
366.52003,30.54334,667.30757,-0.28587,119.01336,32.60168
367.12003,30.59327,667.37086,-0.28587,119.21304,32.60477
367.72003,30.64325,667.42762,-0.28588,119.41298,32.60755
368.32000,30.69323,668.19652,-0.28587,119.61292,32.64511
368.92000,30.74334,667.69384,-0.28587,119.81333,32.62056
369.52003,30.79332,667.66045,-0.28587,120.01327,32.61892
370.12003,30.84337,667.38767,-0.28587,120.21345,32.60560
370.72003,30.89329,667.85137,-0.28588,120.41315,32.62825
371.32000,30.94345,668.17869,-0.28587,120.61379,32.64424
371.92000,30.99344,667.30753,-0.28587,120.81373,32.60168
372.52003,31.04330,667.90744,-0.28587,121.01319,32.63099
373.12003,31.09329,667.83270,-0.28587,121.21313,32.62734
373.72003,31.14327,668.01151,-0.28587,121.41305,32.63607
374.32000,31.19332,667.29095,-0.28588,121.61324,32.60087
374.92000,31.24330,667.60909,-0.28587,121.81318,32.61641
375.52003,31.29328,667.53174,-0.28587,122.01310,32.61264
376.12003,31.34333,667.05109,-0.28588,122.21328,32.58915
376.72003,31.39337,666.89672,-0.28587,122.41346,32.58161
377.32000,31.44335,667.11386,-0.28587,122.61339,32.59222
377.92000,31.49340,666.99148,-0.28587,122.81357,32.58624
378.52003,31.54338,667.47679,-0.28588,123.01351,32.60995
379.12003,31.59324,667.01840,-0.28588,123.21296,32.58755
379.72003,31.64335,667.40233,-0.28588,123.41337,32.60632
380.32000,31.69327,668.10655,-0.28588,123.61307,32.64072
380.92000,31.74338,668.42507,-0.28588,123.81349,32.65628
381.52003,31.79324,668.73282,-0.28588,124.01295,32.67131
382.12003,31.84328,669.15527,-0.28588,124.21311,32.69196
382.72003,31.89333,669.22577,-0.28587,124.41329,32.69540
383.32000,31.94337,669.34186,-0.28587,124.61348,32.70107
383.92000,31.99336,669.27299,-0.28587,124.81340,32.69770
384.52003,32.04334,669.12733,-0.28587,125.01333,32.69059
385.12003,32.09338,669.67150,-0.28588,125.21352,32.71717
385.72003,32.14331,668.98623,-0.28588,125.41320,32.68370
386.32000,32.19329,668.92505,-0.28588,125.61315,32.68071
386.92000,32.24327,668.90861,-0.28588,125.81308,32.67990
387.52003,32.29326,668.96570,-0.28587,126.01303,32.68269
388.12003,32.34330,668.24486,-0.28588,126.21319,32.64748
388.72003,32.39329,667.95405,-0.28588,126.41313,32.63327
389.32000,32.44333,668.06539,-0.28588,126.61330,32.63871
389.92000,32.49332,668.12243,-0.28587,126.81324,32.64149
390.52003,32.54348,668.00741,-0.28588,127.01391,32.63588
391.12003,32.59334,667.67232,-0.28587,127.21336,32.61950
391.72003,32.64333,668.23880,-0.28588,127.41328,32.64718
392.32000,32.69337,667.75489,-0.28588,127.61346,32.62354
392.92000,32.74323,668.30087,-0.28587,127.81291,32.65021
393.52003,32.79328,667.54399,-0.28587,128.01310,32.61324
394.12003,32.84326,667.61179,-0.28588,128.21304,32.61655
394.72003,32.89331,668.29878,-0.28588,128.41321,32.65011
395.32000,32.94329,667.64532,-0.28587,128.61314,32.61818
395.92000,32.99339,667.92150,-0.28587,128.81355,32.63168
396.52003,33.04338,668.46479,-0.28588,129.01349,32.65822
397.12003,33.09336,668.50679,-0.28587,129.21343,32.66027
397.72003,33.14335,668.31941,-0.28588,129.41337,32.65112
398.32000,33.19327,668.39913,-0.28588,129.61307,32.65501
398.92000,33.24331,669.56519,-0.28587,129.81324,32.71198
399.52003,33.29330,668.45864,-0.28587,130.01318,32.65792
400.12003,33.34334,669.03122,-0.28588,130.21334,32.68589
400.72003,33.39333,668.95387,-0.28588,130.41329,32.68211
401.32000,33.44325,668.51615,-0.28588,130.61298,32.66073
401.92000,33.49330,668.31224,-0.28587,130.81316,32.65077
402.52003,33.54328,668.27578,-0.28588,131.01308,32.64899
403.12003,33.59338,668.16323,-0.28587,131.21351,32.64349
403.72003,33.64342,667.96797,-0.28588,131.41367,32.63395
404.32000,33.69335,668.44085,-0.28588,131.61339,32.65705
404.92000,33.74327,668.49212,-0.28587,131.81307,32.65956
405.52003,33.79332,668.62358,-0.28588,132.01325,32.66598
406.12003,33.84330,668.93254,-0.28588,132.21319,32.68107
406.72003,33.89335,669.15955,-0.28588,132.41338,32.69217
407.32000,33.94333,669.33450,-0.28588,132.61330,32.70071
407.92000,33.99332,668.83173,-0.28588,132.81324,32.67615
408.52003,34.04330,669.01273,-0.28587,133.01316,32.68499
409.12003,34.09328,669.24463,-0.28588,133.21311,32.69632
409.72003,34.14333,668.50767,-0.28588,133.41328,32.66032
410.32000,34.19325,668.85408,-0.28588,133.61299,32.67724
410.92000,34.24335,668.25990,-0.28588,133.81339,32.64821
411.52003,34.29328,668.75997,-0.28588,134.01309,32.67264
412.12003,34.34332,668.14013,-0.28588,134.21326,32.64236
412.72003,34.39331,667.74902,-0.28588,134.41321,32.62325
413.32000,34.44329,668.16136,-0.28588,134.61313,32.64340
413.92000,34.49334,667.89449,-0.28588,134.81332,32.63036
414.52003,34.54332,667.96308,-0.28588,135.01325,32.63371
415.12003,34.59336,667.77556,-0.28588,135.21342,32.62455
415.72003,34.64329,667.89873,-0.28588,135.41312,32.63057
416.32000,34.69339,668.05105,-0.28587,135.61355,32.63801
416.92000,34.74337,667.47046,-0.28588,135.81347,32.60964
417.52003,34.79342,667.20080,-0.28588,136.01365,32.59647
418.12003,34.84334,668.03973,-0.28588,136.21334,32.63745
418.72003,34.89333,667.98655,-0.28588,136.41329,32.63486
419.32000,34.94337,667.78073,-0.28587,136.61345,32.62480
419.92000,34.99330,667.84928,-0.28588,136.81316,32.62815
420.52003,35.04328,667.79135,-0.28588,137.01309,32.62532
421.12003,35.09326,668.24546,-0.28588,137.21304,32.64751
421.72003,35.14331,668.22036,-0.28588,137.41320,32.64628
422.32000,35.19335,668.66167,-0.28588,137.61338,32.66784
422.92000,35.24339,668.61124,-0.28588,137.81356,32.66537
423.52003,35.29338,668.91583,-0.28587,138.01349,32.68026
424.12003,35.34336,668.71941,-0.28588,138.21342,32.67066
424.72003,35.39341,668.54055,-0.28588,138.41360,32.66192
425.32000,35.44333,668.28118,-0.28588,138.61330,32.64925
425.92000,35.49332,668.29384,-0.28588,138.81325,32.64987
426.52003,35.54330,668.41575,-0.28587,139.01317,32.65583
427.12003,35.59328,668.50679,-0.28588,139.21311,32.66027
427.72003,35.64327,668.91923,-0.28588,139.41305,32.68042
428.32000,35.69325,669.07750,-0.28588,139.61298,32.68816
428.92000,35.74329,669.28389,-0.28587,139.81315,32.69824
429.52003,35.79334,668.92067,-0.28587,140.01334,32.68049
430.12003,35.84350,669.32030,-0.28588,140.21398,32.70002
430.72003,35.89343,669.34596,-0.28588,140.41368,32.70127
431.32000,35.94341,669.58833,-0.28588,140.61360,32.71311
431.92000,35.99328,670.04594,-0.28588,140.81308,32.73547
432.52003,36.04326,669.46312,-0.28588,141.01300,32.70699
433.12003,36.09336,669.42978,-0.28588,141.21343,32.70536
433.72003,36.14329,669.80319,-0.28588,141.41312,32.72361
434.32000,36.19333,670.31672,-0.28588,141.61330,32.74870
434.92000,36.24337,670.35602,-0.28588,141.81347,32.75062
435.52003,36.29336,670.43221,-0.28588,142.01342,32.75434
436.12003,36.34334,670.73731,-0.28588,142.21334,32.76925
436.72003,36.39345,669.93264,-0.28588,142.41376,32.72993
437.32000,36.44343,670.76571,-0.28588,142.61369,32.77063
437.92000,36.49341,670.23388,-0.28588,142.81363,32.74465
438.52003,36.54334,669.77870,-0.28588,143.01332,32.72241
439.12003,36.59320,670.58811,-0.28588,143.21280,32.76196
439.72003,36.64330,670.22233,-0.28588,143.41320,32.74409
440.32000,36.69335,670.09404,-0.28588,143.61339,32.73782
440.92000,36.74339,670.14061,-0.28587,143.81355,32.74009
441.52003,36.79326,669.77986,-0.28588,144.01301,32.72247
442.12003,36.84336,669.17073,-0.28588,144.21343,32.69271
442.72003,36.89334,669.04188,-0.28588,144.41336,32.68642
443.32000,36.94339,668.49184,-0.28588,144.61353,32.65954
443.92000,36.99337,668.64174,-0.28588,144.81348,32.66687
444.52003,37.04336,667.96038,-0.28588,145.01340,32.63358
445.12003,37.09334,667.82078,-0.28588,145.21334,32.62676
445.72003,37.14332,667.55163,-0.28588,145.41327,32.61361
446.32000,37.19337,668.24201,-0.28588,145.61346,32.64734
446.92000,37.24329,668.24914,-0.28588,145.81314,32.64769
447.52003,37.29328,668.41212,-0.28588,146.01309,32.65565
448.12003,37.34338,667.45076,-0.28588,146.21350,32.60868
448.72003,37.39337,667.54315,-0.28588,146.41343,32.61319
449.32000,37.44341,667.87167,-0.28588,146.61361,32.62924
449.92000,37.49333,668.51424,-0.28588,146.81331,32.66064
450.52003,37.54344,668.26232,-0.28588,147.01372,32.64833
451.12003,37.59342,668.21850,-0.28588,147.21366,32.64619
451.72003,37.64340,667.99209,-0.28588,147.41360,32.63513
452.32000,37.69327,668.67769,-0.28588,147.61306,32.66862
452.92000,37.74331,668.29571,-0.28588,147.81322,32.64996
453.52003,37.79336,668.80421,-0.28588,148.01340,32.67480
454.12003,37.84328,668.40751,-0.28588,148.21310,32.65542
454.72003,37.89327,668.55736,-0.28588,148.41305,32.66274
455.32000,37.94331,668.37012,-0.28588,148.61321,32.65359
455.92000,37.99341,668.27233,-0.28588,148.81363,32.64882
456.52003,38.04340,668.78009,-0.28588,149.01357,32.67363
457.12003,38.09344,667.87079,-0.28588,149.21374,32.62920
457.72003,38.14342,667.83559,-0.28588,149.41367,32.62748
458.32000,38.19335,667.76839,-0.28588,149.61338,32.62420
458.92000,38.24333,668.02134,-0.28588,149.81331,32.63655
459.52003,38.29326,667.84616,-0.28588,150.01301,32.62800
460.12003,38.34330,668.81003,-0.28588,150.21318,32.67509
460.72003,38.39334,668.55727,-0.28588,150.41336,32.66274
461.32000,38.44333,668.35554,-0.28588,150.61328,32.65288
461.92000,38.49331,668.68691,-0.28588,150.81323,32.66907
462.52003,38.54336,669.03858,-0.28588,151.01340,32.68625
463.12003,38.59340,669.08235,-0.28588,151.21357,32.68839
463.72003,38.64338,669.59662,-0.28588,151.41351,32.71352
464.32000,38.69343,669.62987,-0.28588,151.61369,32.71514
464.92000,38.74335,669.94061,-0.28588,151.81339,32.73032
465.52003,38.79334,670.31928,-0.28588,152.01333,32.74882
466.12003,38.84326,669.00738,-0.28588,152.21301,32.68473
466.72003,38.89324,669.33990,-0.28588,152.41294,32.70097
467.32000,38.94323,668.97650,-0.28588,152.61289,32.68322
467.92000,38.99327,668.37445,-0.28588,152.81307,32.65381
468.52003,39.04326,668.19000,-0.28588,153.01300,32.64479
469.12003,39.09336,667.63433,-0.28588,153.21342,32.61765
469.72003,39.14340,667.24806,-0.28588,153.41358,32.59878
470.32000,39.19333,666.84238,-0.28587,153.61329,32.57896
470.92000,39.24337,667.24545,-0.28588,153.81345,32.59865
471.52003,39.29336,666.59283,-0.28588,154.01341,32.56676
472.12003,39.34334,666.49192,-0.28588,154.21332,32.56184
472.72003,39.39332,666.54799,-0.28588,154.41327,32.56458
473.32000,39.44325,666.39106,-0.28588,154.61297,32.55691
473.92000,39.49329,666.64172,-0.28588,154.81313,32.56915
474.52003,39.54333,666.64829,-0.28588,155.01331,32.56947
475.12003,39.59338,666.51362,-0.28588,155.21349,32.56290
475.72003,39.64324,667.22506,-0.28588,155.41294,32.59765
476.32003,39.69335,667.32685,-0.28588,155.61336,32.60263
476.92000,39.74333,666.99395,-0.28588,155.81330,32.58636
477.52003,39.79337,666.68983,-0.28588,156.01348,32.57150
478.12003,39.84324,666.97747,-0.28588,156.21293,32.58556
478.72003,39.89328,667.30818,-0.28588,156.41310,32.60172
479.32003,39.94327,666.68908,-0.28588,156.61304,32.57147
479.92000,39.99325,667.34836,-0.28588,156.81298,32.60368
480.52003,40.04335,667.51065,-0.28588,157.01340,32.61161
481.12003,40.09322,666.99833,-0.28588,157.21285,32.58657
481.72003,40.14332,667.57207,-0.28588,157.41327,32.61460
482.32003,40.19337,667.64113,-0.28588,157.61344,32.61798
482.92000,40.24335,667.49300,-0.28588,157.81337,32.61074
483.52003,40.29333,667.99899,-0.28588,158.01331,32.63546
484.12003,40.34332,668.13962,-0.28588,158.21325,32.64233
484.72003,40.39336,667.93896,-0.28588,158.41342,32.63253
485.32003,40.44328,668.87233,-0.28588,158.61311,32.67813
485.92000,40.49333,668.67573,-0.28588,158.81329,32.66853
486.52003,40.54325,668.21203,-0.28588,159.01299,32.64587
487.12003,40.59330,668.39107,-0.28588,159.21316,32.65462
487.72003,40.64334,667.91042,-0.28588,159.41334,32.63114
488.32003,40.69332,667.75209,-0.28588,159.61328,32.62340
488.92000,40.74331,666.86976,-0.28588,159.81321,32.58030
489.52003,40.79335,666.87316,-0.28588,160.01338,32.58046
490.12003,40.84340,667.61211,-0.28588,160.21358,32.61656
490.72003,40.89338,666.11008,-0.28588,160.41349,32.54318
491.32003,40.94337,666.36349,-0.28588,160.61344,32.55556
491.92000,40.99329,666.01662,-0.28588,160.81312,32.53861
492.52003,41.04327,665.67026,-0.28588,161.01308,32.52169
493.12003,41.09325,665.69331,-0.28588,161.21299,32.52282
493.72003,41.14324,665.76484,-0.28588,161.41294,32.52631
494.32003,41.19322,666.16316,-0.28588,161.61287,32.54577
494.92000,41.24327,666.17075,-0.28588,161.81307,32.54614
495.52003,41.29337,665.75645,-0.28588,162.01346,32.52590
496.12003,41.34336,665.64563,-0.28588,162.21340,32.52049
496.72003,41.39340,666.02626,-0.28588,162.41359,32.53909
497.32003,41.44338,665.40530,-0.28588,162.61351,32.50875
497.92000,41.49337,666.15962,-0.28588,162.81345,32.54560
498.52003,41.54335,665.24236,-0.28588,163.01339,32.50079
499.12003,41.59328,665.05326,-0.28588,163.21309,32.49155
499.72003,41.64326,664.94788,-0.28588,163.41302,32.48640
500.32003,41.69330,664.31882,-0.28588,163.61320,32.45567
500.92000,41.74329,663.79071,-0.28588,163.81314,32.42987
501.52003,41.79327,663.18465,-0.28588,164.01308,32.40026
502.12003,41.84338,663.13976,-0.28588,164.21349,32.39806
502.72003,41.89330,663.38424,-0.28588,164.41317,32.41001
503.32003,41.94335,662.74772,-0.28588,164.61337,32.37891
503.92000,41.99339,662.69748,-0.28588,164.81352,32.37646
504.52003,42.04325,663.04845,-0.28588,165.01299,32.39360
505.12003,42.09329,662.68286,-0.28588,165.21316,32.37574
505.72003,42.14328,661.52364,-0.28588,165.41311,32.31911
506.32003,42.19338,661.62883,-0.28588,165.61351,32.32425
506.92000,42.24325,660.72741,-0.28588,165.81298,32.28020
507.52003,42.29329,661.10566,-0.28588,166.01315,32.29869
508.12003,42.34327,660.88988,-0.28588,166.21308,32.28814
508.72003,42.39338,660.07110,-0.28588,166.41350,32.24814
509.32003,42.44342,659.74598,-0.28588,166.61367,32.23226
509.92000,42.49335,659.10071,-0.28588,166.81337,32.20073
510.52003,42.54333,659.48660,-0.28588,167.01331,32.21959
511.12003,42.59326,659.09340,-0.28588,167.21300,32.20037
511.72003,42.64336,658.30322,-0.28588,167.41343,32.16177
512.32000,42.69328,658.66685,-0.28588,167.61311,32.17954
512.92003,42.74333,658.93969,-0.28588,167.81329,32.19287
513.52003,42.79331,657.70997,-0.28588,168.01322,32.13279
514.12000,42.84330,658.00217,-0.28588,168.21316,32.14706
514.72003,42.89340,657.45092,-0.28588,168.41357,32.12013
515.32000,42.94327,656.54167,-0.28588,168.61304,32.07571
515.92003,42.99343,655.40485,-0.28588,168.81368,32.02017
516.52003,43.04341,654.47399,-0.28588,169.01362,31.97469
517.12000,43.09339,652.27491,-0.28588,169.21356,31.86725
517.72003,43.14332,652.35244,-0.28588,169.41326,31.87104
518.32000,43.19324,651.10717,-0.28588,169.61294,31.81020
518.92003,43.24335,649.30925,-0.28588,169.81337,31.72237
519.52003,43.29327,647.39939,-0.28588,170.01306,31.62906
520.12000,43.34331,644.74619,-0.28588,170.21323,31.49944
520.72003,43.39324,642.37034,-0.28588,170.41293,31.38336
521.32000,43.44334,639.43388,-0.28588,170.61335,31.23990
521.92003,43.49333,635.75879,-0.28588,170.81329,31.06035
522.52003,43.54331,631.70516,-0.28588,171.01322,30.86231
523.12000,43.59341,627.70853,-0.28588,171.21363,30.66705
523.72003,43.64340,620.30386,-0.28588,171.41359,30.30529
524.32000,43.69338,609.75165,-0.28588,171.61350,29.78976
524.92006,43.74325,587.17537,-0.28588,171.81298,28.68678
525.17806,43.76489,2.45564,-0.28588,171.89955,0.11997