File: Manufatura Aditiva/Dados/Ensaios AMR/Ensaios/Ensaios FDM/Tracao_OLABI_25_05_2018_FDM_YZ5.is_metal_RawData/Specimen_RawData_2.csv
Time,Extension,Load,Strain 1,Tensile strain,Tensile stress
(sec),(mm),(N),(mm/mm),(%),(MPa)
0.00000,0.00006,20.41878,0.00077,0.07663,1.00633
0.80000,0.06667,49.29527,0.00180,0.17983,2.42950
1.60000,0.13339,78.58879,0.00288,0.28752,3.87322
2.40000,0.20000,108.14493,0.00395,0.39514,5.32988
3.20000,0.26672,136.68238,0.00503,0.50323,6.73634
4.00000,0.33339,165.52737,0.00611,0.61129,8.15796
4.80000,0.40005,194.16006,0.00721,0.72071,9.56911
5.60000,0.46666,221.56129,0.00829,0.82914,10.91957
6.40000,0.53332,249.62167,0.00937,0.93689,12.30251
7.20000,0.59993,276.97606,0.01044,1.04424,13.65066
8.00000,0.66671,304.14716,0.01153,1.15275,14.98978
8.80000,0.73338,330.63029,0.01261,1.26088,16.29499
9.60000,0.79992,356.35172,0.01370,1.37025,17.56266
10.40000,0.86665,382.83581,0.01479,1.47920,18.86792
11.20000,0.93331,408.33396,0.01586,1.58567,20.12459
12.00000,1.00010,434.21774,0.01695,1.69493,21.40026
12.80000,1.06670,459.67693,0.01804,1.80449,22.65501
13.60000,1.13325,484.40988,0.01915,1.91456,23.87396
14.40000,1.19998,507.54906,0.02022,2.02204,25.01437
15.20000,1.26664,530.92260,0.02132,2.13227,26.16633
16.00000,1.33337,554.50322,0.02243,2.24320,27.32849
16.80000,1.40003,577.25697,0.02354,2.35434,28.44990
17.60000,1.46670,599.22067,0.02464,2.46367,29.53237
18.40000,1.53324,620.19406,0.02576,2.57614,30.56604
19.20000,1.60003,641.86393,0.02690,2.68952,31.63403
20.00000,1.66669,663.23928,0.02804,2.80395,32.68750
20.80000,1.73330,681.68393,0.02916,2.91563,33.59654
21.60000,1.79996,702.04926,0.03032,3.03226,34.60024
22.30200,1.85850,718.78284,0.03135,3.24693,35.42495
23.10200,1.92510,736.41441,0.03249,3.51335,36.29391
23.90200,1.99189,752.82236,0.03364,3.78049,37.10257
24.70200,2.05849,769.86747,0.03197,4.04692,37.94263
25.50200,2.12516,785.61781,0.00520,4.31358,38.71889
26.30200,2.19182,799.97750,-0.01097,4.58024,39.42660
27.10200,2.25849,813.98739,-0.14040,4.84690,40.11707
27.90200,2.32521,828.12496,-0.14038,5.11380,40.81384
28.70200,2.39176,841.03867,-0.14040,5.37998,41.45028
29.50200,2.45848,852.56919,-0.14041,5.64688,42.01856
30.30200,2.52521,863.60015,-0.14042,5.91378,42.56222
31.10200,2.59181,872.10359,-0.14042,6.18020,42.98130
31.90200,2.65848,881.72900,-0.14042,6.44687,43.45569
32.70200,2.72520,887.87433,-0.14042,6.71377,43.75856
33.50200,2.79187,895.46181,-0.14043,6.98043,44.13251
34.30200,2.85842,900.53268,-0.14043,7.24661,44.38242
35.10200,2.92514,904.00837,-0.14043,7.51351,44.55372
35.90200,2.99181,906.87824,-0.14043,7.78017,44.69516
36.70200,3.05853,908.18638,-0.14043,8.04707,44.75963
37.50200,3.12514,909.96251,-0.14043,8.31349,44.84717
38.30200,3.19186,909.33396,-0.14044,8.58039,44.81619
39.10200,3.25853,907.70638,-0.14044,8.84706,44.73598
39.90200,3.32513,905.57672,-0.14043,9.11348,44.63102
40.70200,3.39192,902.81768,-0.14043,9.38062,44.49504
41.50200,3.45846,898.99348,-0.14044,9.64680,44.30656
42.30200,3.52513,894.91475,-0.14043,9.91346,44.10555
43.10200,3.59173,890.71188,-0.14043,10.17988,43.89841
43.90200,3.65858,886.51413,-0.14044,10.44726,43.69152
44.70200,3.72518,881.51814,-0.14044,10.71368,43.44530
45.50200,3.79179,876.57841,-0.14044,10.98011,43.20185
46.30200,3.85846,872.12091,-0.14044,11.24677,42.98216
47.10200,3.92506,866.79514,-0.14044,11.51319,42.71968
47.90200,3.99185,861.83446,-0.14044,11.78033,42.47520
48.70200,4.05869,857.60672,-0.14044,12.04771,42.26683
49.50200,4.12518,852.77734,-0.14044,12.31365,42.02882
50.30200,4.19178,848.47575,-0.14044,12.58007,41.81682
51.10200,4.25851,844.65547,-0.14044,12.84697,41.62854
51.90200,4.32523,839.55592,-0.14044,13.11387,41.37720
52.70200,4.39178,836.22290,-0.14044,13.38006,41.21294
53.50200,4.45850,830.77280,-0.14044,13.64696,40.94433
54.30200,4.52523,826.73235,-0.14044,13.91386,40.74520
55.10200,4.59183,822.51877,-0.14044,14.18028,40.53754
55.90200,4.65862,817.21637,-0.14044,14.44742,40.27621
56.70200,4.72516,813.51018,-0.14044,14.71360,40.09355
57.50200,4.79183,808.62269,-0.14044,14.98026,39.85267
58.30200,4.85855,802.00993,-0.14044,15.24716,39.52676
59.10200,4.92516,796.58572,-0.14044,15.51358,39.25943
59.90200,4.99182,788.64088,-0.14044,15.78024,38.86788
60.70200,5.05849,780.73773,-0.14044,16.04691,38.47837
61.50200,5.12521,771.22888,-0.14044,16.31381,38.00973
62.30200,5.19176,760.98307,-0.14045,16.57999,37.50477
63.10200,5.25855,749.22214,-0.14044,16.84713,36.92514
63.90200,5.32521,737.14796,-0.14044,17.11379,36.33007
64.70200,5.39188,724.06530,-0.14044,17.38045,35.68529
65.50201,5.45848,711.06297,-0.14044,17.64687,35.04448
66.30200,5.52515,697.30412,-0.14044,17.91353,34.36638
67.10201,5.59193,684.97369,-0.14044,18.18067,33.75868
67.90200,5.65854,675.29804,-0.14044,18.44710,33.28181
68.70200,5.72508,666.44400,-0.14045,18.71328,32.84545
69.50201,5.79181,660.08102,-0.14044,18.98018,32.53185
70.30200,5.85859,655.31828,-0.14044,19.24732,32.29712
71.10201,5.92526,651.82364,-0.14044,19.51398,32.12489
71.90200,5.99180,649.71624,-0.14044,19.78016,32.02103
72.70200,6.05841,649.10585,-0.14044,20.04658,31.99094
73.50201,6.12513,647.82556,-0.14045,20.31348,31.92785
74.30200,6.19186,647.76135,-0.14044,20.58038,31.92468
75.10201,6.25852,648.07348,-0.14044,20.84705,31.94006
75.90200,6.32507,648.94906,-0.14044,21.11323,31.98322
76.70200,6.39186,649.27060,-0.14045,21.38037,31.99906
77.50201,6.45852,650.12448,-0.14044,21.64703,32.04115
78.30200,6.52525,650.27364,-0.14045,21.91393,32.04850
79.10201,6.59173,651.26126,-0.14044,22.17987,32.09717
79.90200,6.65846,651.92068,-0.14044,22.44677,32.12967
80.70200,6.72518,651.76724,-0.14044,22.71367,32.12211
81.50201,6.79179,651.84496,-0.14045,22.98010,32.12594
82.30200,6.85851,652.24953,-0.14044,23.24700,32.14588
83.10201,6.92524,652.28208,-0.14045,23.51390,32.14748
83.90200,6.99184,652.45368,-0.14044,23.78032,32.15594
84.70200,7.05845,652.75193,-0.14044,24.04674,32.17064
85.50201,7.12517,653.37485,-0.14044,24.31364,32.20134
86.30200,7.19184,653.33513,-0.14044,24.58030,32.19938
87.10201,7.25844,652.67035,-0.14044,24.84672,32.16662
87.90200,7.32517,652.65787,-0.14045,25.11362,32.16600
88.70200,7.39189,652.97168,-0.14045,25.38052,32.18147
89.50201,7.45850,653.27915,-0.14045,25.64695,32.19662
90.30200,7.52522,653.68968,-0.14045,25.91385,32.21686
91.10201,7.59177,653.24320,-0.14044,26.18003,32.19485
91.90201,7.65838,653.55469,-0.14044,26.44645,32.21021
92.70200,7.72522,654.03059,-0.14044,26.71383,32.23366
93.50201,7.79183,654.27930,-0.14045,26.98025,32.24591
94.30200,7.85849,654.64773,-0.14045,27.24691,32.26407
95.10201,7.92510,654.85439,-0.14044,27.51333,32.27426
95.90201,7.99188,654.99926,-0.14045,27.78048,32.28140
96.70200,8.05849,654.93002,-0.14044,28.04690,32.27798
97.50201,8.12515,654.83171,-0.14045,28.31356,32.27314
98.30200,8.19182,655.13933,-0.14045,28.58022,32.28830
99.10201,8.25848,655.64113,-0.14044,28.84688,32.31303
99.90201,8.32509,655.84299,-0.14045,29.11330,32.32298
100.70200,8.39187,655.71638,-0.14045,29.38044,32.31674
101.50201,8.45854,655.26818,-0.14045,29.64710,32.29465
102.30200,8.52514,656.19559,-0.14045,29.91353,32.34036
103.10201,8.59187,656.18237,-0.14044,30.18042,32.33971
103.90201,8.65847,656.19517,-0.14045,30.44685,32.34034
104.70200,8.72526,655.45142,-0.14045,30.71398,32.30368
105.50201,8.79186,656.03228,-0.14045,30.98041,32.33231
106.30200,8.85841,656.18157,-0.14044,31.24659,32.33967
107.10201,8.92508,655.82744,-0.14045,31.51325,32.32222
107.90201,8.99186,656.71438,-0.14044,31.78039,32.36593
108.70200,9.05865,656.35429,-0.14045,32.04753,32.34818
109.50201,9.12513,656.62474,-0.14044,32.31348,32.36151
110.30200,9.19180,657.22624,-0.14044,32.58013,32.39116
111.10201,9.25852,656.74209,-0.14045,32.84704,32.36729
111.90201,9.32525,656.59541,-0.14044,33.11394,32.36007
112.70200,9.39185,656.41599,-0.14045,33.38036,32.35122
113.50201,9.45846,656.75993,-0.14045,33.64678,32.36817
114.30200,9.52512,656.77594,-0.14045,33.91345,32.36896
115.10201,9.59185,657.77288,-0.14044,34.18034,32.41809
115.90201,9.65851,657.77376,-0.14045,34.44700,32.41814
116.70200,9.72512,657.33772,-0.14045,34.71342,32.39665
117.50201,9.79184,657.83141,-0.14044,34.98032,32.42098
118.30200,9.85845,657.77544,-0.14045,35.24675,32.41822
119.10201,9.92518,658.52655,-0.14045,35.51365,32.45524
119.90201,9.99196,657.98955,-0.14045,35.78078,32.42877
120.70200,10.05845,657.92063,-0.14045,36.04673,32.42538
121.50201,10.12517,658.88693,-0.14045,36.31363,32.47300
122.30201,10.19178,658.94239,-0.14045,36.58005,32.47573
123.10201,10.25850,659.33145,-0.14045,36.84695,32.49491
123.90201,10.32517,658.87081,-0.14045,37.11362,32.47221
124.70200,10.39183,659.21941,-0.14045,37.38028,32.48939
125.50201,10.45850,658.93852,-0.14045,37.64694,32.47554
126.30201,10.52510,658.69819,-0.14045,37.91336,32.46370
127.10201,10.59189,658.76595,-0.14045,38.18050,32.46704
127.90201,10.65855,658.77889,-0.14045,38.44716,32.46768
128.70201,10.72510,659.00949,-0.14044,38.71334,32.47904
129.50200,10.79176,657.63863,-0.14045,38.98000,32.41148
130.30200,10.85855,658.08864,-0.14045,39.24714,32.43366
131.10200,10.92515,657.73316,-0.14045,39.51356,32.41614
131.90202,10.99182,658.33596,-0.14045,39.78022,32.44585
132.70202,11.05843,657.38489,-0.14045,40.04665,32.39897
133.50200,11.12515,657.70191,-0.14045,40.31354,32.41460
134.30200,11.19188,657.55504,-0.14045,40.58045,32.40736
135.10200,11.25854,657.63420,-0.14045,40.84711,32.41126
135.90202,11.32515,658.15281,-0.14044,41.11353,32.43682
136.70202,11.39175,659.10420,-0.14044,41.37995,32.48371
137.50202,11.45854,658.06201,-0.14045,41.64709,32.43235
138.30200,11.52514,658.42848,-0.14045,41.91351,32.45041
139.10200,11.59181,658.41954,-0.14044,42.18017,32.44997
139.90202,11.65847,658.62066,-0.14045,42.44684,32.45988
140.70202,11.72514,658.42983,-0.14044,42.71350,32.45047
141.50202,11.79174,658.81927,-0.14045,42.97992,32.46967
142.30200,11.85853,659.10141,-0.14045,43.24706,32.48357
143.10200,11.92519,658.93247,-0.14045,43.51372,32.47525
143.90202,11.99186,659.25140,-0.14044,43.78038,32.49096
144.70202,12.05840,658.90676,-0.14045,44.04656,32.47398
145.50202,12.12513,658.56157,-0.14045,44.31346,32.45697
146.30200,12.19191,658.75691,-0.14045,44.58061,32.46659
147.10200,12.25846,659.34951,-0.14045,44.84679,32.49580
147.90202,12.32507,659.27063,-0.14044,45.11321,32.49191
148.70202,12.39179,659.76158,-0.14045,45.38011,32.51611
149.50202,12.45858,659.65033,-0.14045,45.64725,32.51062
150.30200,12.52524,660.30952,-0.14044,45.91391,32.54311
151.10200,12.59179,660.01313,-0.14045,46.18009,32.52850
151.90202,12.65845,660.04605,-0.14045,46.44675,32.53013
152.70202,12.72512,660.49290,-0.14045,46.71341,32.55215
153.50202,12.79178,661.04275,-0.14045,46.98007,32.57925
154.30200,12.85845,660.15930,-0.14045,47.24674,32.53571
155.10200,12.92511,661.10920,-0.14045,47.51340,32.58252
155.90202,12.99190,660.61830,-0.14045,47.78054,32.55833
156.70202,13.05850,661.06399,-0.14045,48.04696,32.58030
157.50202,13.12517,660.74049,-0.14045,48.31362,32.56435
158.30200,13.19183,660.89369,-0.14045,48.58028,32.57190
159.10200,13.25850,660.76755,-0.14045,48.84694,32.56569
159.90202,13.32516,660.86692,-0.14045,49.11360,32.57058
160.70202,13.39177,660.75497,-0.14045,49.38003,32.56507
161.50202,13.45856,661.21337,-0.14045,49.64717,32.58766
162.30200,13.52522,661.10380,-0.14045,49.91383,32.58226
163.10200,13.59177,661.38227,-0.14045,50.18001,32.59598
163.90202,13.65843,661.35242,-0.14045,50.44667,32.59451
164.70202,13.72528,661.75428,-0.14045,50.71405,32.61432
165.50202,13.79182,662.27927,-0.14045,50.98023,32.64019
166.30200,13.85843,662.37738,-0.14045,51.24665,32.64503
167.10200,13.92515,662.40104,-0.14045,51.51356,32.64619
167.90202,13.99182,661.77431,-0.14045,51.78022,32.61530
168.70202,14.05860,662.38483,-0.14045,52.04736,32.64539
169.50202,14.12521,662.55666,-0.14045,52.31377,32.65386
170.30200,14.19175,661.87712,-0.14045,52.57996,32.62037
171.10200,14.25842,661.76895,-0.14045,52.84662,32.61504
171.90202,14.32526,662.22292,-0.14045,53.11400,32.63741
172.70202,14.39187,660.99465,-0.14045,53.38042,32.57688
173.50202,14.45842,662.09454,-0.14045,53.64661,32.63109
174.30200,14.52514,662.00923,-0.14045,53.91350,32.62688
175.10200,14.59186,661.65077,-0.14045,54.18040,32.60921
175.90202,14.65853,661.71228,-0.14045,54.44707,32.61225
176.70202,14.72514,661.80872,-0.14045,54.71349,32.61700
177.50202,14.79180,662.21301,-0.14045,54.98015,32.63692
178.30200,14.85847,662.51620,-0.14045,55.24681,32.65187
179.10200,14.92513,662.94745,-0.14045,55.51347,32.67312
179.90202,14.99186,662.91448,-0.14045,55.78038,32.67150
180.70202,15.05858,663.15550,-0.14045,56.04727,32.68338
181.50202,15.12513,663.03541,-0.14045,56.31346,32.67746
182.30200,15.19185,662.66675,-0.14045,56.58036,32.65929
183.10200,15.25846,663.09911,-0.14045,56.84678,32.68060
183.90202,15.32518,662.63219,-0.14045,57.11368,32.65759
184.70202,15.39179,663.20654,-0.14045,57.38010,32.68589
185.50202,15.45851,663.02293,-0.14045,57.64700,32.67684
186.30200,15.52512,662.84165,-0.14045,57.91342,32.66791
187.10200,15.59178,663.13590,-0.14045,58.18008,32.68241
187.90202,15.65857,663.49357,-0.14045,58.44722,32.70004
188.70202,15.72511,662.81855,-0.14045,58.71340,32.66677
189.50202,15.79184,663.21804,-0.14045,58.98030,32.68646
190.30200,15.85850,663.31429,-0.14045,59.24697,32.69120
191.10200,15.92523,663.00752,-0.14045,59.51386,32.67608
191.90202,15.99184,662.69175,-0.14045,59.78029,32.66052
192.70202,16.05844,663.28566,-0.14045,60.04671,32.68979
193.50202,16.12511,663.87816,-0.14045,60.31337,32.71899
194.30200,16.19183,663.72794,-0.14045,60.58027,32.71159
195.10200,16.25850,663.95253,-0.14045,60.84694,32.72266
195.90202,16.32516,664.46946,-0.14045,61.11359,32.74813
196.70202,16.39183,664.86383,-0.14045,61.38026,32.76757
197.50202,16.45843,664.65605,-0.14045,61.64667,32.75733
198.30200,16.52516,664.67193,-0.14045,61.91357,32.75811
199.10200,16.59188,665.14746,-0.14045,62.18048,32.78155
199.90202,16.65849,665.19058,-0.14045,62.44690,32.78367
200.70202,16.72515,665.08027,-0.14045,62.71356,32.77824
201.50202,16.79176,664.68348,-0.14045,62.97998,32.75868
202.30202,16.85848,664.22992,-0.14045,63.24688,32.73633
203.10200,16.92521,663.48920,-0.14045,63.51378,32.69982
203.90202,16.99182,664.29982,-0.14045,63.78021,32.73977
204.70202,17.05842,664.34178,-0.14045,64.04663,32.74184
205.50202,17.12508,664.55202,-0.14045,64.31329,32.75220
206.30202,17.19199,664.20827,-0.14045,64.58091,32.73526
207.10200,17.25860,664.36329,-0.14045,64.84733,32.74290
207.90202,17.32508,665.33452,-0.14045,65.11327,32.79077
208.70202,17.39181,665.32227,-0.14045,65.38017,32.79016
209.50202,17.45853,666.11073,-0.14045,65.64708,32.82902
210.30202,17.52520,665.43794,-0.14045,65.91373,32.79586
211.10200,17.59180,665.83203,-0.14045,66.18016,32.81529
211.90202,17.65847,665.92577,-0.14045,66.44681,32.81991
212.70202,17.72513,666.21979,-0.14045,66.71348,32.83440
213.50202,17.79186,665.88996,-0.14045,66.98038,32.81814
214.30202,17.85858,665.93960,-0.14045,67.24728,32.82059
215.10200,17.92513,665.33377,-0.14045,67.51346,32.79073
215.90202,17.99179,665.19342,-0.14045,67.78013,32.78381
216.70202,18.05852,665.60381,-0.14045,68.04702,32.80404
217.50202,18.12518,665.16092,-0.14045,68.31368,32.78221
218.30202,18.19179,664.87966,-0.14045,68.58011,32.76835
219.10200,18.25857,665.46714,-0.14045,68.84724,32.79730
219.90202,18.32512,664.87119,-0.14045,69.11343,32.76793
220.70202,18.39179,665.61769,-0.14045,69.38009,32.80473
221.50202,18.45857,665.93112,-0.14045,69.64723,32.82017
222.30202,18.52518,665.59380,-0.14045,69.91365,32.80355
223.10200,18.59178,665.75310,-0.14045,70.18008,32.81140
223.90202,18.65839,666.66049,-0.14045,70.44649,32.85612
224.70202,18.72517,666.51339,-0.14045,70.71363,32.84887
225.50202,18.79196,666.58156,-0.14045,70.98078,32.85223
226.30202,18.85850,665.94500,-0.14045,71.24696,32.82085
227.10200,18.92517,667.10762,-0.14045,71.51362,32.87815
227.90202,18.99177,666.34533,-0.14045,71.78004,32.84058
228.70202,19.05856,665.64148,-0.14045,72.04717,32.80590
229.50202,19.12522,666.14640,-0.14045,72.31384,32.83078
230.30202,19.19177,666.27176,-0.14045,72.58002,32.83696
231.10200,19.25849,665.84563,-0.14045,72.84692,32.81596
231.90202,19.32516,665.16646,-0.14045,73.11358,32.78249
232.70202,19.39189,665.16148,-0.14045,73.38049,32.78224
233.50202,19.45849,664.92083,-0.14045,73.64690,32.77038
234.30202,19.52510,664.75100,-0.14045,73.91333,32.76201
235.10200,19.59188,665.04353,-0.14045,74.18047,32.77643
235.90202,19.65855,665.55319,-0.14045,74.44713,32.80154
236.70202,19.72527,665.40376,-0.14045,74.71403,32.79418
237.50202,19.79188,664.97703,-0.14045,74.98045,32.77315
238.30202,19.85848,664.81554,-0.14045,75.24688,32.76519
239.10200,19.92515,665.06304,-0.14045,75.51353,32.77739
239.90202,19.99181,664.24287,-0.14045,75.78019,32.73697
240.70202,20.05854,664.10722,-0.14045,76.04709,32.73028
241.50202,20.12508,663.90764,-0.14045,76.31328,32.72044
242.30202,20.19175,663.96543,-0.14045,76.57993,32.72329
243.10200,20.25841,663.44384,-0.14045,76.84660,32.69759
243.90202,20.32526,663.36081,-0.14045,77.11398,32.69349
244.70202,20.39186,664.15486,-0.14045,77.38039,32.73263
245.50202,20.45853,663.76473,-0.14045,77.64706,32.71340
246.30202,20.52513,664.14932,-0.14045,77.91348,32.73236
247.10200,20.59180,664.23835,-0.14045,78.18014,32.73674
247.90202,20.65858,664.04692,-0.14045,78.44728,32.72731
248.70202,20.72513,664.27598,-0.14045,78.71347,32.73860
249.50202,20.79180,664.20692,-0.14045,78.98013,32.73520
250.30202,20.85846,664.68203,-0.14045,79.24680,32.75861
251.10200,20.92525,664.64748,-0.14045,79.51393,32.75691
251.90202,20.99185,664.21707,-0.14045,79.78035,32.73569
252.70202,21.05840,664.71021,-0.14045,80.04654,32.76000
253.50202,21.12524,665.02271,-0.14045,80.31391,32.77540
254.30202,21.19185,664.74965,-0.14045,80.58034,32.76194
255.10200,21.25851,664.93582,-0.14045,80.84699,32.77112
255.90202,21.32518,665.81410,-0.14045,81.11365,32.81440
256.70203,21.39184,665.37936,-0.14045,81.38031,32.79298
257.50202,21.45845,665.67576,-0.14045,81.64673,32.80759
258.30200,21.52511,665.26150,-0.14045,81.91340,32.78717
259.10202,21.59190,665.23249,-0.14045,82.18054,32.78574
259.90202,21.65850,664.76446,-0.14045,82.44697,32.76267
260.70203,21.72511,665.47096,-0.14045,82.71338,32.79749
261.50202,21.79177,665.18956,-0.14045,82.98005,32.78362
262.30200,21.85850,665.57024,-0.14045,83.24695,32.80238
263.10203,21.92523,665.25084,-0.14045,83.51385,32.78664
263.90200,21.99183,665.26863,-0.14045,83.78026,32.78752
264.70203,22.05850,666.21676,-0.14045,84.04693,32.83425
265.50200,22.12510,665.65964,-0.14045,84.31334,32.80679
266.30200,22.19195,665.44954,-0.14046,84.58073,32.79644
267.10203,22.25861,665.65094,-0.14045,84.84740,32.80636
267.90200,22.32504,665.33810,-0.14045,85.11309,32.79094
268.70203,22.39176,665.22877,-0.14045,85.38000,32.78556
269.50200,22.45849,665.13782,-0.14045,85.64690,32.78107
270.30200,22.52521,665.55655,-0.14045,85.91380,32.80171
271.10203,22.59188,665.28507,-0.14045,86.18045,32.78833
271.90200,22.65848,665.14071,-0.14045,86.44689,32.78122
272.70203,22.72515,665.95208,-0.14045,86.71354,32.82121
273.50200,22.79181,665.63790,-0.14045,86.98020,32.80572
274.30200,22.85854,666.26980,-0.14045,87.24710,32.83686
275.10203,22.92514,666.73444,-0.14045,87.51352,32.85976
275.90200,22.99187,666.99255,-0.14045,87.78043,32.87248
276.70203,23.05848,666.95241,-0.14045,88.04685,32.87051
277.50200,23.12520,666.62785,-0.14046,88.31374,32.85451
278.30200,23.19186,666.16884,-0.14045,88.58041,32.83189
279.10203,23.25847,666.81388,-0.14045,88.84683,32.86368
279.90200,23.32513,666.48792,-0.14046,89.11349,32.84761
280.70203,23.39180,666.10854,-0.14045,89.38015,32.82891
281.50200,23.45847,666.37225,-0.14045,89.64682,32.84191
282.30200,23.52519,666.31683,-0.14045,89.91371,32.83918
283.10203,23.59192,666.81611,-0.14045,90.18061,32.86379
283.90200,23.65846,667.66734,-0.14045,90.44679,32.90574
284.70203,23.72513,667.32042,-0.14045,90.71345,32.88864
285.50200,23.79197,667.43195,-0.14046,90.98083,32.89414
286.30200,23.85846,667.78143,-0.14045,91.24678,32.91136
287.10203,23.92512,668.45147,-0.14045,91.51344,32.94439
287.90200,23.99185,668.07126,-0.14045,91.78033,32.92565
288.70203,24.05846,668.12369,-0.14046,92.04677,32.92823
289.50200,24.12512,667.75233,-0.14045,92.31343,32.90993
290.30200,24.19178,667.84075,-0.14045,92.58008,32.91429
291.10203,24.25851,667.30585,-0.14045,92.84699,32.88792
291.90200,24.32517,667.58213,-0.14045,93.11364,32.90154
292.70203,24.39190,666.82622,-0.14045,93.38055,32.86428
293.50200,24.45857,665.94779,-0.14045,93.64721,32.82099
294.30200,24.52511,666.24144,-0.14045,93.91339,32.83546
295.10203,24.59184,665.50160,-0.14045,94.18029,32.79900
295.90200,24.65844,665.75357,-0.14045,94.44671,32.81142
296.70203,24.72517,664.97573,-0.14045,94.71361,32.77309
297.50200,24.79183,665.34071,-0.14045,94.98028,32.79107
298.30200,24.85850,665.69671,-0.14045,95.24694,32.80862
299.10203,24.92510,665.78584,-0.14045,95.51336,32.81301
299.90200,24.99177,666.30933,-0.14045,95.78002,32.83881
300.70203,25.05861,667.09942,-0.14046,96.04740,32.87775
301.50200,25.12516,667.16098,-0.14045,96.31358,32.88078
302.30200,25.19176,667.51218,-0.14045,96.58000,32.89809
303.10203,25.25843,667.47870,-0.14046,96.84666,32.89644
303.90200,25.32521,666.90417,-0.14046,97.11380,32.86813
304.70203,25.39188,667.10049,-0.14045,97.38047,32.87780
305.50200,25.45848,666.36745,-0.14045,97.64689,32.84167
306.30200,25.52515,665.86649,-0.14045,97.91355,32.81699
307.10203,25.59176,664.87133,-0.14045,98.17998,32.76794
307.90200,25.65860,665.20004,-0.14046,98.44735,32.78414
308.70203,25.72521,665.85420,-0.14045,98.71377,32.81638
309.50200,25.79175,666.21504,-0.14045,98.97996,32.83416
310.30200,25.85848,665.67753,-0.14045,99.24685,32.80767
311.10203,25.92514,665.82179,-0.14046,99.51352,32.81478
311.90200,25.99187,666.00018,-0.14045,99.78042,32.82357
312.70203,26.05853,665.18714,-0.14046,100.04708,32.78350
313.50200,26.12514,665.90202,-0.14046,100.31350,32.81874
314.30200,26.19186,666.01615,-0.14046,100.58041,32.82436
315.10203,26.25847,665.77480,-0.14045,100.84682,32.81247
315.90200,26.32519,666.15394,-0.14046,101.11371,32.83115
316.70203,26.39186,665.94058,-0.14045,101.38038,32.82064
317.50200,26.45846,665.75129,-0.14045,101.64680,32.81131
318.30200,26.52507,666.08121,-0.14045,101.91323,32.82757
319.10203,26.59180,666.44633,-0.14045,102.18012,32.84556
319.90200,26.65852,665.80665,-0.14045,102.44702,32.81404
320.70203,26.72513,666.75334,-0.14045,102.71345,32.86069
321.50200,26.79179,666.49783,-0.14046,102.98011,32.84810
322.30200,26.85851,666.66459,-0.14046,103.24700,32.85632
323.10203,26.92524,667.38492,-0.14046,103.51391,32.89182
323.90200,26.99185,667.01402,-0.14045,103.78033,32.87354
324.70203,27.05839,667.20936,-0.14045,104.04651,32.88317
325.50200,27.12512,666.47651,-0.14046,104.31341,32.84705
326.30200,27.19184,667.60206,-0.14045,104.58032,32.90252
327.10203,27.25863,666.30719,-0.14046,104.84746,32.83871
327.90200,27.32517,666.39055,-0.14046,105.11364,32.84282
328.70203,27.39172,666.36717,-0.14045,105.37982,32.84166
329.50200,27.45844,666.03008,-0.14045,105.64673,32.82505
330.30200,27.52523,665.37051,-0.14045,105.91387,32.79254
331.10203,27.59184,665.91422,-0.14046,106.18029,32.81934
331.90200,27.65838,665.79427,-0.14045,106.44647,32.81343
332.70203,27.72522,665.60386,-0.14045,106.71384,32.80404
333.50200,27.79183,665.74444,-0.14046,106.98026,32.81097
334.30200,27.85855,665.65140,-0.14046,107.24716,32.80639
335.10203,27.92522,665.83403,-0.14045,107.51383,32.81539
335.90200,27.99177,665.86705,-0.14045,107.78002,32.81701
336.70203,28.05843,665.84623,-0.14046,108.04666,32.81599
337.50200,28.12516,665.41354,-0.14045,108.31357,32.79466
338.30200,28.19182,664.41456,-0.14045,108.58023,32.74543
339.10203,28.25849,664.76837,-0.14045,108.84690,32.76287
339.90200,28.32515,663.67439,-0.14046,109.11355,32.70895
340.70203,28.39182,663.46796,-0.14045,109.38021,32.69878
341.50200,28.45848,662.72449,-0.14045,109.64688,32.66213
342.30200,28.52527,662.84081,-0.14045,109.91402,32.66787
343.10203,28.59181,662.28891,-0.14045,110.18020,32.64067
343.90200,28.65848,661.62501,-0.14045,110.44686,32.60794
344.70203,28.72508,661.92034,-0.14045,110.71329,32.62250
345.50200,28.79193,661.81719,-0.14046,110.98067,32.61742
346.30200,28.85853,661.75009,-0.14045,111.24709,32.61411
347.10203,28.92514,661.77784,-0.14046,111.51351,32.61548
347.90200,28.99180,662.49007,-0.14045,111.78017,32.65058
348.70203,29.05847,662.90079,-0.14045,112.04683,32.67082
349.50200,29.12519,662.82623,-0.14045,112.31372,32.66715
350.30200,29.19180,663.84925,-0.14045,112.58014,32.71757
351.10203,29.25853,663.41865,-0.14045,112.84705,32.69635
351.90200,29.32519,664.18215,-0.14046,113.11371,32.73397
352.70203,29.39174,664.30327,-0.14046,113.37990,32.73994
353.50200,29.45852,663.97721,-0.14046,113.64703,32.72387
354.30200,29.52519,663.49064,-0.14045,113.91370,32.69989
355.10203,29.59179,663.27881,-0.14045,114.18011,32.68945
355.90200,29.65846,662.47266,-0.14046,114.44678,32.64972
356.70203,29.72513,662.55997,-0.14045,114.71344,32.65403
357.50200,29.79191,662.34334,-0.14045,114.98058,32.64335
358.30200,29.85845,662.15512,-0.14046,115.24676,32.63407
359.10203,29.92512,662.39187,-0.14045,115.51342,32.64574
359.90200,29.99178,662.56667,-0.14045,115.78008,32.65435
360.70203,30.05851,662.20080,-0.14046,116.04699,32.63633
361.50200,30.12524,661.43004,-0.14045,116.31389,32.59834
362.30200,30.19178,661.24122,-0.14045,116.58007,32.58903
363.10203,30.25845,661.45700,-0.14046,116.84674,32.59967
363.90200,30.32517,661.63163,-0.14046,117.11364,32.60827
364.70203,30.39195,660.41970,-0.14046,117.38076,32.54854
365.50200,30.45844,662.27298,-0.14045,117.64672,32.63988
366.30203,30.52505,661.89901,-0.14045,117.91314,32.62145
367.10203,30.59183,662.36267,-0.14046,118.18027,32.64430
367.90200,30.65850,662.75522,-0.14046,118.44693,32.66365
368.70203,30.72516,662.86572,-0.14045,118.71359,32.66909
369.50200,30.79177,662.61776,-0.14046,118.98003,32.65687
370.30203,30.85849,661.57514,-0.14045,119.24692,32.60549
371.10203,30.92516,661.72727,-0.14046,119.51357,32.61299
371.90200,30.99194,661.99927,-0.14046,119.78072,32.62639
372.70203,31.05849,661.65337,-0.14045,120.04691,32.60934
373.50200,31.12509,661.19987,-0.14046,120.31332,32.58699
374.30203,31.19182,661.27572,-0.14045,120.58022,32.59073
375.10203,31.25842,660.97248,-0.14046,120.84664,32.57579
375.90200,31.32521,661.27991,-0.14046,121.11378,32.59094
376.70203,31.39187,661.51838,-0.14045,121.38044,32.60269
377.50200,31.45848,662.31582,-0.14045,121.64687,32.64199
378.30203,31.52514,662.23657,-0.14045,121.91352,32.63809
379.10203,31.59181,662.66865,-0.14045,122.18019,32.65938
379.90200,31.65859,662.58651,-0.14046,122.44732,32.65533
380.70203,31.72514,662.60053,-0.14045,122.71349,32.65602
381.50200,31.79175,663.36025,-0.14045,122.97993,32.69347
382.30203,31.85847,663.47900,-0.14045,123.24682,32.69932
383.10203,31.92520,663.41944,-0.14046,123.51372,32.69638
383.90200,31.99180,663.27625,-0.14046,123.78016,32.68933
384.70203,32.05847,663.96492,-0.14046,124.04681,32.72327
385.50200,32.12513,663.92263,-0.14045,124.31347,32.72118
386.30203,32.19180,664.07421,-0.14046,124.58014,32.72865
387.10203,32.25858,663.63174,-0.14045,124.84727,32.70685
387.90200,32.32513,663.93036,-0.14046,125.11345,32.72157
388.70203,32.39179,663.74876,-0.14045,125.38012,32.71262
389.50200,32.45852,662.97580,-0.14045,125.64702,32.67452
390.30203,32.52518,662.99429,-0.14046,125.91367,32.67543
391.10203,32.59185,663.62992,-0.14046,126.18035,32.70676
391.90200,32.65845,663.24291,-0.14046,126.44676,32.68768
392.70203,32.72518,663.49218,-0.14046,126.71366,32.69997
393.50200,32.79179,663.54387,-0.14046,126.98009,32.70251
394.30203,32.85851,663.53432,-0.14046,127.24699,32.70205
395.10203,32.92518,664.09600,-0.14045,127.51365,32.72973
395.90200,32.99190,663.69721,-0.14045,127.78056,32.71008
396.70203,33.05845,663.43159,-0.14046,128.04674,32.69698
397.50200,33.12511,662.64672,-0.14046,128.31339,32.65830
398.30203,33.19184,663.11616,-0.14046,128.58030,32.68144
399.10203,33.25856,663.00342,-0.14046,128.84719,32.67588
399.90200,33.32505,663.63527,-0.14046,129.11314,32.70702
400.70203,33.39177,664.09302,-0.14045,129.38005,32.72958
401.50200,33.45850,664.39668,-0.14046,129.64693,32.74454
402.30203,33.52522,664.25186,-0.14046,129.91383,32.73741
403.10203,33.59183,664.85163,-0.14046,130.18026,32.76697
403.90200,33.65849,664.05027,-0.14046,130.44692,32.72747
404.70203,33.72510,665.23585,-0.14046,130.71333,32.78590
405.50200,33.79183,664.44171,-0.14045,130.98025,32.74677
406.30203,33.85855,663.54983,-0.14045,131.24714,32.70281
407.10203,33.92509,664.06489,-0.14045,131.51332,32.72820
407.90200,33.99182,663.78657,-0.14046,131.78023,32.71448
408.70203,34.05849,663.26121,-0.14046,132.04689,32.68859
409.50200,34.12521,663.54657,-0.14046,132.31379,32.70265
410.30203,34.19176,663.99891,-0.14045,132.57998,32.72494
411.10203,34.25848,664.27072,-0.14045,132.84688,32.73834
411.90200,34.32520,664.08133,-0.14046,133.11377,32.72900
412.70203,34.39175,664.47156,-0.14045,133.37996,32.74824
413.50200,34.45854,663.70494,-0.14045,133.64710,32.71045
414.30203,34.52520,663.58913,-0.14046,133.91376,32.70475
415.10203,34.59181,664.02028,-0.14046,134.18019,32.72600
415.90200,34.65847,663.33320,-0.14046,134.44684,32.69213
416.70203,34.72514,664.24808,-0.14045,134.71349,32.73722
417.50200,34.79192,664.04357,-0.14046,134.98064,32.72714
418.30203,34.85847,664.21321,-0.14045,135.24683,32.73550
419.10203,34.92519,664.06652,-0.14046,135.51372,32.72828
419.90200,34.99186,664.45400,-0.14046,135.78039,32.74737
420.70203,35.05846,664.41637,-0.14046,136.04680,32.74552
421.50200,35.12525,664.62401,-0.14046,136.31394,32.75575
422.30203,35.19180,664.90928,-0.14046,136.58013,32.76981
423.10203,35.25834,664.46974,-0.14045,136.84632,32.74815
423.90200,35.32518,665.04176,-0.14046,137.11368,32.77634
424.70203,35.39191,666.05317,-0.14046,137.38060,32.82619
425.50200,35.45846,665.85918,-0.14046,137.64677,32.81663
426.30203,35.52506,666.23217,-0.14046,137.91319,32.83501
427.10203,35.59178,665.71925,-0.14045,138.18009,32.80973
427.90200,35.65851,666.06496,-0.14045,138.44700,32.82677
428.70203,35.72530,666.87744,-0.14046,138.71413,32.86681
429.50200,35.79178,666.89439,-0.14046,138.98007,32.86765
430.30203,35.85845,667.28638,-0.14045,139.24675,32.88697
431.10203,35.92511,667.53356,-0.14046,139.51340,32.89915
431.90200,35.99178,667.59079,-0.14046,139.78006,32.90197
432.70203,36.05851,667.39977,-0.14046,140.04697,32.89255
433.50200,36.12517,667.05872,-0.14046,140.31363,32.87574
434.30203,36.19183,667.46329,-0.14045,140.58028,32.89568
435.10203,36.25844,667.19982,-0.14046,140.84672,32.88270
435.90200,36.32516,667.22450,-0.14046,141.11360,32.88391
436.70203,36.39189,666.84447,-0.14046,141.38051,32.86518
437.50200,36.45850,667.15549,-0.14046,141.64693,32.88051
438.30203,36.52510,667.52802,-0.14046,141.91334,32.89887
439.10203,36.59171,666.48317,-0.14046,142.17978,32.84738
439.90200,36.65849,666.59069,-0.14045,142.44692,32.85268
440.70203,36.72522,666.45229,-0.14046,142.71381,32.84586
441.50200,36.79182,666.35055,-0.14046,142.98023,32.84084
442.30203,36.85849,666.05806,-0.14046,143.24690,32.82643
443.10203,36.92515,666.55641,-0.14046,143.51356,32.85099
443.90200,36.99188,666.99125,-0.14046,143.78046,32.87242
444.70203,37.05848,667.59852,-0.14045,144.04689,32.90235
445.50200,37.12515,667.91596,-0.14046,144.31354,32.91799
446.30203,37.19187,667.71763,-0.14046,144.58044,32.90822
447.10203,37.25848,668.03508,-0.14046,144.84687,32.92386
447.90200,37.32514,668.14488,-0.14046,145.11352,32.92928
448.70203,37.39187,668.11824,-0.14046,145.38041,32.92796
449.50200,37.45848,668.72537,-0.14046,145.64685,32.95789
450.30203,37.52514,668.46390,-0.14046,145.91351,32.94500
451.10203,37.59192,668.14595,-0.14046,146.18064,32.92933
451.90200,37.65853,668.21286,-0.14046,146.44707,32.93262
452.70203,37.72520,668.86842,-0.14046,146.71373,32.96494
453.50200,37.79186,668.63168,-0.14046,146.98038,32.95327
454.30203,37.85847,668.84039,-0.14046,147.24681,32.96355
455.10203,37.92513,668.78432,-0.14046,147.51347,32.96079
455.90200,37.99186,669.23574,-0.14045,147.78037,32.98304
456.70203,38.05840,669.28868,-0.14046,148.04657,32.98565
457.50200,38.12507,668.95066,-0.14046,148.31322,32.96899
458.30203,38.19191,668.51843,-0.14046,148.58059,32.94769
459.10203,38.25864,668.80458,-0.14046,148.84750,32.96179
459.90200,38.32512,668.28104,-0.14046,149.11344,32.93599
460.70203,38.39179,668.57431,-0.14046,149.38010,32.95044
461.50200,38.45852,668.21729,-0.14046,149.64701,32.93285
462.30203,38.52524,668.11042,-0.14046,149.91391,32.92758
463.10203,38.59190,667.83885,-0.14046,150.18055,32.91419
463.90200,38.65839,668.45166,-0.14046,150.44651,32.94439
464.70203,38.72512,667.86883,-0.14045,150.71341,32.91567
465.50200,38.79190,668.06199,-0.14046,150.98054,32.92519
466.30203,38.85857,668.23205,-0.14046,151.24722,32.93357
467.10203,38.92517,668.05258,-0.14046,151.51364,32.92473
467.90200,38.99178,668.16611,-0.14046,151.78005,32.93032
468.70203,39.05850,668.05701,-0.14046,152.04695,32.92495
469.50200,39.12522,668.52882,-0.14045,152.31384,32.94820
470.30203,39.19183,669.25921,-0.14046,152.58026,32.98420
471.10203,39.25844,669.19657,-0.14045,152.84669,32.98111
471.90200,39.32516,670.02769,-0.14046,153.11359,33.02207
472.70203,39.39182,670.04659,-0.14046,153.38025,33.02300
473.50200,39.45849,670.48203,-0.14045,153.64692,33.04446
474.30203,39.52522,670.02159,-0.14046,153.91382,33.02177
475.10203,39.59188,670.00575,-0.14045,154.18048,33.02099
475.90200,39.65849,670.23383,-0.14046,154.44691,33.03223
476.70203,39.72515,669.88347,-0.14046,154.71357,33.01496
477.50200,39.79188,670.02536,-0.14045,154.98047,33.02195
478.30203,39.85854,669.68510,-0.14046,155.24712,33.00518
479.10203,39.92515,669.54643,-0.14045,155.51355,32.99835
479.90200,39.99182,669.84007,-0.14045,155.78021,33.01282
480.70203,40.05854,669.21460,-0.14046,156.04711,32.98199
481.50200,40.12520,669.38531,-0.14046,156.31377,32.99041
482.30203,40.19181,669.20538,-0.14046,156.58017,32.98154
483.10203,40.25848,668.50646,-0.14046,156.84686,32.94710
483.90200,40.32514,669.00351,-0.14045,157.11350,32.97159
484.70203,40.39187,668.38572,-0.14046,157.38040,32.94115
485.50200,40.45853,669.02325,-0.14046,157.64709,32.97256
486.30203,40.52508,668.62553,-0.14045,157.91326,32.95296
487.10203,40.59180,668.27284,-0.14046,158.18015,32.93558
487.90200,40.65853,667.70413,-0.14046,158.44707,32.90755
488.70203,40.72519,667.51200,-0.14046,158.71372,32.89808
489.50200,40.79180,667.69337,-0.14045,158.98014,32.90702
490.30203,40.85852,666.47017,-0.14046,159.24704,32.84674
491.10203,40.92519,666.00768,-0.14045,159.51370,32.82394
491.90203,40.99180,666.14226,-0.14046,159.78013,32.83058
492.70203,41.05858,665.70449,-0.14046,160.04727,32.80900
493.50200,41.12512,666.12945,-0.14046,160.31344,32.82994
494.30203,41.19179,665.39017,-0.14045,160.58010,32.79351
495.10203,41.25845,665.05214,-0.14046,160.84676,32.77685
495.90203,41.32518,665.53233,-0.14046,161.11367,32.80052
496.70203,41.39184,665.23282,-0.14046,161.38033,32.78576
497.50200,41.45851,664.90048,-0.14046,161.64700,32.76937
498.30203,41.52518,665.10979,-0.14046,161.91366,32.77969
499.10203,41.59178,664.87477,-0.14045,162.18007,32.76811
499.90203,41.65851,664.83030,-0.14046,162.44698,32.76592
500.70203,41.72523,664.67668,-0.14045,162.71387,32.75835
501.50200,41.79178,665.08432,-0.14046,162.98006,32.77844
502.30203,41.85844,666.03329,-0.14045,163.24672,32.82521
503.10203,41.92517,664.94313,-0.14046,163.51361,32.77148
503.90203,41.99189,664.78765,-0.14045,163.78051,32.76382
504.70203,42.05844,665.24553,-0.14046,164.04670,32.78638
505.50200,42.12510,665.73764,-0.14046,164.31336,32.81063
506.30203,42.19183,665.47869,-0.14046,164.58026,32.79787
507.10203,42.25849,665.09279,-0.14046,164.84691,32.77885
507.90203,42.32516,665.61615,-0.14046,165.11359,32.80465
508.70203,42.39182,665.94905,-0.14046,165.38024,32.82106
509.50200,42.45849,666.79865,-0.14045,165.64690,32.86293
510.30203,42.52516,666.37779,-0.14045,165.91358,32.84219
511.10203,42.59182,666.47697,-0.14046,166.18023,32.84707
511.90203,42.65849,666.53606,-0.14046,166.44689,32.84999
512.70203,42.72515,666.70552,-0.14046,166.71356,32.85834
513.50200,42.79182,666.27231,-0.14046,166.98022,32.83699
514.30200,42.85842,665.75017,-0.14046,167.24664,32.81125
515.10206,42.92521,666.58854,-0.14046,167.51378,32.85257
515.90203,42.99187,666.45546,-0.14046,167.78044,32.84601
516.70203,43.05842,666.66603,-0.14045,168.04662,32.85639
517.50200,43.12514,666.04181,-0.14046,168.31352,32.82563
518.30200,43.19175,665.78961,-0.14045,168.57994,32.81320
519.10206,43.25859,665.91715,-0.14046,168.84732,32.81948
519.90203,43.32520,665.20227,-0.14046,169.11376,32.78425
520.70203,43.39174,665.39794,-0.14046,169.37993,32.79389
521.50200,43.45847,664.32790,-0.14046,169.64682,32.74116
522.30200,43.52525,664.23402,-0.14046,169.91396,32.73653
523.10206,43.59186,664.61903,-0.14045,170.18039,32.75550
523.90203,43.65847,664.71589,-0.14045,170.44681,32.76028
524.70200,43.72513,664.39719,-0.14046,170.71348,32.74457
525.50200,43.79180,663.94494,-0.14046,170.98014,32.72228
526.30200,43.85852,663.88794,-0.14046,171.24702,32.71947
527.10206,43.92519,664.07183,-0.14045,171.51369,32.72854
527.90206,43.99185,663.72915,-0.14046,171.78035,32.71165
528.70200,44.05851,663.40836,-0.14046,172.04701,32.69584
529.50200,44.12518,664.14615,-0.14046,172.31368,32.73220
530.30200,44.19191,663.69623,-0.14046,172.58058,32.71003
531.10206,44.25851,663.49134,-0.14046,172.84700,32.69993
531.90206,44.32518,663.07364,-0.14045,173.11367,32.67934
532.70200,44.39178,662.85008,-0.14045,173.38008,32.66832
533.50200,44.45851,663.42931,-0.14046,173.64699,32.69687
534.30200,44.52518,663.07527,-0.14046,173.91366,32.67942
535.10206,44.59190,663.20254,-0.14045,174.18053,32.68570
535.90206,44.65851,663.59579,-0.14046,174.44696,32.70507
536.70200,44.72505,663.37814,-0.14046,174.71316,32.69435
537.50200,44.79189,662.29156,-0.14046,174.98052,32.64080
538.30200,44.85856,662.11587,-0.14046,175.24718,32.63214
539.10206,44.92511,661.79829,-0.14046,175.51337,32.61649
539.90206,44.99177,660.76978,-0.14046,175.78002,32.56580
540.70200,45.05855,660.72117,-0.14045,176.04717,32.56340
541.50200,45.12516,659.82277,-0.14046,176.31360,32.51912
542.30200,45.19183,659.67436,-0.14046,176.58025,32.51181
543.10206,45.25849,659.37312,-0.14046,176.84691,32.49696
543.90206,45.32516,658.86853,-0.14046,177.11359,32.47210
544.70200,45.39182,658.99873,-0.14046,177.38024,32.47851
545.50200,45.45849,659.09894,-0.14046,177.64690,32.48345
546.30200,45.52510,659.33485,-0.14045,177.91333,32.49508
547.10206,45.59182,658.85214,-0.14046,178.18023,32.47129
547.90206,45.65854,660.09588,-0.14045,178.44712,32.53259
548.70200,45.72515,659.52791,-0.14045,178.71355,32.50459
549.50200,45.79181,659.54593,-0.14046,178.98020,32.50548
550.30200,45.85854,659.99134,-0.14046,179.24709,32.52743
551.10206,45.92515,660.01681,-0.14046,179.51353,32.52869
551.90206,45.99175,660.64815,-0.14046,179.77995,32.55980
552.70200,46.05847,661.42683,-0.14046,180.04684,32.59818
553.50200,46.12514,661.96499,-0.14045,180.31352,32.62470
554.30200,46.19181,661.87996,-0.14046,180.58017,32.62051
555.10206,46.25841,661.96881,-0.14046,180.84658,32.62489
555.90206,46.32514,661.91070,-0.14046,181.11351,32.62202
556.70200,46.39192,661.85594,-0.14046,181.38063,32.61933
557.50200,46.45847,662.48584,-0.14045,181.64682,32.65037
558.30200,46.52507,662.51424,-0.14046,181.91323,32.65177
559.10206,46.59180,661.46026,-0.14046,182.18015,32.59983
559.90206,46.65852,661.25765,-0.14046,182.44703,32.58984
560.70200,46.72525,660.80135,-0.14046,182.71395,32.56735
561.50200,46.79179,660.03082,-0.14046,182.98012,32.52938
562.30200,46.85846,659.73401,-0.14045,183.24678,32.51475
563.10206,46.92512,659.02201,-0.14046,183.51343,32.47966
563.90206,46.99185,658.23821,-0.14045,183.78035,32.44103
564.70200,47.05851,657.95011,-0.14046,184.04701,32.42683
565.50200,47.12506,658.31225,-0.14045,184.31318,32.44468
566.30200,47.19185,658.19579,-0.14046,184.58034,32.43894
567.10206,47.25851,657.45958,-0.14045,184.84700,32.40265
567.90206,47.32511,658.56478,-0.14046,185.11341,32.45712
568.70200,47.39178,659.14784,-0.14046,185.38008,32.48586
569.50200,47.45856,659.15976,-0.14045,185.64720,32.48645
570.30200,47.52517,659.04064,-0.14046,185.91362,32.48058
571.10206,47.59172,659.15715,-0.14045,186.17983,32.48632
571.90206,47.65856,659.31017,-0.14046,186.44719,32.49386
572.70200,47.72516,659.08949,-0.14046,186.71360,32.48298
573.50200,47.79177,658.72739,-0.14045,186.98003,32.46514
574.30200,47.85844,659.02136,-0.14046,187.24669,32.47963
575.10206,47.92516,659.42924,-0.14046,187.51359,32.49973
575.90206,47.99183,659.57163,-0.14046,187.78026,32.50675
576.70200,48.05849,659.50318,-0.14046,188.04692,32.50337
577.50200,48.12522,659.44172,-0.14046,188.31382,32.50034
578.30200,48.19177,660.20698,-0.14045,188.58001,32.53806
579.10206,48.25861,660.34817,-0.14046,188.84737,32.54502
579.90206,48.32515,660.46179,-0.14046,189.11357,32.55062
580.70200,48.39182,660.96382,-0.14046,189.38023,32.57536
581.50200,48.45843,661.42501,-0.14046,189.64666,32.59809
582.30200,48.52515,661.07949,-0.14045,189.91354,32.58106
583.10206,48.59188,661.21500,-0.14046,190.18046,32.58774
583.90206,48.65842,661.46688,-0.14046,190.44663,32.60015
584.70200,48.72514,661.80225,-0.14045,190.71352,32.61668
585.50200,48.79187,660.90412,-0.14045,190.98043,32.57242
586.30200,48.85860,661.93002,-0.14045,191.24734,32.62298
587.10206,48.92520,661.21044,-0.14046,191.51375,32.58751
587.90206,48.99181,661.72490,-0.14045,191.78019,32.61287
588.70200,49.05847,662.35834,-0.14046,192.04684,32.64409
589.50200,49.12514,662.34278,-0.14046,192.31349,32.64332
590.30200,49.19186,662.38348,-0.14045,192.58040,32.64533
591.10206,49.25853,663.83244,-0.14046,192.84705,32.71674
591.90206,49.32513,662.92933,-0.14046,193.11348,32.67223
592.70200,49.39174,663.78978,-0.14045,193.37991,32.71464
593.50200,49.45846,664.24371,-0.14046,193.64680,32.73701
594.30200,49.52525,664.59961,-0.14046,193.91394,32.75455
595.10206,49.59192,665.27645,-0.14046,194.18061,32.78791
595.90206,49.65846,666.18701,-0.14046,194.44679,32.83278
596.70200,49.72512,666.53155,-0.14046,194.71344,32.84976
597.50200,49.79179,666.66864,-0.14045,194.98012,32.85652
598.30200,49.85852,666.56480,-0.14046,195.24702,32.85140
599.10206,49.92512,665.99222,-0.14046,195.51343,32.82318
599.90206,49.99179,666.68363,-0.14045,195.78010,32.85726
600.70200,50.05851,666.52196,-0.14046,196.04701,32.84929
601.50200,50.12523,666.82012,-0.14045,196.31388,32.86399
602.30200,50.19184,666.62934,-0.14045,196.58031,32.85458
603.10206,50.25839,667.60872,-0.14046,196.84651,32.90285
603.90206,50.32517,667.04713,-0.14046,197.11363,32.87517
604.70200,50.39178,667.79628,-0.14046,197.38007,32.91209
605.50200,50.45850,667.67405,-0.14046,197.64696,32.90607
606.30200,50.52517,667.96429,-0.14046,197.91361,32.92038
607.10206,50.59190,667.63218,-0.14046,198.18053,32.90401
607.90206,50.65844,667.28890,-0.14045,198.44670,32.88709
608.70200,50.72510,666.94738,-0.14045,198.71336,32.87026
609.50200,50.79183,667.06575,-0.14046,198.98027,32.87609
610.30200,50.85844,666.25997,-0.14046,199.24669,32.83638
611.10206,50.92522,666.05117,-0.14046,199.51383,32.82609
611.90206,50.99177,666.39376,-0.14045,199.78002,32.84297
612.70200,51.05843,666.51274,-0.14046,200.04668,32.84883
613.50200,51.12516,666.38659,-0.14045,200.31357,32.84262
614.30200,51.19182,667.51111,-0.14046,200.58024,32.89804
615.10206,51.25843,667.55279,-0.14046,200.84667,32.90009
615.90206,51.32509,668.07964,-0.14046,201.11332,32.92606
616.70200,51.39194,667.50604,-0.14046,201.38071,32.89779
617.50200,51.45854,668.46311,-0.14046,201.64711,32.94496
618.30200,51.52509,668.20658,-0.14045,201.91329,32.93232
619.10206,51.59182,668.69822,-0.14045,202.18022,32.95655
619.90206,51.65848,669.18102,-0.14046,202.44687,32.98034
620.70200,51.72520,669.32766,-0.14046,202.71375,32.98757
621.50200,51.79181,669.44500,-0.14046,202.98018,32.99335
622.30200,51.85842,670.60469,-0.14045,203.24662,33.05051
623.10206,51.92514,670.38210,-0.14046,203.51350,33.03954
623.90206,51.99193,670.50890,-0.14046,203.78065,33.04578
624.70200,52.05859,670.99412,-0.14046,204.04730,33.06970
625.50200,52.12508,671.56381,-0.14046,204.31325,33.09777
626.30200,52.19180,671.54113,-0.14046,204.58016,33.09666
627.10206,52.25853,671.74751,-0.14046,204.84705,33.10683
627.90206,52.32519,671.62402,-0.14045,205.11370,33.10074
628.70200,52.39179,672.55599,-0.14046,205.38013,33.14668
629.50200,52.45846,672.51092,-0.14046,205.64680,33.14445
630.30200,52.52513,672.50608,-0.14046,205.91345,33.14421
631.10206,52.59179,672.66230,-0.14046,206.18012,33.15192
631.90206,52.65852,673.51866,-0.14046,206.44703,33.19412
632.70200,52.72518,673.40410,-0.14046,206.71368,33.18847
633.50200,52.79179,673.86990,-0.14046,206.98009,33.21143
634.30200,52.85846,674.24099,-0.14046,207.24678,33.22972
635.10206,52.92518,674.10655,-0.14046,207.51367,33.22309
635.90206,52.99191,675.16370,-0.14046,207.78058,33.27520
636.70200,53.05845,675.56575,-0.14045,208.04677,33.29501
637.50200,53.12517,676.13856,-0.14046,208.31363,33.32324
638.30200,53.19178,676.78778,-0.14046,208.58006,33.35524
639.10206,53.25851,677.53028,-0.14046,208.84697,33.39183
639.90206,53.32517,677.90337,-0.14046,209.11362,33.41022
640.70200,53.39177,678.64191,-0.14046,209.38003,33.44662
641.50200,53.45850,679.79749,-0.14045,209.64696,33.50357
642.30200,53.52517,680.61803,-0.14046,209.91361,33.54401
643.10206,53.59189,681.40579,-0.14046,210.18052,33.58284
643.90206,53.65850,682.22545,-0.14045,210.44695,33.62323
644.70200,53.72510,683.39086,-0.14046,210.71336,33.68067
645.50200,53.79183,684.47092,-0.14046,210.98025,33.73390
646.30200,53.85850,685.75796,-0.14045,211.24694,33.79733
647.10206,53.92522,687.54852,-0.14046,211.51381,33.88558
647.90206,53.99176,688.22522,-0.14046,211.78000,33.91893
648.70200,54.05855,688.97917,-0.14046,212.04715,33.95609
649.50200,54.12515,690.10435,-0.14046,212.31356,34.01154
650.30200,54.19182,690.99180,-0.14046,212.58020,34.05528
651.10206,54.25855,691.03884,-0.14046,212.84714,34.05759
651.90206,54.32515,692.74497,-0.14045,213.11355,34.14168
652.70200,54.39175,693.94214,-0.14045,213.37996,34.20068
653.50200,54.45842,695.04455,-0.14046,213.64663,34.25502
654.30200,54.52521,694.53716,-0.14045,213.91377,34.23001
655.10206,54.59187,694.55463,-0.14046,214.18042,34.23087
655.90206,54.65854,694.29446,-0.14046,214.44712,34.21805
656.70200,54.72514,694.95090,-0.14046,214.71353,34.25040
657.50200,54.79175,693.24984,-0.14045,214.97993,34.16656
658.30200,54.85859,692.06548,-0.14045,215.24732,34.10819
659.10206,54.92514,689.30481,-0.14046,215.51352,33.97213
659.90206,54.99180,686.03121,-0.14046,215.78016,33.81079
660.70200,55.05847,677.89122,-0.14046,216.04681,33.40962
661.50200,55.12513,663.48561,-0.14046,216.31348,32.69965
662.30200,55.19186,577.26214,-0.14045,216.58037,28.45015
662.36206,55.19688,6.98033,-0.14045,216.60047,0.34402