File: Manufatura Aditiva/Classificação Orientação/Ensaios/Ensaios SLS/Tracao_OLABI_08_06_2018_SLS_ZY6.is_metal_RawData/Specimen_RawData_4.csv
Time,Extension,Load,Strain 1,Tensile strain,Tensile stress
(sec),(mm),(N),(mm/mm),(%),(MPa)
0.00000,0.00006,33.01998,0.00140,0.14010,1.80842
0.10000,0.00419,34.32147,0.00143,0.14306,1.87970
0.20000,0.01381,39.16383,0.00158,0.15825,2.14491
0.30000,0.02356,44.89749,0.00174,0.17446,2.45892
0.40000,0.03270,48.16488,0.00190,0.18975,2.63787
0.50000,0.04149,53.42286,0.00204,0.20432,2.92584
0.60000,0.04986,57.64089,0.00219,0.21884,3.15685
0.70000,0.05823,61.20711,0.00232,0.23229,3.35216
0.80000,0.06667,65.82568,0.00246,0.24609,3.60511
0.90000,0.07498,69.59292,0.00260,0.25961,3.81143
1.00000,0.08329,73.36114,0.00273,0.27300,4.01781
1.10000,0.09178,77.12009,0.00288,0.28751,4.22368
1.20000,0.10003,81.29550,0.00301,0.30135,4.45235
1.30000,0.10840,85.33812,0.00315,0.31527,4.67376
1.40000,0.11683,90.01362,0.00330,0.32979,4.92982
1.50000,0.12496,92.34267,0.00343,0.34258,5.05738
1.60000,0.13333,96.73334,0.00357,0.35695,5.29784
1.70000,0.14170,100.14926,0.00370,0.37032,5.48493
1.80000,0.14989,103.94682,0.00384,0.38375,5.69291
1.90000,0.15832,107.83415,0.00398,0.39754,5.90581
2.00000,0.16663,111.72921,0.00412,0.41167,6.11913
2.10000,0.17494,115.68004,0.00426,0.42609,6.33551
2.20000,0.18331,118.72889,0.00439,0.43916,6.50249
2.30000,0.19163,121.82918,0.00451,0.45079,6.67228
2.40000,0.19994,124.87950,0.00463,0.46263,6.83934
2.50000,0.20837,128.84928,0.00476,0.47633,7.05675
2.60000,0.21668,132.17441,0.00490,0.49025,7.23886
2.70000,0.22493,135.85485,0.00504,0.50389,7.44043
2.80000,0.23336,139.96350,0.00518,0.51791,7.66545
2.90000,0.24167,143.06000,0.00532,0.53175,7.83504
3.00000,0.24992,146.84163,0.00546,0.54574,8.04215
3.10000,0.25841,150.13780,0.00560,0.55983,8.22267
3.20000,0.26666,153.25161,0.00573,0.57304,8.39321
3.30000,0.27497,156.85097,0.00587,0.58689,8.59034
3.40000,0.28346,161.32843,0.00601,0.60084,8.83556
3.50000,0.29171,164.37442,0.00615,0.61472,9.00238
3.60000,0.30002,167.24409,0.00629,0.62910,9.15954
3.70000,0.30839,171.51269,0.00643,0.64250,9.39332
3.80000,0.31665,174.89607,0.00656,0.65606,9.57862
3.90000,0.32502,178.33466,0.00670,0.66983,9.76695
4.00000,0.33333,182.05653,0.00684,0.68367,9.97078
4.10000,0.34164,185.49152,0.00698,0.69776,10.15891
4.20000,0.34995,188.87827,0.00712,0.71163,10.34439
4.30000,0.35826,191.69269,0.00726,0.72574,10.49853
4.40000,0.36657,195.44500,0.00740,0.73960,10.70404
4.50000,0.37500,199.33900,0.00754,0.75356,10.91730
4.60000,0.38337,202.80352,0.00768,0.76751,11.10704
4.70000,0.39162,205.58464,0.00781,0.78083,11.25936
4.80000,0.39999,208.95104,0.00795,0.79520,11.44373
4.90000,0.40824,212.59671,0.00809,0.80910,11.64339
5.00000,0.41667,215.91804,0.00823,0.82313,11.82529
5.10000,0.42504,219.09256,0.00837,0.83737,11.99916
5.20000,0.43335,222.07219,0.00851,0.85050,12.16234
5.30000,0.44166,225.60579,0.00865,0.86468,12.35587
5.40000,0.45010,229.31541,0.00879,0.87852,12.55903
5.50000,0.45829,232.64531,0.00892,0.89198,12.74140
5.60000,0.46666,235.38689,0.00906,0.90610,12.89155
5.70000,0.47503,239.42816,0.00920,0.92003,13.11288
5.80000,0.48334,242.63558,0.00934,0.93396,13.28855
5.90000,0.49165,244.44694,0.00948,0.94816,13.38775
6.00000,0.50002,248.85386,0.00962,0.96249,13.62911
6.10000,0.50827,251.59456,0.00976,0.97630,13.77921
6.20000,0.51664,255.00292,0.00990,0.98988,13.96588
6.30000,0.52501,256.64493,0.01000,1.00006,14.05580
6.40000,0.53326,261.12634,0.01014,1.01374,14.30124
6.50000,0.54169,263.52492,0.01027,1.02743,14.43260
6.60000,0.55000,266.70992,0.01043,1.04257,14.60704
6.70000,0.55831,269.70287,0.01056,1.05633,14.77096
6.80000,0.56674,273.42909,0.01071,1.07070,14.97503
6.90000,0.57500,276.68094,0.01085,1.08473,15.15313
7.00000,0.58331,280.01068,0.01098,1.09844,15.33549
7.10000,0.59174,282.59044,0.01113,1.11296,15.47678
7.20000,0.59993,285.55333,0.01127,1.12675,15.63904
7.30000,0.60818,288.68166,0.01140,1.14030,15.81038
7.40000,0.61673,291.60641,0.01155,1.15471,15.97056
7.50000,0.62492,294.64073,0.01169,1.16875,16.13674
7.60000,0.63329,298.00804,0.01183,1.18261,16.32116
7.70000,0.64178,300.67526,0.01197,1.19684,16.46724
7.80000,0.64997,303.68827,0.01211,1.21057,16.63225
7.90000,0.65828,306.83724,0.01225,1.22487,16.80471
8.00000,0.66677,310.38432,0.01239,1.23943,16.99898
8.10000,0.67490,313.14238,0.01254,1.25365,17.15003
8.20000,0.68333,315.66254,0.01268,1.26764,17.28805
8.30000,0.69176,318.66978,0.01282,1.28206,17.45275
8.40000,0.70002,321.73593,0.01296,1.29585,17.62068
8.50000,0.70839,324.45586,0.01310,1.31025,17.76964
8.60000,0.71664,327.23199,0.01325,1.32490,17.92168
8.70000,0.72489,330.00032,0.01339,1.33906,18.07330
8.80000,0.73344,333.18321,0.01354,1.35408,18.24762
8.90000,0.74169,336.65872,0.01369,1.36919,18.43796
9.00000,0.75000,338.90903,0.01383,1.38274,18.56120
9.10000,0.75843,341.45366,0.01398,1.39796,18.70057
9.20000,0.76662,344.61047,0.01412,1.41197,18.87346
9.30000,0.77493,347.22339,0.01426,1.42588,19.01656
9.40000,0.78336,350.16311,0.01441,1.44070,19.17756
9.50000,0.79161,352.62108,0.01455,1.45529,19.31218
9.60000,0.79992,355.06834,0.01470,1.47011,19.44621
9.70000,0.80835,357.95229,0.01484,1.48434,19.60416
9.80000,0.81660,360.13527,0.01496,1.49631,19.72371
9.90000,0.82498,362.19356,0.01509,1.50892,19.83644
10.00000,0.83341,365.00844,0.01523,1.52346,19.99060
10.10000,0.84166,367.38862,0.01538,1.53844,20.12096
10.20000,0.84991,370.26030,0.01552,1.55228,20.27824
10.30000,0.85840,373.03783,0.01567,1.56732,20.43035
10.40000,0.86665,375.24779,0.01582,1.58213,20.55139
10.50000,0.87502,377.59386,0.01597,1.59697,20.67988
10.60000,0.88333,380.46904,0.01612,1.61182,20.83734
10.70000,0.89164,383.02878,0.01626,1.62630,20.97753
10.80000,0.90007,386.16664,0.01641,1.64118,21.14939
10.90000,0.90832,387.92146,0.01656,1.65568,21.24549
11.00000,0.91669,390.58484,0.01670,1.67043,21.39136
11.10000,0.92506,392.73598,0.01685,1.68535,21.50917
11.20000,0.93331,395.63538,0.01700,1.69986,21.66796
11.30000,0.94162,397.92596,0.01714,1.71446,21.79342
11.40000,0.95000,400.37152,0.01729,1.72945,21.92735
11.50000,0.95825,402.85005,0.01744,1.74413,22.06310
11.60000,0.96656,405.16523,0.01760,1.75953,22.18989
11.70000,0.97505,407.14345,0.01775,1.77468,22.29823
11.80000,0.98336,409.97909,0.01790,1.78974,22.45354
11.90000,0.99161,412.30437,0.01804,1.80430,22.58088
12.00000,1.00010,414.08376,0.01819,1.81928,22.67834
12.10000,1.00835,416.30268,0.01834,1.83424,22.79986
12.20000,1.01666,419.62606,0.01849,1.84917,22.98187
12.30000,1.02509,421.61345,0.01865,1.86493,23.09072
12.40000,1.03328,423.64351,0.01880,1.87981,23.20190
12.50000,1.04165,426.24269,0.01895,1.89491,23.34425
12.60000,1.04996,428.52666,0.01910,1.91012,23.46934
12.70000,1.05827,430.25021,0.01925,1.92515,23.56373
12.80000,1.06664,432.97843,0.01940,1.94018,23.71315
12.90000,1.07502,434.84219,0.01955,1.95549,23.81523
13.00000,1.08333,437.35974,0.01971,1.97092,23.95311
13.10000,1.09176,439.03673,0.01986,1.98604,24.04495
13.20000,1.10001,441.07032,0.02002,2.00164,24.15632
13.30000,1.10838,443.46591,0.02017,2.01683,24.28753
13.40000,1.11675,445.85392,0.02032,2.03213,24.41831
13.50000,1.12500,445.69909,0.02042,2.04238,24.40983
13.60000,1.13325,448.56798,0.02058,2.05802,24.56695
13.70000,1.14174,451.37377,0.02074,2.07377,24.72062
13.80000,1.14993,453.59293,0.02089,2.08870,24.84216
13.90000,1.15824,455.32808,0.02105,2.10465,24.93719
14.00000,1.16673,457.07095,0.02120,2.12035,25.03264
14.10000,1.17498,459.35903,0.02136,2.13596,25.15795
14.20000,1.18329,461.44947,0.02151,2.15144,25.27244
14.30000,1.19178,462.70951,0.02167,2.16690,25.34145
14.40000,1.19998,465.19777,0.02183,2.18289,25.47772
14.50000,1.20829,467.35937,0.02199,2.19871,25.59611
14.60000,1.21672,468.81242,0.02214,2.21400,25.67569
14.70000,1.22491,471.14394,0.02230,2.22973,25.80338
14.80000,1.23334,473.26330,0.02245,2.24550,25.91945
14.90000,1.24171,474.72087,0.02262,2.26155,25.99928
15.00000,1.24996,477.21337,0.02277,2.27728,26.13579
15.10000,1.25833,478.97659,0.02294,2.29377,26.23236
15.20000,1.26670,480.29912,0.02310,2.30952,26.30479
15.30000,1.27495,482.12097,0.02325,2.32500,26.40457
15.40000,1.28344,484.52802,0.02341,2.34064,26.53639
15.50000,1.29169,485.87075,0.02357,2.35652,26.60993
15.60000,1.29994,487.65210,0.02372,2.37246,26.70749
15.70000,1.30837,489.26482,0.02389,2.38909,26.79582
15.80000,1.31662,490.98087,0.02405,2.40507,26.88980
15.90000,1.32488,493.28562,0.02421,2.42138,27.01603
16.00000,1.33343,494.81508,0.02437,2.43697,27.09979
16.10000,1.34162,497.28230,0.02453,2.45342,27.23491
16.20000,1.34993,498.51616,0.02469,2.46921,27.30249
16.30000,1.35848,499.97712,0.02486,2.48562,27.38250
16.40000,1.36667,501.88601,0.02502,2.50199,27.48705
16.50000,1.37504,503.94810,0.02518,2.51815,27.59998
16.60000,1.38341,504.46182,0.02532,2.53183,27.62812
16.70000,1.39160,506.06313,0.02547,2.54701,27.71582
16.80000,1.39997,507.59269,0.02563,2.56313,27.79959
16.90000,1.40840,509.65850,0.02580,2.57959,27.91273
17.00000,1.41659,510.74005,0.02596,2.59580,27.97196
17.10000,1.42496,512.41592,0.02612,2.61228,28.06375
17.20000,1.43333,514.01295,0.02629,2.62860,28.15121
17.30000,1.44164,515.44257,0.02645,2.64482,28.22951
17.40000,1.45001,517.44776,0.02661,2.66123,28.33933
17.50000,1.45839,518.44516,0.02678,2.67757,28.39395
17.60000,1.46664,520.15083,0.02694,2.69397,28.48737
17.70000,1.47501,521.96719,0.02710,2.71041,28.58684
17.80000,1.48320,522.78861,0.02727,2.72699,28.63183
17.90000,1.49157,524.59873,0.02743,2.74316,28.73097
18.00000,1.50000,525.92349,0.02759,2.75928,28.80352
18.10000,1.50819,526.72876,0.02770,2.77015,28.84762
18.20000,1.51656,527.53435,0.02787,2.78677,28.89174
18.30000,1.52505,529.95370,0.02804,2.80397,29.02425
18.40000,1.53336,530.80693,0.02821,2.82052,29.07097
18.50000,1.54167,532.45695,0.02837,2.83741,29.16134
18.60000,1.55010,533.30967,0.02854,2.85354,29.20804
18.70000,1.55829,535.20170,0.02870,2.87023,29.31166
18.80000,1.56666,536.78383,0.02887,2.88671,29.39832
18.90000,1.57509,537.54649,0.02904,2.90369,29.44008
19.00000,1.58335,539.45230,0.02920,2.92031,29.54446
19.10000,1.59166,540.41198,0.02937,2.93739,29.59702
19.20000,1.60003,542.18066,0.02954,2.95424,29.69389
19.30000,1.60828,543.00311,0.02971,2.97055,29.73893
19.40000,1.61665,544.62808,0.02987,2.98694,29.82792
19.50000,1.62502,546.29282,0.03004,3.00399,29.91910
19.60000,1.63333,546.94312,0.03021,3.02092,29.95471
19.70000,1.64176,548.69903,0.03038,3.03811,30.05088
19.80000,1.65001,550.08158,0.03055,3.07112,30.12660
19.90000,1.65832,551.21793,0.03071,3.10436,30.18884
20.00000,1.66663,552.55368,0.03088,3.13760,30.26199
20.02000,1.66831,552.55499,0.03092,3.14430,30.26206
20.12000,1.67656,554.46057,0.03108,3.17730,30.36643
20.22000,1.68493,555.53522,0.03126,3.21079,30.42528
20.32000,1.69336,556.53416,0.03142,3.24451,30.47999
20.42000,1.70161,557.40611,0.03160,3.27751,30.52775
20.52000,1.70998,558.90367,0.03176,3.31099,30.60976
20.62000,1.71841,559.72300,0.03194,3.34471,30.65464
20.72000,1.72660,561.14537,0.03211,3.37748,30.73254
20.82000,1.73497,562.44317,0.03227,3.41096,30.80361
20.92000,1.74334,563.82399,0.03244,3.44444,30.87924
21.02000,1.75165,565.28458,0.03261,3.47769,30.95923
21.12000,1.75996,566.18960,0.03278,3.51093,31.00879
21.22000,1.76833,567.47054,0.03295,3.54441,31.07895
21.32000,1.77664,568.62375,0.03313,3.57765,31.14211
21.42000,1.78502,569.85617,0.03330,3.61114,31.20960
21.52000,1.79333,570.34791,0.03347,3.64438,31.23654
21.62000,1.80164,571.89125,0.03340,3.67762,31.32106
21.72000,1.81007,574.14342,0.03200,3.71134,31.44441
21.82000,1.81844,573.78281,0.03282,3.74483,31.42466
21.92000,1.82669,576.10050,0.03407,3.77783,31.55159
22.02000,1.83512,575.37570,0.03485,3.81155,31.51190
22.12000,1.84331,575.47991,0.09174,3.84432,31.51760
22.22000,1.85162,577.09445,0.02399,3.87756,31.60603
22.32000,1.86005,578.08240,0.00560,3.91128,31.66014
22.42000,1.86830,580.08502,0.00596,3.94428,31.76981
22.52000,1.87667,581.84550,0.00757,3.97777,31.86623
22.62000,1.88504,582.62204,0.00770,4.01125,31.90876
22.72000,1.89329,583.36724,0.00535,4.04425,31.94957
22.82000,1.90160,584.54634,0.00481,4.07749,32.01415
22.92000,1.91004,586.11920,0.00415,4.11122,32.10029
23.02000,1.91829,586.62072,0.00467,4.14422,32.12776
23.12000,1.92660,587.91223,0.00482,4.17746,32.19849
23.22000,1.93503,588.86516,0.00494,4.21118,32.25068
23.32000,1.94328,590.03723,0.00655,4.24419,32.31487
23.42000,1.95165,591.46280,0.01067,4.27767,32.39294
23.52000,1.96002,591.73447,-0.01853,4.31115,32.40783
23.62000,1.96833,592.51101,-0.02450,4.34439,32.45036
23.72000,1.97670,594.10390,-0.02645,4.37788,32.53759
23.82000,1.98501,594.99778,-0.02906,4.41112,32.58655
23.92000,1.99338,595.71862,-0.07758,4.44460,32.62603
24.02000,2.00175,596.83444,-0.13543,4.47808,32.68714
24.12000,2.01000,597.37507,-0.13520,4.51109,32.71675
24.22000,2.01831,599.17183,-0.13520,4.54433,32.81515
24.32000,2.02668,599.71963,-0.13521,4.57781,32.84515
24.42000,2.03499,600.74870,-0.13520,4.61106,32.90151
24.52000,2.04331,601.45799,-0.13521,4.64430,32.94036
24.62000,2.05168,602.39960,-0.13521,4.67778,32.99193
24.72000,2.05999,602.54941,-0.13521,4.71102,33.00013
24.82000,2.06830,602.79137,-0.13521,4.74427,33.01338
24.92000,2.07667,604.40567,-0.13521,4.77775,33.10180
25.02000,2.08498,604.75306,-0.13521,4.81099,33.12082
25.12000,2.09329,605.40587,-0.13521,4.84423,33.15657
25.22000,2.10166,606.66408,-0.13521,4.87772,33.22548
25.32000,2.10997,607.76765,-0.13522,4.91096,33.28592
25.42000,2.11828,608.92892,-0.13522,4.94420,33.34952
25.52000,2.12665,609.73004,-0.13522,4.97768,33.39340
25.62000,2.13490,610.39212,-0.13522,5.01069,33.42966
25.72000,2.14327,611.94338,-0.13522,5.04417,33.51462
25.82000,2.15164,612.51582,-0.13522,5.07765,33.54597
25.92000,2.16001,613.13193,-0.13522,5.11113,33.57971
26.02000,2.16839,614.05390,-0.13522,5.14462,33.63020
26.12000,2.17670,615.18410,-0.13522,5.17786,33.69210
26.22000,2.18501,615.69293,-0.13522,5.21110,33.71997
26.32000,2.19338,616.23477,-0.13522,5.24459,33.74965
26.42000,2.20169,617.74808,-0.13522,5.27783,33.83253
26.52000,2.21000,617.64163,-0.13522,5.31107,33.82669
26.62000,2.21837,618.64746,-0.13522,5.34455,33.88178
26.72000,2.22668,620.05068,-0.13522,5.37780,33.95863
26.82000,2.23505,621.07989,-0.13522,5.41128,34.01500
26.92000,2.24342,622.23179,-0.13522,5.44476,34.07809
27.02000,2.25167,622.64614,-0.13522,5.47776,34.10078
27.12000,2.25998,623.45052,-0.13523,5.51101,34.14483
27.22000,2.26841,624.22152,-0.13522,5.54473,34.18706
27.32000,2.27672,625.05836,-0.13522,5.57797,34.23289
27.42000,2.28503,625.85124,-0.13523,5.61122,34.27631
27.52000,2.29335,626.73329,-0.13522,5.64446,34.32462
27.62000,2.30166,627.70988,-0.13523,5.67770,34.37811
27.72000,2.30997,628.20190,-0.13522,5.71094,34.40506
27.82000,2.31834,629.12642,-0.13523,5.74443,34.45569
27.92000,2.32665,630.67372,-0.13523,5.77767,34.54043
28.02000,2.33502,631.24141,-0.13523,5.81115,34.57152
28.12000,2.34333,631.22320,-0.13523,5.84439,34.57052
28.22000,2.35164,632.49096,-0.13523,5.87764,34.63996
28.32000,2.35995,633.58601,-0.13523,5.91088,34.69993
28.42000,2.36826,633.66066,-0.13523,5.94412,34.70402
28.52000,2.37663,634.83133,-0.13523,5.97760,34.76813
28.62000,2.38494,635.81616,-0.13523,6.01085,34.82207
28.72000,2.39331,636.80625,-0.13523,6.04433,34.87629
28.82000,2.40162,636.63353,-0.13523,6.07757,34.86683
28.92000,2.41005,637.86111,-0.13523,6.11129,34.93407
29.02000,2.41831,638.90889,-0.13523,6.14430,34.99145
29.12000,2.42668,639.47593,-0.13523,6.17778,35.02251
29.22000,2.43511,639.44017,-0.13523,6.21150,35.02055
29.32000,2.44336,640.90593,-0.13523,6.24451,35.10082
29.42000,2.45167,641.25112,-0.13523,6.27775,35.11973
29.52000,2.46004,641.62379,-0.13523,6.31123,35.14014
29.62000,2.46829,642.62548,-0.13523,6.34423,35.19500
29.72000,2.47666,644.18451,-0.13523,6.37772,35.28038
29.82000,2.48503,644.47215,-0.13523,6.41120,35.29613
29.92000,2.49334,645.22452,-0.13523,6.44444,35.33734
30.02000,2.50165,646.48334,-0.13523,6.47768,35.40628
30.12000,2.51002,646.93838,-0.13523,6.51117,35.43121
30.22000,2.51833,647.17643,-0.13523,6.54441,35.44424
30.32000,2.52670,648.28033,-0.13523,6.57789,35.50470
30.42000,2.53507,649.21854,-0.13523,6.61137,35.55608
30.52000,2.54333,649.41701,-0.13523,6.64438,35.56695
30.62000,2.55170,650.04337,-0.13523,6.67786,35.60126
30.72000,2.55989,650.60714,-0.13523,6.71062,35.63213
30.82000,2.56826,651.87453,-0.13523,6.74410,35.70155
30.92000,2.57669,652.62532,-0.13523,6.77783,35.74266
31.02000,2.58494,652.80590,-0.13523,6.81083,35.75256
31.12000,2.59331,653.54435,-0.13524,6.84431,35.79300
31.22000,2.60168,654.34403,-0.13523,6.87779,35.83680
31.32000,2.60993,654.64610,-0.13524,6.91080,35.85334
31.42000,2.61830,655.60089,-0.13524,6.94428,35.90563
31.52000,2.62667,656.38134,-0.13523,6.97776,35.94837
31.62000,2.63498,656.91248,-0.13523,7.01101,35.97746
31.72000,2.64329,657.69479,-0.13523,7.04425,36.02031
31.82000,2.65166,658.07328,-0.13523,7.07773,36.04103
31.92000,2.65997,658.59151,-0.13523,7.11097,36.06942
32.02000,2.66829,659.72651,-0.13523,7.14422,36.13158
32.12000,2.67666,659.97769,-0.13524,7.17770,36.14534
32.22000,2.68503,661.08704,-0.13523,7.21118,36.20609
32.32000,2.69334,661.54008,-0.13524,7.24442,36.23090
32.42000,2.70171,662.71368,-0.13523,7.27791,36.29518
32.52000,2.71002,663.12905,-0.13524,7.31115,36.31793
32.62000,2.71839,663.23685,-0.13523,7.34463,36.32383
32.72000,2.72670,663.67136,-0.13524,7.37787,36.34763
32.82000,2.73501,664.94769,-0.13524,7.41112,36.41753
32.92000,2.74332,664.90411,-0.13523,7.44436,36.41514
33.02000,2.75163,666.00940,-0.13524,7.47760,36.47568
33.12000,2.76000,666.16144,-0.13524,7.51109,36.48400
33.22000,2.76837,667.48476,-0.13524,7.54457,36.55648
33.32000,2.77668,667.41449,-0.13524,7.57781,36.55263
33.42000,2.78505,667.98590,-0.13523,7.61129,36.58393
33.52000,2.79342,669.08672,-0.13523,7.64477,36.64421
33.62000,2.80162,669.31047,-0.13524,7.67754,36.65647
33.72000,2.80999,669.88510,-0.13524,7.71102,36.68794
33.82000,2.81830,670.58341,-0.13524,7.74427,36.72618
33.92000,2.82661,671.41512,-0.13524,7.77751,36.77174
34.02000,2.83492,671.41093,-0.13524,7.81075,36.77151
34.12000,2.84329,672.51157,-0.13524,7.84423,36.83179
34.22000,2.85160,672.98538,-0.13524,7.87748,36.85773
34.32000,2.85997,673.22636,-0.13524,7.91096,36.87093
34.42000,2.86840,674.22739,-0.13524,7.94468,36.92576
34.52000,2.87671,674.52677,-0.13524,7.97792,36.94215
34.62000,2.88508,675.27406,-0.13524,8.01140,36.98308
34.72000,2.89339,675.82028,-0.13524,8.04465,37.01300
34.82000,2.90170,676.69842,-0.13524,8.07789,37.06109
34.92000,2.91001,675.41604,-0.13524,8.11113,36.99086
35.02000,2.91833,676.22308,-0.13524,8.14438,37.03506
35.12000,2.92664,676.80767,-0.13524,8.17762,37.06707
35.22000,2.93507,677.40208,-0.13524,8.21134,37.09963
35.32000,2.94326,677.95310,-0.13524,8.24410,37.12980
35.42000,2.95157,679.16997,-0.13524,8.27735,37.19645
35.52000,2.96006,679.15437,-0.13524,8.31131,37.19559
35.62000,2.96837,680.17794,-0.13524,8.34455,37.25165
35.72000,2.97668,680.20029,-0.13524,8.37779,37.25288
35.82000,2.98511,680.63098,-0.13524,8.41152,37.27647
35.92000,2.99330,681.74298,-0.13524,8.44428,37.33737
36.02000,3.00155,682.47737,-0.13524,8.47728,37.37759
36.12000,3.01004,683.15496,-0.13524,8.51124,37.41470
36.22000,3.01823,683.33354,-0.13524,8.54401,37.42448
36.32000,3.02660,684.29722,-0.13524,8.57749,37.47726
36.42000,3.03503,684.35026,-0.13524,8.61121,37.48016
36.52000,3.04323,684.84680,-0.13524,8.64398,37.50735
36.62000,3.05166,685.61351,-0.13524,8.67770,37.54935
36.72000,3.06009,685.86445,-0.13524,8.71142,37.56309
36.82000,3.06834,687.06665,-0.13524,8.74442,37.62893
36.92000,3.07677,687.22605,-0.13524,8.77815,37.63766
37.02000,3.08502,687.47210,-0.13524,8.81115,37.65114
37.12000,3.09327,688.51239,-0.13523,8.84415,37.70811
37.22000,3.10170,688.71798,-0.13524,8.87787,37.71937
37.32000,3.11001,689.08669,-0.13524,8.91112,37.73956
37.42000,3.11832,689.68572,-0.13524,8.94436,37.77237
37.52000,3.12675,690.03943,-0.13524,8.97808,37.79174
37.62000,3.13500,690.25601,-0.13524,9.01108,37.80360
37.72000,3.14331,691.24303,-0.13524,9.04433,37.85766
37.82000,3.15180,691.88294,-0.13524,9.07829,37.89271
37.92000,3.15999,692.42720,-0.13524,9.11105,37.92252
38.02000,3.16825,692.68402,-0.13524,9.14406,37.93658
38.12000,3.17674,693.64365,-0.13524,9.17802,37.98914
38.22000,3.18493,693.43820,-0.13524,9.21078,37.97789
38.32000,3.19330,694.15295,-0.13524,9.24426,38.01703
38.42000,3.20173,694.71104,-0.13524,9.27798,38.04760
38.52000,3.20992,695.46835,-0.13524,9.31075,38.08907
38.62000,3.21829,696.21932,-0.13523,9.34423,38.13020
38.72000,3.22666,696.55087,-0.13523,9.37771,38.14836
38.82000,3.23491,696.29797,-0.13523,9.41072,38.13451
38.92000,3.24328,697.78296,-0.13523,9.44420,38.21584
39.02000,3.25165,697.22021,-0.13523,9.47768,38.18502
39.12000,3.25996,698.42646,-0.13523,9.51092,38.25108
39.22000,3.26839,698.20508,-0.13523,9.54465,38.23896
39.32000,3.27664,699.15908,-0.13524,9.57765,38.29120
39.42000,3.28495,699.12220,-0.13524,9.61089,38.28918
39.52000,3.29338,699.53632,-0.13524,9.64461,38.31186
39.62000,3.30164,700.40850,-0.13524,9.67762,38.35963
39.72000,3.30995,701.14303,-0.13524,9.71086,38.39986
39.82000,3.31838,700.83956,-0.13523,9.74458,38.38324
39.92000,3.32663,701.64492,-0.13524,9.77759,38.42735
40.02000,3.33500,702.05685,-0.13524,9.81107,38.44991
40.12000,3.34343,702.55939,-0.13524,9.84479,38.47743
40.22000,3.35174,702.91213,-0.13524,9.87803,38.49675
40.32000,3.36005,703.23357,-0.13523,9.91128,38.51435
40.42000,3.36842,703.27716,-0.13524,9.94476,38.51674
40.52000,3.37661,704.15130,-0.13523,9.97752,38.56461
40.62000,3.38498,704.01393,-0.13524,10.01100,38.55709
40.72000,3.39335,705.19494,-0.13524,10.04449,38.62177
40.82000,3.40166,705.71946,-0.13524,10.07773,38.65050
40.92000,3.40997,705.70600,-0.13524,10.11097,38.64976
41.02000,3.41834,706.19923,-0.13524,10.14445,38.67677
41.12000,3.42666,706.86061,-0.13524,10.17770,38.71300
41.22000,3.43497,707.26145,-0.13524,10.21094,38.73495
41.32000,3.44334,707.39803,-0.13524,10.24442,38.74243
41.42000,3.45159,708.06211,-0.13524,10.27743,38.77880
41.52000,3.45996,708.30877,-0.13524,10.31091,38.79231
41.62000,3.46833,708.46612,-0.13524,10.34439,38.80093
41.72000,3.47658,708.94575,-0.13524,10.37739,38.82719
41.82000,3.48507,709.32284,-0.13524,10.41135,38.84785
41.92000,3.49332,709.67679,-0.13524,10.44436,38.86723
42.02000,3.50163,710.88546,-0.13524,10.47760,38.93343
42.12000,3.51012,711.09361,-0.13524,10.51156,38.94483
42.22000,3.51831,710.76653,-0.13524,10.54433,38.92691
42.32000,3.52668,711.44225,-0.13524,10.57781,38.96392
42.42000,3.53511,711.61566,-0.13524,10.61153,38.97342
42.52000,3.54330,711.81771,-0.13524,10.64429,38.98449
42.62000,3.55162,712.22745,-0.13524,10.67754,39.00692
42.72000,3.56005,713.02145,-0.13524,10.71126,39.05041
42.82000,3.56830,712.97064,-0.13524,10.74426,39.04763
42.92000,3.57661,713.97154,-0.13524,10.77750,39.10244
43.02000,3.58510,714.27892,-0.13524,10.81147,39.11928
43.12000,3.59329,714.07589,-0.13524,10.84423,39.10816
43.22000,3.60166,713.97508,-0.13524,10.87771,39.10264
43.32000,3.61009,715.10589,-0.13524,10.91143,39.16457
43.42000,3.61822,715.65425,-0.13524,10.94396,39.19460
43.52000,3.62665,716.19432,-0.13524,10.97768,39.22418
43.62000,3.63502,715.89611,-0.13524,11.01116,39.20785
43.72000,3.64321,717.30865,-0.13524,11.04393,39.28521
43.82000,3.65176,716.65389,-0.13524,11.07813,39.24935
43.92000,3.66001,717.37482,-0.13524,11.11113,39.28883
44.02000,3.66826,717.84686,-0.13524,11.14413,39.31469
44.12000,3.67675,717.77520,-0.13524,11.17809,39.31076
44.22000,3.68501,717.85487,-0.13524,11.21110,39.31512
44.32000,3.69332,718.65674,-0.13524,11.24434,39.35904
44.42000,3.70181,719.05237,-0.13524,11.27830,39.38071
44.52000,3.71000,719.26396,-0.13524,11.31107,39.39230
44.62000,3.71825,719.02927,-0.13524,11.34407,39.37944
44.72000,3.72680,719.72306,-0.13524,11.37827,39.41744
44.82000,3.73499,720.16679,-0.13524,11.41103,39.44174
44.92000,3.74330,720.22839,-0.13524,11.44428,39.44512
45.02000,3.75179,720.67361,-0.13524,11.47824,39.46950
45.12000,3.75992,721.27515,-0.13524,11.51076,39.50245
45.22000,3.76829,722.06813,-0.13524,11.54425,39.54588
45.32000,3.77678,722.31214,-0.13524,11.57821,39.55924
45.42000,3.78491,722.25905,-0.13524,11.61073,39.55633
45.52000,3.79334,722.81542,-0.13524,11.64445,39.58680
45.62000,3.80171,722.70464,-0.13524,11.67793,39.58073
45.72000,3.80991,722.92374,-0.13524,11.71070,39.59274
45.82000,3.81840,723.44933,-0.13524,11.74466,39.62152
45.92000,3.82671,723.59685,-0.13524,11.77790,39.62960
46.02000,3.83490,724.02926,-0.13524,11.81067,39.65328
46.12000,3.84339,724.54056,-0.13524,11.84463,39.68128
46.22000,3.85170,724.07392,-0.13524,11.87787,39.65573
46.32000,3.86001,724.75541,-0.13524,11.91111,39.69305
46.42000,3.86838,725.35276,-0.13524,11.94460,39.72577
46.52000,3.87663,725.10424,-0.13524,11.97760,39.71215
46.62000,3.88500,726.04180,-0.13524,12.01108,39.76350
46.72000,3.89331,726.31869,-0.13524,12.04433,39.77867
46.82000,3.90156,726.02984,-0.13524,12.07733,39.76285
46.92000,3.90993,727.13471,-0.13524,12.11081,39.82336
47.02000,3.91836,726.66369,-0.13524,12.14453,39.79756
47.12000,3.92661,727.72908,-0.13524,12.17754,39.85591
47.22000,3.93499,727.53932,-0.13524,12.21102,39.84552
47.32000,3.94336,727.46822,-0.13524,12.24450,39.84163
47.42000,3.95161,728.06943,-0.13524,12.27750,39.87455
47.52000,3.95998,728.28177,-0.13524,12.31099,39.88618
47.62000,3.96835,728.70557,-0.13524,12.34447,39.90939
47.72000,3.97666,728.71433,-0.13524,12.37771,39.90987
47.82000,3.98497,728.82338,-0.13524,12.41095,39.91584
47.92000,3.99328,729.95420,-0.13524,12.44420,39.97778
48.02000,4.00159,729.65780,-0.13524,12.47744,39.96154
48.12000,4.01002,728.99489,-0.13524,12.51116,39.92524
48.22000,4.01833,730.35262,-0.13524,12.54440,39.99960
48.32000,4.02664,730.37418,-0.13524,12.57765,40.00078
48.42000,4.03501,731.25227,-0.13524,12.61113,40.04887
48.52000,4.04326,731.13581,-0.13524,12.64413,40.04249
48.62000,4.05163,731.20287,-0.13524,12.67761,40.04616
48.72000,4.06006,731.73856,-0.13524,12.71134,40.07550
48.82000,4.06832,732.05568,-0.13524,12.74434,40.09287
48.92000,4.07663,732.04609,-0.13524,12.77758,40.09234
49.02000,4.08506,732.18229,-0.13524,12.81130,40.09980
49.12000,4.09325,732.91324,-0.13524,12.84407,40.13984
49.22000,4.10162,732.99133,-0.13524,12.87755,40.14411
49.32000,4.11005,733.48694,-0.13524,12.91127,40.17125
49.42000,4.11830,733.31194,-0.13524,12.94428,40.16167
49.52000,4.12667,733.32880,-0.13524,12.97776,40.16259
49.62000,4.13504,734.16186,-0.13524,13.01124,40.20822
49.72000,4.14329,734.57188,-0.13524,13.04424,40.23067
49.82000,4.15166,734.42897,-0.13524,13.07772,40.22285
49.92000,4.16003,735.02609,-0.13524,13.11121,40.25555
50.02000,4.16828,734.41113,-0.13524,13.14421,40.22187
50.12000,4.17665,735.14138,-0.13524,13.17769,40.26186
50.22000,4.18503,735.35913,-0.13524,13.21118,40.27379
50.32000,4.19322,735.58325,-0.13524,13.24394,40.28606
50.42000,4.20165,735.88137,-0.13524,13.27766,40.30239
50.52000,4.21002,736.70102,-0.13524,13.31114,40.34728
50.62000,4.21833,735.76341,-0.13524,13.34439,40.29593
50.72000,4.22682,736.52128,-0.13524,13.37835,40.33744
50.82000,4.23501,736.55220,-0.13524,13.41111,40.33913
50.92000,4.24326,736.90680,-0.13524,13.44412,40.35855
51.02000,4.25169,737.46066,-0.13524,13.47784,40.38889
51.12000,4.25994,737.21204,-0.13524,13.51084,40.37527
51.22000,4.26831,737.49768,-0.13524,13.54432,40.39091
51.32000,4.27674,738.07007,-0.13524,13.57805,40.42226
51.42000,4.28499,738.42816,-0.13524,13.61105,40.44187
51.52000,4.29330,738.30960,-0.13524,13.64429,40.43538
51.62000,4.30173,738.61810,-0.13524,13.67801,40.45227
51.72000,4.30999,738.51994,-0.13524,13.71102,40.44690
51.82000,4.31836,738.53927,-0.13524,13.74450,40.44796
51.92000,4.32673,738.99282,-0.13525,13.77798,40.47280
52.02000,4.33492,739.84452,-0.13524,13.81074,40.51944
52.12000,4.34329,740.10012,-0.13524,13.84423,40.53344
52.22000,4.35166,739.84172,-0.13524,13.87771,40.51929
52.32000,4.35997,739.85187,-0.13524,13.91095,40.51985
52.42000,4.36834,740.43907,-0.13524,13.94444,40.55201
52.52000,4.37665,740.04796,-0.13524,13.97768,40.53059
52.62000,4.38496,740.82650,-0.13524,14.01092,40.57322
52.72000,4.39339,740.83442,-0.13524,14.04464,40.57366
52.82000,4.40164,740.98869,-0.13524,14.07765,40.58211
52.92000,4.41001,740.93384,-0.13524,14.11113,40.57910
53.02000,4.41844,741.58558,-0.13524,14.14485,40.61480
53.12000,4.42663,742.09399,-0.13524,14.17761,40.64264
53.22000,4.43501,742.29380,-0.13524,14.21110,40.65358
53.32000,4.44332,741.63401,-0.13524,14.24434,40.61745
53.42000,4.45163,742.37878,-0.13524,14.27758,40.65824
53.52000,4.46000,742.83294,-0.13524,14.31106,40.68311
53.62000,4.46837,741.77701,-0.13524,14.34455,40.62528
53.72000,4.47662,742.80528,-0.13524,14.37755,40.68160
53.82000,4.48499,742.43182,-0.13524,14.41103,40.66114
53.92000,4.49336,743.05441,-0.13524,14.44451,40.69524
54.02000,4.50167,743.16915,-0.13524,14.47776,40.70153
54.12000,4.50998,743.11914,-0.13524,14.51100,40.69879
54.22000,4.51829,743.88306,-0.13524,14.54424,40.74062
54.32000,4.52660,743.91174,-0.13524,14.57749,40.74220
54.42000,4.53497,744.13316,-0.13524,14.61097,40.75432
54.52000,4.54328,744.55133,-0.13524,14.64421,40.77723
54.62000,4.55159,744.25363,-0.13524,14.67745,40.76092
54.72000,4.55996,744.77200,-0.13524,14.71093,40.78931
54.82000,4.56828,744.51063,-0.13524,14.74418,40.77499
54.92000,4.57665,745.03999,-0.13524,14.77766,40.80399
55.02000,4.58508,745.30239,-0.13524,14.81138,40.81836
55.12000,4.59339,745.01801,-0.13524,14.84462,40.80278
55.22000,4.60170,746.15618,-0.13524,14.87787,40.86512
55.32000,4.61001,745.38421,-0.13524,14.91111,40.82284
55.42000,4.61826,745.82575,-0.13524,14.94411,40.84702
55.52000,4.62663,745.98426,-0.13524,14.97760,40.85570
55.62000,4.63500,745.78854,-0.13524,15.01108,40.84498
55.72000,4.64331,746.27264,-0.13525,15.04432,40.87149
55.82000,4.65168,745.76270,-0.13524,15.07780,40.84357
55.92000,4.66005,747.32155,-0.13524,15.11129,40.92894
56.02000,4.66842,747.33840,-0.13524,15.14477,40.92987
56.12000,4.67673,747.00629,-0.13524,15.17801,40.91167
56.22000,4.68510,746.34422,-0.13525,15.21149,40.87542
56.32000,4.69336,747.16187,-0.13524,15.24450,40.92020
56.42000,4.70167,747.88686,-0.13524,15.27774,40.95990
56.52000,4.70998,747.59731,-0.13524,15.31098,40.94405
56.62000,4.71829,747.28075,-0.13524,15.34423,40.92671
56.72000,4.72666,745.85453,-0.13524,15.37771,40.84860
56.82000,4.73491,746.03860,-0.13524,15.41071,40.85868
56.92000,4.74328,746.37183,-0.13524,15.44420,40.87693
57.02000,4.75165,746.57337,-0.13524,15.47768,40.88797
57.12000,4.76002,746.61896,-0.13525,15.51116,40.89046
57.22000,4.76839,747.29868,-0.13524,15.54464,40.92769
57.32000,4.77670,748.00905,-0.13524,15.57788,40.96659
57.42000,4.78495,747.56970,-0.13524,15.61089,40.94253
57.52000,4.79326,747.85519,-0.13524,15.64413,40.95817
57.62000,4.80169,748.17548,-0.13524,15.67785,40.97571
57.72000,4.80994,748.73599,-0.13524,15.71086,41.00641
57.82000,4.81832,748.40733,-0.13524,15.74434,40.98841
57.92000,4.82675,748.83793,-0.13524,15.77806,41.01199
58.02000,4.83500,748.88021,-0.13524,15.81106,41.01431
58.12000,4.84337,749.25525,-0.13524,15.84454,41.03485
58.22000,4.85180,749.48664,-0.13525,15.87827,41.04752
58.32000,4.85999,749.26908,-0.13524,15.91103,41.03560
58.42000,4.86836,750.00268,-0.13524,15.94451,41.07578
58.52000,4.87673,750.14979,-0.13524,15.97800,41.08384
58.62000,4.88498,749.56068,-0.13524,16.01100,41.05157
58.72000,4.89335,750.06057,-0.13524,16.04448,41.07895
58.82000,4.90160,750.14350,-0.13524,16.07749,41.08349
58.92000,4.90991,750.17307,-0.13524,16.11073,41.08511
59.02000,4.91834,751.17368,-0.13524,16.14445,41.13992
59.12000,4.92665,750.66714,-0.13524,16.17769,41.11217
59.22000,4.93502,750.70206,-0.13524,16.21117,41.11408
59.32000,4.94340,751.21699,-0.13524,16.24466,41.14228
59.42000,4.95165,751.60293,-0.13524,16.27766,41.16342
59.52000,4.95996,751.22691,-0.13524,16.31090,41.14283
59.62000,4.96833,751.69527,-0.13525,16.34438,41.16848
59.72000,4.97658,751.31305,-0.13524,16.37739,41.14754
59.82000,4.98489,752.57709,-0.13524,16.41063,41.21677
59.92000,4.99332,752.61095,-0.13524,16.44435,41.21863
60.02000,5.00163,751.98151,-0.13524,16.47760,41.18415
60.12000,5.00994,751.92284,-0.13524,16.51084,41.18094
60.22000,5.01837,752.11274,-0.13524,16.54456,41.19134
60.32000,5.02668,752.36391,-0.13524,16.57780,41.20510
60.42000,5.03505,752.77118,-0.13524,16.61129,41.22741
60.52000,5.04336,752.45225,-0.13524,16.64453,41.20994
60.62000,5.05167,752.39390,-0.13524,16.67777,41.20674
60.72000,5.05998,752.18966,-0.13524,16.71101,41.19556
60.82000,5.06830,753.12522,-0.13524,16.74426,41.24680
60.92000,5.07667,752.76280,-0.13525,16.77774,41.22694
61.02000,5.08504,753.12988,-0.13524,16.81122,41.24705
61.12000,5.09329,752.78194,-0.13525,16.84422,41.22799
61.22000,5.10166,753.05998,-0.13524,16.87771,41.24322
61.32000,5.11003,753.12448,-0.13524,16.91119,41.24675
61.42000,5.11834,753.44406,-0.13524,16.94443,41.26426
61.52000,5.12665,753.07195,-0.13524,16.97767,41.24388
61.62000,5.13496,753.15214,-0.13524,17.01092,41.24827
61.72000,5.14321,753.46157,-0.13524,17.04392,41.26522
61.82000,5.15158,753.23703,-0.13525,17.07740,41.25292
61.92000,5.16001,753.69976,-0.13524,17.11112,41.27826
62.02000,5.16832,754.26749,-0.13524,17.14437,41.30935
62.12000,5.17663,754.04919,-0.13524,17.17761,41.29740
62.22000,5.18500,753.75540,-0.13524,17.21109,41.28131
62.32000,5.19326,753.66707,-0.13524,17.24410,41.27647
62.42000,5.20169,753.95866,-0.13524,17.27782,41.29244
62.52000,5.21000,753.85962,-0.13525,17.31106,41.28701
62.62000,5.21831,753.68402,-0.13524,17.34430,41.27740
62.72000,5.22668,754.44337,-0.13525,17.37779,41.31898
62.82000,5.23499,753.97994,-0.13524,17.41103,41.29361
62.92000,5.24330,754.17836,-0.13524,17.44427,41.30447
63.02000,5.25161,754.47229,-0.13524,17.47752,41.32057
63.12000,5.25998,753.74213,-0.13525,17.51100,41.28058
63.22000,5.26835,754.59825,-0.13524,17.54448,41.32747
63.32000,5.27666,753.90679,-0.13524,17.57772,41.28960
63.42000,5.28503,754.39168,-0.13525,17.61121,41.31615
63.52000,5.29334,754.10502,-0.13525,17.64445,41.30046
63.62000,5.30171,753.74413,-0.13524,17.67793,41.28069
63.72000,5.30996,753.45305,-0.13524,17.71093,41.26475
63.82000,5.31828,753.68811,-0.13524,17.74418,41.27762
63.92000,5.32671,753.38073,-0.13524,17.77790,41.26079
64.02000,5.33490,753.16667,-0.13525,17.81066,41.24907
64.12000,5.34327,752.12233,-0.13524,17.84414,41.19187
64.22000,5.35170,751.74696,-0.13524,17.87786,41.17131
64.32000,5.36001,480.08994,-0.13525,17.91111,26.29333
64.35400,5.36294,3.09344,-0.13524,17.92283,0.16942