File: Manufatura Aditiva/Classificação Orientação/Ensaios/Ensaios SLS/Tracao_OLABI_08_06_2018_SLS_ZY6.is_metal_RawData/Specimen_RawData_5.csv
Time,Extension,Load,Strain 1,Tensile strain,Tensile stress
(sec),(mm),(N),(mm/mm),(%),(MPa)
0.00000,0.00006,22.64189,0.00128,0.12780,1.21829
0.10000,0.00419,24.78316,0.00131,0.13119,1.33350
0.20000,0.01381,28.49624,0.00147,0.14663,1.53329
0.30000,0.02362,33.90468,0.00163,0.16308,1.82430
0.40000,0.03270,38.73555,0.00179,0.17885,2.08424
0.50000,0.04143,43.81149,0.00194,0.19374,2.35736
0.60000,0.04986,47.89538,0.00208,0.20841,2.57710
0.70000,0.05823,51.50901,0.00222,0.22187,2.77154
0.80000,0.06667,56.02179,0.00236,0.23611,3.01436
0.90000,0.07498,59.95210,0.00250,0.24980,3.22583
1.00000,0.08329,64.57593,0.00264,0.26363,3.47463
1.10000,0.09178,68.49191,0.00278,0.27834,3.68533
1.20000,0.10003,73.15347,0.00292,0.29222,3.93616
1.30000,0.10834,76.45120,0.00307,0.30678,4.11360
1.40000,0.11683,81.09602,0.00321,0.32105,4.36352
1.50000,0.12496,84.57900,0.00335,0.33461,4.55093
1.60000,0.13333,88.98475,0.00349,0.34865,4.78799
1.70000,0.14170,93.26875,0.00363,0.36255,5.01850
1.80000,0.14989,96.28678,0.00377,0.37672,5.18089
1.90000,0.15832,100.68732,0.00391,0.39101,5.41767
2.00000,0.16663,104.37166,0.00405,0.40469,5.61591
2.10000,0.17494,108.91282,0.00419,0.41920,5.86025
2.20000,0.18331,111.88579,0.00433,0.43317,6.02022
2.30000,0.19163,115.72966,0.00447,0.44692,6.22705
2.40000,0.19994,119.71256,0.00461,0.46084,6.44135
2.50000,0.20837,123.86736,0.00476,0.47565,6.66491
2.60000,0.21668,127.26083,0.00490,0.48972,6.84750
2.70000,0.22493,130.95462,0.00503,0.50323,7.04625
2.80000,0.23336,135.04040,0.00518,0.51778,7.26610
2.90000,0.24167,138.84573,0.00531,0.53149,7.47085
3.00000,0.24992,142.52431,0.00545,0.54532,7.66878
3.10000,0.25841,146.01214,0.00560,0.56014,7.85645
3.20000,0.26666,150.32006,0.00574,0.57395,8.08825
3.30000,0.27497,153.55600,0.00588,0.58819,8.26236
3.40000,0.28346,156.96655,0.00603,0.60272,8.44587
3.50000,0.29171,160.85180,0.00617,0.61661,8.65493
3.60000,0.30002,164.19058,0.00631,0.63075,8.83457
3.70000,0.30839,168.30761,0.00645,0.64471,9.05610
3.80000,0.31665,172.19379,0.00659,0.65871,9.26520
3.90000,0.32502,174.58994,0.00670,0.67006,9.39413
4.00000,0.33333,177.55672,0.00682,0.68173,9.55376
4.10000,0.34164,180.79105,0.00696,0.69645,9.72779
4.20000,0.34995,185.64112,0.00710,0.71041,9.98876
4.30000,0.35826,188.29951,0.00725,0.72457,10.13180
4.40000,0.36657,192.79330,0.00738,0.73830,10.37360
4.50000,0.37500,195.70480,0.00752,0.75245,10.53026
4.60000,0.38337,199.36371,0.00767,0.76675,10.72713
4.70000,0.39162,203.36257,0.00781,0.78081,10.94230
4.80000,0.39999,206.04804,0.00795,0.79507,11.08679
4.90000,0.40824,209.79082,0.00810,0.80952,11.28818
5.00000,0.41667,213.61907,0.00824,0.82363,11.49417
5.10000,0.42504,216.63054,0.00839,0.83856,11.65620
5.20000,0.43335,220.37078,0.00852,0.85215,11.85745
5.30000,0.44166,223.87342,0.00866,0.86606,12.04592
5.40000,0.45010,227.29437,0.00880,0.88050,12.22999
5.50000,0.45829,230.10240,0.00894,0.89447,12.38108
5.60000,0.46666,234.41126,0.00909,0.90945,12.61293
5.70000,0.47503,238.11935,0.00923,0.92346,12.81245
5.80000,0.48334,241.03960,0.00938,0.93761,12.96958
5.90000,0.49165,244.27711,0.00952,0.95187,13.14378
6.00000,0.50002,248.25730,0.00966,0.96637,13.35794
6.10000,0.50827,251.55388,0.00981,0.98056,13.53532
6.20000,0.51664,254.75316,0.00995,0.99474,13.70746
6.30000,0.52501,258.38234,0.01009,1.00927,13.90274
6.40000,0.53326,261.67391,0.01023,1.02349,14.07984
6.50000,0.54169,265.95111,0.01038,1.03759,14.30999
6.60000,0.55000,268.52607,0.01053,1.05257,14.44854
6.70000,0.55831,271.56784,0.01066,1.06625,14.61221
6.80000,0.56674,275.09360,0.01081,1.08056,14.80192
6.90000,0.57500,278.93172,0.01096,1.09580,15.00843
7.00000,0.58331,281.82298,0.01110,1.10967,15.16400
7.10000,0.59174,285.18301,0.01124,1.12425,15.34479
7.20000,0.59993,288.76546,0.01138,1.13847,15.53755
7.30000,0.60818,291.29328,0.01153,1.15277,15.67357
7.40000,0.61673,295.06292,0.01167,1.16696,15.87640
7.50000,0.62492,297.70758,0.01181,1.18120,16.01870
7.60000,0.63329,301.24430,0.01196,1.19589,16.20900
7.70000,0.64178,304.99336,0.01211,1.21118,16.41073
7.80000,0.64997,307.25286,0.01225,1.22501,16.53230
7.90000,0.65828,310.81780,0.01240,1.24009,16.72412
8.00000,0.66677,314.74542,0.01255,1.25458,16.93546
8.10000,0.67490,317.31594,0.01269,1.26902,17.07377
8.20000,0.68333,320.23042,0.01283,1.28317,17.23059
8.30000,0.69176,323.74000,0.01298,1.29826,17.41942
8.40000,0.70002,326.30423,0.01312,1.31225,17.55740
8.50000,0.70839,329.54323,0.01327,1.32743,17.73168
8.60000,0.71664,332.17967,0.01342,1.34237,17.87354
8.70000,0.72489,335.68274,0.01356,1.35649,18.06203
8.80000,0.73344,338.83958,0.01372,1.37158,18.23188
8.90000,0.74169,341.39943,0.01386,1.38608,18.36962
9.00000,0.75000,345.38463,0.01400,1.40016,18.58405
9.10000,0.75843,347.25387,0.01416,1.41556,18.68463
9.20000,0.76662,350.67440,0.01430,1.43025,18.86868
9.30000,0.77493,353.19033,0.01445,1.44452,19.00405
9.40000,0.78336,356.05726,0.01460,1.45986,19.15831
9.50000,0.79161,357.92165,0.01469,1.46869,19.25863
9.60000,0.79992,360.68964,0.01484,1.48387,19.40757
9.70000,0.80835,363.74645,0.01498,1.49825,19.57204
9.80000,0.81666,366.34398,0.01513,1.51308,19.71181
9.90000,0.82498,369.11345,0.01528,1.52800,19.86083
10.00000,0.83341,371.08869,0.01543,1.54304,19.96711
10.10000,0.84166,374.64784,0.01558,1.55775,20.15861
10.20000,0.84991,377.67247,0.01573,1.57251,20.32136
10.30000,0.85840,380.35067,0.01587,1.58731,20.46547
10.40000,0.86665,382.90506,0.01602,1.60197,20.60291
10.50000,0.87502,385.41195,0.01617,1.61692,20.73780
10.60000,0.88333,388.18712,0.01633,1.63253,20.88712
10.70000,0.89164,391.21695,0.01648,1.64768,21.05015
10.80000,0.90007,393.73343,0.01662,1.66244,21.18555
10.90000,0.90832,396.34197,0.01677,1.67739,21.32591
11.00000,0.91669,399.02325,0.01692,1.69220,21.47018
11.10000,0.92506,401.62383,0.01707,1.70728,21.61011
11.20000,0.93331,404.21854,0.01723,1.72273,21.74972
11.30000,0.94162,406.96356,0.01738,1.73805,21.89742
11.40000,0.95000,408.91273,0.01753,1.75298,22.00230
11.50000,0.95825,412.20854,0.01768,1.76839,22.17964
11.60000,0.96656,414.77927,0.01784,1.78352,22.31796
11.70000,0.97505,417.06450,0.01798,1.79848,22.44092
11.80000,0.98336,419.42415,0.01814,1.81362,22.56788
11.90000,0.99161,421.81145,0.01829,1.82892,22.69634
12.00000,1.00010,424.51927,0.01844,1.84430,22.84204
12.10000,1.00835,427.61071,0.01860,1.85968,23.00838
12.20000,1.01666,429.12317,0.01875,1.87455,23.08976
12.30000,1.02509,432.51170,0.01890,1.89007,23.27209
12.40000,1.03328,433.84843,0.01905,1.90503,23.34401
12.50000,1.04165,436.01710,0.01920,1.92013,23.46070
12.60000,1.04996,439.25946,0.01936,1.93581,23.63516
12.70000,1.05827,441.37454,0.01952,1.95157,23.74897
12.80000,1.06664,443.98457,0.01967,1.96670,23.88940
12.90000,1.07502,445.57429,0.01982,1.98221,23.97494
13.00000,1.08333,448.37282,0.01998,1.99778,24.12552
13.10000,1.09176,451.31147,0.02013,2.01330,24.28364
13.20000,1.10001,453.22767,0.02029,2.02883,24.38675
13.30000,1.10838,455.62563,0.02045,2.04456,24.51577
13.40000,1.11675,458.22756,0.02061,2.06062,24.65578
13.50000,1.12500,459.90921,0.02076,2.07571,24.74626
13.60000,1.13325,462.65465,0.02091,2.09141,24.89398
13.70000,1.14174,464.02314,0.02107,2.10713,24.96762
13.80000,1.14999,466.53356,0.02123,2.12293,25.10269
13.90000,1.15824,468.57689,0.02140,2.13955,25.21264
14.00000,1.16673,470.87818,0.02156,2.15557,25.33646
14.10000,1.17498,473.39275,0.02171,2.17124,25.47177
14.20000,1.18329,475.53298,0.02187,2.18711,25.58692
14.30000,1.19178,476.97439,0.02203,2.20316,25.66448
14.40000,1.19998,478.60024,0.02219,2.21878,25.75196
14.50000,1.20829,481.97750,0.02234,2.23442,25.93368
14.60000,1.21672,483.94571,0.02252,2.25151,26.03959
14.70000,1.22491,485.18456,0.02267,2.26711,26.10625
14.80000,1.23334,487.42164,0.02283,2.28294,26.22662
14.90000,1.24171,489.21639,0.02300,2.29955,26.32318
15.00000,1.24996,492.09720,0.02316,2.31552,26.47819
15.10000,1.25833,492.94676,0.02331,2.33130,26.52390
15.20000,1.26670,495.22212,0.02347,2.34682,26.64633
15.30000,1.27495,495.17835,0.02358,2.35784,26.64398
15.40000,1.28338,497.97515,0.02374,2.37428,26.79447
15.50000,1.29175,499.75896,0.02390,2.39012,26.89045
15.60000,1.29994,501.40228,0.02406,2.40642,26.97887
15.70000,1.30837,504.13716,0.02422,2.42245,27.12602
15.80000,1.31662,505.82998,0.02439,2.43852,27.21711
15.90000,1.32488,508.44932,0.02455,2.45491,27.35805
16.00000,1.33343,509.56747,0.02472,2.47191,27.41821
16.10000,1.34162,511.21884,0.02488,2.48821,27.50707
16.20000,1.34993,513.45355,0.02504,2.50415,27.62731
16.30000,1.35848,514.26040,0.02521,2.52101,27.67072
16.40000,1.36667,516.28458,0.02537,2.53745,27.77964
16.50000,1.37504,518.29107,0.02554,2.55377,27.88760
16.60000,1.38341,520.13597,0.02571,2.57082,27.98687
16.70000,1.39166,521.51466,0.02587,2.58675,28.06105
16.80000,1.39997,523.12771,0.02603,2.60319,28.14785
16.90000,1.40840,525.34151,0.02620,2.62020,28.26696
17.00000,1.41659,526.93053,0.02637,2.63672,28.35246
17.10000,1.42496,528.46530,0.02653,2.65326,28.43505
17.20000,1.43333,530.29303,0.02670,2.67030,28.53339
17.30000,1.44164,531.50347,0.02687,2.68741,28.59852
17.40000,1.45001,533.71643,0.02704,2.70400,28.71759
17.50000,1.45839,535.26843,0.02721,2.72072,28.80110
17.60000,1.46664,536.44958,0.02737,2.73656,28.86465
17.70000,1.47501,538.13448,0.02753,2.75323,28.95531
17.80000,1.48320,539.81799,0.02770,2.76995,29.04590
17.90000,1.49157,541.07904,0.02787,2.78734,29.11375
18.00000,1.50000,542.48967,0.02804,2.80430,29.18965
18.10000,1.50819,543.87501,0.02821,2.82126,29.26419
18.20000,1.51662,545.98087,0.02838,2.83763,29.37750
18.30000,1.52505,547.44235,0.02855,2.85491,29.45614
18.40000,1.53336,548.41540,0.02871,2.87148,29.50850
18.50000,1.54161,550.25006,0.02888,2.88845,29.60721
18.60000,1.55010,551.66096,0.02906,2.90579,29.68313
18.70000,1.55829,553.18037,0.02923,2.92259,29.76488
18.80000,1.56666,554.64739,0.02939,2.93917,29.84382
18.90000,1.57509,555.89704,0.02956,2.95617,29.91106
19.00000,1.58335,557.84723,0.02974,2.97364,30.01599
19.10000,1.59166,558.98745,0.02991,2.99075,30.07734
19.20000,1.60003,559.97907,0.03008,3.00777,30.13070
19.30000,1.60828,561.64954,0.03025,3.02468,30.22058
19.40000,1.61665,563.15297,0.03042,3.04202,30.30148
19.50000,1.62502,564.34935,0.03059,3.05898,30.36585
19.60000,1.63333,566.38634,0.03076,3.07637,30.47546
19.70000,1.64176,567.45885,0.03093,3.11009,30.53316
19.80000,1.65001,568.12735,0.03111,3.14309,30.56913
19.89800,1.65814,569.44513,0.03127,3.17562,30.64004
19.99800,1.66645,571.97898,0.03144,3.20886,30.77638
20.09800,1.67476,572.35300,0.03162,3.24210,30.79650
20.19800,1.68307,573.80977,0.03179,3.27535,30.87489
20.29800,1.69150,575.03181,0.03196,3.30907,30.94064
20.39800,1.69976,575.81244,0.03214,3.34207,30.98265
20.49800,1.70813,578.11183,0.03231,3.37555,31.10637
20.59800,1.71656,578.51672,0.03248,3.40928,31.12815
20.69800,1.72481,579.90877,0.03265,3.44228,31.20305
20.79800,1.73312,580.98701,0.03283,3.47552,31.26107
20.89800,1.74161,582.61929,0.03300,3.50948,31.34890
20.99800,1.74974,583.56924,0.03318,3.54201,31.40001
21.09800,1.75811,585.24334,0.03332,3.57549,31.49009
21.19800,1.76654,585.83585,0.03342,3.60921,31.52197
21.29800,1.77479,587.00321,0.03350,3.64222,31.58478
21.39800,1.78316,589.13031,0.03375,3.67570,31.69924
21.49800,1.79153,589.17771,0.03406,3.70918,31.70179
21.59800,1.79978,590.68073,0.03148,3.74218,31.78266
21.69800,1.80821,592.05140,0.00521,3.77591,31.85641
21.79800,1.81664,591.93312,0.00630,3.80963,31.85005
21.89800,1.82489,594.06487,0.00441,3.84263,31.96475
21.99800,1.83321,594.56718,0.00662,3.87587,31.99178
22.09800,1.84152,596.88156,0.00739,3.90912,32.11631
22.19800,1.84977,597.45777,0.00706,3.94212,32.14731
22.29800,1.85820,598.36102,0.00599,3.97584,32.19591
22.39800,1.86651,600.14580,0.00450,4.00908,32.29195
22.49800,1.87476,600.98059,0.00391,4.04209,32.33686
22.59800,1.88319,602.02209,0.00420,4.07581,32.39290
22.69800,1.89150,603.11970,0.00471,4.10905,32.45196
22.79800,1.89975,603.73163,0.00494,4.14206,32.48489
22.89800,1.90824,605.34230,0.00602,4.17602,32.57155
22.99800,1.91643,606.31689,0.00641,4.20878,32.62399
23.09800,1.92474,607.72817,-0.00262,4.24202,32.69993
23.19800,1.93323,607.60588,-0.01901,4.27598,32.69335
23.29800,1.94142,608.32826,-0.02341,4.30875,32.73222
23.39800,1.94980,608.95532,-0.02827,4.34223,32.76596
23.49800,1.95817,609.90341,-0.13874,4.37571,32.81697
23.59800,1.96648,610.73853,-0.13542,4.40896,32.86191
23.69800,1.97485,612.12755,-0.13544,4.44244,32.93665
23.79800,1.98322,613.27838,-0.13545,4.47592,32.99857
23.89800,1.99159,614.74014,-0.13545,4.50940,33.07722
23.99800,1.99990,616.03282,-0.13545,4.54265,33.14677
24.09800,2.00821,616.77475,-0.13545,4.57589,33.18670
24.19800,2.01652,617.37401,-0.13545,4.60913,33.21894
24.29800,2.02483,617.73593,-0.13545,4.64237,33.23841
24.39800,2.03320,619.91545,-0.13546,4.67586,33.35569
24.49800,2.04151,620.79504,-0.13545,4.70910,33.40302
24.59800,2.04988,621.94713,-0.13546,4.74258,33.46500
24.69800,2.05819,623.14607,-0.13546,4.77582,33.52952
24.79800,2.06650,623.63851,-0.13546,4.80907,33.55602
24.89800,2.07487,624.34836,-0.13546,4.84255,33.59421
24.99800,2.08313,625.62875,-0.13546,4.87555,33.66310
25.09800,2.09150,626.77176,-0.13546,4.90904,33.72460
25.19800,2.09981,627.84483,-0.13546,4.94228,33.78234
25.29800,2.10812,628.25750,-0.13546,4.97552,33.80455
25.39800,2.11643,629.81090,-0.13546,5.00876,33.88813
25.49800,2.12480,629.79353,-0.13546,5.04225,33.88720
25.59800,2.13311,630.93686,-0.13546,5.07549,33.94872
25.69800,2.14142,632.69828,-0.13546,5.10873,34.04349
25.79800,2.14979,633.17851,-0.13546,5.14221,34.06933
25.89800,2.15822,634.12287,-0.13546,5.17594,34.12014
25.99800,2.16653,635.19925,-0.13546,5.20918,34.17806
26.09800,2.17484,635.90859,-0.13546,5.24242,34.21623
26.19800,2.18321,636.30277,-0.13547,5.27590,34.23744
26.29800,2.19152,638.01454,-0.13546,5.30915,34.32954
26.39800,2.19983,638.40672,-0.13547,5.34239,34.35064
26.49800,2.20821,639.55840,-0.13546,5.37587,34.41261
26.59800,2.21652,639.99160,-0.13546,5.40912,34.43592
26.69800,2.22483,641.57927,-0.13547,5.44236,34.52135
26.79800,2.23320,642.30016,-0.13547,5.47584,34.56014
26.89800,2.24157,643.27172,-0.13547,5.50932,34.61242
26.99800,2.24982,643.71424,-0.13547,5.54233,34.63623
27.09800,2.25819,645.42769,-0.13546,5.57581,34.72842
27.19800,2.26656,646.10089,-0.13547,5.60929,34.76464
27.29800,2.27487,646.18811,-0.13546,5.64253,34.76934
27.39800,2.28318,647.03296,-0.13547,5.67578,34.81480
27.49800,2.29149,648.11301,-0.13547,5.70902,34.87291
27.59800,2.29980,649.24941,-0.13547,5.74226,34.93406
27.69800,2.30817,650.22148,-0.13547,5.77574,34.98636
27.79800,2.31654,649.98185,-0.13547,5.80923,34.97346
27.89800,2.32485,652.11970,-0.13547,5.84247,35.08850
27.99800,2.33317,652.78597,-0.13547,5.87571,35.12435
28.09800,2.34148,653.53629,-0.13547,5.90896,35.16472
28.19800,2.34985,654.10882,-0.13547,5.94244,35.19553
28.29800,2.35816,654.98031,-0.13547,5.97568,35.24242
28.39800,2.36647,655.21682,-0.13547,6.00892,35.25514
28.49800,2.37478,656.98498,-0.13547,6.04217,35.35028
28.59800,2.38315,657.27117,-0.13547,6.07565,35.36568
28.69800,2.39146,658.49801,-0.13547,6.10889,35.43169
28.79800,2.39983,658.98797,-0.13547,6.14237,35.45806
28.89800,2.40814,660.51460,-0.13547,6.17562,35.54020
28.99800,2.41645,660.62342,-0.13547,6.20886,35.54605
29.09800,2.42482,661.22692,-0.13547,6.24234,35.57853
29.19800,2.43325,662.30074,-0.13547,6.27606,35.63631
29.29800,2.44156,663.16100,-0.13547,6.30931,35.68259
29.39800,2.44981,663.98475,-0.13547,6.34231,35.72692
29.49800,2.45824,664.58764,-0.13547,6.37603,35.75936
29.59800,2.46650,665.45606,-0.13547,6.40903,35.80608
29.69800,2.47481,665.70919,-0.13546,6.44228,35.81970
29.79800,2.48324,666.68368,-0.13546,6.47600,35.87214
29.89800,2.49149,668.01612,-0.13546,6.50900,35.94383
29.99800,2.49980,668.30856,-0.13546,6.54224,35.95957
30.09800,2.50823,669.60808,-0.13546,6.57597,36.02949
30.19800,2.51648,669.73716,-0.13546,6.60897,36.03643
30.29800,2.52485,670.73568,-0.13546,6.64245,36.09016
30.39800,2.53322,671.34895,-0.13546,6.67593,36.12316
30.49800,2.54147,671.89238,-0.13546,6.70894,36.15240
30.59800,2.54984,671.94505,-0.13546,6.74242,36.15524
30.69800,2.55809,672.79185,-0.13546,6.77542,36.20080
30.79800,2.56646,673.58874,-0.13546,6.80891,36.24368
30.89800,2.57483,674.48975,-0.13546,6.84239,36.29216
30.99800,2.58309,674.86763,-0.13546,6.87539,36.31249
31.09800,2.59152,675.41618,-0.13546,6.90911,36.34201
31.19800,2.59983,676.23197,-0.13546,6.94236,36.38590
31.29800,2.60814,676.54611,-0.13547,6.97560,36.40281
31.39800,2.61645,677.68553,-0.13546,7.00884,36.46411
31.49800,2.62482,678.42691,-0.13546,7.04232,36.50401
31.59800,2.63319,678.99171,-0.13546,7.07581,36.53439
31.69800,2.64150,680.34697,-0.13546,7.10905,36.60732
31.79800,2.64987,680.78656,-0.13546,7.14253,36.63097
31.89800,2.65812,680.88323,-0.13546,7.17554,36.63617
31.99800,2.66643,681.76398,-0.13546,7.20878,36.68356
32.09800,2.67480,682.55807,-0.13546,7.24226,36.72629
32.19800,2.68317,683.43831,-0.13546,7.27574,36.77365
32.29800,2.69148,684.17811,-0.13547,7.30899,36.81346
32.39800,2.69985,684.76070,-0.13547,7.34247,36.84481
32.49800,2.70816,685.33109,-0.13546,7.37571,36.87550
32.59800,2.71654,686.60663,-0.13546,7.40919,36.94413
32.69800,2.72485,686.40318,-0.13546,7.44244,36.93318
32.79800,2.73322,687.41911,-0.13547,7.47592,36.98785
32.89800,2.74147,687.96924,-0.13546,7.50892,37.01744
32.99800,2.74978,688.38629,-0.13546,7.54216,37.03989
33.09800,2.75821,689.31179,-0.13546,7.57589,37.08968
33.19800,2.76652,689.82150,-0.13546,7.60913,37.11711
33.29800,2.77483,690.18784,-0.13546,7.64237,37.13682
33.39800,2.78320,691.27576,-0.13546,7.67585,37.19536
33.49800,2.79157,692.00243,-0.13546,7.70934,37.23446
33.59800,2.79982,691.86860,-0.13546,7.74234,37.22726
33.69800,2.80813,693.04635,-0.13546,7.77558,37.29063
33.79800,2.81650,693.85874,-0.13547,7.80907,37.33434
33.89800,2.82475,694.52990,-0.13547,7.84207,37.37045
33.99800,2.83307,694.31621,-0.13546,7.87531,37.35896
34.09800,2.84150,695.72022,-0.13547,7.90903,37.43450
34.19800,2.84975,696.21652,-0.13546,7.94204,37.46121
34.29800,2.85812,697.06556,-0.13547,7.97552,37.50689
34.39800,2.86655,696.98212,-0.13546,8.00924,37.50240
34.49800,2.87486,698.01840,-0.13546,8.04248,37.55816
34.59800,2.88323,698.42939,-0.13546,8.07597,37.58027
34.69800,2.89154,698.82367,-0.13547,8.10921,37.60149
34.79800,2.89985,699.52123,-0.13546,8.14245,37.63902
34.89800,2.90816,699.94163,-0.13547,8.17569,37.66164
34.99800,2.91647,700.55770,-0.13546,8.20894,37.69479
35.09800,2.92478,700.87677,-0.13547,8.24218,37.71196
35.19800,2.93315,702.31482,-0.13546,8.27566,37.78934
35.29800,2.94146,702.78882,-0.13547,8.30891,37.81484
35.39800,2.94971,703.77900,-0.13546,8.34191,37.86812
35.49800,2.95820,703.92052,-0.13546,8.37587,37.87573
35.59800,2.96658,704.35512,-0.13547,8.40935,37.89912
35.69800,2.97483,704.27326,-0.13547,8.44235,37.89471
35.79800,2.98332,705.76798,-0.13546,8.47632,37.97514
35.89800,2.99145,706.80301,-0.13547,8.50884,38.03083
35.99800,2.99976,706.39621,-0.13546,8.54208,38.00894
36.09800,3.00819,707.23267,-0.13547,8.57581,38.05395
36.19800,3.01644,707.79673,-0.13547,8.60881,38.08430
36.29800,3.02475,708.11422,-0.13547,8.64205,38.10138
36.39800,3.03324,709.11292,-0.13547,8.67601,38.15512
36.49800,3.04143,709.49243,-0.13546,8.70878,38.17554
36.59800,3.04980,710.11870,-0.13546,8.74226,38.20924
36.69800,3.05829,710.53156,-0.13547,8.77622,38.23145
36.79800,3.06654,710.88644,-0.13547,8.80922,38.25055
36.89800,3.07485,711.43392,-0.13547,8.84247,38.28001
36.99800,3.08328,711.61916,-0.13547,8.87619,38.28997
37.09800,3.09142,712.70098,-0.13547,8.90871,38.34818
37.19800,3.09985,713.13754,-0.13547,8.94243,38.37167
37.29800,3.10822,713.77247,-0.13546,8.97592,38.40584
37.39800,3.11647,714.32367,-0.13546,9.00892,38.43549
37.49800,3.12490,714.00907,-0.13547,9.04264,38.41857
37.59800,3.13321,713.88450,-0.13547,9.07588,38.41187
37.69800,3.14146,715.55232,-0.13547,9.10889,38.50161
37.79800,3.14995,715.55404,-0.13546,9.14285,38.50170
37.89800,3.15820,716.68290,-0.13547,9.17585,38.56244
37.99800,3.16645,715.44303,-0.13547,9.20886,38.49572
38.09800,3.17488,715.96163,-0.13546,9.24258,38.52363
38.19800,3.18313,715.91958,-0.13547,9.27558,38.52137
38.29800,3.19144,717.10302,-0.13547,9.30882,38.58504
38.39800,3.19981,716.91652,-0.13547,9.34231,38.57501
38.49800,3.20812,718.22833,-0.13547,9.37555,38.64559
38.59800,3.21644,718.83919,-0.13547,9.40879,38.67846
38.69800,3.22487,719.14350,-0.13546,9.44251,38.69484
38.79800,3.23312,719.28846,-0.13547,9.47552,38.70263
38.89800,3.24143,721.06761,-0.13547,9.50876,38.79837
38.99800,3.24986,720.28735,-0.13547,9.54248,38.75638
39.09800,3.25817,721.47911,-0.13547,9.57573,38.82051
39.19800,3.26648,721.36074,-0.13547,9.60897,38.81414
39.29800,3.27485,722.20117,-0.13547,9.64245,38.85936
39.39800,3.28316,722.16927,-0.13547,9.67569,38.85764
39.49800,3.29147,723.36961,-0.13546,9.70894,38.92223
39.59800,3.29978,723.03908,-0.13546,9.74218,38.90444
39.69800,3.30815,724.18526,-0.13547,9.77566,38.96611
39.79800,3.31652,724.32458,-0.13547,9.80914,38.97361
39.89800,3.32477,725.41479,-0.13547,9.84215,39.03227
39.99800,3.33320,725.52115,-0.13547,9.87587,39.03799
40.09800,3.34157,726.25042,-0.13547,9.90935,39.07724
40.19800,3.34989,726.33028,-0.13547,9.94259,39.08153
40.29800,3.35814,726.88176,-0.13547,9.97560,39.11121
40.39800,3.36657,727.22989,-0.13547,10.00932,39.12994
40.49800,3.37482,727.77378,-0.13547,10.04232,39.15920
40.59800,3.38313,728.32084,-0.13547,10.07556,39.18864
40.69800,3.39156,728.45593,-0.13546,10.10929,39.19591
40.79800,3.39981,729.31135,-0.13547,10.14229,39.24194
40.89800,3.40812,729.68504,-0.13547,10.17553,39.26204
40.99800,3.41661,729.66996,-0.13547,10.20949,39.26123
41.09800,3.42486,730.24691,-0.13547,10.24250,39.29227
41.19800,3.43317,730.73059,-0.13547,10.27574,39.31830
41.29800,3.44154,730.79183,-0.13547,10.30922,39.32159
41.39800,3.44973,731.90527,-0.13547,10.34199,39.38150
41.49800,3.45810,731.91486,-0.13547,10.37547,39.38202
41.59800,3.46648,731.89810,-0.13547,10.40895,39.38112
41.69800,3.47479,732.99007,-0.13547,10.44219,39.43988
41.79800,3.48316,733.38100,-0.13547,10.47568,39.46091
41.89800,3.49147,733.39012,-0.13547,10.50892,39.46140
41.99800,3.49978,734.10138,-0.13547,10.54216,39.49967
42.09800,3.50821,734.03795,-0.13547,10.57588,39.49626
42.19800,3.51658,734.75726,-0.13547,10.60937,39.53496
42.29800,3.52483,735.56351,-0.13547,10.64237,39.57834
42.39800,3.53326,735.55666,-0.13547,10.67609,39.57798
42.49800,3.54151,736.33366,-0.13546,10.70910,39.61978
42.59800,3.54976,736.63616,-0.13547,10.74210,39.63606
42.69800,3.55825,737.07998,-0.13547,10.77606,39.65994
42.79800,3.56644,737.92678,-0.13547,10.80882,39.70551
42.89800,3.57475,737.76022,-0.13547,10.84207,39.69654
42.99800,3.58330,737.88017,-0.13547,10.87627,39.70300
43.09800,3.59150,738.51836,-0.13547,10.90903,39.73734
43.19800,3.59981,739.37024,-0.13547,10.94227,39.78317
43.29800,3.60824,739.10118,-0.13547,10.97599,39.76870
43.39800,3.61643,739.35930,-0.13547,11.00876,39.78258
43.49800,3.62480,740.13709,-0.13547,11.04224,39.82443
43.59800,3.63323,740.61523,-0.13547,11.07596,39.85016
43.69800,3.64142,741.25724,-0.13547,11.10873,39.88470
43.79800,3.64979,741.04141,-0.13547,11.14221,39.87309
43.89800,3.65822,741.03214,-0.13547,11.17593,39.87259
43.99800,3.66641,741.92518,-0.13547,11.20870,39.92065
44.09800,3.67484,742.25552,-0.13547,11.24242,39.93842
44.19800,3.68321,742.31005,-0.13547,11.27590,39.94135
44.29800,3.69140,742.50358,-0.13547,11.30866,39.95177
44.39800,3.69995,743.95789,-0.13547,11.34286,40.03002
44.49800,3.70820,743.97749,-0.13547,11.37587,40.03107
44.59800,3.71640,744.87366,-0.13547,11.40863,40.07929
44.69800,3.72495,744.09074,-0.13547,11.44283,40.03717
44.79800,3.73314,744.61214,-0.13547,11.47560,40.06522
44.89800,3.74145,745.52153,-0.13547,11.50884,40.11415
44.99800,3.75000,745.34663,-0.13547,11.54304,40.10474
45.09800,3.75813,746.14435,-0.13547,11.57556,40.14766
45.19800,3.76644,746.46799,-0.13547,11.60881,40.16508
45.29800,3.77499,746.19376,-0.13547,11.64301,40.15032
45.39800,3.78312,746.28703,-0.13547,11.67553,40.15534
45.49800,3.79149,747.11945,-0.13547,11.70902,40.20013
45.59800,3.79986,747.98549,-0.13547,11.74250,40.24673
45.69800,3.80811,747.74865,-0.13547,11.77550,40.23399
45.79800,3.81648,748.53073,-0.13547,11.80898,40.27607
45.89800,3.82491,748.26870,-0.13547,11.84270,40.26197
45.99800,3.83310,749.17907,-0.13547,11.87547,40.31096
46.09800,3.84147,749.13921,-0.13547,11.90895,40.30881
46.19800,3.84991,749.73870,-0.13547,11.94267,40.34106
46.29800,3.85810,749.66350,-0.13547,11.97544,40.33702
46.39800,3.86653,750.08222,-0.13547,12.00916,40.35955
46.49800,3.87484,750.02192,-0.13547,12.04240,40.35630
46.59800,3.88315,750.90853,-0.13547,12.07564,40.40401
46.69800,3.89152,751.24842,-0.13547,12.10913,40.42230
46.79800,3.89977,751.64763,-0.13547,12.14213,40.44378
46.89800,3.90808,751.95991,-0.13547,12.17537,40.46058
46.99800,3.91651,751.38286,-0.13547,12.20909,40.42953
47.09800,3.92476,751.45611,-0.13547,12.24210,40.43347
47.19800,3.93313,752.31749,-0.13547,12.27558,40.47982
47.29800,3.94156,752.86161,-0.13547,12.30930,40.50910
47.39800,3.94975,752.55549,-0.13547,12.34207,40.49263
47.49800,3.95812,753.78334,-0.13547,12.37555,40.55869
47.59800,3.96655,754.46614,-0.13547,12.40927,40.59543
47.69800,3.97481,753.95079,-0.13547,12.44227,40.56770
47.79800,3.98312,754.15429,-0.13547,12.47551,40.57866
47.89800,3.99149,754.93357,-0.13547,12.50900,40.62059
47.99800,3.99980,754.96132,-0.13547,12.54224,40.62208
48.09800,4.00817,755.08696,-0.13547,12.57572,40.62884
48.19800,4.01654,755.44650,-0.13547,12.60920,40.64819
48.29800,4.02479,755.80883,-0.13547,12.64221,40.66768
48.39800,4.03316,756.27156,-0.13547,12.67569,40.69258
48.49800,4.04153,755.58512,-0.13547,12.70917,40.65564
48.59800,4.04978,756.89377,-0.13547,12.74218,40.72606
48.69800,4.05821,756.72627,-0.13547,12.77590,40.71704
48.79800,4.06646,757.50854,-0.13547,12.80890,40.75914
48.89800,4.07483,756.99599,-0.13547,12.84238,40.73156
48.99800,4.08320,758.05257,-0.13547,12.87587,40.78841
49.09800,4.09139,757.68786,-0.13547,12.90863,40.76878
49.19800,4.09977,758.10985,-0.13547,12.94211,40.79149
49.29800,4.10820,758.15408,-0.13547,12.97583,40.79387
49.39800,4.11645,758.88694,-0.13547,13.00884,40.83330
49.49800,4.12482,759.26748,-0.13547,13.04232,40.85378
49.59800,4.13325,758.90790,-0.13547,13.07604,40.83443
49.69800,4.14150,759.28178,-0.13547,13.10904,40.85455
49.79800,4.14981,759.91405,-0.13547,13.14229,40.88857
49.89800,4.15824,759.86465,-0.13547,13.17601,40.88591
49.99800,4.16643,760.55527,-0.13547,13.20877,40.92307
50.09800,4.17480,760.74158,-0.13547,13.24226,40.93309
50.19800,4.18323,760.71424,-0.13547,13.27598,40.93163
50.29800,4.19136,761.45306,-0.13547,13.30850,40.97138
50.39800,4.19979,761.56273,-0.13547,13.34222,40.97728
50.49800,4.20822,761.66568,-0.13547,13.37595,40.98282
50.59800,4.21653,762.08566,-0.13547,13.40919,41.00542
50.69800,4.22490,761.69302,-0.13547,13.44267,40.98429
50.79800,4.23322,762.85661,-0.13547,13.47591,41.04690
50.89800,4.24147,763.04157,-0.13547,13.50892,41.05685
50.99800,4.24984,763.08870,-0.13547,13.54240,41.05939
51.09800,4.25815,763.36609,-0.13547,13.57564,41.07431
51.19800,4.26646,763.10229,-0.13547,13.60888,41.06012
51.29800,4.27489,763.16153,-0.13547,13.64261,41.06330
51.39800,4.28320,763.69988,-0.13547,13.67585,41.09227
51.49800,4.29145,764.17606,-0.13547,13.70885,41.11789
51.59800,4.29994,764.54058,-0.13547,13.74281,41.13751
51.69800,4.30813,764.70166,-0.13547,13.77558,41.14618
51.79800,4.31644,764.78999,-0.13547,13.80882,41.15093
51.89800,4.32493,765.11744,-0.13547,13.84278,41.16855
51.99800,4.33306,765.62995,-0.13547,13.87531,41.19613
52.09800,4.34149,765.40206,-0.13547,13.90903,41.18386
52.19800,4.34986,765.97114,-0.13547,13.94251,41.21448
52.29800,4.35812,766.20057,-0.13547,13.97551,41.22683
52.39800,4.36649,765.88206,-0.13547,14.00900,41.20969
52.49800,4.37486,766.26171,-0.13547,14.04248,41.23012
52.59800,4.38317,766.89068,-0.13547,14.07572,41.26396
52.69800,4.39148,766.59592,-0.13547,14.10896,41.24810
52.79800,4.39985,766.45026,-0.13547,14.14245,41.24026
52.89800,4.40816,766.74479,-0.13547,14.17569,41.25611
52.99800,4.41659,767.52799,-0.13547,14.20941,41.29825
53.09800,4.42484,767.85344,-0.13547,14.24241,41.31576
53.19800,4.43309,768.17651,-0.13547,14.27542,41.33315
53.29800,4.44146,768.11714,-0.13547,14.30890,41.32995
53.39800,4.44977,768.50154,-0.13547,14.34214,41.35064
53.49800,4.45814,767.87393,-0.13547,14.37562,41.31686
53.59800,4.46651,768.84534,-0.13547,14.40911,41.36913
53.69800,4.47477,768.85382,-0.13547,14.44211,41.36959
53.79800,4.48320,769.42947,-0.13547,14.47583,41.40056
53.89800,4.49157,769.29331,-0.13547,14.50931,41.39324
53.99800,4.49982,769.92237,-0.13547,14.54232,41.42709
54.09800,4.50813,770.05625,-0.13547,14.57556,41.43429
54.19800,4.51644,770.21797,-0.13547,14.60880,41.44299
54.29800,4.52475,770.28368,-0.13547,14.64205,41.44653
54.39800,4.53312,770.30552,-0.13547,14.67553,41.44770
54.49800,4.54143,770.32908,-0.13547,14.70877,41.44897
54.59800,4.54980,770.04130,-0.13547,14.74226,41.43348
54.69800,4.55811,771.16853,-0.13547,14.77550,41.49414
54.79800,4.56648,770.60661,-0.13547,14.80898,41.46390
54.89800,4.57485,770.92797,-0.13547,14.84246,41.48119
54.99800,4.58322,772.02767,-0.13547,14.87594,41.54036
55.09800,4.59153,772.19820,-0.13547,14.90919,41.54954
55.19800,4.59990,771.83689,-0.13547,14.94267,41.53010
55.29800,4.60816,772.19810,-0.13547,14.97567,41.54953
55.39800,4.61647,772.50549,-0.13547,15.00892,41.56607
55.49800,4.62484,772.36062,-0.13547,15.04240,41.55828
55.59800,4.63321,772.65883,-0.13547,15.07588,41.57433
55.69800,4.64146,773.17897,-0.13547,15.10888,41.60231
55.79800,4.64989,772.86945,-0.13547,15.14260,41.58566
55.89800,4.65826,773.23793,-0.13547,15.17609,41.60548
55.99800,4.66651,773.01990,-0.13547,15.20909,41.59375
56.09800,4.67494,773.24444,-0.13547,15.24281,41.60583
56.19800,4.68325,773.14437,-0.13547,15.27606,41.60045
56.29800,4.69150,774.42182,-0.13547,15.30906,41.66919
56.39800,4.69981,774.22750,-0.13547,15.34230,41.65873
56.49800,4.70818,773.94857,-0.13547,15.37578,41.64372
56.59800,4.71643,774.17367,-0.13547,15.40879,41.65583
56.69800,4.72480,774.51612,-0.13547,15.44227,41.67426
56.79800,4.73312,774.49312,-0.13547,15.47551,41.67302
56.89800,4.74149,774.32245,-0.13547,15.50900,41.66384
56.99800,4.74980,775.23659,-0.13547,15.54224,41.71303
57.09800,4.75817,775.04669,-0.13547,15.57572,41.70281
57.19800,4.76654,775.11403,-0.13547,15.60920,41.70643
57.29800,4.77485,775.14113,-0.13547,15.64244,41.70789
57.39800,4.78316,775.45648,-0.13547,15.67569,41.72486
57.49800,4.79141,776.03464,-0.13547,15.70869,41.75597
57.59800,4.79984,775.59380,-0.13547,15.74241,41.73225
57.69800,4.80809,776.21010,-0.13547,15.77542,41.76541
57.79800,4.81646,776.36233,-0.13547,15.80890,41.77360
57.89800,4.82489,776.46822,-0.13547,15.84262,41.77930
57.99800,4.83320,777.09756,-0.13547,15.87586,41.81316
58.09800,4.84157,776.83767,-0.13547,15.90935,41.79918
58.19800,4.84994,776.65513,-0.13547,15.94283,41.78935
58.29800,4.85814,777.23521,-0.13547,15.97559,41.82056
58.39800,4.86651,777.33486,-0.13547,16.00907,41.82593
58.49800,4.87494,776.67814,-0.13547,16.04280,41.79059
58.59800,4.88319,777.47940,-0.13547,16.07580,41.83371
58.69800,4.89144,777.31507,-0.13547,16.10880,41.82486
58.79800,4.89981,777.95847,-0.13548,16.14228,41.85948
58.89800,4.90812,777.47200,-0.13547,16.17553,41.83331
58.99800,4.91643,778.33906,-0.13547,16.20877,41.87996
59.09800,4.92486,778.19955,-0.13547,16.24249,41.87245
59.19800,4.93317,778.35484,-0.13547,16.27573,41.88081
59.29800,4.94154,778.64523,-0.13547,16.30922,41.89643
59.39800,4.94985,778.45571,-0.13547,16.34246,41.88624
59.49800,4.95810,778.52197,-0.13547,16.37547,41.88980
59.59800,4.96653,778.66204,-0.13547,16.40919,41.89734
59.69800,4.97472,779.17422,-0.13547,16.44195,41.92490
59.79800,4.98310,778.75946,-0.13547,16.47543,41.90258
59.89800,4.99153,779.44170,-0.13547,16.50915,41.93929
59.99800,4.99978,779.73250,-0.13547,16.54216,41.95494
60.09800,5.00815,779.37897,-0.13547,16.57564,41.93591
60.19800,5.01652,779.99891,-0.13547,16.60912,41.96927
60.29800,5.02483,779.59700,-0.13547,16.64236,41.94765
60.39800,5.03320,779.94759,-0.13547,16.67584,41.96651
60.49800,5.04157,780.08748,-0.13547,16.70933,41.97404
60.59800,5.04982,780.39290,-0.13547,16.74233,41.99047
60.69800,5.05813,780.01646,-0.13547,16.77558,41.97021
60.79800,5.06650,780.45581,-0.13547,16.80906,41.99385
60.89800,5.07481,781.14644,-0.13547,16.84230,42.03102
60.99800,5.08318,780.53735,-0.13547,16.87578,41.99824
61.09800,5.09149,780.93889,-0.13547,16.90903,42.01985
61.19800,5.09974,780.63030,-0.13547,16.94203,42.00325
61.29800,5.10817,781.54644,-0.13547,16.97575,42.05254
61.39800,5.11655,780.64166,-0.13547,17.00923,42.00386
61.49800,5.12486,780.80185,-0.13547,17.04248,42.01247
61.59800,5.13311,781.32665,-0.13547,17.07548,42.04071
61.69800,5.14142,781.54709,-0.13547,17.10872,42.05257
61.79800,5.14979,781.95482,-0.13547,17.14220,42.07451
61.89800,5.15816,782.39311,-0.13547,17.17568,42.09809
61.99800,5.16647,782.43939,-0.13547,17.20893,42.10059
62.09800,5.17478,781.82956,-0.13547,17.24217,42.06777
62.19800,5.18315,782.45606,-0.13547,17.27565,42.10148
62.29800,5.19140,782.15832,-0.13547,17.30866,42.08546
62.39800,5.19983,782.17778,-0.13547,17.34238,42.08651
62.49800,5.20820,781.83617,-0.13547,17.37586,42.06813
62.59800,5.21651,782.39720,-0.13547,17.40911,42.09832
62.69800,5.22482,782.55711,-0.13547,17.44235,42.10692
62.79800,5.23319,782.45010,-0.13547,17.47583,42.10116
62.89800,5.24145,782.11464,-0.13547,17.50883,42.08311
62.99800,5.24982,782.88652,-0.13547,17.54232,42.12465
63.09800,5.25819,782.88186,-0.13547,17.57580,42.12439
63.19800,5.26644,782.47897,-0.13547,17.60880,42.10271
63.29800,5.27481,782.96363,-0.13547,17.64228,42.12880
63.39800,5.28324,783.82259,-0.13547,17.67601,42.17501
63.49800,5.29155,783.33858,-0.13547,17.70925,42.14897
63.59800,5.29986,783.50781,-0.13547,17.74249,42.15807
63.69800,5.30823,783.50892,-0.13547,17.77597,42.15813
63.79800,5.31654,783.22235,-0.13547,17.80922,42.14272
63.89800,5.32485,784.25175,-0.13548,17.84246,42.19810
63.99800,5.33316,783.57952,-0.13547,17.87570,42.16193
64.09800,5.34141,784.65501,-0.13547,17.90871,42.21980
64.19800,5.34984,784.28043,-0.13547,17.94243,42.19965
64.29800,5.35815,784.15237,-0.13547,17.97567,42.19276
64.39800,5.36647,784.27466,-0.13547,18.00891,42.19934
64.49800,5.37490,784.44816,-0.13547,18.04263,42.20867
64.59800,5.38315,784.46763,-0.13547,18.07564,42.20972
64.69800,5.39146,784.47070,-0.13547,18.10888,42.20988
64.79800,5.39989,784.27708,-0.13547,18.14260,42.19947
64.89800,5.40814,784.92388,-0.13547,18.17561,42.23427
64.99800,5.41645,784.80504,-0.13547,18.20885,42.22787
65.09800,5.42488,784.22120,-0.13547,18.24257,42.19646
65.19800,5.43307,784.89622,-0.13547,18.27534,42.23278
65.29800,5.44144,784.36136,-0.13547,18.30882,42.20400
65.39800,5.44987,785.03462,-0.13547,18.34254,42.24023
65.49800,5.45812,785.01115,-0.13547,18.37554,42.23896
65.59800,5.46649,784.90414,-0.13547,18.40902,42.23321
65.69801,5.47492,785.20635,-0.13548,18.44275,42.24947
65.79801,5.48317,785.18447,-0.13547,18.47575,42.24829
65.89800,5.49155,785.76412,-0.13547,18.50923,42.27948
65.99800,5.49992,785.32156,-0.13547,18.54271,42.25566
66.09800,5.50811,785.43108,-0.13547,18.57548,42.26156
66.19801,5.51648,785.92338,-0.13547,18.60896,42.28805
66.29801,5.52485,785.27611,-0.13547,18.64244,42.25322
66.39800,5.53316,785.71932,-0.13547,18.67568,42.27707
66.49800,5.54159,785.42642,-0.13547,18.70941,42.26131
66.59800,5.54984,785.50819,-0.13547,18.74241,42.26571
66.69801,5.55815,786.26992,-0.13547,18.77565,42.30669
66.79801,5.56658,785.34707,-0.13547,18.80937,42.25704
66.89800,5.57483,785.71523,-0.13547,18.84238,42.27685
66.99800,5.58314,785.89432,-0.13548,18.87562,42.28648
67.09800,5.59151,785.82531,-0.13547,18.90910,42.28277
67.19801,5.59982,785.33702,-0.13547,18.94235,42.25650
67.29801,5.60813,785.68868,-0.13547,18.97559,42.27542
67.39800,5.61650,786.03281,-0.13547,19.00907,42.29394
67.49800,5.62488,785.23736,-0.13547,19.04255,42.25114
67.59800,5.63313,785.79234,-0.13547,19.07556,42.28100
67.69801,5.64156,785.48808,-0.13547,19.10928,42.26463
67.79801,5.64987,785.87858,-0.13547,19.14252,42.28564
67.89800,5.65812,785.38852,-0.13547,19.17553,42.25927
67.99800,5.66649,785.02465,-0.13547,19.20901,42.23969
68.09800,5.67480,785.75248,-0.13547,19.24225,42.27885
68.19801,5.68311,784.35335,-0.13547,19.27549,42.20357
68.29801,5.69142,785.20998,-0.13547,19.30874,42.24966
68.39800,5.69979,784.44686,-0.13547,19.34222,42.20860
68.49800,5.70816,784.44537,-0.13547,19.37570,42.20852
68.59800,5.71647,783.31111,-0.13547,19.40894,42.14749
68.69801,5.72478,782.59679,-0.13547,19.44219,42.10905
68.79801,5.73321,779.98200,-0.13547,19.47591,41.96836
68.89800,5.74153,775.53289,-0.13547,19.50915,41.72897
68.96800,5.74750,7.23343,-0.13547,19.53307,0.38921