File: Manufatura Aditiva/Classificação Orientação/Ensaios/Ensaios SLS/Tracao_OLABI_08_06_2018_SLS_ZY6.is_metal_RawData/Specimen_RawData_2.csv
Time,Extension,Load,Strain 1,Tensile strain,Tensile stress
(sec),(mm),(N),(mm/mm),(%),(MPa)
0.00000,0.00006,33.86109,0.00148,0.14845,1.83086
0.10000,0.00419,35.67933,0.00152,0.15185,1.92918
0.20000,0.01381,40.30316,0.00167,0.16684,2.17919
0.30000,0.02362,45.62965,0.00182,0.18239,2.46719
0.40000,0.03270,49.86086,0.00198,0.19762,2.69597
0.50000,0.04143,54.31589,0.00212,0.21163,2.93685
0.60000,0.04986,59.24680,0.00226,0.22579,3.20346
0.70000,0.05823,63.32137,0.00239,0.23927,3.42378
0.80000,0.06673,66.84747,0.00254,0.25378,3.61443
0.90000,0.07498,70.75229,0.00267,0.26741,3.82556
1.00000,0.08329,75.00057,0.00281,0.28084,4.05527
1.10000,0.09178,79.79637,0.00295,0.29498,4.31458
1.20000,0.10003,83.60155,0.00308,0.30830,4.52032
1.30000,0.10840,87.45150,0.00322,0.32177,4.72849
1.40000,0.11683,91.59868,0.00336,0.33584,4.95273
1.50000,0.12496,95.84749,0.00349,0.34885,5.18246
1.60000,0.13333,99.34856,0.00363,0.36290,5.37176
1.70000,0.14170,103.36261,0.00377,0.37689,5.58880
1.80000,0.14989,107.37599,0.00390,0.39037,5.80580
1.90000,0.15832,110.55338,0.00404,0.40406,5.97760
2.00000,0.16663,114.75114,0.00417,0.41734,6.20458
2.10000,0.17494,118.31895,0.00431,0.43128,6.39749
2.20000,0.18331,122.38610,0.00445,0.44525,6.61740
2.30000,0.19163,126.31315,0.00459,0.45909,6.82973
2.40000,0.19994,129.53910,0.00472,0.47235,7.00416
2.50000,0.20837,133.79895,0.00486,0.48629,7.23449
2.60000,0.21668,136.79524,0.00500,0.49992,7.39650
2.70000,0.22499,141.50244,0.00513,0.51320,7.65101
2.80000,0.23336,144.70296,0.00527,0.52705,7.82407
2.90000,0.24167,148.37754,0.00541,0.54084,8.02275
3.00000,0.24992,152.06749,0.00554,0.55445,8.22226
3.10000,0.25841,156.01739,0.00569,0.56861,8.43583
3.20000,0.26666,159.28677,0.00582,0.58195,8.61261
3.30000,0.27497,162.88655,0.00596,0.59598,8.80725
3.40000,0.28340,167.15560,0.00610,0.60957,9.03808
3.50000,0.29171,170.65624,0.00623,0.62349,9.22736
3.60000,0.30002,174.14584,0.00638,0.63755,9.41604
3.70000,0.30839,178.49483,0.00651,0.65146,9.65119
3.80000,0.31665,181.76492,0.00665,0.66499,9.82800
3.90000,0.32502,185.13221,0.00678,0.67840,10.01007
4.00000,0.33333,188.62905,0.00692,0.69238,10.19914
4.10000,0.34164,192.28483,0.00706,0.70632,10.39681
4.20000,0.34995,195.99833,0.00719,0.71933,10.59760
4.30000,0.35826,198.92282,0.00733,0.73319,10.75572
4.40000,0.36657,202.87153,0.00747,0.74679,10.96923
4.50000,0.37500,206.15561,0.00761,0.76066,11.14680
4.60000,0.38331,210.00833,0.00776,0.77560,11.35512
4.70000,0.39162,213.68249,0.00789,0.78905,11.55378
4.80000,0.39999,217.18871,0.00803,0.80284,11.74336
4.90000,0.40824,219.96815,0.00817,0.81651,11.89364
5.00000,0.41661,223.74967,0.00830,0.82992,12.09811
5.10000,0.42504,227.32774,0.00844,0.84409,12.29157
5.20000,0.43335,230.76988,0.00858,0.85762,12.47769
5.30000,0.44166,233.80979,0.00871,0.87093,12.64206
5.40000,0.45010,236.78546,0.00883,0.88333,12.80295
5.50000,0.45829,240.03929,0.00897,0.89733,12.97889
5.60000,0.46666,243.48071,0.00911,0.91074,13.16496
5.70000,0.47503,246.77280,0.00925,0.92452,13.34297
5.80000,0.48334,250.27441,0.00939,0.93867,13.53230
5.90000,0.49171,254.07132,0.00952,0.95222,13.73759
6.00000,0.50002,256.97893,0.00966,0.96604,13.89481
6.10000,0.50827,260.66164,0.00980,0.98013,14.09393
6.20000,0.51664,263.88366,0.00994,0.99378,14.26815
6.30000,0.52495,266.70306,0.01007,1.00737,14.42059
6.40000,0.53326,270.90658,0.01021,1.02129,14.64787
6.50000,0.54169,274.35585,0.01035,1.03545,14.83438
6.60000,0.55000,277.39955,0.01050,1.05020,14.99895
6.70000,0.55831,281.06584,0.01064,1.06353,15.19718
6.80000,0.56674,283.71890,0.01078,1.07810,15.34063
6.90000,0.57500,287.52859,0.01092,1.09198,15.54662
7.00000,0.58331,290.71162,0.01106,1.10554,15.71873
7.10000,0.59174,294.14219,0.01120,1.12016,15.90422
7.20000,0.59993,297.44583,0.01133,1.13334,16.08285
7.30000,0.60818,300.43237,0.01147,1.14727,16.24433
7.40000,0.61673,303.65733,0.01162,1.16185,16.41870
7.50000,0.62498,306.60210,0.01176,1.17637,16.57792
7.60000,0.63329,310.13377,0.01191,1.19056,16.76888
7.70000,0.64178,313.15200,0.01205,1.20537,16.93208
7.80000,0.64997,315.61658,0.01219,1.21875,17.06534
7.90000,0.65828,319.06578,0.01233,1.23279,17.25183
8.00000,0.66677,322.22301,0.01247,1.24713,17.42255
8.10000,0.67490,325.97466,0.01261,1.26148,17.62540
8.20000,0.68333,328.15228,0.01275,1.27521,17.74314
8.30000,0.69176,332.04060,0.01290,1.29017,17.95338
8.40000,0.70002,335.18453,0.01304,1.30423,18.12337
8.50000,0.70839,337.45989,0.01319,1.31881,18.24640
8.60000,0.71664,340.58790,0.01333,1.33316,18.41553
8.70000,0.72489,343.87910,0.01347,1.34664,18.59349
8.80000,0.73344,347.09205,0.01361,1.36141,18.76721
8.90000,0.74169,350.03852,0.01376,1.37603,18.92653
9.00000,0.75000,352.93840,0.01390,1.38986,19.08332
9.10000,0.75843,355.69253,0.01405,1.40486,19.23224
9.20000,0.76662,358.37379,0.01419,1.41929,19.37721
9.30000,0.77493,361.94241,0.01433,1.43333,19.57017
9.40000,0.78336,364.42277,0.01447,1.44748,19.70428
9.50000,0.79161,366.52514,0.01462,1.46218,19.81796
9.60000,0.79992,369.85623,0.01477,1.47669,19.99807
9.70000,0.80835,372.78617,0.01491,1.49120,20.15649
9.80000,0.81666,375.42554,0.01506,1.50565,20.29920
9.90000,0.82498,377.89652,0.01520,1.52025,20.43280
10.00000,0.83341,381.09154,0.01535,1.53453,20.60556
10.10000,0.84166,383.89699,0.01549,1.54898,20.75725
10.20000,0.84991,386.80262,0.01564,1.56353,20.91435
10.30000,0.85840,389.32499,0.01579,1.57854,21.05074
10.40000,0.86665,391.28899,0.01593,1.59300,21.15693
10.50000,0.87502,394.77334,0.01608,1.60817,21.34533
10.60000,0.88333,397.04777,0.01622,1.62248,21.46831
10.70000,0.89164,399.85119,0.01637,1.63732,21.61989
10.80000,0.90007,401.94909,0.01651,1.65144,21.73332
10.90000,0.90832,405.22330,0.01666,1.66622,21.91036
11.00000,0.91669,407.79174,0.01681,1.68091,22.04923
11.10000,0.92506,410.21421,0.01696,1.69580,22.18022
11.20000,0.93331,412.68067,0.01711,1.71091,22.31358
11.30000,0.94162,415.17597,0.01725,1.72533,22.44850
11.40000,0.95000,417.77031,0.01740,1.74040,22.58877
11.50000,0.95825,420.12213,0.01754,1.75403,22.71593
11.60000,0.96656,422.14012,0.01767,1.76678,22.82505
11.70000,0.97505,424.74177,0.01781,1.78141,22.96572
11.80000,0.98336,426.67110,0.01796,1.79615,23.07004
11.90000,0.99161,429.63894,0.01812,1.81168,23.23051
12.00000,1.00010,432.33582,0.01827,1.82667,23.37633
12.10000,1.00835,434.43413,0.01842,1.84176,23.48978
12.20000,1.01666,436.52188,0.01857,1.85653,23.60267
12.30000,1.02509,438.79100,0.01871,1.87139,23.72536
12.40000,1.03328,441.72024,0.01887,1.88667,23.88374
12.50000,1.04165,444.40334,0.01902,1.90163,24.02882
12.60000,1.04996,446.41397,0.01917,1.91659,24.13753
12.70000,1.05827,449.38857,0.01932,1.93207,24.29837
12.80000,1.06664,451.54141,0.01947,1.94690,24.41477
12.90000,1.07502,453.46548,0.01962,1.96181,24.51880
13.00000,1.08333,456.23761,0.01977,1.97672,24.66869
13.10000,1.09170,457.53941,0.01992,1.99235,24.73908
13.20000,1.10001,460.38730,0.02008,2.00755,24.89307
13.30000,1.10832,462.73563,0.02023,2.02285,25.02004
13.40000,1.11675,464.42184,0.02037,2.03699,25.11121
13.50000,1.12500,466.28858,0.02050,2.05021,25.21215
13.60000,1.13325,468.49246,0.02066,2.06558,25.33131
13.70000,1.14168,470.67096,0.02081,2.08057,25.44910
13.80000,1.14999,472.21985,0.02096,2.09635,25.53285
13.90000,1.15824,475.33880,0.02112,2.11221,25.70149
14.00000,1.16673,477.48224,0.02128,2.12809,25.81739
14.10000,1.17498,479.29664,0.02143,2.14345,25.91549
14.20000,1.18329,481.73401,0.02159,2.15855,26.04728
14.30000,1.19178,483.08517,0.02174,2.17436,26.12034
14.40000,1.19998,485.58358,0.02190,2.18987,26.25542
14.50000,1.20829,487.59840,0.02206,2.20551,26.36437
14.60000,1.21672,490.14729,0.02222,2.22213,26.50218
14.70000,1.22491,491.32179,0.02237,2.23741,26.56569
14.80000,1.23334,493.52567,0.02253,2.25292,26.68485
14.90000,1.24171,494.94808,0.02269,2.26895,26.76176
15.00000,1.24996,498.27471,0.02284,2.28450,26.94163
15.10000,1.25833,499.48343,0.02300,2.30037,27.00699
15.20000,1.26670,501.42710,0.02316,2.31582,27.11208
15.30000,1.27495,503.00546,0.02332,2.33169,27.19742
15.40000,1.28338,504.66810,0.02348,2.34768,27.28732
15.50000,1.29175,506.59468,0.02364,2.36395,27.39149
15.60000,1.29994,508.67293,0.02379,2.37936,27.50386
15.70000,1.30837,510.36179,0.02396,2.39574,27.59518
15.80000,1.31662,512.61429,0.02412,2.41181,27.71697
15.90000,1.32488,514.65649,0.02428,2.42773,27.82739
16.00000,1.33343,515.77720,0.02444,2.44405,27.88799
16.10000,1.34162,517.73638,0.02460,2.46022,27.99392
16.20000,1.34993,519.94575,0.02476,2.47574,28.11338
16.30000,1.35842,521.32779,0.02492,2.49216,28.18811
16.40000,1.36667,523.27015,0.02509,2.50855,28.29313
16.50000,1.37504,524.27221,0.02525,2.52491,28.34731
16.60000,1.38341,526.96355,0.02541,2.54141,28.49283
16.70000,1.39160,527.90996,0.02557,2.55745,28.54400
16.80000,1.39997,529.79025,0.02573,2.57316,28.64567
16.90000,1.40840,531.12232,0.02590,2.58970,28.71770
17.00000,1.41659,533.24709,0.02606,2.60582,28.83258
17.10000,1.42496,534.40090,0.02623,2.62279,28.89497
17.20000,1.43333,536.51342,0.02639,2.63907,29.00919
17.30000,1.44164,538.04116,0.02656,2.65619,29.09180
17.40000,1.45001,539.17775,0.02672,2.67178,29.15325
17.50000,1.45839,541.03825,0.02689,2.68869,29.25385
17.60000,1.46664,541.83900,0.02704,2.70424,29.29715
17.70000,1.47501,543.69252,0.02721,2.72085,29.39737
17.80000,1.48320,545.92113,0.02738,2.73753,29.51787
17.90000,1.49157,546.87778,0.02755,2.75455,29.56959
18.00000,1.50000,548.16417,0.02771,2.77076,29.63915
18.10000,1.50819,550.30389,0.02787,2.78708,29.75484
18.20000,1.51656,551.49617,0.02804,2.80369,29.81931
18.30000,1.52505,553.30195,0.02820,2.82030,29.91695
18.40000,1.53336,554.19346,0.02837,2.83685,29.96515
18.50000,1.54161,555.11044,0.02853,2.85327,30.01473
18.60000,1.55004,556.94822,0.02871,2.87078,30.11410
18.70000,1.55829,558.36146,0.02887,2.88708,30.19051
18.80000,1.56666,559.53395,0.02904,2.90367,30.25391
18.90000,1.57509,561.25601,0.02920,2.91974,30.34702
19.00000,1.58335,562.71120,0.02936,2.93623,30.42570
19.10000,1.59166,562.91497,0.02950,2.95031,30.43672
19.20000,1.60003,564.68532,0.02967,2.96669,30.53244
19.30000,1.60834,566.12818,0.02984,2.98363,30.61046
19.40000,1.61665,567.33079,0.03000,2.99959,30.67548
19.50000,1.62502,568.35646,0.03017,3.01674,30.73094
19.60000,1.63333,570.36136,0.03034,3.03392,30.83935
19.70000,1.64176,572.06624,0.03051,3.05076,30.93153
19.80000,1.65007,572.39584,0.03068,3.06798,30.94935
19.90000,1.65832,574.01843,0.03084,3.08442,31.03708
20.00000,1.66663,576.16201,0.03101,3.11766,31.15299
20.10000,1.67488,576.88230,0.03118,3.15066,31.19193
20.15200,1.67925,577.64696,0.03127,3.16812,31.23328
20.25200,1.68762,578.70988,0.03144,3.20160,31.29075
20.35200,1.69599,580.23501,0.03161,3.23509,31.37321
20.45200,1.70430,581.19530,0.03178,3.26833,31.42513
20.55200,1.71267,583.07983,0.03195,3.30181,31.52703
20.65200,1.72104,583.85814,0.03212,3.33529,31.56911
20.75200,1.72935,585.00865,0.03229,3.36854,31.63132
20.85200,1.73766,586.19543,0.03246,3.40178,31.69549
20.95200,1.74597,587.79535,0.03263,3.43502,31.78200
21.05200,1.75422,589.20681,0.03281,3.46803,31.85832
21.15200,1.76271,590.30419,0.03298,3.50199,31.91765
21.25200,1.77102,590.67146,0.03314,3.53523,31.93751
21.35200,1.77928,592.24893,0.03332,3.56823,32.02280
21.45200,1.78771,593.78054,0.03349,3.60195,32.10562
21.55200,1.79596,594.79228,0.03366,3.63496,32.16032
21.65200,1.80433,595.29021,0.03384,3.66844,32.18724
21.75200,1.81282,596.86908,0.03401,3.70240,32.27261
21.85200,1.82107,598.06872,0.03418,3.73540,32.33748
21.95200,1.82938,599.60918,0.03436,3.76865,32.42077
22.05200,1.83775,600.69887,0.03453,3.80213,32.47969
22.15200,1.84600,601.54600,0.03470,3.83513,32.52549
22.25200,1.85425,602.61935,0.03488,3.86814,32.58353
22.35200,1.86268,603.66271,0.03505,3.90186,32.63995
22.45200,1.87099,604.72661,0.03524,3.93510,32.69747
22.55200,1.87930,605.60056,0.03540,3.96834,32.74472
22.65200,1.88773,606.82977,0.03576,4.00207,32.81119
22.75200,1.89592,607.80854,0.03510,4.03483,32.86411
22.85200,1.90430,609.51412,0.03210,4.06831,32.95633
22.95200,1.91267,609.86397,0.00301,4.10179,32.97525
23.05200,1.92092,610.95483,0.00400,4.13480,33.03423
23.15200,1.92935,612.53211,0.00408,4.16852,33.11951
23.25200,1.93760,612.88620,0.00401,4.20152,33.13866
23.35200,1.94591,614.00840,0.00414,4.23477,33.19933
23.45200,1.95440,615.21959,0.00371,4.26873,33.26482
23.55200,1.96265,616.24125,0.00426,4.30173,33.32006
23.65200,1.97096,616.85620,0.00568,4.33497,33.35331
23.75200,1.97939,618.11609,0.00581,4.36870,33.42144
23.85200,1.98770,619.56304,0.00589,4.40194,33.49967
23.95200,1.99601,620.03522,0.00568,4.43518,33.52520
24.05200,2.00444,621.05013,0.00524,4.46890,33.58008
24.15200,2.01269,621.46485,0.00439,4.50191,33.60250
24.25200,2.02094,622.85732,0.00496,4.53491,33.67779
24.35200,2.02938,624.44555,-0.00950,4.56863,33.76367
24.45200,2.03769,625.03978,-0.01978,4.60187,33.79580
24.55200,2.04600,626.05152,-0.02732,4.63512,33.85050
24.65200,2.05443,627.13930,-0.13804,4.66884,33.90932
24.75200,2.06268,627.29898,-0.13531,4.70184,33.91795
24.85200,2.07099,628.81592,-0.13536,4.73508,33.99997
24.95200,2.07936,629.28209,-0.13535,4.76857,34.02518
25.05200,2.08767,630.86292,-0.13535,4.80181,34.11066
25.15200,2.09598,631.28704,-0.13536,4.83505,34.13359
25.25200,2.10429,632.23420,-0.13536,4.86830,34.18480
25.35200,2.11260,633.55435,-0.13535,4.90154,34.25618
25.45200,2.12091,634.65843,-0.13536,4.93478,34.31588
25.55200,2.12922,635.28847,-0.13536,4.96802,34.34995
25.65200,2.13759,636.32294,-0.13536,5.00151,34.40588
25.75200,2.14596,637.11312,-0.13536,5.03499,34.44860
25.85200,2.15433,637.26194,-0.13537,5.06847,34.45665
25.95200,2.16271,638.63788,-0.13537,5.10195,34.53104
26.05200,2.17108,640.07640,-0.13536,5.13543,34.60883
26.15200,2.17939,640.43291,-0.13536,5.16868,34.62810
26.25200,2.18770,641.37490,-0.13537,5.20192,34.67904
26.35200,2.19601,641.73117,-0.13536,5.23516,34.69830
26.45200,2.20432,642.99041,-0.13537,5.26841,34.76639
26.55200,2.21269,643.93627,-0.13536,5.30189,34.81753
26.65200,2.22100,644.78097,-0.13536,5.33513,34.86320
26.75200,2.22931,646.01512,-0.13537,5.36838,34.92993
26.85200,2.23768,646.24464,-0.13537,5.40186,34.94234
26.95200,2.24605,647.23510,-0.13537,5.43534,34.99590
27.05200,2.25442,647.93210,-0.13537,5.46882,35.03358
27.15200,2.26273,648.62021,-0.13537,5.50206,35.07079
27.25200,2.27104,649.81296,-0.13537,5.53531,35.13528
27.35200,2.27935,650.51769,-0.13537,5.56855,35.17339
27.45200,2.28767,651.57204,-0.13537,5.60179,35.23039
27.55200,2.29598,652.52972,-0.13537,5.63504,35.28218
27.65200,2.30429,653.37089,-0.13537,5.66828,35.32766
27.75200,2.31266,653.74863,-0.13537,5.70176,35.34808
27.85200,2.32097,654.81928,-0.13537,5.73500,35.40597
27.95200,2.32934,655.32275,-0.13537,5.76849,35.43319
28.05200,2.33771,656.58595,-0.13537,5.80197,35.50150
28.15200,2.34596,657.16184,-0.13537,5.83497,35.53263
28.25200,2.35427,658.11686,-0.13537,5.86822,35.58427
28.35200,2.36264,658.84609,-0.13537,5.90170,35.62370
28.45200,2.37089,658.93615,-0.13537,5.93470,35.62857
28.55200,2.37926,660.81118,-0.13537,5.96818,35.72995
28.65200,2.38769,661.34045,-0.13537,6.00190,35.75857
28.75200,2.39594,662.02483,-0.13537,6.03491,35.79557
28.85200,2.40431,662.53510,-0.13537,6.06839,35.82317
28.95200,2.41269,663.59090,-0.13537,6.10187,35.88025
29.05200,2.42100,664.37330,-0.13537,6.13512,35.92255
29.15200,2.42937,665.10276,-0.13537,6.16860,35.96200
29.25200,2.43774,665.85266,-0.13537,6.20208,36.00254
29.35200,2.44605,666.21220,-0.13537,6.23532,36.02198
29.45200,2.45436,667.31079,-0.13537,6.26857,36.08139
29.55200,2.46267,668.24718,-0.13537,6.30181,36.13202
29.65200,2.47098,668.60709,-0.13537,6.33505,36.15148
29.75200,2.47935,669.39164,-0.13537,6.36853,36.19390
29.85200,2.48766,670.25749,-0.13538,6.40178,36.24071
29.95200,2.49597,670.30522,-0.13537,6.43502,36.24329
30.05200,2.50434,671.74379,-0.13537,6.46850,36.32108
30.15200,2.51259,672.31953,-0.13537,6.50150,36.35221
30.25200,2.52096,672.65988,-0.13537,6.53499,36.37061
30.35200,2.52939,673.38920,-0.13537,6.56871,36.41005
30.45200,2.53771,674.03112,-0.13537,6.60195,36.44475
30.55200,2.54602,675.41245,-0.13538,6.63520,36.51944
30.65200,2.55433,676.07160,-0.13537,6.66844,36.55508
30.75200,2.56258,677.00031,-0.13537,6.70144,36.60530
30.85200,2.57095,677.55668,-0.13538,6.73492,36.63538
30.95200,2.57932,678.06058,-0.13537,6.76841,36.66262
31.05200,2.58763,678.34626,-0.13538,6.80165,36.67807
31.15200,2.59600,679.65998,-0.13537,6.83513,36.74910
31.25200,2.60431,680.39885,-0.13538,6.86837,36.78905
31.35200,2.61262,680.24914,-0.13538,6.90162,36.78096
31.45200,2.62099,681.60440,-0.13537,6.93510,36.85424
31.55200,2.62936,681.39140,-0.13538,6.96858,36.84272
31.65200,2.63773,683.19156,-0.13537,7.00206,36.94006
31.75200,2.64598,683.76083,-0.13537,7.03507,36.97084
31.85200,2.65429,684.32791,-0.13537,7.06831,37.00150
31.95200,2.66261,685.06696,-0.13538,7.10155,37.04146
32.05200,2.67098,684.79138,-0.13537,7.13503,37.02656
32.15200,2.67929,686.30450,-0.13538,7.16828,37.10837
32.25200,2.68766,686.58865,-0.13537,7.20176,37.12374
32.35200,2.69603,687.29594,-0.13537,7.23524,37.16198
32.45200,2.70434,687.98121,-0.13538,7.26848,37.19903
32.55200,2.71271,688.46843,-0.13538,7.30197,37.22538
32.65200,2.72102,689.28604,-0.13538,7.33521,37.26958
32.75200,2.72933,689.06322,-0.13537,7.36845,37.25753
32.85200,2.73764,689.27533,-0.13538,7.40170,37.26900
32.95200,2.74601,690.41182,-0.13538,7.43518,37.33046
33.05200,2.75432,690.67501,-0.13538,7.46842,37.34468
33.15200,2.76263,691.22249,-0.13538,7.50166,37.37429
33.25200,2.77100,692.49775,-0.13538,7.53515,37.44324
33.35200,2.77937,692.75643,-0.13538,7.56863,37.45723
33.45200,2.78769,692.97128,-0.13538,7.60187,37.46885
33.55200,2.79606,694.18633,-0.13538,7.63535,37.53454
33.65200,2.80437,694.80194,-0.13538,7.66860,37.56783
33.75200,2.81268,695.31328,-0.13538,7.70184,37.59547
33.85200,2.82093,695.93177,-0.13537,7.73484,37.62892
33.95200,2.82930,696.47813,-0.13538,7.76833,37.65846
34.05200,2.83761,697.38049,-0.13538,7.80157,37.70725
34.15200,2.84592,697.82529,-0.13538,7.83481,37.73130
34.25200,2.85423,698.69696,-0.13538,7.86805,37.77843
34.35200,2.86266,699.25967,-0.13538,7.90178,37.80886
34.45200,2.87103,700.00039,-0.13538,7.93526,37.84891
34.55200,2.87940,700.61027,-0.13538,7.96874,37.88188
34.65200,2.88771,701.25982,-0.13538,8.00198,37.91700
34.75200,2.89602,701.84041,-0.13538,8.03523,37.94839
34.85200,2.90433,702.62169,-0.13538,8.06847,37.99064
34.95200,2.91270,702.32237,-0.13538,8.10195,37.97446
35.05200,2.92102,703.25295,-0.13538,8.13519,38.02477
35.15200,2.92927,704.15903,-0.13538,8.16820,38.07376
35.25200,2.93770,704.34739,-0.13538,8.20192,38.08395
35.35200,2.94595,704.87051,-0.13538,8.23492,38.11223
35.45200,2.95432,705.77371,-0.13538,8.26840,38.16107
35.55200,2.96275,706.88981,-0.13538,8.30213,38.22142
35.65200,2.97100,706.99356,-0.13538,8.33513,38.22703
35.75200,2.97937,707.74192,-0.13538,8.36861,38.26749
35.85200,2.98774,708.12763,-0.13538,8.40209,38.28835
35.95200,2.99593,708.55008,-0.13538,8.43486,38.31119
36.05200,3.00430,709.76079,-0.13538,8.46834,38.37665
36.15200,3.01267,709.66566,-0.13538,8.50182,38.37151
36.25200,3.02092,710.03214,-0.13538,8.53483,38.39132
36.35200,3.02929,710.46441,-0.13538,8.56831,38.41470
36.45200,3.03766,711.14679,-0.13538,8.60179,38.45159
36.55200,3.04598,712.26531,-0.13538,8.63503,38.51207
36.65200,3.05435,712.56966,-0.13538,8.66852,38.52853
36.75200,3.06272,712.48407,-0.13538,8.70200,38.52390
36.85200,3.07103,713.60427,-0.13538,8.73524,38.58447
36.95200,3.07946,714.10020,-0.13538,8.76896,38.61128
37.05200,3.08765,714.70034,-0.13538,8.80173,38.64373
37.15200,3.09590,714.71538,-0.13538,8.83473,38.64454
37.25200,3.10439,715.04763,-0.13538,8.86869,38.66251
37.35200,3.11264,716.34110,-0.13538,8.90169,38.73244
37.45200,3.12095,715.84405,-0.13538,8.93494,38.70557
37.55200,3.12944,716.90306,-0.13538,8.96890,38.76283
37.65200,3.13763,717.20141,-0.13538,9.00166,38.77896
37.75200,3.14600,717.62051,-0.13538,9.03514,38.80162
37.85200,3.15449,718.05757,-0.13538,9.06911,38.82526
37.95200,3.16262,718.82731,-0.13538,9.10163,38.86687
38.05200,3.17100,718.99933,-0.13538,9.13511,38.87617
38.15200,3.17937,719.69847,-0.13538,9.16860,38.91398
38.25200,3.18756,719.93899,-0.13538,9.20136,38.92698
38.35200,3.19599,720.96577,-0.13538,9.23508,38.98250
38.45200,3.20430,720.87618,-0.13538,9.26832,38.97766
38.55200,3.21261,722.15521,-0.13538,9.30157,39.04681
38.65200,3.22098,721.64773,-0.13538,9.33505,39.01937
38.75200,3.22929,722.02133,-0.13538,9.36829,39.03957
38.85200,3.23760,722.93431,-0.13538,9.40154,39.08894
38.95200,3.24603,723.31713,-0.13538,9.43526,39.10964
39.05200,3.25434,723.60593,-0.13539,9.46850,39.12526
39.15200,3.26259,724.54950,-0.13538,9.50150,39.17627
39.25200,3.27102,724.89423,-0.13538,9.53522,39.19491
39.35200,3.27927,725.45935,-0.13538,9.56823,39.22547
39.45200,3.28764,726.39240,-0.13538,9.60171,39.27592
39.55200,3.29608,725.86690,-0.13538,9.63543,39.24751
39.65200,3.30427,727.28992,-0.13538,9.66820,39.32445
39.75200,3.31264,727.06849,-0.13538,9.70168,39.31247
39.85200,3.32107,727.39650,-0.13538,9.73540,39.33021
39.95200,3.32932,728.09844,-0.13538,9.76840,39.36816
40.05200,3.33769,728.61835,-0.13538,9.80189,39.39627
40.15200,3.34606,728.46347,-0.13538,9.83537,39.38790
40.25200,3.35437,729.41938,-0.13538,9.86861,39.43959
40.35200,3.36268,729.65049,-0.13538,9.90185,39.45208
40.45200,3.37105,730.21539,-0.13538,9.93534,39.48263
40.55200,3.37930,731.20380,-0.13539,9.96834,39.53607
40.65200,3.38767,731.07230,-0.13538,10.00182,39.52896
40.75200,3.39598,731.90709,-0.13538,10.03506,39.57410
40.85200,3.40429,732.15584,-0.13538,10.06831,39.58755
40.95200,3.41272,732.56860,-0.13539,10.10203,39.60986
41.05200,3.42104,733.39255,-0.13538,10.13527,39.65442
41.15200,3.42929,733.60354,-0.13538,10.16828,39.66582
41.25200,3.43766,733.76265,-0.13538,10.20176,39.67443
41.35200,3.44591,734.36806,-0.13538,10.23476,39.70716
41.45200,3.45422,734.78478,-0.13538,10.26800,39.72969
41.55200,3.46271,734.81351,-0.13538,10.30197,39.73125
41.65200,3.47096,734.89905,-0.13538,10.33497,39.73587
41.75200,3.47927,735.97669,-0.13538,10.36821,39.79414
41.85200,3.48776,736.28272,-0.13539,10.40217,39.81069
41.95200,3.49595,736.74130,-0.13538,10.43494,39.83548
42.05200,3.50432,736.53734,-0.13538,10.46842,39.82446
42.15200,3.51275,737.63230,-0.13538,10.50214,39.88366
42.25200,3.52100,737.31495,-0.13538,10.53514,39.86650
42.35200,3.52937,738.44488,-0.13538,10.56863,39.92759
42.45200,3.53774,738.78467,-0.13539,10.60211,39.94596
42.55200,3.54594,739.15599,-0.13539,10.63487,39.96605
42.65200,3.55431,739.20372,-0.13538,10.66836,39.96862
42.75200,3.56268,738.77727,-0.13538,10.70184,39.94556
42.85200,3.57093,739.56954,-0.13538,10.73484,39.98840
42.95200,3.57942,740.67144,-0.13538,10.76880,40.04799
43.05200,3.58773,741.12038,-0.13539,10.80204,40.07226
43.15200,3.59592,741.66227,-0.13538,10.83481,40.10156
43.25200,3.60441,741.69077,-0.13538,10.86877,40.10310
43.35200,3.61266,741.69687,-0.13538,10.90177,40.10343
43.45200,3.62091,742.73371,-0.13539,10.93478,40.15949
43.55200,3.62940,742.74507,-0.13538,10.96874,40.16011
43.65200,3.63759,743.69241,-0.13538,11.00150,40.21133
43.75200,3.64590,744.05000,-0.13538,11.03474,40.23066
43.85200,3.65439,744.14508,-0.13538,11.06870,40.23580
43.95200,3.66264,744.47109,-0.13538,11.10171,40.25343
44.05200,3.67096,744.94570,-0.13538,11.13495,40.27909
44.15200,3.67945,744.82388,-0.13538,11.16891,40.27251
44.25200,3.68764,745.21406,-0.13538,11.20168,40.29360
44.35200,3.69601,746.31586,-0.13538,11.23516,40.35318
44.45200,3.70450,745.75501,-0.13538,11.26912,40.32285
44.55200,3.71257,746.50138,-0.13538,11.30141,40.36321
44.65200,3.72100,746.56936,-0.13539,11.33513,40.36688
44.75200,3.72937,746.98799,-0.13538,11.36861,40.38952
44.85200,3.73762,747.48052,-0.13538,11.40161,40.41615
44.95200,3.74611,748.00826,-0.13539,11.43557,40.44468
45.05200,3.75436,748.60975,-0.13539,11.46858,40.47721
45.15200,3.76255,748.08584,-0.13538,11.50134,40.44888
45.25200,3.77110,748.32658,-0.13538,11.53554,40.46189
45.35200,3.77941,749.00305,-0.13539,11.56878,40.49847
45.45200,3.78760,749.27560,-0.13539,11.60155,40.51321
45.55200,3.79603,749.85232,-0.13538,11.63527,40.54439
45.65200,3.80429,750.01158,-0.13538,11.66828,40.55301
45.75200,3.81260,750.31822,-0.13538,11.70152,40.56958
45.85200,3.82109,750.64264,-0.13539,11.73548,40.58712
45.95200,3.82934,751.20549,-0.13538,11.76848,40.61756
46.05200,3.83759,752.05769,-0.13539,11.80149,40.66364
46.15200,3.84608,751.82891,-0.13539,11.83545,40.65127
46.25200,3.85433,752.18603,-0.13538,11.86845,40.67057
46.35200,3.86264,752.13732,-0.13538,11.90169,40.66794
46.45200,3.87113,752.85286,-0.13539,11.93565,40.70663
46.55200,3.87932,752.91311,-0.13539,11.96842,40.70989
46.65200,3.88763,753.23568,-0.13539,12.00166,40.72733
46.75200,3.89600,753.19191,-0.13538,12.03514,40.72496
46.85200,3.90425,754.24598,-0.13538,12.06815,40.78196
46.95200,3.91262,754.45944,-0.13538,12.10163,40.79350
47.05200,3.92099,754.52384,-0.13539,12.13511,40.79698
47.15200,3.92931,755.04128,-0.13539,12.16835,40.82496
47.25200,3.93768,755.71067,-0.13538,12.20184,40.86115
47.35200,3.94599,755.52659,-0.13539,12.23508,40.85120
47.45200,3.95436,756.07961,-0.13538,12.26856,40.88110
47.55200,3.96267,755.40324,-0.13539,12.30180,40.84453
47.65200,3.97098,756.30341,-0.13539,12.33505,40.89320
47.75200,3.97929,756.85694,-0.13539,12.36829,40.92313
47.85200,3.98766,757.17713,-0.13539,12.40177,40.94044
47.95200,3.99597,756.83994,-0.13539,12.43501,40.92221
48.05200,4.00428,757.60861,-0.13539,12.46826,40.96377
48.15200,4.01265,757.92274,-0.13538,12.50174,40.98076
48.25200,4.02102,757.57741,-0.13539,12.53522,40.96209
48.35200,4.02927,758.47548,-0.13539,12.56823,41.01065
48.45200,4.03770,758.53844,-0.13539,12.60195,41.01405
48.55200,4.04595,759.28839,-0.13539,12.63495,41.05460
48.65200,4.05433,759.08895,-0.13538,12.66843,41.04382
48.75200,4.06276,759.14664,-0.13539,12.70215,41.04694
48.85200,4.07101,759.90222,-0.13539,12.73516,41.08779
48.95200,4.07932,760.13855,-0.13539,12.76840,41.10057
49.05200,4.08763,760.25664,-0.13539,12.80164,41.10695
49.15200,4.09594,760.70796,-0.13538,12.83489,41.13136
49.25200,4.10431,761.06740,-0.13538,12.86837,41.15079
49.35200,4.11268,761.20682,-0.13539,12.90185,41.15833
49.45200,4.12099,761.83104,-0.13539,12.93509,41.19208
49.55200,4.12936,761.68296,-0.13539,12.96857,41.18407
49.65200,4.13767,761.41339,-0.13539,13.00182,41.16950
49.75200,4.14592,761.96138,-0.13538,13.03482,41.19913
49.85200,4.15435,762.73698,-0.13539,13.06854,41.24107
49.95200,4.16266,762.59119,-0.13539,13.10179,41.23318
50.05200,4.17091,762.28115,-0.13539,13.13479,41.21642
50.15200,4.17934,763.31962,-0.13538,13.16851,41.27257
50.25200,4.18760,763.10579,-0.13539,13.20152,41.26101
50.35200,4.19585,763.54244,-0.13539,13.23452,41.28461
50.45200,4.20434,763.65103,-0.13539,13.26848,41.29049
50.55200,4.21265,764.54026,-0.13539,13.30172,41.33857
50.65200,4.22102,764.00861,-0.13539,13.33521,41.30982
50.75200,4.22945,764.20144,-0.13539,13.36893,41.32025
50.85200,4.23770,764.90128,-0.13539,13.40193,41.35809
50.95200,4.24595,765.78795,-0.13539,13.43493,41.40603
51.05200,4.25438,766.11834,-0.13539,13.46865,41.42389
51.15200,4.26263,765.48313,-0.13538,13.50166,41.38955
51.25200,4.27100,766.13510,-0.13538,13.53514,41.42480
51.35200,4.27943,766.27224,-0.13538,13.56886,41.43221
51.45200,4.28762,766.67792,-0.13539,13.60163,41.45415
51.55200,4.29599,766.94805,-0.13539,13.63511,41.46876
51.65200,4.30436,767.18275,-0.13539,13.66859,41.48145
51.75200,4.31262,767.22126,-0.13539,13.70159,41.48353
51.85200,4.32105,767.36803,-0.13539,13.73532,41.49146
51.95200,4.32930,767.67355,-0.13539,13.76832,41.50798
52.05200,4.33761,768.27439,-0.13538,13.80156,41.54047
52.15200,4.34604,768.07500,-0.13538,13.83528,41.52969
52.25200,4.35429,768.27323,-0.13539,13.86829,41.54041
52.35200,4.36260,768.61870,-0.13539,13.90153,41.55909
52.45200,4.37109,769.17340,-0.13539,13.93549,41.58908
52.55200,4.37928,768.82816,-0.13539,13.96826,41.57041
52.65200,4.38759,769.30933,-0.13539,14.00150,41.59643
52.75200,4.39608,769.76251,-0.13539,14.03546,41.62093
52.85200,4.40433,769.36795,-0.13539,14.06846,41.59960
52.95200,4.41270,769.79226,-0.13539,14.10195,41.62254
53.05200,4.42107,770.45872,-0.13539,14.13543,41.65858
53.15200,4.42933,770.29108,-0.13539,14.16843,41.64951
53.25200,4.43764,770.61458,-0.13539,14.20167,41.66700
53.35200,4.44601,770.57593,-0.13539,14.23516,41.66491
53.45200,4.45426,771.33463,-0.13538,14.26816,41.70594
53.55200,4.46263,771.28420,-0.13539,14.30164,41.70321
53.65200,4.47100,771.70786,-0.13539,14.33513,41.72612
53.75200,4.47931,771.74264,-0.13539,14.36837,41.72800
53.85200,4.48774,771.98246,-0.13538,14.40209,41.74097
53.95200,4.49599,771.90776,-0.13539,14.43509,41.73693
54.05200,4.50430,772.10236,-0.13539,14.46834,41.74745
54.15200,4.51267,772.81906,-0.13539,14.50182,41.78620
54.25200,4.52086,772.44299,-0.13539,14.53458,41.76587
54.35200,4.52929,773.23895,-0.13538,14.56831,41.80890
54.45200,4.53766,773.02395,-0.13539,14.60178,41.79728
54.55200,4.54591,772.93273,-0.13539,14.63479,41.79235
54.65200,4.55423,773.87234,-0.13539,14.66803,41.84315
54.75200,4.56266,773.30805,-0.13539,14.70175,41.81264
54.85200,4.57097,773.94545,-0.13539,14.73500,41.84710
54.95200,4.57934,773.79439,-0.13539,14.76848,41.83894
55.05200,4.58771,774.13227,-0.13539,14.80196,41.85720
55.15200,4.59602,774.76888,-0.13538,14.83521,41.89163
55.25200,4.60433,775.23794,-0.13539,14.86845,41.91699
55.35200,4.61270,774.16333,-0.13539,14.90193,41.85889
55.45200,4.62101,774.92734,-0.13539,14.93517,41.90020
55.55200,4.62932,775.41219,-0.13539,14.96842,41.92641
55.65200,4.63763,775.53587,-0.13539,15.00166,41.93310
55.75200,4.64600,775.64125,-0.13539,15.03514,41.93880
55.85200,4.65437,775.48148,-0.13539,15.06862,41.93016
55.95200,4.66268,776.02114,-0.13539,15.10186,41.95934
56.05200,4.67105,776.43343,-0.13539,15.13535,41.98163
56.15200,4.67948,776.26659,-0.13539,15.16907,41.97261
56.25200,4.68768,776.33234,-0.13539,15.20183,41.97616
56.35200,4.69605,776.82659,-0.13539,15.23532,42.00289
56.45200,4.70436,777.00345,-0.13539,15.26856,42.01245
56.55200,4.71261,776.66407,-0.13539,15.30156,41.99410
56.65200,4.72098,777.32224,-0.13539,15.33504,42.02969
56.75200,4.72935,777.52895,-0.13538,15.36853,42.04086
56.85200,4.73760,777.92509,-0.13539,15.40153,42.06228
56.95200,4.74591,778.18474,-0.13538,15.43477,42.07632
57.05200,4.75434,777.76597,-0.13539,15.46849,42.05368
57.15200,4.76265,777.94446,-0.13539,15.50174,42.06333
57.25200,4.77102,778.55028,-0.13539,15.53522,42.09609
57.35200,4.77939,778.25999,-0.13539,15.56870,42.08039
57.45200,4.78758,778.78148,-0.13539,15.60147,42.10859
57.55200,4.79595,778.34763,-0.13539,15.63495,42.08513
57.65200,4.80432,778.72500,-0.13539,15.66843,42.10553
57.75200,4.81264,778.67284,-0.13539,15.70167,42.10271
57.85200,4.82101,779.30959,-0.13539,15.73516,42.13714
57.95200,4.82938,779.35373,-0.13539,15.76864,42.13953
58.05200,4.83769,779.50065,-0.13539,15.80188,42.14747
58.15200,4.84612,779.75662,-0.13539,15.83560,42.16131
58.25200,4.85437,780.04473,-0.13539,15.86861,42.17689
58.35200,4.86268,780.18205,-0.13539,15.90185,42.18431
58.45200,4.87105,780.66462,-0.13539,15.93533,42.21041
58.55200,4.87930,779.75108,-0.13539,15.96834,42.16101
58.65200,4.88767,780.44306,-0.13539,16.00182,42.19843
58.75200,4.89604,780.71831,-0.13539,16.03530,42.21331
58.85200,4.90423,780.99570,-0.13539,16.06806,42.22831
58.95200,4.91260,781.26509,-0.13539,16.10155,42.24287
59.05200,4.92103,781.02788,-0.13539,16.13527,42.23005
59.15200,4.92934,781.75282,-0.13539,16.16851,42.26925
59.25200,4.93766,781.45135,-0.13539,16.20175,42.25295
59.35200,4.94609,781.83198,-0.13539,16.23547,42.27353
59.45200,4.95428,781.53564,-0.13539,16.26824,42.25750
59.55200,4.96265,782.14509,-0.13539,16.30172,42.29046
59.65200,4.97096,782.09331,-0.13539,16.33496,42.28766
59.75200,4.97927,782.13485,-0.13539,16.36820,42.28990
59.85200,4.98764,782.44386,-0.13539,16.40169,42.30661
59.95200,4.99601,782.26728,-0.13539,16.43517,42.29707
60.05200,5.00432,782.05969,-0.13539,16.46841,42.28584
60.15200,5.01263,782.14426,-0.13539,16.50166,42.29041
60.25200,5.02100,783.12997,-0.13539,16.53514,42.34371
60.35200,5.02943,783.66753,-0.13539,16.56886,42.37278
60.45200,5.03774,783.20131,-0.13539,16.60210,42.34757
60.55200,5.04599,783.73319,-0.13539,16.63511,42.37632
60.65200,5.05430,783.60606,-0.13539,16.66835,42.36945
60.75200,5.06267,783.46292,-0.13539,16.70183,42.36171
60.85200,5.07093,784.00876,-0.13538,16.73484,42.39122
60.95200,5.07930,784.01593,-0.13539,16.76832,42.39161
61.05200,5.08767,783.82064,-0.13539,16.80180,42.38105
61.15200,5.09598,784.32076,-0.13539,16.83504,42.40810
61.25200,5.10435,784.04630,-0.13539,16.86853,42.39325
61.35200,5.11272,784.87620,-0.13539,16.90201,42.43813
61.45200,5.12097,784.62278,-0.13539,16.93501,42.42443
61.55200,5.12928,784.93692,-0.13539,16.96825,42.44141
61.65200,5.13765,784.68546,-0.13539,17.00173,42.42781
61.75200,5.14590,784.38399,-0.13539,17.03474,42.41151
61.85200,5.15427,785.26502,-0.13539,17.06822,42.45915
61.95200,5.16264,785.27145,-0.13539,17.10170,42.45950
62.05200,5.17101,785.15317,-0.13539,17.13518,42.45310
62.15200,5.17932,785.52905,-0.13538,17.16843,42.47343
62.25200,5.18763,785.40808,-0.13539,17.20167,42.46688
62.35200,5.19601,785.60701,-0.13539,17.23515,42.47764
62.45200,5.20432,785.68859,-0.13539,17.26840,42.48205
62.55200,5.21269,785.86508,-0.13539,17.30188,42.49160
62.65200,5.22100,785.61585,-0.13539,17.33512,42.47812
62.75200,5.22931,785.98047,-0.13539,17.36837,42.49784
62.85200,5.23762,786.15574,-0.13539,17.40161,42.50731
62.95200,5.24593,786.75300,-0.13539,17.43485,42.53960
63.05200,5.25430,785.90922,-0.13539,17.46833,42.49398
63.15200,5.26261,785.85036,-0.13539,17.50158,42.49080
63.25200,5.27098,786.49698,-0.13539,17.53506,42.52576
63.35200,5.27941,787.20869,-0.13539,17.56878,42.56425
63.45200,5.28766,787.34327,-0.13539,17.60178,42.57152
63.55200,5.29603,787.09060,-0.13539,17.63527,42.55786
63.65200,5.30440,787.31924,-0.13539,17.66875,42.57022
63.75200,5.31271,786.46578,-0.13539,17.70199,42.52407
63.85200,5.32097,787.24446,-0.13539,17.73499,42.56618
63.95200,5.32934,787.39058,-0.13539,17.76848,42.57408
64.05200,5.33759,787.48306,-0.13539,17.80148,42.57908
64.15200,5.34596,787.73536,-0.13539,17.83496,42.59272
64.25201,5.35439,787.43137,-0.13539,17.86868,42.57629
64.35200,5.36264,787.51640,-0.13539,17.90169,42.58088
64.45200,5.37095,787.81322,-0.13539,17.93493,42.59693
64.55200,5.37938,787.59631,-0.13539,17.96865,42.58521
64.65200,5.38769,787.94537,-0.13539,18.00189,42.60408
64.75201,5.39600,787.79282,-0.13539,18.03514,42.59583
64.85200,5.40431,788.66957,-0.13539,18.06838,42.64323
64.95200,5.41262,788.46589,-0.13539,18.10163,42.63222
65.05200,5.42093,788.52922,-0.13539,18.13487,42.63565
65.15200,5.42930,788.98389,-0.13539,18.16835,42.66023
65.25201,5.43762,788.77183,-0.13539,18.20159,42.64877
65.35200,5.44599,788.29415,-0.13539,18.23507,42.62294
65.45200,5.45430,788.80051,-0.13539,18.26832,42.65031
65.55200,5.46261,788.99637,-0.13539,18.30156,42.66090
65.65200,5.47110,789.07553,-0.13539,18.33552,42.66518
65.75201,5.47941,789.43027,-0.13539,18.36876,42.68436
65.85201,5.48766,789.39293,-0.13539,18.40177,42.68235
65.95200,5.49603,788.80377,-0.13539,18.43525,42.65049
66.05200,5.50428,789.70240,-0.13539,18.46825,42.69908
66.15200,5.51259,789.46007,-0.13539,18.50149,42.68598
66.25201,5.52102,789.26589,-0.13539,18.53522,42.67548
66.35201,5.52927,789.94576,-0.13539,18.56822,42.71224
66.45200,5.53764,789.84909,-0.13539,18.60170,42.70701
66.55200,5.54607,789.75847,-0.13539,18.63542,42.70211
66.65200,5.55432,790.33067,-0.13539,18.66843,42.73305
66.75201,5.56275,789.75111,-0.13539,18.70215,42.70171
66.85201,5.57113,789.85533,-0.13539,18.73563,42.70735
66.95200,5.57932,790.04550,-0.13539,18.76840,42.71763
67.05200,5.58769,789.93840,-0.13539,18.80188,42.71184
67.15200,5.59600,791.07760,-0.13539,18.83512,42.77344
67.25201,5.60431,790.31531,-0.13539,18.86836,42.73222
67.35201,5.61268,790.37426,-0.13538,18.90185,42.73541
67.45200,5.62099,790.13333,-0.13539,18.93509,42.72238
67.55200,5.62936,791.10377,-0.13539,18.96857,42.77485
67.65200,5.63773,790.40360,-0.13539,19.00205,42.73699
67.75201,5.64598,790.38627,-0.13539,19.03506,42.73606
67.85201,5.65429,790.69417,-0.13539,19.06830,42.75270
67.95200,5.66266,790.90837,-0.13539,19.10178,42.76429
68.05200,5.67091,791.48347,-0.13539,19.13479,42.79538
68.15200,5.67928,790.60039,-0.13539,19.16827,42.74763
68.25201,5.68766,791.23499,-0.13539,19.20175,42.78195
68.35201,5.69597,791.14074,-0.13539,19.23499,42.77685
68.45200,5.70428,790.75135,-0.13539,19.26824,42.75580
68.55200,5.71265,791.13217,-0.13539,19.30172,42.77639
68.65200,5.72096,791.75215,-0.13539,19.33496,42.80991
68.75201,5.72933,791.50116,-0.13539,19.36844,42.79634
68.85201,5.73770,791.51914,-0.13539,19.40193,42.79731
68.95200,5.74607,791.10330,-0.13539,19.43541,42.77483
69.05200,5.75438,791.49902,-0.13539,19.46865,42.79622
69.15200,5.76269,791.04854,-0.13539,19.50189,42.77187
69.25201,5.77100,791.94009,-0.13539,19.53514,42.82007
69.35201,5.77931,792.03174,-0.13539,19.56838,42.82503
69.45200,5.78762,791.79602,-0.13539,19.60162,42.81228
69.55200,5.79599,791.97288,-0.13539,19.63511,42.82184
69.65200,5.80436,792.39486,-0.13539,19.66859,42.84466
69.75201,5.81267,791.97511,-0.13539,19.70183,42.82196
69.85201,5.82099,792.05129,-0.13539,19.73507,42.82608
69.95200,5.82942,791.96282,-0.13539,19.76879,42.82130
70.05200,5.83773,792.00072,-0.13539,19.80204,42.82335
70.15200,5.84598,792.18848,-0.13539,19.83504,42.83350
70.25201,5.85441,791.96850,-0.13539,19.86876,42.82161
70.35201,5.86260,792.14107,-0.13539,19.90153,42.83094
70.45200,5.87091,792.73852,-0.13539,19.93477,42.86324
70.55200,5.87934,792.60385,-0.13539,19.96849,42.85596
70.65200,5.88759,792.46936,-0.13539,20.00149,42.84869
70.75201,5.89602,792.69679,-0.13539,20.03522,42.86098
70.85201,5.90439,792.23402,-0.13539,20.06870,42.83596
70.95200,5.91264,792.01739,-0.13539,20.10170,42.82425
71.05200,5.92101,792.94471,-0.13539,20.13518,42.87439
71.15200,5.92938,792.98168,-0.13539,20.16867,42.87639
71.25201,5.93763,792.92739,-0.13539,20.20167,42.87346
71.35201,5.94595,792.36412,-0.13539,20.23491,42.84300
71.45200,5.95432,792.59323,-0.13539,20.26839,42.85538
71.55200,5.96263,793.05302,-0.13539,20.30164,42.88025
71.65200,5.97106,793.24702,-0.13539,20.33536,42.89074
71.75201,5.97937,792.68329,-0.13539,20.36860,42.86026
71.85201,5.98762,792.59118,-0.13539,20.40160,42.85527
71.95200,5.99605,793.29889,-0.13539,20.43533,42.89354
72.05200,6.00436,793.06941,-0.13539,20.46857,42.88113
72.15200,6.01261,792.83770,-0.13539,20.50157,42.86861
72.25201,6.02116,792.91956,-0.13539,20.53577,42.87303
72.35201,6.02929,792.97218,-0.13539,20.56830,42.87588
72.45200,6.03760,793.54551,-0.13539,20.60154,42.90688
72.55200,6.04609,793.40031,-0.13539,20.63550,42.89902
72.65200,6.05422,793.43850,-0.13539,20.66803,42.90109
72.75201,6.06259,793.17531,-0.13539,20.70151,42.88686
72.85201,6.07108,793.65233,-0.13539,20.73547,42.91265
72.95200,6.07928,793.86346,-0.13539,20.76823,42.92407
73.05200,6.08765,793.46597,-0.13539,20.80172,42.90258
73.15200,6.09608,793.56162,-0.13539,20.83544,42.90775
73.25201,6.10433,793.37927,-0.13539,20.86844,42.89789
73.35201,6.11270,793.09437,-0.13539,20.90193,42.88248
73.45200,6.12101,793.69228,-0.13539,20.93517,42.91481
73.55200,6.12932,793.39640,-0.13539,20.96841,42.89882
73.65200,6.13769,793.71510,-0.13539,21.00189,42.91605
73.75201,6.14600,792.83658,-0.13539,21.03513,42.86855
73.85201,6.15425,793.73335,-0.13539,21.06814,42.91703
73.95200,6.16268,793.47314,-0.13539,21.10186,42.90296
74.05200,6.17105,793.42928,-0.13539,21.13534,42.90059
74.15200,6.17930,793.38104,-0.13539,21.16835,42.89798
74.25201,6.18779,793.75338,-0.13539,21.20230,42.91811
74.35201,6.19598,793.89056,-0.13539,21.23507,42.92553
74.45200,6.20430,793.63203,-0.13539,21.26831,42.91155
74.55200,6.21273,793.08841,-0.13539,21.30204,42.88216
74.65200,6.22098,793.21750,-0.13539,21.33504,42.88914
74.75201,6.22923,793.65717,-0.13539,21.36804,42.91291
74.85201,6.23772,793.12501,-0.13539,21.40200,42.88414
74.95200,6.24597,793.25736,-0.13539,21.43501,42.89130
75.05200,6.25428,792.81339,-0.13539,21.46825,42.86729
75.15200,6.26271,793.12548,-0.13539,21.50197,42.88417
75.25201,6.27102,793.06094,-0.13539,21.53521,42.88068
75.35201,6.27933,793.07770,-0.13539,21.56846,42.88158
75.45200,6.28764,792.70778,-0.13539,21.60170,42.86158
75.55200,6.29595,793.06606,-0.13539,21.63494,42.88095
75.65200,6.30426,793.13843,-0.13539,21.66819,42.88486
75.75201,6.31263,792.64687,-0.13539,21.70167,42.85829
75.85201,6.32094,792.71561,-0.13539,21.73491,42.86200
75.95200,6.32932,792.78825,-0.13539,21.76839,42.86593
76.05200,6.33763,792.03332,-0.13539,21.80164,42.82511
76.15200,6.34594,791.96282,-0.13539,21.83488,42.82130
76.25201,6.35437,792.69195,-0.13539,21.86860,42.86073
76.35201,6.36268,791.70745,-0.13539,21.90184,42.80749
76.45200,6.37105,791.94531,-0.13539,21.93533,42.82035
76.55200,6.37948,791.99215,-0.13539,21.96905,42.82289
76.65200,6.38767,790.96351,-0.13539,22.00181,42.76727
76.75201,6.39592,790.58530,-0.13539,22.03481,42.74682
76.85201,6.40429,790.65347,-0.13539,22.06830,42.75050
76.95200,6.41260,789.96662,-0.13539,22.10154,42.71337
77.05200,6.42097,789.52415,-0.13539,22.13502,42.68944
77.15200,6.42940,788.94384,-0.13539,22.16875,42.65807
77.25201,6.43765,787.93010,-0.13539,22.20175,42.60325
77.35201,6.44597,786.99104,-0.13539,22.23499,42.55248
77.45200,6.45445,785.83648,-0.13539,22.26895,42.49005
77.55200,6.46271,783.18184,-0.13539,22.30195,42.34652
77.65200,6.47102,779.55127,-0.13539,22.33520,42.15021
77.75201,6.47939,507.69229,-0.13539,22.36868,27.45084
77.78600,6.48226,6.19558,-0.13539,22.38016,0.33499