File: Manufatura Aditiva/Classificação Direção/Ensaios/Ensaios SLS/Tracao_OLABI_08_06_2018_SLS_ZX3.is_metal_RawData/Specimen_RawData_2.csv
Time,Extension,Load,Strain 1,Tensile strain,Tensile stress
(sec),(mm),(N),(mm/mm),(%),(MPa)
0.00000,0.00006,27.57632,0.00127,0.12661,1.41219
0.10000,0.00419,29.28941,0.00129,0.12942,1.49991
0.20000,0.01375,33.94675,0.00144,0.14414,1.73842
0.30000,0.02356,39.59481,0.00160,0.16030,2.02765
0.40000,0.03270,44.67929,0.00175,0.17536,2.28803
0.50000,0.04143,49.92220,0.00189,0.18930,2.55652
0.60000,0.04986,54.82741,0.00203,0.20324,2.80772
0.70000,0.05823,58.57431,0.00217,0.21713,2.99960
0.80000,0.06667,62.82763,0.00231,0.23081,3.21741
0.90000,0.07498,67.60179,0.00245,0.24490,3.46189
1.00000,0.08329,71.78765,0.00258,0.25817,3.67625
1.10000,0.09178,76.13836,0.00272,0.27185,3.89905
1.20000,0.10003,80.15322,0.00285,0.28535,4.10465
1.30000,0.10840,84.96523,0.00298,0.29836,4.35108
1.40000,0.11683,89.38520,0.00313,0.31279,4.57742
1.50000,0.12496,93.34507,0.00326,0.32577,4.78021
1.60000,0.13339,97.11515,0.00340,0.33965,4.97328
1.70000,0.14170,101.53921,0.00354,0.35370,5.19983
1.80000,0.14989,105.29448,0.00367,0.36666,5.39214
1.90000,0.15832,109.78139,0.00381,0.38067,5.62192
2.00000,0.16663,113.44638,0.00394,0.39390,5.80960
2.10000,0.17494,117.97399,0.00408,0.40774,6.04146
2.20000,0.18331,121.77865,0.00421,0.42139,6.23630
2.30000,0.19163,125.37433,0.00435,0.43454,6.42043
2.40000,0.19994,129.56396,0.00449,0.44857,6.63498
2.50000,0.20837,133.24248,0.00463,0.46258,6.82336
2.60000,0.21668,137.69901,0.00477,0.47661,7.05158
2.70000,0.22493,141.79510,0.00490,0.49007,7.26134
2.80000,0.23336,145.62238,0.00504,0.50394,7.45734
2.90000,0.24167,149.57449,0.00517,0.51679,7.65972
3.00000,0.24992,153.33062,0.00531,0.53069,7.85208
3.10000,0.25841,156.68314,0.00545,0.54483,8.02376
3.20000,0.26666,160.37492,0.00558,0.55840,8.21282
3.30000,0.27497,164.53828,0.00572,0.57225,8.42602
3.40000,0.28346,169.10277,0.00587,0.58651,8.65977
3.50000,0.29171,172.77508,0.00600,0.60021,8.84783
3.60000,0.30002,176.53874,0.00614,0.61393,9.04057
3.70000,0.30839,180.03923,0.00627,0.62747,9.21983
3.80000,0.31665,183.17602,0.00641,0.64060,9.38046
3.90000,0.32502,187.77148,0.00655,0.65482,9.61580
4.00000,0.33333,191.16370,0.00668,0.66837,9.78951
4.10000,0.34164,193.53145,0.00677,0.67723,9.91076
4.20000,0.34995,196.86695,0.00690,0.69036,10.08158
4.30000,0.35826,200.73203,0.00704,0.70418,10.27951
4.40000,0.36657,204.43602,0.00718,0.71807,10.46919
4.50000,0.37500,208.34371,0.00732,0.73160,10.66930
4.60000,0.38337,212.56695,0.00746,0.74570,10.88557
4.70000,0.39162,215.61338,0.00759,0.75949,11.04158
4.80000,0.39999,218.96786,0.00773,0.77323,11.21336
4.90000,0.40824,223.06221,0.00787,0.78677,11.42304
5.00000,0.41661,226.37672,0.00801,0.80072,11.59277
5.10000,0.42504,229.59355,0.00814,0.81435,11.75751
5.20000,0.43335,234.28798,0.00828,0.82795,11.99791
5.30000,0.44166,237.47431,0.00842,0.84196,12.16108
5.40000,0.45010,241.55246,0.00856,0.85638,12.36992
5.50000,0.45829,244.65239,0.00870,0.87021,12.52867
5.60000,0.46666,248.30520,0.00885,0.88476,12.71573
5.70000,0.47503,252.21866,0.00899,0.89860,12.91614
5.80000,0.48334,255.12963,0.00912,0.91202,13.06521
5.90000,0.49171,259.15815,0.00926,0.92575,13.27151
6.00000,0.50002,262.72503,0.00940,0.93986,13.45417
6.10000,0.50827,266.04352,0.00954,0.95378,13.62411
6.20000,0.51664,269.64317,0.00967,0.96746,13.80845
6.30000,0.52495,272.78608,0.00982,0.98150,13.96940
6.40000,0.53326,276.86425,0.00996,0.99580,14.17824
6.50000,0.54169,279.72234,0.01009,1.00935,14.32461
6.60000,0.55000,283.60207,0.01024,1.02369,14.52329
6.70000,0.55831,286.88912,0.01037,1.03710,14.69162
6.80000,0.56674,290.36768,0.01051,1.05112,14.86976
6.90000,0.57500,294.03351,0.01065,1.06548,15.05748
7.00000,0.58331,296.93979,0.01079,1.07904,15.20632
7.10000,0.59174,299.65520,0.01093,1.09330,15.34537
7.20000,0.59993,303.17225,0.01107,1.10685,15.52548
7.30000,0.60818,306.16301,0.01120,1.12008,15.67864
7.40000,0.61673,309.80743,0.01134,1.13428,15.86527
7.50000,0.62498,313.40823,0.01148,1.14841,16.04967
7.60000,0.63329,317.06176,0.01163,1.16261,16.23676
7.70000,0.64178,320.08158,0.01177,1.17668,16.39141
7.80000,0.64997,323.13296,0.01191,1.19091,16.54767
7.90000,0.65828,326.69927,0.01205,1.20460,16.73030
8.00000,0.66671,329.23380,0.01218,1.21835,16.86009
8.10000,0.67490,332.12882,0.01232,1.23165,17.00835
8.20000,0.68333,334.05954,0.01240,1.24017,17.10722
8.30000,0.69176,337.29938,0.01255,1.25502,17.27313
8.40000,0.70002,340.44383,0.01269,1.26946,17.43416
8.50000,0.70839,343.41419,0.01284,1.28379,17.58627
8.60000,0.71670,346.95303,0.01298,1.29829,17.76750
8.70000,0.72495,349.86048,0.01312,1.31205,17.91639
8.80000,0.73344,353.14267,0.01326,1.32594,18.08447
8.90000,0.74169,356.68828,0.01341,1.34054,18.26604
9.00000,0.75000,359.41822,0.01354,1.35420,18.40584
9.10000,0.75843,362.69599,0.01369,1.36912,18.57370
9.20000,0.76662,365.48970,0.01384,1.38358,18.71676
9.30000,0.77493,368.24662,0.01398,1.39770,18.85794
9.40000,0.78336,371.52211,0.01413,1.41278,19.02568
9.50000,0.79161,375.04949,0.01426,1.42645,19.20632
9.60000,0.79992,377.77151,0.01441,1.44088,19.34571
9.70000,0.80835,380.78215,0.01455,1.45528,19.49989
9.80000,0.81660,383.92742,0.01469,1.46925,19.66096
9.90000,0.82498,386.46618,0.01484,1.48358,19.79097
10.00000,0.83341,388.86073,0.01498,1.49820,19.91360
10.10000,0.84166,392.11414,0.01513,1.51276,20.08020
10.20000,0.84991,395.07938,0.01527,1.52707,20.23205
10.30000,0.85840,397.63907,0.01542,1.54153,20.36313
10.40000,0.86665,400.34680,0.01556,1.55602,20.50180
10.50000,0.87502,403.77742,0.01570,1.57008,20.67748
10.60000,0.88333,406.37148,0.01585,1.58469,20.81032
10.70000,0.89164,409.35897,0.01599,1.59899,20.96331
10.80000,0.90007,411.57636,0.01614,1.61370,21.07686
10.90000,0.90832,414.73443,0.01628,1.62845,21.23859
11.00000,0.91669,417.48686,0.01643,1.64287,21.37954
11.10000,0.92506,420.34439,0.01657,1.65708,21.52588
11.20000,0.93331,422.76653,0.01672,1.67187,21.64991
11.30000,0.94162,425.47509,0.01686,1.68643,21.78862
11.40000,0.95000,428.36890,0.01701,1.70130,21.93681
11.50000,0.95825,431.09269,0.01716,1.71610,22.07630
11.60000,0.96656,433.42547,0.01731,1.73096,22.19576
11.70000,0.97499,436.86032,0.01745,1.74539,22.37166
11.80000,0.98336,438.89438,0.01760,1.75998,22.47582
11.90000,0.99161,439.55739,0.01768,1.76773,22.50978
12.00000,1.00004,442.77003,0.01783,1.78332,22.67430
12.10000,1.00835,444.60609,0.01799,1.79866,22.76832
12.20000,1.01666,446.96275,0.01813,1.81329,22.88901
12.30000,1.02509,450.21353,0.01829,1.82859,23.05548
12.40000,1.03328,452.46682,0.01843,1.84313,23.17087
12.50000,1.04165,455.27681,0.01858,1.85786,23.31477
12.60000,1.05002,457.44521,0.01873,1.87267,23.42581
12.70000,1.05827,460.43014,0.01888,1.88779,23.57867
12.80000,1.06658,462.51025,0.01903,1.90273,23.68519
12.90000,1.07496,464.97234,0.01918,1.91782,23.81128
13.00000,1.08333,467.20011,0.01933,1.93295,23.92536
13.10000,1.09170,469.33400,0.01948,1.94761,24.03464
13.20000,1.10001,472.29338,0.01963,1.96280,24.18619
13.30000,1.10838,474.99402,0.01978,1.97766,24.32449
13.40000,1.11675,477.68643,0.01993,1.99315,24.46237
13.50000,1.12500,479.31708,0.02008,2.00813,24.54587
13.60000,1.13325,481.94472,0.02023,2.02330,24.68044
13.70000,1.14168,483.83931,0.02039,2.03858,24.77746
13.80000,1.14993,487.21922,0.02054,2.05419,24.95054
13.90000,1.15824,488.69047,0.02069,2.06908,25.02588
14.00000,1.16673,491.16146,0.02084,2.08418,25.15242
14.10000,1.17498,493.30923,0.02100,2.10008,25.26241
14.20000,1.18329,495.59716,0.02115,2.11517,25.37958
14.30000,1.19178,497.98558,0.02130,2.13046,25.50189
14.40000,1.19998,499.82215,0.02146,2.14623,25.59594
14.50000,1.20829,503.12597,0.02162,2.16153,25.76513
14.60000,1.21672,504.90294,0.02177,2.17701,25.85613
14.70000,1.22491,506.59762,0.02192,2.19231,25.94291
14.80000,1.23334,508.98562,0.02208,2.20820,26.06520
14.90000,1.24171,510.31765,0.02224,2.22369,26.13342
15.00000,1.24996,513.15613,0.02239,2.23926,26.27877
15.10000,1.25833,514.90758,0.02255,2.25493,26.36847
15.20000,1.26670,516.58186,0.02270,2.27018,26.45421
15.30000,1.27495,518.55566,0.02286,2.28597,26.55528
15.40000,1.28344,521.01468,0.02301,2.30144,26.68121
15.50000,1.29175,521.62870,0.02314,2.31426,26.71265
15.60000,1.29994,524.07198,0.02330,2.33003,26.83778
15.70000,1.30837,525.45061,0.02346,2.34564,26.90837
15.80000,1.31662,527.98949,0.02361,2.36117,27.03839
15.90000,1.32488,529.82513,0.02377,2.37697,27.13239
16.00000,1.33343,531.49350,0.02393,2.39312,27.21783
16.10000,1.34162,534.28663,0.02409,2.40890,27.36087
16.20000,1.34993,535.68073,0.02425,2.42497,27.43226
16.30000,1.35848,534.99164,0.02434,2.43374,27.39697
16.40000,1.36667,537.06244,0.02450,2.45050,27.50302
16.50000,1.37504,539.51959,0.02466,2.46602,27.62885
16.60000,1.38341,541.36277,0.02482,2.48220,27.72324
16.70000,1.39160,542.56110,0.02498,2.49762,27.78461
16.80000,1.39997,545.15130,0.02514,2.51365,27.91725
16.90000,1.40840,546.24253,0.02530,2.53006,27.97313
17.00000,1.41659,548.47696,0.02546,2.54622,28.08756
17.10000,1.42496,550.37816,0.02562,2.56230,28.18492
17.20000,1.43333,552.17273,0.02578,2.57841,28.27682
17.30000,1.44164,553.79448,0.02595,2.59450,28.35987
17.40000,1.45001,555.24930,0.02611,2.61065,28.43437
17.50000,1.45839,557.34147,0.02627,2.62693,28.54151
17.60000,1.46664,559.06740,0.02643,2.64321,28.62989
17.70000,1.47501,560.96767,0.02659,2.65920,28.72721
17.80000,1.48320,562.70920,0.02675,2.67515,28.81639
17.90000,1.49157,564.12588,0.02692,2.69217,28.88894
18.00000,1.50000,565.33669,0.02708,2.70789,28.95094
18.10000,1.50819,567.64316,0.02725,2.72453,29.06906
18.20000,1.51656,569.12675,0.02741,2.74091,29.14503
18.30000,1.52505,570.23801,0.02757,2.75723,29.20194
18.40000,1.53336,572.12384,0.02773,2.77335,29.29852
18.50000,1.54167,573.27510,0.02789,2.78947,29.35747
18.60000,1.55004,575.29476,0.02806,2.80613,29.46090
18.70000,1.55829,577.06819,0.02823,2.82287,29.55172
18.80000,1.56666,578.37907,0.02839,2.83934,29.61885
18.90000,1.57509,580.08842,0.02856,2.85589,29.70638
19.00000,1.58335,581.51009,0.02873,2.87250,29.77919
19.10000,1.59166,583.45953,0.02889,2.88911,29.87902
19.20000,1.60003,585.20916,0.02906,2.90575,29.96862
19.30000,1.60828,586.06062,0.02922,2.92197,30.01222
19.40000,1.61665,587.63041,0.02939,2.93900,30.09261
19.50000,1.62502,589.22200,0.02956,2.95588,30.17411
19.60000,1.63333,590.71053,0.02973,2.97263,30.25034
19.70000,1.64176,591.55016,0.02989,2.98913,30.29334
19.80000,1.65007,593.89547,0.03006,3.00566,30.41344
19.90000,1.65832,594.84555,0.03023,3.02266,30.46210
20.00000,1.66663,596.51006,0.03039,3.03933,30.54734
20.10000,1.67488,597.44786,0.03056,3.05582,30.59536
20.20000,1.68325,599.26575,0.03073,3.08931,30.68846
20.30000,1.69168,599.90152,0.03090,3.12303,30.72101
20.36200,1.69683,600.89338,0.03100,3.14359,30.77181
20.46200,1.70514,602.94727,0.03117,3.17684,30.87699
20.56200,1.71351,603.36050,0.03134,3.21032,30.89815
20.66200,1.72182,604.40754,0.03151,3.24356,30.95177
20.76200,1.73019,606.06222,0.03168,3.27704,31.03650
20.86200,1.73850,607.85417,0.03184,3.31029,31.12827
20.96200,1.74681,608.86149,0.03201,3.34353,31.17986
21.06200,1.75506,610.15515,0.03218,3.37653,31.24610
21.16200,1.76349,611.74287,0.03235,3.41026,31.32741
21.26200,1.77186,612.59624,0.03252,3.44374,31.37111
21.36200,1.78011,613.63252,0.03269,3.47674,31.42418
21.46200,1.78854,614.95099,0.03286,3.51046,31.49170
21.56200,1.79679,616.64097,0.03303,3.54347,31.57824
21.66200,1.80516,618.01178,0.03320,3.57695,31.64844
21.76200,1.81365,619.07298,0.03338,3.61091,31.70279
21.86200,1.82191,620.26386,0.03355,3.64391,31.76377
21.96200,1.83016,621.89237,0.03372,3.67692,31.84717
22.06200,1.83859,622.57745,0.03390,3.71064,31.88225
22.16200,1.84684,623.99977,0.03406,3.74364,31.95509
22.26200,1.85509,624.83153,0.03423,3.77665,31.99768
22.36200,1.86352,623.75967,0.03432,3.81037,31.94279
22.46200,1.87183,625.49883,0.03403,3.84361,32.03185
22.56200,1.88020,626.91993,0.03425,3.87709,32.10463
22.66200,1.88857,627.85200,0.03438,3.91057,32.15236
22.76200,1.89676,629.33555,0.03456,3.94334,32.22833
22.86200,1.90513,629.90896,0.03472,3.97682,32.25770
22.96200,1.91350,630.94120,0.03476,4.01030,32.31056
23.06200,1.92175,632.55099,0.03475,4.04331,32.39299
23.16200,1.93018,633.96478,0.02382,4.07703,32.46540
23.26200,1.93844,634.60353,0.01372,4.11003,32.49811
23.36200,1.94675,635.94286,0.00522,4.14327,32.56669
23.46200,1.95524,636.74133,0.00555,4.17724,32.60758
23.56200,1.96349,638.25250,0.00545,4.21024,32.68497
23.66200,1.97180,638.21189,0.00527,4.24348,32.68289
23.76200,1.98029,640.86709,0.00537,4.27744,32.81886
23.86200,1.98854,641.63143,0.00545,4.31045,32.85801
23.96200,1.99685,642.67591,0.00580,4.34369,32.91150
24.06200,2.00528,643.58274,0.00482,4.37741,32.95793
24.16200,2.01353,644.78535,0.00502,4.41041,33.01952
24.26200,2.02178,646.26276,0.00471,4.44342,33.09518
24.36200,2.03021,647.20144,0.00680,4.47714,33.14325
24.46200,2.03852,647.56428,0.00665,4.51038,33.16183
24.56200,2.04683,648.88857,0.00647,4.54362,33.22964
24.66200,2.05520,650.69911,0.00613,4.57711,33.32236
24.76200,2.06345,651.32570,0.00684,4.61011,33.35445
24.86200,2.07183,652.46429,0.00863,4.64359,33.41276
24.96200,2.08020,653.45173,0.00751,4.67707,33.46333
25.06200,2.08851,654.55637,0.00109,4.71032,33.51989
25.16200,2.09682,655.08368,-0.00692,4.74356,33.54690
25.26200,2.10507,656.23424,-0.09921,4.77656,33.60582
25.36200,2.11344,657.03643,-0.13820,4.81005,33.64690
25.46200,2.12175,658.60054,-0.13799,4.84329,33.72700
25.56200,2.13006,659.78928,-0.13795,4.87653,33.78787
25.66200,2.13843,660.31748,-0.13796,4.91002,33.81492
25.76200,2.14680,661.49370,-0.13796,4.94350,33.87516
25.86200,2.15517,662.46330,-0.13796,4.97698,33.92481
25.96200,2.16354,663.08537,-0.13796,5.01046,33.95667
26.06200,2.17191,664.10191,-0.13796,5.04394,34.00872
26.16200,2.18022,665.81671,-0.13796,5.07719,34.09654
26.26200,2.18853,665.64460,-0.13796,5.11043,34.08772
26.36200,2.19685,667.49938,-0.13797,5.14367,34.18270
26.46200,2.20516,667.68783,-0.13796,5.17692,34.19236
26.56200,2.21353,669.40426,-0.13797,5.21040,34.28025
26.66200,2.22184,669.69590,-0.13797,5.24364,34.29519
26.76200,2.23015,671.56944,-0.13796,5.27688,34.39114
26.86200,2.23852,671.51142,-0.13797,5.31037,34.38816
26.96200,2.24689,672.57578,-0.13797,5.34385,34.44267
27.06200,2.25520,673.27390,-0.13797,5.37709,34.47842
27.16200,2.26357,674.28923,-0.13797,5.41057,34.53041
27.26200,2.27182,676.03933,-0.13797,5.44358,34.62004
27.36200,2.28019,676.39644,-0.13797,5.47706,34.63832
27.46200,2.28856,677.26690,-0.13797,5.51054,34.68290
27.56200,2.29681,677.95306,-0.13797,5.54354,34.71804
27.66200,2.30518,678.78491,-0.13797,5.57703,34.76064
27.76200,2.31349,679.95633,-0.13797,5.61027,34.82063
27.86200,2.32181,680.23428,-0.13797,5.64351,34.83486
27.96200,2.33018,681.17310,-0.13797,5.67699,34.88294
28.06200,2.33855,683.12217,-0.13797,5.71048,34.98275
28.16200,2.34680,683.10825,-0.13798,5.74348,34.98204
28.26200,2.35511,683.72688,-0.13797,5.77672,35.01372
28.36200,2.36348,684.90417,-0.13797,5.81021,35.07401
28.46200,2.37179,686.25603,-0.13797,5.84345,35.14323
28.56200,2.38010,686.79117,-0.13797,5.87669,35.17064
28.66200,2.38853,687.53203,-0.13797,5.91041,35.20858
28.76200,2.39678,688.69847,-0.13797,5.94342,35.26831
28.86200,2.40515,689.15151,-0.13798,5.97690,35.29152
28.96200,2.41352,690.14109,-0.13798,6.01038,35.34219
29.06200,2.42183,690.83921,-0.13798,6.04362,35.37794
29.16200,2.43020,691.67428,-0.13798,6.07711,35.42070
29.26200,2.43851,692.37393,-0.13798,6.11035,35.45654
29.36200,2.44689,693.52277,-0.13798,6.14383,35.51537
29.46200,2.45520,694.21642,-0.13798,6.17707,35.55089
29.56200,2.46351,694.45926,-0.13798,6.21032,35.56332
29.66200,2.47182,695.20334,-0.13798,6.24356,35.60143
29.76200,2.48025,696.48675,-0.13798,6.27728,35.66715
29.86200,2.48850,697.32550,-0.13798,6.31028,35.71011
29.96200,2.49681,698.48453,-0.13798,6.34353,35.76946
30.06200,2.50518,698.77640,-0.13798,6.37701,35.78440
30.16200,2.51349,699.63108,-0.13797,6.41025,35.82817
30.26200,2.52180,700.18391,-0.13798,6.44350,35.85648
30.36200,2.53023,701.36609,-0.13798,6.47722,35.91702
30.46200,2.53854,701.59612,-0.13798,6.51046,35.92880
30.56200,2.54679,702.13964,-0.13798,6.54346,35.95664
30.66200,2.55516,703.80978,-0.13798,6.57695,36.04216
30.76200,2.56341,704.50725,-0.13798,6.60995,36.07788
30.86200,2.57179,704.74236,-0.13798,6.64343,36.08992
30.96200,2.58016,705.63597,-0.13798,6.67691,36.13568
31.06200,2.58847,703.54580,-0.13798,6.71016,36.02865
31.16200,2.59684,705.24863,-0.13798,6.74364,36.11585
31.26200,2.60515,706.02708,-0.13798,6.77688,36.15571
31.36200,2.61346,706.42787,-0.13798,6.81012,36.17624
31.46200,2.62183,707.51430,-0.13798,6.84361,36.23187
31.56200,2.63014,708.33210,-0.13798,6.87685,36.27375
31.66200,2.63857,709.07180,-0.13798,6.91057,36.31163
31.76200,2.64682,710.39069,-0.13798,6.94358,36.37917
31.86200,2.65507,711.10791,-0.13798,6.97658,36.41590
31.96200,2.66344,711.22851,-0.13798,7.01006,36.42208
32.06200,2.67181,711.93296,-0.13798,7.04354,36.45815
32.16200,2.68012,712.82974,-0.13798,7.07679,36.50408
32.26200,2.68849,713.64050,-0.13798,7.11027,36.54560
32.36200,2.69686,714.14686,-0.13798,7.14375,36.57153
32.46200,2.70518,715.64368,-0.13798,7.17699,36.64818
32.56200,2.71355,715.81979,-0.13798,7.21048,36.65720
32.66200,2.72186,716.80807,-0.13798,7.24372,36.70781
32.76200,2.73017,717.46735,-0.13798,7.27696,36.74157
32.86200,2.73848,717.80412,-0.13798,7.31020,36.75882
32.96200,2.74685,719.27472,-0.13798,7.34369,36.83413
33.06200,2.75516,719.37442,-0.13798,7.37693,36.83923
33.16200,2.76353,720.52521,-0.13798,7.41041,36.89816
33.26200,2.77184,720.86719,-0.13798,7.44366,36.91568
33.36200,2.78021,721.51511,-0.13798,7.47714,36.94886
33.46200,2.78852,721.65113,-0.13798,7.51038,36.95582
33.56200,2.79683,722.38538,-0.13798,7.54362,36.99342
33.66200,2.80520,722.66888,-0.13798,7.57710,37.00794
33.76200,2.81351,724.43066,-0.13798,7.61035,37.09816
33.86200,2.82177,724.89567,-0.13799,7.64335,37.12197
33.96200,2.83014,725.61754,-0.13798,7.67683,37.15894
34.06200,2.83845,725.89489,-0.13798,7.71008,37.17315
34.16200,2.84676,726.53848,-0.13798,7.74332,37.20610
34.26200,2.85507,727.40912,-0.13798,7.77656,37.25069
34.36200,2.86350,727.58156,-0.13798,7.81028,37.25952
34.46200,2.87187,728.46985,-0.13798,7.84376,37.30501
34.56200,2.88024,728.89673,-0.13798,7.87725,37.32687
34.66200,2.88861,729.45138,-0.13799,7.91073,37.35527
34.76200,2.89680,730.15420,-0.13798,7.94349,37.39127
34.86200,2.90517,730.62298,-0.13799,7.97698,37.41527
34.96200,2.91354,731.83980,-0.13799,8.01046,37.47758
35.06200,2.92185,732.16609,-0.13798,8.04370,37.49429
35.16200,2.93010,733.47739,-0.13798,8.07671,37.56145
35.26200,2.93853,733.28638,-0.13799,8.11043,37.55167
35.36200,2.94672,734.28419,-0.13798,8.14319,37.60276
35.46200,2.95516,734.15879,-0.13799,8.17691,37.59634
35.56200,2.96359,734.59451,-0.13799,8.21063,37.61866
35.66200,2.97184,735.50735,-0.13799,8.24364,37.66540
35.76200,2.98021,736.17152,-0.13799,8.27712,37.69941
35.86200,2.98858,736.88016,-0.13799,8.31060,37.73570
35.96200,2.99671,737.39351,-0.13798,8.34313,37.76199
36.06200,3.00520,738.47692,-0.13799,8.37709,37.81747
36.16200,3.01351,738.30918,-0.13799,8.41033,37.80888
36.26200,3.02176,738.67072,-0.13799,8.44333,37.82740
36.36200,3.03019,740.11576,-0.13798,8.47706,37.90140
36.46200,3.03844,739.98864,-0.13799,8.51006,37.89489
36.56200,3.04681,740.52517,-0.13799,8.54354,37.92236
36.66200,3.05524,741.55601,-0.13799,8.57726,37.97515
36.76200,3.06349,742.16067,-0.13799,8.61027,38.00612
36.86200,3.07180,742.39746,-0.13799,8.64351,38.01825
36.96200,3.08029,742.14484,-0.13799,8.67747,38.00531
37.06200,3.08849,743.04100,-0.13799,8.71024,38.05120
37.16200,3.09674,744.38648,-0.13799,8.74324,38.12010
37.26200,3.10523,744.16939,-0.13799,8.77720,38.10899
37.36200,3.11348,744.71934,-0.13799,8.81020,38.13715
37.46200,3.12179,745.37401,-0.13799,8.84345,38.17067
37.56200,3.13028,746.10491,-0.13799,8.87741,38.20810
37.66200,3.13841,746.40810,-0.13799,8.90993,38.22363
37.76200,3.14684,747.12895,-0.13798,8.94365,38.26054
37.86200,3.15527,747.67275,-0.13799,8.97737,38.28839
37.96200,3.16340,748.08062,-0.13799,9.00990,38.30928
38.06200,3.17183,748.58023,-0.13799,9.04362,38.33487
38.16200,3.18014,748.65771,-0.13799,9.07686,38.33883
38.26200,3.18839,749.87821,-0.13798,9.10987,38.40133
38.36200,3.19682,749.77302,-0.13799,9.14359,38.39595
38.46200,3.20514,750.96153,-0.13799,9.17683,38.45681
38.56200,3.21345,751.48451,-0.13799,9.21007,38.48359
38.66200,3.22182,751.91879,-0.13799,9.24356,38.50583
38.76200,3.23013,752.53653,-0.13799,9.27680,38.53747
38.86200,3.23844,752.69570,-0.13799,9.31004,38.54562
38.96200,3.24687,752.66417,-0.13799,9.34376,38.54400
39.06200,3.25518,753.66511,-0.13799,9.37701,38.59526
39.16200,3.26343,754.41138,-0.13798,9.41001,38.63348
39.26200,3.27186,754.20332,-0.13799,9.44373,38.62282
39.36200,3.28011,754.61715,-0.13799,9.47674,38.64402
39.46200,3.28848,756.01838,-0.13799,9.51022,38.71577
39.56200,3.29691,756.13023,-0.13799,9.54394,38.72150
39.66200,3.30510,756.19319,-0.13799,9.57670,38.72472
39.76200,3.31347,756.58597,-0.13799,9.61019,38.74484
39.86200,3.32184,757.42565,-0.13799,9.64367,38.78784
39.96200,3.33016,757.85113,-0.13799,9.67691,38.80963
40.06200,3.33859,757.75259,-0.13799,9.71063,38.80458
40.16200,3.34690,758.87120,-0.13799,9.74388,38.86187
40.26200,3.35521,759.21649,-0.13799,9.77712,38.87955
40.36200,3.36358,759.73989,-0.13799,9.81060,38.90635
40.46200,3.37183,760.13659,-0.13799,9.84360,38.92667
40.56200,3.38014,760.58153,-0.13799,9.87685,38.94945
40.66200,3.38851,760.84770,-0.13799,9.91033,38.96308
40.76200,3.39682,761.28757,-0.13799,9.94357,38.98561
40.86200,3.40519,761.79323,-0.13799,9.97706,39.01150
40.96200,3.41356,762.23831,-0.13799,10.01054,39.03429
41.06200,3.42187,762.35933,-0.13799,10.04378,39.04049
41.16200,3.43012,762.78010,-0.13799,10.07678,39.06204
41.26200,3.43849,763.79520,-0.13799,10.11027,39.11403
41.36200,3.44680,764.21164,-0.13799,10.14351,39.13535
41.46200,3.45506,764.40531,-0.13799,10.17651,39.14527
41.56200,3.46355,764.68932,-0.13799,10.21047,39.15981
41.66200,3.47180,765.45719,-0.13799,10.24348,39.19913
41.76200,3.48011,765.65463,-0.13799,10.27672,39.20925
41.86200,3.48854,766.37827,-0.13799,10.31044,39.24630
41.96200,3.49679,766.38693,-0.13799,10.34344,39.24675
42.06200,3.50516,766.70661,-0.13799,10.37693,39.26312
42.16200,3.51359,767.90084,-0.13799,10.41065,39.32428
42.26200,3.52178,767.56184,-0.13799,10.44341,39.30692
42.36200,3.53021,768.24347,-0.13799,10.47713,39.34182
42.46200,3.53858,768.81489,-0.13800,10.51062,39.37108
42.56200,3.54677,769.16865,-0.13799,10.54338,39.38920
42.66200,3.55520,769.75119,-0.13799,10.57710,39.41903
42.76200,3.56345,769.59711,-0.13799,10.61011,39.41114
42.86200,3.57176,770.42170,-0.13799,10.64335,39.45337
42.96200,3.58025,769.99348,-0.13799,10.67731,39.43144
43.06200,3.58857,771.15893,-0.13800,10.71055,39.49112
43.16200,3.59676,771.24820,-0.13799,10.74332,39.49569
43.26200,3.60525,772.23023,-0.13799,10.77728,39.54598
43.36200,3.61350,771.63936,-0.13799,10.81028,39.51572
43.46200,3.62175,772.96998,-0.13799,10.84329,39.58387
43.56200,3.63024,773.39509,-0.13799,10.87724,39.60564
43.66200,3.63837,773.46046,-0.13799,10.90977,39.60898
43.76200,3.64674,774.08087,-0.13799,10.94325,39.64075
43.86200,3.65529,774.20827,-0.13799,10.97745,39.64728
43.96200,3.66348,774.34238,-0.13799,11.01022,39.65415
44.06200,3.67179,775.81848,-0.13799,11.04346,39.72974
44.16200,3.68028,775.04115,-0.13800,11.07742,39.68993
44.26200,3.68847,775.47170,-0.13799,11.11019,39.71198
44.36200,3.69684,776.13625,-0.13799,11.14367,39.74601
44.46200,3.70527,776.40787,-0.13799,11.17739,39.75992
44.56200,3.71347,776.96554,-0.13799,11.21015,39.78848
44.66200,3.72184,776.84796,-0.13799,11.24364,39.78246
44.76200,3.73021,777.06431,-0.13799,11.27712,39.79354
44.86200,3.73846,777.90353,-0.13799,11.31012,39.83651
44.96200,3.74695,778.54069,-0.13799,11.34408,39.86914
45.06200,3.75520,779.12174,-0.13799,11.37709,39.89890
45.16200,3.76339,778.67117,-0.13799,11.40985,39.87582
45.26200,3.77194,779.20035,-0.13800,11.44405,39.90292
45.36200,3.78025,779.56249,-0.13800,11.47729,39.92147
45.46200,3.78844,780.05088,-0.13799,11.51006,39.94648
45.56200,3.79687,780.70578,-0.13799,11.54378,39.98002
45.66200,3.80512,780.49162,-0.13800,11.57678,39.96905
45.76200,3.81343,781.34919,-0.13799,11.61003,40.01297
45.86200,3.82192,781.51990,-0.13799,11.64399,40.02171
45.96200,3.83012,781.35803,-0.13799,11.67675,40.01342
46.06200,3.83843,781.56851,-0.13799,11.70999,40.02420
46.16200,3.84692,782.40288,-0.13799,11.74395,40.06693
46.26200,3.85517,783.01430,-0.13799,11.77696,40.09824
46.36200,3.86348,783.68448,-0.13799,11.81020,40.13256
46.46200,3.87191,780.06419,-0.13799,11.84392,39.94716
46.56200,3.88016,781.17535,-0.13799,11.87693,40.00406
46.66200,3.88847,781.18071,-0.13799,11.91017,40.00434
46.76200,3.89678,782.52414,-0.13799,11.94341,40.07314
46.86200,3.90509,782.89742,-0.13799,11.97665,40.09225
46.96200,3.91346,783.90026,-0.13799,12.01014,40.14361
47.06200,3.92183,783.24163,-0.13799,12.04362,40.10988
47.16200,3.93008,783.89756,-0.13799,12.07662,40.14347
47.26200,3.93851,783.97831,-0.13799,12.11034,40.14760
47.36200,3.94682,784.44062,-0.13799,12.14359,40.17128
47.46200,3.95513,784.69710,-0.13799,12.17683,40.18441
47.56200,3.96357,785.46396,-0.13799,12.21055,40.22368
47.66200,3.97182,785.73786,-0.13799,12.24355,40.23771
47.76200,3.98013,785.79895,-0.13799,12.27680,40.24084
47.86200,3.98850,786.57828,-0.13799,12.31028,40.28075
47.96200,3.99681,786.75561,-0.13800,12.34352,40.28983
48.06200,4.00512,787.69429,-0.13799,12.37677,40.33790
48.16200,4.01349,787.88660,-0.13799,12.41025,40.34775
48.26200,4.02180,788.09587,-0.13799,12.44349,40.35846
48.36200,4.03011,787.96791,-0.13800,12.47673,40.35191
48.46200,4.03854,788.26370,-0.13800,12.51045,40.36706
48.56200,4.04679,789.39339,-0.13799,12.54346,40.42491
48.66200,4.05516,789.24317,-0.13800,12.57694,40.41722
48.76200,4.06359,789.33565,-0.13799,12.61066,40.42196
48.86200,4.07178,789.42291,-0.13799,12.64343,40.42642
48.96200,4.08015,790.10725,-0.13799,12.67691,40.46147
49.06200,4.08847,790.21743,-0.13799,12.71015,40.46711
49.16200,4.09678,791.02824,-0.13799,12.74340,40.50863
49.26200,4.10515,790.93371,-0.13799,12.77688,40.50379
49.36200,4.11346,791.55089,-0.13799,12.81012,40.53540
49.46200,4.12183,792.45083,-0.13799,12.84360,40.58148
49.56200,4.13020,791.63807,-0.13799,12.87708,40.53986
49.66200,4.13851,792.20347,-0.13799,12.91033,40.56881
49.76200,4.14676,792.71942,-0.13800,12.94333,40.59524
49.86200,4.15519,792.87309,-0.13799,12.97705,40.60311
49.96200,4.16350,793.34611,-0.13800,13.01029,40.62733
50.06200,4.17175,793.36427,-0.13799,13.04330,40.62826
50.16200,4.18024,793.21647,-0.13800,13.07726,40.62069
50.26200,4.18843,794.43669,-0.13799,13.11002,40.68318
50.36200,4.19668,794.20721,-0.13799,13.14303,40.67142
50.46200,4.20523,794.62947,-0.13799,13.17723,40.69305
50.56200,4.21348,795.02529,-0.13799,13.21023,40.71332
50.66200,4.22186,795.20475,-0.13799,13.24371,40.72251
50.76200,4.23029,795.43767,-0.13800,13.27744,40.73444
50.86200,4.23848,795.33812,-0.13799,13.31020,40.72934
50.96200,4.24679,795.35106,-0.13799,13.34344,40.73000
51.06200,4.25516,795.96471,-0.13799,13.37692,40.76143
51.16200,4.26341,796.31507,-0.13799,13.40993,40.77937
51.26200,4.27190,796.70120,-0.13799,13.44389,40.79914
51.36200,4.28021,796.71536,-0.13800,13.47713,40.79987
51.46200,4.28846,797.25878,-0.13800,13.51013,40.82770
51.56200,4.29689,797.28775,-0.13799,13.54386,40.82918
51.66200,4.30514,797.57934,-0.13799,13.57686,40.84411
51.76200,4.31345,797.42428,-0.13799,13.61010,40.83617
51.86200,4.32188,798.28212,-0.13799,13.64383,40.88010
51.96200,4.33013,798.30121,-0.13799,13.67683,40.88108
52.06200,4.33845,798.89130,-0.13799,13.71007,40.91130
52.16200,4.34688,798.86550,-0.13800,13.74379,40.90998
52.26200,4.35513,799.63105,-0.13799,13.77680,40.94918
52.36200,4.36344,799.16632,-0.13799,13.81004,40.92538
52.46200,4.37193,799.71189,-0.13800,13.84400,40.95332
52.56200,4.38012,799.15123,-0.13799,13.87676,40.92461
52.66200,4.38843,800.03692,-0.13799,13.91001,40.96997
52.76200,4.39686,799.90495,-0.13799,13.94373,40.96321
52.86200,4.40517,800.45527,-0.13799,13.97697,40.99139
52.96200,4.41354,800.73848,-0.13799,14.01045,41.00589
53.06200,4.42191,801.06314,-0.13800,14.04394,41.02252
53.16200,4.43010,801.35176,-0.13800,14.07670,41.03730
53.26200,4.43847,801.42431,-0.13800,14.11018,41.04102
53.36200,4.44684,801.94734,-0.13800,14.14366,41.06780
53.46200,4.45515,801.79647,-0.13799,14.17691,41.06007
53.56200,4.46347,801.72364,-0.13799,14.21015,41.05634
53.66200,4.47178,801.91344,-0.13799,14.24339,41.06606
53.76200,4.48015,802.06245,-0.13799,14.27687,41.07369
53.86200,4.48858,802.69026,-0.13800,14.31060,41.10584
53.96200,4.49683,802.27470,-0.13799,14.34360,41.08456
54.06200,4.50514,802.85575,-0.13800,14.37684,41.11432
54.16200,4.51345,803.14633,-0.13800,14.41009,41.12920
54.26200,4.52170,803.24877,-0.13800,14.44309,41.13445
54.36200,4.53007,803.32356,-0.13799,14.47657,41.13828
54.46200,4.53850,803.65045,-0.13799,14.51029,41.15501
54.56200,4.54675,803.88999,-0.13800,14.54330,41.16728
54.66200,4.55506,804.18810,-0.13800,14.57654,41.18255
54.76200,4.56349,804.25199,-0.13799,14.61026,41.18582
54.86200,4.57180,803.84631,-0.13800,14.64351,41.16505
54.96200,4.58023,804.25795,-0.13800,14.67723,41.18613
55.06200,4.58854,805.49307,-0.13799,14.71047,41.24938
55.16200,4.59686,805.01158,-0.13799,14.74371,41.22472
55.26200,4.60517,805.03281,-0.13800,14.77696,41.22581
55.36200,4.61348,805.95911,-0.13799,14.81020,41.27324
55.46200,4.62185,805.64823,-0.13799,14.84368,41.25732
55.56200,4.63016,805.73345,-0.13799,14.87692,41.26168
55.66200,4.63847,806.48437,-0.13799,14.91017,41.30014
55.76200,4.64684,806.31804,-0.13799,14.94365,41.29162
55.86200,4.65521,806.38621,-0.13799,14.97713,41.29511
55.96200,4.66352,806.03752,-0.13800,15.01037,41.27726
56.06200,4.67189,806.74924,-0.13800,15.04386,41.31371
56.16200,4.68026,806.64763,-0.13800,15.07734,41.30850
56.26200,4.68851,807.20624,-0.13800,15.11034,41.33711
56.36200,4.69688,806.88512,-0.13800,15.14382,41.32066
56.46200,4.70519,808.02459,-0.13800,15.17707,41.37902
56.56200,4.71338,807.54803,-0.13800,15.20983,41.35461
56.66200,4.72182,807.62766,-0.13800,15.24355,41.35869
56.76200,4.73019,808.52527,-0.13799,15.27704,41.40466
56.86200,4.73844,808.35856,-0.13799,15.31004,41.39612
56.96200,4.74675,808.48979,-0.13800,15.34328,41.40284
57.06200,4.75518,808.63405,-0.13800,15.37700,41.41022
57.16200,4.76349,808.52434,-0.13800,15.41025,41.40461
57.26200,4.77186,809.11471,-0.13800,15.44373,41.43484
57.36200,4.78017,808.49808,-0.13800,15.47697,41.40326
57.46200,4.78842,809.43722,-0.13799,15.50997,41.45135
57.56200,4.79679,809.70628,-0.13799,15.54346,41.46513
57.66200,4.80510,809.37855,-0.13800,15.57670,41.44835
57.76200,4.81347,809.81860,-0.13800,15.61018,41.47089
57.86200,4.82184,809.81953,-0.13800,15.64366,41.47094
57.96200,4.83021,809.99844,-0.13800,15.67715,41.48009
58.06200,4.83852,810.29022,-0.13800,15.71039,41.49504
58.16200,4.84695,810.76296,-0.13800,15.74411,41.51925
58.26200,4.85521,810.39434,-0.13799,15.77711,41.50037
58.36200,4.86352,810.89726,-0.13800,15.81036,41.52613
58.46200,4.87195,810.95556,-0.13800,15.84408,41.52911
58.56200,4.88014,810.76752,-0.13800,15.87684,41.51948
58.66200,4.88851,811.35463,-0.13800,15.91032,41.54955
58.76200,4.89688,811.08687,-0.13800,15.94380,41.53584
58.86200,4.90513,811.44115,-0.13799,15.97681,41.55398
58.96200,4.91344,811.89666,-0.13800,16.01005,41.57730
59.06200,4.92181,811.27491,-0.13800,16.04353,41.54546
59.16200,4.93018,812.08395,-0.13800,16.07702,41.58689
59.26200,4.93849,811.97601,-0.13800,16.11026,41.58137
59.36200,4.94692,812.07035,-0.13800,16.14398,41.58620
59.46200,4.95517,812.35813,-0.13800,16.17699,41.60094
59.56200,4.96348,812.87995,-0.13800,16.21023,41.62766
59.66200,4.97180,812.62710,-0.13800,16.24347,41.61471
59.76200,4.98011,813.13038,-0.13799,16.27672,41.64048
59.86200,4.98848,812.63948,-0.13800,16.31020,41.61535
59.96200,4.99679,813.04582,-0.13800,16.34344,41.63615
60.06200,5.00516,813.53132,-0.13800,16.37692,41.66101
60.16200,5.01353,813.48112,-0.13800,16.41040,41.65844
60.26200,5.02184,813.55534,-0.13800,16.44365,41.66225
60.36200,5.03027,813.65164,-0.13800,16.47737,41.66718
60.46200,5.03858,814.25468,-0.13800,16.51061,41.69806
60.56200,5.04677,813.90524,-0.13800,16.54338,41.68016
60.66200,5.05514,813.75754,-0.13800,16.57686,41.67260
60.76200,5.06351,814.44206,-0.13800,16.61034,41.70765
60.86200,5.07182,813.85905,-0.13800,16.64358,41.67780
60.96200,5.08013,814.39624,-0.13800,16.67683,41.70531
61.06200,5.08850,815.01203,-0.13800,16.71031,41.73684
61.16200,5.09681,815.04239,-0.13800,16.74355,41.73840
61.26200,5.10518,814.45752,-0.13800,16.77703,41.70845
61.36200,5.11356,814.87428,-0.13800,16.81051,41.72979
61.46200,5.12181,815.13384,-0.13800,16.84352,41.74308
61.56200,5.13012,815.18926,-0.13800,16.87676,41.74592
61.66200,5.13849,815.76230,-0.13800,16.91024,41.77526
61.76200,5.14680,815.86186,-0.13800,16.94349,41.78036
61.86200,5.15511,815.99355,-0.13799,16.97673,41.78711
61.96200,5.16348,816.04859,-0.13799,17.01021,41.78992
62.06200,5.17185,815.52230,-0.13800,17.04369,41.76297
62.16200,5.18016,815.62670,-0.13800,17.07694,41.76832
62.26200,5.18841,815.84929,-0.13800,17.10994,41.77972
62.36200,5.19684,816.51025,-0.13800,17.14366,41.81357
62.46200,5.20515,816.44924,-0.13800,17.17690,41.81044
62.56200,5.21352,816.38796,-0.13800,17.21039,41.80730
62.66200,5.22183,816.45390,-0.13800,17.24363,41.81068
62.76200,5.23015,816.83043,-0.13800,17.27687,41.82996
62.86200,5.23846,816.76217,-0.13800,17.31012,41.82647
62.96200,5.24677,816.96650,-0.13800,17.34336,41.83693
63.06200,5.25514,817.15565,-0.13800,17.37684,41.84662
63.16200,5.26345,817.70839,-0.13800,17.41008,41.87492
63.26200,5.27182,817.62727,-0.13800,17.44357,41.87077
63.36200,5.28025,816.96659,-0.13800,17.47729,41.83694
63.46200,5.28850,817.07602,-0.13800,17.51029,41.84254
63.56200,5.29687,817.45312,-0.13800,17.54377,41.86185
63.66200,5.30524,817.50210,-0.13800,17.57726,41.86436
63.76200,5.31349,818.09293,-0.13800,17.61026,41.89462
63.86200,5.32186,818.07664,-0.13800,17.64374,41.89378
63.96200,5.33017,817.57735,-0.13800,17.67698,41.86821
64.06200,5.33842,818.25536,-0.13800,17.70999,41.90294
64.16200,5.34680,817.99543,-0.13800,17.74347,41.88962
64.26200,5.35517,818.05307,-0.13800,17.77695,41.89257
64.36200,5.36354,818.55534,-0.13800,17.81044,41.91830
64.46200,5.37179,818.28544,-0.13800,17.84344,41.90448
64.56200,5.38022,818.86612,-0.13800,17.87716,41.93421
64.66200,5.38853,818.71459,-0.13800,17.91040,41.92645
64.76200,5.39684,818.51343,-0.13800,17.94365,41.91615
64.86200,5.40515,819.03050,-0.13800,17.97689,41.94263
64.96200,5.41346,819.15306,-0.13800,18.01013,41.94891
65.06200,5.42183,819.54347,-0.13800,18.04361,41.96890
65.16200,5.43014,819.95400,-0.13800,18.07686,41.98992
65.26200,5.43845,818.77355,-0.13800,18.11010,41.92947
65.36200,5.44682,820.02487,-0.13800,18.14358,41.99355
65.46200,5.45513,819.36158,-0.13800,18.17683,41.95958
65.56201,5.46344,819.42845,-0.13800,18.21007,41.96301
65.66200,5.47193,819.72945,-0.13800,18.24403,41.97842
65.76200,5.48018,819.54813,-0.13800,18.27703,41.96914
65.86200,5.48850,820.00326,-0.13800,18.31027,41.99244
65.96201,5.49687,819.79530,-0.13800,18.34376,41.98180
66.06201,5.50512,819.59348,-0.13800,18.37676,41.97146
66.16200,5.51343,820.32178,-0.13800,18.41000,42.00875
66.26200,5.52186,820.52108,-0.13800,18.44373,42.01896
66.36200,5.53017,820.30334,-0.13800,18.47697,42.00781
66.46201,5.53848,820.17537,-0.13800,18.51021,42.00126
66.56201,5.54691,820.43111,-0.13800,18.54393,42.01435
66.66200,5.55516,820.05961,-0.13800,18.57693,41.99533
66.76200,5.56359,819.46487,-0.13800,18.61066,41.96487
66.86200,5.57190,820.54995,-0.13800,18.64390,42.02044
66.96201,5.58015,820.36275,-0.13800,18.67690,42.01085
67.06201,5.58852,821.18046,-0.13800,18.71039,42.05273
67.16200,5.59683,820.86409,-0.13800,18.74363,42.03653
67.26200,5.60515,820.77486,-0.13800,18.77687,42.03196
67.36200,5.61352,820.51465,-0.13800,18.81035,42.01863
67.46201,5.62177,821.37734,-0.13800,18.84336,42.06281
67.56201,5.63014,821.32909,-0.13800,18.87684,42.06034
67.66200,5.63857,821.15447,-0.13800,18.91056,42.05140
67.76200,5.64682,821.27051,-0.13800,18.94357,42.05734
67.86200,5.65513,821.60058,-0.13800,18.97681,42.07424
67.96201,5.66350,821.26362,-0.13800,19.01029,42.05699
68.06201,5.67175,821.97469,-0.13800,19.04329,42.09340
68.16200,5.68012,821.43759,-0.13800,19.07678,42.06590
68.26200,5.68849,821.47419,-0.13800,19.11026,42.06777
68.36200,5.69680,821.99043,-0.13800,19.14350,42.09421
68.46201,5.70511,822.06298,-0.13800,19.17674,42.09792
68.56201,5.71348,821.62712,-0.13800,19.21023,42.07560
68.66200,5.72179,822.23015,-0.13800,19.24347,42.10648
68.76200,5.73017,822.16254,-0.13800,19.27695,42.10302
68.86200,5.73854,822.14307,-0.13800,19.31043,42.10202
68.96201,5.74685,822.27839,-0.13800,19.34368,42.10896
69.06201,5.75522,822.34526,-0.13800,19.37716,42.11238
69.16200,5.76353,822.23378,-0.13800,19.41040,42.10667
69.26200,5.77178,822.59635,-0.13800,19.44340,42.12524
69.36200,5.78015,822.39863,-0.13800,19.47689,42.11511
69.46201,5.78846,822.23732,-0.13800,19.51013,42.10685
69.56201,5.79677,822.40701,-0.13800,19.54337,42.11554
69.66200,5.80520,822.15201,-0.13800,19.57709,42.10248
69.76200,5.81351,822.94596,-0.13800,19.61034,42.14314
69.86200,5.82182,822.48859,-0.13800,19.64358,42.11972
69.96201,5.83025,822.49967,-0.13800,19.67730,42.12029
70.06201,5.83850,822.73418,-0.13800,19.71031,42.13229
70.16200,5.84681,823.04087,-0.13800,19.74355,42.14800
70.26200,5.85518,822.58722,-0.13800,19.77703,42.12477
70.36201,5.86344,823.26885,-0.13800,19.81003,42.15968
70.46201,5.87175,822.96394,-0.13800,19.84328,42.14406
70.56201,5.88018,823.01199,-0.13800,19.87700,42.14652
70.66200,5.88843,823.18112,-0.13800,19.91000,42.15518
70.76200,5.89686,823.15067,-0.13800,19.94372,42.15362
70.86201,5.90517,823.25898,-0.13800,19.97697,42.15917
70.96201,5.91348,822.71304,-0.13800,20.01021,42.13121
71.06201,5.92191,823.00799,-0.13800,20.04393,42.14632
71.16200,5.93016,823.12068,-0.13800,20.07693,42.15209
71.26200,5.93847,823.23691,-0.13800,20.11018,42.15804
71.36201,5.94684,823.40119,-0.13800,20.14366,42.16645
71.46201,5.95515,823.41190,-0.13800,20.17690,42.16700
71.56201,5.96346,823.27016,-0.13800,20.21014,42.15974
71.66200,5.97189,823.36664,-0.13800,20.24387,42.16468
71.76200,5.98020,823.43491,-0.13800,20.27711,42.16818
71.86201,5.98846,823.84851,-0.13800,20.31011,42.18936
71.96201,5.99695,823.35211,-0.13800,20.34407,42.16394
72.06201,6.00520,823.87784,-0.13800,20.37708,42.19086
72.16200,6.01345,823.69493,-0.13800,20.41008,42.18150
72.26200,6.02200,823.86974,-0.13800,20.44428,42.19045
72.36201,6.03013,823.89601,-0.13800,20.47681,42.19179
72.46201,6.03838,823.93661,-0.13800,20.50981,42.19387
72.56201,6.04693,823.78210,-0.13800,20.54401,42.18596
72.66200,6.05506,824.36632,-0.13800,20.57654,42.21588
72.76200,6.06349,823.86648,-0.13800,20.61026,42.19028
72.86201,6.07186,824.44856,-0.13800,20.64374,42.22009
72.96201,6.08011,824.36241,-0.13800,20.67674,42.21568
73.06201,6.08848,824.16870,-0.13800,20.71023,42.20576
73.16200,6.09685,824.26090,-0.13800,20.74371,42.21048
73.26200,6.10516,824.59757,-0.13800,20.77695,42.22772
73.36201,6.11353,823.64399,-0.13800,20.81043,42.17889
73.46201,6.12185,824.32833,-0.13800,20.84368,42.21393
73.56201,6.13010,824.05834,-0.13800,20.87668,42.20010
73.66200,6.13853,824.49615,-0.13800,20.91040,42.22253
73.76200,6.14684,823.79151,-0.13800,20.94364,42.18644
73.86201,6.15509,825.10244,-0.13800,20.97665,42.25357
73.96201,6.16352,823.91091,-0.13800,21.01037,42.19255
74.06201,6.17183,824.52903,-0.13800,21.04361,42.22421
74.16200,6.18014,824.44418,-0.13800,21.07686,42.21986
74.26200,6.18863,824.11030,-0.13800,21.11081,42.20277
74.36201,6.19682,824.29014,-0.13800,21.14358,42.21198
74.46201,6.20507,824.28968,-0.13800,21.17658,42.21195
74.56201,6.21356,824.92130,-0.13800,21.21054,42.24430
74.66200,6.22175,824.52977,-0.13800,21.24331,42.22425
74.76200,6.23012,824.68968,-0.13800,21.27679,42.23244
74.86201,6.23856,824.06886,-0.13800,21.31051,42.20065
74.96201,6.24681,825.02356,-0.13800,21.34352,42.24953
75.06201,6.25518,824.36567,-0.13800,21.37700,42.21584
75.16200,6.26355,824.50649,-0.13800,21.41048,42.22306
75.26200,6.27186,823.82895,-0.13800,21.44372,42.18836
75.36201,6.28017,824.38756,-0.13800,21.47697,42.21696
75.46201,6.28848,824.59003,-0.13800,21.51021,42.22733
75.56201,6.29679,824.56768,-0.13800,21.54345,42.22619
75.66200,6.30510,824.75198,-0.13799,21.57669,42.23563
75.76200,6.31347,824.80526,-0.13800,21.61018,42.23835
75.86201,6.32178,824.33894,-0.13800,21.64342,42.21447
75.96201,6.33015,825.25611,-0.13800,21.67690,42.26144
76.06201,6.33846,825.03799,-0.13800,21.71014,42.25027
76.16200,6.34677,824.91804,-0.13800,21.74339,42.24413
76.26200,6.35526,824.60148,-0.13800,21.77735,42.22792
76.36201,6.36352,824.05079,-0.13800,21.81035,42.19972
76.46201,6.37189,824.74370,-0.13800,21.84383,42.23520
76.56201,6.38032,824.79697,-0.13800,21.87756,42.23793
76.66200,6.38845,824.82174,-0.13800,21.91008,42.23920
76.76200,6.39676,825.25434,-0.13800,21.94332,42.26135
76.86201,6.40519,824.63305,-0.13800,21.97704,42.22954
76.96201,6.41344,824.66882,-0.13800,22.01005,42.23137
77.06201,6.42181,824.53191,-0.13800,22.04353,42.22436
77.16200,6.43024,824.50705,-0.13800,22.07725,42.22308
77.26200,6.43849,824.34937,-0.13800,22.11026,42.21501
77.36201,6.44680,824.42435,-0.13800,22.14350,42.21885
77.46201,6.45523,824.24600,-0.13800,22.17722,42.20972
77.56201,6.46354,824.70505,-0.13800,22.21046,42.23322
77.66200,6.47185,824.46355,-0.13800,22.24371,42.22086
77.76200,6.48016,824.40292,-0.13800,22.27695,42.21775
77.86201,6.48841,824.80907,-0.13800,22.30995,42.23855
77.96201,6.49679,824.09773,-0.13800,22.34343,42.20212
78.06201,6.50516,824.13796,-0.13800,22.37692,42.20418
78.16200,6.51341,824.29172,-0.13800,22.40992,42.21206
78.26200,6.52184,824.82584,-0.13800,22.44364,42.23941
78.36201,6.53009,824.42742,-0.13800,22.47665,42.21901
78.46201,6.53840,824.76335,-0.13800,22.50989,42.23621
78.56201,6.54695,824.41606,-0.13800,22.54409,42.21843
78.66200,6.55520,824.54244,-0.13800,22.57709,42.22490
78.76200,6.56351,823.93438,-0.13800,22.61034,42.19376
78.86201,6.57194,824.38085,-0.13800,22.64406,42.21662
78.96201,6.58013,824.78216,-0.13800,22.67682,42.23717
79.06201,6.58844,824.74966,-0.13800,22.71007,42.23551
79.16200,6.59699,824.61685,-0.13800,22.74426,42.22871
79.26200,6.60512,824.25503,-0.13800,22.77679,42.21018
79.36201,6.61344,824.22169,-0.13800,22.81003,42.20847
79.46201,6.62193,824.29098,-0.13800,22.84399,42.21202
79.56201,6.63012,823.60758,-0.13800,22.87676,42.17702
79.66200,6.63849,824.14402,-0.13800,22.91024,42.20449
79.76200,6.64692,823.92870,-0.13800,22.94396,42.19347
79.86201,6.65511,824.43217,-0.13800,22.97672,42.21925
79.96201,6.66354,823.48231,-0.13800,23.01044,42.17061
80.06201,6.67191,824.17056,-0.13800,23.04393,42.20585
80.16200,6.68010,823.32250,-0.13800,23.07669,42.16242
80.26200,6.68853,823.61102,-0.13800,23.11041,42.17720
80.36201,6.69684,823.11509,-0.13800,23.14366,42.15180
80.46201,6.70509,823.85018,-0.13800,23.17666,42.18945
80.56201,6.71358,823.67091,-0.13800,23.21062,42.18026
80.66200,6.72189,822.70922,-0.13800,23.24387,42.13102
80.76200,6.73014,822.81679,-0.13800,23.27687,42.13652
80.86201,6.73857,823.06014,-0.13800,23.31059,42.14899
80.96201,6.74677,821.99592,-0.13800,23.34336,42.09449
81.06201,6.75502,823.33358,-0.13800,23.37636,42.16299
81.16200,6.76357,822.79630,-0.13800,23.41056,42.13548
81.26200,6.77182,822.88506,-0.13800,23.44356,42.14002
81.36201,6.78007,822.73912,-0.13800,23.47656,42.13255
81.46201,6.78856,822.60426,-0.13800,23.51053,42.12564
81.56201,6.79681,822.27411,-0.13800,23.54353,42.10873
81.66200,6.80518,822.49902,-0.13800,23.57701,42.12025
81.76200,6.81361,821.98633,-0.13800,23.61073,42.09400
81.86201,6.82180,822.16598,-0.13800,23.64350,42.10320
81.96201,6.83017,822.62494,-0.13800,23.67698,42.12670
82.06201,6.83854,821.87112,-0.13800,23.71046,42.08810
82.16200,6.84679,821.96919,-0.13800,23.74347,42.09312
82.26200,6.85516,821.41599,-0.13800,23.77695,42.06479
82.36201,6.86347,821.88882,-0.13800,23.81019,42.08900
82.46201,6.87179,821.44486,-0.13800,23.84343,42.06627
82.56201,6.88016,821.32202,-0.13800,23.87692,42.05998
82.66200,6.88847,820.87032,-0.13800,23.91016,42.03685
82.76200,6.89684,820.99363,-0.13800,23.94364,42.04316
82.86201,6.90527,820.71284,-0.13800,23.97736,42.02878
82.96201,6.91352,820.46352,-0.13800,24.01037,42.01601
83.06201,6.92177,820.74469,-0.13800,24.04337,42.03041
83.16200,6.93020,820.14920,-0.13800,24.07709,41.99992
83.26200,6.93845,820.11530,-0.13800,24.11010,41.99818
83.36201,6.94676,819.43590,-0.13800,24.14334,41.96339
83.46201,6.95519,819.74631,-0.13801,24.17706,41.97929
83.56201,6.96338,819.19245,-0.13800,24.20982,41.95092
83.66200,6.97181,819.41783,-0.13800,24.24354,41.96246
83.76200,6.98018,819.53555,-0.13800,24.27703,41.96849
83.86201,6.98850,818.80977,-0.13800,24.31027,41.93133
83.96201,6.99687,819.06710,-0.13800,24.34375,41.94450
84.06201,7.00524,818.77504,-0.13800,24.37724,41.92955
84.16200,7.01355,818.69559,-0.13800,24.41048,41.92548
84.26200,7.02180,818.22313,-0.13800,24.44348,41.90128
84.36201,7.03011,818.14378,-0.13800,24.47672,41.89722
84.46201,7.03848,817.43840,-0.13800,24.51021,41.86110
84.56201,7.04679,817.53368,-0.13800,24.54345,41.86598
84.66200,7.05516,817.00254,-0.13800,24.57693,41.83878
84.76200,7.06347,816.86582,-0.13800,24.61017,41.83178
84.86201,7.07196,816.54787,-0.13800,24.64413,41.81549
84.96201,7.08021,816.28133,-0.13800,24.67714,41.80185
85.06201,7.08852,815.86307,-0.13800,24.71038,41.78043
85.16200,7.09695,815.86288,-0.13800,24.74410,41.78041
85.26200,7.10514,815.48085,-0.13800,24.77687,41.76085
85.36201,7.11340,815.56421,-0.13800,24.80987,41.76512
85.46201,7.12188,814.92858,-0.13800,24.84383,41.73257
85.56201,7.13014,814.79130,-0.13800,24.87683,41.72554
85.66200,7.13845,814.45957,-0.13800,24.91008,41.70855
85.76200,7.14688,813.63088,-0.13800,24.94380,41.66611
85.86201,7.15507,814.04904,-0.13800,24.97656,41.68753
85.96201,7.16344,813.51409,-0.13800,25.01005,41.66013
86.06201,7.17193,812.79092,-0.13800,25.04401,41.62310
86.16200,7.18012,812.13778,-0.13800,25.07677,41.58965
86.26200,7.18843,812.54290,-0.13800,25.11002,41.61040
86.36201,7.19686,811.62313,-0.13800,25.14374,41.56330
86.46201,7.20505,811.26783,-0.13800,25.17650,41.54510
86.56201,7.21348,810.18154,-0.13800,25.21022,41.48947
86.66200,7.22185,809.71224,-0.13800,25.24370,41.46544
86.76200,7.23004,809.37166,-0.13800,25.27647,41.44800
86.86201,7.23847,809.06525,-0.13800,25.31019,41.43231
86.96201,7.24685,808.74069,-0.13800,25.34367,41.41569
87.06201,7.25516,808.00783,-0.13800,25.37692,41.37816
87.16200,7.26365,807.08312,-0.13800,25.41088,41.33080
87.26200,7.27184,806.72782,-0.13800,25.44364,41.31261
87.36201,7.28015,806.47692,-0.13800,25.47688,41.29976
87.46201,7.28858,805.66397,-0.13800,25.51060,41.25813
87.56201,7.29677,804.70545,-0.13800,25.54337,41.20904
87.66200,7.30508,803.63359,-0.13800,25.57661,41.15415
87.76200,7.31357,802.85724,-0.13800,25.61057,41.11440
87.86201,7.32182,801.86306,-0.13800,25.64358,41.06348
87.96201,7.33019,800.77723,-0.13800,25.67706,41.00788
88.06201,7.33856,799.73713,-0.13800,25.71054,40.95461
88.16200,7.34681,798.55118,-0.13800,25.74354,40.89388
88.26200,7.35512,797.04020,-0.13800,25.77679,40.81651
88.36201,7.36355,795.61444,-0.13800,25.81051,40.74349
88.46201,7.37181,792.79877,-0.13800,25.84351,40.59930
88.56201,7.38012,790.61296,-0.13800,25.87675,40.48737
88.66200,7.38849,788.67087,-0.13800,25.91024,40.38791
88.76200,7.39680,785.56985,-0.13800,25.94348,40.22911
88.86201,7.40517,781.18881,-0.13800,25.97696,40.00475
88.96201,7.41348,633.69158,-0.13800,26.01021,32.45140
89.00201,7.41695,6.28261,-0.13800,26.02407,0.32173