File: Manufatura Aditiva/Dados/Ensaios AMR/Ensaios/Ensaios SLS/Tracao_OLABI_06_06_2018_SLS_XY1.is_metal_RawData/Specimen_RawData_1.csv
Time,Extension,Load,Strain 1,Tensile strain,Tensile stress
(sec),(mm),(N),(mm/mm),(%),(MPa)
0.00000,0.00000,12.66817,0.00043,0.04347,0.58036
0.20000,0.01291,18.79149,0.00059,0.05948,0.86089
0.40000,0.03247,29.84486,0.00092,0.09211,1.36727
0.60000,0.04980,39.83408,0.00121,0.12123,1.82491
0.80000,0.06673,48.04604,0.00149,0.14894,2.20112
1.00000,0.08341,56.62122,0.00177,0.17685,2.59397
1.20000,0.10009,65.13013,0.00205,0.20474,2.98379
1.40000,0.11677,74.18405,0.00232,0.23221,3.39857
1.60000,0.13339,82.18118,0.00260,0.25994,3.76494
1.80000,0.14995,90.33931,0.00287,0.28722,4.13869
2.00000,0.16651,98.97551,0.00314,0.31445,4.53434
2.20000,0.18325,107.17444,0.00342,0.34246,4.90995
2.40000,0.19994,115.25297,0.00370,0.36996,5.28005
2.60000,0.21668,123.60415,0.00398,0.39775,5.66264
2.80000,0.23336,130.99705,0.00425,0.42522,6.00133
3.00000,0.24998,138.81177,0.00453,0.45300,6.35934
3.20000,0.26672,147.28684,0.00481,0.48108,6.74761
3.40000,0.28340,155.05094,0.00509,0.50886,7.10330
3.60000,0.30008,162.12030,0.00537,0.53661,7.42717
3.80000,0.31665,169.55744,0.00564,0.56422,7.76789
4.00000,0.33327,177.76976,0.00592,0.59197,8.14412
4.20000,0.34995,185.13950,0.00620,0.61951,8.48174
4.40000,0.36663,192.61927,0.00646,0.64643,8.82441
4.60000,0.38331,199.91677,0.00675,0.67451,9.15873
4.80000,0.39999,207.11129,0.00702,0.70159,9.48833
5.00000,0.41661,214.53716,0.00729,0.72934,9.82853
5.20000,0.43335,222.51362,0.00757,0.75711,10.19395
5.40000,0.45004,229.99148,0.00785,0.78520,10.53654
5.60000,0.46666,237.32297,0.00813,0.81289,10.87241
5.80000,0.48334,244.48277,0.00840,0.84036,11.20042
6.00000,0.50002,252.07105,0.00869,0.86913,11.54806
6.20000,0.51664,259.14356,0.00897,0.89670,11.87207
6.40000,0.53326,266.13772,0.00925,0.92464,12.19249
6.60000,0.55000,273.52273,0.00953,0.95264,12.53082
6.80000,0.56674,280.08898,0.00981,0.98092,12.83164
7.00000,0.58331,288.11239,0.01009,1.00915,13.19921
7.20000,0.59993,294.40913,0.01037,1.03742,13.48768
7.40000,0.61673,300.88366,0.01066,1.06552,13.78430
7.60000,0.63329,307.80463,0.01094,1.09444,14.10137
7.80000,0.64991,314.11240,0.01122,1.12248,14.39034
8.00000,0.66671,321.78450,0.01151,1.15068,14.74182
8.20000,0.68333,327.37572,0.01177,1.17703,14.99797
8.40000,0.69996,333.98916,0.01205,1.20459,15.30095
8.60000,0.71664,340.36359,0.01233,1.23258,15.59298
8.80000,0.73344,346.56732,0.01261,1.26117,15.87719
9.00000,0.75000,353.05577,0.01290,1.28965,16.17444
9.20000,0.76662,360.55525,0.01319,1.31856,16.51801
9.40000,0.78336,366.38835,0.01347,1.34701,16.78525
9.60000,0.79992,372.32069,0.01376,1.37623,17.05702
9.80000,0.81660,378.64202,0.01406,1.40580,17.34662
10.00000,0.83341,384.88994,0.01435,1.43478,17.63285
10.20000,0.84997,391.25015,0.01463,1.46331,17.92423
10.40000,0.86671,397.01085,0.01493,1.49281,18.18815
10.60000,0.88333,402.30541,0.01522,1.52195,18.43070
10.80000,0.90007,408.23990,0.01551,1.55122,18.70258
11.00000,0.91663,414.02546,0.01580,1.58014,18.96763
11.20000,0.93331,420.20543,0.01610,1.60966,19.25075
11.40000,0.95000,425.59453,0.01639,1.63914,19.49764
11.60000,0.96656,431.71379,0.01669,1.66930,19.77798
11.80000,0.98330,437.05301,0.01699,1.69910,20.02259
12.00000,1.00004,442.72249,0.01729,1.72877,20.28232
12.20000,1.01666,448.43070,0.01759,1.75854,20.54383
12.40000,1.03328,453.59153,0.01787,1.78667,20.78026
12.60000,1.04996,458.23618,0.01815,1.81460,20.99304
12.80000,1.06664,463.35310,0.01845,1.84479,21.22746
13.00000,1.08333,468.77395,0.01875,1.87487,21.47581
13.20000,1.10001,473.45762,0.01905,1.90534,21.69038
13.40000,1.11675,478.86302,0.01936,1.93644,21.93802
13.60000,1.13325,484.38050,0.01966,1.96627,22.19079
13.80000,1.14993,488.82132,0.01998,1.99771,22.39423
14.00000,1.16673,493.24175,0.02028,2.02829,22.59674
14.20000,1.18329,498.30079,0.02059,2.05923,22.82851
14.40000,1.19998,502.80862,0.02090,2.09009,23.03503
14.60000,1.21672,508.08354,0.02121,2.12150,23.27669
14.80000,1.23334,511.69335,0.02153,2.15279,23.44206
15.00000,1.24996,516.50158,0.02184,2.18447,23.66234
15.20000,1.26664,521.01403,0.02216,2.21596,23.86907
15.40000,1.28344,525.49886,0.02248,2.24786,24.07453
15.60000,1.29994,529.40706,0.02279,2.27914,24.25358
15.80000,1.31656,533.54241,0.02311,2.31095,24.44303
16.00000,1.33343,537.84186,0.02344,2.34367,24.64000
16.20000,1.34993,541.65912,0.02375,2.37537,24.81488
16.40000,1.36667,545.49635,0.02408,2.40811,24.99067
16.60000,1.38341,549.17433,0.02441,2.44062,25.15917
16.80000,1.39997,553.23006,0.02473,2.47287,25.34497
17.00000,1.41659,556.34030,0.02502,2.50240,25.48746
17.20000,1.43333,559.44957,0.02534,2.53382,25.62991
17.40000,1.45001,562.90422,0.02566,2.56627,25.78817
17.60000,1.46664,566.57353,0.02599,2.59888,25.95627
17.80000,1.48326,570.45761,0.02632,2.63151,26.13421
18.00000,1.50006,573.28958,0.02665,2.66495,26.26395
18.20000,1.51656,577.38475,0.02698,2.69755,26.45156
18.40000,1.53330,580.50393,0.02731,2.73111,26.59446
18.60000,1.55004,583.93381,0.02765,2.76473,26.75159
18.80000,1.56666,587.53323,0.02797,2.79742,26.91649
19.00000,1.58341,590.09828,0.02831,2.83129,27.03401
19.20000,1.60003,593.15911,0.02865,2.86499,27.17423
19.40000,1.61665,596.41874,0.02898,2.89813,27.32356
19.60000,1.63333,599.09658,0.02932,2.93228,27.44624
19.80000,1.65001,602.80324,0.02966,2.96627,27.61605
20.00000,1.66663,605.66049,0.03001,3.00085,27.74695
20.20000,1.68325,608.52743,0.03035,3.03492,27.87830
20.40000,1.69993,610.75087,0.03068,3.06837,27.98016
20.60000,1.71668,613.86102,0.03103,3.11929,28.12264
20.77000,1.73085,617.04903,0.03132,3.17597,28.26869
20.97000,1.74741,619.48653,0.03166,3.24222,28.38036
21.17000,1.76421,622.05349,0.03201,3.30942,28.49796
21.37000,1.78077,625.41408,0.03235,3.37567,28.65192
21.57000,1.79745,627.66382,0.03270,3.44239,28.75499
21.77000,1.81431,629.98808,0.03305,3.50983,28.86147
21.97000,1.83087,633.29879,0.03339,3.57608,29.01314
22.17000,1.84744,635.13936,0.03375,3.64233,29.09746
22.37000,1.86418,638.13529,0.03410,3.70929,29.23471
22.57000,1.88086,640.15756,0.03445,3.77602,29.32736
22.77000,1.89748,642.57598,0.03480,3.84250,29.43815
22.97000,1.91416,645.42806,0.03527,3.90923,29.56881
23.17000,1.93084,647.91893,0.03513,3.97595,29.68293
23.37000,1.94746,649.30632,0.03257,4.04244,29.74649
23.57000,1.96420,651.08240,0.01350,4.10940,29.82785
23.77000,1.98095,653.10826,0.01271,4.17637,29.92066
23.97000,1.99751,654.78580,0.00842,4.24261,29.99752
24.17000,2.01419,657.08761,0.01013,4.30934,30.10297
24.37000,2.03087,659.29606,0.01033,4.37606,30.20414
24.57000,2.04755,661.59936,0.00846,4.44279,30.30966
24.77000,2.06411,663.52095,-0.02213,4.50904,30.39770
24.97000,2.08079,666.51325,-0.13770,4.57576,30.53478
25.17000,2.09748,668.32900,-0.13697,4.64248,30.61797
25.37000,2.11410,670.38853,-0.13697,4.70897,30.71232
25.57000,2.13078,673.19004,-0.13698,4.77570,30.84067
25.77000,2.14752,674.73650,-0.13698,4.84266,30.91151
25.97000,2.16420,676.52985,-0.13699,4.90939,30.99367
26.17000,2.18088,679.25383,-0.13699,4.97611,31.11846
26.37000,2.19750,680.67880,-0.13699,5.04260,31.18375
26.57000,2.21418,682.67295,-0.13699,5.10932,31.27510
26.77000,2.23087,684.45452,-0.13699,5.17605,31.35672
26.97000,2.24749,687.00919,-0.13700,5.24253,31.47376
27.17000,2.26423,689.32981,-0.13700,5.30950,31.58007
27.37000,2.28085,690.62146,-0.13700,5.37598,31.63925
27.57000,2.29747,692.51521,-0.13700,5.44247,31.72600
27.77000,2.31415,695.05759,-0.13700,5.50919,31.84248
27.97000,2.33083,696.87688,-0.13700,5.57592,31.92582
28.17000,2.34745,699.01440,-0.13700,5.64240,32.02375
28.37000,2.36414,700.06549,-0.13700,5.70913,32.07190
28.57000,2.38082,701.78085,-0.13700,5.77585,32.15049
28.77000,2.39750,703.81332,-0.13700,5.84258,32.24360
28.97000,2.41412,705.61431,-0.13701,5.90907,32.32611
29.17000,2.43086,707.32571,-0.13700,5.97603,32.40451
29.37000,2.44748,709.50808,-0.13701,6.04252,32.50449
29.57000,2.46416,711.04178,-0.13701,6.10924,32.57476
29.77000,2.48091,713.02145,-0.13701,6.17620,32.66545
29.97000,2.49747,714.42476,-0.13701,6.24245,32.72974
30.17000,2.51415,716.33635,-0.13701,6.30918,32.81731
30.37000,2.53089,717.62144,-0.13701,6.37614,32.87619
30.57000,2.54751,718.93977,-0.13701,6.44263,32.93658
30.77000,2.56407,721.20237,-0.13701,6.50887,33.04024
30.97000,2.58081,722.49216,-0.13701,6.57584,33.09933
31.17000,2.59749,724.22782,-0.13701,6.64256,33.17884
31.37000,2.61412,725.79356,-0.13701,6.70905,33.25058
31.57000,2.63080,727.03762,-0.13701,6.77577,33.30757
31.77000,2.64754,729.46879,-0.13701,6.84274,33.41895
31.97000,2.66410,730.29813,-0.13701,6.90898,33.45694
32.17000,2.68084,731.82555,-0.13701,6.97595,33.52692
32.37000,2.69752,733.06682,-0.13701,7.04267,33.58378
32.57000,2.71420,735.25817,-0.13701,7.10940,33.68417
32.77000,2.73083,735.19568,-0.13701,7.17589,33.68131
32.97000,2.74751,736.54694,-0.13702,7.24261,33.74322
33.17000,2.76419,738.54574,-0.13701,7.30934,33.83479
33.37000,2.78087,739.16879,-0.13701,7.37606,33.86333
33.57000,2.79749,741.39079,-0.13701,7.44255,33.96513
33.77000,2.81417,742.10912,-0.13701,7.50927,33.99804
33.97000,2.83079,744.25004,-0.13701,7.57576,34.09612
34.17000,2.84747,745.63273,-0.13701,7.64248,34.15946
34.37000,2.86422,746.47483,-0.13702,7.70945,34.19804
34.57000,2.88090,747.84821,-0.13701,7.77617,34.26096
34.77000,2.89752,748.91569,-0.13701,7.84266,34.30986
34.97000,2.91426,750.85815,-0.13702,7.90962,34.39885
35.17000,2.93082,752.77328,-0.13701,7.97587,34.48659
35.37000,2.94738,753.35675,-0.13701,8.04212,34.51332
35.57000,2.96424,755.19178,-0.13701,8.10956,34.59739
35.77000,2.98092,756.45330,-0.13701,8.17628,34.65518
35.97000,2.99743,757.33145,-0.13701,8.24229,34.69541
36.17000,3.01411,758.46128,-0.13701,8.30902,34.74717
36.37000,3.03085,760.17682,-0.13702,8.37598,34.82577
36.57000,3.04741,761.50792,-0.13702,8.44223,34.88675
36.77000,3.06415,762.56245,-0.13702,8.50919,34.93506
36.97000,3.08095,763.34430,-0.13702,8.57639,34.97088
37.17000,3.09745,765.09127,-0.13702,8.64240,35.05091
37.37000,3.11414,766.65957,-0.13702,8.70913,35.12276
37.57000,3.13094,767.50698,-0.13702,8.77633,35.16158
37.77000,3.14756,768.36292,-0.13702,8.84282,35.20079
37.97000,3.16412,769.39221,-0.13701,8.90906,35.24795
38.17000,3.18080,770.28139,-0.13702,8.97579,35.28868
38.37000,3.19748,771.54846,-0.13702,9.04251,35.34673
38.57000,3.21410,773.42037,-0.13702,9.10900,35.43249
38.77000,3.23078,773.81716,-0.13702,9.17572,35.45067
38.97000,3.24753,775.41936,-0.13702,9.24269,35.52407
39.17000,3.26415,776.34370,-0.13702,9.30917,35.56641
39.37000,3.28083,777.48187,-0.13702,9.37590,35.61856
39.57000,3.29751,778.98381,-0.13702,9.44262,35.68737
39.77000,3.31413,779.82340,-0.13702,9.50911,35.72583
39.97000,3.33081,780.60455,-0.13702,9.57583,35.76162
40.17000,3.34755,782.00363,-0.13702,9.64280,35.82571
40.37000,3.36424,782.62752,-0.13702,9.70953,35.85429
40.57000,3.38080,783.08014,-0.13702,9.77577,35.87503
40.77000,3.39748,784.78185,-0.13702,9.84250,35.95299
40.97000,3.41428,785.49553,-0.13702,9.90970,35.98568
41.17000,3.43084,787.23198,-0.13702,9.97595,36.06524
41.37000,3.44740,787.76311,-0.13702,10.04219,36.08957
41.57000,3.46414,788.52260,-0.13702,10.10916,36.12436
41.77000,3.48082,789.41938,-0.13702,10.17588,36.16545
41.97000,3.49751,790.22879,-0.13702,10.24261,36.20253
42.17000,3.51425,791.51271,-0.13702,10.30957,36.26135
42.37000,3.53093,792.45316,-0.13702,10.37630,36.30443
42.57000,3.54743,793.39603,-0.13702,10.44230,36.34763
42.77000,3.56411,794.08903,-0.13702,10.50903,36.37938
42.97000,3.58097,795.00135,-0.13702,10.57647,36.42117
43.17000,3.59747,795.80359,-0.13702,10.64248,36.45792
43.37000,3.61410,796.92118,-0.13702,10.70897,36.50912
43.57000,3.63090,797.77110,-0.13702,10.77617,36.54806
43.77000,3.64746,798.98685,-0.13702,10.84242,36.60376
43.97000,3.66408,799.30769,-0.13702,10.90890,36.61846
44.17000,3.68094,799.97918,-0.13702,10.97635,36.64922
44.37000,3.69756,801.12312,-0.13702,11.04283,36.70163
44.57000,3.71412,801.63572,-0.13702,11.10908,36.72511
44.77000,3.73080,802.56788,-0.13702,11.17580,36.76781
44.97000,3.74761,803.56160,-0.13702,11.24301,36.81334
45.17000,3.76405,804.63337,-0.13702,11.30877,36.86244
45.37000,3.78079,805.14401,-0.13702,11.37574,36.88583
45.57000,3.79759,805.90313,-0.13702,11.44294,36.92061
45.77000,3.81415,806.68395,-0.13702,11.50919,36.95638
45.97000,3.83077,807.62692,-0.13702,11.57567,36.99958
46.17000,3.84757,808.55992,-0.13702,11.64288,37.04233
46.37000,3.86419,808.76797,-0.13702,11.70936,37.05186
46.57000,3.88088,809.56202,-0.13702,11.77609,37.08824
46.77000,3.89744,810.63285,-0.13702,11.84234,37.13729
46.97000,3.91418,811.19351,-0.13702,11.90930,37.16298
47.17000,3.93080,811.87589,-0.13702,11.97579,37.19424
47.37000,3.94748,812.56134,-0.13702,12.04251,37.22564
47.57000,3.96422,813.52778,-0.13703,12.10947,37.26992
47.77000,3.98072,814.52122,-0.13702,12.17548,37.31543
47.97000,3.99747,814.83759,-0.13702,12.24245,37.32993
48.17000,4.01421,815.49250,-0.13702,12.30941,37.35993
48.37000,4.03083,816.15010,-0.13703,12.37590,37.39005
48.57000,4.04751,816.54172,-0.13702,12.44262,37.40800
48.77000,4.06419,817.37591,-0.13703,12.50935,37.44621
48.97000,4.08081,818.28889,-0.13702,12.57583,37.48804
49.17000,4.09743,817.90881,-0.13702,12.64232,37.47063
49.37000,4.11411,818.74132,-0.13702,12.70904,37.50877
49.57000,4.13092,819.32154,-0.13702,12.77625,37.53535
49.77000,4.14748,820.06082,-0.13703,12.84249,37.56921
49.97000,4.16410,820.62175,-0.13702,12.90898,37.59491
50.17000,4.18090,821.36514,-0.13702,12.97618,37.62897
50.37000,4.19746,821.68309,-0.13703,13.04243,37.64354
50.57000,4.21420,823.04571,-0.13703,13.10939,37.70596
50.77000,4.23094,823.63281,-0.13703,13.17636,37.73286
50.97000,4.24751,824.16730,-0.13702,13.24261,37.75734
51.17000,4.26407,825.39413,-0.13702,13.30885,37.81355
51.37000,4.28087,825.59409,-0.13702,13.37605,37.82271
51.57000,4.29755,826.25682,-0.13702,13.44278,37.85307
51.77000,4.31411,826.74520,-0.13703,13.50903,37.87545
51.97000,4.33079,827.66488,-0.13702,13.57575,37.91758
52.17000,4.34759,828.39867,-0.13702,13.64295,37.95119
52.37000,4.36415,828.54433,-0.13702,13.70920,37.95787
52.57000,4.38078,829.45134,-0.13702,13.77569,37.99942
52.77000,4.39752,830.11035,-0.13703,13.84265,38.02961
52.97000,4.41420,830.59520,-0.13703,13.90938,38.05182
53.17000,4.43082,830.78742,-0.13702,13.97586,38.06063
53.37000,4.44750,831.28987,-0.13703,14.04259,38.08365
53.57000,4.46418,832.08820,-0.13702,14.10931,38.12022
53.77000,4.48086,832.23842,-0.13703,14.17604,38.12710
53.97000,4.49749,833.50167,-0.13703,14.24253,38.18497
54.17000,4.51411,833.83312,-0.13703,14.30901,38.20016
54.37000,4.53073,834.53394,-0.13703,14.37550,38.23227
54.57000,4.54747,834.79481,-0.13703,14.44246,38.24422
54.77000,4.56415,835.13511,-0.13703,14.50919,38.25981
54.97000,4.58089,835.88297,-0.13703,14.57615,38.29407
55.17000,4.59757,836.34602,-0.13703,14.64287,38.31528
55.37000,4.61413,836.95091,-0.13703,14.70912,38.34299
55.57000,4.63082,837.57676,-0.13703,14.77585,38.37167
55.77000,4.64750,837.68163,-0.13703,14.84257,38.37647
55.97000,4.66424,838.57011,-0.13703,14.90954,38.41718
56.17000,4.68092,838.51423,-0.13703,14.97626,38.41462
56.37000,4.69748,839.21440,-0.13703,15.04251,38.44669
56.57000,4.71404,840.16686,-0.13703,15.10876,38.49033
56.77000,4.73084,840.47383,-0.13703,15.17596,38.50439
56.97000,4.74752,841.41772,-0.13702,15.24268,38.54763
57.17000,4.76415,840.76999,-0.13703,15.30917,38.51796
57.37000,4.78083,841.45078,-0.13703,15.37590,38.54915
57.57000,4.79745,841.67952,-0.13702,15.44238,38.55963
57.77000,4.81419,842.58476,-0.13703,15.50934,38.60110
57.97000,4.83087,842.73629,-0.13703,15.57607,38.60804
58.17000,4.84761,843.15157,-0.13703,15.64303,38.62706
58.37000,4.86417,843.63371,-0.13703,15.70928,38.64915
58.57000,4.88080,844.29597,-0.13703,15.77577,38.67949
58.77000,4.89754,844.59325,-0.13703,15.84273,38.69311
58.97000,4.91410,845.62358,-0.13703,15.90898,38.74031
59.17000,4.93078,844.86259,-0.13703,15.97570,38.70545
59.37000,4.94752,845.01421,-0.13703,16.04267,38.71240
59.57000,4.96414,845.81953,-0.13703,16.10915,38.74929
59.77000,4.98076,846.72282,-0.13703,16.17564,38.79067
59.97000,4.99750,846.44556,-0.13703,16.24260,38.77797
60.17000,5.01419,847.42187,-0.13703,16.30933,38.82270
60.37000,5.03087,847.44599,-0.13703,16.37605,38.82380
60.57000,5.04749,848.16674,-0.13703,16.44254,38.85682
60.77000,5.06417,848.04399,-0.13703,16.50926,38.85120
60.97000,5.08079,848.40311,-0.13703,16.57575,38.86765
61.17000,5.09747,848.33940,-0.13703,16.64247,38.86473
61.37000,5.11421,849.30863,-0.13703,16.70944,38.90914
61.57000,5.13084,849.05261,-0.13703,16.77593,38.89741
61.77000,5.14746,849.53085,-0.13703,16.84241,38.91932
61.97000,5.16420,850.13155,-0.13703,16.90937,38.94684
62.17000,5.18082,850.57449,-0.13703,16.97586,38.96713
62.37000,5.19750,851.08746,-0.13703,17.04258,38.99063
62.57000,5.21412,850.44187,-0.13703,17.10907,38.96105
62.77000,5.23080,851.10664,-0.13703,17.17580,38.99151
62.97000,5.24748,852.03815,-0.13703,17.24252,39.03418
63.17000,5.26411,851.69217,-0.13703,17.30901,39.01833
63.37000,5.28091,852.14218,-0.13703,17.37621,39.03895
63.57000,5.29753,852.36346,-0.13703,17.44270,39.04909
63.77000,5.31421,852.29259,-0.13703,17.50942,39.04584
63.97000,5.33077,852.92151,-0.13703,17.57567,39.07465
64.17000,5.34751,853.49036,-0.13703,17.64263,39.10071
64.37000,5.36419,853.66247,-0.13703,17.70936,39.10860
64.57000,5.38081,854.20143,-0.13703,17.77584,39.13329
64.77000,5.39750,854.13624,-0.13703,17.84257,39.13030
64.97000,5.41412,854.45810,-0.13703,17.90906,39.14505
65.17000,5.43074,854.33610,-0.13703,17.97554,39.13946
65.37000,5.44754,855.28223,-0.13703,18.04274,39.18280
65.57000,5.46410,855.18500,-0.13703,18.10899,39.17835
65.77001,5.48084,855.41923,-0.13703,18.17596,39.18908
65.97000,5.49758,855.12595,-0.13703,18.24292,39.17564
66.17001,5.51415,856.14426,-0.13703,18.30917,39.22229
66.37000,5.53083,856.38193,-0.13703,18.37589,39.23318
66.57000,5.54751,855.80982,-0.13703,18.44262,39.20697
66.77001,5.56425,856.72457,-0.13703,18.50958,39.24888
66.97000,5.58081,856.35474,-0.13703,18.57583,39.23194
67.17001,5.59749,856.05718,-0.13703,18.64255,39.21831
67.37000,5.61417,856.54026,-0.13703,18.70928,39.24044
67.57000,5.63079,857.29854,-0.13703,18.77576,39.27518
67.77001,5.64748,857.64332,-0.13703,18.84249,39.29097
67.97000,5.66416,857.17011,-0.13703,18.90922,39.26929
68.17001,5.68078,857.38655,-0.13703,18.97570,39.27921
68.37000,5.69752,858.15890,-0.13703,19.04266,39.31459
68.57000,5.71414,858.15070,-0.13703,19.10915,39.31422
68.77001,5.73082,857.83424,-0.13703,19.17587,39.29972
68.97000,5.74750,857.98176,-0.13703,19.24260,39.30648
69.17001,5.76419,859.07029,-0.13703,19.30933,39.35635
69.37000,5.78087,858.81436,-0.13703,19.37605,39.34462
69.57000,5.79743,858.80300,-0.13703,19.44230,39.34410
69.77001,5.81417,859.02866,-0.13703,19.50926,39.35444
69.97000,5.83091,858.99644,-0.13703,19.57623,39.35296
70.17001,5.84747,859.38936,-0.13703,19.64247,39.37096
70.37000,5.86409,859.42168,-0.13703,19.70896,39.37244
70.57000,5.88077,859.53372,-0.13703,19.77568,39.37757
70.77001,5.89752,860.20604,-0.13703,19.84265,39.40837
70.97000,5.91420,860.10192,-0.13703,19.90937,39.40361
71.17001,5.93082,859.89349,-0.13703,19.97586,39.39406
71.37000,5.94756,860.14550,-0.13703,20.04282,39.40560
71.57000,5.96412,860.67980,-0.13703,20.10907,39.43008
71.77001,5.98080,860.13936,-0.13703,20.17579,39.40532
71.97000,5.99760,860.30234,-0.13703,20.24300,39.41279
72.17001,6.01417,860.84828,-0.13703,20.30925,39.43780
72.37000,6.03079,860.72972,-0.13703,20.37573,39.43237
72.57000,6.04753,860.72590,-0.13703,20.44269,39.43219
72.77001,6.06415,861.56074,-0.13703,20.50918,39.47044
72.97000,6.08077,860.77480,-0.13703,20.57567,39.43443
73.17001,6.09751,860.85238,-0.13703,20.64263,39.43799
73.37000,6.11425,862.05015,-0.13703,20.70960,39.49286
73.57000,6.13075,861.66160,-0.13703,20.77560,39.47506
73.77001,6.14744,862.08265,-0.13703,20.84233,39.49435
73.97000,6.16418,862.11786,-0.13703,20.90929,39.49596
74.17001,6.18086,861.61792,-0.13703,20.97602,39.47306
74.37000,6.19748,861.80978,-0.13703,21.04250,39.48185
74.57001,6.21422,862.31418,-0.13703,21.10947,39.50496
74.77001,6.23078,862.32787,-0.13703,21.17572,39.50558
74.97000,6.24740,862.16591,-0.13703,21.24220,39.49817
75.17001,6.26420,862.18147,-0.13703,21.30940,39.49887
75.37000,6.28089,862.22338,-0.13703,21.37613,39.50080
75.57001,6.29745,862.42817,-0.13703,21.44237,39.51018
75.77001,6.31407,862.28419,-0.13703,21.50886,39.50358
75.97000,6.33081,862.76168,-0.13703,21.57582,39.52546
76.17001,6.34743,862.36969,-0.13703,21.64231,39.50750
76.37000,6.36423,863.10729,-0.13703,21.70951,39.54129
76.57001,6.38091,862.67227,-0.13703,21.77624,39.52136
76.77001,6.39742,863.34320,-0.13703,21.84225,39.55210
76.97000,6.41410,862.79437,-0.13703,21.90897,39.52695
77.17001,6.43090,863.15516,-0.13703,21.97617,39.54348
77.37000,6.44752,862.96340,-0.13703,22.04266,39.53470
77.57001,6.46420,862.53081,-0.13703,22.10939,39.51488
77.77001,6.48082,862.98408,-0.13703,22.17587,39.53564
77.97000,6.49750,863.11735,-0.13703,22.24260,39.54175
78.17001,6.51407,863.30473,-0.13703,22.30885,39.55033
78.37000,6.53075,863.17156,-0.13703,22.37557,39.54424
78.57001,6.54767,862.77770,-0.13703,22.44325,39.52619
78.77001,6.56423,862.85351,-0.13703,22.50950,39.52966
78.97000,6.58079,863.29207,-0.13703,22.57575,39.54976
79.17001,6.59759,863.12555,-0.13703,22.64295,39.54213
79.37000,6.61415,863.26478,-0.13703,22.70920,39.54850
79.57001,6.63077,863.56448,-0.13703,22.77568,39.56224
79.77001,6.64764,863.63843,-0.13703,22.84312,39.56562
79.97000,6.66426,863.12722,-0.13703,22.90961,39.54220
80.17001,6.68076,863.95964,-0.13703,22.97562,39.58034
80.37000,6.69744,863.07190,-0.13703,23.04234,39.53967
80.57001,6.71430,863.61105,-0.13703,23.10978,39.56437
80.77001,6.73080,863.19698,-0.13703,23.17579,39.54540
80.97000,6.74742,863.59708,-0.13703,23.24228,39.56373
81.17001,6.76422,863.64662,-0.13703,23.30948,39.56600
81.37000,6.78079,863.73864,-0.13703,23.37573,39.57021
81.57001,6.79747,863.67875,-0.13703,23.44245,39.56747
81.77001,6.81427,863.85626,-0.13703,23.50966,39.57560
81.97000,6.83083,863.62334,-0.13703,23.57590,39.56493
82.17001,6.84739,863.75615,-0.13703,23.64215,39.57102
82.37000,6.86413,862.99358,-0.13703,23.70912,39.53608
82.57001,6.88087,863.89678,-0.13703,23.77608,39.57746
82.77001,6.89749,863.36564,-0.13703,23.84256,39.55313
82.97000,6.91418,863.42804,-0.13703,23.90929,39.55598
83.17001,6.93086,863.14585,-0.13703,23.97602,39.54306
83.37000,6.94742,863.15786,-0.13703,24.04226,39.54361
83.57001,6.96410,863.92341,-0.13703,24.10899,39.57868
83.77001,6.98084,863.16401,-0.13703,24.17595,39.54389
83.97000,6.99752,862.84690,-0.13703,24.24268,39.52936
84.17001,7.01414,863.10441,-0.13703,24.30916,39.54116
84.37000,7.03077,862.85016,-0.13703,24.37565,39.52951
84.57001,7.04751,863.03772,-0.13703,24.44261,39.53811
84.77001,7.06413,863.06464,-0.13703,24.50910,39.53934
84.97000,7.08087,863.18525,-0.13703,24.57606,39.54486
85.17001,7.09761,863.21430,-0.13703,24.64303,39.54619
85.37000,7.11411,862.99460,-0.13703,24.70903,39.53613
85.57001,7.13079,863.20760,-0.13703,24.77576,39.54589
85.77001,7.14754,863.34189,-0.13703,24.84273,39.55204
85.97000,7.16416,862.28279,-0.13703,24.90921,39.50352
86.17001,7.18084,862.93733,-0.13703,24.97593,39.53350
86.37000,7.19746,863.25547,-0.13703,25.04242,39.54808
86.57001,7.21420,862.60485,-0.13703,25.10938,39.51827
86.77001,7.23076,863.20657,-0.13703,25.17563,39.54584
86.97000,7.24750,863.25044,-0.13703,25.24260,39.54785
87.17001,7.26430,862.66175,-0.13704,25.30980,39.52088
87.37000,7.28081,862.41346,-0.13703,25.37580,39.50950
87.57001,7.29749,862.69882,-0.13703,25.44253,39.52258
87.77001,7.31423,862.49514,-0.13703,25.50950,39.51324
87.97000,7.33085,861.58961,-0.13703,25.57598,39.47176
88.17001,7.34741,863.28126,-0.13703,25.64223,39.54926
88.37000,7.36415,862.46012,-0.13703,25.70919,39.51164
88.57001,7.38077,862.24740,-0.13703,25.77568,39.50190
88.77001,7.39746,862.45229,-0.13703,25.84240,39.51128
88.97000,7.41414,862.19357,-0.13703,25.90913,39.49943
89.17001,7.43088,862.27152,-0.13703,25.97609,39.50300
89.37000,7.44750,861.68684,-0.13703,26.04258,39.47622
89.57001,7.46418,862.21322,-0.13703,26.10931,39.50033
89.77001,7.48086,862.39986,-0.13703,26.17603,39.50888
89.97000,7.49748,861.55701,-0.13703,26.24252,39.47027
90.17001,7.51422,861.39096,-0.13703,26.30948,39.46266
90.37000,7.53090,861.89164,-0.13703,26.37620,39.48560
90.57001,7.54753,861.36032,-0.13703,26.44269,39.46126
90.77001,7.56421,861.12404,-0.13703,26.50942,39.45043
90.97000,7.58083,861.32884,-0.13704,26.57590,39.45982
91.17001,7.59751,861.35268,-0.13703,26.64263,39.46091
91.37000,7.61419,861.00316,-0.13704,26.70935,39.44489
91.57001,7.63081,860.77796,-0.13704,26.77584,39.43458
91.77001,7.64749,860.78113,-0.13703,26.84256,39.43472
91.97000,7.66418,860.87920,-0.13703,26.90929,39.43922
92.17001,7.68086,860.98658,-0.13703,26.97601,39.44413
92.37000,7.69754,861.01070,-0.13704,27.04274,39.44524
92.57001,7.71422,860.65102,-0.13703,27.10946,39.42876
92.77001,7.73078,860.76455,-0.13703,27.17571,39.43396
92.97000,7.74746,860.76548,-0.13703,27.24244,39.43401
93.17001,7.76414,860.17605,-0.13703,27.30916,39.40700
93.37000,7.78077,860.85470,-0.13703,27.37564,39.43810
93.57001,7.79745,860.07118,-0.13703,27.44237,39.40220
93.77001,7.81419,859.74345,-0.13703,27.50933,39.38718
93.97000,7.83075,859.69940,-0.13703,27.57558,39.38517
94.17001,7.84749,860.20911,-0.13704,27.64255,39.40852
94.37000,7.86423,860.33409,-0.13704,27.70951,39.41424
94.57001,7.88085,859.66494,-0.13703,27.77600,39.38359
94.77001,7.89753,858.99662,-0.13703,27.84272,39.35297
94.97000,7.91422,859.13260,-0.13704,27.90945,39.35920
95.17001,7.93084,859.36049,-0.13704,27.97593,39.36964
95.37000,7.94746,859.11751,-0.13703,28.04242,39.35851
95.57001,7.96414,859.02838,-0.13704,28.10914,39.35442
95.77001,7.98082,858.68454,-0.13704,28.17587,39.33867
95.97000,7.99750,858.83355,-0.13703,28.24259,39.34550
96.17001,8.01418,859.15476,-0.13703,28.30932,39.36021
96.37000,8.03081,859.04105,-0.13703,28.37580,39.35500
96.57001,8.04749,858.30875,-0.13703,28.44253,39.32146
96.77001,8.06411,858.19857,-0.13703,28.50901,39.31641
96.97000,8.08079,858.27373,-0.13704,28.57574,39.31985
97.17001,8.09747,857.99936,-0.13703,28.64246,39.30728
97.37000,8.11409,858.11475,-0.13704,28.70895,39.31257
97.57001,8.13083,858.00514,-0.13704,28.77592,39.30755
97.77001,8.14751,857.26203,-0.13704,28.84264,39.27350
97.97000,8.16420,857.40341,-0.13703,28.90937,39.27998
98.17001,8.18088,857.17048,-0.13704,28.97609,39.26931
98.37000,8.19750,857.19684,-0.13703,29.04257,39.27052
98.57001,8.21418,856.70315,-0.13703,29.10930,39.24790
98.77001,8.23080,856.40680,-0.13704,29.17579,39.23432
98.97000,8.24754,856.60079,-0.13703,29.24275,39.24321
99.17001,8.26416,856.18971,-0.13703,29.30923,39.22438
99.37000,8.28078,856.27250,-0.13704,29.37572,39.22817
99.57001,8.29741,856.06286,-0.13704,29.44221,39.21857
99.77001,8.31421,855.53396,-0.13703,29.50941,39.19434
99.97000,8.33089,855.44968,-0.13703,29.57614,39.19048
100.17001,8.34751,855.63501,-0.13703,29.64262,39.19897
100.37000,8.36419,855.44558,-0.13704,29.70935,39.19029
100.57001,8.38075,855.20828,-0.13703,29.77560,39.17942
100.77001,8.39743,855.01829,-0.13704,29.84232,39.17071
100.97000,8.41424,854.44413,-0.13704,29.90952,39.14441
101.17001,8.43086,854.67622,-0.13703,29.97601,39.15504
101.37000,8.44748,854.46639,-0.13704,30.04249,39.14543
101.57001,8.46422,854.74597,-0.13703,30.10946,39.15824
101.77001,8.48090,854.02150,-0.13703,30.17618,39.12505
101.97000,8.49740,854.31822,-0.13703,30.24219,39.13864
102.17001,8.51414,853.98164,-0.13703,30.30916,39.12322
102.37000,8.53088,853.33241,-0.13704,30.37612,39.09348
102.57001,8.54751,853.98732,-0.13703,30.44261,39.12348
102.77001,8.56407,852.87318,-0.13703,30.50885,39.07244
102.97000,8.58093,853.28482,-0.13704,30.57630,39.09130
103.17001,8.59749,852.65869,-0.13703,30.64254,39.06261
103.37000,8.61423,852.72528,-0.13703,30.70951,39.06566
103.57001,8.63085,852.55960,-0.13704,30.77599,39.05807
103.77001,8.64747,852.46088,-0.13704,30.84248,39.05355
103.97000,8.66415,852.52943,-0.13703,30.90920,39.05669
104.17001,8.68078,850.98632,-0.13703,30.97569,38.98600
104.37000,8.69752,851.58516,-0.13703,31.04265,39.01343
104.57001,8.71408,851.36965,-0.13704,31.10890,39.00356
104.77001,8.73076,851.23731,-0.13704,31.17562,38.99749
104.97000,8.74750,850.56601,-0.13703,31.24259,38.96674
105.17001,8.76418,851.19782,-0.13703,31.30932,38.99569
105.37000,8.78086,850.52168,-0.13703,31.37604,38.96471
105.57001,8.79760,849.70919,-0.13703,31.44300,38.92749
105.77001,8.81417,849.30714,-0.13704,31.50925,38.90907
105.97000,8.83079,849.47515,-0.13703,31.57574,38.91677
106.17001,8.84747,849.70854,-0.13704,31.64246,38.92746
106.37000,8.86427,848.89438,-0.13704,31.70967,38.89016
106.57001,8.88083,848.85946,-0.13703,31.77592,38.88856
106.77001,8.89745,848.86802,-0.13703,31.84240,38.88895
106.97001,8.91413,848.20054,-0.13704,31.90912,38.85837
107.17001,8.93070,848.40367,-0.13703,31.97537,38.86768
107.37000,8.94750,847.47626,-0.13704,32.04257,38.82519
107.57001,8.96430,847.43304,-0.13704,32.10978,38.82321
107.77001,8.98074,847.50960,-0.13703,32.17554,38.82672
107.97001,8.99742,846.44035,-0.13704,32.24227,38.77773
108.17001,9.01422,846.07694,-0.13704,32.30947,38.76109
108.37000,9.03084,846.06716,-0.13704,32.37596,38.76064
108.57001,9.04747,845.97506,-0.13704,32.44244,38.75642
108.77001,9.06421,845.17067,-0.13704,32.50941,38.71957
108.97001,9.08089,844.99288,-0.13704,32.57614,38.71142
109.17001,9.09739,845.52690,-0.13703,32.64214,38.73589
109.37000,9.11413,844.61709,-0.13704,32.70911,38.69421
109.57001,9.13099,844.34301,-0.13703,32.77655,38.68165
109.77001,9.14743,843.24796,-0.13704,32.84232,38.63148
109.97001,9.16406,843.42435,-0.13703,32.90881,38.63956
110.17001,9.18086,843.28838,-0.13704,32.97601,38.63333
110.37000,9.19754,842.70500,-0.13704,33.04273,38.60661
110.57001,9.21416,842.46509,-0.13703,33.10922,38.59562
110.77001,9.23090,842.05931,-0.13704,33.17618,38.57703
110.97001,9.24752,841.41837,-0.13703,33.24267,38.54766
111.17001,9.26408,841.21758,-0.13704,33.30891,38.53846
111.37000,9.28082,840.96305,-0.13704,33.37588,38.52680
111.57001,9.29756,840.62014,-0.13704,33.44284,38.51109
111.77001,9.31413,839.93105,-0.13703,33.50909,38.47952
111.97001,9.33081,838.95512,-0.13704,33.57581,38.43481
112.17001,9.34749,838.96667,-0.13703,33.64254,38.43534
112.37000,9.36411,839.04909,-0.13703,33.70903,38.43912
112.57001,9.38079,838.40387,-0.13704,33.77575,38.40956
112.77001,9.39753,838.17309,-0.13704,33.84272,38.39899
112.97001,9.41427,837.41071,-0.13703,33.90968,38.36406
113.17001,9.43084,836.94337,-0.13704,33.97593,38.34265
113.37000,9.44752,836.61759,-0.13703,34.04265,38.32772
113.57001,9.46420,835.98839,-0.13704,34.10937,38.29890
113.77001,9.48082,835.08361,-0.13704,34.17586,38.25745
113.97001,9.49756,835.01386,-0.13703,34.24283,38.25425
114.17001,9.51418,835.05074,-0.13703,34.30931,38.25594
114.37000,9.53074,834.33092,-0.13703,34.37556,38.22297
114.57001,9.54743,833.97683,-0.13703,34.44228,38.20675
114.77001,9.56423,833.39177,-0.13703,34.50949,38.17994
114.97001,9.58091,832.76713,-0.13704,34.57622,38.15133
115.17001,9.59747,832.13458,-0.13703,34.64246,38.12234
115.37000,9.61415,831.79027,-0.13704,34.70919,38.10657
115.57001,9.63089,831.49197,-0.13704,34.77615,38.09291
115.77001,9.64745,830.96707,-0.13703,34.84240,38.06886
115.97001,9.66419,829.82499,-0.13703,34.90936,38.01654
116.17001,9.68094,829.43561,-0.13704,34.97632,37.99870
116.37000,9.69744,829.15230,-0.13704,35.04233,37.98572
116.57001,9.71412,828.68543,-0.13704,35.10906,37.96433
116.77001,9.73086,827.76416,-0.13704,35.17602,37.92213
116.97001,9.74754,827.70754,-0.13703,35.24275,37.91953
117.17001,9.76416,826.80974,-0.13704,35.30923,37.87840
117.37000,9.78084,825.77076,-0.13704,35.37596,37.83080
117.57001,9.79746,825.40428,-0.13703,35.44244,37.81401
117.77001,9.81409,825.16456,-0.13703,35.50893,37.80303
117.97001,9.83077,824.59487,-0.13704,35.57566,37.77693
118.17001,9.84751,823.70825,-0.13704,35.64262,37.73631
118.37000,9.86419,823.59947,-0.13703,35.70934,37.73133
118.57001,9.88075,822.12174,-0.13704,35.77559,37.66363
118.77001,9.89749,822.41278,-0.13704,35.84255,37.67696
118.97001,9.91417,820.79666,-0.13704,35.90928,37.60292
119.17001,9.93085,820.72401,-0.13704,35.97600,37.59960
119.37000,9.94754,819.84568,-0.13704,36.04273,37.55936
119.57001,9.96416,818.96437,-0.13704,36.10922,37.51898
119.77001,9.98084,818.34542,-0.13704,36.17594,37.49063
119.97001,9.99746,818.14472,-0.13703,36.24243,37.48143
120.17001,10.01414,815.77785,-0.13703,36.30915,37.37300
120.37000,10.03076,816.01609,-0.13703,36.37564,37.38391
120.57001,10.04750,815.09594,-0.13704,36.44260,37.34176
120.77001,10.06418,814.66073,-0.13704,36.50932,37.32182
120.97001,10.08081,813.89137,-0.13704,36.57581,37.28658
121.17001,10.09749,812.95352,-0.13704,36.64254,37.24361
121.37000,10.11417,812.80209,-0.13704,36.70926,37.23667
121.57001,10.13085,811.40622,-0.13704,36.77599,37.17273
121.77001,10.14753,810.59858,-0.13704,36.84271,37.13572
121.97001,10.16415,810.07117,-0.13704,36.90920,37.11156
122.17001,10.18089,808.91093,-0.13704,36.97616,37.05841
122.37000,10.19752,808.00448,-0.13704,37.04265,37.01688
122.57001,10.21414,807.12829,-0.13704,37.10913,36.97674
122.77001,10.23082,806.25815,-0.13704,37.17586,36.93688
122.97001,10.24744,805.51598,-0.13704,37.24234,36.90288
123.17001,10.26412,803.92268,-0.13704,37.30907,36.82988
123.37000,10.28086,803.44221,-0.13703,37.37603,36.80787
123.57001,10.29754,802.41291,-0.13704,37.44276,36.76072
123.77001,10.31417,801.04209,-0.13704,37.50925,36.69791
123.97001,10.33079,800.12577,-0.13704,37.57573,36.65594
124.17001,10.34747,799.41945,-0.13704,37.64246,36.62358
124.37000,10.36415,797.81944,-0.13704,37.70919,36.55028
124.57001,10.38089,797.28533,-0.13704,37.77615,36.52581
124.77001,10.39757,796.49845,-0.13703,37.84287,36.48976
124.97001,10.41407,794.84154,-0.13704,37.90888,36.41385
125.17001,10.43081,793.52446,-0.13704,37.97584,36.35351
125.37000,10.44750,792.79877,-0.13703,38.04257,36.32027
125.57001,10.46412,791.07583,-0.13704,38.10906,36.24133
125.77001,10.48080,789.78864,-0.13704,38.17578,36.18237
125.97001,10.49748,788.89886,-0.13704,38.24251,36.14160
126.17001,10.51416,787.41452,-0.13704,38.30923,36.07360
126.37000,10.53084,786.01930,-0.13704,38.37596,36.00968
126.57001,10.54746,785.00006,-0.13704,38.44244,35.96299
126.77001,10.56421,783.57533,-0.13704,38.50940,35.89772
126.97001,10.58083,782.20554,-0.13703,38.57589,35.83496
127.17001,10.59745,780.54550,-0.13704,38.64237,35.75891
127.37000,10.61413,779.70126,-0.13704,38.70910,35.72023
127.57001,10.63075,778.14977,-0.13704,38.77559,35.64915
127.77001,10.64749,776.34696,-0.13704,38.84255,35.56656
127.97001,10.66417,774.91058,-0.13704,38.90928,35.50076
128.17002,10.68085,773.69423,-0.13704,38.97600,35.44503
128.37001,10.69747,771.57132,-0.13704,39.04248,35.34778
128.57001,10.71410,770.58733,-0.13704,39.10898,35.30270
128.77001,10.73090,768.73023,-0.13704,39.17617,35.21762
128.97000,10.74746,767.24915,-0.13704,39.24242,35.14977
129.17002,10.76420,766.14758,-0.13704,39.30939,35.09930
129.37001,10.78088,763.83352,-0.13704,39.37611,34.99329
129.57001,10.79744,762.15519,-0.13704,39.44236,34.91640
129.77001,10.81413,760.21818,-0.13704,39.50908,34.82766
129.97000,10.83087,758.95302,-0.13704,39.57605,34.76970
130.17002,10.84755,756.82891,-0.13704,39.64278,34.67239
130.37001,10.86411,755.01883,-0.13704,39.70902,34.58947
130.57001,10.88079,752.53733,-0.13704,39.77575,34.47578
130.77001,10.89753,750.26322,-0.13704,39.84271,34.37160
130.97000,10.91415,747.59829,-0.13704,39.90920,34.24951
131.17002,10.93077,744.74416,-0.13704,39.97568,34.11876
131.37002,10.94752,741.43503,-0.13703,40.04265,33.96716
131.57000,10.96408,738.02168,-0.13704,40.10890,33.81078
131.77000,10.98082,732.69433,-0.13704,40.17586,33.56672
131.97000,10.99756,721.88112,-0.13704,40.24282,33.07133
132.05600,11.00479,8.72759,-0.13704,40.27176,0.39983