File: Manufatura Aditiva/Dados/Ensaios AMR/Ensaios/Ensaios SLS/Tracao_OLABI_06_06_2018_SLS_XY1.is_metal_RawData/Specimen_RawData_4.csv
Time,Extension,Load,Strain 1,Tensile strain,Tensile stress
(sec),(mm),(N),(mm/mm),(%),(MPa)
0.00000,0.00006,19.37749,0.00085,0.08457,0.89959
0.20000,0.01387,26.52555,0.00103,0.10309,1.23143
0.40000,0.03270,36.75422,0.00134,0.13362,1.70629
0.60000,0.04986,46.96143,0.00162,0.16224,2.18016
0.80000,0.06673,55.28351,0.00190,0.18985,2.56650
1.00000,0.08335,63.62923,0.00217,0.21693,2.95395
1.20000,0.10003,72.35546,0.00244,0.24419,3.35906
1.40000,0.11677,81.37821,0.00272,0.27213,3.77793
1.60000,0.13339,89.69721,0.00299,0.29933,4.16414
1.80000,0.14995,97.40129,0.00327,0.32651,4.52180
2.00000,0.16657,105.91227,0.00354,0.35398,4.91691
2.20000,0.18325,114.16220,0.00382,0.38162,5.29991
2.40000,0.19994,121.90494,0.00409,0.40940,5.65936
2.60000,0.21668,128.99549,0.00435,0.43473,5.98854
2.80000,0.23336,136.74522,0.00462,0.46172,6.34831
3.00000,0.24998,144.40132,0.00489,0.48949,6.70374
3.20000,0.26672,152.74822,0.00518,0.51810,7.09124
3.40000,0.28340,161.32779,0.00546,0.54559,7.48954
3.60000,0.30002,168.41750,0.00573,0.57295,7.81868
3.80000,0.31665,175.88795,0.00602,0.60170,8.16549
4.00000,0.33327,182.95582,0.00630,0.62953,8.49361
4.20000,0.34995,191.59933,0.00657,0.65732,8.89488
4.40000,0.36663,198.47937,0.00686,0.68563,9.21428
4.60000,0.38331,204.65697,0.00709,0.70919,9.50108
4.80000,0.39999,212.26166,0.00737,0.73670,9.85412
5.00000,0.41661,219.80491,0.00764,0.76434,10.20431
5.20000,0.43335,227.31349,0.00793,0.79268,10.55289
5.40000,0.45004,234.55641,0.00821,0.82067,10.88914
5.60000,0.46666,242.60683,0.00848,0.84809,11.26287
5.80000,0.48334,249.73263,0.00876,0.87595,11.59369
6.00000,0.50002,256.96261,0.00905,0.90498,11.92933
6.20000,0.51664,264.40120,0.00934,0.93365,12.27466
6.40000,0.53326,271.42300,0.00961,0.96106,12.60065
6.60000,0.55000,278.74624,0.00989,0.98940,12.94063
6.80000,0.56674,285.03779,0.01018,1.01763,13.23271
7.00000,0.58331,291.70811,0.01046,1.04597,13.54237
7.20000,0.59993,298.10094,0.01071,1.07126,13.83916
7.40000,0.61673,304.38630,0.01098,1.09826,14.13095
7.60000,0.63335,311.47378,0.01126,1.12645,14.45998
7.80000,0.64997,318.31991,0.01155,1.15465,14.77781
8.00000,0.66671,325.11819,0.01183,1.18344,15.09341
8.20000,0.68333,331.80951,0.01212,1.21177,15.40406
8.40000,0.70002,337.91421,0.01241,1.24067,15.68746
8.60000,0.71664,344.89878,0.01269,1.26926,16.01172
8.80000,0.73344,350.85799,0.01298,1.29787,16.28837
9.00000,0.75000,357.30849,0.01326,1.32634,16.58783
9.20000,0.76662,362.96360,0.01355,1.35480,16.85036
9.40000,0.78342,368.10443,0.01379,1.37903,17.08903
9.60000,0.79998,374.40818,0.01407,1.40727,17.38167
9.80000,0.81660,380.06378,0.01437,1.43658,17.64423
10.00000,0.83335,386.65815,0.01466,1.46555,17.95037
10.20000,0.84997,392.64569,0.01494,1.49396,18.22834
10.40000,0.86671,398.67293,0.01523,1.52318,18.50815
10.60000,0.88333,404.35279,0.01553,1.55259,18.77183
10.80000,0.90007,409.90734,0.01582,1.58163,19.02970
11.00000,0.91669,416.21765,0.01611,1.61117,19.32265
11.20000,0.93331,421.62803,0.01641,1.64057,19.57383
11.40000,0.95000,427.56596,0.01670,1.67041,19.84949
11.60000,0.96656,432.63463,0.01698,1.69825,20.08480
11.80000,0.98330,437.71127,0.01725,1.72471,20.32048
12.00000,1.00004,443.06917,0.01754,1.75444,20.56922
12.20000,1.01666,448.63964,0.01784,1.78404,20.82782
12.40000,1.03334,455.11066,0.01814,1.81399,21.12824
12.60000,1.04996,459.89882,0.01845,1.84470,21.35052
12.80000,1.06664,464.86086,0.01875,1.87496,21.58088
13.00000,1.08333,470.13015,0.01905,1.90497,21.82551
13.20000,1.10001,474.74881,0.01935,1.93532,22.03992
13.40000,1.11675,480.03886,0.01966,1.96616,22.28551
13.60000,1.13325,484.94856,0.01997,1.99667,22.51344
13.80000,1.14993,490.46637,0.02028,2.02765,22.76960
14.00000,1.16673,493.74714,0.02054,2.05415,22.92191
14.20000,1.18329,498.04519,0.02085,2.08502,23.12145
14.40000,1.19998,503.30912,0.02116,2.11625,23.36582
14.60000,1.21672,508.09546,0.02148,2.14776,23.58802
14.80000,1.23334,512.10225,0.02179,2.17930,23.77404
15.00000,1.24990,517.07095,0.02211,2.21075,24.00471
15.20000,1.26664,521.19545,0.02242,2.24199,24.19618
15.40000,1.28344,525.44288,0.02274,2.27408,24.39337
15.60000,1.29994,529.62117,0.02305,2.30531,24.58734
15.80000,1.31656,533.38106,0.02338,2.33790,24.76189
16.00000,1.33343,537.51152,0.02370,2.37011,24.95365
16.20000,1.34993,541.62070,0.02402,2.40225,25.14441
16.40000,1.36667,544.78752,0.02430,2.43008,25.29143
16.60000,1.38341,546.75951,0.02458,2.45822,25.38298
16.80000,1.39997,550.89979,0.02491,2.49057,25.57519
17.00000,1.41659,554.74183,0.02523,2.52303,25.75355
17.20000,1.43333,558.78912,0.02556,2.55587,25.94145
17.40000,1.45001,562.19385,0.02589,2.58854,26.09951
17.60000,1.46664,566.26922,0.02621,2.62132,26.28871
17.80000,1.48320,569.76937,0.02655,2.65473,26.45120
18.00000,1.50000,572.81232,0.02688,2.68790,26.59246
18.20000,1.51662,575.86324,0.02721,2.72086,26.73410
18.40000,1.53330,579.34360,0.02754,2.75417,26.89568
18.60000,1.55004,583.33259,0.02788,2.78789,27.08086
18.80000,1.56666,586.21163,0.02821,2.82139,27.21452
19.00000,1.58341,589.52691,0.02855,2.85507,27.36843
19.20000,1.60003,591.33992,0.02884,2.88409,27.45260
19.40000,1.61665,594.38650,0.02918,2.91794,27.59403
19.60000,1.63339,597.90746,0.02952,2.95182,27.75749
19.80000,1.65001,600.55293,0.02986,2.98580,27.88031
20.00000,1.66663,603.42639,0.03020,3.01999,28.01370
20.20000,1.68325,606.75982,0.03054,3.07021,28.16846
20.40000,1.69993,609.47635,0.03088,3.13694,28.29457
20.51600,1.70968,610.89299,0.03108,3.17592,28.36034
20.71600,1.72630,613.71387,0.03142,3.24241,28.49129
20.91600,1.74298,616.15380,0.03177,3.30913,28.60457
21.11600,1.75966,619.20788,0.03211,3.37586,28.74635
21.31600,1.77635,621.80739,0.03246,3.44258,28.86703
21.51600,1.79303,624.55819,0.03281,3.50931,28.99474
21.71600,1.80977,627.82043,0.03316,3.57627,29.14618
21.91600,1.82633,629.94789,0.03351,3.64252,29.24495
22.11600,1.84295,633.37246,0.03385,3.70900,29.40393
22.31600,1.85969,633.61544,0.03416,3.77597,29.41521
22.51600,1.87631,637.11032,0.03450,3.84245,29.57746
22.71600,1.89300,638.63550,0.03485,3.90918,29.64827
22.91600,1.90974,641.75758,0.03521,3.97614,29.79321
23.11600,1.92630,643.13300,0.03556,4.04239,29.85706
23.31600,1.94292,646.17130,0.03591,4.10888,29.99811
23.51600,1.95972,648.53835,0.03626,4.17608,30.10800
23.71600,1.97640,651.11425,0.03662,4.24280,30.22758
23.91600,1.99308,653.41899,0.03697,4.30953,30.33458
24.11600,2.00964,655.53891,0.03733,4.37578,30.43300
24.31600,2.02639,657.35467,0.03778,4.44274,30.51729
24.51600,2.04301,660.25676,0.03802,4.50923,30.65202
24.71600,2.05969,662.61729,0.03570,4.57595,30.76161
24.91600,2.07631,664.38033,0.03641,4.64244,30.84345
25.11600,2.09293,667.24340,0.03423,4.70892,30.97637
25.31600,2.10961,669.62801,0.03396,4.77565,31.08707
25.51600,2.12629,671.21908,0.03400,4.84237,31.16094
25.71600,2.14297,672.79432,0.03250,4.90910,31.23407
25.91600,2.15972,673.81766,0.03145,4.97606,31.28158
26.11600,2.17634,675.77846,0.03171,5.04255,31.37260
26.31600,2.19302,675.57315,0.00964,5.10927,31.36307
26.51600,2.20970,678.60377,0.00943,5.17600,31.50377
26.71600,2.22632,680.49356,0.00774,5.24249,31.59150
26.91600,2.24306,682.51439,-0.03877,5.30945,31.68532
27.11600,2.25968,685.32876,0.02763,5.37594,31.81597
27.31600,2.27643,687.00635,0.00110,5.44290,31.89385
27.51600,2.29299,688.40301,0.05635,5.50915,31.95869
27.71600,2.30967,690.13960,0.05463,5.57587,32.03931
27.91600,2.32635,692.75489,-0.04393,5.64260,32.16072
28.11600,2.34297,694.20841,-0.00227,5.70908,32.22820
28.31600,2.35965,695.82476,0.02078,5.77581,32.30324
28.51600,2.37627,697.57756,-0.12915,5.84229,32.38461
28.71600,2.39295,699.43266,-0.13638,5.90902,32.47074
28.91600,2.40970,701.28692,-0.13646,5.97598,32.55682
29.11600,2.42632,702.85066,-0.13646,6.04247,32.62941
29.31600,2.44300,704.56527,-0.13647,6.10919,32.70901
29.51600,2.45974,706.18726,-0.13647,6.17616,32.78432
29.71600,2.47636,708.25918,-0.13648,6.24264,32.88050
29.91600,2.49304,709.08903,-0.13648,6.30937,32.91903
30.11600,2.50966,711.29831,-0.13649,6.37585,33.02159
30.31600,2.52640,711.02963,-0.13649,6.44282,33.00912
30.51600,2.54303,713.44394,-0.13649,6.50930,33.12120
30.71600,2.55953,715.32093,-0.13649,6.57531,33.20834
30.91600,2.57633,716.64616,-0.13649,6.64252,33.26986
31.11600,2.59295,718.08207,-0.13649,6.70900,33.33652
31.31600,2.60963,719.76897,-0.13649,6.77573,33.41484
31.51600,2.62631,721.45239,-0.13649,6.84245,33.49299
31.71600,2.64299,722.94269,-0.13649,6.90918,33.56218
31.91600,2.65962,724.36663,-0.13649,6.97566,33.62828
32.11600,2.67630,725.62913,-0.13650,7.04239,33.68689
32.31600,2.69304,727.80089,-0.13650,7.10935,33.78772
32.51600,2.70972,729.12057,-0.13650,7.17608,33.84898
32.71600,2.72634,730.07308,-0.13650,7.24256,33.89320
32.91600,2.74296,731.82988,-0.13650,7.30905,33.97476
33.11600,2.75964,732.98239,-0.13650,7.37577,34.02826
33.31600,2.77632,734.27581,-0.13650,7.44250,34.08831
33.51600,2.79307,735.60448,-0.13650,7.50946,34.14999
33.71600,2.80969,737.23802,-0.13650,7.57595,34.22583
33.91600,2.82631,738.46434,-0.13650,7.64244,34.28276
34.11600,2.84299,739.69215,-0.13651,7.70916,34.33976
34.31600,2.85961,741.14236,-0.13651,7.77565,34.40709
34.51600,2.87641,742.56565,-0.13651,7.84285,34.47316
34.71600,2.89303,743.65307,-0.13651,7.90934,34.52364
34.91600,2.90972,745.42779,-0.13651,7.97606,34.60603
35.11600,2.92628,746.26682,-0.13651,8.04231,34.64499
35.31600,2.94296,747.83596,-0.13651,8.10903,34.71783
35.51600,2.95970,749.15141,-0.13651,8.17600,34.77890
35.71600,2.97638,748.76598,-0.13651,8.24272,34.76101
35.91600,2.99300,749.78634,-0.13651,8.30921,34.80838
36.11600,3.00968,751.01699,-0.13651,8.37593,34.86551
36.31600,3.02625,753.15353,-0.13651,8.44218,34.96469
36.51600,3.04293,753.74655,-0.13651,8.50891,34.99223
36.71600,3.05973,755.38969,-0.13652,8.57611,35.06851
36.91600,3.07641,756.85936,-0.13651,8.64283,35.13674
37.11600,3.09291,757.84875,-0.13651,8.70884,35.18267
37.31600,3.10965,759.51573,-0.13651,8.77580,35.26006
37.51600,3.12645,760.33473,-0.13651,8.84301,35.29808
37.71600,3.14301,761.37930,-0.13651,8.90926,35.34657
37.91600,3.15964,762.77559,-0.13651,8.97574,35.41139
38.11600,3.17638,764.25783,-0.13652,9.04271,35.48021
38.31600,3.19294,765.78562,-0.13652,9.10895,35.55113
38.51600,3.20956,765.85268,-0.13652,9.17544,35.55424
38.71600,3.22636,766.71536,-0.13652,9.24264,35.59430
38.91600,3.24298,768.76553,-0.13651,9.30913,35.68947
39.11600,3.25960,769.24139,-0.13652,9.37561,35.71156
39.31600,3.27628,770.52866,-0.13652,9.44234,35.77132
39.51600,3.29303,771.23176,-0.13652,9.50930,35.80397
39.71600,3.30959,772.74684,-0.13652,9.57555,35.87430
39.91600,3.32627,773.53488,-0.13652,9.64227,35.91089
40.11600,3.34307,774.54816,-0.13652,9.70948,35.95793
40.31600,3.35969,775.40916,-0.13652,9.77596,35.99790
40.51600,3.37631,776.16987,-0.13652,9.84245,36.03321
40.71600,3.39305,777.77491,-0.13652,9.90941,36.10773
40.91600,3.40968,778.44542,-0.13652,9.97590,36.13885
41.11600,3.42636,779.33436,-0.13652,10.04262,36.18013
41.31600,3.44298,780.22052,-0.13652,10.10911,36.22126
41.51600,3.45960,780.86830,-0.13652,10.17560,36.25134
41.71600,3.47628,782.75241,-0.13652,10.24232,36.33881
41.91600,3.49302,783.11265,-0.13652,10.30929,36.35553
42.11600,3.50976,784.63210,-0.13652,10.37625,36.42607
42.31600,3.52638,784.89622,-0.13652,10.44274,36.43833
42.51600,3.54295,784.64700,-0.13653,10.50898,36.42676
42.71600,3.55969,784.96058,-0.13653,10.57595,36.44132
42.91600,3.57631,786.62513,-0.13652,10.64243,36.51859
43.11600,3.59299,787.28059,-0.13652,10.70916,36.54902
43.31600,3.60973,788.77546,-0.13653,10.77612,36.61842
43.51600,3.62635,789.64233,-0.13653,10.84261,36.65866
43.71600,3.64285,790.54777,-0.13652,10.90862,36.70070
43.91600,3.65966,791.30800,-0.13653,10.97582,36.73599
44.11600,3.67646,792.03295,-0.13653,11.04302,36.76965
44.31600,3.69296,792.89945,-0.13653,11.10903,36.80988
44.51600,3.70964,794.07478,-0.13653,11.17576,36.86444
44.71600,3.72644,794.84442,-0.13653,11.24296,36.90017
44.91600,3.74300,795.78776,-0.13653,11.30921,36.94396
45.11600,3.75956,796.94558,-0.13653,11.37545,36.99771
45.31600,3.77642,797.34279,-0.13653,11.44290,37.01616
45.51600,3.79299,798.30671,-0.13653,11.50914,37.06091
45.71600,3.80961,798.52073,-0.13653,11.57563,37.07084
45.91600,3.82635,799.37885,-0.13653,11.64259,37.11068
46.11600,3.84303,800.79092,-0.13653,11.70932,37.17623
46.31600,3.85965,801.41453,-0.13653,11.77580,37.20518
46.51600,3.87633,801.58589,-0.13653,11.84253,37.21314
46.71600,3.89301,803.01510,-0.13653,11.90925,37.27949
46.91600,3.90957,803.09324,-0.13653,11.97550,37.28312
47.11600,3.92632,803.73278,-0.13653,12.04246,37.31281
47.31600,3.94306,804.88063,-0.13653,12.10943,37.36610
47.51600,3.95968,804.97535,-0.13653,12.17591,37.37049
47.71600,3.97630,806.27529,-0.13653,12.24240,37.43084
47.91600,3.99292,807.34706,-0.13653,12.30889,37.48060
48.11600,4.00966,807.65514,-0.13653,12.37585,37.49490
48.31600,4.02634,807.77444,-0.13653,12.44257,37.50044
48.51600,4.04297,808.71200,-0.13653,12.50906,37.54396
48.71600,4.05977,809.91210,-0.13653,12.57626,37.59968
48.91600,4.07627,810.36231,-0.13653,12.64227,37.62058
49.11600,4.09289,810.85796,-0.13653,12.70876,37.64359
49.31600,4.10969,811.51919,-0.13653,12.77596,37.67429
49.51600,4.12631,811.82998,-0.13653,12.84245,37.68871
49.71600,4.14299,812.71315,-0.13654,12.90917,37.72971
49.91600,4.15967,813.92797,-0.13653,12.97590,37.78611
50.11600,4.17636,814.50175,-0.13654,13.04262,37.81275
50.31600,4.19292,814.47568,-0.13653,13.10887,37.81154
50.51600,4.20966,815.32346,-0.13654,13.17583,37.85090
50.71600,4.22652,815.10833,-0.13654,13.24327,37.84091
50.91600,4.24296,816.44896,-0.13653,13.30904,37.90315
51.11600,4.25958,817.39863,-0.13653,13.37553,37.94724
51.31600,4.27638,817.91272,-0.13654,13.44273,37.97110
51.51600,4.29295,818.36060,-0.13653,13.50898,37.99189
51.71600,4.30963,818.74775,-0.13653,13.57570,38.00987
51.91600,4.32637,817.77535,-0.13654,13.64267,37.96473
52.11600,4.34299,818.48865,-0.13654,13.70916,37.99784
52.31600,4.35967,819.49458,-0.13654,13.77588,38.04454
52.51600,4.37629,820.30650,-0.13654,13.84237,38.08223
52.71600,4.39303,820.46660,-0.13654,13.90933,38.08966
52.91600,4.40965,821.27005,-0.13654,13.97582,38.12696
53.11600,4.42634,821.57580,-0.13654,14.04254,38.14116
53.31600,4.44302,822.43718,-0.13653,14.10927,38.18115
53.51600,4.45964,823.27351,-0.13653,14.17575,38.21997
53.71600,4.47632,823.55617,-0.13654,14.24248,38.23310
53.91600,4.49300,824.30663,-0.13654,14.30920,38.26794
54.11600,4.50962,824.78449,-0.13654,14.37569,38.29012
54.31600,4.52624,825.76340,-0.13653,14.44218,38.33556
54.51600,4.54292,826.23037,-0.13654,14.50890,38.35724
54.71600,4.55967,826.64927,-0.13654,14.57586,38.37669
54.91600,4.57629,827.37524,-0.13654,14.64235,38.41039
55.11600,4.59303,827.71601,-0.13654,14.70931,38.42621
55.31600,4.60971,828.82838,-0.13654,14.77604,38.47786
55.51600,4.62633,828.33814,-0.13654,14.84253,38.45510
55.71600,4.64301,828.87774,-0.13654,14.90925,38.48014
55.91600,4.65969,830.02932,-0.13654,14.97598,38.53361
56.11600,4.67644,829.74369,-0.13654,15.04294,38.52035
56.31600,4.69306,831.00395,-0.13654,15.10942,38.57885
56.51600,4.70962,831.02230,-0.13654,15.17567,38.57970
56.71600,4.72636,830.82234,-0.13654,15.24264,38.57042
56.91600,4.74298,832.63488,-0.13654,15.30912,38.65457
57.11600,4.75966,832.39432,-0.13654,15.37585,38.64340
57.31600,4.77640,833.08304,-0.13654,15.44281,38.67537
57.51600,4.79296,833.58018,-0.13654,15.50906,38.69846
57.71600,4.80965,833.81701,-0.13654,15.57578,38.70945
57.91600,4.82639,834.12454,-0.13654,15.64275,38.72372
58.11600,4.84307,834.28770,-0.13654,15.70947,38.73130
58.31600,4.85963,834.91234,-0.13654,15.77572,38.76030
58.51600,4.87637,835.23514,-0.13654,15.84268,38.77528
58.71600,4.89305,836.05750,-0.13654,15.90941,38.81346
58.91600,4.90955,836.30551,-0.13654,15.97542,38.82497
59.11600,4.92630,836.36092,-0.13654,16.04238,38.82755
59.31600,4.94304,837.49844,-0.13654,16.10934,38.88036
59.51600,4.95966,837.54342,-0.13654,16.17583,38.88245
59.71600,4.97622,837.56996,-0.13654,16.24208,38.88368
59.91600,4.99302,838.32471,-0.13654,16.30928,38.91872
60.11600,5.00964,838.19283,-0.13654,16.37577,38.91259
60.31600,5.02638,838.94599,-0.13654,16.44273,38.94756
60.51600,5.04300,839.45589,-0.13654,16.50922,38.97123
60.71600,5.05969,839.47657,-0.13654,16.57594,38.97219
60.91600,5.07631,839.66907,-0.13654,16.64243,38.98113
61.11600,5.09293,839.72625,-0.13654,16.70891,38.98378
61.31600,5.10967,840.13483,-0.13655,16.77588,39.00275
61.51600,5.12635,840.71523,-0.13654,16.84260,39.02969
61.71600,5.14291,841.21106,-0.13654,16.90885,39.05271
61.91600,5.15965,841.64217,-0.13655,16.97581,39.07273
62.11600,5.17634,841.70476,-0.13654,17.04254,39.07563
62.31600,5.19296,842.00557,-0.13655,17.10902,39.08960
62.51600,5.20970,842.99603,-0.13654,17.17599,39.13558
62.71600,5.22632,842.55356,-0.13655,17.24248,39.11504
62.91600,5.24294,842.66784,-0.13654,17.30896,39.12034
63.11600,5.25962,843.02789,-0.13654,17.37569,39.13706
63.31600,5.27636,843.10900,-0.13654,17.44265,39.14082
63.51600,5.29304,843.52968,-0.13655,17.50938,39.16035
63.71600,5.30967,844.25798,-0.13654,17.57586,39.19416
63.91600,5.32635,844.33947,-0.13655,17.64259,39.19795
64.11600,5.34297,844.20554,-0.13655,17.70907,39.19173
64.31600,5.35959,845.12075,-0.13654,17.77556,39.23422
64.51601,5.37639,844.81928,-0.13655,17.84276,39.22022
64.71600,5.39295,845.04522,-0.13655,17.90901,39.23071
64.91600,5.40963,845.17198,-0.13655,17.97573,39.23660
65.11600,5.42631,845.50474,-0.13655,18.04246,39.25204
65.31600,5.44294,846.25361,-0.13655,18.10894,39.28681
65.51601,5.45962,845.98251,-0.13655,18.17567,39.27422
65.71600,5.47642,846.00681,-0.13655,18.24287,39.27535
65.91600,5.49310,846.52379,-0.13655,18.30960,39.29935
66.11601,5.50960,846.28295,-0.13655,18.37561,39.28817
66.31600,5.52628,847.11621,-0.13655,18.44233,39.32685
66.51601,5.54308,846.98806,-0.13655,18.50953,39.32091
66.71600,5.55971,847.34596,-0.13655,18.57602,39.33752
66.91600,5.57633,847.74531,-0.13655,18.64251,39.35606
67.11601,5.59307,847.63207,-0.13655,18.70947,39.35080
67.31600,5.60963,848.40050,-0.13655,18.77572,39.38648
67.51601,5.62631,848.12744,-0.13655,18.84244,39.37380
67.71600,5.64299,848.50723,-0.13655,18.90917,39.39143
67.91600,5.65967,848.87883,-0.13655,18.97589,39.40868
68.11601,5.67629,848.70504,-0.13655,19.04238,39.40062
68.31600,5.69292,849.15394,-0.13655,19.10886,39.42146
68.51601,5.70966,849.58281,-0.13655,19.17583,39.44137
68.71600,5.72628,849.32726,-0.13655,19.24231,39.42950
68.91600,5.74308,849.16260,-0.13655,19.30952,39.42186
69.11601,5.75976,849.28283,-0.13655,19.37624,39.42744
69.31600,5.77632,849.93243,-0.13655,19.44249,39.45760
69.51601,5.79300,849.89956,-0.13655,19.50921,39.45607
69.71600,5.80963,849.76619,-0.13655,19.57570,39.44988
69.91600,5.82637,850.38356,-0.13655,19.64266,39.47854
70.11601,5.84305,850.60559,-0.13655,19.70939,39.48885
70.31600,5.85961,850.28028,-0.13655,19.77564,39.47375
70.51601,5.87629,849.98291,-0.13655,19.84236,39.45994
70.71600,5.89291,850.57840,-0.13655,19.90885,39.48759
70.91600,5.90965,850.96154,-0.13655,19.97581,39.50537
71.11601,5.92645,851.35456,-0.13655,20.04301,39.52362
71.31600,5.94296,850.89700,-0.13655,20.10902,39.50238
71.51601,5.95964,851.65100,-0.13655,20.17575,39.53738
71.71600,5.97638,851.53794,-0.13655,20.24271,39.53213
71.91600,5.99306,849.51790,-0.13655,20.30943,39.43835
72.11601,6.00968,849.81062,-0.13655,20.37592,39.45194
72.31600,6.02636,850.08983,-0.13655,20.44265,39.46490
72.51601,6.04304,850.52084,-0.13655,20.50937,39.48491
72.71600,6.05960,850.99172,-0.13655,20.57562,39.50677
72.91600,6.07629,850.95428,-0.13656,20.64234,39.50504
73.11601,6.09309,851.35382,-0.13655,20.70955,39.52359
73.31600,6.10965,851.05048,-0.13655,20.77579,39.50950
73.51601,6.12627,851.80150,-0.13655,20.84228,39.54437
73.71600,6.14301,851.84276,-0.13655,20.90924,39.54628
73.91600,6.15969,852.19070,-0.13655,20.97597,39.56244
74.11601,6.17631,852.51853,-0.13655,21.04246,39.57766
74.31600,6.19306,852.64565,-0.13656,21.10942,39.58356
74.51601,6.20968,853.08366,-0.13655,21.17591,39.60389
74.71600,6.22624,852.55811,-0.13655,21.24215,39.57949
74.91600,6.24298,853.10386,-0.13655,21.30912,39.60483
75.11601,6.25972,852.57897,-0.13655,21.37608,39.58046
75.31600,6.27634,852.74344,-0.13655,21.44257,39.58810
75.51601,6.29290,852.81655,-0.13656,21.50881,39.59149
75.71600,6.30964,853.61805,-0.13656,21.57578,39.62870
75.91600,6.32627,853.71491,-0.13655,21.64226,39.63320
76.11601,6.34295,853.54270,-0.13655,21.70899,39.62520
76.31600,6.35969,853.73782,-0.13655,21.77595,39.63426
76.51601,6.37643,853.78606,-0.13655,21.84292,39.63650
76.71600,6.39287,854.45615,-0.13655,21.90869,39.66761
76.91600,6.40961,853.55416,-0.13655,21.97565,39.62573
77.11601,6.42635,854.16269,-0.13656,22.04261,39.65398
77.31600,6.44298,854.22462,-0.13655,22.10910,39.65686
77.51601,6.45972,853.56999,-0.13656,22.17606,39.62647
77.71600,6.47640,853.99263,-0.13656,22.24279,39.64609
77.91600,6.49296,854.25228,-0.13655,22.30904,39.65814
78.11601,6.50958,853.95742,-0.13656,22.37552,39.64445
78.31600,6.52632,854.33563,-0.13655,22.44249,39.66201
78.51601,6.54306,854.82188,-0.13656,22.50945,39.68459
78.71600,6.55968,854.62919,-0.13655,22.57594,39.67564
78.91600,6.57637,854.12292,-0.13655,22.64266,39.65214
79.11601,6.59305,854.26103,-0.13655,22.70939,39.65855
79.31600,6.60961,854.92013,-0.13655,22.77563,39.68915
79.51601,6.62635,854.38620,-0.13655,22.84260,39.66436
79.71600,6.64309,854.47161,-0.13656,22.90956,39.66833
79.91600,6.65965,854.77224,-0.13656,22.97581,39.68228
80.11601,6.67621,854.83445,-0.13655,23.04205,39.68517
80.31600,6.69307,854.21288,-0.13656,23.10950,39.65631
80.51601,6.70970,854.33340,-0.13656,23.17599,39.66191
80.71600,6.72626,854.89126,-0.13656,23.24223,39.68781
80.91600,6.74300,854.69428,-0.13655,23.30920,39.67867
81.11601,6.75962,855.11440,-0.13656,23.37568,39.69817
81.31600,6.77624,854.56930,-0.13656,23.44217,39.67286
81.51601,6.79298,855.30998,-0.13656,23.50913,39.70725
81.71600,6.80972,854.74467,-0.13656,23.57610,39.68100
81.91600,6.82629,855.18369,-0.13656,23.64234,39.70139
82.11601,6.84297,854.84684,-0.13656,23.70907,39.68575
82.31600,6.85971,854.99976,-0.13656,23.77603,39.69284
82.51601,6.87627,854.58504,-0.13656,23.84228,39.67359
82.71600,6.89301,855.04716,-0.13656,23.90924,39.69505
82.91600,6.90969,854.30983,-0.13656,23.97597,39.66082
83.11601,6.92631,854.91063,-0.13655,24.04245,39.68871
83.31600,6.94294,854.78984,-0.13656,24.10894,39.68310
83.51601,6.95962,854.82495,-0.13656,24.17566,39.68473
83.71600,6.97636,855.02230,-0.13656,24.24263,39.69389
83.91600,6.99304,854.49750,-0.13656,24.30935,39.66953
84.11601,7.00966,854.45475,-0.13656,24.37584,39.66754
84.31600,7.02634,854.51221,-0.13656,24.44257,39.67021
84.51601,7.04290,854.55906,-0.13656,24.50881,39.67239
84.71600,7.05964,854.61671,-0.13656,24.57577,39.67506
84.91600,7.07639,854.16175,-0.13656,24.64274,39.65394
85.11601,7.09301,854.34327,-0.13656,24.70923,39.66237
85.31600,7.10963,854.13698,-0.13656,24.77571,39.65279
85.51601,7.12631,854.71077,-0.13656,24.84244,39.67943
85.71600,7.14299,854.63999,-0.13656,24.90916,39.67614
85.91600,7.15961,854.02615,-0.13656,24.97565,39.64765
86.11601,7.17635,854.13037,-0.13656,25.04261,39.65248
86.31600,7.19309,854.56930,-0.13656,25.10958,39.67286
86.51601,7.20960,854.55840,-0.13656,25.17558,39.67236
86.71600,7.22628,854.80018,-0.13656,25.24231,39.68358
86.91600,7.24308,854.24501,-0.13656,25.30951,39.65781
87.11601,7.25970,854.56297,-0.13656,25.37600,39.67257
87.31600,7.27632,854.54574,-0.13656,25.44248,39.67177
87.51601,7.29300,854.08688,-0.13656,25.50921,39.65046
87.71600,7.30974,853.86690,-0.13656,25.57617,39.64025
87.91600,7.32631,853.69842,-0.13656,25.64242,39.63243
88.11601,7.34293,853.85777,-0.13656,25.70890,39.63983
88.31600,7.35973,853.80683,-0.13656,25.77611,39.63746
88.51601,7.37623,854.56325,-0.13656,25.84212,39.67258
88.71600,7.39297,854.30760,-0.13656,25.90908,39.66071
88.91601,7.40971,853.82769,-0.13656,25.97605,39.63843
89.11601,7.42627,853.66275,-0.13656,26.04229,39.63078
89.31600,7.44301,854.03770,-0.13656,26.10925,39.64818
89.51601,7.45970,853.81158,-0.13656,26.17598,39.63768
89.71600,7.47632,853.17465,-0.13656,26.24247,39.60812
89.91601,7.49306,853.21842,-0.13656,26.30943,39.61015
90.11601,7.50962,853.56878,-0.13656,26.37568,39.62641
90.31600,7.52642,853.24962,-0.13656,26.44288,39.61160
90.51601,7.54298,853.11159,-0.13656,26.50913,39.60519
90.71600,7.55972,853.21898,-0.13656,26.57609,39.61017
90.91601,7.57635,852.71560,-0.13656,26.64258,39.58680
91.11601,7.59297,852.87746,-0.13656,26.70906,39.59432
91.31600,7.60971,852.39196,-0.13656,26.77603,39.57178
91.51601,7.62633,853.55388,-0.13656,26.84252,39.62572
91.71600,7.64295,852.66158,-0.13656,26.90900,39.58430
91.91601,7.65969,852.70293,-0.13656,26.97597,39.58622
92.11601,7.67631,851.94968,-0.13656,27.04245,39.55125
92.31600,7.69305,852.43238,-0.13656,27.10942,39.57365
92.51601,7.70968,852.68170,-0.13656,27.17590,39.58523
92.71600,7.72630,852.35490,-0.13656,27.24239,39.57006
92.91601,7.74304,852.14125,-0.13656,27.30935,39.56014
93.11601,7.75960,851.86129,-0.13656,27.37560,39.54714
93.31600,7.77622,852.24062,-0.13656,27.44209,39.56475
93.51601,7.79302,851.27382,-0.13656,27.50929,39.51987
93.71600,7.80970,851.74246,-0.13656,27.57601,39.54163
93.91601,7.82627,852.04868,-0.13656,27.64226,39.55584
94.11601,7.84295,851.80402,-0.13656,27.70898,39.54448
94.31600,7.85969,850.74184,-0.13656,27.77595,39.49517
94.51601,7.87637,851.48495,-0.13656,27.84267,39.52967
94.71600,7.89305,851.44518,-0.13656,27.90940,39.52782
94.91601,7.90973,851.40141,-0.13656,27.97613,39.52579
95.11601,7.92629,851.37617,-0.13656,28.04237,39.52462
95.31600,7.94303,851.15544,-0.13656,28.10933,39.51437
95.51601,7.95972,850.69165,-0.13657,28.17606,39.49284
95.71600,7.97634,850.90250,-0.13657,28.24255,39.50263
95.91601,7.99302,850.64434,-0.13656,28.30927,39.49065
96.11601,8.00964,850.45770,-0.13656,28.37576,39.48198
96.31600,8.02632,850.63642,-0.13656,28.44248,39.49028
96.51601,8.04300,850.11516,-0.13657,28.50921,39.46608
96.71600,8.05962,850.14645,-0.13656,28.57569,39.46753
96.91601,8.07630,849.65872,-0.13656,28.64242,39.44489
97.11601,8.09293,849.61532,-0.13656,28.70890,39.44287
97.31600,8.10961,850.08442,-0.13656,28.77563,39.46465
97.51601,8.12629,849.70463,-0.13657,28.84235,39.44702
97.71600,8.14297,849.29075,-0.13657,28.90908,39.42781
97.91601,8.15971,850.29043,-0.13656,28.97604,39.47422
98.11601,8.17633,849.64270,-0.13656,29.04253,39.44415
98.31600,8.19301,848.71473,-0.13657,29.10925,39.40107
98.51601,8.20970,849.05978,-0.13657,29.17598,39.41708
98.71600,8.22632,848.87818,-0.13656,29.24246,39.40865
98.91601,8.24300,848.28893,-0.13657,29.30919,39.38130
99.11601,8.25962,848.50751,-0.13656,29.37568,39.39145
99.31600,8.27630,848.19477,-0.13657,29.44240,39.37693
99.51601,8.29298,848.09829,-0.13657,29.50913,39.37245
99.71600,8.30960,848.54569,-0.13657,29.57561,39.39322
99.91601,8.32634,847.66932,-0.13657,29.64258,39.35254
100.11601,8.34303,847.89097,-0.13657,29.70930,39.36282
100.31600,8.35965,847.39691,-0.13656,29.77578,39.33989
100.51601,8.37627,847.38303,-0.13656,29.84227,39.33924
100.71600,8.39301,847.64827,-0.13656,29.90924,39.35155
100.91601,8.40969,846.59886,-0.13657,29.97596,39.30284
101.11601,8.42631,847.18084,-0.13657,30.04245,39.32986
101.31600,8.44299,846.86158,-0.13657,30.10917,39.31504
101.51601,8.45973,846.60519,-0.13656,30.17614,39.30313
101.71600,8.47630,846.64123,-0.13657,30.24239,39.30481
101.91601,8.49292,846.24225,-0.13656,30.30887,39.28628
102.11601,8.50972,846.22800,-0.13657,30.37608,39.28562
102.31600,8.52634,845.13025,-0.13657,30.44256,39.23466
102.51601,8.54296,845.28998,-0.13657,30.50905,39.24207
102.71600,8.55964,845.64565,-0.13657,30.57577,39.25859
102.91601,8.57638,845.74660,-0.13657,30.64273,39.26327
103.11601,8.59301,844.95405,-0.13657,30.70922,39.22648
103.31600,8.60969,844.70045,-0.13657,30.77595,39.21471
103.51601,8.62643,844.32866,-0.13657,30.84291,39.19744
103.71600,8.64293,844.62771,-0.13657,30.90892,39.21133
103.91601,8.65961,845.05761,-0.13657,30.97564,39.23129
104.11601,8.67641,844.26310,-0.13657,31.04285,39.19440
104.31600,8.69297,843.98733,-0.13657,31.10909,39.18160
104.51601,8.70959,844.05253,-0.13657,31.17558,39.18463
104.71600,8.72628,844.06221,-0.13657,31.24231,39.18508
104.91601,8.74296,843.88005,-0.13657,31.30903,39.17662
105.11601,8.75964,843.30458,-0.13657,31.37575,39.14990
105.31600,8.77638,843.37695,-0.13657,31.44272,39.15326
105.51601,8.79306,842.71133,-0.13657,31.50944,39.12236
105.71600,8.80962,842.88903,-0.13657,31.57569,39.13061
105.91601,8.82630,842.37885,-0.13656,31.64242,39.10693
106.11601,8.84304,842.34076,-0.13657,31.70938,39.10516
106.31600,8.85967,841.38978,-0.13657,31.77586,39.06101
106.51601,8.87629,841.37321,-0.13657,31.84235,39.06024
106.71600,8.89303,841.60361,-0.13657,31.90931,39.07094
106.91601,8.90959,841.22811,-0.13657,31.97556,39.05350
107.11601,8.92621,841.05013,-0.13656,32.04205,39.04524
107.31600,8.94301,840.41478,-0.13657,32.10925,39.01575
107.51601,8.95969,840.21827,-0.13657,32.17598,39.00662
107.71600,8.97626,840.39513,-0.13657,32.24222,39.01484
107.91601,8.99300,839.63852,-0.13657,32.30919,38.97971
108.11601,9.00974,838.93659,-0.13657,32.37615,38.94712
108.31600,9.02624,839.11726,-0.13657,32.44216,38.95551
108.51601,9.04298,839.65175,-0.13657,32.50912,38.98032
108.71600,9.05984,838.78608,-0.13657,32.57657,38.94014
108.91601,9.07628,838.86674,-0.13657,32.64234,38.94388
109.11601,9.09297,838.34855,-0.13656,32.70906,38.91982
109.31600,9.10977,837.96624,-0.13657,32.77626,38.90207
109.51601,9.12639,837.31217,-0.13657,32.84275,38.87171
109.71600,9.14289,837.47339,-0.13657,32.90876,38.87919
109.91601,9.15969,837.41993,-0.13657,32.97596,38.87671
110.11601,9.17631,836.56358,-0.13657,33.04245,38.83696
110.31600,9.19293,836.53480,-0.13657,33.10893,38.83562
110.51601,9.20967,836.35151,-0.13657,33.17589,38.82711
110.71600,9.22647,835.78238,-0.13657,33.24310,38.80069
110.91601,9.24292,836.06485,-0.13657,33.30887,38.81380
111.11601,9.25966,835.41926,-0.13657,33.37583,38.78383
111.31600,9.27634,835.03909,-0.13657,33.44256,38.76618
111.51601,9.29296,834.64514,-0.13657,33.50905,38.74789
111.71600,9.30964,834.51364,-0.13657,33.57577,38.74179
111.91601,9.32632,834.33567,-0.13657,33.64249,38.73353
112.11601,9.34300,833.80295,-0.13657,33.70922,38.70880
112.31600,9.35957,833.63932,-0.13657,33.77547,38.70120
112.51601,9.37631,833.08928,-0.13657,33.84243,38.67566
112.71600,9.39305,832.80848,-0.13657,33.90940,38.66263
112.91601,9.40967,831.92196,-0.13657,33.97588,38.62147
113.11601,9.42635,832.04601,-0.13657,34.04261,38.62723
113.31600,9.44303,831.44661,-0.13657,34.10933,38.59940
113.51601,9.45965,830.97545,-0.13657,34.17582,38.57753
113.71600,9.47640,830.40735,-0.13657,34.24278,38.55116
113.91601,9.49308,830.77317,-0.13657,34.30950,38.56814
114.11601,9.50970,829.90946,-0.13657,34.37599,38.52804
114.31600,9.52626,830.73201,-0.13657,34.44224,38.56623
114.51601,9.54300,829.17828,-0.13657,34.50920,38.49410
114.71600,9.55974,828.30070,-0.13657,34.57617,38.45336
114.91601,9.57630,828.27145,-0.13657,34.64241,38.45200
115.11601,9.59293,827.73482,-0.13657,34.70890,38.42709
115.31600,9.60973,826.87298,-0.13657,34.77610,38.38708
115.51601,9.62629,826.84103,-0.13657,34.84235,38.38559
115.71600,9.64297,825.95320,-0.13657,34.90908,38.34438
115.91601,9.65971,825.72550,-0.13657,34.97604,38.33381
116.11601,9.67639,825.64512,-0.13657,35.04277,38.33007
116.31600,9.69295,825.53858,-0.13657,35.10901,38.32513
116.51601,9.70963,824.99459,-0.13657,35.17573,38.29987
116.71600,9.72643,824.41848,-0.13657,35.24294,38.27313
116.91601,9.74294,824.13545,-0.13657,35.30895,38.25999
117.11601,9.75968,823.34671,-0.13657,35.37591,38.22337
117.31600,9.77636,823.33023,-0.13657,35.44264,38.22261
117.51601,9.79292,822.35485,-0.13657,35.50888,38.17733
117.71600,9.80960,821.99285,-0.13657,35.57561,38.16052
117.91601,9.82634,821.50763,-0.13657,35.64257,38.13799
118.11601,9.84296,820.51400,-0.13657,35.70906,38.09187
118.31600,9.85970,819.79148,-0.13657,35.77602,38.05832
118.51601,9.87627,819.43814,-0.13657,35.84227,38.04192
118.71600,9.89301,819.05210,-0.13657,35.90923,38.02400
118.91601,9.90963,818.29028,-0.13657,35.97572,37.98863
119.11601,9.92637,818.36889,-0.13657,36.04268,37.99228
119.31600,9.94311,816.51546,-0.13657,36.10965,37.90623
119.51601,9.95967,816.94601,-0.13657,36.17589,37.92622
119.71600,9.97629,815.60928,-0.13657,36.24238,37.86417
119.91601,9.99298,814.98753,-0.13657,36.30910,37.83530
120.11601,10.00960,814.91275,-0.13657,36.37559,37.83183
120.31601,10.02628,813.69625,-0.13657,36.44232,37.77536
120.51601,10.04296,812.75571,-0.13657,36.50904,37.73169
120.71600,10.05964,812.37080,-0.13657,36.57576,37.71382
120.91601,10.07626,811.61913,-0.13657,36.64225,37.67892
121.11601,10.09300,810.96282,-0.13657,36.70922,37.64846
121.31601,10.10975,810.35709,-0.13657,36.77618,37.62033
121.51601,10.12631,809.87643,-0.13657,36.84242,37.59802
121.71600,10.14299,808.45375,-0.13657,36.90915,37.53197
121.91601,10.15979,807.81691,-0.13657,36.97635,37.50241
122.11601,10.17629,807.24107,-0.13657,37.04236,37.47568
122.31601,10.19297,805.78392,-0.13657,37.10909,37.40803
122.51601,10.20971,805.31752,-0.13657,37.17605,37.38638
122.71600,10.22633,804.20794,-0.13657,37.24253,37.33487
122.91601,10.24296,803.58768,-0.13657,37.30903,37.30607
123.11601,10.25964,802.00732,-0.13657,37.37575,37.23270
123.31601,10.27638,800.75609,-0.13657,37.44271,37.17461
123.51601,10.29300,799.23263,-0.13657,37.50920,37.10389
123.71600,10.30962,798.11504,-0.13657,37.57568,37.05201
123.91601,10.32642,796.84630,-0.13657,37.64289,36.99311
124.11601,10.34292,794.24512,-0.13657,37.70889,36.87235
124.31601,10.35967,791.96952,-0.13657,37.77586,36.76670
124.51601,10.37641,788.98324,-0.13657,37.84283,36.62807
124.71600,10.39303,787.50690,-0.13657,37.90931,36.55953
124.91601,10.40965,784.09072,-0.13657,37.97580,36.40094
125.11601,10.42627,781.38635,-0.13657,38.04228,36.27539
125.31601,10.44301,778.73557,-0.13657,38.10925,36.15232
125.51601,10.45963,775.08865,-0.13657,38.17573,35.98302
125.71600,10.47637,772.05980,-0.13657,38.24270,35.84241
125.91601,10.49300,768.91975,-0.13657,38.30918,35.69663
126.11601,10.50962,764.81160,-0.13657,38.37567,35.50591
126.31601,10.52630,760.53776,-0.13657,38.44239,35.30750
126.51601,10.54298,756.13759,-0.13657,38.50912,35.10323
126.71600,10.55966,751.33843,-0.13657,38.57584,34.88043
126.91601,10.57640,743.86043,-0.13657,38.64281,34.53327
127.11601,10.59308,215.41074,-0.13658,38.70953,10.00031
127.13601,10.59476,9.24869,-0.13658,38.71623,0.42936