File: Manufatura Aditiva/Dados/Ensaios AMR/Ensaios/Ensaios SLS/Tracao_OLABI_06_06_2018_SLS_XY1.is_metal_RawData/Specimen_RawData_5.csv
Time,Extension,Load,Strain 1,Tensile strain,Tensile stress
(sec),(mm),(N),(mm/mm),(%),(MPa)
0.00000,0.00006,29.28014,0.00125,0.12506,1.36983
0.20000,0.01387,35.32496,0.00144,0.14382,1.65263
0.40000,0.03270,45.75647,0.00175,0.17524,2.14065
0.60000,0.04980,54.56055,0.00205,0.20459,2.55254
0.80000,0.06673,63.58446,0.00232,0.23201,2.97471
1.00000,0.08335,71.54625,0.00260,0.25995,3.34719
1.20000,0.10003,79.80696,0.00288,0.28828,3.73366
1.40000,0.11677,88.70494,0.00316,0.31629,4.14994
1.60000,0.13339,97.03211,0.00344,0.34435,4.53951
1.80000,0.14995,104.61985,0.00372,0.37207,4.89450
2.00000,0.16657,112.82888,0.00400,0.39999,5.27854
2.20000,0.18325,120.60952,0.00428,0.42842,5.64255
2.40000,0.19994,127.64736,0.00456,0.45629,5.97181
2.60000,0.21668,135.88727,0.00485,0.48454,6.35730
2.80000,0.23336,143.09892,0.00513,0.51272,6.69469
3.00000,0.24998,150.73812,0.00541,0.54064,7.05208
3.20000,0.26672,158.10989,0.00569,0.56860,7.39695
3.40000,0.28340,166.42500,0.00597,0.59691,7.78596
3.60000,0.30002,173.85677,0.00625,0.62485,8.13365
3.80000,0.31665,180.29186,0.00653,0.65267,8.43471
4.00000,0.33327,188.00059,0.00681,0.68061,8.79535
4.20000,0.34995,195.88170,0.00709,0.70882,9.16406
4.40000,0.36663,202.93500,0.00738,0.73782,9.49403
4.60000,0.38331,210.02286,0.00767,0.76666,9.82563
4.80000,0.39999,215.41570,0.00789,0.78935,10.07793
5.00000,0.41661,222.93688,0.00817,0.81699,10.42980
5.20000,0.43335,229.82813,0.00844,0.84438,10.75219
5.40000,0.45010,237.52830,0.00873,0.87324,11.11244
5.60000,0.46666,243.90426,0.00901,0.90117,11.41073
5.80000,0.48334,251.26736,0.00929,0.92929,11.75520
6.00000,0.50002,258.00571,0.00958,0.95781,12.07044
6.20000,0.51664,264.72406,0.00986,0.98573,12.38475
6.40000,0.53326,272.12459,0.01014,1.01396,12.73098
6.60000,0.55000,279.05609,0.01044,1.04406,13.05526
6.80000,0.56674,285.84308,0.01072,1.07231,13.37278
7.00000,0.58331,292.58293,0.01101,1.10100,13.68809
7.20000,0.59993,299.38621,0.01129,1.12928,14.00637
7.40000,0.61673,305.40684,0.01158,1.15823,14.28804
7.60000,0.63335,311.82016,0.01187,1.18682,14.58808
7.80000,0.64997,319.16129,0.01215,1.21539,14.93152
8.00000,0.66671,325.44208,0.01245,1.24452,15.22536
8.20000,0.68333,331.74506,0.01273,1.27271,15.52024
8.40000,0.70002,337.44378,0.01302,1.30198,15.78684
8.60000,0.71664,344.08593,0.01332,1.33164,16.09759
8.80000,0.73344,348.97351,0.01356,1.35628,16.32625
9.00000,0.75000,354.55285,0.01385,1.38492,16.58727
9.20000,0.76662,361.37383,0.01414,1.41444,16.90638
9.40000,0.78342,367.02782,0.01444,1.44382,17.17089
9.60000,0.79998,373.27206,0.01473,1.47292,17.46302
9.80000,0.81660,378.33627,0.01502,1.50232,17.69994
10.00000,0.83341,384.17829,0.01532,1.53169,17.97325
10.20000,0.84997,389.75121,0.01562,1.56154,18.23397
10.40000,0.86671,395.95319,0.01592,1.59154,18.52413
10.60000,0.88333,401.27290,0.01621,1.62113,18.77300
10.80000,0.90007,407.45651,0.01651,1.65099,19.06229
11.00000,0.91669,412.29823,0.01680,1.68030,19.28881
11.20000,0.93331,417.87159,0.01710,1.71015,19.54955
11.40000,0.95000,422.86324,0.01740,1.74042,19.78308
11.60000,0.96656,428.60955,0.01771,1.77098,20.05191
11.80000,0.98330,433.95888,0.01801,1.80123,20.30217
12.00000,1.00010,437.13301,0.01824,1.82414,20.45067
12.20000,1.01666,442.72360,0.01855,1.85497,20.71222
12.40000,1.03328,448.13072,0.01886,1.88563,20.96518
12.60000,1.04996,453.87256,0.01916,1.91627,21.23380
12.80000,1.06664,458.38687,0.01947,1.94719,21.44500
13.00000,1.08333,463.09340,0.01978,1.97827,21.66519
13.20000,1.10001,467.47136,0.02009,2.00945,21.87000
13.40000,1.11675,472.82814,0.02040,2.04033,22.12062
13.60000,1.13319,477.41272,0.02072,2.07207,22.33510
13.80000,1.14993,481.95422,0.02104,2.10394,22.54757
14.00000,1.16673,487.59342,0.02136,2.13555,22.81139
14.20000,1.18329,491.09645,0.02168,2.16790,22.97527
14.40000,1.19998,496.57105,0.02200,2.19978,23.23139
14.60000,1.21672,500.45187,0.02232,2.23218,23.41295
14.80000,1.23334,504.26889,0.02265,2.26473,23.59153
15.00000,1.24996,508.94185,0.02297,2.29689,23.81014
15.20000,1.26664,513.42580,0.02329,2.32913,24.01992
15.40000,1.28344,517.02526,0.02361,2.36133,24.18832
15.60000,1.29994,518.95133,0.02389,2.38908,24.27843
15.80000,1.31656,523.82322,0.02422,2.42173,24.50635
16.00000,1.33343,527.00634,0.02454,2.45448,24.65527
16.20000,1.34993,530.71794,0.02487,2.48741,24.82891
16.40000,1.36667,535.02428,0.02521,2.52121,25.03038
16.60000,1.38341,539.17482,0.02555,2.55478,25.22455
16.80000,1.39997,541.74084,0.02588,2.58783,25.34460
17.00000,1.41659,545.53929,0.02622,2.62165,25.52231
17.20000,1.43333,549.16050,0.02655,2.65529,25.69172
17.40000,1.45001,552.27303,0.02689,2.68872,25.83734
17.60000,1.46664,555.74034,0.02723,2.72266,25.99955
17.80000,1.48320,559.20118,0.02757,2.75686,26.16146
18.00000,1.50006,562.72103,0.02791,2.79098,26.32613
18.20000,1.51656,565.51411,0.02825,2.82493,26.45680
18.40000,1.53330,568.31813,0.02859,2.85925,26.58798
18.60000,1.55004,571.97441,0.02894,2.89374,26.75904
18.80000,1.56666,574.71646,0.02928,2.92821,26.88732
19.00000,1.58341,577.98582,0.02963,2.96285,27.04027
19.20000,1.60003,581.08582,0.02997,2.99729,27.18530
19.40000,1.61665,584.08356,0.03032,3.03191,27.32555
19.60000,1.63339,586.98403,0.03066,3.08197,27.46124
19.76600,1.64726,589.02232,0.03095,3.13745,27.55660
19.96600,1.66370,591.19351,0.03124,3.20322,27.65818
20.16600,1.68044,593.29015,0.03159,3.27019,27.75626
20.36600,1.69712,596.32915,0.03194,3.33691,27.89844
20.56600,1.71387,599.11539,0.03229,3.40387,28.02879
20.76600,1.73049,601.63937,0.03265,3.47036,28.14687
20.96600,1.74711,604.08330,0.03300,3.53685,28.26121
21.16600,1.76385,607.00178,0.03335,3.60381,28.39774
21.36600,1.78041,609.83407,0.03370,3.67006,28.53025
21.56600,1.79715,612.26627,0.03406,3.73702,28.64404
21.76600,1.81401,614.72915,0.03442,3.80446,28.75926
21.96600,1.83052,617.61094,0.03477,3.87047,28.89408
22.16600,1.84714,619.39452,0.03512,3.93696,28.97752
22.36600,1.86382,621.70560,0.03549,4.00368,29.08564
22.56600,1.88056,624.34645,0.03584,4.07065,29.20919
22.76600,1.89712,627.04440,0.03620,4.13689,29.33541
22.96600,1.91380,629.07459,0.03657,4.20362,29.43039
23.16600,1.93054,631.13491,0.03693,4.27058,29.52678
23.36600,1.94710,633.80785,0.03729,4.33683,29.65183
23.56600,1.96385,636.10571,0.03766,4.40379,29.75933
23.76600,1.98065,638.24886,0.03808,4.47100,29.85960
23.96600,1.99721,640.52539,0.03771,4.53724,29.96610
24.16600,2.01383,642.23669,0.03880,4.60373,30.04616
24.36600,2.03051,643.79349,0.03888,4.67046,30.11899
24.56600,2.04719,645.30717,0.04277,4.73718,30.18981
24.76600,2.06381,648.15599,0.04130,4.80367,30.32309
24.96600,2.08044,650.06660,0.03665,4.87015,30.41247
25.16600,2.09712,652.14029,0.03666,4.93688,30.50949
25.36600,2.11374,655.11744,0.03109,5.00336,30.64877
25.56600,2.13042,656.28607,0.03115,5.07009,30.70344
25.76600,2.14716,657.09716,0.03096,5.13705,30.74139
25.96600,2.16384,659.05498,0.03860,5.20378,30.83298
26.16600,2.18058,660.85788,0.04427,5.27074,30.91733
26.36600,2.19714,663.48147,0.05046,5.33699,31.04007
26.56600,2.21383,665.36353,0.05792,5.40371,31.12812
26.76600,2.23057,667.61547,0.05847,5.47068,31.23347
26.96600,2.24719,669.09026,0.04430,5.53716,31.30247
27.16600,2.26393,670.60501,0.02192,5.60413,31.37333
27.36600,2.28049,672.97174,-0.02104,5.67037,31.48406
27.56600,2.29717,674.81366,-0.01166,5.73710,31.57023
27.76600,2.31385,676.12221,-0.06725,5.80382,31.63145
27.96600,2.33047,678.13848,-0.07413,5.87031,31.72578
28.16600,2.34716,679.63894,-0.07909,5.93704,31.79597
28.36600,2.36378,681.59536,-0.13289,6.00352,31.88750
28.56600,2.38046,683.45107,-0.13763,6.07025,31.97432
28.76600,2.39714,685.52513,-0.13771,6.13697,32.07135
28.96600,2.41382,686.89021,-0.13765,6.20370,32.13522
29.16600,2.43056,688.14382,-0.13747,6.27066,32.19386
29.36600,2.44718,690.73695,-0.13720,6.33715,32.31518
29.56600,2.46381,691.93430,-0.13687,6.40363,32.37120
29.76600,2.48055,693.96906,-0.13685,6.47060,32.46639
29.96600,2.49717,695.39659,-0.13632,6.53708,32.53317
30.16600,2.51385,697.14314,-0.11931,6.60381,32.61488
30.36600,2.53059,698.58832,-0.05605,6.67077,32.68250
30.56600,2.54715,699.85059,-0.05623,6.73702,32.74155
30.76600,2.56377,702.26085,-0.05624,6.80350,32.85431
30.96600,2.58045,703.24894,-0.05627,6.87023,32.90054
31.16600,2.59714,705.44672,-0.05628,6.93695,33.00336
31.36600,2.61376,706.56030,-0.05629,7.00344,33.05545
31.56600,2.63050,707.66998,-0.05631,7.07041,33.10737
31.76600,2.64718,709.36172,-0.05631,7.13713,33.18651
31.96600,2.66374,710.19395,-0.05632,7.20338,33.22545
32.16600,2.68048,711.89827,-0.05632,7.27034,33.30518
32.36600,2.69716,713.40757,-0.05633,7.33707,33.37579
32.56600,2.71385,715.24079,-0.05633,7.40379,33.46156
32.76600,2.73053,715.92140,-0.05633,7.47052,33.49340
32.96600,2.74715,717.82232,-0.05634,7.53700,33.58233
33.16600,2.76383,719.21954,-0.05634,7.60373,33.64770
33.36600,2.78051,720.83054,-0.05634,7.67045,33.72306
33.56600,2.79713,720.22490,-0.05634,7.73694,33.69473
33.76600,2.81381,722.12019,-0.05634,7.80366,33.78340
33.96600,2.83043,723.27121,-0.05635,7.87015,33.83725
34.16600,2.84712,724.93013,-0.05635,7.93687,33.91486
34.36600,2.86386,726.44432,-0.05635,8.00384,33.98570
34.56600,2.88054,727.31450,-0.05635,8.07056,34.02641
34.76600,2.89716,728.63740,-0.05636,8.13705,34.08830
34.96600,2.91390,730.27918,-0.05636,8.20401,34.16511
35.16600,2.93052,731.71621,-0.05636,8.27050,34.23234
35.36600,2.94708,732.83333,-0.05635,8.33675,34.28460
35.56600,2.96388,734.40489,-0.05636,8.40395,34.35812
35.76600,2.98057,735.48597,-0.05635,8.47067,34.40870
35.96600,2.99707,736.63970,-0.05635,8.53668,34.46268
36.16600,3.01381,737.61414,-0.05635,8.60365,34.50826
36.36600,3.03049,738.92041,-0.05635,8.67037,34.56937
36.56600,3.04711,740.12182,-0.05635,8.73686,34.62558
36.76600,3.06385,741.79503,-0.05636,8.80382,34.70386
36.96600,3.08065,742.56416,-0.05635,8.87103,34.73985
37.16600,3.09716,744.27426,-0.05635,8.93703,34.81985
37.36600,3.11384,744.90854,-0.05635,9.00376,34.84952
37.56600,3.13058,745.93453,-0.05635,9.07072,34.89752
37.76600,3.14720,747.45989,-0.05636,9.13721,34.96888
37.96600,3.16376,748.29222,-0.05635,9.20346,35.00782
38.16600,3.18050,748.87625,-0.05635,9.27042,35.03514
38.36600,3.19718,751.08390,-0.05635,9.33714,35.13843
38.56600,3.21375,751.14453,-0.05635,9.40339,35.14127
38.76600,3.23043,752.36959,-0.05635,9.47012,35.19858
38.96600,3.24717,754.20584,-0.05635,9.53708,35.28448
39.16600,3.26379,754.48365,-0.05635,9.60357,35.29748
39.36600,3.28047,755.98615,-0.05636,9.67029,35.36777
39.56600,3.29715,757.04758,-0.05635,9.73702,35.41743
39.76600,3.31377,758.11963,-0.05635,9.80350,35.46759
39.96600,3.33051,759.47419,-0.05635,9.87047,35.53096
40.16600,3.34720,759.79983,-0.05636,9.93719,35.54619
40.36600,3.36388,760.99155,-0.05635,10.00392,35.60194
40.56600,3.38044,761.46196,-0.05635,10.07016,35.62395
40.76600,3.39712,762.28357,-0.05635,10.13689,35.66239
40.96600,3.41392,763.52428,-0.05635,10.20409,35.72043
41.16600,3.43048,764.49774,-0.05635,10.27034,35.76598
41.36600,3.44710,765.38096,-0.05636,10.33682,35.80730
41.56600,3.46384,765.50674,-0.05635,10.40379,35.81318
41.76600,3.48047,766.97203,-0.05636,10.47028,35.88173
41.96600,3.49715,767.83369,-0.05635,10.53700,35.92204
42.16600,3.51389,769.90370,-0.05636,10.60396,36.01889
42.36600,3.53057,770.12940,-0.05635,10.67069,36.02945
42.56600,3.54713,771.07633,-0.05636,10.73694,36.07375
42.76600,3.56375,771.75777,-0.05635,10.80342,36.10563
42.96600,3.58061,772.52248,-0.05635,10.87086,36.14140
43.16600,3.59712,773.44105,-0.05635,10.93687,36.18438
43.36600,3.61380,774.48539,-0.05635,11.00360,36.23323
43.56600,3.63060,775.73820,-0.05635,11.07080,36.29185
43.76600,3.64710,776.01192,-0.05635,11.13681,36.30465
43.96600,3.66378,776.54249,-0.05635,11.20353,36.32947
44.16600,3.68058,777.89538,-0.05635,11.27074,36.39277
44.36600,3.69720,776.90626,-0.05635,11.33722,36.34649
44.56600,3.71376,778.11773,-0.05635,11.40347,36.40317
44.76600,3.73051,778.77571,-0.05635,11.47043,36.43395
44.96600,3.74731,779.92617,-0.05635,11.53764,36.48777
45.16600,3.76369,780.84148,-0.05635,11.60317,36.53059
45.36600,3.78049,780.75710,-0.05635,11.67037,36.52665
45.56600,3.79723,782.01797,-0.05635,11.73733,36.58564
45.76600,3.81379,782.88438,-0.05635,11.80358,36.62617
45.96600,3.83041,783.67544,-0.05635,11.87007,36.66318
46.16600,3.84721,784.52323,-0.05635,11.93727,36.70284
46.36600,3.86390,785.40612,-0.05635,12.00399,36.74414
46.56600,3.88052,785.77083,-0.05635,12.07048,36.76121
46.76600,3.89714,786.21283,-0.05635,12.13697,36.78189
46.96600,3.91382,786.88608,-0.05635,12.20369,36.81339
47.16600,3.93044,788.76121,-0.05635,12.27018,36.90111
47.36600,3.94712,788.82454,-0.05635,12.33690,36.90407
47.56600,3.96392,789.68126,-0.05635,12.40411,36.94415
47.76600,3.98043,790.20839,-0.05635,12.47011,36.96881
47.96600,3.99711,790.79149,-0.05635,12.53684,36.99609
48.16600,4.01385,791.29431,-0.05635,12.60380,37.01962
48.36600,4.03053,792.28049,-0.05635,12.67053,37.06575
48.56600,4.04715,792.71663,-0.05635,12.73701,37.08616
48.76600,4.06383,793.84437,-0.05635,12.80374,37.13892
48.96600,4.08051,794.54696,-0.05635,12.87046,37.17179
49.16600,4.09707,794.73034,-0.05635,12.93671,37.18037
49.36600,4.11382,795.90213,-0.05635,13.00367,37.23519
49.56600,4.13056,796.46427,-0.05634,13.07064,37.26149
49.76600,4.14712,796.47526,-0.05635,13.13689,37.26200
49.96600,4.16380,797.79187,-0.05634,13.20361,37.32360
50.16600,4.18054,798.14596,-0.05635,13.27057,37.34016
50.36600,4.19710,798.80478,-0.05635,13.33682,37.37098
50.56600,4.21384,799.61559,-0.05635,13.40379,37.40892
50.76600,4.23058,800.12316,-0.05635,13.47075,37.43266
50.96600,4.24715,800.59953,-0.05635,13.53700,37.45495
51.16600,4.26377,801.58673,-0.05635,13.60348,37.50113
51.36600,4.28057,801.98403,-0.05635,13.67069,37.51972
51.56600,4.29725,802.33160,-0.05635,13.73741,37.53598
51.76600,4.31375,802.33505,-0.05635,13.80342,37.53614
51.96600,4.33043,803.21115,-0.05635,13.87014,37.57713
52.16600,4.34723,804.00519,-0.05635,13.93735,37.61428
52.36600,4.36380,804.20468,-0.05635,14.00359,37.62361
52.56600,4.38048,805.00841,-0.05635,14.07032,37.66121
52.76600,4.39722,804.63644,-0.05635,14.13728,37.64381
52.96600,4.41390,805.95706,-0.05635,14.20401,37.70559
53.16600,4.43046,807.12028,-0.05635,14.27026,37.76001
53.36600,4.44714,807.37127,-0.05635,14.33698,37.77176
53.56600,4.46382,807.34110,-0.05635,14.40371,37.77034
53.76600,4.48051,808.09910,-0.05635,14.47043,37.80581
53.96600,4.49719,809.08388,-0.05635,14.53716,37.85188
54.16600,4.51375,808.97873,-0.05635,14.60340,37.84696
54.36600,4.53043,809.15038,-0.05635,14.67013,37.85499
54.56600,4.54711,809.82130,-0.05635,14.73685,37.88638
54.76600,4.56379,809.72193,-0.05635,14.80358,37.88173
54.96600,4.58053,810.81083,-0.05635,14.87054,37.93267
55.16600,4.59721,811.78239,-0.05635,14.93727,37.97812
55.36600,4.61384,811.82364,-0.05635,15.00375,37.98005
55.56600,4.63046,812.24907,-0.05635,15.07024,37.99996
55.76600,4.64720,812.54253,-0.05634,15.13720,38.01369
55.96600,4.66388,813.08223,-0.05635,15.20393,38.03894
56.16600,4.68062,813.61933,-0.05635,15.27089,38.06406
56.36600,4.69718,813.98068,-0.05634,15.33714,38.08097
56.56600,4.71374,814.33244,-0.05634,15.40339,38.09742
56.76600,4.73054,814.95680,-0.05634,15.47059,38.12663
56.96600,4.74717,815.25994,-0.05634,15.53708,38.14082
57.16600,4.76385,815.27010,-0.05635,15.60380,38.14129
57.36600,4.78047,815.72393,-0.05634,15.67029,38.16252
57.56600,4.79715,816.31513,-0.05634,15.73701,38.19018
57.76600,4.81383,817.03626,-0.05634,15.80374,38.22392
57.96600,4.83057,817.31630,-0.05635,15.87070,38.23702
58.16600,4.84725,817.54690,-0.05635,15.93743,38.24781
58.36600,4.86382,818.61308,-0.05635,16.00367,38.29769
58.56600,4.88050,818.11557,-0.05635,16.07040,38.27441
58.76600,4.89718,819.27646,-0.05635,16.13712,38.32872
58.96600,4.91380,819.06524,-0.05635,16.20361,38.31884
59.16600,4.93048,819.63735,-0.05635,16.27033,38.34561
59.36600,4.94722,819.56191,-0.05635,16.33730,38.34208
59.56600,4.96378,820.82199,-0.05635,16.40355,38.40103
59.76600,4.98046,821.03191,-0.05635,16.47027,38.41085
59.96600,4.99715,820.67270,-0.05635,16.53699,38.39404
60.16600,5.01383,821.06581,-0.05635,16.60372,38.41244
60.36600,5.03057,821.94982,-0.05635,16.67068,38.45379
60.56600,5.04713,821.68924,-0.05635,16.73693,38.44160
60.76600,5.06387,823.10252,-0.05635,16.80389,38.50772
60.96600,5.08049,822.40039,-0.05635,16.87038,38.47487
61.16600,5.09711,822.64524,-0.05635,16.93687,38.48633
61.36600,5.11386,822.70587,-0.05635,17.00383,38.48916
61.56600,5.13048,823.15374,-0.05635,17.07032,38.51012
61.76600,5.14716,823.80697,-0.05635,17.13704,38.54068
61.96600,5.16384,824.57643,-0.05635,17.20377,38.57668
62.16600,5.18052,824.17661,-0.05635,17.27049,38.55797
62.36600,5.19714,824.86933,-0.05635,17.33698,38.59038
62.56600,5.21382,824.59236,-0.05635,17.40370,38.57742
62.76600,5.23044,824.78318,-0.05635,17.47019,38.58635
62.96600,5.24713,825.26030,-0.05635,17.53691,38.60867
63.16600,5.26381,825.15907,-0.05636,17.60364,38.60393
63.36600,5.28055,825.99251,-0.05635,17.67060,38.64293
63.56600,5.29717,826.07660,-0.05635,17.73709,38.64686
63.76600,5.31385,826.51144,-0.05634,17.80381,38.66720
63.96600,5.33047,826.65933,-0.05634,17.87030,38.67412
64.16600,5.34715,827.16485,-0.05635,17.93703,38.69777
64.36600,5.36383,827.02544,-0.05634,18.00375,38.69125
64.56600,5.38046,826.96695,-0.05635,18.07024,38.68851
64.76601,5.39720,827.98088,-0.05635,18.13720,38.73595
64.96600,5.41376,827.33119,-0.05634,18.20345,38.70555
65.16600,5.43044,828.19266,-0.05634,18.27017,38.74586
65.36600,5.44718,828.28430,-0.05634,18.33714,38.75014
65.56600,5.46374,828.28403,-0.05634,18.40338,38.75013
65.76601,5.48054,829.17903,-0.05634,18.47059,38.79200
65.96600,5.49723,829.09996,-0.05634,18.53731,38.78830
66.16600,5.51379,829.28808,-0.05634,18.60356,38.79710
66.36601,5.53047,829.99514,-0.05634,18.67028,38.83018
66.56600,5.54721,829.91710,-0.05634,18.73725,38.82653
66.76601,5.56389,829.72031,-0.05634,18.80397,38.81733
66.96600,5.58045,830.66309,-0.05634,18.87022,38.86143
67.16600,5.59713,830.28888,-0.05634,18.93695,38.84393
67.36601,5.61387,830.78500,-0.05634,19.00391,38.86713
67.56600,5.63044,830.49349,-0.05634,19.07016,38.85350
67.76601,5.64712,829.15742,-0.05634,19.13688,38.79099
67.96600,5.66386,830.30434,-0.05634,19.20385,38.84465
68.16600,5.68042,830.13922,-0.05634,19.27009,38.83692
68.36601,5.69716,830.62984,-0.05634,19.33706,38.85987
68.56600,5.71384,830.66709,-0.05634,19.40378,38.86162
68.76601,5.73052,831.33392,-0.05634,19.47051,38.89281
68.96600,5.74720,830.61531,-0.05634,19.53723,38.85920
69.16600,5.76389,831.21033,-0.05634,19.60396,38.88703
69.36601,5.78057,831.58063,-0.05634,19.67068,38.90436
69.56600,5.79707,832.16727,-0.05634,19.73669,38.93180
69.76601,5.81381,832.50394,-0.05634,19.80365,38.94755
69.96600,5.83055,832.27726,-0.05635,19.87062,38.93695
70.16600,5.84717,832.35204,-0.05635,19.93710,38.94044
70.36601,5.86379,832.92639,-0.05635,20.00359,38.96732
70.56600,5.88048,832.65845,-0.05635,20.07031,38.95478
70.76601,5.89716,833.38860,-0.05634,20.13704,38.98894
70.96600,5.91384,833.56183,-0.05634,20.20376,38.99704
71.16600,5.93052,833.17505,-0.05635,20.27049,38.97895
71.36601,5.94720,833.84151,-0.05635,20.33721,39.01013
71.56600,5.96382,833.84514,-0.05634,20.40370,39.01030
71.76601,5.98050,834.12901,-0.05635,20.47043,39.02358
71.96600,5.99724,834.63266,-0.05634,20.53739,39.04714
72.16600,6.01381,834.35746,-0.05634,20.60364,39.03427
72.36601,6.03049,833.95038,-0.05635,20.67036,39.01522
72.56600,6.04717,834.96207,-0.05635,20.73709,39.06255
72.76601,6.06385,835.29474,-0.05634,20.80381,39.07812
72.96600,6.08041,834.94512,-0.05635,20.87006,39.06176
73.16600,6.09721,834.97856,-0.05635,20.93726,39.06332
73.36601,6.11395,835.63682,-0.05634,21.00423,39.09412
73.56600,6.13046,835.63626,-0.05634,21.07023,39.09409
73.76601,6.14714,834.95444,-0.05634,21.13696,39.06219
73.96600,6.16388,835.46191,-0.05634,21.20392,39.08594
74.16600,6.18050,835.20487,-0.05635,21.27041,39.07391
74.36601,6.19718,835.42429,-0.05635,21.33714,39.08418
74.56600,6.21386,835.43090,-0.05635,21.40386,39.08449
74.76601,6.23042,836.38811,-0.05634,21.47011,39.12927
74.96600,6.24710,835.94862,-0.05634,21.53683,39.10871
75.16600,6.26385,836.30569,-0.05635,21.60379,39.12541
75.36601,6.28059,836.39435,-0.05634,21.67076,39.12956
75.56600,6.29709,836.05815,-0.05634,21.73677,39.11383
75.76601,6.31377,836.28949,-0.05634,21.80349,39.12465
75.96600,6.33051,836.82761,-0.05634,21.87046,39.14983
76.16600,6.34713,835.64734,-0.05634,21.93694,39.09461
76.36601,6.36387,836.37098,-0.05634,22.00391,39.12847
76.56600,6.38061,836.10704,-0.05634,22.07087,39.11612
76.76601,6.39706,836.68493,-0.05634,22.13664,39.14315
76.96600,6.41374,836.70793,-0.05634,22.20337,39.14423
77.16600,6.43054,836.78942,-0.05634,22.27057,39.14804
77.36601,6.44716,836.59999,-0.05634,22.33705,39.13918
77.56600,6.46384,836.51217,-0.05635,22.40378,39.13507
77.76601,6.48052,836.48795,-0.05635,22.47050,39.13394
77.96600,6.49714,836.18248,-0.05634,22.53699,39.11965
78.16600,6.51377,836.95706,-0.05634,22.60348,39.15589
78.36601,6.53039,836.56386,-0.05634,22.66996,39.13749
78.56600,6.54731,836.51068,-0.05635,22.73764,39.13500
78.76601,6.56387,837.74216,-0.05634,22.80389,39.19262
78.96600,6.58043,837.06751,-0.05634,22.87014,39.16105
79.16600,6.59723,837.31767,-0.05635,22.93734,39.17276
79.36601,6.61379,837.04712,-0.05634,23.00359,39.16010
79.56600,6.63048,837.23972,-0.05635,23.07031,39.16911
79.76601,6.64728,837.40680,-0.05635,23.13751,39.17693
79.96600,6.66390,836.35449,-0.05635,23.20400,39.12770
80.16600,6.68040,837.76666,-0.05635,23.27001,39.19376
80.36601,6.69714,836.91971,-0.05635,23.33697,39.15414
80.56600,6.71400,837.38882,-0.05635,23.40441,39.17609
80.76601,6.73050,837.05913,-0.05634,23.47042,39.16066
80.96600,6.74706,836.96619,-0.05634,23.53667,39.15631
81.16600,6.76387,837.77560,-0.05634,23.60387,39.19418
81.36601,6.78043,838.03404,-0.05634,23.67012,39.20627
81.56600,6.79711,836.92782,-0.05634,23.73685,39.15452
81.76601,6.81397,837.45765,-0.05634,23.80429,39.17931
81.96600,6.83047,837.77858,-0.05634,23.87030,39.19432
82.16600,6.84709,837.14947,-0.05634,23.93678,39.16489
82.36601,6.86377,837.12228,-0.05634,24.00351,39.16362
82.56600,6.88052,837.95507,-0.05633,24.07047,39.20258
82.76601,6.89720,837.32251,-0.05634,24.13719,39.17298
82.96600,6.91382,837.30994,-0.05634,24.20368,39.17239
83.16600,6.93050,836.98044,-0.05634,24.27041,39.15698
83.36601,6.94712,837.74459,-0.05634,24.33689,39.19273
83.56600,6.96374,837.70668,-0.05634,24.40338,39.19096
83.76601,6.98054,837.90123,-0.05633,24.47058,39.20006
83.96600,6.99716,837.81220,-0.05634,24.53707,39.19589
84.16600,7.01385,836.90668,-0.05634,24.60379,39.15353
84.36601,7.03047,837.38230,-0.05634,24.67028,39.17578
84.56600,7.04715,837.15115,-0.05634,24.73700,39.16497
84.76601,7.06383,837.05541,-0.05634,24.80373,39.16049
84.96600,7.08051,837.21755,-0.05634,24.87046,39.16807
85.16600,7.09725,836.96349,-0.05634,24.93742,39.15619
85.36601,7.11375,837.58952,-0.05634,25.00343,39.18547
85.56600,7.13043,836.27980,-0.05634,25.07015,39.12420
85.76601,7.14718,836.55333,-0.05634,25.13711,39.13700
85.96600,7.16386,836.93704,-0.05633,25.20384,39.15495
86.16600,7.18048,837.20740,-0.05634,25.27032,39.16760
86.36601,7.19716,836.90854,-0.05634,25.33705,39.15361
86.56600,7.21384,837.05606,-0.05634,25.40378,39.16052
86.76601,7.23046,836.97541,-0.05634,25.47026,39.15675
86.96600,7.24714,836.76409,-0.05634,25.53699,39.14686
87.16600,7.26395,837.05680,-0.05634,25.60419,39.16055
87.36601,7.28051,835.92478,-0.05634,25.67044,39.10759
87.56600,7.29713,837.05755,-0.05634,25.73693,39.16059
87.76601,7.31393,837.05587,-0.05634,25.80413,39.16051
87.96600,7.33049,836.15119,-0.05634,25.87037,39.11818
88.16601,7.34711,836.63343,-0.05634,25.93686,39.14074
88.36601,7.36379,836.97261,-0.05634,26.00358,39.15661
88.56600,7.38047,836.24534,-0.05634,26.07031,39.12259
88.76601,7.39710,836.76055,-0.05634,26.13680,39.14669
88.96600,7.41378,836.70579,-0.05634,26.20352,39.14413
89.16601,7.43052,836.51002,-0.05633,26.27048,39.13497
89.36601,7.44720,836.34639,-0.05634,26.33721,39.12732
89.56600,7.46388,836.23445,-0.05634,26.40394,39.12208
89.76601,7.48050,835.56892,-0.05634,26.47042,39.09094
89.96600,7.49718,836.73866,-0.05634,26.53715,39.14567
90.16601,7.51392,835.89181,-0.05634,26.60411,39.10605
90.36601,7.53055,836.25261,-0.05634,26.67060,39.12293
90.56600,7.54717,835.08352,-0.05634,26.73708,39.06823
90.76601,7.56385,836.39771,-0.05634,26.80381,39.12972
90.96600,7.58047,835.50299,-0.05634,26.87029,39.08786
91.16601,7.59721,835.77996,-0.05634,26.93726,39.10082
91.36601,7.61383,836.05936,-0.05634,27.00374,39.11389
91.56600,7.63045,835.16501,-0.05634,27.07023,39.07205
91.76601,7.64714,834.92491,-0.05634,27.13696,39.06081
91.96600,7.66388,835.34941,-0.05634,27.20392,39.08067
92.16601,7.68050,835.54704,-0.05634,27.27041,39.08992
92.36601,7.69718,835.18019,-0.05634,27.33713,39.07276
92.56600,7.71392,834.99169,-0.05635,27.40409,39.06394
92.76601,7.73048,835.09218,-0.05634,27.47034,39.06864
92.96600,7.74716,834.81772,-0.05634,27.53707,39.05580
93.16601,7.76384,835.04422,-0.05634,27.60379,39.06639
93.36601,7.78041,835.24697,-0.05634,27.67004,39.07588
93.56600,7.79715,834.77711,-0.05634,27.73700,39.05390
93.76601,7.81389,834.83979,-0.05634,27.80397,39.05683
93.96600,7.83045,834.57502,-0.05634,27.87021,39.04445
94.16601,7.84713,834.17371,-0.05635,27.93694,39.02567
94.36601,7.86387,833.95531,-0.05634,28.00390,39.01545
94.56600,7.88055,834.36975,-0.05634,28.07063,39.03484
94.76601,7.89717,833.85650,-0.05634,28.13711,39.01083
94.96600,7.91386,834.31322,-0.05634,28.20384,39.03220
95.16601,7.93048,834.20947,-0.05634,28.27033,39.02734
95.36601,7.94716,833.97403,-0.05634,28.33705,39.01633
95.56600,7.96378,833.53072,-0.05634,28.40354,38.99559
95.76601,7.98052,833.65887,-0.05634,28.47050,39.00158
95.96600,7.99714,833.51098,-0.05634,28.53698,38.99467
96.16601,8.01382,833.76924,-0.05634,28.60371,39.00675
96.36601,8.03051,833.37510,-0.05634,28.67044,38.98831
96.56600,8.04713,833.57589,-0.05634,28.73692,38.99770
96.76601,8.06381,832.88783,-0.05634,28.80364,38.96551
96.96600,8.08049,832.93524,-0.05634,28.87037,38.96773
97.16601,8.09711,832.92546,-0.05634,28.93686,38.96727
97.36601,8.11373,833.11889,-0.05634,29.00334,38.97632
97.56600,8.13047,832.93328,-0.05634,29.07031,38.96764
97.76601,8.14716,832.73379,-0.05634,29.13703,38.95831
97.96600,8.16384,832.97268,-0.05634,29.20375,38.96948
98.16601,8.18052,832.81584,-0.05634,29.27049,38.96214
98.36601,8.19720,832.30501,-0.05634,29.33721,38.93825
98.56600,8.21382,831.93844,-0.05634,29.40369,38.92110
98.76601,8.23050,831.80759,-0.05634,29.47042,38.91497
98.96600,8.24718,831.57215,-0.05634,29.53714,38.90396
99.16601,8.26386,831.90156,-0.05634,29.60387,38.91937
99.36601,8.28049,831.81160,-0.05634,29.67036,38.91516
99.56600,8.29705,831.57532,-0.05634,29.73660,38.90411
99.76601,8.31385,831.62617,-0.05634,29.80380,38.90649
99.96600,8.33053,831.73756,-0.05634,29.87053,38.91170
100.16601,8.34715,831.47073,-0.05634,29.93701,38.89922
100.36601,8.36389,831.79595,-0.05634,30.00398,38.91443
100.56600,8.38045,830.60758,-0.05634,30.07023,38.85883
100.76601,8.39713,830.68190,-0.05634,30.13695,38.86231
100.96600,8.41394,830.96381,-0.05634,30.20416,38.87550
101.16601,8.43050,830.77587,-0.05634,30.27040,38.86671
101.36601,8.44712,830.42653,-0.05634,30.33689,38.85036
101.56600,8.46386,830.49685,-0.05633,30.40385,38.85365
101.76601,8.48054,829.96832,-0.05633,30.47058,38.82893
101.96600,8.49710,829.67859,-0.05634,30.53682,38.81537
102.16601,8.51378,829.99533,-0.05633,30.60355,38.83019
102.36601,8.53059,829.34611,-0.05634,30.67075,38.79982
102.56600,8.54721,829.41400,-0.05634,30.73724,38.80299
102.76601,8.56377,829.18294,-0.05634,30.80348,38.79218
102.96600,8.58057,829.30019,-0.05634,30.87069,38.79767
103.16601,8.59719,829.27467,-0.05634,30.93717,38.79647
103.36601,8.61387,828.72808,-0.05634,31.00390,38.77090
103.56600,8.63055,828.86824,-0.05634,31.07063,38.77746
103.76601,8.64712,829.23258,-0.05634,31.13687,38.79451
103.96600,8.66380,827.93385,-0.05634,31.20359,38.73375
104.16601,8.68042,828.10093,-0.05634,31.27008,38.74157
104.36601,8.69716,827.73538,-0.05634,31.33705,38.72446
104.56600,8.71372,827.97650,-0.05633,31.40329,38.73574
104.76601,8.73040,827.43196,-0.05634,31.47002,38.71027
104.96600,8.74720,827.28490,-0.05634,31.53722,38.70339
105.16601,8.76382,827.41482,-0.05635,31.60371,38.70947
105.36601,8.78051,827.40365,-0.05634,31.67043,38.70894
105.56600,8.79725,827.07312,-0.05634,31.73740,38.69348
105.76601,8.81387,826.46012,-0.05634,31.80388,38.66480
105.96600,8.83049,826.92737,-0.05634,31.87037,38.68666
106.16601,8.84717,826.68765,-0.05634,31.93709,38.67545
106.36601,8.86391,826.83628,-0.05634,32.00406,38.68240
106.56600,8.88047,826.06785,-0.05634,32.07030,38.64645
106.76601,8.89710,826.48611,-0.05633,32.13679,38.66602
106.96600,8.91384,825.20973,-0.05634,32.20375,38.60630
107.16601,8.93040,825.98990,-0.05633,32.27000,38.64280
107.36601,8.94714,825.38733,-0.05634,32.33697,38.61461
107.56600,8.96400,825.41704,-0.05634,32.40441,38.61600
107.76601,8.98044,825.46677,-0.05634,32.47018,38.61833
107.96600,8.99712,825.02486,-0.05634,32.53690,38.59766
108.16601,9.01386,824.38625,-0.05633,32.60386,38.56778
108.36601,9.03048,825.02868,-0.05634,32.67035,38.59783
108.56600,9.04717,824.50453,-0.05634,32.73708,38.57331
108.76601,9.06391,824.05284,-0.05634,32.80404,38.55218
108.96600,9.08053,823.38247,-0.05634,32.87053,38.52082
109.16601,9.09709,824.07780,-0.05634,32.93678,38.55335
109.36601,9.11383,823.66774,-0.05634,33.00374,38.53416
109.56600,9.13063,823.56930,-0.05634,33.07094,38.52956
109.76601,9.14713,823.13837,-0.05634,33.13695,38.50940
109.96600,9.16376,822.71211,-0.05633,33.20343,38.48946
110.16601,9.18050,822.31509,-0.05634,33.27040,38.47088
110.36601,9.19718,821.90121,-0.05634,33.33713,38.45152
110.56600,9.21386,821.93278,-0.05634,33.40385,38.45300
110.76601,9.23054,821.98195,-0.05634,33.47058,38.45530
110.96600,9.24716,821.48779,-0.05634,33.53706,38.43218
111.16601,9.26378,821.21091,-0.05634,33.60355,38.41922
111.36601,9.28046,820.86558,-0.05634,33.67027,38.40307
111.56600,9.29721,821.18418,-0.05634,33.73724,38.41797
111.76601,9.31383,820.98423,-0.05634,33.80372,38.40862
111.96600,9.33051,820.72355,-0.05634,33.87044,38.39642
112.16601,9.34719,820.17258,-0.05634,33.93717,38.37065
112.36601,9.36381,819.82119,-0.05634,34.00366,38.35421
112.56600,9.38049,819.49607,-0.05634,34.07038,38.33900
112.76601,9.39717,819.22803,-0.05634,34.13711,38.32646
112.96600,9.41392,819.72321,-0.05634,34.20407,38.34962
113.16601,9.43048,818.86910,-0.05634,34.27032,38.30967
113.36601,9.44716,818.60274,-0.05634,34.33705,38.29720
113.56600,9.46384,818.46034,-0.05634,34.40377,38.29054
113.76601,9.48052,817.63975,-0.05634,34.47049,38.25215
113.96600,9.49720,817.98993,-0.05634,34.53722,38.26854
114.16601,9.51388,817.35570,-0.05634,34.60394,38.23886
114.36601,9.53044,817.58602,-0.05634,34.67019,38.24964
114.56600,9.54713,816.10642,-0.05634,34.73692,38.18042
114.76601,9.56387,816.52449,-0.05634,34.80388,38.19998
114.96600,9.58055,816.38452,-0.05634,34.87061,38.19343
115.16601,9.59711,816.11481,-0.05634,34.93685,38.18081
115.36601,9.61379,815.77273,-0.05634,35.00358,38.16481
115.56600,9.63053,815.86419,-0.05634,35.07054,38.16909
115.76601,9.64709,815.69273,-0.05634,35.13679,38.16106
115.96600,9.66389,814.84644,-0.05634,35.20399,38.12147
116.16601,9.68058,815.04853,-0.05634,35.27072,38.13092
116.36601,9.69708,814.01234,-0.05634,35.33672,38.08245
116.56600,9.71376,814.07046,-0.05634,35.40345,38.08517
116.76601,9.73056,813.47050,-0.05634,35.47066,38.05710
116.96600,9.74718,813.24186,-0.05633,35.53714,38.04640
117.16601,9.76380,812.62514,-0.05634,35.60363,38.01755
117.36601,9.78048,811.98253,-0.05633,35.67035,37.98749
117.56600,9.79717,811.84162,-0.05634,35.73707,37.98090
117.76601,9.81379,811.53307,-0.05634,35.80356,37.96646
117.96600,9.83047,811.25628,-0.05634,35.87028,37.95351
118.16601,9.84715,811.10736,-0.05634,35.93701,37.94654
118.36601,9.86383,810.66163,-0.05634,36.00373,37.92569
118.56600,9.88045,810.20677,-0.05633,36.07022,37.90441
118.76601,9.89719,809.25841,-0.05634,36.13719,37.86004
118.96600,9.91387,809.54824,-0.05633,36.20391,37.87360
119.16601,9.93056,808.69710,-0.05634,36.27063,37.83378
119.36601,9.94724,808.36192,-0.05634,36.33736,37.81810
119.56600,9.96386,807.06254,-0.05634,36.40384,37.75731
119.76601,9.98048,807.08442,-0.05633,36.47033,37.75834
119.96600,9.99710,807.04903,-0.05633,36.53682,37.75668
120.16601,10.01384,805.88805,-0.05634,36.60378,37.70237
120.36601,10.03046,805.41559,-0.05633,36.67027,37.68026
120.56601,10.04715,804.77549,-0.05634,36.73700,37.65031
120.76601,10.06383,804.10000,-0.05634,36.80372,37.61871
120.96600,10.08051,803.45133,-0.05633,36.87044,37.58837
121.16601,10.09713,803.04425,-0.05634,36.93693,37.56932
121.36601,10.11387,802.44029,-0.05634,37.00390,37.54107
121.56601,10.13049,801.58450,-0.05633,37.07038,37.50103
121.76601,10.14717,800.24591,-0.05633,37.13711,37.43840
121.96600,10.16386,800.10444,-0.05633,37.20383,37.43179
122.16601,10.18054,798.80822,-0.05633,37.27055,37.37114
122.36601,10.19716,797.85269,-0.05633,37.33704,37.32644
122.56601,10.21384,797.71569,-0.05633,37.40377,37.32003
122.76601,10.23052,796.70474,-0.05634,37.47049,37.27274
122.96600,10.24708,794.78752,-0.05634,37.53674,37.18304
123.16601,10.26376,794.41387,-0.05634,37.60346,37.16556
123.36601,10.28056,792.64557,-0.05634,37.67067,37.08283
123.56601,10.29724,791.90303,-0.05634,37.73739,37.04810
123.76601,10.31381,790.27358,-0.05634,37.80364,36.97186
123.96600,10.33049,788.90715,-0.05634,37.87036,36.90794
124.16601,10.34717,786.07230,-0.05633,37.93709,36.77531
124.36601,10.36385,784.19494,-0.05634,38.00381,36.68748
124.56601,10.38053,781.41754,-0.05633,38.07054,36.55754
124.76601,10.39721,777.45230,-0.05634,38.13726,36.37204
124.96600,10.41371,770.45360,-0.05634,38.20327,36.04461
125.16601,10.43052,747.89901,-0.05633,38.27048,34.98943
125.23601,10.43643,5.92137,-0.05633,38.29415,0.27702