File: Manufatura Aditiva/Dados/Ensaios AMR/Ensaios/Ensaios SLS/Tracao_OLABI_06_06_2018_SLS_XY1.is_metal_RawData/Specimen_RawData_3.csv
Time,Extension,Load,Strain 1,Tensile strain,Tensile stress
(sec),(mm),(N),(mm/mm),(%),(MPa)
0.00000,0.00006,24.40095,0.00124,0.12363,1.14983
0.20000,0.01381,31.08542,0.00142,0.14225,1.46481
0.40000,0.03270,40.57367,0.00174,0.17358,1.91192
0.60000,0.04986,49.57807,0.00203,0.20302,2.33623
0.80000,0.06673,57.90392,0.00231,0.23071,2.72856
1.00000,0.08335,66.70213,0.00258,0.25792,3.14315
1.20000,0.10009,75.06080,0.00285,0.28526,3.53703
1.40000,0.11677,83.45731,0.00313,0.31337,3.93270
1.60000,0.13339,91.02990,0.00341,0.34070,4.28953
1.80000,0.14995,98.87979,0.00368,0.36803,4.65944
2.00000,0.16657,105.19308,0.00391,0.39086,4.95693
2.20000,0.18325,113.60798,0.00418,0.41831,5.35346
2.40000,0.19994,120.63081,0.00446,0.44560,5.68439
2.60000,0.21668,128.15485,0.00473,0.47327,6.03894
2.80000,0.23336,135.93512,0.00501,0.50066,6.40557
3.00000,0.24998,143.46670,0.00528,0.52824,6.76047
3.20000,0.26672,150.72338,0.00555,0.55515,7.10242
3.40000,0.28340,157.40237,0.00579,0.57911,7.41715
3.60000,0.30008,164.23347,0.00607,0.60720,7.73905
3.80000,0.31665,171.49827,0.00634,0.63411,8.08138
4.00000,0.33327,177.86181,0.00661,0.66115,8.38125
4.20000,0.34995,185.82280,0.00688,0.68848,8.75639
4.40000,0.36663,193.29004,0.00716,0.71558,9.10826
4.60000,0.38331,200.34288,0.00743,0.74251,9.44061
4.80000,0.39999,206.38139,0.00766,0.76579,9.72515
5.00000,0.41661,212.75727,0.00793,0.79272,10.02560
5.20000,0.43335,220.10095,0.00820,0.81984,10.37165
5.40000,0.45004,226.71993,0.00847,0.84674,10.68355
5.60000,0.46666,233.41232,0.00874,0.87385,10.99891
5.80000,0.48334,240.45550,0.00901,0.90075,11.33080
6.00000,0.50002,246.85403,0.00924,0.92409,11.63232
6.20000,0.51664,253.14668,0.00951,0.95129,11.92884
6.40000,0.53326,259.66433,0.00978,0.97811,12.23597
6.60000,0.55000,266.70161,0.01005,1.00524,12.56758
6.80000,0.56674,273.86690,0.01033,1.03276,12.90522
7.00000,0.58331,278.97116,0.01055,1.05512,13.14575
7.20000,0.59993,285.24387,0.01082,1.08200,13.44133
7.40000,0.61673,291.27006,0.01109,1.10900,13.72530
7.60000,0.63329,297.82425,0.01135,1.13490,14.03415
7.80000,0.64997,302.56165,0.01158,1.15807,14.25738
8.00000,0.66671,309.13372,0.01185,1.18528,14.56707
8.20000,0.68333,315.14503,0.01212,1.21243,14.85034
8.40000,0.70002,320.56016,0.01238,1.23760,15.10551
8.60000,0.71664,325.82455,0.01263,1.26309,15.35358
8.80000,0.73344,332.32083,0.01290,1.28955,15.65970
9.00000,0.75000,337.42858,0.01314,1.31421,15.90039
9.20000,0.76662,343.00876,0.01339,1.33946,16.16334
9.40000,0.78336,348.74729,0.01366,1.36554,16.43376
9.60000,0.79998,354.02365,0.01391,1.39053,16.68239
9.80000,0.81660,358.36641,0.01413,1.41334,16.88703
10.00000,0.83341,364.35882,0.01440,1.43968,17.16940
10.20000,0.84997,368.45454,0.01465,1.46492,17.36241
10.40000,0.86671,373.51982,0.01487,1.48737,17.60109
10.60000,0.88333,377.78330,0.01513,1.51283,17.80200
10.80000,0.90007,382.84718,0.01538,1.53808,18.04062
11.00000,0.91669,387.37033,0.01563,1.56283,18.25376
11.20000,0.93331,391.93761,0.01586,1.58596,18.46898
11.40000,0.95000,396.96265,0.01612,1.61158,18.70577
11.60000,0.96656,402.19454,0.01637,1.63656,18.95231
11.80000,0.98330,405.59839,0.01659,1.65926,19.11271
12.00000,1.00004,410.81118,0.01686,1.68558,19.35835
12.20000,1.01666,415.66938,0.01712,1.71179,19.58727
12.40000,1.03334,419.35053,0.01738,1.73764,19.76074
12.60000,1.04996,424.34921,0.01761,1.76133,19.99629
12.80000,1.06664,429.28681,0.01788,1.78772,20.22896
13.00000,1.08333,433.66686,0.01814,1.81389,20.43536
13.20000,1.10001,437.24244,0.01838,1.83759,20.60385
13.40000,1.11675,441.96243,0.01863,1.86264,20.82626
13.60000,1.13319,447.34031,0.01890,1.88998,21.07968
13.80000,1.14993,451.53303,0.01916,1.91638,21.27725
14.00000,1.16673,455.00309,0.01941,1.94088,21.44077
14.20000,1.18329,459.67023,0.01969,1.96874,21.66069
14.40000,1.19998,464.02663,0.01996,1.99645,21.86598
14.60000,1.21672,468.42927,0.02024,2.02387,22.07344
14.80000,1.23334,471.68937,0.02048,2.04810,22.22706
15.00000,1.24996,476.34933,0.02077,2.07685,22.44665
15.20000,1.26664,480.27225,0.02105,2.10454,22.63151
15.40000,1.28344,483.54892,0.02129,2.12881,22.78591
15.60000,1.29994,488.65611,0.02157,2.15750,23.02657
15.80000,1.31656,492.36007,0.02186,2.18627,23.20111
16.00000,1.33343,496.63577,0.02214,2.21444,23.40259
16.20000,1.34993,499.59994,0.02240,2.23963,23.54227
16.40000,1.36667,503.65911,0.02270,2.26953,23.73355
16.60000,1.38341,507.73462,0.02299,2.29871,23.92559
16.80000,1.39997,510.31061,0.02324,2.32356,24.04698
17.00000,1.41659,514.15730,0.02353,2.35315,24.22825
17.20000,1.43333,518.02099,0.02383,2.38289,24.41031
17.40000,1.45001,520.30981,0.02409,2.40882,24.51817
17.60000,1.46664,524.34597,0.02438,2.43816,24.70836
17.80000,1.48326,528.65413,0.02469,2.46858,24.91137
18.00000,1.50000,530.78681,0.02495,2.49472,25.01187
18.20000,1.51662,534.03219,0.02525,2.52518,25.16479
18.40000,1.53330,537.80181,0.02555,2.55546,25.34243
18.60000,1.55004,541.38415,0.02585,2.58501,25.51124
18.80000,1.56666,542.69014,0.02612,2.61220,25.57278
19.00000,1.58341,547.34033,0.02643,2.64334,25.79190
19.20000,1.60003,550.34179,0.02674,2.67382,25.93334
19.40000,1.61665,552.46912,0.02701,2.70098,26.03358
19.60000,1.63339,555.86295,0.02732,2.73161,26.19351
19.80000,1.65001,559.26149,0.02763,2.76273,26.35366
20.00000,1.66663,563.06757,0.02794,2.79396,26.53301
20.20000,1.68325,565.47415,0.02824,2.82429,26.64641
20.40000,1.69993,567.37680,0.02852,2.85187,26.73607
20.60000,1.71668,570.49403,0.02884,2.88416,26.88296
20.80000,1.73330,572.90909,0.02915,2.91505,26.99676
21.00000,1.74992,576.45929,0.02946,2.94630,27.16405
21.20000,1.76666,578.31891,0.02974,2.97416,27.25168
21.40000,1.78334,581.38995,0.03006,3.00630,27.39640
21.60000,1.80002,584.61549,0.03038,3.03849,27.54839
21.80000,1.81676,586.39091,0.03070,3.08803,27.63206
21.98400,1.83201,589.58530,0.03099,3.14902,27.78258
22.18400,1.84863,591.73596,0.03131,3.21550,27.88393
22.38400,1.86531,593.58650,0.03160,3.28223,27.97113
22.58400,1.88205,596.02605,0.03193,3.34919,28.08609
22.78400,1.89862,599.11474,0.03225,3.41544,28.23163
22.98400,1.91530,602.01297,0.03257,3.48216,28.36820
23.18400,1.93204,604.26951,0.03290,3.54913,28.47453
23.38400,1.94860,606.96290,0.03323,3.61537,28.60145
23.58400,1.96534,609.22583,0.03355,3.68234,28.70809
23.78400,1.98208,611.32945,0.03387,3.74930,28.80722
23.98400,1.99870,613.85799,0.03420,3.81579,28.92637
24.18400,2.01532,615.76399,0.03452,3.88227,29.01618
24.38400,2.03201,618.35544,0.03484,3.94900,29.13830
24.58400,2.04869,620.39886,0.03517,4.01572,29.23459
24.78400,2.06531,622.27533,0.03550,4.08221,29.32301
24.98400,2.08193,624.45947,0.03583,4.14870,29.42593
25.18400,2.09861,626.54866,0.03615,4.21542,29.52438
25.38400,2.11523,628.84088,0.03648,4.28191,29.63239
25.58400,2.13191,631.08727,0.03682,4.34863,29.73825
25.78400,2.14866,633.68287,0.03728,4.41560,29.86056
25.98400,2.16534,635.40479,0.03704,4.48232,29.94170
26.18400,2.18208,636.71595,0.03653,4.54929,30.00348
26.38400,2.19870,640.14988,0.03037,4.61577,30.16530
26.58400,2.21538,642.51050,0.02528,4.68250,30.27654
26.78400,2.23206,643.77529,0.02284,4.74922,30.33614
26.98400,2.24868,645.49646,0.01864,4.81571,30.41724
27.18400,2.26542,647.56526,0.01426,4.88267,30.51473
27.38400,2.28199,648.32941,0.01123,4.94892,30.55074
27.58400,2.29867,650.38614,0.01086,5.01564,30.64766
27.78400,2.31535,651.92496,0.02145,5.08237,30.72017
27.98400,2.33197,653.70067,0.01747,5.14885,30.80384
28.18400,2.34865,655.57477,0.04140,5.21558,30.89215
28.38400,2.36527,657.82708,0.05497,5.28207,30.99829
28.58400,2.38195,659.72893,0.05097,5.34879,31.08791
28.78400,2.39863,661.26883,0.05364,5.41552,31.16047
28.98400,2.41532,663.06666,0.05133,5.48224,31.24519
29.18400,2.43206,664.43384,0.00007,5.54921,31.30961
29.38400,2.44862,666.62100,-0.04727,5.61545,31.41268
29.58400,2.46536,668.47196,-0.13604,5.68242,31.49990
29.78400,2.48210,669.55783,-0.13617,5.74938,31.55107
29.98400,2.49860,671.82700,-0.13618,5.81539,31.65800
30.18400,2.51528,673.36680,-0.13618,5.88211,31.73055
30.38400,2.53203,674.82628,-0.13618,5.94908,31.79933
30.58400,2.54871,677.20059,-0.13619,6.01580,31.91121
30.78400,2.56527,678.55399,-0.13619,6.08205,31.97499
30.98400,2.58195,679.98795,-0.13619,6.14877,32.04256
31.18400,2.59869,681.75094,-0.13619,6.21574,32.12563
31.38400,2.61525,683.68427,-0.13620,6.28198,32.21674
31.58400,2.63199,684.76046,-0.13620,6.34895,32.26745
31.78400,2.64873,686.92542,-0.13620,6.41591,32.36947
31.98400,2.66524,688.55109,-0.13620,6.48192,32.44607
32.18400,2.68204,689.47165,-0.13620,6.54912,32.48945
32.38400,2.69866,691.73784,-0.13620,6.61561,32.59624
32.58400,2.71540,692.81557,-0.13620,6.68257,32.64703
32.78400,2.73208,694.44370,-0.13620,6.74930,32.72375
32.98400,2.74864,696.27846,-0.13620,6.81555,32.81020
33.18400,2.76532,697.56899,-0.13620,6.88227,32.87102
33.38400,2.78201,699.70018,-0.13620,6.94900,32.97144
33.58400,2.79869,699.96235,-0.13621,7.01572,32.98380
33.78400,2.81537,701.86979,-0.13621,7.08245,33.07368
33.98400,2.83193,703.35711,-0.13620,7.14869,33.14376
34.18400,2.84861,704.54325,-0.13621,7.21542,33.19966
34.38400,2.86535,705.78489,-0.13621,7.28238,33.25817
34.58400,2.88209,707.40483,-0.13621,7.34935,33.33450
34.78400,2.89871,708.51650,-0.13621,7.41583,33.38689
34.98400,2.91534,709.60410,-0.13621,7.48232,33.43814
35.18400,2.93202,711.21529,-0.13621,7.54904,33.51406
35.38400,2.94858,712.98536,-0.13621,7.61529,33.59747
35.58400,2.96538,714.26355,-0.13621,7.68249,33.65770
35.78400,2.98212,714.79278,-0.13621,7.74946,33.68264
35.98400,2.99862,716.48816,-0.13621,7.81547,33.76253
36.18400,3.01524,718.28831,-0.13621,7.88195,33.84736
36.38400,3.03204,718.54908,-0.13621,7.94915,33.85965
36.58400,3.04861,720.40572,-0.13621,8.01540,33.94714
36.78400,3.06535,721.50691,-0.13621,8.08237,33.99902
36.98400,3.08209,722.26268,-0.13622,8.14933,34.03464
37.18400,3.09865,724.29203,-0.13621,8.21558,34.13027
37.38400,3.11533,724.81385,-0.13621,8.28230,34.15485
37.58400,3.13207,726.75422,-0.13622,8.34927,34.24629
37.78400,3.14875,727.48684,-0.13622,8.41599,34.28081
37.98400,3.16526,729.58302,-0.13621,8.48200,34.37959
38.18400,3.18200,730.20882,-0.13621,8.54896,34.40908
38.38400,3.19868,731.74383,-0.13622,8.61569,34.48141
38.58400,3.21524,732.77112,-0.13622,8.68194,34.52982
38.78400,3.23192,733.29336,-0.13622,8.74866,34.55443
38.98400,3.24866,734.72890,-0.13622,8.81562,34.62207
39.18400,3.26534,736.11173,-0.13622,8.88235,34.68724
39.38400,3.28196,736.91201,-0.13622,8.94883,34.72495
39.58400,3.29865,738.51598,-0.13622,9.01556,34.80053
39.78400,3.31533,739.73695,-0.13622,9.08229,34.85807
39.98400,3.33201,740.38007,-0.13622,9.14901,34.88837
40.18400,3.34875,742.05380,-0.13622,9.21597,34.96724
40.38400,3.36537,742.28011,-0.13622,9.28246,34.97791
40.58400,3.38193,743.09055,-0.13622,9.34871,35.01609
40.78400,3.39861,744.91948,-0.13622,9.41543,35.10228
40.98400,3.41541,745.51618,-0.13622,9.48264,35.13039
41.18400,3.43198,746.66739,-0.13622,9.54888,35.18464
41.38400,3.44860,747.93785,-0.13622,9.61537,35.24451
41.58400,3.46534,748.82940,-0.13622,9.68233,35.28652
41.78400,3.48196,749.78373,-0.13622,9.74882,35.33149
41.98400,3.49864,750.66877,-0.13622,9.81554,35.37320
42.18400,3.51538,751.29052,-0.13622,9.88251,35.40250
42.38400,3.53206,752.99405,-0.13623,9.94923,35.48277
42.58400,3.54857,753.89929,-0.13622,10.01524,35.52542
42.78400,3.56525,755.40706,-0.13622,10.08196,35.59648
42.98400,3.58217,755.53004,-0.13622,10.14965,35.60227
43.18400,3.59867,756.75314,-0.13623,10.21565,35.65991
43.38400,3.61523,757.90342,-0.13622,10.28190,35.71411
43.58400,3.63203,753.52518,-0.13622,10.34911,35.50780
43.78400,3.64865,755.38331,-0.13622,10.41559,35.59536
43.98400,3.66528,756.26532,-0.13623,10.48208,35.63692
44.18400,3.68208,757.63087,-0.13622,10.54928,35.70127
44.38400,3.69876,759.52783,-0.13622,10.61601,35.79066
44.58400,3.71526,760.31056,-0.13622,10.68201,35.82754
44.78400,3.73200,762.17605,-0.13623,10.74898,35.91545
44.98400,3.74880,762.74206,-0.13623,10.81618,35.94212
45.18400,3.76524,764.18878,-0.13622,10.88195,36.01029
45.38400,3.78192,764.53998,-0.13622,10.94867,36.02684
45.58400,3.79873,766.74521,-0.13623,11.01588,36.13076
45.78400,3.81535,767.23360,-0.13623,11.08236,36.15377
45.98400,3.83191,768.09209,-0.13623,11.14861,36.19422
46.18400,3.84877,769.35962,-0.13622,11.21605,36.25395
46.38400,3.86539,769.88228,-0.13622,11.28254,36.27858
46.58400,3.88201,771.11232,-0.13623,11.34902,36.33654
46.78400,3.89857,771.78562,-0.13623,11.41527,36.36827
46.98400,3.91531,773.07126,-0.13623,11.48224,36.42885
47.18400,3.93200,774.47044,-0.13622,11.54896,36.49479
47.38400,3.94862,774.71491,-0.13623,11.61545,36.50631
47.58400,3.96542,775.08255,-0.13623,11.68265,36.52363
47.78400,3.98192,776.20377,-0.13623,11.74866,36.57647
47.98400,3.99860,776.61271,-0.13623,11.81538,36.59573
48.18400,4.01534,777.55852,-0.13623,11.88235,36.64030
48.38400,4.03202,779.03359,-0.13623,11.94907,36.70981
48.58400,4.04865,779.92296,-0.13623,12.01556,36.75172
48.78400,4.06533,780.22801,-0.13623,12.08228,36.76609
48.98400,4.08201,781.64367,-0.13623,12.14901,36.83281
49.18400,4.09863,782.15050,-0.13623,12.21549,36.85669
49.38400,4.11525,782.69690,-0.13623,12.28198,36.88243
49.58400,4.13211,783.45481,-0.13623,12.34942,36.91815
49.78400,4.14861,784.04509,-0.13623,12.41543,36.94596
49.98400,4.16529,784.65873,-0.13623,12.48215,36.97488
50.18400,4.18204,784.90768,-0.13623,12.54912,36.98661
50.38400,4.19860,782.81965,-0.13623,12.61537,36.88822
50.58400,4.21534,783.75293,-0.13623,12.68233,36.93220
50.78400,4.23202,784.88616,-0.13623,12.74906,36.98560
50.98400,4.24870,785.85949,-0.13623,12.81578,37.03146
51.18400,4.26526,787.39543,-0.13623,12.88203,37.10384
51.38400,4.28200,788.22467,-0.13623,12.94899,37.14292
51.58400,4.29874,788.95884,-0.13623,13.01596,37.17751
51.78400,4.31531,789.69598,-0.13623,13.08220,37.21225
51.98400,4.33193,790.43740,-0.13623,13.14869,37.24718
52.18400,4.34873,791.36621,-0.13623,13.21589,37.29095
52.38400,4.36529,791.84696,-0.13623,13.28214,37.31361
52.58400,4.38197,791.86289,-0.13623,13.34886,37.31436
52.78400,4.39865,793.16031,-0.13623,13.41559,37.37550
52.98400,4.41539,793.88609,-0.13623,13.48255,37.40969
53.18400,4.43196,794.32260,-0.13623,13.54880,37.43026
53.38400,4.44864,795.25691,-0.13623,13.61552,37.47429
53.58400,4.46538,795.89421,-0.13623,13.68249,37.50432
53.78400,4.48200,796.53999,-0.13623,13.74898,37.53475
53.98400,4.49862,796.79787,-0.13623,13.81546,37.54691
54.18400,4.51524,797.76691,-0.13623,13.88195,37.59257
54.38400,4.53192,798.12808,-0.13623,13.94867,37.60958
54.58400,4.54866,799.25852,-0.13623,14.01564,37.66286
54.78400,4.56529,799.70546,-0.13623,14.08212,37.68392
54.98400,4.58203,800.45173,-0.13623,14.14909,37.71908
55.18400,4.59871,800.44018,-0.13623,14.21581,37.71854
55.38400,4.61533,800.97364,-0.13623,14.28230,37.74368
55.58400,4.63201,801.57788,-0.13623,14.34902,37.77215
55.78400,4.64869,802.00927,-0.13623,14.41575,37.79248
55.98400,4.66537,803.11913,-0.13623,14.48247,37.84478
56.18400,4.68211,803.44127,-0.13623,14.54944,37.85995
56.38400,4.69868,803.37254,-0.13623,14.61568,37.85672
56.58400,4.71530,804.21818,-0.13623,14.68217,37.89656
56.78400,4.73198,804.08333,-0.13623,14.74890,37.89021
56.98400,4.74866,805.23863,-0.13623,14.81562,37.94465
57.18400,4.76534,805.49708,-0.13623,14.88235,37.95683
57.38400,4.78196,805.86849,-0.13623,14.94883,37.97433
57.58400,4.79864,806.94044,-0.13623,15.01556,38.02485
57.78400,4.81533,807.39418,-0.13623,15.08228,38.04623
57.98400,4.83201,808.21598,-0.13623,15.14901,38.08495
58.18400,4.84875,807.99107,-0.13623,15.21597,38.07435
58.38400,4.86531,808.92453,-0.13623,15.28222,38.11834
58.58400,4.88199,809.44933,-0.13623,15.34894,38.14307
58.78400,4.89867,809.54358,-0.13623,15.41567,38.14751
58.98400,4.91529,810.34983,-0.13623,15.48215,38.18550
59.18400,4.93198,810.38335,-0.13623,15.54888,38.18708
59.38400,4.94872,810.92147,-0.13623,15.61584,38.21244
59.58400,4.96534,811.12767,-0.13624,15.68233,38.22216
59.78400,4.98196,807.54440,-0.13623,15.74881,38.05331
59.98400,4.99864,808.67093,-0.13623,15.81554,38.10639
60.18400,5.01538,809.62805,-0.13623,15.88250,38.15149
60.38400,5.03200,810.44948,-0.13623,15.94899,38.19020
60.58400,5.04868,811.16809,-0.13623,16.01571,38.22406
60.78400,5.06531,811.67677,-0.13623,16.08220,38.24803
60.98400,5.08199,812.51338,-0.13624,16.14892,38.28745
61.18400,5.09861,813.00465,-0.13623,16.21541,38.31060
61.38400,5.11535,813.08633,-0.13623,16.28238,38.31445
61.58400,5.13197,813.65770,-0.13624,16.34886,38.34138
61.78400,5.14865,814.54851,-0.13623,16.41558,38.38335
61.98400,5.16533,815.00141,-0.13623,16.48231,38.40470
62.18400,5.18202,815.87443,-0.13624,16.54904,38.44584
62.38400,5.19864,816.09916,-0.13624,16.61552,38.45642
62.58400,5.21532,816.17441,-0.13623,16.68225,38.45997
62.78400,5.23200,816.71122,-0.13624,16.74897,38.48527
62.98400,5.24862,816.93027,-0.13624,16.81546,38.49559
63.18400,5.26530,817.32217,-0.13624,16.88218,38.51406
63.38400,5.28204,818.17154,-0.13624,16.94915,38.55408
63.58400,5.29872,817.95687,-0.13624,17.01587,38.54396
63.78400,5.31535,818.68675,-0.13624,17.08236,38.57836
63.98400,5.33197,819.09560,-0.13623,17.14884,38.59762
64.18400,5.34865,819.36270,-0.13624,17.21557,38.61021
64.38400,5.36533,819.50342,-0.13624,17.28230,38.61684
64.58400,5.38195,819.70328,-0.13624,17.34878,38.62626
64.78400,5.39869,820.30762,-0.13624,17.41574,38.65474
64.98400,5.41531,821.74707,-0.13623,17.48223,38.72256
65.18400,5.43193,820.76434,-0.13624,17.54872,38.67626
65.38400,5.44868,820.66273,-0.13624,17.61568,38.67147
65.58400,5.46530,821.94693,-0.13624,17.68216,38.73198
65.78401,5.48204,822.31443,-0.13624,17.74913,38.74930
65.98400,5.49872,821.93548,-0.13624,17.81586,38.73145
66.18401,5.51528,822.85330,-0.13624,17.88210,38.77469
66.38400,5.53196,822.68259,-0.13624,17.94883,38.76665
66.58400,5.54870,823.50951,-0.13623,18.01579,38.80561
66.78401,5.56544,824.14234,-0.13624,18.08275,38.83544
66.98400,5.58201,823.77782,-0.13624,18.14900,38.81826
67.18401,5.59863,823.75100,-0.13624,18.21549,38.81700
67.38400,5.61537,823.89582,-0.13624,18.28245,38.82382
67.58400,5.63199,824.26844,-0.13624,18.34894,38.84138
67.78401,5.64867,824.67645,-0.13624,18.41567,38.86061
67.98400,5.66535,825.37336,-0.13624,18.48239,38.89344
68.18401,5.68192,825.15683,-0.13623,18.54864,38.88324
68.38400,5.69866,825.43297,-0.13624,18.61560,38.89626
68.58400,5.71534,825.88801,-0.13624,18.68233,38.91770
68.78401,5.73202,826.49058,-0.13624,18.74905,38.94609
68.98400,5.74870,827.10097,-0.13624,18.81578,38.97485
69.18401,5.76532,826.02547,-0.13624,18.88226,38.92418
69.38400,5.78200,826.98846,-0.13624,18.94899,38.96955
69.58400,5.79862,826.94236,-0.13624,19.01547,38.96738
69.78401,5.81537,827.77627,-0.13624,19.08244,39.00668
69.98400,5.83205,827.46632,-0.13624,19.14916,38.99207
70.18401,5.84867,827.47685,-0.13624,19.21565,38.99257
70.38400,5.86529,828.30284,-0.13624,19.28213,39.03149
70.58400,5.88197,827.86186,-0.13624,19.34886,39.01071
70.78401,5.89871,827.81147,-0.13624,19.41582,39.00834
70.98400,5.91539,828.66587,-0.13624,19.48255,39.04860
71.18401,5.93195,829.08077,-0.13624,19.54879,39.06815
71.38400,5.94870,828.62899,-0.13624,19.61576,39.04686
71.58400,5.96532,829.38699,-0.13624,19.68224,39.08258
71.78401,5.98200,828.85427,-0.13624,19.74897,39.05747
71.98400,5.99880,829.78727,-0.13624,19.81617,39.10144
72.18401,6.01536,829.49819,-0.13624,19.88242,39.08782
72.38400,6.03198,830.10467,-0.13624,19.94891,39.11639
72.58400,6.04866,829.78895,-0.13624,20.01563,39.10152
72.78401,6.06534,830.58430,-0.13624,20.08236,39.13900
72.98400,6.08191,829.97819,-0.13624,20.14860,39.11044
73.18401,6.09865,830.80325,-0.13624,20.21557,39.14931
73.38400,6.11545,830.72828,-0.13624,20.28277,39.14578
73.58401,6.13195,830.75585,-0.13624,20.34878,39.14708
73.78401,6.14863,830.65853,-0.13624,20.41550,39.14249
73.98400,6.16537,831.37676,-0.13624,20.48247,39.17634
74.18401,6.18199,831.16200,-0.13624,20.54895,39.16622
74.38400,6.19868,831.16200,-0.13624,20.61568,39.16622
74.58401,6.21536,831.39585,-0.13624,20.68240,39.17724
74.78401,6.23198,831.54617,-0.13624,20.74889,39.18432
74.98400,6.24860,832.24354,-0.13624,20.81537,39.21718
75.18401,6.26534,832.09937,-0.13624,20.88234,39.21039
75.38400,6.28208,831.61937,-0.13624,20.94930,39.18777
75.58401,6.29858,831.55986,-0.13624,21.01531,39.18497
75.78401,6.31527,832.45672,-0.13624,21.08204,39.22723
75.98400,6.33201,832.85728,-0.13624,21.14900,39.24611
76.18401,6.34863,832.84816,-0.13624,21.21549,39.24567
76.38400,6.36543,832.39013,-0.13624,21.28269,39.22409
76.58401,6.38205,829.66955,-0.13624,21.34918,39.09589
76.78401,6.39861,829.77591,-0.13624,21.41542,39.10090
76.98400,6.41523,830.28870,-0.13624,21.48191,39.12507
77.18401,6.43203,830.38732,-0.13624,21.54911,39.12971
77.38400,6.44871,831.18910,-0.13624,21.61584,39.16750
77.58401,6.46534,831.17550,-0.13624,21.68232,39.16685
77.78401,6.48196,831.88294,-0.13624,21.74881,39.20019
77.98400,6.49870,831.72554,-0.13624,21.81577,39.19278
78.18401,6.51526,832.13579,-0.13624,21.88202,39.21210
78.38400,6.53194,833.38367,-0.13624,21.94874,39.27091
78.58401,6.54880,832.75707,-0.13624,22.01619,39.24138
78.78401,6.56536,833.22553,-0.13624,22.08243,39.26346
78.98400,6.58193,833.67396,-0.13624,22.14868,39.28459
79.18401,6.59873,833.38097,-0.13624,22.21588,39.27078
79.38400,6.61535,834.09715,-0.13624,22.28237,39.30453
79.58401,6.63191,834.20752,-0.13625,22.34862,39.30973
79.78401,6.64871,834.69031,-0.13624,22.41582,39.33248
79.98400,6.66545,834.09585,-0.13625,22.48279,39.30447
80.18401,6.68189,834.73828,-0.13624,22.54855,39.33474
80.38400,6.69864,834.83038,-0.13624,22.61552,39.33908
80.58401,6.71550,834.41185,-0.13624,22.68296,39.31936
80.78401,6.73200,834.73334,-0.13624,22.74897,39.33451
80.98400,6.74856,834.69134,-0.13624,22.81521,39.33253
81.18401,6.76536,835.34485,-0.13624,22.88242,39.36332
81.38400,6.78198,834.83057,-0.13624,22.94890,39.33909
81.58401,6.79860,835.35472,-0.13624,23.01539,39.36379
81.78401,6.81540,834.44128,-0.13624,23.08259,39.32075
81.98400,6.83197,835.91305,-0.13624,23.14884,39.39010
82.18401,6.84859,835.66410,-0.13624,23.21533,39.37837
82.38400,6.86527,835.33591,-0.13624,23.28205,39.36290
82.58401,6.88201,835.31206,-0.13625,23.34902,39.36178
82.78401,6.89869,835.16110,-0.13624,23.41574,39.35466
82.98400,6.91531,835.77074,-0.13624,23.48223,39.38339
83.18401,6.93199,835.84376,-0.13624,23.54895,39.38683
83.38400,6.94862,835.46955,-0.13624,23.61544,39.36920
83.58401,6.96530,835.56138,-0.13624,23.68216,39.37353
83.78401,6.98198,835.01711,-0.13624,23.74889,39.34788
83.98400,6.99872,835.83891,-0.13624,23.81585,39.38660
84.18401,7.01534,835.40212,-0.13624,23.88234,39.36602
84.38400,7.03196,835.64948,-0.13624,23.94882,39.37768
84.58401,7.04870,835.73461,-0.13624,24.01579,39.38169
84.78401,7.06532,835.84338,-0.13625,24.08227,39.38682
84.98400,7.08201,836.25726,-0.13624,24.14900,39.40632
85.18401,7.09875,836.18714,-0.13624,24.21596,39.40302
85.38400,7.11531,835.49619,-0.13625,24.28221,39.37046
85.58401,7.13199,836.22877,-0.13624,24.34893,39.40498
85.78401,7.14867,835.26950,-0.13624,24.41566,39.35978
85.98400,7.16535,835.90755,-0.13624,24.48238,39.38984
86.18401,7.18197,836.02984,-0.13624,24.54887,39.39560
86.38400,7.19865,835.58140,-0.13625,24.61560,39.37447
86.58401,7.21534,835.71095,-0.13625,24.68232,39.38058
86.78401,7.23196,835.97731,-0.13624,24.74881,39.39313
86.98400,7.24864,835.60245,-0.13625,24.81553,39.37546
87.18401,7.26544,835.80948,-0.13625,24.88273,39.38522
87.38400,7.28200,836.13973,-0.13624,24.94898,39.40078
87.58401,7.29862,836.33196,-0.13624,25.01547,39.40984
87.78401,7.31542,835.76255,-0.13624,25.08267,39.38301
87.98400,7.33205,835.88324,-0.13624,25.14916,39.38869
88.18401,7.34861,836.47501,-0.13624,25.21541,39.41658
88.38400,7.36529,835.56399,-0.13624,25.28213,39.37365
88.58401,7.38197,835.89228,-0.13624,25.34885,39.38912
88.78401,7.39859,836.01708,-0.13624,25.41534,39.39500
88.98400,7.41533,835.46769,-0.13624,25.48231,39.36911
89.18401,7.43201,835.78229,-0.13624,25.54903,39.38394
89.38400,7.44869,835.66606,-0.13625,25.61575,39.37846
89.58401,7.46538,835.13781,-0.13624,25.68248,39.35357
89.78401,7.48206,835.71589,-0.13625,25.74920,39.38081
89.98400,7.49868,835.58084,-0.13625,25.81569,39.37444
90.18401,7.51542,835.64809,-0.13624,25.88265,39.37761
90.38400,7.53204,835.41637,-0.13625,25.94914,39.36670
90.58401,7.54872,835.21605,-0.13625,26.01587,39.35725
90.78401,7.56534,835.52254,-0.13625,26.08235,39.37170
90.98400,7.58197,835.14322,-0.13625,26.14884,39.35382
91.18401,7.59865,835.04682,-0.13625,26.21557,39.34928
91.38400,7.61539,835.64771,-0.13624,26.28253,39.37759
91.58401,7.63195,835.48669,-0.13625,26.34877,39.37001
91.78401,7.64869,835.02633,-0.13625,26.41574,39.34832
91.98400,7.66537,835.56958,-0.13625,26.48246,39.37391
92.18401,7.68199,834.87052,-0.13624,26.54895,39.34097
92.38400,7.69867,835.30229,-0.13625,26.61567,39.36132
92.58401,7.71542,835.49954,-0.13624,26.68264,39.37061
92.78401,7.73204,835.46843,-0.13625,26.74912,39.36915
92.98400,7.74860,834.94484,-0.13624,26.81537,39.34447
93.18401,7.76534,835.04375,-0.13625,26.88234,39.34914
93.38400,7.78190,834.44240,-0.13624,26.94858,39.32080
93.58401,7.79864,834.69450,-0.13624,27.01555,39.33268
93.78401,7.81538,835.15700,-0.13624,27.08251,39.35447
93.98400,7.83188,834.95593,-0.13625,27.14851,39.34500
94.18401,7.84863,834.81614,-0.13625,27.21548,39.33841
94.38400,7.86537,834.88496,-0.13624,27.28245,39.34165
94.58401,7.88205,834.27951,-0.13625,27.34917,39.31312
94.78401,7.89867,834.43765,-0.13625,27.41565,39.32058
94.98400,7.91529,834.62195,-0.13625,27.48214,39.32926
95.18401,7.93203,834.16561,-0.13625,27.54911,39.30775
95.38400,7.94865,834.86941,-0.13625,27.61559,39.34092
95.58401,7.96528,834.26256,-0.13625,27.68208,39.31232
95.78401,7.98202,833.96351,-0.13625,27.74904,39.29823
95.98400,7.99864,833.77492,-0.13625,27.81553,39.28934
96.18401,8.01532,833.93101,-0.13625,27.88225,39.29670
96.38400,8.03200,834.07601,-0.13624,27.94898,39.30354
96.58401,8.04868,833.34791,-0.13624,28.01570,39.26922
96.78401,8.06530,833.39587,-0.13625,28.08219,39.27148
96.98400,8.08192,833.60355,-0.13625,28.14867,39.28127
97.18401,8.09867,833.88174,-0.13625,28.21564,39.29438
97.38400,8.11529,833.78060,-0.13625,28.28212,39.28961
97.58401,8.13197,833.73738,-0.13625,28.34885,39.28758
97.78401,8.14865,833.25626,-0.13625,28.41558,39.26490
97.98400,8.16539,833.15419,-0.13625,28.48254,39.26009
98.18401,8.18207,833.01654,-0.13625,28.54927,39.25361
98.38400,8.19869,833.01319,-0.13625,28.61575,39.25345
98.58401,8.21531,833.19983,-0.13625,28.68223,39.26225
98.78401,8.23200,832.79451,-0.13625,28.74897,39.24314
98.98400,8.24868,832.73463,-0.13625,28.81569,39.24033
99.18401,8.26536,832.91652,-0.13625,28.88241,39.24890
99.38400,8.28198,832.94986,-0.13625,28.94890,39.25047
99.58401,8.29854,832.58031,-0.13625,29.01514,39.23305
99.78401,8.31540,832.84117,-0.13625,29.08259,39.24535
99.98400,8.33202,832.12629,-0.13624,29.14907,39.21166
100.18401,8.34865,832.33612,-0.13625,29.21556,39.22155
100.38400,8.36533,832.53356,-0.13625,29.28228,39.23085
100.58401,8.38195,832.55256,-0.13625,29.34877,39.23175
100.78401,8.39863,832.74432,-0.13625,29.41549,39.24078
100.98400,8.41543,831.46039,-0.13625,29.48270,39.18028
101.18401,8.43205,831.77891,-0.13625,29.54918,39.19529
101.38400,8.44861,831.56414,-0.13625,29.61543,39.18517
101.58401,8.46535,831.55725,-0.13625,29.68239,39.18484
101.78401,8.48210,831.15445,-0.13625,29.74936,39.16586
101.98400,8.49860,831.67497,-0.13625,29.81537,39.19039
102.18401,8.51534,830.77531,-0.13625,29.88233,39.14800
102.38400,8.53208,831.14328,-0.13625,29.94930,39.16534
102.58401,8.54870,830.93578,-0.13625,30.01578,39.15556
102.78401,8.56526,831.13294,-0.13625,30.08203,39.16485
102.98400,8.58206,830.33256,-0.13625,30.14923,39.12713
103.18401,8.59874,831.00852,-0.13625,30.21595,39.15899
103.38400,8.61537,831.05564,-0.13625,30.28244,39.16121
103.58401,8.63199,830.48269,-0.13625,30.34893,39.13421
103.78401,8.64867,830.35491,-0.13625,30.41565,39.12819
103.98400,8.66535,830.74979,-0.13625,30.48238,39.14679
104.18401,8.68197,829.98853,-0.13625,30.54886,39.11092
104.38400,8.69865,830.26728,-0.13625,30.61559,39.12406
104.58401,8.71522,830.51333,-0.13625,30.68184,39.13565
104.78401,8.73190,829.61507,-0.13624,30.74856,39.09332
104.98401,8.74870,830.02690,-0.13625,30.81577,39.11273
105.18401,8.76538,829.59458,-0.13625,30.88249,39.09236
105.38400,8.78200,829.32981,-0.13625,30.94898,39.07988
105.58401,8.79874,829.09325,-0.13625,31.01594,39.06873
105.78401,8.81536,829.01474,-0.13625,31.08242,39.06504
105.98401,8.83198,828.71318,-0.13625,31.14891,39.05082
106.18401,8.84867,828.51471,-0.13625,31.21564,39.04147
106.38400,8.86541,828.72724,-0.13625,31.28260,39.05149
106.58401,8.88197,827.70912,-0.13625,31.34885,39.00351
106.78401,8.89859,828.27723,-0.13625,31.41533,39.03028
106.98401,8.91533,828.38815,-0.13625,31.48230,39.03551
107.18401,8.93189,828.39262,-0.13625,31.54854,39.03572
107.38400,8.94863,827.75597,-0.13625,31.61551,39.00572
107.58401,8.96543,827.66209,-0.13625,31.68271,39.00130
107.78401,8.98194,827.90209,-0.13625,31.74872,39.01260
107.98401,8.99862,827.52081,-0.13625,31.81545,38.99464
108.18401,9.01536,827.28658,-0.13625,31.88241,38.98360
108.38400,9.03204,826.96853,-0.13625,31.94914,38.96861
108.58401,9.04866,827.14641,-0.13625,32.01562,38.97700
108.78401,9.06534,826.96257,-0.13625,32.08234,38.96833
108.98401,9.08208,827.09119,-0.13625,32.14931,38.97439
109.18401,9.09859,826.53677,-0.13625,32.21532,38.94827
109.38400,9.11533,825.76834,-0.13625,32.28228,38.91206
109.58401,9.13213,825.52563,-0.13625,32.34949,38.90062
109.78401,9.14863,826.20205,-0.13625,32.41549,38.93250
109.98401,9.16519,825.81863,-0.13625,32.48174,38.91443
110.18401,9.18205,825.95292,-0.13625,32.54918,38.92076
110.38400,9.19867,825.56391,-0.13625,32.61567,38.90242
110.58401,9.21535,825.22649,-0.13625,32.68239,38.88652
110.78401,9.23204,824.69834,-0.13625,32.74912,38.86164
110.98401,9.24872,824.40749,-0.13625,32.81584,38.84793
111.18401,9.26528,824.73140,-0.13625,32.88209,38.86319
111.38400,9.28196,824.00814,-0.13625,32.94881,38.82911
111.58401,9.29870,823.74569,-0.13625,33.01578,38.81675
111.78401,9.31532,823.69950,-0.13625,33.08226,38.81457
111.98401,9.33200,824.00860,-0.13625,33.14899,38.82914
112.18401,9.34863,823.34410,-0.13625,33.21548,38.79782
112.38400,9.36531,822.91057,-0.13625,33.28220,38.77739
112.58401,9.38199,823.16464,-0.13625,33.34892,38.78936
112.78401,9.39867,822.72440,-0.13625,33.41565,38.76862
112.98401,9.41541,822.14428,-0.13625,33.48262,38.74128
113.18401,9.43197,822.21804,-0.13625,33.54886,38.74476
113.38400,9.44865,821.84300,-0.13625,33.61559,38.72709
113.58401,9.46539,821.53613,-0.13625,33.68255,38.71263
113.78401,9.48202,822.50377,-0.13626,33.74904,38.75822
113.98401,9.49870,821.53864,-0.13625,33.81576,38.71275
114.18401,9.51532,820.30129,-0.13625,33.88225,38.65444
114.38400,9.53194,820.48588,-0.13625,33.94873,38.66314
114.58401,9.54868,820.40466,-0.13625,34.01570,38.65931
114.78401,9.56536,819.89067,-0.13625,34.08242,38.63509
114.98401,9.58210,819.41085,-0.13625,34.14939,38.61248
115.18401,9.59860,819.36438,-0.13625,34.21539,38.61029
115.38400,9.61529,819.60727,-0.13625,34.28212,38.62173
115.58401,9.63209,818.68423,-0.13625,34.34933,38.57824
115.78401,9.64859,818.33005,-0.13625,34.41533,38.56155
115.98401,9.66539,818.35818,-0.13625,34.48254,38.56287
116.18401,9.68207,817.33800,-0.13625,34.54926,38.51480
116.38400,9.69863,818.04236,-0.13625,34.61551,38.54799
116.58401,9.71531,816.90643,-0.13625,34.68224,38.49446
116.78401,9.73199,816.16221,-0.13625,34.74896,38.45940
116.98401,9.74868,815.28239,-0.13625,34.81568,38.41793
117.18401,9.76530,814.22012,-0.13625,34.88217,38.36788
117.38400,9.78198,812.75003,-0.13625,34.94889,38.29861
117.58401,9.79866,811.36571,-0.13625,35.01562,38.23337
117.78401,9.81528,808.83633,-0.13625,35.08210,38.11419
117.98401,9.83190,804.43136,-0.13625,35.14859,37.90661
118.18401,9.84870,799.25153,-0.13625,35.21580,37.66253
118.38400,9.86533,787.63375,-0.13625,35.28228,37.11507
118.58401,9.88195,773.35541,-0.13625,35.34876,36.44224
118.78401,9.89863,757.38709,-0.13626,35.41549,35.68978
118.98401,9.91537,733.04721,-0.13625,35.48245,34.54283
119.16200,9.93032,3.98042,-0.13625,35.54224,0.18757