File: Manufatura Aditiva/Classificação Orientação/Ensaios/Ensaios SLS/Tracao_OLABI_21_12_2018_SLS_45.is_metal_RawData/Specimen_RawData_4.csv
Time,Extension,Load,Strain 1,Tensile strain,Tensile stress
(sec),(mm),(N),(mm/mm),(%),(MPa)
0.00000,0.00006,25.44935,0.00095,0.09499,1.27333
0.20000,0.01369,31.21037,0.00113,0.11269,1.56158
0.40000,0.03265,42.01132,0.00142,0.14249,2.10200
0.60000,0.04986,50.95687,0.00171,0.17066,2.54958
0.80000,0.06667,59.92615,0.00198,0.19763,2.99835
1.00000,0.08341,68.05497,0.00225,0.22534,3.40506
1.20000,0.10003,77.21494,0.00252,0.25181,3.86337
1.40000,0.11671,85.83090,0.00279,0.27887,4.29447
1.60000,0.13333,93.95553,0.00307,0.30716,4.70097
1.80000,0.14995,102.43560,0.00334,0.33446,5.12527
2.00000,0.16663,110.74356,0.00361,0.36147,5.54095
2.20000,0.18331,118.74952,0.00389,0.38906,5.94152
2.40000,0.19994,125.63328,0.00412,0.41172,6.28594
2.60000,0.21668,132.85974,0.00439,0.43919,6.64751
2.80000,0.23330,141.50116,0.00466,0.46643,7.07987
3.00000,0.25004,149.16958,0.00494,0.49418,7.46355
3.20000,0.26672,157.30532,0.00522,0.52174,7.87062
3.40000,0.28334,164.91796,0.00550,0.54952,8.25151
3.60000,0.29996,172.22635,0.00577,0.57716,8.61718
3.80000,0.31659,181.25803,0.00605,0.60544,9.06907
4.00000,0.33339,188.55010,0.00634,0.63370,9.43392
4.20000,0.35001,196.73286,0.00661,0.66140,9.84334
4.40000,0.36669,204.13524,0.00689,0.68911,10.21371
4.60000,0.38337,211.40480,0.00717,0.71750,10.57743
4.80000,0.39993,219.22612,0.00745,0.74548,10.96876
5.00000,0.41667,226.40112,0.00773,0.77324,11.32776
5.20000,0.43341,233.88572,0.00802,0.80151,11.70224
5.40000,0.44998,241.93020,0.00829,0.82941,12.10474
5.60000,0.46660,249.50295,0.00858,0.85777,12.48364
5.80000,0.48328,256.21157,0.00886,0.88598,12.81930
6.00000,0.50002,264.17086,0.00915,0.91472,13.21753
6.20000,0.51658,270.40092,0.00941,0.94060,13.52925
6.40000,0.53332,276.32588,0.00965,0.96465,13.82570
6.60000,0.55012,284.01227,0.00993,0.99318,14.21028
6.80000,0.56668,290.78063,0.01022,1.02161,14.54892
7.00000,0.58325,297.83896,0.01050,1.05047,14.90208
7.20000,0.59999,305.46458,0.01079,1.07896,15.28362
7.40000,0.61667,312.22845,0.01107,1.10732,15.62205
7.60000,0.63329,319.00632,0.01136,1.13639,15.96117
7.80000,0.64991,326.25131,0.01164,1.16442,16.32367
8.00000,0.66665,332.50363,0.01193,1.19284,16.63649
8.20000,0.68333,338.65101,0.01222,1.22185,16.94407
8.40000,0.70002,345.95369,0.01251,1.25085,17.30946
8.60000,0.71676,352.78089,0.01281,1.28053,17.65105
8.80000,0.73332,359.49182,0.01309,1.30862,17.98682
9.00000,0.75000,365.42683,0.01338,1.33816,18.28378
9.20000,0.76668,371.83783,0.01367,1.36724,18.60454
9.40000,0.78330,378.90703,0.01397,1.39665,18.95824
9.60000,0.80004,384.18469,0.01426,1.42626,19.22231
9.80000,0.81660,390.56898,0.01456,1.45571,19.54174
10.00000,0.83329,395.43035,0.01481,1.48072,19.78497
10.20000,0.84991,401.62164,0.01510,1.50989,20.09475
10.40000,0.86659,408.16632,0.01539,1.53932,20.42220
10.60000,0.88345,413.93619,0.01569,1.56946,20.71089
10.80000,0.90001,420.17181,0.01599,1.59898,21.02289
11.00000,0.91663,425.63961,0.01629,1.62864,21.29646
11.20000,0.93337,432.16543,0.01659,1.65907,21.62297
11.40000,0.94994,438.92073,0.01689,1.68936,21.96097
11.60000,0.96662,444.47342,0.01720,1.71957,22.23879
11.80000,0.98330,450.55305,0.01750,1.74977,22.54298
12.00000,0.99998,455.34349,0.01781,1.78053,22.78267
12.20000,1.01660,461.01375,0.01811,1.81141,23.06637
12.40000,1.03328,467.03089,0.01842,1.84182,23.36743
12.60000,1.05008,471.82557,0.01873,1.87261,23.60733
12.80000,1.06658,477.44047,0.01904,1.90377,23.88827
13.00000,1.08333,482.26719,0.01935,1.93469,24.12977
13.20000,1.10001,487.68674,0.01966,1.96599,24.40093
13.40000,1.11663,491.78223,0.01997,1.99682,24.60584
13.60000,1.13331,497.22386,0.02028,2.02799,24.87811
13.80000,1.15005,501.50901,0.02058,2.05815,25.09251
14.00000,1.16679,506.47124,0.02088,2.08775,25.34079
14.20000,1.18329,510.67653,0.02119,2.11939,25.55120
14.40000,1.20003,515.45692,0.02151,2.15114,25.79038
14.60000,1.21672,519.87641,0.02183,2.18285,26.01151
14.80000,1.23328,524.36073,0.02216,2.21576,26.23588
15.00000,1.24996,528.97665,0.02248,2.24776,26.46683
15.20000,1.26664,533.28336,0.02280,2.28038,26.68231
15.40000,1.28326,537.64265,0.02312,2.31220,26.90042
15.60000,1.29994,541.89479,0.02345,2.34511,27.11318
15.80000,1.31668,546.06716,0.02378,2.37799,27.32194
16.00000,1.33337,549.33699,0.02411,2.41087,27.48554
16.20000,1.35005,553.17213,0.02444,2.44398,27.67743
16.40000,1.36673,557.97980,0.02477,2.47695,27.91797
16.60000,1.38341,561.52288,0.02510,2.51012,28.09525
16.80000,1.39997,564.70889,0.02544,2.54412,28.25466
17.00000,1.41665,568.70901,0.02577,2.57740,28.45480
17.20000,1.43339,572.15812,0.02611,2.61127,28.62737
17.40000,1.44995,576.44197,0.02645,2.64489,28.84171
17.60000,1.46664,579.36944,0.02678,2.67809,28.98818
17.80000,1.48338,583.10227,0.02713,2.71283,29.17495
18.00000,1.50000,586.10141,0.02747,2.74695,29.32501
18.20000,1.51668,589.15946,0.02781,2.78115,29.47802
18.40000,1.53330,592.68964,0.02815,2.81518,29.65465
18.60000,1.54998,594.15256,0.02844,2.84446,29.72784
18.80000,1.56666,597.60921,0.02879,2.87888,29.90079
19.00000,1.58335,601.30409,0.02914,2.91374,30.08566
19.20000,1.60003,604.43250,0.02948,2.94848,30.24219
19.40000,1.61671,607.13873,0.02983,2.98312,30.37759
19.60000,1.63333,610.57447,0.03018,3.01820,30.54950
19.80000,1.65001,613.33142,0.03053,3.05299,30.68744
20.00000,1.66663,616.16795,0.03088,3.10394,30.82936
20.20000,1.68331,619.56500,0.03124,3.17066,30.99933
20.31800,1.69318,620.96561,0.03145,3.21013,31.06941
20.51800,1.70980,623.92419,0.03180,3.27661,31.21744
20.71800,1.72642,625.98349,0.03215,3.34310,31.32047
20.91800,1.74316,629.18365,0.03251,3.41006,31.48059
21.11800,1.75984,632.01953,0.03287,3.47679,31.62248
21.31800,1.77653,634.82802,0.03323,3.54351,31.76300
21.51800,1.79321,635.88829,0.03220,3.61024,31.81605
21.71800,1.80983,638.55699,0.03263,3.67672,31.94958
21.91800,1.82657,641.69653,0.03242,3.74369,32.10666
22.11800,1.84319,644.32877,0.03152,3.81017,32.23836
22.31800,1.85987,646.27770,0.02650,3.87690,32.33587
22.51800,1.87649,648.72894,0.00092,3.94338,32.45852
22.71800,1.89311,650.80579,0.00088,4.00987,32.56243
22.91800,1.90974,653.57829,0.00205,4.07636,32.70115
23.11800,1.92648,655.29053,0.00153,4.14332,32.78682
23.31800,1.94316,657.87244,0.00383,4.21005,32.91600
23.51800,1.95990,660.47055,0.00638,4.27701,33.04600
23.71800,1.97652,662.49692,0.02100,4.34350,33.14738
23.91800,1.99320,664.71850,0.05169,4.41022,33.25854
24.11800,2.00982,667.26105,0.01587,4.47671,33.38575
24.31800,2.02650,669.48677,0.01108,4.54343,33.49712
24.51800,2.04325,671.19189,-0.00684,4.61040,33.58243
24.71800,2.05981,673.20433,-0.08090,4.67664,33.68312
24.91800,2.07655,675.44547,-0.08001,4.74361,33.79525
25.11800,2.09317,676.32888,-0.05881,4.81009,33.83945
25.31800,2.10979,678.51325,-0.06124,4.87658,33.94875
25.51800,2.12647,680.80174,-0.05872,4.94330,34.06325
25.71800,2.14309,682.52156,-0.06017,5.00979,34.14930
25.91800,2.15978,684.58961,-0.06002,5.07651,34.25277
26.11800,2.17652,686.82809,-0.05990,5.14348,34.36477
26.31800,2.19314,688.44086,-0.06014,5.20996,34.44547
26.51800,2.20982,690.91101,-0.06019,5.27669,34.56906
26.71800,2.22650,692.82218,-0.06029,5.34341,34.66468
26.91800,2.24318,694.16566,-0.06031,5.41014,34.73190
27.11800,2.25986,696.48284,-0.06034,5.47686,34.84784
27.31800,2.27648,698.43526,-0.06039,5.54335,34.94553
27.51800,2.29323,700.20957,-0.06041,5.61031,35.03430
27.71800,2.30985,702.03887,-0.06039,5.67680,35.12583
27.91800,2.32653,703.61299,-0.06042,5.74353,35.20459
28.11800,2.34321,705.50456,-0.06047,5.81025,35.29923
28.31800,2.35977,706.78778,-0.06048,5.87650,35.36344
28.51800,2.37645,709.00316,-0.06050,5.94322,35.47428
28.71800,2.39313,710.60499,-0.06054,6.00995,35.55443
28.91800,2.40982,711.91150,-0.06057,6.07667,35.61980
29.11800,2.42656,713.55924,-0.06056,6.14364,35.70224
29.31800,2.44312,715.86668,-0.06057,6.20988,35.81769
29.51800,2.45986,717.25897,-0.06062,6.27685,35.88735
29.71800,2.47648,718.77721,-0.06063,6.34333,35.96331
29.91800,2.49316,720.14518,-0.06065,6.41006,36.03176
30.11800,2.50984,722.14464,-0.06069,6.47678,36.13180
30.31800,2.52652,723.01812,-0.06070,6.54351,36.17551
30.51800,2.54315,723.89459,-0.06067,6.60999,36.21936
30.71800,2.55983,725.56860,-0.06074,6.67672,36.30312
30.91800,2.57651,726.93639,-0.06074,6.74345,36.37155
31.11800,2.59313,728.61440,-0.06073,6.80993,36.45551
31.31800,2.60975,730.53800,-0.06076,6.87642,36.55175
31.51800,2.62643,731.89959,-0.06075,6.94314,36.61988
31.71800,2.64317,732.91622,-0.06074,7.01011,36.67075
31.91800,2.65986,734.84802,-0.06076,7.07683,36.76740
32.11800,2.67654,736.00393,-0.06077,7.14356,36.82524
32.31800,2.69316,736.67411,-0.06080,7.21004,36.85877
32.51800,2.70984,738.89345,-0.06080,7.27677,36.96981
32.71800,2.72646,739.90026,-0.06079,7.34325,37.02019
32.91800,2.74308,742.22255,-0.06082,7.40974,37.13638
33.11800,2.75982,742.82666,-0.06080,7.47670,37.16661
33.31800,2.77662,744.51626,-0.06081,7.54391,37.25114
33.51800,2.79319,744.95724,-0.06086,7.61015,37.27321
33.71800,2.80981,746.55018,-0.06086,7.67664,37.35291
33.91800,2.82649,747.96113,-0.06086,7.74336,37.42350
34.11800,2.84317,749.28319,-0.06089,7.81009,37.48965
34.31800,2.85985,750.46802,-0.06092,7.87681,37.54893
34.51800,2.87647,751.60209,-0.06089,7.94330,37.60567
34.71800,2.89315,753.21202,-0.06092,8.01003,37.68623
34.91800,2.90978,754.45157,-0.06095,8.07651,37.74825
35.11800,2.92646,754.22013,-0.06091,8.14324,37.73667
35.31800,2.94332,755.33879,-0.06093,8.21068,37.79264
35.51800,2.95988,756.56734,-0.06097,8.27693,37.85411
35.71800,2.97644,758.06836,-0.06096,8.34317,37.92921
35.91800,2.99312,759.18240,-0.06097,8.40990,37.98495
36.11800,3.00980,760.47834,-0.06097,8.47662,38.04979
36.31800,3.02642,761.79802,-0.06097,8.54311,38.11582
36.51800,3.04317,762.38704,-0.06100,8.61007,38.14529
36.71800,3.05985,763.67585,-0.06100,8.67680,38.20977
36.91800,3.07647,765.31661,-0.06097,8.74328,38.29187
37.11800,3.09315,766.49841,-0.06101,8.81001,38.35100
37.31800,3.10983,767.01785,-0.06101,8.87673,38.37699
37.51800,3.12651,768.77456,-0.06099,8.94346,38.46489
37.71800,3.14319,769.47561,-0.06103,9.01018,38.49996
37.91800,3.15987,770.83074,-0.06102,9.07691,38.56776
38.11800,3.17644,771.65985,-0.06100,9.14316,38.60925
38.31800,3.19318,772.66530,-0.06104,9.21012,38.65955
38.51800,3.20980,773.83677,-0.06105,9.27661,38.71817
38.71800,3.22648,774.72432,-0.06102,9.34333,38.76257
38.91800,3.24310,775.72055,-0.06105,9.40982,38.81242
39.11800,3.25978,776.44042,-0.06104,9.47654,38.84844
39.31800,3.27652,777.21979,-0.06103,9.54351,38.88743
39.51800,3.29321,779.00854,-0.06105,9.61023,38.97693
39.71800,3.30983,780.03672,-0.06105,9.67672,39.02837
39.91800,3.32657,780.53172,-0.06107,9.74368,39.05314
40.11800,3.34313,782.04880,-0.06105,9.80993,39.12905
40.31800,3.35975,782.59511,-0.06105,9.87641,39.15638
40.51800,3.37655,783.64341,-0.06108,9.94362,39.20883
40.71800,3.39329,784.53347,-0.06103,10.01058,39.25336
40.91800,3.40979,785.21995,-0.06106,10.07659,39.28771
41.11800,3.42642,786.30690,-0.06109,10.14308,39.34210
41.31800,3.44322,786.81214,-0.06107,10.21028,39.36738
41.51800,3.45978,788.13788,-0.06109,10.27653,39.43371
41.71800,3.47652,788.48200,-0.06108,10.34349,39.45093
41.91800,3.49326,789.84713,-0.06109,10.41045,39.51923
42.11800,3.50982,790.68039,-0.06109,10.47670,39.56092
42.31800,3.52650,791.25511,-0.06104,10.54343,39.58968
42.51800,3.54319,792.43425,-0.06110,10.61015,39.64867
42.71800,3.55993,793.06932,-0.06108,10.67712,39.68045
42.91800,3.57649,793.34183,-0.06104,10.74336,39.69408
43.11800,3.59317,794.97034,-0.06111,10.81009,39.77557
43.31800,3.60985,795.11618,-0.06109,10.87681,39.78286
43.51800,3.62641,795.87642,-0.06107,10.94306,39.82090
43.71800,3.64315,797.21957,-0.06111,11.01002,39.88810
43.91800,3.65989,797.43313,-0.06110,11.07699,39.89879
44.11800,3.67646,798.53414,-0.06109,11.14323,39.95388
44.31800,3.69308,798.94979,-0.06110,11.20972,39.97467
44.51800,3.70982,799.68814,-0.06109,11.27668,40.01162
44.71800,3.72650,800.61611,-0.06112,11.34341,40.05804
44.91800,3.74318,801.47339,-0.06112,11.41014,40.10094
45.11800,3.75980,802.03870,-0.06109,11.47662,40.12922
45.31800,3.77654,802.95075,-0.06112,11.54358,40.17486
45.51800,3.79311,803.59690,-0.06109,11.60983,40.20719
45.71800,3.80979,804.65749,-0.06108,11.67656,40.26025
45.91800,3.82653,804.97898,-0.06114,11.74352,40.27634
46.11800,3.84315,805.67999,-0.06111,11.81001,40.31141
46.31800,3.85983,805.65196,-0.06109,11.87673,40.31001
46.51800,3.87645,807.06542,-0.06113,11.94322,40.38073
46.71800,3.89319,807.72182,-0.06109,12.01018,40.41357
46.91800,3.90987,807.79279,-0.06109,12.07691,40.41712
47.11800,3.92650,808.45160,-0.06112,12.14339,40.45008
47.31800,3.94318,809.81711,-0.06112,12.21012,40.51841
47.51800,3.95980,810.09706,-0.06110,12.27660,40.53241
47.71800,3.97642,810.77954,-0.06109,12.34309,40.56656
47.91800,3.99322,811.27807,-0.06112,12.41029,40.59151
48.11800,4.00990,812.12837,-0.06113,12.47702,40.63405
48.31800,4.02652,812.66090,-0.06108,12.54350,40.66069
48.51800,4.04314,813.54100,-0.06111,12.60999,40.70473
48.71800,4.05983,813.95665,-0.06116,12.67672,40.72552
48.91800,4.07645,815.20043,-0.06109,12.74320,40.78776
49.11800,4.09319,814.93640,-0.06111,12.81016,40.77455
49.31800,4.10987,815.85264,-0.06117,12.87689,40.82039
49.51800,4.12649,816.15895,-0.06111,12.94338,40.83572
49.71800,4.14317,816.46368,-0.06112,13.01010,40.85096
49.91800,4.15991,817.61330,-0.06114,13.07707,40.90848
50.11800,4.17648,818.22183,-0.06112,13.14331,40.93893
50.31800,4.19322,819.12205,-0.06112,13.21028,40.98397
50.51800,4.20984,819.24461,-0.06113,13.27676,40.99010
50.71800,4.22646,819.81784,-0.06114,13.34325,41.01878
50.91800,4.24314,820.53812,-0.06111,13.40997,41.05482
51.11800,4.25982,821.67909,-0.06112,13.47670,41.11191
51.31800,4.27656,821.24006,-0.06115,13.54366,41.08994
51.51800,4.29318,821.87178,-0.06112,13.61015,41.12155
51.71800,4.30975,822.18274,-0.06112,13.67640,41.13711
51.91800,4.32649,822.96599,-0.06116,13.74336,41.17630
52.11800,4.34311,823.42178,-0.06111,13.80985,41.19910
52.31800,4.35979,823.98327,-0.06114,13.87657,41.22720
52.51800,4.37653,824.10760,-0.06115,13.94354,41.23342
52.71800,4.39315,824.80768,-0.06109,14.01002,41.26845
52.91800,4.40983,825.40307,-0.06115,14.07675,41.29824
53.11800,4.42646,825.63786,-0.06118,14.14323,41.30998
53.31800,4.44320,826.61621,-0.06110,14.21020,41.35894
53.51800,4.45982,825.09583,-0.06115,14.27668,41.28286
53.71800,4.47650,825.67763,-0.06117,14.34341,41.31197
53.91800,4.49318,826.56685,-0.06110,14.41013,41.35646
54.11800,4.50986,826.66762,-0.06113,14.47686,41.36151
54.31800,4.52648,827.82358,-0.06115,14.54334,41.41935
54.51800,4.54322,827.97119,-0.06112,14.61031,41.42673
54.71800,4.55985,828.19052,-0.06114,14.67679,41.43770
54.91800,4.57641,830.01945,-0.06114,14.74304,41.52921
55.11800,4.59315,829.55528,-0.06115,14.81000,41.50599
55.31800,4.60989,830.33675,-0.06113,14.87697,41.54509
55.51800,4.62651,830.69019,-0.06115,14.94345,41.56277
55.71800,4.64319,831.72340,-0.06117,15.01018,41.61447
55.91800,4.65987,831.64554,-0.06117,15.07690,41.61057
56.11800,4.67655,832.50189,-0.06114,15.14363,41.65342
56.31800,4.69312,832.54687,-0.06121,15.20988,41.65567
56.51800,4.70986,833.08425,-0.06115,15.27684,41.68256
56.71800,4.72654,833.75052,-0.06111,15.34357,41.71589
56.91800,4.74316,834.23601,-0.06118,15.41005,41.74018
57.11800,4.75978,834.46102,-0.06113,15.47654,41.75144
57.31800,4.77646,834.70438,-0.06115,15.54326,41.76362
57.51800,4.79314,834.96915,-0.06118,15.60999,41.77687
57.71800,4.80983,834.85469,-0.06113,15.67671,41.77114
57.91800,4.82657,835.90578,-0.06118,15.74368,41.82373
58.11800,4.84319,836.22467,-0.06116,15.81016,41.83968
58.31800,4.85981,836.13349,-0.06110,15.87665,41.83512
58.51800,4.87649,837.64596,-0.06119,15.94338,41.91080
58.71800,4.89317,837.76116,-0.06116,16.01010,41.91656
58.91800,4.90985,837.99949,-0.06109,16.07682,41.92849
59.11800,4.92647,838.67265,-0.06120,16.14331,41.96217
59.31800,4.94310,838.95214,-0.06116,16.20979,41.97615
59.51800,4.95984,838.55689,-0.06112,16.27676,41.95638
59.71800,4.97646,839.24849,-0.06118,16.34325,41.99098
59.91800,4.99314,839.82460,-0.06116,16.40997,42.01980
60.11800,5.00982,839.47945,-0.06111,16.47670,42.00253
60.31800,5.02644,840.41739,-0.06116,16.54318,42.04946
60.51800,5.04312,840.26391,-0.06118,16.60991,42.04178
60.71800,5.05981,840.62433,-0.06112,16.67663,42.05982
60.91800,5.07649,841.54382,-0.06116,16.74336,42.10582
61.11800,5.09323,841.20883,-0.06115,16.81032,42.08906
61.31800,5.10985,842.12273,-0.06115,16.87680,42.13479
61.51800,5.12647,841.89763,-0.06115,16.94329,42.12353
61.71800,5.14315,842.18774,-0.06115,17.01002,42.13804
61.91800,5.15977,842.76013,-0.06117,17.07650,42.16668
62.11800,5.17651,842.46974,-0.06113,17.14347,42.15215
62.31800,5.19320,843.19701,-0.06116,17.21019,42.18854
62.51800,5.20982,843.01857,-0.06119,17.27668,42.17961
62.71800,5.22644,844.19567,-0.06113,17.34316,42.23851
62.91800,5.24312,843.86114,-0.06114,17.40989,42.22177
63.11800,5.25992,844.32568,-0.06119,17.47709,42.24501
63.31800,5.27654,844.44396,-0.06116,17.54358,42.25093
63.51800,5.29316,845.07680,-0.06112,17.61006,42.28259
63.71800,5.30990,845.24313,-0.06119,17.67703,42.29091
63.91800,5.32653,845.54795,-0.06117,17.74351,42.30617
64.11800,5.34321,845.87010,-0.06110,17.81024,42.32228
64.31800,5.35989,845.79987,-0.06117,17.87697,42.31877
64.51800,5.37651,845.91070,-0.06119,17.94345,42.32431
64.71800,5.39313,846.56337,-0.06116,18.00994,42.35697
64.91801,5.40975,846.81967,-0.06118,18.07642,42.36980
65.11800,5.42655,847.04868,-0.06117,18.14363,42.38125
65.31800,5.44312,846.75746,-0.06117,18.20987,42.36668
65.51800,5.45980,846.89967,-0.06119,18.27660,42.37380
65.71800,5.47648,847.96585,-0.06119,18.34332,42.42714
65.91801,5.49316,847.80650,-0.06118,18.41005,42.41917
66.11800,5.50984,848.10117,-0.06119,18.47677,42.43391
66.31800,5.52652,847.81460,-0.06117,18.54350,42.41957
66.51801,5.54320,848.65205,-0.06120,18.61022,42.46148
66.71800,5.55982,848.74034,-0.06123,18.67671,42.46589
66.91801,5.57645,848.52530,-0.06120,18.74319,42.45514
67.11800,5.59313,849.67986,-0.06115,18.80992,42.51290
67.31800,5.60981,849.16772,-0.06118,18.87665,42.48728
67.51801,5.62655,849.72763,-0.06118,18.94361,42.51529
67.71800,5.64323,849.93755,-0.06113,19.01034,42.52579
67.91801,5.65979,849.39869,-0.06118,19.07658,42.49883
68.11800,5.67647,849.82514,-0.06118,19.14331,42.52017
68.31800,5.69316,849.94724,-0.06116,19.21003,42.52628
68.51801,5.70984,850.29565,-0.06117,19.27676,42.54371
68.71800,5.72646,850.73207,-0.06117,19.34324,42.56555
68.91801,5.74308,850.26510,-0.06116,19.40973,42.54218
69.11800,5.75988,850.80676,-0.06115,19.47693,42.56929
69.31800,5.77650,850.48229,-0.06117,19.54342,42.55305
69.51801,5.79318,851.05365,-0.06118,19.61014,42.58164
69.71800,5.80998,851.35037,-0.06118,19.67735,42.59649
69.91801,5.82643,851.74870,-0.06117,19.74312,42.61641
70.11800,5.84311,851.65892,-0.06116,19.80984,42.61192
70.31800,5.85991,851.27475,-0.06120,19.87704,42.59270
70.51801,5.87647,852.41525,-0.06114,19.94329,42.64977
70.71800,5.89315,851.93655,-0.06118,20.01001,42.62581
70.91801,5.90983,852.23988,-0.06123,20.07674,42.64099
71.11800,5.92651,852.31736,-0.06113,20.14347,42.64487
71.31800,5.94313,851.96942,-0.06119,20.20995,42.62746
71.51801,5.95988,852.48789,-0.06125,20.27691,42.65340
71.71800,5.97662,853.57511,-0.06108,20.34388,42.70780
71.91801,5.99318,853.21190,-0.06123,20.41013,42.68962
72.11800,6.00986,853.14214,-0.06124,20.47685,42.68613
72.31800,6.02648,853.47174,-0.06108,20.54334,42.70263
72.51801,6.04316,853.15472,-0.06125,20.61006,42.68676
72.71800,6.05990,853.45060,-0.06117,20.67703,42.70157
72.91801,6.07653,853.44026,-0.06116,20.74351,42.70105
73.11800,6.09315,854.17293,-0.06120,20.81000,42.73771
73.31800,6.10977,853.28091,-0.06118,20.87648,42.69308
73.51801,6.12645,853.81679,-0.06119,20.94321,42.71989
73.71800,6.14319,853.93367,-0.06120,21.01017,42.72574
73.91801,6.15987,854.38220,-0.06120,21.07690,42.74818
74.11800,6.17643,854.17768,-0.06117,21.14315,42.73795
74.31800,6.19312,853.83859,-0.06119,21.20987,42.72098
74.51801,6.20980,854.29279,-0.06123,21.27659,42.74371
74.71800,6.22648,854.25787,-0.06113,21.34332,42.74196
74.91801,6.24328,854.06601,-0.06124,21.41052,42.73236
75.11800,6.25990,854.39421,-0.06116,21.47701,42.74878
75.31800,6.27646,854.11482,-0.06120,21.54326,42.73480
75.51801,6.29314,854.62769,-0.06123,21.60998,42.76046
75.71800,6.30982,854.68618,-0.06116,21.67671,42.76339
75.91801,6.32639,854.63887,-0.06118,21.74295,42.76102
76.11800,6.34319,854.66923,-0.06120,21.81016,42.76254
76.31800,6.35993,854.91501,-0.06117,21.87712,42.77484
76.51801,6.37649,855.11385,-0.06119,21.94337,42.78479
76.71800,6.39317,854.72474,-0.06118,22.01010,42.76532
76.91801,6.40991,855.35329,-0.06117,22.07706,42.79676
77.11800,6.42653,854.77913,-0.06121,22.14354,42.76804
77.31800,6.44315,855.04306,-0.06117,22.21003,42.78125
77.51801,6.45990,855.07249,-0.06116,22.27699,42.78272
77.71800,6.47646,855.56153,-0.06121,22.34324,42.80719
77.91801,6.49314,855.60987,-0.06119,22.40997,42.80960
78.11800,6.50982,854.66355,-0.06117,22.47669,42.76226
78.31800,6.52656,855.78728,-0.06120,22.54366,42.81848
78.51801,6.54306,855.63408,-0.06119,22.60966,42.81081
78.71800,6.55974,855.96517,-0.06114,22.67639,42.82738
78.91801,6.57655,856.13308,-0.06122,22.74359,42.83578
79.11800,6.59323,855.66202,-0.06121,22.81031,42.81221
79.31800,6.60985,856.01779,-0.06112,22.87680,42.83001
79.51801,6.62653,855.70142,-0.06122,22.94353,42.81419
79.71800,6.64315,856.13579,-0.06121,23.01001,42.83592
79.91801,6.65977,856.13383,-0.06115,23.07650,42.83582
80.11800,6.67645,856.27362,-0.06122,23.14323,42.84282
80.31800,6.69319,855.80787,-0.06120,23.21019,42.81951
80.51801,6.70976,855.95213,-0.06115,23.27643,42.82673
80.71800,6.72644,856.11902,-0.06123,23.34316,42.83508
80.91801,6.74318,855.51701,-0.06117,23.41012,42.80496
81.11800,6.75980,856.11297,-0.06113,23.47661,42.83478
81.31800,6.77648,856.42952,-0.06125,23.54334,42.85062
81.51801,6.79322,856.18943,-0.06118,23.61030,42.83860
81.71800,6.80978,855.66891,-0.06110,23.67655,42.81256
81.91801,6.82647,855.44158,-0.06125,23.74327,42.80118
82.11800,6.84315,855.85006,-0.06119,23.81000,42.82162
82.31800,6.85989,856.10542,-0.06111,23.87696,42.83440
82.51801,6.87657,855.72097,-0.06123,23.94369,42.81516
82.71800,6.89313,856.42645,-0.06120,24.00993,42.85046
82.91801,6.90987,855.98491,-0.06113,24.07690,42.82837
83.11800,6.92643,856.61104,-0.06124,24.14314,42.85970
83.31800,6.94305,856.30510,-0.06120,24.20963,42.84439
83.51801,6.95986,856.43958,-0.06112,24.27683,42.85112
83.71800,6.97648,855.64731,-0.06123,24.34332,42.81148
83.91801,6.99316,856.00484,-0.06120,24.41005,42.82936
84.11800,7.00984,855.58593,-0.06114,24.47677,42.80841
84.31800,7.02652,855.74808,-0.06122,24.54349,42.81652
84.51801,7.04320,855.53052,-0.06119,24.61022,42.80563
84.71800,7.05982,855.97867,-0.06116,24.67670,42.82806
84.91801,7.07656,855.58891,-0.06121,24.74367,42.80856
85.11800,7.09313,856.19902,-0.06115,24.80992,42.83908
85.31800,7.10987,855.80209,-0.06119,24.87688,42.81922
85.51801,7.12661,856.05886,-0.06123,24.94384,42.83207
85.71800,7.14311,856.35353,-0.06115,25.00985,42.84681
85.91801,7.15985,856.04694,-0.06119,25.07682,42.83147
86.11800,7.17647,855.54989,-0.06123,25.14330,42.80660
86.31800,7.19315,855.41820,-0.06115,25.21003,42.80001
86.51801,7.20984,855.42137,-0.06120,25.27675,42.80017
86.71800,7.22646,855.97616,-0.06124,25.34324,42.82793
86.91801,7.24320,855.09783,-0.06113,25.41021,42.78399
87.11800,7.25988,856.05914,-0.06117,25.47693,42.83208
87.31800,7.27650,855.38076,-0.06126,25.54341,42.79814
87.51801,7.29318,855.43590,-0.06116,25.61014,42.80090
87.71800,7.30980,854.73293,-0.06119,25.67663,42.76573
87.91801,7.32654,854.60525,-0.06119,25.74359,42.75934
88.11800,7.34317,854.88604,-0.06118,25.81007,42.77339
88.31800,7.35985,855.10006,-0.06120,25.87680,42.78410
88.51801,7.37659,855.07743,-0.06116,25.94377,42.78296
88.71800,7.39315,854.94593,-0.06120,26.01001,42.77638
88.91801,7.40977,854.70192,-0.06123,26.07650,42.76418
89.11800,7.42645,854.78704,-0.06115,26.14322,42.76844
89.31800,7.44313,854.75910,-0.06120,26.20995,42.76704
89.51801,7.45988,855.03096,-0.06124,26.27691,42.78064
89.71800,7.47644,855.13778,-0.06117,26.34316,42.78598
89.91801,7.49318,854.60320,-0.06120,26.41012,42.75924
90.11800,7.50986,854.89340,-0.06123,26.47685,42.77376
90.31800,7.52648,854.61736,-0.06116,26.54333,42.75994
90.51801,7.54322,854.47300,-0.06121,26.61030,42.75272
90.71800,7.55978,853.98443,-0.06122,26.67654,42.72828
90.91801,7.57646,854.86183,-0.06117,26.74327,42.77217
91.11800,7.59321,854.14955,-0.06122,26.81023,42.73654
91.31800,7.60977,854.36106,-0.06126,26.87648,42.74712
91.51801,7.62651,854.41638,-0.06120,26.94345,42.74989
91.71800,7.64313,854.51780,-0.06120,27.00993,42.75496
91.91801,7.65981,854.33517,-0.06121,27.07666,42.74583
92.11800,7.67655,853.99020,-0.06121,27.14362,42.72857
92.31800,7.69317,853.60715,-0.06120,27.21011,42.70940
92.51801,7.70980,854.36394,-0.06117,27.27659,42.74726
92.71800,7.72654,853.58322,-0.06122,27.34356,42.70820
92.91801,7.74322,853.50284,-0.06121,27.41028,42.70418
93.11800,7.75984,853.88366,-0.06120,27.47677,42.72324
93.31800,7.77652,853.91374,-0.06119,27.54349,42.72474
93.51801,7.79320,853.71416,-0.06119,27.61022,42.71475
93.71800,7.80982,853.30140,-0.06122,27.67670,42.69410
93.91801,7.82644,853.73651,-0.06120,27.74319,42.71587
94.11800,7.84319,853.94857,-0.06118,27.81015,42.72648
94.31800,7.85981,853.52436,-0.06124,27.87664,42.70526
94.51801,7.87649,853.46308,-0.06119,27.94336,42.70219
94.71800,7.89311,853.58936,-0.06117,28.00985,42.70851
94.91801,7.90979,852.92077,-0.06126,28.07657,42.67506
95.11800,7.92647,853.15779,-0.06122,28.14330,42.68692
95.31800,7.94315,852.97562,-0.06115,28.21003,42.67780
95.51801,7.95989,852.85595,-0.06125,28.27699,42.67181
95.71800,7.97652,852.73003,-0.06124,28.34348,42.66552
95.91801,7.99314,852.62638,-0.06118,28.40996,42.66033
96.11800,8.00982,852.47625,-0.06123,28.47669,42.65282
96.31800,8.02650,852.84300,-0.06124,28.54341,42.67117
96.51801,8.04312,852.92133,-0.06121,28.60990,42.67509
96.71800,8.05980,852.52775,-0.06123,28.67662,42.65539
96.91801,8.07642,853.11811,-0.06123,28.74311,42.68493
97.11800,8.09311,852.95429,-0.06118,28.80983,42.67673
97.31801,8.10985,852.28849,-0.06123,28.87680,42.64342
97.51801,8.12659,852.38703,-0.06120,28.94376,42.64835
97.71800,8.14315,852.18297,-0.06122,29.01001,42.63814
97.91801,8.15983,852.22879,-0.06124,29.07673,42.64043
98.11800,8.17651,851.92854,-0.06120,29.14346,42.62541
98.31801,8.19313,851.83671,-0.06121,29.20994,42.62082
98.51801,8.20981,851.73259,-0.06120,29.27667,42.61561
98.71800,8.22656,851.28983,-0.06121,29.34363,42.59346
98.91801,8.24312,851.78958,-0.06120,29.40988,42.61846
99.11800,8.25986,852.04076,-0.06123,29.47684,42.63103
99.31801,8.27648,851.84798,-0.06121,29.54333,42.62138
99.51801,8.29316,850.81030,-0.06122,29.61006,42.56946
99.71800,8.30984,851.12322,-0.06122,29.67678,42.58512
99.91801,8.32652,851.13728,-0.06123,29.74351,42.58582
100.11800,8.34326,850.53770,-0.06117,29.81047,42.55582
100.31801,8.35977,851.00997,-0.06120,29.87648,42.57945
100.51801,8.37645,850.83432,-0.06127,29.94320,42.57066
100.71800,8.39319,850.75870,-0.06115,30.01017,42.56688
100.91801,8.40981,850.13099,-0.06122,30.07665,42.53547
101.11800,8.42649,850.05211,-0.06125,30.14338,42.53153
101.31801,8.44317,850.05695,-0.06113,30.21010,42.53177
101.51801,8.45979,849.50374,-0.06128,30.27659,42.50409
101.71800,8.47654,849.92247,-0.06123,30.34356,42.52504
101.91801,8.49316,850.01662,-0.06113,30.41004,42.52975
102.11800,8.50984,849.53215,-0.06129,30.47676,42.50551
102.31801,8.52640,849.37261,-0.06116,30.54301,42.49753
102.51801,8.54308,849.10821,-0.06116,30.60973,42.48430
102.71800,8.55988,848.89503,-0.06131,30.67694,42.47363
102.91801,8.57656,849.37345,-0.06114,30.74366,42.49757
103.11800,8.59318,848.70029,-0.06116,30.81015,42.46389
103.31801,8.60987,848.09149,-0.06132,30.87687,42.43343
103.51801,8.62649,848.45172,-0.06117,30.94336,42.45145
103.71800,8.64317,848.48925,-0.06117,31.01009,42.45333
103.91801,8.65991,847.74615,-0.06134,31.07705,42.41615
104.11800,8.67653,847.50215,-0.06119,31.14353,42.40394
104.31801,8.69309,848.36371,-0.06118,31.20978,42.44705
104.51801,8.70971,847.82327,-0.06131,31.27627,42.42001
104.71800,8.72652,847.51993,-0.06120,31.34347,42.40483
104.91801,8.74314,847.61623,-0.06118,31.40996,42.40965
105.11800,8.75982,847.30200,-0.06127,31.47668,42.39393
105.31801,8.77656,846.68277,-0.06119,31.54365,42.36295
105.51801,8.79312,847.23579,-0.06124,31.60989,42.39061
105.71800,8.80980,846.84864,-0.06126,31.67662,42.37124
105.91801,8.82660,846.32868,-0.06113,31.74382,42.34523
106.11800,8.84322,846.56989,-0.06121,31.81031,42.35730
106.31801,8.85979,846.24505,-0.06129,31.87656,42.34105
106.51801,8.87647,845.78181,-0.06112,31.94328,42.31787
106.71800,8.89321,845.94777,-0.06124,32.01025,42.32617
106.91801,8.90983,845.50083,-0.06129,32.07673,42.30381
107.11800,8.92651,845.42884,-0.06110,32.14346,42.30021
107.31801,8.94319,844.85207,-0.06122,32.21018,42.27135
107.51801,8.95975,845.69920,-0.06126,32.27643,42.31373
107.71800,8.97644,844.12815,-0.06115,32.34316,42.23513
107.91801,8.99324,844.90338,-0.06130,32.41036,42.27391
108.11800,9.00986,844.50319,-0.06122,32.47684,42.25389
108.31801,9.02648,843.96759,-0.06108,32.54333,42.22709
108.51801,9.04316,843.77974,-0.06138,32.61006,42.21769
108.71800,9.05990,843.57355,-0.06119,32.67702,42.20738
108.91801,9.07646,843.60400,-0.06102,32.74326,42.20890
109.11800,9.09314,843.81131,-0.06140,32.80999,42.21928
109.31801,9.10989,843.33448,-0.06117,32.87695,42.19542
109.51801,9.12645,843.13415,-0.06107,32.94320,42.18539
109.71800,9.14313,843.35841,-0.06141,33.00993,42.19661
109.91801,9.15981,843.18863,-0.06113,33.07665,42.18812
110.11800,9.17643,842.85606,-0.06114,33.14314,42.17148
110.31801,9.19317,842.44171,-0.06143,33.21010,42.15075
110.51801,9.20985,842.11882,-0.06109,33.27683,42.13459
110.71800,9.22653,841.65391,-0.06116,33.34355,42.11133
110.91801,9.24316,841.35365,-0.06143,33.41003,42.09631
111.11800,9.25984,840.29865,-0.06110,33.47676,42.04352
111.31801,9.27664,841.42992,-0.06117,33.54397,42.10012
111.51801,9.29314,840.64826,-0.06139,33.60997,42.06102
111.71800,9.30964,840.89413,-0.06112,33.67598,42.07331
111.91801,9.32644,840.29464,-0.06122,33.74318,42.04332
112.11800,9.34312,840.36682,-0.06139,33.80991,42.04693
112.31801,9.35987,839.72318,-0.06115,33.87688,42.01473
112.51801,9.37655,839.99597,-0.06126,33.94360,42.02838
112.71800,9.39317,839.76127,-0.06135,34.01008,42.01664
112.91801,9.40979,839.46213,-0.06113,34.07657,42.00167
113.11800,9.42647,838.75554,-0.06126,34.14330,41.96631
113.31801,9.44327,838.91302,-0.06128,34.21050,41.97419
113.51801,9.45983,837.82319,-0.06110,34.27675,41.91967
113.71800,9.47646,838.14235,-0.06126,34.34323,41.93563
113.91801,9.49320,837.61150,-0.06126,34.41020,41.90907
114.11800,9.50976,837.61048,-0.06112,34.47644,41.90902
114.31801,9.52650,837.75762,-0.06125,34.54341,41.91639
114.51801,9.54324,837.80456,-0.06125,34.61037,41.91873
114.71800,9.55986,836.84893,-0.06123,34.67686,41.87092
114.91801,9.57648,837.03324,-0.06125,34.74334,41.88014
115.11800,9.59316,836.15463,-0.06121,34.81007,41.83618
115.31801,9.60985,836.62411,-0.06122,34.87679,41.85967
115.51801,9.62647,835.97191,-0.06123,34.94328,41.82704
115.71800,9.64315,835.38713,-0.06123,35.01000,41.79778
115.91801,9.65983,834.94587,-0.06121,35.07673,41.77570
116.11800,9.67645,835.03686,-0.06120,35.14321,41.78025
116.31801,9.69313,834.19913,-0.06126,35.20994,41.73834
116.51801,9.70987,834.63416,-0.06122,35.27690,41.76011
116.71800,9.72655,833.67052,-0.06118,35.34363,41.71189
116.91801,9.74324,833.73440,-0.06129,35.41036,41.71509
117.11800,9.75986,832.84285,-0.06123,35.47684,41.67048
117.31801,9.77642,833.13305,-0.06119,35.54309,41.68500
117.51801,9.79310,832.81072,-0.06128,35.60981,41.66887
117.71800,9.80978,832.11623,-0.06120,35.67654,41.63412
117.91801,9.82652,832.20778,-0.06121,35.74350,41.63870
118.11800,9.84320,831.83944,-0.06125,35.81023,41.62027
118.31801,9.85982,831.17783,-0.06116,35.87671,41.58717
118.51801,9.87651,831.08628,-0.06126,35.94343,41.58259
118.71800,9.89319,830.86519,-0.06127,36.01016,41.57153
118.91801,9.90981,829.93507,-0.06113,36.07665,41.52499
119.11800,9.92655,829.64636,-0.06122,36.14361,41.51054
119.31801,9.94317,829.77572,-0.06129,36.21010,41.51702
119.51801,9.95985,828.89013,-0.06121,36.27683,41.47271
119.71800,9.97653,829.02117,-0.06117,36.34354,41.47926
119.91801,9.99322,828.32184,-0.06129,36.41028,41.44427
120.11800,10.00984,828.08211,-0.06122,36.47676,41.43228
120.31801,10.02646,828.02298,-0.06118,36.54324,41.42932
120.51801,10.04320,827.73212,-0.06131,36.61021,41.41477
120.71800,10.05982,826.63251,-0.06122,36.67670,41.35975
120.91801,10.07650,826.56667,-0.06123,36.74342,41.35646
121.11800,10.09324,826.29556,-0.06124,36.81038,41.34289
121.31801,10.10981,825.31711,-0.06118,36.87663,41.29393
121.51801,10.12643,825.39115,-0.06125,36.94312,41.29764
121.71800,10.14317,824.75971,-0.06122,37.01008,41.26605
121.91801,10.15985,824.55184,-0.06119,37.07681,41.25565
122.11800,10.17659,823.76106,-0.06127,37.14377,41.21608
122.31801,10.19315,823.02587,-0.06120,37.21001,41.17929
122.51801,10.20983,823.33507,-0.06123,37.27674,41.19477
122.71800,10.22651,822.26554,-0.06127,37.34347,41.14125
122.91801,10.24308,822.01855,-0.06124,37.40971,41.12889
123.11800,10.25982,821.58903,-0.06125,37.47668,41.10740
123.31801,10.27650,821.43713,-0.06130,37.54340,41.09980
123.51801,10.29312,820.66515,-0.06122,37.60989,41.06118
123.71800,10.30980,819.80517,-0.06123,37.67661,41.01815
123.91801,10.32648,819.76438,-0.06127,37.74334,41.01611
124.11800,10.34316,819.14514,-0.06120,37.81006,40.98513
124.31801,10.35984,818.63878,-0.06122,37.87679,40.95979
124.51801,10.37653,817.98173,-0.06124,37.94352,40.92692
124.71800,10.39315,817.32804,-0.06125,38.01000,40.89421
124.91801,10.40977,817.00841,-0.06121,38.07648,40.87822
125.11800,10.42651,815.89129,-0.06121,38.14345,40.82232
125.31801,10.44313,816.04542,-0.06125,38.20993,40.83004
125.51801,10.45987,815.62568,-0.06122,38.27690,40.80903
125.71800,10.47649,815.67774,-0.06121,38.34339,40.81164
125.91801,10.49311,815.20947,-0.06125,38.40987,40.78821
126.11800,10.50980,814.59684,-0.06125,38.47660,40.75756
126.31801,10.52648,813.96485,-0.06124,38.54333,40.72594
126.51801,10.54322,813.29336,-0.06120,38.61029,40.69234
126.71800,10.55984,812.86822,-0.06127,38.67677,40.67107
126.91801,10.57646,811.57973,-0.06123,38.74326,40.60660
127.11800,10.59320,811.53484,-0.06118,38.81022,40.60435
127.31801,10.60976,810.80860,-0.06127,38.87647,40.56802
127.51801,10.62651,810.50470,-0.06123,38.94343,40.55281
127.71800,10.64325,810.00812,-0.06119,39.01040,40.52797
127.91801,10.65981,809.66996,-0.06133,39.07664,40.51105
128.11801,10.67643,808.58544,-0.06115,39.14313,40.45678
128.31801,10.69317,807.54170,-0.06125,39.21010,40.40456
128.51801,10.70991,807.24917,-0.06128,39.27706,40.38992
128.71800,10.72647,806.21019,-0.06116,39.34331,40.33794
128.91800,10.74316,806.13587,-0.06124,39.41003,40.33422
129.11801,10.75984,805.04976,-0.06125,39.47676,40.27988
129.31801,10.77646,804.79849,-0.06118,39.54324,40.26731
129.51801,10.79320,803.38735,-0.06125,39.61020,40.19670
129.71800,10.80994,803.23368,-0.06124,39.67717,40.18901
129.91800,10.82650,802.59033,-0.06117,39.74342,40.15682
130.11801,10.84318,801.58738,-0.06125,39.81014,40.10664
130.31801,10.85980,801.23870,-0.06125,39.87663,40.08920
130.51801,10.87654,800.85220,-0.06115,39.94359,40.06986
130.71800,10.89323,799.27789,-0.06126,40.01032,39.99109
130.91800,10.90979,799.13940,-0.06133,40.07657,39.98416
131.11802,10.92647,798.04128,-0.06115,40.14329,39.92921
131.31802,10.94315,797.50279,-0.06120,40.21001,39.90227
131.51800,10.95983,796.71321,-0.06130,40.27674,39.86277
131.71800,10.97663,795.89160,-0.06119,40.34394,39.82166
131.91800,10.99319,795.34799,-0.06120,40.41019,39.79446
132.11802,11.00976,794.48037,-0.06130,40.47644,39.75105
132.31802,11.02650,793.20259,-0.06124,40.54340,39.68712
132.51800,11.04318,792.46340,-0.06121,40.61013,39.65013
132.71800,11.05980,792.08678,-0.06128,40.67661,39.63129
132.91800,11.07648,791.00216,-0.06128,40.74334,39.57702
133.11802,11.09322,790.22832,-0.06121,40.81030,39.53830
133.31802,11.10978,789.75130,-0.06125,40.87655,39.51443
133.51800,11.12647,788.56247,-0.06127,40.94327,39.45495
133.71800,11.14321,787.76982,-0.06122,41.01023,39.41529
133.91800,11.15983,786.72525,-0.06125,41.07672,39.36303
134.11802,11.17651,785.44477,-0.06123,41.14345,39.29896
134.31802,11.19319,785.48975,-0.06126,41.21017,39.30121
134.51800,11.20981,784.05254,-0.06127,41.27666,39.22930
134.71800,11.22643,783.61677,-0.06124,41.34315,39.20750
134.91800,11.24323,781.66779,-0.06125,41.41035,39.10999
135.11802,11.25992,780.65828,-0.06123,41.47708,39.05947
135.31802,11.27642,780.21181,-0.06130,41.54308,39.03714
135.51800,11.29316,779.48924,-0.06128,41.61004,39.00098
135.71800,11.30990,778.03484,-0.06121,41.67701,38.92822
135.91800,11.32652,777.05495,-0.06126,41.74350,38.87918
136.11802,11.34314,775.87334,-0.06131,41.80998,38.82006
136.31802,11.35982,774.72655,-0.06127,41.87670,38.76269
136.51800,11.37645,774.02769,-0.06116,41.94319,38.72772
136.71800,11.39307,772.56565,-0.06125,42.00968,38.65457
136.91800,11.40987,771.24005,-0.06127,42.07688,38.58824
137.11802,11.42661,769.90752,-0.06114,42.14385,38.52157
137.31802,11.44317,769.03854,-0.06127,42.21010,38.47809
137.51800,11.45979,767.81809,-0.06128,42.27658,38.41703
137.71800,11.47653,766.10511,-0.06117,42.34354,38.33132
137.91800,11.49316,764.70315,-0.06127,42.41003,38.26117
138.11802,11.50984,763.61364,-0.06127,42.47675,38.20666
138.31802,11.52652,761.56151,-0.06119,42.54348,38.10398
138.51800,11.54308,760.74735,-0.06129,42.60972,38.06325
138.71800,11.55976,759.73580,-0.06123,42.67645,38.01264
138.91800,11.57650,757.28102,-0.06119,42.74342,37.88982
139.11802,11.59318,755.67705,-0.06129,42.81014,37.80956
139.31802,11.60986,754.11340,-0.06124,42.87687,37.73133
139.51800,11.62649,752.36801,-0.06119,42.94335,37.64400
139.71800,11.64317,750.16920,-0.06131,43.01008,37.53399
139.91800,11.65979,748.07955,-0.06123,43.07656,37.42943
140.11802,11.67647,746.04806,-0.06117,43.14328,37.32779
140.31802,11.69327,743.25684,-0.06127,43.21049,37.18813
140.51800,11.70983,740.01076,-0.06126,43.27674,37.02571
140.71800,11.72639,735.68998,-0.06121,43.34298,36.80953
140.91800,11.74319,729.32239,-0.06125,43.41019,36.49093
141.11802,11.75981,719.49223,-0.06123,43.47667,35.99909
141.30600,11.77560,0.45433,-0.06122,43.53981,0.02273