File: Manufatura Aditiva/Classificação Orientação/Ensaios/Ensaios SLS/Tracao_OLABI_21_12_2018_SLS_45.is_metal_RawData/Specimen_RawData_1.csv
Time,Extension,Load,Strain 1,Tensile strain,Tensile stress
(sec),(mm),(N),(mm/mm),(%),(MPa)
0.00000,0.00000,31.90932,0.00114,0.11422,1.54218
0.20000,0.01190,38.05973,0.00130,0.12960,1.83943
0.40000,0.03211,49.81944,0.00165,0.16546,2.40778
0.60000,0.04974,60.16943,0.00196,0.19606,2.90800
0.80000,0.06655,70.17031,0.00225,0.22499,3.39134
1.00000,0.08335,79.29461,0.00254,0.25445,3.83232
1.20000,0.09997,88.29314,0.00283,0.28251,4.26722
1.40000,0.11665,98.02548,0.00312,0.31160,4.73759
1.60000,0.13327,106.94845,0.00340,0.34010,5.16884
1.80000,0.14989,115.20192,0.00369,0.36878,5.56773
2.00000,0.16663,123.84414,0.00397,0.39692,5.98541
2.20000,0.18325,132.67371,0.00425,0.42528,6.41215
2.40000,0.19988,141.52516,0.00454,0.45400,6.83994
2.60000,0.21662,150.63731,0.00483,0.48299,7.28033
2.80000,0.23330,158.41915,0.00511,0.51084,7.65643
3.00000,0.24998,166.80644,0.00539,0.53938,8.06179
3.20000,0.26666,175.55911,0.00568,0.56803,8.48481
3.40000,0.28334,184.17783,0.00596,0.59650,8.90135
3.60000,0.29990,192.37415,0.00625,0.62494,9.29748
3.80000,0.31659,201.56887,0.00653,0.65349,9.74186
4.00000,0.33333,209.40558,0.00682,0.68222,10.12061
4.20000,0.34995,217.14219,0.00710,0.70961,10.49452
4.40000,0.36663,226.43928,0.00738,0.73820,10.94385
4.60000,0.38331,234.07703,0.00767,0.76651,11.31299
4.80000,0.39987,242.31332,0.00794,0.79444,11.71105
5.00000,0.41661,249.58667,0.00823,0.82254,12.06257
5.20000,0.43335,258.68048,0.00852,0.85200,12.50208
5.40000,0.44998,265.83157,0.00880,0.88024,12.84769
5.60000,0.46660,274.48682,0.00909,0.90909,13.26600
5.80000,0.48328,282.73680,0.00938,0.93768,13.66472
6.00000,0.50002,289.79473,0.00966,0.96595,14.00583
6.20000,0.51658,298.11282,0.00994,0.99402,14.40785
6.40000,0.53332,305.83756,0.01023,1.02282,14.78119
6.60000,0.55006,313.65838,0.01052,1.05167,15.15917
6.80000,0.56662,320.78282,0.01080,1.08023,15.50350
7.00000,0.58319,328.64164,0.01108,1.10840,15.88331
7.20000,0.59993,333.90024,0.01131,1.13062,16.13746
7.40000,0.61661,341.82894,0.01160,1.16024,16.52066
7.60000,0.63323,348.92142,0.01189,1.18937,16.86344
7.80000,0.64985,356.60756,0.01217,1.21725,17.23491
8.00000,0.66665,364.05986,0.01246,1.24608,17.59508
8.20000,0.68327,370.52550,0.01275,1.27502,17.90757
8.40000,0.69996,377.88502,0.01304,1.30419,18.26326
8.60000,0.71670,384.81846,0.01333,1.33258,18.59835
8.80000,0.73326,391.81290,0.01362,1.36160,18.93639
9.00000,0.74994,399.14357,0.01390,1.39010,19.29069
9.20000,0.76662,406.11820,0.01419,1.41916,19.62777
9.40000,0.78324,412.73045,0.01449,1.44862,19.94734
9.60000,0.79998,419.78667,0.01478,1.47756,20.28837
9.80000,0.81660,426.39473,0.01506,1.50642,20.60774
10.00000,0.83323,434.06240,0.01536,1.53573,20.97832
10.20000,0.84991,440.47926,0.01565,1.56467,21.28845
10.40000,0.86659,446.99847,0.01594,1.59411,21.60352
10.60000,0.88345,453.68192,0.01622,1.62215,21.92653
10.80000,0.89995,458.90794,0.01648,1.64845,22.17911
11.00000,0.91657,465.19982,0.01678,1.67785,22.48320
11.20000,0.93331,471.27977,0.01708,1.70768,22.77704
11.40000,0.94994,478.05747,0.01737,1.73736,23.10461
11.60000,0.96656,484.01346,0.01767,1.76686,23.39246
11.80000,0.98330,489.96257,0.01797,1.79716,23.67999
12.00000,0.99998,496.36229,0.01827,1.82720,23.98928
12.20000,1.01654,501.87563,0.01857,1.85666,24.25574
12.40000,1.03322,507.58230,0.01887,1.88744,24.53155
12.60000,1.05002,513.42570,0.01918,1.91790,24.81396
12.80000,1.06658,518.69713,0.01948,1.94781,25.06873
13.00000,1.08327,525.33098,0.01979,1.97862,25.38935
13.20000,1.10001,529.33400,0.02010,2.00961,25.58281
13.40000,1.11657,535.82406,0.02040,2.03978,25.89648
13.60000,1.13331,540.27503,0.02071,2.07061,26.11160
13.80000,1.14999,545.44858,0.02102,2.10169,26.36164
14.00000,1.16673,549.35934,0.02129,2.12879,26.55064
14.20000,1.18323,553.30708,0.02158,2.15803,26.74144
14.40000,1.19998,559.12361,0.02190,2.18950,27.02255
14.60000,1.21666,564.22073,0.02222,2.22155,27.26890
14.80000,1.23328,569.20717,0.02253,2.25260,27.50989
15.00000,1.24990,573.72558,0.02284,2.28435,27.72827
15.20000,1.26658,578.42545,0.02316,2.31623,27.95541
15.40000,1.28320,583.13501,0.02348,2.34811,28.18303
15.60000,1.29988,587.15292,0.02380,2.37981,28.37721
15.80000,1.31662,591.65591,0.02412,2.41175,28.59484
16.00000,1.33331,595.96989,0.02444,2.44406,28.80334
16.20000,1.34999,600.17142,0.02476,2.47628,29.00640
16.40000,1.36667,604.44647,0.02509,2.50867,29.21301
16.60000,1.38335,608.81996,0.02541,2.54144,29.42439
16.80000,1.39991,612.41919,0.02574,2.57369,29.59834
17.00000,1.41659,616.26178,0.02607,2.60729,29.78405
17.20000,1.43333,620.13785,0.02641,2.64095,29.97138
17.40000,1.44990,623.78468,0.02673,2.67342,30.14763
17.60000,1.46658,627.96180,0.02707,2.70660,30.34951
17.80000,1.48332,631.94730,0.02740,2.74035,30.54214
18.00000,1.49994,634.69191,0.02773,2.77322,30.67478
18.20000,1.51662,636.78911,0.02802,2.80211,30.77614
18.40000,1.53330,640.63505,0.02836,2.83569,30.96202
18.60000,1.54992,644.20761,0.02869,2.86926,31.13468
18.80000,1.56660,647.58565,0.02903,2.90334,31.29794
19.00000,1.58329,650.61855,0.02937,2.93723,31.44452
19.20000,1.60003,653.95730,0.02971,2.97139,31.60588
19.40000,1.61665,656.97678,0.03006,3.00564,31.75181
19.60000,1.63327,659.75883,0.03040,3.04003,31.88627
19.80000,1.64995,663.60137,0.03075,3.07489,32.07198
20.00000,1.66663,666.30007,0.03109,3.12477,32.20241
20.19400,1.68272,669.59299,0.03143,3.18911,32.36156
20.39400,1.69952,672.30803,0.03178,3.25631,32.49277
20.59400,1.71614,674.88966,0.03212,3.32280,32.61755
20.79400,1.73276,677.89727,0.03247,3.38928,32.76291
20.99400,1.74944,680.46423,0.03283,3.45601,32.88697
21.19400,1.76612,682.81479,0.03318,3.52273,33.00057
21.39400,1.78280,685.92299,0.03348,3.58946,33.15079
21.59400,1.79942,688.02475,0.03406,3.65594,33.25237
21.79400,1.81617,690.73904,0.03291,3.72291,33.38355
21.99400,1.83285,693.32449,0.01222,3.78963,33.50851
22.19400,1.84947,695.48017,0.00674,3.85612,33.61269
22.39400,1.86615,697.51800,0.00783,3.92284,33.71118
22.59400,1.88283,700.75206,0.00621,3.98957,33.86748
22.79400,1.89939,703.14077,0.00496,4.05582,33.98293
22.99400,1.91607,705.79266,0.00510,4.12254,34.11110
23.19400,1.93276,707.47891,0.00643,4.18927,34.19259
23.39400,1.94950,709.70925,0.00884,4.25623,34.30038
23.59400,1.96612,712.26005,0.00117,4.32272,34.42366
23.79400,1.98280,714.53759,-0.02534,4.38944,34.53374
23.99400,1.99948,716.28504,-0.10629,4.45617,34.61819
24.19400,2.01610,718.52263,-0.13866,4.52265,34.72634
24.39400,2.03284,720.51310,-0.11294,4.58962,34.82254
24.59400,2.04946,720.75813,-0.03521,4.65610,34.83438
24.79400,2.06621,723.16481,-0.05118,4.72307,34.95070
24.99400,2.08283,725.40580,-0.05516,4.78955,35.05900
25.19400,2.09945,727.56321,-0.05562,4.85604,35.16327
25.39400,2.11607,729.37510,-0.05461,4.92252,35.25084
25.59400,2.13269,731.74075,-0.05534,4.98901,35.36517
25.79400,2.14943,733.28749,-0.05498,5.05597,35.43993
25.99400,2.16605,735.12839,-0.05512,5.12246,35.52890
26.19400,2.18273,736.98154,-0.05511,5.18918,35.61846
26.39400,2.19948,738.77042,-0.05509,5.25615,35.70492
26.59400,2.21610,740.62333,-0.05513,5.32263,35.79447
26.79400,2.23284,742.76063,-0.05511,5.38960,35.89776
26.99400,2.24946,744.59501,-0.05513,5.45608,35.98642
27.19400,2.26614,746.21816,-0.05512,5.52281,36.06487
27.39400,2.28282,747.58688,-0.05514,5.58953,36.13102
27.59400,2.29944,749.42904,-0.05514,5.65602,36.22005
27.79400,2.31619,751.20241,-0.05514,5.72299,36.30576
27.99400,2.33281,753.19447,-0.05516,5.78947,36.40203
28.19400,2.34937,755.24901,-0.05515,5.85572,36.50133
28.39400,2.36611,756.12264,-0.05516,5.92268,36.54355
28.59400,2.38273,757.86831,-0.05513,5.98917,36.62792
28.79400,2.39941,759.50380,-0.05515,6.05589,36.70697
28.99400,2.41615,760.66009,-0.05516,6.12286,36.76285
29.19400,2.43277,762.46257,-0.05515,6.18934,36.84996
29.39400,2.44946,764.15353,-0.05517,6.25607,36.93169
29.59400,2.46608,765.73566,-0.05518,6.32255,37.00815
29.79400,2.48282,767.13655,-0.05517,6.38952,37.07586
29.99400,2.49950,768.44404,-0.05517,6.45624,37.13905
30.19400,2.51618,769.85024,-0.05519,6.52297,37.20701
30.39400,2.53280,771.51675,-0.05518,6.58945,37.28755
30.59400,2.54942,773.23131,-0.05518,6.65594,37.37042
30.79400,2.56611,774.39854,-0.05518,6.72266,37.42683
30.99400,2.58279,775.44604,-0.05518,6.78939,37.47746
31.19400,2.59941,777.52471,-0.05518,6.85588,37.57792
31.39400,2.61603,778.32690,-0.05519,6.92236,37.61669
31.59400,2.63271,779.69250,-0.05518,6.98909,37.68269
31.79400,2.64945,781.08707,-0.05518,7.05605,37.75009
31.99400,2.66619,782.13280,-0.05518,7.12302,37.80063
32.19400,2.68275,783.66706,-0.05520,7.18926,37.87478
32.39400,2.69950,784.24541,-0.05521,7.25623,37.90273
32.59400,2.71606,785.68868,-0.05521,7.32247,37.97248
32.79400,2.73268,787.35463,-0.05521,7.38896,38.05300
32.99400,2.74942,788.71157,-0.05520,7.45592,38.11858
33.19400,2.76622,789.77877,-0.05519,7.52313,38.17016
33.39400,2.78278,790.68281,-0.05520,7.58937,38.21385
33.59400,2.79952,792.05343,-0.05520,7.65634,38.28009
33.79400,2.81608,793.11226,-0.05521,7.72258,38.33127
33.99400,2.83271,794.43539,-0.05520,7.78907,38.39521
34.19400,2.84951,796.23815,-0.05521,7.85627,38.48234
34.39400,2.86619,796.87405,-0.05521,7.92300,38.51308
34.59400,2.88269,796.96076,-0.05521,7.98901,38.51727
34.79400,2.89937,799.73564,-0.05521,8.05573,38.65137
34.99400,2.91617,799.91380,-0.05521,8.12294,38.65999
35.19400,2.93285,800.88349,-0.05522,8.18966,38.70685
35.39400,2.94948,802.16117,-0.05520,8.25615,38.76860
35.59400,2.96616,802.87559,-0.05522,8.32287,38.80313
35.79400,2.98278,803.51699,-0.05521,8.38936,38.83413
35.99400,2.99940,803.37198,-0.05521,8.45584,38.82712
36.19400,3.01614,804.56780,-0.05521,8.52281,38.88491
36.39400,3.03276,805.97736,-0.05522,8.58929,38.95304
36.59400,3.04944,807.21620,-0.05522,8.65602,39.01291
36.79400,3.06606,808.46865,-0.05522,8.72250,39.07344
36.99400,3.08281,809.28383,-0.05521,8.78947,39.11284
37.19400,3.09943,810.55276,-0.05522,8.85595,39.17417
37.39400,3.11611,811.56148,-0.05523,8.92268,39.22292
37.59400,3.13285,812.61359,-0.05522,8.98964,39.27377
37.79400,3.14947,813.36824,-0.05522,9.05613,39.31024
37.99400,3.16609,815.03205,-0.05522,9.12262,39.39066
38.19400,3.18277,816.03164,-0.05521,9.18934,39.43896
38.39400,3.19946,816.34587,-0.05523,9.25606,39.45415
38.59400,3.21608,817.42583,-0.05522,9.32255,39.50635
38.79400,3.23276,817.75319,-0.05522,9.38928,39.52217
38.99400,3.24944,818.99781,-0.05522,9.45600,39.58232
39.19400,3.26606,820.72476,-0.05522,9.52249,39.66579
39.39400,3.28274,820.67484,-0.05522,9.58921,39.66337
39.59400,3.29954,821.80388,-0.05522,9.65642,39.71794
39.79400,3.31610,822.89595,-0.05524,9.72266,39.77072
39.99400,3.33273,823.43118,-0.05523,9.78915,39.79659
40.19400,3.34947,824.97960,-0.05523,9.85611,39.87142
40.39400,3.36609,825.55395,-0.05524,9.92260,39.89918
40.59400,3.38283,825.86352,-0.05524,9.98956,39.91414
40.79400,3.39957,827.10134,-0.05523,10.05653,39.97396
40.99400,3.41613,828.85865,-0.05523,10.12277,40.05890
41.19400,3.43269,829.66862,-0.05523,10.18902,40.09805
41.39400,3.44944,829.66257,-0.05524,10.25598,40.09775
41.59400,3.46624,830.31505,-0.05524,10.32319,40.12929
41.79400,3.48274,831.24917,-0.05524,10.38920,40.17443
41.99400,3.49936,832.27223,-0.05524,10.45568,40.22388
42.19400,3.51616,832.92620,-0.05522,10.52289,40.25548
42.39400,3.53284,834.17892,-0.05524,10.58961,40.31603
42.59400,3.54940,834.38028,-0.05525,10.65586,40.32576
42.79400,3.56620,835.28524,-0.05526,10.72306,40.36950
42.99400,3.58283,835.96120,-0.05525,10.78955,40.40216
43.19400,3.59939,837.07999,-0.05525,10.85579,40.45624
43.39400,3.61613,837.95786,-0.05523,10.92276,40.49866
43.59400,3.63281,838.37444,-0.05524,10.98948,40.51880
43.79400,3.64943,838.96350,-0.05524,11.05597,40.54727
43.99400,3.66611,840.00072,-0.05522,11.12269,40.59740
44.19400,3.68273,840.64584,-0.05525,11.18918,40.62857
44.39400,3.69941,841.68650,-0.05525,11.25590,40.67887
44.59400,3.71610,841.90900,-0.05526,11.32263,40.68962
44.79400,3.73284,842.06676,-0.05527,11.38959,40.69725
44.99400,3.74946,843.13005,-0.05527,11.45608,40.74864
45.19400,3.76614,843.59376,-0.05524,11.52280,40.77105
45.39400,3.78270,844.55647,-0.05524,11.58905,40.81758
45.59400,3.79944,844.89463,-0.05524,11.65602,40.83392
45.79400,3.81612,845.41254,-0.05526,11.72274,40.85895
45.99400,3.83275,846.75802,-0.05525,11.78923,40.92398
46.19400,3.84949,846.94372,-0.05528,11.85619,40.93295
46.39400,3.86611,847.43081,-0.05529,11.92268,40.95649
46.59400,3.88273,847.67062,-0.05527,11.98916,40.96808
46.79400,3.89947,849.24875,-0.05527,12.05613,41.04435
46.99400,3.91615,849.85401,-0.05524,12.12285,41.07361
47.19400,3.93277,850.58622,-0.05525,12.18934,41.10899
47.39400,3.94945,850.87288,-0.05526,12.25606,41.12285
47.59400,3.96614,851.74860,-0.05525,12.32279,41.16517
47.79400,3.98270,852.43201,-0.05524,12.38904,41.19820
47.99400,3.99944,852.49515,-0.05526,12.45600,41.20126
48.19400,4.01624,853.39844,-0.05526,12.52320,41.24491
48.39400,4.03274,853.54466,-0.05527,12.58921,41.25198
48.59400,4.04942,854.25703,-0.05527,12.65594,41.28641
48.79400,4.06616,854.53037,-0.05528,12.72290,41.29962
48.99400,4.08279,855.75664,-0.05526,12.78939,41.35888
49.19400,4.09941,855.95567,-0.05527,12.85587,41.36850
49.39400,4.11615,855.09419,-0.05526,12.92284,41.32687
49.59400,4.13277,855.45881,-0.05528,12.98932,41.34449
49.79400,4.14945,855.54607,-0.05526,13.05605,41.34871
49.99400,4.16607,857.08639,-0.05527,13.12253,41.42315
50.19400,4.18287,857.60448,-0.05529,13.18974,41.44819
50.39400,4.19949,858.40374,-0.05526,13.25622,41.48682
50.59400,4.21612,858.71499,-0.05526,13.32271,41.50186
50.79400,4.23274,859.31709,-0.05526,13.38919,41.53096
50.99400,4.24942,859.83565,-0.05525,13.45592,41.55602
51.19400,4.26610,860.32739,-0.05526,13.52264,41.57979
51.39400,4.28278,860.26238,-0.05527,13.58937,41.57664
51.59400,4.29946,861.01098,-0.05527,13.65609,41.61283
51.79400,4.31608,861.59455,-0.05529,13.72258,41.64103
51.99400,4.33271,862.01634,-0.05529,13.78907,41.66142
52.19400,4.34945,862.76541,-0.05529,13.85603,41.69762
52.39400,4.36613,862.49653,-0.05529,13.92275,41.68462
52.59400,4.38281,862.96201,-0.05527,13.98948,41.70712
52.79400,4.39949,863.41659,-0.05526,14.05621,41.72909
52.99400,4.41611,864.64351,-0.05528,14.12269,41.78839
53.19400,4.43279,864.24435,-0.05529,14.18942,41.76910
53.39400,4.44941,864.52952,-0.05529,14.25590,41.78288
53.59400,4.46616,865.21152,-0.05528,14.32287,41.81584
53.79400,4.48284,865.39658,-0.05530,14.38959,41.82478
53.99400,4.49940,865.42238,-0.05528,14.45584,41.82603
54.19400,4.51614,866.54937,-0.05527,14.52280,41.88050
54.39400,4.53282,866.75128,-0.05526,14.58953,41.89025
54.59400,4.54944,866.75081,-0.05527,14.65601,41.89023
54.79400,4.56618,867.67506,-0.05526,14.72298,41.93490
54.99400,4.58275,867.33149,-0.05528,14.78923,41.91830
55.19400,4.59943,868.45402,-0.05526,14.85595,41.97255
55.39400,4.61617,868.47171,-0.05527,14.92292,41.97340
55.59400,4.63285,869.27712,-0.05526,14.98964,42.01233
55.79400,4.64941,869.30450,-0.05527,15.05588,42.01365
55.99400,4.66615,869.45929,-0.05528,15.12285,42.02113
56.19400,4.68283,869.79959,-0.05530,15.18957,42.03758
56.39400,4.69939,870.21729,-0.05530,15.25582,42.05777
56.59400,4.71614,869.84131,-0.05529,15.32279,42.03960
56.79400,4.73282,870.74796,-0.05529,15.38951,42.08342
56.99400,4.74944,870.71965,-0.05528,15.45600,42.08205
57.19400,4.76606,871.96724,-0.05528,15.52248,42.14235
57.39400,4.78274,871.69893,-0.05529,15.58921,42.12938
57.59400,4.79942,871.75621,-0.05528,15.65593,42.13214
57.79400,4.81616,872.26434,-0.05533,15.72290,42.15670
57.99400,4.83278,872.10899,-0.05533,15.78938,42.14920
58.19400,4.84947,872.98350,-0.05531,15.85611,42.19146
58.39400,4.86615,872.94411,-0.05531,15.92283,42.18956
58.59400,4.88271,873.54137,-0.05529,15.98908,42.21842
58.79400,4.89945,873.51333,-0.05527,16.05604,42.21707
58.99400,4.91613,874.18268,-0.05525,16.12277,42.24942
59.19400,4.93275,874.16507,-0.05527,16.18926,42.24857
59.39400,4.94943,874.54952,-0.05526,16.25598,42.26715
59.59400,4.96606,875.04210,-0.05526,16.32247,42.29095
59.79400,4.98274,875.22250,-0.05526,16.38919,42.29967
59.99400,4.99942,874.32340,-0.05526,16.45592,42.25622
60.19400,5.01610,875.64113,-0.05527,16.52264,42.31990
60.39400,5.03272,875.68732,-0.05528,16.58913,42.32214
60.59400,5.04940,876.23997,-0.05529,16.65585,42.34885
60.79400,5.06614,875.75521,-0.05529,16.72282,42.32542
60.99400,5.08282,875.54846,-0.05529,16.78954,42.31543
61.19400,5.09945,876.56286,-0.05528,16.85603,42.36445
61.39400,5.11613,877.06819,-0.05529,16.92275,42.38887
61.59400,5.13275,876.89878,-0.05528,16.98924,42.38069
61.79400,5.14943,877.19010,-0.05528,17.05596,42.39477
61.99400,5.16617,876.92766,-0.05528,17.12293,42.38208
62.19400,5.18279,877.31546,-0.05529,17.18941,42.40083
62.39400,5.19941,877.66722,-0.05529,17.25590,42.41782
62.59400,5.21610,877.42629,-0.05529,17.32263,42.40618
62.79400,5.23272,878.56455,-0.05528,17.38911,42.46119
62.99400,5.24940,878.11975,-0.05528,17.45584,42.43970
63.19400,5.26614,878.52608,-0.05530,17.52280,42.45934
63.39400,5.28288,878.73731,-0.05528,17.58976,42.46954
63.59400,5.29944,878.89563,-0.05528,17.65601,42.47720
63.79400,5.31612,878.84692,-0.05528,17.72273,42.47484
63.99400,5.33286,879.61461,-0.05529,17.78970,42.51194
64.19400,5.34948,879.09717,-0.05526,17.85618,42.48693
64.39400,5.36611,879.43831,-0.05528,17.92267,42.50342
64.59400,5.38279,879.88935,-0.05528,17.98940,42.52522
64.79401,5.39941,879.61750,-0.05528,18.05588,42.51208
64.99400,5.41609,879.48861,-0.05527,18.12261,42.50585
65.19400,5.43277,879.95073,-0.05527,18.18933,42.52819
65.39400,5.44945,879.92856,-0.05528,18.25606,42.52711
65.59400,5.46607,880.36619,-0.05528,18.32254,42.54827
65.79401,5.48276,880.63525,-0.05527,18.38927,42.56127
65.99400,5.49950,880.81723,-0.05528,18.45623,42.57006
66.19400,5.51606,880.61541,-0.05527,18.52248,42.56031
66.39401,5.53286,880.71134,-0.05528,18.58968,42.56495
66.59400,5.54954,880.68936,-0.05526,18.65641,42.56388
66.79401,5.56604,880.92955,-0.05528,18.72242,42.57549
66.99400,5.58272,880.48093,-0.05526,18.78914,42.55381
67.19400,5.59941,880.79199,-0.05528,18.85587,42.56885
67.39401,5.61615,881.05239,-0.05526,18.92283,42.58143
67.59400,5.63283,881.80350,-0.05528,18.98956,42.61773
67.79401,5.64945,881.86562,-0.05527,19.05604,42.62074
67.99400,5.66613,882.40830,-0.05528,19.12277,42.64696
68.19400,5.68269,881.72043,-0.05529,19.18901,42.61372
68.39401,5.69943,881.82529,-0.05530,19.25598,42.61879
68.59400,5.71617,881.45519,-0.05529,19.32294,42.60090
68.79401,5.73268,881.91535,-0.05530,19.38895,42.62314
68.99400,5.74942,881.96713,-0.05526,19.45591,42.62564
69.19400,5.76616,881.98464,-0.05530,19.52288,42.62649
69.39401,5.78290,882.61878,-0.05529,19.58984,42.65714
69.59400,5.79946,881.76047,-0.05529,19.65609,42.61565
69.79401,5.81614,882.55890,-0.05529,19.72281,42.65424
69.99400,5.83282,883.04710,-0.05529,19.78954,42.67784
70.19400,5.84939,882.84556,-0.05530,19.85579,42.66809
70.39401,5.86607,882.50721,-0.05529,19.92251,42.65174
70.59400,5.88293,882.64924,-0.05528,19.98995,42.65861
70.79401,5.89943,882.62493,-0.05530,20.05596,42.65743
70.99400,5.91611,883.12076,-0.05528,20.12269,42.68140
71.19400,5.93285,883.21110,-0.05528,20.18965,42.68576
71.39401,5.94947,883.39299,-0.05529,20.25613,42.69455
71.59400,5.96609,883.29250,-0.05528,20.32262,42.68970
71.79401,5.98284,882.99867,-0.05528,20.38959,42.67550
71.99400,5.99952,883.42857,-0.05529,20.45631,42.69627
72.19400,6.01608,883.88566,-0.05527,20.52256,42.71836
72.39401,6.03276,883.41301,-0.05532,20.58928,42.69552
72.59400,6.04950,883.30312,-0.05528,20.65625,42.69021
72.79401,6.06612,883.57348,-0.05530,20.72273,42.70328
72.99400,6.08274,883.66512,-0.05530,20.78922,42.70771
73.19400,6.09942,883.32938,-0.05531,20.85594,42.69148
73.39401,6.11611,883.82531,-0.05529,20.92267,42.71545
73.59400,6.13279,883.74233,-0.05530,20.98939,42.71144
73.79401,6.14947,883.83723,-0.05532,21.05612,42.71602
73.99400,6.16621,883.77567,-0.05533,21.12308,42.71305
74.19400,6.18265,883.88389,-0.05533,21.18885,42.71828
74.39401,6.19933,884.09586,-0.05534,21.25558,42.72852
74.59400,6.21613,883.69055,-0.05532,21.32278,42.70893
74.79401,6.23276,883.92990,-0.05529,21.38927,42.72050
74.99400,6.24950,883.49096,-0.05531,21.45623,42.69929
75.19400,6.26618,883.65013,-0.05527,21.52296,42.70698
75.39401,6.28274,883.88342,-0.05532,21.58920,42.71825
75.59400,6.29936,884.28156,-0.05529,21.65569,42.73750
75.79401,6.31610,883.92906,-0.05532,21.72265,42.72046
75.99400,6.33278,883.78675,-0.05530,21.78938,42.71358
76.19400,6.34946,883.81441,-0.05531,21.85610,42.71492
76.39401,6.36615,884.00031,-0.05530,21.92283,42.72390
76.59400,6.38289,883.91220,-0.05529,21.98979,42.71965
76.79401,6.39945,883.61809,-0.05532,22.05604,42.70543
76.99400,6.41613,884.26191,-0.05530,22.12276,42.73655
77.19400,6.43287,883.70685,-0.05529,22.18973,42.70972
77.39401,6.44943,883.72501,-0.05529,22.25598,42.71060
77.59400,6.46599,883.56482,-0.05529,22.32222,42.70286
77.79401,6.48285,884.39025,-0.05529,22.38966,42.74275
77.99400,6.49948,883.73525,-0.05530,22.45615,42.71109
78.19400,6.51610,884.41540,-0.05528,22.52264,42.74397
78.39401,6.53278,883.75127,-0.05529,22.58936,42.71187
78.59400,6.54946,884.72124,-0.05530,22.65609,42.75875
78.79401,6.56608,884.32673,-0.05527,22.72257,42.73968
78.99400,6.58282,884.05004,-0.05533,22.78954,42.72631
79.19400,6.59956,884.12156,-0.05529,22.85650,42.72976
79.39401,6.61613,883.52906,-0.05530,22.92275,42.70113
79.59400,6.63275,883.37380,-0.05533,22.98923,42.69363
79.79401,6.64949,882.34134,-0.05524,23.05620,42.64373
79.99400,6.66611,882.54036,-0.05535,23.12268,42.65335
80.19400,6.68279,882.40877,-0.05527,23.18941,42.64698
80.39401,6.69947,882.64532,-0.05531,23.25613,42.65842
80.59400,6.71609,882.65613,-0.05529,23.32262,42.65894
80.79401,6.73278,883.49655,-0.05530,23.38935,42.69956
80.99400,6.74940,882.86996,-0.05529,23.45583,42.66927
81.19400,6.76614,883.11238,-0.05529,23.52280,42.68099
81.39401,6.78276,882.73510,-0.05530,23.58928,42.66276
81.59400,6.79944,883.28980,-0.05528,23.65600,42.68956
81.79401,6.81612,883.28812,-0.05531,23.72273,42.68948
81.99400,6.83274,883.36244,-0.05530,23.78922,42.69308
82.19400,6.84942,883.23243,-0.05529,23.85594,42.68679
82.39401,6.86623,882.52975,-0.05534,23.92315,42.65283
82.59400,6.88285,883.48193,-0.05531,23.98963,42.69885
82.79401,6.89941,883.32547,-0.05535,24.05588,42.69129
82.99400,6.91609,883.48100,-0.05534,24.12260,42.69881
83.19400,6.93277,883.36235,-0.05530,24.18933,42.69307
83.39401,6.94939,883.26186,-0.05532,24.25581,42.68821
83.59400,6.96613,882.38260,-0.05528,24.32278,42.64572
83.79401,6.98281,882.96328,-0.05528,24.38950,42.67379
83.99400,6.99944,883.05734,-0.05533,24.45599,42.67833
84.19400,7.01606,883.07317,-0.05530,24.52248,42.67910
84.39401,7.03286,882.97492,-0.05533,24.58968,42.67435
84.59400,7.04948,882.90134,-0.05533,24.65617,42.67079
84.79401,7.06610,882.80914,-0.05532,24.72265,42.66634
84.99400,7.08278,882.52081,-0.05533,24.78938,42.65240
85.19400,7.09946,882.70865,-0.05537,24.85610,42.66148
85.39401,7.11614,882.66497,-0.05533,24.92282,42.65937
85.59400,7.13271,882.52956,-0.05535,24.98907,42.65282
85.79401,7.14951,882.77794,-0.05535,25.05628,42.66483
85.99400,7.16607,882.08951,-0.05534,25.12252,42.63155
86.19401,7.18269,883.39653,-0.05533,25.18901,42.69473
86.39401,7.19943,883.07550,-0.05530,25.25597,42.67921
86.59400,7.21605,882.28211,-0.05531,25.32246,42.64087
86.79401,7.23279,882.51447,-0.05526,25.38942,42.65209
86.99400,7.24948,882.52528,-0.05534,25.45615,42.65261
87.19401,7.26616,882.20695,-0.05528,25.52287,42.63723
87.39401,7.28278,882.11838,-0.05534,25.58936,42.63295
87.59400,7.29940,882.41193,-0.05528,25.65584,42.64714
87.79401,7.31620,882.20527,-0.05530,25.72305,42.63715
87.99400,7.33276,882.20229,-0.05526,25.78929,42.63700
88.19401,7.34944,882.20946,-0.05531,25.85602,42.63735
88.39401,7.36613,881.45249,-0.05529,25.92275,42.60077
88.59400,7.38281,881.46143,-0.05531,25.98947,42.60120
88.79401,7.39949,881.96546,-0.05534,26.05619,42.62556
88.99400,7.41605,880.85635,-0.05531,26.12244,42.57196
89.19401,7.43273,881.70161,-0.05535,26.18917,42.61281
89.39401,7.44947,881.31456,-0.05530,26.25613,42.59410
89.59400,7.46603,880.71814,-0.05533,26.32238,42.56528
89.79401,7.48283,881.22748,-0.05527,26.38958,42.58989
89.99400,7.49952,881.15800,-0.05531,26.45631,42.58654
90.19401,7.51608,880.92880,-0.05530,26.52256,42.57546
90.39401,7.53282,881.04941,-0.05532,26.58952,42.58129
90.59400,7.54944,881.39670,-0.05532,26.65600,42.59807
90.79401,7.56606,880.48205,-0.05533,26.72249,42.55387
90.99400,7.58280,880.70566,-0.05531,26.78946,42.56467
91.19401,7.59948,880.59604,-0.05533,26.85618,42.55938
91.39401,7.61611,880.86715,-0.05532,26.92266,42.57248
91.59400,7.63273,880.06174,-0.05533,26.98915,42.53355
91.79401,7.64947,880.61774,-0.05529,27.05611,42.56042
91.99400,7.66609,880.73909,-0.05531,27.12260,42.56629
92.19401,7.68283,879.95343,-0.05532,27.18956,42.52832
92.39401,7.69951,880.15283,-0.05531,27.25629,42.53796
92.59400,7.71613,879.50993,-0.05532,27.32278,42.50689
92.79401,7.73281,879.99804,-0.05531,27.38950,42.53048
92.99400,7.74950,879.70356,-0.05530,27.45623,42.51624
93.19401,7.76612,879.98053,-0.05530,27.52271,42.52963
93.39401,7.78286,879.42295,-0.05529,27.58968,42.50268
93.59400,7.79942,879.23743,-0.05532,27.65592,42.49371
93.79401,7.81610,879.25429,-0.05531,27.72265,42.49453
93.99400,7.83278,879.03934,-0.05531,27.78937,42.48414
94.19401,7.84940,878.93847,-0.05531,27.85586,42.47926
94.39401,7.86614,878.88492,-0.05532,27.92282,42.47668
94.59400,7.88271,878.77139,-0.05531,27.98907,42.47119
94.79401,7.89939,878.73004,-0.05531,28.05580,42.46919
94.99400,7.91613,878.56501,-0.05531,28.12276,42.46122
95.19401,7.93281,877.89716,-0.05532,28.18948,42.42894
95.39401,7.94955,877.92138,-0.05531,28.25645,42.43011
95.59400,7.96617,878.20096,-0.05533,28.32293,42.44362
95.79401,7.98279,877.48757,-0.05534,28.38942,42.40914
95.99400,7.99942,877.63499,-0.05534,28.45591,42.41627
96.19401,8.01610,877.55369,-0.05532,28.52263,42.41234
96.39401,8.03278,876.89729,-0.05533,28.58936,42.38062
96.59400,8.04940,877.20444,-0.05530,28.65584,42.39546
96.79401,8.06608,877.52370,-0.05530,28.72257,42.41089
96.99400,8.08276,877.32309,-0.05529,28.78929,42.40119
97.19401,8.09944,876.58679,-0.05530,28.85602,42.36561
97.39401,8.11612,876.89795,-0.05529,28.92274,42.38065
97.59400,8.13287,876.95727,-0.05530,28.98971,42.38351
97.79401,8.14949,875.93319,-0.05531,29.05619,42.33402
97.99400,8.16605,875.77123,-0.05530,29.12244,42.32619
98.19401,8.18273,875.99624,-0.05531,29.18916,42.33707
98.39401,8.19953,876.18828,-0.05530,29.25637,42.34635
98.59400,8.21609,875.92294,-0.05531,29.32261,42.33352
98.79401,8.23271,875.70203,-0.05532,29.38910,42.32285
98.99400,8.24952,875.60015,-0.05532,29.45631,42.31792
99.19401,8.26614,875.57519,-0.05530,29.52279,42.31672
99.39401,8.28276,875.68192,-0.05531,29.58927,42.32188
99.59400,8.29950,875.02925,-0.05532,29.65624,42.29033
99.79401,8.31618,874.26798,-0.05532,29.72296,42.25354
99.99400,8.33274,875.15153,-0.05531,29.78921,42.29624
100.19401,8.34948,874.75358,-0.05532,29.85618,42.27701
100.39401,8.36610,874.26510,-0.05532,29.92266,42.25340
100.59400,8.38279,874.18677,-0.05535,29.98939,42.24961
100.79401,8.39947,874.49700,-0.05543,30.05611,42.26461
100.99400,8.41615,873.35901,-0.05543,30.12284,42.20961
101.19401,8.43271,873.59268,-0.05535,30.18908,42.22090
101.39401,8.44939,873.30230,-0.05533,30.25581,42.20687
101.59400,8.46619,873.67641,-0.05533,30.32301,42.22495
101.79401,8.48281,873.22798,-0.05530,30.38950,42.20327
101.99400,8.49944,872.78979,-0.05532,30.45599,42.18210
102.19401,8.51606,872.27952,-0.05529,30.52247,42.15744
102.39401,8.53274,872.71789,-0.05531,30.58919,42.17862
102.59400,8.54948,872.15751,-0.05530,30.65616,42.15154
102.79401,8.56616,872.29181,-0.05531,30.72289,42.15803
102.99400,8.58284,871.77884,-0.05531,30.78961,42.13324
103.19401,8.59946,872.05982,-0.05530,30.85610,42.14682
103.39401,8.61608,871.52533,-0.05531,30.92258,42.12099
103.59400,8.63282,870.82973,-0.05531,30.98954,42.08737
103.79401,8.64951,870.79182,-0.05532,31.05627,42.08554
103.99400,8.66607,870.69971,-0.05534,31.12252,42.08109
104.19401,8.68281,870.37785,-0.05536,31.18948,42.06553
104.39401,8.69943,869.97524,-0.05536,31.25596,42.04607
104.59400,8.71599,869.98232,-0.05538,31.32221,42.04641
104.79401,8.73285,869.96593,-0.05536,31.38966,42.04562
104.99400,8.74953,869.22413,-0.05534,31.45638,42.00977
105.19401,8.76604,869.39931,-0.05533,31.52239,42.01823
105.39401,8.78278,868.99456,-0.05535,31.58935,41.99867
105.59400,8.79952,869.40527,-0.05537,31.65632,42.01852
105.79401,8.81608,868.84797,-0.05536,31.72257,41.99159
105.99400,8.83276,868.39786,-0.05534,31.78929,41.96983
106.19401,8.84962,868.10980,-0.05533,31.85673,41.95591
106.39401,8.86606,868.34850,-0.05533,31.92250,41.96745
106.59400,8.88275,867.83059,-0.05532,31.98923,41.94242
106.79401,8.89949,867.34463,-0.05533,32.05619,41.91893
106.99400,8.91617,867.36847,-0.05532,32.12291,41.92009
107.19401,8.93273,867.41904,-0.05534,32.18916,41.92253
107.39401,8.94941,866.40157,-0.05532,32.25589,41.87336
107.59400,8.96615,866.03928,-0.05531,32.32285,41.85585
107.79401,8.98271,866.41647,-0.05532,32.38910,41.87407
107.99400,8.99945,866.25554,-0.05532,32.45606,41.86629
108.19401,9.01625,865.80357,-0.05533,32.52327,41.84445
108.39401,9.03270,864.99648,-0.05531,32.58903,41.80545
108.59400,9.04944,865.12854,-0.05531,32.65600,41.81183
108.79401,9.06612,864.65776,-0.05532,32.72272,41.78907
108.99400,9.08280,864.70768,-0.05533,32.78945,41.79149
109.19401,9.09948,863.82013,-0.05533,32.85618,41.74859
109.39401,9.11616,864.00099,-0.05534,32.92290,41.75733
109.59400,9.13284,863.76565,-0.05533,32.98962,41.74596
109.79401,9.14941,863.75205,-0.05533,33.05587,41.74530
109.99400,9.16609,863.10413,-0.05532,33.12260,41.71399
110.19401,9.18277,862.73337,-0.05534,33.18932,41.69607
110.39401,9.19939,862.22989,-0.05534,33.25581,41.67174
110.59400,9.21613,861.95059,-0.05536,33.32277,41.65824
110.79401,9.23287,861.74877,-0.05533,33.38974,41.64848
110.99400,9.24949,861.30854,-0.05534,33.45622,41.62721
111.19401,9.26618,860.73624,-0.05532,33.52295,41.59955
111.39401,9.28286,860.08487,-0.05533,33.58967,41.56807
111.59400,9.29942,860.30411,-0.05533,33.65592,41.57866
111.79401,9.31598,860.12464,-0.05532,33.72216,41.56999
111.99400,9.33272,859.32640,-0.05533,33.78913,41.53141
112.19401,9.34952,858.99793,-0.05533,33.85633,41.51553
112.39401,9.36608,858.66405,-0.05534,33.92258,41.49940
112.59400,9.38276,857.70274,-0.05533,33.98930,41.45294
112.79401,9.39951,857.91340,-0.05533,34.05627,41.46312
112.99400,9.41607,857.34082,-0.05532,34.12252,41.43545
113.19401,9.43275,857.31382,-0.05532,34.18924,41.43414
113.39401,9.44949,856.52256,-0.05532,34.25620,41.39590
113.59400,9.46623,855.43878,-0.05531,34.32317,41.34352
113.79401,9.48273,855.96051,-0.05532,34.38918,41.36874
113.99400,9.49941,854.96726,-0.05532,34.45590,41.32073
114.19401,9.51622,854.90197,-0.05532,34.52311,41.31758
114.39401,9.53272,854.06406,-0.05531,34.58911,41.27708
114.59400,9.54946,853.27243,-0.05532,34.65607,41.23882
114.79401,9.56620,853.37609,-0.05532,34.72304,41.24383
114.99400,9.58270,853.18740,-0.05534,34.78905,41.23471
115.19401,9.59944,852.13883,-0.05534,34.85601,41.18403
115.39401,9.61606,852.05855,-0.05538,34.92250,41.18015
115.59400,9.63280,851.25742,-0.05537,34.98946,41.14143
115.79401,9.64949,850.34519,-0.05537,35.05619,41.09735
115.99400,9.66605,850.71670,-0.05533,35.12243,41.11530
116.19401,9.68285,849.66756,-0.05534,35.18964,41.06460
116.39401,9.69947,849.36665,-0.05532,35.25612,41.05005
116.59400,9.71615,848.90248,-0.05533,35.32285,41.02762
116.79401,9.73283,847.78909,-0.05530,35.38958,40.97381
116.99400,9.74951,846.91448,-0.05533,35.45630,40.93154
117.19401,9.76601,846.72514,-0.05532,35.52231,40.92239
117.39401,9.78270,846.61366,-0.05533,35.58903,40.91700
117.59401,9.79938,845.31270,-0.05532,35.65575,40.85413
117.79401,9.81612,844.97062,-0.05533,35.72272,40.83759
117.99400,9.83280,844.51269,-0.05534,35.78945,40.81546
118.19401,9.84948,843.45024,-0.05531,35.85617,40.76411
118.39401,9.86610,842.53987,-0.05533,35.92266,40.72011
118.59401,9.88278,841.99188,-0.05534,35.98938,40.69363
118.79401,9.89952,841.04305,-0.05534,36.05634,40.64777
118.99400,9.91609,840.37855,-0.05535,36.12259,40.61566
119.19401,9.93277,839.33380,-0.05536,36.18932,40.56516
119.39401,9.94957,838.49505,-0.05538,36.25652,40.52463
119.59401,9.96613,837.49462,-0.05538,36.32277,40.47628
119.79401,9.98281,836.55901,-0.05535,36.38949,40.43106
119.99400,9.99949,834.40403,-0.05533,36.45622,40.32691
120.19401,10.01618,834.49241,-0.05536,36.52295,40.33118
120.39401,10.03280,832.90786,-0.05540,36.58943,40.25460
120.59401,10.04942,831.61006,-0.05536,36.65591,40.19188
120.79401,10.06610,830.32623,-0.05534,36.72264,40.12983
120.99400,10.08278,828.89004,-0.05531,36.78936,40.06041
121.19401,10.09946,826.72769,-0.05532,36.85609,39.95591
121.39401,10.11614,825.67893,-0.05532,36.92282,39.90522
121.59401,10.13270,824.25615,-0.05534,36.98906,39.83646
121.79401,10.14945,822.01464,-0.05532,37.05603,39.72813
121.99400,10.16619,819.39325,-0.05532,37.12299,39.60143
122.19401,10.18281,816.58605,-0.05532,37.18947,39.46576
122.39401,10.19949,811.65815,-0.05533,37.25620,39.22759
122.59401,10.21611,804.63337,-0.05533,37.32269,38.88808
122.79401,10.23279,790.65580,-0.05533,37.38941,38.21255
122.92400,10.24367,4.50230,-0.05533,37.43294,0.21760