File: Manufatura Aditiva/Classificação Direção/Ensaios/Ensaios FDM/Tracao_OLABI_23_05_2018_FDM_XZ3.is_metal_RawData/Specimen_RawData_2.csv
Time,Extension,Load,Strain 1,Tensile strain,Tensile stress
(sec),(mm),(N),(mm/mm),(%),(MPa)
0.00000,0.00000,24.76682,0.00099,0.09883,1.19987
0.40000,0.03265,37.91946,0.00145,0.14534,1.83708
0.80000,0.06667,52.41476,0.00197,0.19730,2.53933
1.20000,0.10009,67.25371,0.00249,0.24877,3.25823
1.60000,0.13339,81.33453,0.00299,0.29894,3.94040
2.00000,0.16663,95.06346,0.00349,0.34944,4.60552
2.40000,0.20000,108.36148,0.00400,0.39981,5.24977
2.80000,0.23330,121.83769,0.00450,0.45029,5.90265
3.20000,0.26672,135.55032,0.00500,0.50046,6.56698
3.60000,0.30002,148.86385,0.00551,0.55080,7.21198
4.00000,0.33333,162.29558,0.00599,0.59862,7.86270
4.40000,0.36663,174.37395,0.00649,0.64897,8.44786
4.80000,0.40005,187.73389,0.00699,0.69925,9.09511
5.20000,0.43329,200.86514,0.00750,0.74958,9.73127
5.60000,0.46666,213.48957,0.00797,0.79661,10.34289
6.00000,0.50002,226.95444,0.00847,0.84675,10.99522
6.40000,0.53332,239.20650,0.00897,0.89670,11.58879
6.80000,0.56674,251.77104,0.00944,0.94449,12.19750
7.20000,0.59993,264.02294,0.00994,0.99419,12.79107
7.60000,0.63329,276.71400,0.01045,1.04455,13.40591
8.00000,0.66671,289.83846,0.01095,1.09453,14.04174
8.40000,0.69996,301.59873,0.01140,1.14018,14.61149
8.80000,0.73338,314.07152,0.01191,1.19057,15.21576
9.20000,0.76662,326.49362,0.01240,1.24022,15.81757
9.60000,0.79992,337.16522,0.01287,1.28660,16.33457
10.00000,0.83335,350.10241,0.01337,1.33660,16.96134
10.40000,0.86671,361.68071,0.01387,1.38700,17.52227
10.80000,0.89995,373.71463,0.01437,1.43698,18.10528
11.20000,0.93331,384.24316,0.01482,1.48197,18.61535
11.60000,0.96656,396.96577,0.01532,1.53220,19.23172
12.00000,1.00010,407.91072,0.01583,1.58322,19.76197
12.40000,1.03328,418.51983,0.01628,1.62806,20.27595
12.80000,1.06670,430.44463,0.01678,1.67796,20.85366
13.20000,1.10001,441.34669,0.01726,1.72648,21.38183
13.60000,1.13331,452.19166,0.01771,1.77115,21.90724
14.00000,1.16679,463.40702,0.01822,1.82245,22.45058
14.40000,1.19998,475.01782,0.01873,1.87260,23.01309
14.80000,1.23334,485.06646,0.01917,1.91747,23.49992
15.20000,1.26670,497.12686,0.01968,1.96803,24.08420
15.60000,1.30000,507.59409,0.02018,2.01827,24.59131
16.00000,1.33337,517.11136,0.02062,2.06247,25.05239
16.40000,1.36667,528.11713,0.02114,2.11352,25.58558
16.80000,1.40003,539.53701,0.02164,2.16384,26.13884
17.20000,1.43333,547.56771,0.02208,2.20849,26.52790
17.60000,1.46670,558.54083,0.02259,2.25896,27.05951
18.00000,1.49994,567.64400,0.02302,2.30227,27.50053
18.40000,1.53324,577.21031,0.02354,2.35354,27.96399
18.80000,1.56666,588.02362,0.02405,2.40469,28.48786
19.20000,1.60003,595.82214,0.02447,2.44709,28.86567
19.60000,1.63333,606.24219,0.02499,2.49897,29.37049
20.00000,1.66675,616.37009,0.02551,2.55113,29.86116
20.40000,1.69999,624.25570,0.02592,2.59248,30.24319
20.80000,1.73330,633.47653,0.02644,2.64410,30.68991
21.20000,1.76672,643.16974,0.02696,2.69622,31.15951
21.60000,1.79996,653.40805,0.02749,2.74860,31.65553
22.00000,1.83339,660.47595,0.02790,2.79038,31.99794
22.40000,1.86669,670.15626,0.02844,2.84357,32.46692
22.80000,1.89999,678.99264,0.02897,2.89728,32.89502
23.20000,1.93329,687.83723,0.02950,2.95046,33.32351
23.60000,1.96660,695.03151,0.02992,2.99247,33.67205
24.00000,2.00002,703.76443,0.03047,3.06637,34.09513
24.37200,2.03099,712.91635,0.03097,3.19025,34.53851
24.77200,2.06435,721.20684,0.03152,3.32370,34.94016
25.17200,2.09771,727.65811,0.03196,3.45715,35.25270
25.57200,2.13102,736.33124,0.03251,3.59036,35.67289
25.97200,2.16432,744.42932,0.03307,3.72358,36.06522
26.37200,2.19762,750.82583,0.03352,3.85679,36.37511
26.77200,2.23104,758.17434,0.03408,3.99048,36.73112
27.17200,2.26441,766.57026,0.03245,4.12393,37.13787
27.57200,2.29765,773.85902,0.01913,4.25690,37.49099
27.97200,2.33101,781.65364,0.01794,4.39035,37.86861
28.37200,2.36438,786.70261,0.01139,4.52380,38.11322
28.77200,2.39762,793.94244,0.00952,4.65677,38.46397
29.17200,2.43098,800.39501,0.00883,4.79022,38.77657
29.57200,2.46434,804.99472,0.00980,4.92367,38.99942
29.97200,2.49759,811.58839,0.01037,5.05664,39.31886
30.37200,2.53101,818.34141,-0.13622,5.19033,39.64602
30.77200,2.56437,825.16186,-0.13485,5.32378,39.97645
31.17200,2.59767,827.72234,-0.13486,5.45699,40.10049
31.57200,2.63098,834.49949,-0.13486,5.59020,40.42883
31.97200,2.66428,841.20221,-0.13486,5.72341,40.75355
32.37200,2.69770,846.60929,-0.13486,5.85710,41.01551
32.77200,2.73100,852.18456,-0.13486,5.99032,41.28561
33.17200,2.76437,857.15996,-0.13486,6.12377,41.52665
33.57200,2.79773,859.88026,-0.13487,6.25722,41.65844
33.97200,2.83097,864.66828,-0.13486,6.39019,41.89041
34.37200,2.86434,869.13249,-0.13487,6.52364,42.10669
34.77200,2.89764,874.18975,-0.13487,6.65685,42.35169
35.17200,2.93100,878.80064,-0.13487,6.79030,42.57507
35.57200,2.96442,883.06023,-0.13487,6.92399,42.78144
35.97200,2.99761,886.44670,-0.13487,7.05672,42.94550
36.37200,3.03097,886.94002,-0.13487,7.19017,42.96940
36.77200,3.06427,890.29372,-0.13487,7.32338,43.13188
37.17200,3.09763,893.95149,-0.13487,7.45683,43.30909
37.57200,3.13100,895.84114,-0.13487,7.59028,43.40063
37.97200,3.16436,899.46762,-0.13488,7.72373,43.57632
38.37200,3.19772,901.33669,-0.13487,7.85718,43.66687
38.77200,3.23096,903.32543,-0.13488,7.99015,43.76322
39.17200,3.26433,904.87869,-0.13488,8.12360,43.83847
39.57200,3.29763,905.66352,-0.13488,8.25682,43.87650
39.97200,3.33099,907.56165,-0.13488,8.39027,43.96845
40.37200,3.36435,909.06220,-0.13488,8.52372,44.04115
40.77200,3.39760,908.84613,-0.13487,8.65669,44.03068
41.17200,3.43102,908.71993,-0.13488,8.79038,44.02457
41.57200,3.46438,909.53130,-0.13488,8.92383,44.06388
41.97200,3.49763,909.02941,-0.13488,9.05680,44.03956
42.37200,3.53105,908.66433,-0.13488,9.19049,44.02188
42.77200,3.56429,907.59955,-0.13488,9.32346,43.97029
43.17200,3.59759,906.98674,-0.13488,9.45667,43.94060
43.57200,3.63108,905.12475,-0.13488,9.59060,43.85040
43.97200,3.66426,903.24692,-0.13488,9.72333,43.75942
44.37200,3.69768,901.80496,-0.13488,9.85702,43.68956
44.77200,3.73092,900.19731,-0.13488,9.98999,43.61168
45.17200,3.76429,898.10872,-0.13488,10.12344,43.51049
45.57200,3.79777,895.53744,-0.13488,10.25737,43.38592
45.97200,3.83095,893.34687,-0.13488,10.39011,43.27979
46.37200,3.86437,890.93661,-0.13488,10.52379,43.16302
46.77200,3.89768,888.45203,-0.13488,10.65701,43.04265
47.17200,3.93092,886.39064,-0.13488,10.78998,42.94279
47.57200,3.96440,883.36114,-0.13488,10.92390,42.79602
47.97200,3.99764,880.77886,-0.13488,11.05688,42.67091
48.37200,4.03095,878.36990,-0.13488,11.19009,42.55421
48.77200,4.06443,875.82618,-0.13488,11.32402,42.43097
49.17200,4.09761,873.30844,-0.13488,11.45675,42.30899
49.57200,4.13110,870.40337,-0.13488,11.59068,42.16825
49.97200,4.16428,868.40056,-0.13488,11.72341,42.07122
50.37200,4.19764,865.72254,-0.13488,11.85686,41.94148
50.77200,4.23100,862.86375,-0.13488,11.99031,41.80298
51.17200,4.26431,860.53647,-0.13488,12.12352,41.69024
51.57200,4.29773,857.93445,-0.13488,12.25721,41.56417
51.97200,4.33097,855.37964,-0.13488,12.39018,41.44040
52.37200,4.36427,853.24887,-0.13488,12.52339,41.33717
52.77200,4.39758,850.71055,-0.13488,12.65661,41.21420
53.17200,4.43106,848.62234,-0.13488,12.79053,41.11303
53.57200,4.46436,846.44230,-0.13488,12.92375,41.00742
53.97200,4.49766,843.69490,-0.13488,13.05696,40.87431
54.37200,4.53103,840.60701,-0.13488,13.19041,40.72472
54.77200,4.56433,838.89617,-0.13489,13.32362,40.64183
55.17200,4.59769,836.33903,-0.13488,13.45707,40.51795
55.57200,4.63100,833.61901,-0.13489,13.59028,40.38617
55.97200,4.66436,831.89411,-0.13488,13.72373,40.30260
56.37200,4.69766,829.08832,-0.13488,13.85694,40.16667
56.77200,4.73102,826.75228,-0.13488,13.99039,40.05350
57.17200,4.76433,824.28958,-0.13488,14.12360,39.93419
57.57200,4.79769,821.09626,-0.13488,14.25705,39.77948
57.97200,4.83093,818.72316,-0.13489,14.39002,39.66451
58.37200,4.86435,816.04440,-0.13488,14.52371,39.53474
58.77200,4.89766,813.45867,-0.13488,14.65692,39.40947
59.17200,4.93096,809.93772,-0.13488,14.79013,39.23889
59.57200,4.96432,807.42314,-0.13488,14.92358,39.11707
59.97200,4.99762,803.76957,-0.13489,15.05679,38.94006
60.37200,5.03099,800.68465,-0.13488,15.19024,38.79061
60.77200,5.06435,797.36523,-0.13489,15.32369,38.62979
61.17200,5.09765,793.24702,-0.13488,15.45690,38.43027
61.57200,5.13101,789.09034,-0.13488,15.59036,38.22890
61.97200,5.16432,785.13362,-0.13488,15.72357,38.03721
62.37200,5.19762,780.47863,-0.13488,15.85678,37.81169
62.77200,5.23104,775.71440,-0.13488,15.99047,37.58088
63.17200,5.26423,771.03791,-0.13488,16.12320,37.35432
63.57200,5.29765,765.36047,-0.13489,16.25689,37.07926
63.97200,5.33107,759.62199,-0.13489,16.39058,36.80125
64.37200,5.36431,754.30400,-0.13488,16.52355,36.54361
64.77200,5.39779,748.21226,-0.13488,16.65748,36.24849
65.17200,5.43098,742.33818,-0.13488,16.79021,35.96391
65.57201,5.46428,735.90758,-0.13489,16.92342,35.65236
65.97200,5.49764,729.54679,-0.13488,17.05687,35.34420
66.37200,5.53101,722.69659,-0.13488,17.19032,35.01233
66.77200,5.56437,715.96033,-0.13489,17.32377,34.68599
67.17201,5.59767,709.40894,-0.13489,17.45698,34.36859
67.57201,5.63091,703.67334,-0.13489,17.58995,34.09072
67.97200,5.66440,697.62031,-0.13489,17.72388,33.79747
68.37200,5.69764,691.43986,-0.13488,17.85685,33.49805
68.77200,5.73100,685.23213,-0.13488,17.99031,33.19730
69.17201,5.76431,680.77813,-0.13488,18.12352,32.98152
69.57201,5.79767,676.14336,-0.13489,18.25697,32.75698
69.97200,5.83109,672.16954,-0.13488,18.39066,32.56446
70.37200,5.86433,668.24425,-0.13488,18.52363,32.37429
70.77200,5.89764,664.83929,-0.13488,18.65684,32.20933
71.17201,5.93100,662.35396,-0.13489,18.79029,32.08893
71.57201,5.96430,659.64065,-0.13488,18.92350,31.95748
71.97200,5.99772,657.22764,-0.13489,19.05719,31.84057
72.37200,6.03103,655.68192,-0.13489,19.19040,31.76569
72.77200,6.06427,654.42459,-0.13488,19.32337,31.70477
73.17201,6.09769,652.83370,-0.13489,19.45706,31.62770
73.57201,6.13093,651.48692,-0.13489,19.59003,31.56245
73.97200,6.16430,651.33586,-0.13489,19.72348,31.55514
74.37200,6.19778,650.55070,-0.13489,19.85741,31.51710
74.77200,6.23096,650.25673,-0.13488,19.99014,31.50286
75.17201,6.26432,650.04150,-0.13488,20.12360,31.49243
75.57201,6.29769,650.06004,-0.13489,20.25705,31.49333
75.97200,6.33099,649.17575,-0.13489,20.39025,31.45049
76.37200,6.36423,649.68793,-0.13489,20.52323,31.47530
76.77200,6.39771,650.06963,-0.13489,20.65715,31.49379
77.17201,6.43108,650.40872,-0.13489,20.79061,31.51022
77.57201,6.46432,650.45236,-0.13489,20.92358,31.51233
77.97200,6.49774,650.27326,-0.13489,21.05727,31.50366
78.37200,6.53093,651.10517,-0.13489,21.19000,31.54396
78.77200,6.56435,651.20081,-0.13488,21.32369,31.54859
79.17201,6.59771,651.28277,-0.13489,21.45714,31.55256
79.57201,6.63095,651.41427,-0.13489,21.59011,31.55894
79.97200,6.66432,651.48296,-0.13489,21.72356,31.56226
80.37200,6.69762,651.88236,-0.13489,21.85677,31.58161
80.77200,6.73098,651.93153,-0.13489,21.99022,31.58399
81.17201,6.76428,652.22145,-0.13489,22.12344,31.59804
81.57201,6.79759,651.91677,-0.13489,22.25664,31.58328
81.97200,6.83101,652.84078,-0.13489,22.39033,31.62804
82.37200,6.86431,652.78024,-0.13489,22.52354,31.62511
82.77200,6.89767,652.93168,-0.13489,22.65700,31.63245
83.17201,6.93110,653.14765,-0.13489,22.79069,31.64291
83.57201,6.96434,653.87329,-0.13489,22.92365,31.67807
83.97201,6.99764,653.92288,-0.13489,23.05687,31.68047
84.37200,7.03101,653.68079,-0.13489,23.19032,31.66874
84.77200,7.06431,654.04321,-0.13489,23.32353,31.68630
85.17201,7.09779,655.39763,-0.13489,23.45746,31.75191
85.57201,7.13097,655.47521,-0.13489,23.59019,31.75567
85.97201,7.16434,655.29537,-0.13489,23.72364,31.74696
86.37200,7.19764,656.14684,-0.13489,23.85685,31.78821
86.77200,7.23094,656.06334,-0.13488,23.99006,31.78417
87.17201,7.26436,656.19899,-0.13488,24.12375,31.79074
87.57201,7.29773,656.39666,-0.13489,24.25720,31.80032
87.97201,7.33097,656.43578,-0.13489,24.39017,31.80221
88.37200,7.36433,656.70707,-0.13489,24.52362,31.81535
88.77200,7.39763,656.68528,-0.13489,24.65683,31.81430
89.17201,7.43100,656.53445,-0.13489,24.79029,31.80699
89.57201,7.46430,656.83974,-0.13488,24.92350,31.82178
89.97201,7.49766,657.34182,-0.13489,25.05694,31.84611
90.37200,7.53102,657.04840,-0.13488,25.19040,31.83189
90.77200,7.56433,657.94578,-0.13489,25.32361,31.87536
91.17201,7.59769,658.13810,-0.13489,25.45706,31.88468
91.57201,7.63099,657.35043,-0.13488,25.59027,31.84652
91.97201,7.66424,658.34885,-0.13488,25.72324,31.89489
92.37200,7.69772,658.68297,-0.13489,25.85717,31.91108
92.77200,7.73102,658.74029,-0.13489,25.99038,31.91386
93.17201,7.76438,658.80883,-0.13489,26.12383,31.91718
93.57201,7.79763,658.68502,-0.13489,26.25680,31.91118
93.97201,7.83099,658.71784,-0.13489,26.39025,31.91277
94.37200,7.86429,659.20954,-0.13489,26.52346,31.93659
94.77200,7.89765,659.33759,-0.13489,26.65691,31.94279
95.17201,7.93102,659.57024,-0.13489,26.79036,31.95407
95.57201,7.96432,659.75245,-0.13489,26.92357,31.96289
95.97201,7.99768,659.74495,-0.13489,27.05702,31.96253
96.37200,8.03098,659.92884,-0.13489,27.19023,31.97144
96.77200,8.06435,659.79548,-0.13489,27.32368,31.96498
97.17201,8.09771,660.12717,-0.13489,27.45714,31.98105
97.57201,8.13089,660.24284,-0.13489,27.58987,31.98665
97.97201,8.16437,660.47972,-0.13489,27.72380,31.99813
98.37200,8.19768,660.66617,-0.13489,27.85701,32.00716
98.77200,8.23092,660.60233,-0.13489,27.98998,32.00407
99.17201,8.26434,660.06244,-0.13489,28.12367,31.97791
99.57201,8.29765,660.41518,-0.13489,28.25688,31.99500
99.97201,8.33095,660.49066,-0.13489,28.39009,31.99866
100.37200,8.36443,660.08377,-0.13489,28.52402,31.97894
100.77200,8.39755,660.02910,-0.13489,28.65651,31.97630
101.17201,8.43104,660.28824,-0.13489,28.79044,31.98885
101.57201,8.46434,660.02514,-0.13489,28.92365,31.97610
101.97201,8.49770,660.69630,-0.13489,29.05710,32.00862
102.37200,8.53100,660.07143,-0.13489,29.19031,31.97835
102.77200,8.56425,660.89882,-0.13489,29.32329,32.01843
103.17201,8.59767,660.96243,-0.13489,29.45697,32.02151
103.57201,8.63109,660.78021,-0.13489,29.59066,32.01268
103.97201,8.66433,660.94417,-0.13489,29.72364,32.02063
104.37200,8.69770,660.78389,-0.13489,29.85709,32.01286
104.77200,8.73088,660.61239,-0.13489,29.98982,32.00455
105.17201,8.76424,660.91209,-0.13489,30.12327,32.01907
105.57201,8.79778,660.84238,-0.13489,30.25744,32.01570
105.97201,8.83097,660.81560,-0.13489,30.39017,32.01440
106.37200,8.86439,660.46380,-0.13489,30.52386,31.99735
106.77200,8.89769,660.76345,-0.13489,30.65707,32.01187
107.17201,8.93094,661.15377,-0.13489,30.79004,32.03078
107.57201,8.96448,661.61663,-0.13489,30.92421,32.05321
107.97201,8.99754,661.74907,-0.13489,31.05646,32.05962
108.37200,9.03102,660.83651,-0.13489,31.19039,32.01541
108.77200,9.06433,661.70706,-0.13489,31.32360,32.05759
109.17201,9.09757,661.46948,-0.13489,31.45657,32.04608
109.57201,9.13105,661.56029,-0.13489,31.59050,32.05048
109.97201,9.16429,661.40946,-0.13489,31.72348,32.04317
110.37200,9.19760,662.53077,-0.13489,31.85668,32.09749
110.77200,9.23096,662.43340,-0.13489,31.99013,32.09278
111.17201,9.26432,662.50004,-0.13489,32.12359,32.09600
111.57201,9.29768,662.91424,-0.13488,32.25704,32.11607
111.97201,9.33105,663.20449,-0.13489,32.39048,32.13013
112.37200,9.36429,662.99546,-0.13489,32.52346,32.12001
112.77200,9.39765,662.76132,-0.13489,32.65691,32.10866
113.17201,9.43096,662.65967,-0.13489,32.79012,32.10374
113.57201,9.46438,663.51006,-0.13489,32.92381,32.14494
113.97201,9.49768,662.89511,-0.13489,33.05702,32.11514
114.37200,9.53098,662.93939,-0.13489,33.19023,32.11729
114.77200,9.56435,663.23718,-0.13489,33.32368,32.13172
115.17201,9.59765,663.51364,-0.13489,33.45689,32.14511
115.57201,9.63095,663.65181,-0.13489,33.59010,32.15180
115.97201,9.66425,663.31131,-0.13489,33.72331,32.13531
116.37201,9.69762,664.02638,-0.13489,33.85676,32.16995
116.77200,9.73098,663.44081,-0.13489,33.99021,32.14158
117.17201,9.76434,664.02620,-0.13489,34.12366,32.16994
117.57201,9.79770,663.44142,-0.13489,34.25711,32.14161
117.97201,9.83101,664.32599,-0.13489,34.39032,32.18447
118.37201,9.86425,663.91649,-0.13489,34.52329,32.16463
118.77200,9.89767,663.98457,-0.13489,34.65698,32.16792
119.17201,9.93097,664.96022,-0.13489,34.79019,32.21519
119.57201,9.96434,664.57936,-0.13489,34.92365,32.19674
119.97201,9.99770,664.58662,-0.13489,35.05709,32.19709
120.37201,10.03100,664.59673,-0.13489,35.19031,32.19758
120.77200,10.06437,664.87216,-0.13489,35.32376,32.21093
121.17201,10.09761,664.63668,-0.13489,35.45673,32.19952
121.57201,10.13109,665.34118,-0.13489,35.59066,32.23365
121.97201,10.16433,664.87631,-0.13489,35.72363,32.21113
122.37201,10.19764,665.12264,-0.13489,35.85684,32.22306
122.77200,10.23106,664.94979,-0.13489,35.99053,32.21469
123.17201,10.26436,665.00753,-0.13489,36.12374,32.21748
123.57201,10.29766,665.09913,-0.13489,36.25695,32.22192
123.97201,10.33097,665.18802,-0.13489,36.39016,32.22623
124.37201,10.36433,665.08683,-0.13489,36.52361,32.22132
124.77200,10.39769,664.28557,-0.13489,36.65706,32.18251
125.17201,10.43094,664.56310,-0.13489,36.79004,32.19595
125.57201,10.46430,664.94821,-0.13489,36.92348,32.21461
125.97201,10.49766,664.96581,-0.13489,37.05693,32.21546
126.37201,10.53096,664.57372,-0.13488,37.19015,32.19647
126.77200,10.56438,664.57121,-0.13489,37.32384,32.19635
127.17201,10.59769,664.67980,-0.13489,37.45705,32.20161
127.57201,10.63099,664.28403,-0.13489,37.59026,32.18243
127.97201,10.66435,665.54588,-0.13489,37.72371,32.24356
128.37201,10.69766,664.84525,-0.13489,37.85692,32.20962
128.77200,10.73102,664.71235,-0.13489,37.99037,32.20318
129.17202,10.76426,664.94378,-0.13489,38.12334,32.21440
129.57201,10.79756,665.30677,-0.13489,38.25655,32.23198
129.97200,10.83105,664.81065,-0.13489,38.39048,32.20795
130.37201,10.86435,664.85950,-0.13489,38.52369,32.21031
130.77200,10.89765,665.03594,-0.13489,38.65690,32.21886
131.17202,10.93101,665.21522,-0.13489,38.79035,32.22755
131.57200,10.96420,665.05261,-0.13489,38.92308,32.21967
131.97200,10.99768,664.65121,-0.13489,39.05701,32.20022
132.37202,11.03110,664.49810,-0.13489,39.19070,32.19280
132.77200,11.06434,664.76208,-0.13489,39.32367,32.20559
133.17202,11.09765,664.91966,-0.13489,39.45688,32.21323
133.57200,11.13101,664.56078,-0.13489,39.59034,32.19584
133.97200,11.16437,664.77265,-0.13489,39.72378,32.20610
134.37202,11.19761,664.58019,-0.13489,39.85676,32.19678
134.77200,11.23104,664.78681,-0.13489,39.99045,32.20679
135.17202,11.26434,664.70900,-0.13489,40.12366,32.20302
135.57200,11.29770,665.26630,-0.13489,40.25711,32.23002
135.97200,11.33107,665.00320,-0.13489,40.39056,32.21727
136.37202,11.36431,664.99235,-0.13489,40.52353,32.21675
136.77200,11.39767,665.73769,-0.13488,40.65698,32.25286
137.17202,11.43097,665.81788,-0.13489,40.79019,32.25674
137.57200,11.46434,665.04329,-0.13489,40.92364,32.21922
137.97200,11.49770,665.51208,-0.13489,41.05709,32.24193
138.37202,11.53088,665.87669,-0.13489,41.18983,32.25959
138.77200,11.56436,666.22440,-0.13489,41.32375,32.27644
139.17202,11.59755,666.25811,-0.13489,41.45648,32.27807
139.57200,11.63097,666.32419,-0.13489,41.59017,32.28127
139.97200,11.66439,666.88759,-0.13489,41.72386,32.30857
140.37202,11.69764,666.90827,-0.13489,41.85684,32.30957
140.77200,11.73106,666.79479,-0.13489,41.99052,32.30407
141.17202,11.76430,667.10482,-0.13489,42.12349,32.31909
141.57200,11.79760,667.31474,-0.13489,42.25671,32.32926
141.97200,11.83114,667.41765,-0.13489,42.39088,32.33425
142.37202,11.86421,667.40909,-0.13489,42.52313,32.33383
142.77200,11.89769,666.81416,-0.13489,42.65706,32.30501
143.17202,11.93105,667.26860,-0.13489,42.79051,32.32703
143.57200,11.96430,667.04135,-0.13489,42.92348,32.31602
143.97200,11.99772,666.77090,-0.13489,43.05717,32.30291
144.37202,12.03090,666.94152,-0.13489,43.18990,32.31118
144.77200,12.06432,666.85025,-0.13489,43.32359,32.30676
145.17202,12.09775,667.21286,-0.13489,43.45728,32.32433
145.57200,12.13099,666.62603,-0.13489,43.59025,32.29589
145.97200,12.16441,666.66603,-0.13489,43.72394,32.29783
146.37202,12.19765,667.28564,-0.13489,43.85691,32.32785
146.77200,12.23096,667.08815,-0.13489,43.99013,32.31828
147.17202,12.26438,666.52009,-0.13489,44.12381,32.29076
147.57200,12.29762,666.67693,-0.13489,44.25679,32.29836
147.97200,12.33098,666.64447,-0.13489,44.39023,32.29679
148.37202,12.36435,666.95004,-0.13489,44.52368,32.31159
148.77200,12.39759,666.77351,-0.13489,44.65666,32.30304
149.17202,12.43107,667.53388,-0.13489,44.79059,32.33988
149.57200,12.46437,667.26669,-0.13489,44.92379,32.32693
149.97200,12.49762,667.47386,-0.13489,45.05677,32.33697
150.37202,12.53098,667.84145,-0.13489,45.19022,32.35478
150.77200,12.56434,667.43819,-0.13489,45.32367,32.33524
151.17202,12.59777,667.77123,-0.13489,45.45736,32.35138
151.57200,12.63107,668.30139,-0.13489,45.59057,32.37706
151.97200,12.66431,667.88266,-0.13489,45.72354,32.35677
152.37202,12.69761,668.20364,-0.13489,45.85675,32.37233
152.77200,12.73098,668.01645,-0.13489,45.99020,32.36325
153.17202,12.76434,668.47503,-0.13489,46.12365,32.38548
153.57200,12.79770,667.51679,-0.13489,46.25710,32.33905
153.97200,12.83106,668.12625,-0.13489,46.39055,32.36858
154.37202,12.86425,668.04616,-0.13489,46.52328,32.36470
154.77200,12.89773,667.53603,-0.13489,46.65721,32.33998
155.17202,12.93097,667.79181,-0.13489,46.79018,32.35238
155.57200,12.96428,668.32127,-0.13489,46.92340,32.37803
155.97200,12.99770,668.34558,-0.13489,47.05709,32.37920
156.37202,13.03100,667.99805,-0.13489,47.19030,32.36237
156.77200,13.06436,668.16648,-0.13489,47.32375,32.37053
157.17202,13.09772,667.99098,-0.13489,47.45720,32.36202
157.57200,13.13097,668.67373,-0.13489,47.59017,32.39510
157.97200,13.16433,668.38395,-0.13489,47.72362,32.38106
158.37202,13.19763,667.67838,-0.13489,47.85683,32.34688
158.77200,13.23100,667.95922,-0.13489,47.99028,32.36049
159.17202,13.26436,668.06809,-0.13489,48.12373,32.36576
159.57200,13.29760,668.00071,-0.13489,48.25670,32.36250
159.97200,13.33096,667.71284,-0.13489,48.39015,32.34855
160.37202,13.36433,667.93854,-0.13489,48.52360,32.35948
160.77200,13.39763,667.61165,-0.13489,48.65682,32.34365
161.17202,13.43099,667.64154,-0.13489,48.79026,32.34509
161.57200,13.46435,667.69305,-0.13489,48.92371,32.34759
161.97200,13.49760,667.46809,-0.13489,49.05669,32.33669
162.37202,13.53108,667.36140,-0.13489,49.19061,32.33152
162.77200,13.56432,667.82837,-0.13489,49.32359,32.35415
163.17202,13.59768,667.39102,-0.13489,49.45703,32.33296
163.57200,13.63105,668.25883,-0.13489,49.59048,32.37500
163.97202,13.66429,667.49882,-0.13489,49.72346,32.33818
164.37202,13.69777,667.41155,-0.13489,49.85739,32.33395
164.77200,13.73090,668.00350,-0.13489,49.98988,32.36263
165.17202,13.76426,667.21682,-0.13489,50.12333,32.32452
165.57200,13.79768,667.90013,-0.13489,50.25702,32.35762
165.97202,13.83092,667.72918,-0.13489,50.38999,32.34934
166.37202,13.86441,667.13905,-0.13489,50.52392,32.32075
166.77200,13.89765,667.24624,-0.13489,50.65689,32.32594
167.17202,13.93089,667.33137,-0.13489,50.78986,32.33007
167.57200,13.96443,667.62422,-0.13489,50.92403,32.34425
167.97202,13.99768,666.91018,-0.13489,51.05700,32.30966
168.37202,14.03098,667.38240,-0.13489,51.19022,32.33254
168.77200,14.06434,667.53333,-0.13489,51.32366,32.33985
169.17202,14.09764,668.19731,-0.13489,51.45687,32.37202
169.57200,14.13107,667.72588,-0.13489,51.59056,32.34918
169.97202,14.16431,667.74092,-0.13489,51.72354,32.34991
170.37202,14.19773,667.76080,-0.13489,51.85723,32.35087
170.77200,14.23098,667.51437,-0.13489,51.99020,32.33893
171.17202,14.26422,667.60294,-0.13489,52.12317,32.34322
171.57200,14.29776,667.92336,-0.13489,52.25734,32.35875
171.97202,14.33100,667.38622,-0.13489,52.39031,32.33273
172.37202,14.36430,668.01612,-0.13489,52.52352,32.36324
172.77200,14.39773,667.32788,-0.13489,52.65721,32.32990
173.17202,14.43091,667.57784,-0.13489,52.78994,32.34201
173.57200,14.46439,666.65732,-0.13489,52.92388,32.29741
173.97202,14.49770,666.86803,-0.13489,53.05708,32.30762
174.37202,14.53094,666.49057,-0.13489,53.19005,32.28933
174.77200,14.56436,667.06040,-0.13489,53.32375,32.31694
175.17202,14.59766,666.20782,-0.13489,53.45696,32.27563
175.57200,14.63097,666.16647,-0.13489,53.59017,32.27363
175.97202,14.66439,666.54249,-0.13489,53.72385,32.29185
176.37202,14.69763,665.75557,-0.13489,53.85683,32.25372
176.77200,14.73099,665.63133,-0.13489,53.99027,32.24770
177.17202,14.76430,665.40972,-0.13489,54.12349,32.23697
177.57200,14.79772,665.67734,-0.13489,54.25717,32.24994
177.97202,14.83096,665.40590,-0.13489,54.39015,32.23678
178.37202,14.86433,665.37536,-0.13489,54.52360,32.23531
178.77200,14.89769,665.97350,-0.13489,54.65705,32.26428
179.17202,14.93099,664.83924,-0.13489,54.79026,32.20933
179.57200,14.96441,665.44339,-0.13489,54.92395,32.23860
179.97202,14.99766,666.15189,-0.13489,55.05692,32.27293
180.37202,15.03102,666.13308,-0.13489,55.19037,32.27201
180.77200,15.06438,666.10281,-0.13489,55.32382,32.27055
181.17202,15.09762,666.48675,-0.13489,55.45679,32.28915
181.57200,15.13099,666.01941,-0.13489,55.59025,32.26651
181.97202,15.16423,666.18589,-0.13489,55.72321,32.27457
182.37202,15.19771,666.44591,-0.13489,55.85715,32.28717
182.77200,15.23107,666.62929,-0.13489,55.99059,32.29605
183.17202,15.26432,667.10492,-0.13489,56.12356,32.31910
183.57200,15.29774,667.64751,-0.13489,56.25725,32.34538
183.97202,15.33092,667.41570,-0.13489,56.38999,32.33415
184.37202,15.36428,667.51218,-0.13489,56.52344,32.33883
184.77200,15.39771,667.64574,-0.13489,56.65713,32.34529
185.17202,15.43101,667.10557,-0.13489,56.79034,32.31913
185.57200,15.46437,667.41230,-0.13489,56.92379,32.33399
185.97202,15.49762,667.59875,-0.13489,57.05676,32.34302
186.37202,15.53098,666.98417,-0.13489,57.19021,32.31325
186.77200,15.56434,666.74855,-0.13489,57.32366,32.30183
187.17202,15.59764,666.83064,-0.13489,57.45687,32.30581
187.57200,15.63100,666.85784,-0.13489,57.59032,32.30713
187.97202,15.66437,666.60359,-0.13489,57.72377,32.29481
188.37202,15.69767,666.24125,-0.13489,57.85698,32.27725
188.77200,15.73097,665.85005,-0.13489,57.99019,32.25830
189.17202,15.76434,666.44545,-0.13489,58.12364,32.28715
189.57200,15.79764,666.03911,-0.13489,58.25685,32.26746
189.97202,15.83100,665.91455,-0.13489,58.39030,32.26143
190.37202,15.86436,666.69378,-0.13489,58.52375,32.29918
190.77200,15.89767,665.71473,-0.13489,58.65697,32.25175
191.17202,15.93097,666.27287,-0.13489,58.79018,32.27879
191.57200,15.96433,665.93997,-0.13489,58.92362,32.26266
191.97202,15.99769,666.01695,-0.13490,59.05707,32.26639
192.37202,16.03100,666.16130,-0.13489,59.19029,32.27338
192.77200,16.06442,666.18486,-0.13489,59.32397,32.27452
193.17202,16.09766,665.97858,-0.13489,59.45695,32.26453
193.57200,16.13103,666.26803,-0.13489,59.59040,32.27855
193.97202,16.16433,667.06589,-0.13489,59.72360,32.31720
194.37202,16.19769,667.08326,-0.13489,59.85706,32.31805
194.77200,16.23099,666.88578,-0.13489,59.99027,32.30848
195.17202,16.26424,667.48364,-0.13489,60.12324,32.33744
195.57200,16.29766,667.06771,-0.13489,60.25693,32.31729
195.97202,16.33096,667.24448,-0.13489,60.39014,32.32586
196.37202,16.36432,666.99055,-0.13489,60.52359,32.31356
196.77200,16.39769,667.85249,-0.13489,60.65705,32.35531
197.17202,16.43093,667.57249,-0.13489,60.79001,32.34175
197.57200,16.46435,667.32643,-0.13489,60.92370,32.32983
197.97202,16.49771,667.49295,-0.13489,61.05716,32.33789
198.37202,16.53090,667.31283,-0.13489,61.18989,32.32917
198.77200,16.56444,667.51628,-0.13489,61.32405,32.33902
199.17202,16.59762,667.22720,-0.13489,61.45679,32.32502
199.57200,16.63093,667.34781,-0.13489,61.59000,32.33086
199.97202,16.66447,667.49537,-0.13489,61.72416,32.33801
200.37202,16.69753,667.27265,-0.13489,61.85642,32.32722
200.77200,16.73107,667.42916,-0.13489,61.99059,32.33480
201.17202,16.76432,668.04271,-0.13489,62.12355,32.36453
201.57200,16.79762,667.78534,-0.13489,62.25677,32.35206
201.97202,16.83110,667.74008,-0.13489,62.39070,32.34987
202.37202,16.86422,667.75791,-0.13489,62.52319,32.35073
202.77200,16.89765,668.04127,-0.13489,62.65689,32.36446
203.17202,16.93101,667.98613,-0.13489,62.79033,32.36179
203.57200,16.96431,668.12900,-0.13489,62.92354,32.36871
203.97202,16.99773,667.38813,-0.13489,63.05724,32.33282
204.37202,17.03098,667.90837,-0.13489,63.19020,32.35802
204.77200,17.06428,667.77584,-0.13489,63.32341,32.35160
205.17202,17.09770,666.96340,-0.13489,63.45711,32.31224
205.57200,17.13089,667.79079,-0.13489,63.58984,32.35233
205.97202,17.16449,667.11651,-0.13489,63.72424,32.31966
206.37202,17.19773,667.07674,-0.13489,63.85722,32.31773
206.77200,17.23091,666.84596,-0.13489,63.98995,32.30655
207.17202,17.26445,666.28461,-0.13489,64.12411,32.27935
207.57200,17.29758,666.99074,-0.13489,64.25661,32.31356
207.97202,17.33106,666.61481,-0.13489,64.39053,32.29535
208.37202,17.36430,666.50086,-0.13489,64.52351,32.28983
208.77200,17.39761,666.24749,-0.13489,64.65672,32.27756
209.17202,17.43103,665.89820,-0.13489,64.79041,32.26064
209.57200,17.46433,666.42589,-0.13489,64.92362,32.28620
209.97202,17.49769,666.23706,-0.13489,65.05708,32.27705
210.37202,17.53100,665.53093,-0.13489,65.19028,32.24284
210.77200,17.56430,665.78160,-0.13489,65.32350,32.25499
211.17202,17.59772,665.81182,-0.13489,65.45718,32.25645
211.57200,17.63102,666.12540,-0.13489,65.59039,32.27164
211.97202,17.66433,665.90849,-0.13489,65.72360,32.26113
212.37202,17.69763,665.72228,-0.13489,65.85681,32.25211
212.77200,17.73093,665.69238,-0.13489,65.99002,32.25066
213.17202,17.76441,665.63464,-0.13489,66.12395,32.24786
213.57200,17.79766,666.34547,-0.13489,66.25692,32.28230
213.97202,17.83102,665.98463,-0.13489,66.39038,32.26482
214.37202,17.86432,666.06635,-0.13489,66.52359,32.26878
214.77200,17.89763,666.72112,-0.13489,66.65680,32.30050
215.17202,17.93105,665.87394,-0.13489,66.79049,32.25946
215.57200,17.96429,665.54295,-0.13489,66.92346,32.24342
215.97202,17.99765,665.63245,-0.13489,67.05691,32.24776
216.37202,18.03096,665.69224,-0.13489,67.19012,32.25066
216.77200,18.06432,665.46830,-0.13489,67.32357,32.23981
217.17202,18.09768,666.10482,-0.13489,67.45702,32.27065
217.57200,18.13098,665.97536,-0.13489,67.59024,32.26437
217.97202,18.16429,665.87008,-0.13489,67.72344,32.25927
218.37202,18.19759,666.31725,-0.13489,67.85665,32.28094
218.77200,18.23095,666.56303,-0.13489,67.99011,32.29284
219.17202,18.26443,666.43632,-0.13489,68.12403,32.28671
219.57200,18.29768,666.25518,-0.13489,68.25700,32.27793
219.97202,18.33098,666.17555,-0.13489,68.39022,32.27407
220.37202,18.36440,666.55325,-0.13489,68.52390,32.29237
220.77200,18.39764,666.28745,-0.13489,68.65687,32.27949
221.17202,18.43101,666.28093,-0.13489,68.79033,32.27917
221.57200,18.46431,666.12754,-0.13489,68.92354,32.27174
221.97202,18.49767,666.33401,-0.13489,69.05698,32.28175
222.37202,18.53110,665.58947,-0.13489,69.19068,32.24568
222.77200,18.56434,666.29997,-0.13489,69.32365,32.28010
223.17202,18.59764,666.15031,-0.13489,69.45686,32.27285
223.57200,18.63094,665.82812,-0.13489,69.59007,32.25724
223.97202,18.66425,665.96512,-0.13489,69.72328,32.26388
224.37202,18.69767,665.69587,-0.13489,69.85697,32.25083
224.77200,18.73097,665.79855,-0.13489,69.99019,32.25581
225.17202,18.76433,665.86840,-0.13489,70.12363,32.25919
225.57200,18.79770,665.64018,-0.13489,70.25708,32.24813
225.97202,18.83100,665.58053,-0.13489,70.39030,32.24524
226.37202,18.86436,665.78351,-0.13489,70.52374,32.25508
226.77200,18.89760,665.18583,-0.13489,70.65672,32.22612
227.17202,18.93097,666.11622,-0.13489,70.79017,32.27120
227.57200,18.96433,665.82328,-0.13489,70.92361,32.25700
227.97202,18.99763,665.85066,-0.13489,71.05682,32.25833
228.37202,19.03106,665.72190,-0.13489,71.19052,32.25209
228.77202,19.06436,665.72358,-0.13489,71.32373,32.25217
229.17202,19.09760,666.62943,-0.13489,71.45670,32.29606
229.57200,19.13102,666.25644,-0.13489,71.59039,32.27799
229.97202,19.16427,666.90426,-0.13489,71.72336,32.30938
230.37202,19.19775,667.24839,-0.13489,71.85729,32.32605
230.77202,19.23099,666.86166,-0.13489,71.99026,32.30731
231.17202,19.26429,666.95190,-0.13489,72.12347,32.31168
231.57200,19.29766,666.61132,-0.13490,72.25692,32.29518
231.97202,19.33102,667.30636,-0.13489,72.39037,32.32885
232.37202,19.36438,666.79348,-0.13489,72.52382,32.30401
232.77202,19.39768,666.51548,-0.13489,72.65703,32.29054
233.17202,19.43099,666.66361,-0.13489,72.79025,32.29771
233.57200,19.46435,667.18096,-0.13489,72.92370,32.32278
233.97202,19.49765,666.89174,-0.13489,73.05690,32.30877
234.37202,19.53095,666.41304,-0.13489,73.19012,32.28558
234.77202,19.56432,666.67721,-0.13489,73.32357,32.29837
235.17202,19.59762,665.75371,-0.13490,73.45677,32.25364
235.57200,19.63104,666.06267,-0.13489,73.59047,32.26860
235.97202,19.66428,666.33858,-0.13489,73.72344,32.28197
236.37202,19.69771,666.07553,-0.13489,73.85713,32.26923
236.77202,19.73101,666.25103,-0.13490,73.99035,32.27773
237.17202,19.76425,666.62030,-0.13489,74.12331,32.29562
237.57200,19.79773,666.41155,-0.13489,74.25723,32.28550
237.97202,19.83092,666.42421,-0.13489,74.38996,32.28612
238.37202,19.86440,667.04340,-0.13489,74.52390,32.31612
238.77202,19.89758,666.82799,-0.13490,74.65663,32.30568
239.17202,19.93089,666.59511,-0.13489,74.78984,32.29440
239.57200,19.96437,666.53504,-0.13489,74.92377,32.29149
239.97202,19.99761,666.65513,-0.13489,75.05674,32.29731
240.37202,20.03109,667.11884,-0.13489,75.19067,32.31977
240.77202,20.06434,666.81420,-0.13489,75.32364,32.30501
241.17202,20.09764,666.94925,-0.13489,75.45685,32.31155
241.57200,20.13100,666.49616,-0.13489,75.59030,32.28960
241.97202,20.16430,666.86706,-0.13489,75.72352,32.30757
242.37202,20.19767,667.21486,-0.13489,75.85697,32.32442
242.77202,20.23109,666.99022,-0.13490,75.99066,32.31354
243.17202,20.26427,666.89365,-0.13489,76.12339,32.30886
243.57200,20.29775,666.95875,-0.13489,76.25731,32.31202
243.97202,20.33094,666.40023,-0.13489,76.39005,32.28495
244.37202,20.36430,666.31087,-0.13489,76.52351,32.28063
244.77202,20.39772,666.33462,-0.13489,76.65719,32.28178
245.17202,20.43091,666.95623,-0.13489,76.78992,32.31189
245.57200,20.46433,666.35543,-0.13490,76.92361,32.28279
245.97202,20.49763,665.67385,-0.13489,77.05682,32.24976
246.37202,20.53099,666.62547,-0.13489,77.19027,32.29587
246.77202,20.56436,667.41901,-0.13489,77.32372,32.33431
247.17202,20.59766,666.63548,-0.13489,77.45693,32.29635
247.57200,20.63096,667.05411,-0.13489,77.59014,32.31664
247.97202,20.66432,667.00792,-0.13489,77.72360,32.31440
248.37202,20.69763,667.31260,-0.13489,77.85680,32.32916
248.77202,20.73105,667.26385,-0.13489,77.99048,32.32679
249.17202,20.76435,667.76075,-0.13489,78.12370,32.35087
249.57200,20.79766,667.09039,-0.13489,78.25692,32.31839
249.97202,20.83102,667.71521,-0.13489,78.39036,32.34866
250.37202,20.86432,668.15387,-0.13489,78.52358,32.36992
250.77202,20.89774,668.02204,-0.13489,78.65727,32.36353
251.17202,20.93104,668.33887,-0.13489,78.79047,32.37888
251.57200,20.96429,667.97496,-0.13489,78.92345,32.36125
251.97202,20.99759,668.27242,-0.13490,79.05666,32.37566
252.37202,21.03101,668.02343,-0.13489,79.19034,32.36359
252.77202,21.06426,668.29589,-0.13489,79.32332,32.37679
253.17202,21.09768,668.42553,-0.13489,79.45701,32.38308
253.57200,21.13104,667.95275,-0.13489,79.59046,32.36017
253.97202,21.16435,667.87042,-0.13490,79.72368,32.35618
254.37202,21.19771,667.90911,-0.13489,79.85712,32.35806
254.77202,21.23101,667.40178,-0.13489,79.99033,32.33348
255.17202,21.26431,667.51093,-0.13489,80.12355,32.33876
255.57200,21.29767,667.66338,-0.13489,80.25699,32.34615
255.97202,21.33098,667.26441,-0.13489,80.39021,32.32682
256.37202,21.36434,666.59162,-0.13489,80.52366,32.29423
256.77200,21.39776,666.57146,-0.13489,80.65735,32.29325
257.17200,21.43095,666.59478,-0.13489,80.79008,32.29438
257.57202,21.46431,667.02464,-0.13490,80.92353,32.31520
257.97202,21.49767,665.94947,-0.13489,81.05698,32.26312
258.37202,21.53097,666.17550,-0.13489,81.19019,32.27407
258.77200,21.56439,666.23837,-0.13489,81.32387,32.27711
259.17200,21.59764,666.13476,-0.13489,81.45685,32.27209
259.57202,21.63100,666.38454,-0.13490,81.59030,32.28419
259.97202,21.66436,666.56936,-0.13489,81.72375,32.29315
260.37202,21.69761,666.68866,-0.13489,81.85672,32.29893
260.77200,21.73103,666.26845,-0.13489,81.99040,32.27857
261.17203,21.76433,667.39065,-0.13489,82.12362,32.33294
261.57202,21.79764,666.78599,-0.13489,82.25684,32.30365
261.97202,21.83106,667.13439,-0.13489,82.39052,32.32052
262.37200,21.86430,667.14692,-0.13489,82.52349,32.32113
262.77200,21.89766,666.70044,-0.13489,82.65694,32.29950
263.17203,21.93102,667.69146,-0.13489,82.79039,32.34751
263.57203,21.96421,667.16508,-0.13489,82.92313,32.32201
263.97200,21.99781,667.27181,-0.13489,83.05753,32.32718
264.37200,22.03087,667.22143,-0.13489,83.18979,32.32474
264.77200,22.06436,667.49468,-0.13490,83.32372,32.33798
265.17203,22.09772,667.12531,-0.13489,83.45717,32.32008
265.57203,22.13090,666.91870,-0.13489,83.58989,32.31007
265.97200,22.16438,668.10357,-0.13489,83.72383,32.36748
266.37200,22.19763,667.55754,-0.13490,83.85680,32.34102
266.77200,22.23099,667.52508,-0.13489,83.99025,32.33945
267.17203,22.26435,667.97887,-0.13489,84.12370,32.36143
267.57203,22.29759,667.36159,-0.13489,84.25668,32.33153
267.97200,22.33096,668.20439,-0.13489,84.39013,32.37236
268.37200,22.36432,668.29487,-0.13489,84.52358,32.37674
268.77200,22.39762,667.70739,-0.13489,84.65678,32.34828
269.17203,22.43104,667.73272,-0.13489,84.79047,32.34951
269.57203,22.46435,667.65454,-0.13489,84.92369,32.34572
269.97200,22.49771,668.04686,-0.13490,85.05714,32.36473
270.37200,22.53095,666.71893,-0.13490,85.19011,32.30040
270.77200,22.56425,667.76075,-0.13489,85.32331,32.35087
271.17203,22.59774,667.59642,-0.13489,85.45724,32.34291
271.57203,22.63098,667.03339,-0.13489,85.59022,32.31563
271.97200,22.66440,667.43721,-0.13489,85.72391,32.33519
272.37200,22.69770,666.84657,-0.13489,85.85712,32.30658
272.77200,22.73101,666.54477,-0.13489,85.99032,32.29196
273.17203,22.76437,666.74654,-0.13489,86.12378,32.30173
273.57203,22.79767,666.96242,-0.13490,86.25699,32.31219
273.97200,22.83104,665.50816,-0.13490,86.39044,32.24174
274.37200,22.86428,666.51972,-0.13489,86.52341,32.29074
274.77200,22.89764,666.39506,-0.13489,86.65686,32.28471
275.17203,22.93100,665.73718,-0.13489,86.79031,32.25283
275.57203,22.96431,665.70970,-0.13489,86.92352,32.25150
275.97200,22.99767,665.89690,-0.13489,87.05698,32.26057
276.37200,23.03091,665.92474,-0.13490,87.18994,32.26192
276.77200,23.06433,665.66346,-0.13489,87.32364,32.24926
277.17203,23.09770,665.75422,-0.13489,87.45708,32.25366
277.57203,23.13100,665.57960,-0.13489,87.59030,32.24520
277.97200,23.16436,665.78742,-0.13489,87.72374,32.25527
278.37200,23.19766,666.21304,-0.13489,87.85695,32.27589
278.77200,23.23097,665.76875,-0.13489,87.99017,32.25436
279.17203,23.26439,666.10239,-0.13490,88.12386,32.27053
279.57203,23.29769,666.08670,-0.13489,88.25707,32.26977
279.97200,23.33099,665.77406,-0.13489,88.39028,32.25462
280.37200,23.36436,666.19543,-0.13489,88.52373,32.27504
280.77200,23.39766,666.63125,-0.13489,88.65694,32.29615
281.17203,23.43102,666.97034,-0.13490,88.79039,32.31258
281.57203,23.46433,666.14118,-0.13489,88.92360,32.27241
281.97200,23.49763,666.55078,-0.13489,89.05681,32.29225
282.37200,23.53105,665.88712,-0.13490,89.19050,32.26010
282.77200,23.56435,666.20340,-0.13489,89.32371,32.27542
283.17203,23.59772,667.03297,-0.13489,89.45716,32.31561
283.57203,23.63102,666.49779,-0.13489,89.59037,32.28968
283.97200,23.66432,666.21155,-0.13489,89.72358,32.27581
284.37200,23.69762,666.68168,-0.13489,89.85679,32.29859
284.77200,23.73093,667.05886,-0.13489,89.99001,32.31686
285.17203,23.76435,666.77891,-0.13489,90.12369,32.30330
285.57203,23.79765,666.96587,-0.13489,90.25691,32.31236
285.97200,23.83095,666.93500,-0.13489,90.39012,32.31086
286.37200,23.86438,666.78179,-0.13489,90.52381,32.30344
286.77200,23.89762,667.31861,-0.13489,90.65678,32.32945
287.17203,23.93098,667.68718,-0.13489,90.79023,32.34731
287.57203,23.96435,667.99507,-0.13489,90.92368,32.36222
287.97200,23.99765,667.54473,-0.13489,91.05690,32.34040
288.37200,24.03101,667.96504,-0.13490,91.19034,32.36077
288.77200,24.06431,667.62241,-0.13489,91.32355,32.34417
289.17203,24.09762,667.74739,-0.13489,91.45677,32.35022
289.57203,24.13098,668.24863,-0.13490,91.59021,32.37450
289.97200,24.16434,668.09808,-0.13489,91.72366,32.36721
290.37200,24.19770,667.75568,-0.13489,91.85712,32.35062
290.77200,24.23101,667.73291,-0.13489,91.99032,32.34952
291.17203,24.26431,667.77724,-0.13489,92.12353,32.35167
291.57203,24.29761,667.56099,-0.13489,92.25675,32.34119
291.97200,24.33104,667.60397,-0.13489,92.39044,32.34327
292.37200,24.36440,667.57523,-0.13490,92.52388,32.34188
292.77200,24.39764,667.40108,-0.13489,92.65686,32.33344
293.17203,24.43100,667.99591,-0.13489,92.79031,32.36226
293.57203,24.46436,667.85249,-0.13489,92.92375,32.35531
293.97200,24.49761,668.09449,-0.13489,93.05673,32.36704
294.37200,24.53097,667.86231,-0.13489,93.19018,32.35579
294.77200,24.56427,667.74148,-0.13489,93.32339,32.34993
295.17203,24.59764,668.11279,-0.13489,93.45684,32.36792
295.57203,24.63094,668.16406,-0.13489,93.59006,32.37041
295.97200,24.66430,668.27140,-0.13490,93.72349,32.37561
296.37200,24.69772,668.71028,-0.13489,93.85720,32.39687
296.77200,24.73091,667.80802,-0.13489,93.98993,32.35316
297.17203,24.76433,668.36001,-0.13489,94.12361,32.37990
297.57203,24.79763,668.22129,-0.13489,94.25682,32.37318
297.97200,24.83093,667.83461,-0.13489,94.39003,32.35445
298.37200,24.86442,667.93398,-0.13489,94.52396,32.35926
298.77200,24.89766,668.25710,-0.13489,94.65694,32.37492
299.17203,24.93096,668.64765,-0.13489,94.79015,32.39384
299.57203,24.96444,668.37459,-0.13489,94.92407,32.38061
299.97200,24.99757,669.09445,-0.13489,95.05656,32.41548
300.37200,25.03105,668.45492,-0.13489,95.19050,32.38450
300.77200,25.06435,667.89757,-0.13490,95.32371,32.35750
301.17203,25.09766,668.47797,-0.13490,95.45692,32.38562
301.57203,25.13108,668.19401,-0.13489,95.59061,32.37186
301.97200,25.16420,668.69021,-0.13489,95.72310,32.39590
302.37200,25.19768,668.52584,-0.13489,95.85704,32.38794
302.77200,25.23099,668.50805,-0.13489,95.99024,32.38707
303.17203,25.26429,668.43131,-0.13489,96.12345,32.38335
303.57203,25.29765,668.50684,-0.13489,96.25690,32.38701
303.97200,25.33101,667.80238,-0.13489,96.39035,32.35289
304.37200,25.36432,668.73659,-0.13489,96.52357,32.39814
304.77200,25.39762,669.00263,-0.13489,96.65677,32.41103
305.17203,25.43098,668.70474,-0.13489,96.79023,32.39660
305.57203,25.46434,669.02093,-0.13489,96.92367,32.41192
305.97200,25.49765,669.21692,-0.13490,97.05688,32.42142
306.37200,25.53101,669.53660,-0.13489,97.19033,32.43690
306.77200,25.56443,669.43327,-0.13489,97.32403,32.43190
307.17203,25.59755,669.95709,-0.13489,97.45651,32.45728
307.57203,25.63104,669.32924,-0.13489,97.59045,32.42686
307.97200,25.66434,669.76226,-0.13489,97.72366,32.44783
308.37200,25.69764,669.69511,-0.13489,97.85686,32.44458
308.77200,25.73106,669.58079,-0.13489,97.99055,32.43904
309.17203,25.76437,669.59839,-0.13489,98.12377,32.43990
309.57203,25.79761,669.36975,-0.13489,98.25674,32.42882
309.97200,25.83091,669.17120,-0.13490,98.38995,32.41920
310.37200,25.86428,669.80366,-0.13489,98.52340,32.44984
310.77200,25.89764,669.21329,-0.13490,98.65685,32.42124
311.17203,25.93106,669.35546,-0.13489,98.79054,32.42813
311.57203,25.96436,669.26247,-0.13490,98.92375,32.42362
311.97200,25.99766,669.47439,-0.13490,99.05696,32.43389
312.37200,26.03103,669.09986,-0.13490,99.19041,32.41574
312.77200,26.06433,669.19439,-0.13489,99.32362,32.42032
313.17203,26.09763,669.06996,-0.13489,99.45683,32.41430
313.57203,26.13106,667.89244,-0.13490,99.59053,32.35725
313.97200,26.16424,668.75997,-0.13489,99.72326,32.39928
314.37200,26.19766,668.36393,-0.13490,99.85694,32.38009
314.77200,26.23103,668.22930,-0.13489,99.99040,32.37357
315.17203,26.26427,668.59880,-0.13489,100.12337,32.39147
315.57203,26.29775,668.44793,-0.13489,100.25730,32.38416
315.97200,26.33087,668.10451,-0.13489,100.38979,32.36752
316.37200,26.36430,668.06069,-0.13490,100.52348,32.36540
316.77200,26.39772,667.84485,-0.13489,100.65717,32.35494
317.17203,26.43102,668.30646,-0.13490,100.79038,32.37731
317.57203,26.46438,668.04928,-0.13489,100.92382,32.36485
317.97200,26.49763,667.84718,-0.13490,101.05680,32.35506
318.37200,26.53093,667.86911,-0.13489,101.19002,32.35612
318.77200,26.56435,668.21743,-0.13489,101.32370,32.37299
319.17203,26.59765,668.70102,-0.13490,101.45690,32.39642
319.57203,26.63102,668.79895,-0.13489,101.59037,32.40117
319.97200,26.66438,668.72276,-0.13489,101.72381,32.39748
320.37200,26.69756,669.39946,-0.13489,101.85655,32.43026
320.77200,26.73104,668.78046,-0.13489,101.99047,32.40027
321.17203,26.76429,669.43364,-0.13489,102.12345,32.43192
321.57203,26.79765,669.19480,-0.13489,102.25689,32.42035
321.97200,26.83113,669.04877,-0.13489,102.39083,32.41327
322.37200,26.86432,669.03294,-0.13489,102.52357,32.41250
322.77200,26.89768,670.05404,-0.13489,102.65701,32.46197
323.17203,26.93098,668.68663,-0.13489,102.79022,32.39573
323.57203,26.96422,669.63593,-0.13489,102.92319,32.44172
323.97200,26.99770,669.71700,-0.13489,103.05712,32.44564
324.37200,27.03095,669.76999,-0.13489,103.19009,32.44821
324.77200,27.06431,669.65176,-0.13489,103.32354,32.44248
325.17203,27.09773,669.77879,-0.13489,103.45724,32.44864
325.57203,27.13092,669.24607,-0.13489,103.58996,32.42283
325.97200,27.16434,669.63155,-0.13490,103.72366,32.44150
326.37200,27.19764,669.13427,-0.13489,103.85686,32.41741
326.77200,27.23101,669.28607,-0.13489,103.99032,32.42477
327.17203,27.26443,669.63420,-0.13489,104.12400,32.44163
327.57203,27.29761,668.60002,-0.13489,104.25674,32.39153
327.97200,27.33109,669.01259,-0.13489,104.39067,32.41152
328.37200,27.36433,668.43648,-0.13489,104.52363,32.38361
328.77200,27.39764,668.31675,-0.13489,104.65685,32.37780
329.17203,27.43106,668.49501,-0.13489,104.79054,32.38644
329.57203,27.46430,668.50842,-0.13489,104.92351,32.38709
329.97200,27.49773,668.25706,-0.13489,105.05719,32.37491
330.37200,27.53097,668.25491,-0.13489,105.19017,32.37481
330.77200,27.56427,668.13696,-0.13489,105.32337,32.36909
331.17203,27.59769,668.18846,-0.13489,105.45707,32.37159
331.57203,27.63100,667.89733,-0.13489,105.59028,32.35749
331.97200,27.66430,667.78408,-0.13489,105.72349,32.35200
332.37200,27.69760,668.32448,-0.13489,105.85670,32.37818
332.77200,27.73102,668.08378,-0.13489,105.99040,32.36652
333.17203,27.76433,667.13891,-0.13489,106.12361,32.32074
333.57203,27.79763,667.83712,-0.13489,106.25682,32.35457
333.97200,27.83099,666.91041,-0.13489,106.39026,32.30967
334.37200,27.86424,667.44424,-0.13489,106.52324,32.33553
334.77200,27.89760,666.79781,-0.13489,106.65668,32.30422
335.17203,27.93108,666.73378,-0.13490,106.79063,32.30112
335.57203,27.96432,666.57546,-0.13490,106.92359,32.29345
335.97200,27.99768,666.07152,-0.13489,107.05703,32.26903
336.37200,28.03099,666.48554,-0.13489,107.19024,32.28909
336.77200,28.06429,666.30468,-0.13489,107.32346,32.28033
337.17203,28.09771,666.00442,-0.13489,107.45715,32.26578
337.57203,28.13095,666.40116,-0.13489,107.59012,32.28500
337.97200,28.16438,665.16348,-0.13489,107.72381,32.22504
338.37200,28.19768,665.09787,-0.13489,107.85702,32.22186
338.77200,28.23092,664.87188,-0.13489,107.98999,32.21091
339.17203,28.26441,664.54071,-0.13489,108.12392,32.19487
339.57203,28.29765,663.02754,-0.13489,108.25690,32.12156
339.97200,28.33101,663.29427,-0.13489,108.39033,32.13448
340.37200,28.36431,661.37603,-0.13489,108.52355,32.04155
340.77200,28.39768,660.46771,-0.13489,108.65700,31.99754
341.17203,28.43104,658.81899,-0.13489,108.79046,31.91767
341.57203,28.46428,656.63843,-0.13489,108.92342,31.81203
341.97200,28.49764,652.83743,-0.13489,109.05688,31.62788
342.37200,28.53107,646.51920,-0.13489,109.19057,31.32178
342.74003,28.56174,5.60735,-0.13489,109.31325,0.27166