File: Manufatura Aditiva/Classificação Direção/Ensaios/Ensaios FDM/Tracao_OLABI_23_05_2018_FDM_XZ3.is_metal_RawData/Specimen_RawData_5.csv
Time,Extension,Load,Strain 1,Tensile strain,Tensile stress
(sec),(mm),(N),(mm/mm),(%),(MPa)
0.00000,0.00006,9.72310,0.00066,0.06627,0.47018
0.20000,0.01387,15.03513,0.00083,0.08345,0.72706
0.40000,0.03265,23.09859,0.00112,0.11151,1.11699
0.60000,0.04986,31.65875,0.00138,0.13800,1.53094
0.80000,0.06667,38.57702,0.00163,0.16336,1.86549
1.00000,0.08329,46.92485,0.00189,0.18939,2.26917
1.20000,0.10003,54.02807,0.00215,0.21456,2.61266
1.40000,0.11671,62.09211,0.00240,0.24034,3.00262
1.60000,0.13339,68.74735,0.00266,0.26608,3.32445
1.80000,0.14995,75.53460,0.00291,0.29123,3.65267
2.00000,0.16663,83.39567,0.00317,0.31660,4.03281
2.20000,0.18331,90.03416,0.00342,0.34213,4.35383
2.40000,0.19994,97.56361,0.00368,0.36750,4.71794
2.60000,0.21662,104.90115,0.00394,0.39365,5.07276
2.80000,0.23330,111.58671,0.00419,0.41874,5.39606
3.00000,0.24998,119.30258,0.00444,0.44374,5.76918
3.20000,0.26672,125.68677,0.00469,0.46909,6.07790
3.40000,0.28340,132.74279,0.00495,0.49470,6.41911
3.60000,0.30002,139.94949,0.00518,0.51794,6.76761
3.80000,0.31670,146.27733,0.00543,0.54261,7.07361
4.00000,0.33333,153.36574,0.00568,0.56833,7.41639
4.20000,0.35001,160.10713,0.00594,0.59367,7.74239
4.40000,0.36663,166.57196,0.00619,0.61871,8.05501
4.60000,0.38331,174.07530,0.00645,0.64460,8.41785
4.80000,0.40005,180.66436,0.00670,0.66982,8.73648
5.00000,0.41661,188.11736,0.00695,0.69474,9.09689
5.20000,0.43329,194.52703,0.00720,0.72027,9.40685
5.40000,0.45010,202.26669,0.00745,0.74542,9.78112
5.60000,0.46666,208.20408,0.00770,0.77046,10.06824
5.80000,0.48328,214.89928,0.00796,0.79552,10.39200
6.00000,0.50002,221.61917,0.00821,0.82117,10.71696
6.20000,0.51670,228.79562,0.00846,0.84564,11.06399
6.40000,0.53332,234.75417,0.00868,0.86842,11.35213
6.60000,0.54994,241.46487,0.00894,0.89406,11.67665
6.80000,0.56674,248.62331,0.00919,0.91879,12.02281
7.00000,0.58331,255.84137,0.00944,0.94417,12.37186
7.20000,0.59993,261.83336,0.00969,0.96943,12.66162
7.40000,0.61673,268.49408,0.00995,0.99455,12.98371
7.60000,0.63329,275.63747,0.01019,1.01929,13.32915
7.80000,0.64991,281.86417,0.01044,1.04418,13.63026
8.00000,0.66671,288.94970,0.01070,1.07012,13.97290
8.20000,0.68327,295.25715,0.01095,1.09471,14.27791
8.40000,0.69996,300.92581,0.01116,1.11644,14.55203
8.60000,0.71664,307.67617,0.01142,1.14175,14.87846
8.80000,0.73338,314.72973,0.01167,1.16657,15.21955
9.00000,0.75000,321.07050,0.01191,1.19139,15.52618
9.20000,0.76662,326.87995,0.01217,1.21657,15.80711
9.40000,0.78336,333.21921,0.01242,1.24196,16.11366
9.60000,0.79992,340.26345,0.01267,1.26681,16.45430
9.80000,0.81666,346.68539,0.01292,1.29176,16.76485
10.00000,0.83341,353.37568,0.01317,1.31686,17.08838
10.20000,0.85003,359.10618,0.01341,1.34126,17.36549
10.40000,0.86665,364.60506,0.01363,1.36325,17.63140
10.60000,0.88333,371.13421,0.01388,1.38815,17.94714
10.80000,0.89995,377.45412,0.01413,1.41293,18.25275
11.00000,0.91663,383.04462,0.01438,1.43795,18.52309
11.20000,0.93331,389.35833,0.01463,1.46320,18.82841
11.40000,0.95011,395.82457,0.01488,1.48816,19.14110
11.60000,0.96656,402.17205,0.01511,1.51111,19.44805
11.80000,0.98324,408.40604,0.01537,1.53655,19.74951
12.00000,1.00010,413.67048,0.01561,1.56147,20.00409
12.20000,1.01666,418.16095,0.01582,1.58178,20.22123
12.40000,1.03328,425.34033,0.01607,1.60699,20.56841
12.60000,1.05002,431.34768,0.01633,1.63327,20.85891
12.80000,1.06670,436.88449,0.01658,1.65768,21.12666
13.00000,1.08327,444.08641,0.01683,1.68274,21.47492
13.20000,1.09995,449.85702,0.01708,1.70820,21.75398
13.40000,1.11675,456.14922,0.01733,1.73315,22.05825
13.60000,1.13331,462.07807,0.01758,1.75791,22.34496
13.80000,1.14993,468.87547,0.01783,1.78350,22.67366
14.00000,1.16679,472.35289,0.01804,1.80370,22.84182
14.20000,1.18329,478.32425,0.01828,1.82845,23.13058
14.40000,1.19998,484.91186,0.01854,1.85389,23.44914
14.60000,1.21672,490.66669,0.01880,1.87954,23.72743
14.80000,1.23334,496.83242,0.01905,1.90496,24.02559
15.00000,1.24996,503.26991,0.01930,1.93008,24.33689
15.20000,1.26664,508.68765,0.01955,1.95510,24.59888
15.40000,1.28332,514.43228,0.01980,1.98025,24.87668
15.60000,1.30000,520.62068,0.02005,2.00549,25.17593
15.80000,1.31656,525.98319,0.02031,2.03094,25.43525
16.00000,1.33337,530.31081,0.02049,2.04934,25.64452
16.20000,1.34993,535.93819,0.02075,2.07477,25.91665
16.40000,1.36667,541.86746,0.02100,2.10025,26.20337
16.60000,1.38341,547.11238,0.02126,2.12574,26.45701
16.80000,1.40003,552.56146,0.02151,2.15107,26.72051
17.00000,1.41677,558.10744,0.02177,2.17682,26.98870
17.20000,1.43327,563.88513,0.02202,2.20197,27.26810
17.40000,1.45001,568.84824,0.02228,2.22773,27.50810
17.60000,1.46670,574.97104,0.02253,2.25332,27.80418
17.80000,1.48338,578.85055,0.02272,2.27220,27.99179
18.00000,1.49994,584.28613,0.02298,2.29752,28.25464
18.20000,1.51662,589.42302,0.02323,2.32335,28.50305
18.40000,1.53324,595.20104,0.02349,2.34854,28.78246
18.60000,1.55004,599.92722,0.02374,2.37425,29.01100
18.80000,1.56666,605.83772,0.02400,2.40002,29.29682
19.00000,1.58329,611.70114,0.02426,2.42576,29.58036
19.20000,1.60003,616.16651,0.02451,2.45138,29.79630
19.40000,1.61665,621.08305,0.02477,2.47733,30.03405
19.60000,1.63333,625.35601,0.02496,2.49630,30.24067
19.80000,1.65007,630.48131,0.02522,2.52230,30.48852
20.00000,1.66675,635.13736,0.02548,2.54834,30.71368
20.20000,1.68331,640.84032,0.02574,2.57415,30.98946
20.40000,1.69999,645.63234,0.02599,2.59880,31.22119
20.60000,1.71668,650.93078,0.02625,2.62474,31.47741
20.80000,1.73330,655.84918,0.02651,2.65067,31.71525
21.00000,1.74998,661.20513,0.02677,2.67668,31.97425
21.20000,1.76672,666.05830,0.02703,2.70311,32.20894
21.40000,1.78334,669.78317,0.02722,2.72222,32.38906
21.60000,1.79996,674.56639,0.02749,2.74870,32.62037
21.80000,1.81670,679.76066,0.02775,2.77504,32.87155
22.00000,1.83339,684.58519,0.02802,2.80151,33.10485
22.20000,1.85001,689.96926,0.02828,2.82816,33.36522
22.40000,1.86669,693.80221,0.02854,2.85424,33.55056
22.60000,1.88337,699.64114,0.02881,2.88075,33.83292
22.80000,1.89999,704.29007,0.02907,2.90711,34.05773
23.00000,1.91661,708.35138,0.02934,2.93394,34.25413
23.20000,1.93329,711.42046,0.02953,2.95287,34.40254
23.40000,1.94991,716.09076,0.02980,2.97953,34.62838
23.60000,1.96660,721.45327,0.03007,3.00667,34.88770
23.80000,1.98328,725.23858,0.03034,3.03369,35.07075
24.00000,2.00002,730.44905,0.03061,3.08008,35.32272
24.20000,2.01670,734.83353,0.03088,3.14680,35.53474
24.37200,2.03099,738.02997,0.03111,3.20396,35.68931
24.57200,2.04767,742.90028,0.03138,3.27069,35.92483
24.77200,2.06435,746.73668,0.03165,3.33741,36.11035
24.97200,2.08097,751.62947,0.03193,3.40390,36.34695
25.17200,2.09771,755.44063,0.03220,3.47086,36.53125
25.37200,2.11434,758.03143,0.03239,3.53735,36.65653
25.57200,2.13102,762.60557,0.03266,3.60407,36.87773
25.77200,2.14764,766.64579,0.03294,3.67056,37.07310
25.97200,2.16432,770.64275,0.03322,3.73729,37.26638
26.17200,2.18100,775.29815,0.03350,3.80401,37.49151
26.37200,2.19762,779.07997,0.03377,3.87050,37.67439
26.57200,2.21430,783.01914,0.03356,3.93722,37.86488
26.77200,2.23099,787.20180,0.03433,4.00395,38.06714
26.97200,2.24767,790.39140,0.03466,4.07067,38.22138
27.17200,2.26441,794.38668,0.03568,4.13764,38.41458
27.37200,2.28097,798.02396,0.03766,4.20388,38.59047
27.57200,2.29765,799.63030,0.07027,4.27061,38.66815
27.77200,2.31445,803.04835,0.07771,4.33781,38.83344
27.97200,2.33101,807.62943,0.07775,4.40406,39.05497
28.17200,2.34763,811.18019,0.07839,4.47054,39.22668
28.37200,2.36438,815.40002,0.07423,4.53751,39.43074
28.57200,2.38100,819.30310,0.07407,4.60399,39.61948
28.77200,2.39762,822.20826,0.07617,4.67048,39.75997
28.97200,2.41430,825.76880,0.07641,4.73720,39.93214
29.17200,2.43098,829.52268,0.07495,4.80393,40.11367
29.37200,2.44760,832.99642,0.07143,4.87041,40.28165
29.57200,2.46434,836.73093,0.05493,4.93738,40.46225
29.77200,2.48102,839.31768,-0.06809,5.00410,40.58733
29.97200,2.49759,841.52194,-0.06813,5.07035,40.69393
30.17200,2.51433,844.89593,-0.06814,5.13732,40.85709
30.37200,2.53101,847.34131,-0.06813,5.20404,40.97534
30.57200,2.54769,850.66948,-0.06814,5.27077,41.13628
30.77200,2.56437,853.80804,-0.06814,5.33749,41.28805
30.97200,2.58093,856.40410,-0.06814,5.40374,41.41359
31.17200,2.59767,860.25530,-0.06814,5.47070,41.59983
31.37200,2.61436,862.28093,-0.06814,5.53743,41.69778
31.57200,2.63098,865.66415,-0.06814,5.60391,41.86139
31.77200,2.64766,868.36619,-0.06814,5.67064,41.99205
31.97200,2.66428,870.61441,-0.06815,5.73712,42.10077
32.17200,2.68096,873.28684,-0.06814,5.80385,42.23000
32.37200,2.69770,876.00136,-0.06814,5.87081,42.36127
32.57200,2.71438,876.54497,-0.06815,5.93754,42.38755
32.77200,2.73100,878.71207,-0.06814,6.00403,42.49235
32.97200,2.74769,881.96835,-0.06814,6.07075,42.64981
33.17200,2.76437,883.78321,-0.06815,6.13747,42.73758
33.37200,2.78087,886.34770,-0.06815,6.20348,42.86159
33.57200,2.79773,888.73198,-0.06815,6.27092,42.97689
33.77200,2.81447,891.03132,-0.06815,6.33789,43.08808
33.97200,2.83097,892.22742,-0.06815,6.40390,43.14592
34.17200,2.84765,894.72970,-0.06815,6.47062,43.26693
34.37200,2.86434,896.78206,-0.06815,6.53735,43.36617
34.57200,2.88096,898.03059,-0.06815,6.60383,43.42655
34.77200,2.89764,900.63056,-0.06815,6.67056,43.55228
34.97200,2.91444,901.39369,-0.06815,6.73776,43.58918
35.17200,2.93100,903.63054,-0.06815,6.80401,43.69735
35.37200,2.94768,905.21378,-0.06815,6.87073,43.77391
35.57200,2.96436,906.74236,-0.06815,6.93746,43.84783
35.77200,2.98104,905.56033,-0.06815,7.00418,43.79066
35.97200,2.99761,907.92207,-0.06815,7.07043,43.90487
36.17200,3.01429,909.32902,-0.06815,7.13715,43.97291
36.37200,3.03097,910.47361,-0.06815,7.20388,44.02826
36.57200,3.04759,911.77877,-0.06815,7.27037,44.09137
36.77200,3.06427,912.40909,-0.06815,7.33709,44.12186
36.97200,3.08101,913.55210,-0.06815,7.40405,44.17713
37.17200,3.09763,914.98159,-0.06815,7.47054,44.24625
37.37200,3.11432,915.35263,-0.06815,7.53727,44.26420
37.57200,3.13100,915.97401,-0.06815,7.60399,44.29425
37.77200,3.14768,917.12177,-0.06815,7.67072,44.34975
37.97200,3.16436,917.11609,-0.06816,7.73744,44.34948
38.17200,3.18104,917.98687,-0.06815,7.80417,44.39158
38.37200,3.19772,918.74655,-0.06815,7.87089,44.42832
38.57200,3.21428,918.90441,-0.06815,7.93714,44.43596
38.77200,3.23096,918.90506,-0.06815,8.00386,44.43599
38.97200,3.24777,919.53315,-0.06815,8.07107,44.46636
39.17200,3.26433,919.51396,-0.06815,8.13731,44.46543
39.37200,3.28095,919.56006,-0.06815,8.20380,44.46766
39.57200,3.29763,919.60840,-0.06815,8.27052,44.47000
39.77200,3.31431,918.93841,-0.06815,8.33725,44.43760
39.97200,3.33099,919.29529,-0.06815,8.40397,44.45486
40.17200,3.34773,919.50661,-0.06815,8.47094,44.46507
40.37200,3.36435,918.93282,-0.06815,8.53743,44.43733
40.57200,3.38092,918.28154,-0.06815,8.60367,44.40583
40.77200,3.39760,918.60415,-0.06815,8.67040,44.42143
40.97200,3.41446,917.27804,-0.06816,8.73784,44.35731
41.17200,3.43102,917.51358,-0.06815,8.80409,44.36869
41.37200,3.44764,916.80996,-0.06815,8.87057,44.33467
41.57200,3.46438,915.18415,-0.06815,8.93754,44.25605
41.77200,3.48094,915.93517,-0.06815,9.00378,44.29237
41.97200,3.49763,914.34652,-0.06815,9.07051,44.21555
42.17200,3.51437,913.41147,-0.06816,9.13747,44.17033
42.37200,3.53105,912.11349,-0.06815,9.20420,44.10756
42.57200,3.54761,911.91661,-0.06816,9.27044,44.09804
42.77200,3.56429,910.40544,-0.06816,9.33717,44.02496
42.97200,3.58115,908.78922,-0.06815,9.40461,43.94681
43.17200,3.59759,908.69823,-0.06815,9.47038,43.94241
43.37200,3.61427,907.60561,-0.06816,9.53710,43.88957
43.57200,3.63108,906.13347,-0.06816,9.60431,43.81838
43.77200,3.64764,905.14561,-0.06816,9.67056,43.77061
43.97200,3.66432,903.48469,-0.06816,9.73728,43.69029
44.17200,3.68106,902.37325,-0.06816,9.80424,43.63655
44.37200,3.69768,901.00653,-0.06815,9.87073,43.57046
44.57200,3.71436,899.90245,-0.06815,9.93746,43.51707
44.77200,3.73092,898.81634,-0.06815,10.00370,43.46454
44.97200,3.74767,897.22164,-0.06815,10.07067,43.38743
45.17200,3.76429,895.68486,-0.06816,10.13715,43.31311
45.37200,3.78097,894.42991,-0.06815,10.20388,43.25243
45.57200,3.79777,893.53248,-0.06816,10.27108,43.20903
45.77200,3.81427,892.09871,-0.06815,10.33709,43.13969
45.97200,3.83095,890.80604,-0.06816,10.40381,43.07719
46.17200,3.84769,889.50014,-0.06815,10.47078,43.01403
46.37200,3.86437,888.14413,-0.06816,10.53750,42.94846
46.57200,3.88100,886.69322,-0.06816,10.60399,42.87830
46.77200,3.89762,885.39552,-0.06815,10.67047,42.81554
46.97200,3.91436,884.15770,-0.06816,10.73744,42.75569
47.17200,3.93092,882.59978,-0.06816,10.80369,42.68035
47.37200,3.94760,881.32974,-0.06816,10.87041,42.61893
47.57200,3.96440,879.62421,-0.06816,10.93761,42.53646
47.77200,3.98096,878.50746,-0.06816,11.00386,42.48246
47.97200,3.99758,877.64803,-0.06816,11.07035,42.44090
48.17200,4.01439,876.14255,-0.06816,11.13755,42.36810
48.37200,4.03095,874.52084,-0.06815,11.20380,42.28967
48.57200,4.04769,873.41657,-0.06816,11.27076,42.23627
48.77200,4.06443,872.03356,-0.06816,11.33772,42.16940
48.97200,4.08099,871.79262,-0.06815,11.40397,42.15774
49.17200,4.09761,870.11550,-0.06815,11.47046,42.07664
49.37200,4.11435,869.42436,-0.06816,11.53742,42.04322
49.57200,4.13110,867.57969,-0.06816,11.60439,41.95402
49.77200,4.14766,866.35882,-0.06815,11.67063,41.89498
49.97200,4.16428,864.97897,-0.06816,11.73712,41.82825
50.17200,4.18108,864.03266,-0.06816,11.80432,41.78249
50.37200,4.19764,862.93137,-0.06816,11.87057,41.72924
50.57200,4.21432,862.20251,-0.06816,11.93729,41.69399
50.77200,4.23100,860.75291,-0.06816,12.00402,41.62389
50.97200,4.24774,860.35868,-0.06816,12.07098,41.60483
51.17200,4.26431,859.02400,-0.06815,12.13723,41.54028
51.37200,4.28099,857.56518,-0.06816,12.20395,41.46974
51.57200,4.29773,856.54575,-0.06816,12.27092,41.42044
51.77200,4.31435,855.67525,-0.06816,12.33741,41.37835
51.97200,4.33097,854.68413,-0.06816,12.40389,41.33042
52.17200,4.34759,853.27653,-0.06816,12.47038,41.26235
52.37200,4.36427,852.21501,-0.06816,12.53710,41.21102
52.57200,4.38096,851.53524,-0.06816,12.60383,41.17815
52.77200,4.39758,850.73058,-0.06816,12.67031,41.13924
52.97200,4.41438,849.52237,-0.06816,12.73752,41.08081
53.17200,4.43106,848.85536,-0.06816,12.80424,41.04855
53.37200,4.44762,847.23476,-0.06816,12.87049,40.97018
53.57200,4.46436,846.45906,-0.06816,12.93745,40.93267
53.77200,4.48098,846.15787,-0.06816,13.00394,40.91811
53.97200,4.49766,844.93067,-0.06816,13.07066,40.85876
54.17200,4.51441,843.71772,-0.06816,13.13763,40.80011
54.37200,4.53103,842.97508,-0.06816,13.20411,40.76420
54.57200,4.54759,842.08930,-0.06816,13.27036,40.72136
54.77200,4.56433,841.11476,-0.06816,13.33732,40.67424
54.97200,4.58101,840.47765,-0.06816,13.40405,40.64343
55.17200,4.59769,838.98837,-0.06816,13.47078,40.57141
55.37200,4.61431,838.46226,-0.06816,13.53726,40.54597
55.57200,4.63100,836.96945,-0.06816,13.60399,40.47378
55.77200,4.64768,836.56581,-0.06816,13.67071,40.45426
55.97200,4.66436,835.82364,-0.06816,13.73744,40.41837
56.17200,4.68110,835.23626,-0.06816,13.80440,40.38997
56.37200,4.69766,834.18861,-0.06816,13.87065,40.33931
56.57200,4.71434,833.17365,-0.06816,13.93737,40.29023
56.77200,4.73102,832.79340,-0.06816,14.00410,40.27184
56.97200,4.74764,831.26696,-0.06815,14.07059,40.19802
57.17200,4.76433,830.29401,-0.06816,14.13731,40.15097
57.37200,4.78101,830.10485,-0.06815,14.20403,40.14183
57.57200,4.79763,829.01847,-0.06816,14.27052,40.08929
57.77200,4.81431,828.45539,-0.06816,14.33724,40.06206
57.97200,4.83093,827.57063,-0.06816,14.40373,40.01928
58.17200,4.84767,826.31083,-0.06816,14.47069,39.95835
58.37200,4.86435,825.80158,-0.06816,14.53742,39.93373
58.57200,4.88098,824.81131,-0.06816,14.60391,39.88584
58.77200,4.89766,824.97215,-0.06816,14.67063,39.89362
58.97200,4.91428,823.35770,-0.06816,14.73712,39.81555
59.17200,4.93096,823.31346,-0.06816,14.80384,39.81341
59.37200,4.94770,821.56025,-0.06816,14.87081,39.72863
59.57200,4.96432,820.96802,-0.06816,14.93729,39.69999
59.77200,4.98100,819.83656,-0.06816,15.00401,39.64528
59.97200,4.99768,819.37909,-0.06816,15.07074,39.62315
60.17200,5.01436,818.13931,-0.06816,15.13747,39.56320
60.37200,5.03099,818.03240,-0.06816,15.20395,39.55803
60.57200,5.04767,816.96715,-0.06816,15.27068,39.50652
60.77200,5.06435,816.28300,-0.06816,15.33740,39.47343
60.97200,5.08097,814.98446,-0.06816,15.40389,39.41064
61.17200,5.09765,814.38189,-0.06816,15.47061,39.38150
61.37200,5.11439,813.37411,-0.06816,15.53758,39.33277
61.57200,5.13101,812.98947,-0.06816,15.60406,39.31417
61.77200,5.14770,811.97303,-0.06816,15.67079,39.26501
61.97200,5.16432,810.95695,-0.06816,15.73727,39.21588
62.17200,5.18100,810.21776,-0.06816,15.80400,39.18013
62.37200,5.19762,809.59219,-0.06816,15.87049,39.14988
62.57200,5.21430,809.01794,-0.06816,15.93721,39.12212
62.77200,5.23104,808.01304,-0.06816,16.00417,39.07352
62.97200,5.24766,806.86715,-0.06816,16.07066,39.01811
63.17200,5.26423,806.31403,-0.06816,16.13691,38.99136
63.37200,5.28103,805.16329,-0.06816,16.20411,38.93571
63.57200,5.29765,804.25516,-0.06816,16.27060,38.89180
63.77200,5.31439,804.03620,-0.06815,16.33756,38.88121
63.97200,5.33107,803.39676,-0.06816,16.40429,38.85029
64.17200,5.34763,802.31009,-0.06816,16.47053,38.79774
64.37200,5.36431,801.30901,-0.06816,16.53726,38.74933
64.57201,5.38105,800.64954,-0.06816,16.60422,38.71744
64.77200,5.39774,799.75016,-0.06816,16.67095,38.67395
64.97200,5.41436,799.38574,-0.06816,16.73743,38.65633
65.17200,5.43098,797.93939,-0.06816,16.80392,38.58638
65.37200,5.44766,796.45459,-0.06816,16.87064,38.51458
65.57201,5.46428,796.33174,-0.06816,16.93713,38.50864
65.77200,5.48102,795.44662,-0.06816,17.00410,38.46584
65.97200,5.49764,794.00344,-0.06816,17.07058,38.39605
66.17201,5.51426,793.25773,-0.06816,17.13707,38.35999
66.37200,5.53101,792.73377,-0.06816,17.20403,38.33465
66.57201,5.54763,791.19224,-0.06816,17.27052,38.26011
66.77200,5.56437,790.58344,-0.06816,17.33748,38.23067
66.97200,5.58105,790.05966,-0.06816,17.40421,38.20534
67.17201,5.59767,788.54691,-0.06816,17.47069,38.13219
67.37200,5.61435,788.00227,-0.06816,17.53742,38.10585
67.57201,5.63091,786.54941,-0.06816,17.60366,38.03559
67.77200,5.64766,785.34428,-0.06816,17.67063,37.97731
67.97200,5.66440,784.69170,-0.06816,17.73759,37.94576
68.17201,5.68096,783.83060,-0.06816,17.80384,37.90412
68.37200,5.69764,782.78286,-0.06816,17.87056,37.85345
68.57201,5.71432,781.74947,-0.06816,17.93729,37.80348
68.77200,5.73100,780.67062,-0.06816,18.00402,37.75131
68.97200,5.74768,779.11816,-0.06816,18.07074,37.67624
69.17201,5.76431,778.34446,-0.06816,18.13723,37.63882
69.37200,5.78105,776.95991,-0.06816,18.20419,37.57187
69.57201,5.79767,776.03576,-0.06816,18.27068,37.52718
69.77200,5.81435,774.78942,-0.06816,18.33740,37.46691
69.97200,5.83109,773.26423,-0.06816,18.40436,37.39315
70.17201,5.84771,772.25948,-0.06816,18.47085,37.34457
70.37200,5.86433,771.32289,-0.06816,18.53734,37.29927
70.57201,5.88101,769.97271,-0.06816,18.60406,37.23398
70.77200,5.89764,768.44064,-0.06816,18.67055,37.15990
70.97200,5.91426,767.17352,-0.06816,18.73703,37.09862
71.17201,5.93100,765.83959,-0.06816,18.80400,37.03411
71.37200,5.94780,764.26649,-0.06816,18.87120,36.95805
71.57201,5.96430,762.86430,-0.06816,18.93721,36.89024
71.77200,5.98092,761.57013,-0.06816,19.00370,36.82766
71.97200,5.99772,760.28332,-0.06816,19.07090,36.76543
72.17201,6.01434,758.57234,-0.06816,19.13738,36.68269
72.37200,6.03103,757.19701,-0.06816,19.20411,36.61618
72.57201,6.04771,755.53642,-0.06816,19.27083,36.53588
72.77200,6.06427,754.27494,-0.06816,19.33708,36.47488
72.97200,6.08089,751.96722,-0.06816,19.40357,36.36328
73.17201,6.09769,749.86708,-0.06816,19.47077,36.26173
73.37200,6.11443,749.00165,-0.06816,19.53773,36.21988
73.57201,6.13093,747.65696,-0.06816,19.60374,36.15485
73.77200,6.14756,745.15021,-0.06816,19.67023,36.03363
73.97200,6.16430,743.65172,-0.06816,19.73719,35.96117
74.17201,6.18098,740.87838,-0.06816,19.80392,35.82705
74.37200,6.19778,739.54142,-0.06816,19.87112,35.76240
74.57201,6.21440,737.40962,-0.06816,19.93761,35.65931
74.77200,6.23096,736.02190,-0.06816,20.00385,35.59221
74.97200,6.24758,734.00470,-0.06816,20.07034,35.49466
75.17201,6.26432,731.84138,-0.06816,20.13731,35.39005
75.37200,6.28101,730.14335,-0.06816,20.20403,35.30793
75.57201,6.29769,727.76028,-0.06816,20.27075,35.19270
75.77200,6.31431,725.48711,-0.06816,20.33724,35.08277
75.97200,6.33099,723.61273,-0.06816,20.40396,34.99213
76.17201,6.34761,721.86831,-0.06816,20.47045,34.90777
76.37200,6.36423,719.53340,-0.06816,20.53694,34.79486
76.57201,6.38115,717.83797,-0.06816,20.60462,34.71288
76.77200,6.39771,714.56372,-0.06816,20.67086,34.55454
76.97200,6.41428,712.60026,-0.06816,20.73711,34.45959
77.17201,6.43108,710.90353,-0.06816,20.80432,34.37754
77.37200,6.44764,708.92107,-0.06816,20.87056,34.28168
77.57201,6.46432,706.02531,-0.06816,20.93728,34.14164
77.77200,6.48106,704.35531,-0.06816,21.00425,34.06089
77.97200,6.49774,702.69876,-0.06816,21.07098,33.98078
78.17201,6.51424,699.85949,-0.06816,21.13698,33.84348
78.37200,6.53093,697.36256,-0.06816,21.20371,33.72274
78.57201,6.54779,695.31882,-0.06816,21.27115,33.62391
78.77200,6.56429,693.71429,-0.06816,21.33716,33.54631
78.97200,6.58091,691.75176,-0.06816,21.40364,33.45141
79.17201,6.59771,689.03076,-0.06816,21.47085,33.31983
79.37200,6.61427,687.42814,-0.06816,21.53709,33.24233
79.57201,6.63095,685.12233,-0.06816,21.60382,33.13083
79.77200,6.64769,683.00413,-0.06816,21.67078,33.02840
79.97200,6.66432,680.64486,-0.06816,21.73727,32.91431
80.17201,6.68094,679.73253,-0.06816,21.80376,32.87019
80.37200,6.69762,677.31929,-0.06816,21.87048,32.75349
80.57201,6.71436,675.59928,-0.06816,21.93745,32.67031
80.77200,6.73098,673.29081,-0.06816,22.00393,32.55869
80.97200,6.74766,672.22053,-0.06816,22.07066,32.50693
81.17201,6.76428,670.72003,-0.06816,22.13714,32.43437
81.37200,6.78097,669.10372,-0.06816,22.20387,32.35621
81.57201,6.79759,667.55465,-0.06816,22.27035,32.28130
81.77200,6.81433,666.34472,-0.06816,22.33732,32.22279
81.97200,6.83101,665.22262,-0.06816,22.40404,32.16853
82.17201,6.84769,663.36966,-0.06816,22.47077,32.07892
82.37200,6.86431,662.27429,-0.06816,22.53725,32.02595
82.57201,6.88099,660.75944,-0.06816,22.60398,31.95270
82.77200,6.89767,660.02291,-0.06816,22.67071,31.91708
82.97201,6.91436,658.62495,-0.06816,22.73743,31.84948
83.17201,6.93110,657.84412,-0.06816,22.80439,31.81172
83.37200,6.94760,657.54182,-0.06816,22.87040,31.79710
83.57201,6.96428,655.64672,-0.06816,22.93713,31.70546
83.77200,6.98102,655.39656,-0.06816,23.00409,31.69336
83.97201,6.99764,654.34370,-0.06816,23.07058,31.64245
84.17201,7.01432,653.73951,-0.06816,23.13730,31.61323
84.37200,7.03101,652.90588,-0.06816,23.20403,31.57292
84.57201,7.04769,651.78447,-0.06816,23.27075,31.51869
84.77200,7.06431,651.43653,-0.06816,23.33724,31.50187
84.97201,7.08099,650.74693,-0.06816,23.40396,31.46852
85.17201,7.09779,650.28439,-0.06816,23.47116,31.44615
85.37200,7.11429,650.06213,-0.06816,23.53717,31.43540
85.57201,7.13097,650.07247,-0.06816,23.60390,31.43590
85.77200,7.14777,649.14511,-0.06816,23.67110,31.39106
85.97201,7.16434,648.99032,-0.06816,23.73735,31.38357
86.17201,7.18096,648.22002,-0.06816,23.80384,31.34632
86.37200,7.19764,647.89448,-0.06816,23.87056,31.33058
86.57201,7.21432,647.57252,-0.06816,23.93728,31.31501
86.77200,7.23094,647.74309,-0.06816,24.00377,31.32326
86.97201,7.24762,647.04604,-0.06816,24.07049,31.28955
87.17201,7.26436,646.95389,-0.06816,24.13746,31.28510
87.37200,7.28099,646.96013,-0.06816,24.20395,31.28540
87.57201,7.29767,646.45740,-0.06816,24.27067,31.26109
87.77200,7.31435,647.23445,-0.06816,24.33739,31.29866
87.97201,7.33097,646.07151,-0.06816,24.40388,31.24243
88.17201,7.34771,645.90047,-0.06816,24.47085,31.23416
88.37200,7.36433,645.87165,-0.06816,24.53733,31.23276
88.57201,7.38101,645.58215,-0.06816,24.60406,31.21876
88.77200,7.39763,645.97041,-0.06816,24.67054,31.23754
88.97201,7.41432,645.80208,-0.06816,24.73727,31.22940
89.17201,7.43100,645.31476,-0.06816,24.80399,31.20583
89.37200,7.44768,645.97405,-0.06816,24.87072,31.23771
89.57201,7.46430,645.76669,-0.06816,24.93720,31.22769
89.77200,7.48098,645.21125,-0.06816,25.00393,31.20083
89.97201,7.49766,646.25037,-0.06816,25.07065,31.25108
90.17201,7.51434,645.90471,-0.06815,25.13738,31.23436
90.37200,7.53102,645.72282,-0.06816,25.20410,31.22556
90.57201,7.54777,646.20427,-0.06816,25.27107,31.24885
90.77200,7.56433,646.09428,-0.06816,25.33732,31.24353
90.97201,7.58095,646.45237,-0.06816,25.40380,31.26084
91.17201,7.59769,645.93358,-0.06816,25.47077,31.23576
91.37200,7.61425,646.11589,-0.06816,25.53701,31.24457
91.57201,7.63099,646.71850,-0.06816,25.60398,31.27371
91.77200,7.64773,645.95090,-0.06816,25.67094,31.23659
91.97201,7.66424,646.44022,-0.06816,25.73695,31.26026
92.17201,7.68098,646.93815,-0.06816,25.80391,31.28433
92.37200,7.69772,647.23310,-0.06816,25.87088,31.29860
92.57201,7.71440,646.65056,-0.06816,25.93760,31.27043
92.77200,7.73102,646.33149,-0.06816,26.00409,31.25500
92.97201,7.74770,646.33316,-0.06816,26.07081,31.25508
93.17201,7.76438,646.74900,-0.06816,26.13754,31.27519
93.37200,7.78100,646.66495,-0.06816,26.20402,31.27112
93.57201,7.79763,647.15827,-0.06816,26.27051,31.29498
93.77200,7.81437,647.03319,-0.06816,26.33747,31.28893
93.97201,7.83099,647.11240,-0.06816,26.40396,31.29276
94.17201,7.84767,647.61555,-0.06816,26.47069,31.31709
94.37200,7.86429,647.44088,-0.06816,26.53717,31.30865
94.57201,7.88097,646.99249,-0.06816,26.60390,31.28696
94.77200,7.89765,647.82533,-0.06816,26.67062,31.32724
94.97201,7.91428,647.53233,-0.06816,26.73711,31.31307
95.17201,7.93102,647.69750,-0.06816,26.80407,31.32106
95.37200,7.94758,648.45425,-0.06816,26.87032,31.35765
95.57201,7.96432,648.27553,-0.06816,26.93728,31.34901
95.77200,7.98100,648.64154,-0.06816,27.00400,31.36671
95.97201,7.99768,648.64028,-0.06816,27.07073,31.36665
96.17201,8.01436,648.32517,-0.06816,27.13746,31.35141
96.37200,8.03098,648.39944,-0.06816,27.20394,31.35500
96.57201,8.04767,648.92499,-0.06816,27.27067,31.38041
96.77200,8.06435,649.25770,-0.06816,27.33739,31.39650
96.97201,8.08103,648.90157,-0.06816,27.40412,31.37928
97.17201,8.09771,649.54557,-0.06816,27.47084,31.41042
97.37200,8.11433,649.28508,-0.06816,27.53733,31.39783
97.57201,8.13089,650.02926,-0.06816,27.60358,31.43381
97.77200,8.14769,649.67740,-0.06816,27.67078,31.41680
97.97201,8.16437,650.01482,-0.06816,27.73750,31.43312
98.17201,8.18100,649.80364,-0.06816,27.80399,31.42290
98.37200,8.19768,650.48621,-0.06816,27.87072,31.45591
98.57201,8.21430,650.45441,-0.06816,27.93720,31.45437
98.77200,8.23092,650.41706,-0.06816,28.00369,31.45257
98.97201,8.24772,650.64500,-0.06816,28.07089,31.46359
99.17201,8.26434,650.70526,-0.06816,28.13737,31.46650
99.37200,8.28096,650.81120,-0.06816,28.20386,31.47163
99.57201,8.29765,651.68925,-0.06816,28.27059,31.51409
99.77200,8.31439,650.99942,-0.06816,28.33755,31.48073
99.97201,8.33095,651.39257,-0.06816,28.40380,31.49974
100.17201,8.34763,651.51928,-0.06816,28.47053,31.50587
100.37200,8.36443,652.15458,-0.06816,28.53773,31.53659
100.57201,8.38099,651.65223,-0.06816,28.60397,31.51230
100.77200,8.39755,652.22657,-0.06816,28.67022,31.54007
100.97201,8.41441,652.10336,-0.06816,28.73766,31.53411
101.17201,8.43104,651.74522,-0.06816,28.80415,31.51679
101.37200,8.44772,652.30601,-0.06816,28.87087,31.54391
101.57201,8.46434,652.12939,-0.06816,28.93736,31.53537
101.77200,8.48096,653.16204,-0.06816,29.00385,31.58531
101.97201,8.49770,652.63505,-0.06816,29.07081,31.55982
102.17201,8.51426,652.97522,-0.06816,29.13706,31.57627
102.37200,8.53100,653.28986,-0.06816,29.20402,31.59149
102.57201,8.54757,653.14081,-0.06816,29.27027,31.58428
102.77200,8.56425,653.87762,-0.06816,29.33699,31.61991
102.97201,8.58099,653.09489,-0.06816,29.40395,31.58206
103.17201,8.59767,653.87296,-0.06816,29.47068,31.61969
103.37200,8.61435,653.57392,-0.06816,29.53741,31.60522
103.57201,8.63109,653.68903,-0.06816,29.60437,31.61079
103.77200,8.64765,654.00302,-0.06816,29.67062,31.62597
103.97201,8.66433,653.89439,-0.06816,29.73734,31.62072
104.17201,8.68096,654.16018,-0.06816,29.80383,31.63358
104.37200,8.69770,654.16852,-0.06816,29.87080,31.63398
104.57201,8.71432,653.82095,-0.06816,29.93728,31.61717
104.77200,8.73094,654.01467,-0.06816,30.00377,31.62654
104.97201,8.74768,653.74519,-0.06816,30.07073,31.61351
105.17201,8.76424,654.23870,-0.06816,30.13698,31.63737
105.37200,8.78098,654.04056,-0.06816,30.20394,31.62779
105.57201,8.79778,654.09020,-0.06816,30.27115,31.63019
105.77200,8.81429,654.45881,-0.06816,30.33715,31.64802
105.97201,8.83097,654.43972,-0.06816,30.40388,31.64709
106.17201,8.84765,653.90174,-0.06816,30.47060,31.62108
106.37200,8.86439,654.70915,-0.06816,30.53757,31.66012
106.57201,8.88101,654.49630,-0.06816,30.60405,31.64983
106.77200,8.89769,654.43795,-0.06816,30.67078,31.64701
106.97201,8.91437,654.63344,-0.06816,30.73750,31.65646
107.17201,8.93094,654.70650,-0.06816,30.80375,31.65999
107.37200,8.94768,654.17872,-0.06816,30.87071,31.63447
107.57201,8.96448,654.59544,-0.06816,30.93792,31.65462
107.77200,8.98098,655.08741,-0.06816,31.00392,31.67841
107.97201,8.99754,655.47330,-0.06816,31.07017,31.69707
108.17201,9.01434,654.81747,-0.06816,31.13737,31.66536
108.37200,9.03102,654.35884,-0.06816,31.20410,31.64318
108.57201,9.04771,655.09989,-0.06816,31.27083,31.67902
108.77200,9.06433,654.63488,-0.06816,31.33731,31.65653
108.97201,9.08101,655.35745,-0.06816,31.40403,31.69147
109.17201,9.09757,654.54412,-0.06816,31.47028,31.65214
109.37200,9.11431,654.99903,-0.06816,31.53725,31.67414
109.57201,9.13105,654.96545,-0.06816,31.60421,31.67252
109.77200,9.14767,654.63283,-0.06816,31.67070,31.65643
109.97201,9.16429,654.59888,-0.06816,31.73718,31.65479
110.17201,9.18098,655.04550,-0.06816,31.80391,31.67639
110.37200,9.19760,655.41095,-0.06816,31.87039,31.69406
110.57201,9.21428,654.80825,-0.06816,31.93712,31.66491
110.77200,9.23096,654.92885,-0.06816,32.00384,31.67075
110.97201,9.24776,655.76877,-0.06816,32.07105,31.71136
111.17201,9.26432,655.14366,-0.06816,32.13729,31.68113
111.37200,9.28100,655.43004,-0.06816,32.20402,31.69498
111.57201,9.29768,655.55158,-0.06816,32.27074,31.70086
111.77200,9.31437,655.72150,-0.06816,32.33747,31.70908
111.97201,9.33105,655.55819,-0.06816,32.40419,31.70118
112.17201,9.34767,655.72653,-0.06816,32.47068,31.70932
112.37200,9.36429,655.95992,-0.06816,32.53717,31.72061
112.57201,9.38097,656.05012,-0.06816,32.60389,31.72497
112.77200,9.39771,656.10851,-0.06816,32.67086,31.72779
112.97201,9.41439,655.80504,-0.06816,32.73758,31.71312
113.17201,9.43096,656.02357,-0.06816,32.80383,31.72368
113.37200,9.44764,655.92732,-0.06816,32.87055,31.71903
113.57201,9.46438,656.22525,-0.06816,32.93752,31.73344
113.77200,9.48094,656.59606,-0.06816,33.00377,31.75137
113.97201,9.49768,656.59410,-0.06816,33.07073,31.75127
114.17201,9.51442,656.01449,-0.06816,33.13769,31.72325
114.37200,9.53098,656.46903,-0.06816,33.20394,31.74522
114.57201,9.54760,656.70731,-0.06816,33.27042,31.75675
114.77200,9.56435,656.83634,-0.06816,33.33739,31.76299
114.97201,9.58103,656.65217,-0.06816,33.40411,31.75408
115.17201,9.59765,656.60276,-0.06816,33.47060,31.75169
115.37201,9.61433,656.83406,-0.06816,33.53733,31.76288
115.57201,9.63095,656.59629,-0.06816,33.60381,31.75138
115.77200,9.64757,657.21781,-0.06816,33.67029,31.78144
115.97201,9.66431,657.14200,-0.06816,33.73726,31.77777
116.17201,9.68100,657.80072,-0.06816,33.80399,31.80962
116.37201,9.69762,657.64845,-0.06816,33.87047,31.80226
116.57201,9.71430,657.43984,-0.06816,33.93720,31.79217
116.77200,9.73098,657.39937,-0.06816,34.00392,31.79021
116.97201,9.74772,657.51188,-0.06816,34.07089,31.79565
117.17201,9.76434,657.26670,-0.06816,34.13737,31.78380
117.37201,9.78108,657.77153,-0.06816,34.20433,31.80821
117.57201,9.79770,658.02042,-0.06816,34.27082,31.82025
117.77200,9.81433,657.57469,-0.06816,34.33731,31.79869
117.97201,9.83095,657.86713,-0.06816,34.40379,31.81283
118.17201,9.84763,658.17395,-0.06816,34.47052,31.82767
118.37201,9.86425,658.10587,-0.06816,34.53700,31.82438
118.57201,9.88099,658.06191,-0.06816,34.60397,31.82225
118.77200,9.89767,658.34709,-0.06816,34.67069,31.83604
118.97201,9.91435,658.21791,-0.06816,34.73742,31.82980
119.17201,9.93103,658.80786,-0.06816,34.80414,31.85832
119.37201,9.94766,658.27733,-0.06816,34.87063,31.83267
119.57201,9.96434,658.55938,-0.06816,34.93736,31.84631
119.77200,9.98102,658.61256,-0.06816,35.00408,31.84888
119.97201,9.99770,658.57307,-0.06816,35.07080,31.84697
120.17201,10.01438,659.08777,-0.06816,35.13753,31.87186
120.37201,10.03100,658.61172,-0.06816,35.20401,31.84884
120.57201,10.04762,659.03617,-0.06816,35.27050,31.86937
120.77200,10.06437,658.85587,-0.06816,35.33747,31.86065
120.97201,10.08093,659.12409,-0.06816,35.40371,31.87362
121.17201,10.09761,659.61340,-0.06816,35.47044,31.89728
121.37201,10.11435,659.13768,-0.06816,35.53740,31.87428
121.57201,10.13103,659.50770,-0.06816,35.60413,31.89217
121.77200,10.14765,659.47468,-0.06816,35.67061,31.89057
121.97201,10.16433,659.71664,-0.06816,35.73734,31.90227
122.17201,10.18101,659.98998,-0.06816,35.80407,31.91549
122.37201,10.19764,659.88088,-0.06816,35.87055,31.91021
122.57201,10.21432,659.31077,-0.06816,35.93728,31.88264
122.77200,10.23106,659.87073,-0.06816,36.00424,31.90972
122.97201,10.24762,660.30114,-0.06816,36.07048,31.93054
123.17201,10.26436,660.00163,-0.06816,36.13745,31.91605
123.37201,10.28098,660.29048,-0.06816,36.20394,31.93002
123.57201,10.29766,660.34617,-0.06816,36.27066,31.93271
123.77200,10.31435,660.20875,-0.06816,36.33739,31.92607
123.97201,10.33097,660.25010,-0.06816,36.40387,31.92807
124.17201,10.34765,660.35474,-0.06816,36.47060,31.93313
124.37201,10.36433,660.85570,-0.06816,36.53732,31.95735
124.57201,10.38095,660.55167,-0.06816,36.60381,31.94265
124.77200,10.39769,660.96731,-0.06816,36.67077,31.96275
124.97201,10.41437,660.41723,-0.06816,36.73750,31.93615
125.17201,10.43094,660.76396,-0.06816,36.80375,31.95292
125.37201,10.44762,660.32223,-0.06816,36.87047,31.93156
125.57201,10.46430,661.03134,-0.06816,36.93719,31.96585
125.77200,10.48098,661.03595,-0.06816,37.00392,31.96607
125.97201,10.49766,660.94059,-0.06816,37.07064,31.96146
126.17201,10.51434,661.42851,-0.06816,37.13737,31.98505
126.37201,10.53096,661.28932,-0.06816,37.20386,31.97832
126.57201,10.54758,661.68089,-0.06816,37.27034,31.99726
126.77200,10.56438,661.37649,-0.06816,37.33754,31.98254
126.97201,10.58101,660.92811,-0.06816,37.40403,31.96086
127.17201,10.59769,661.49514,-0.06816,37.47075,31.98828
127.37201,10.61443,662.12774,-0.06816,37.53772,32.01887
127.57201,10.63099,661.91615,-0.06816,37.60397,32.00863
127.77200,10.64761,661.88541,-0.06816,37.67045,32.00715
127.97201,10.66441,661.86916,-0.06816,37.73766,32.00636
128.17202,10.68103,661.83414,-0.06816,37.80414,32.00467
128.37201,10.69766,662.32588,-0.06816,37.87063,32.02845
128.57201,10.71428,662.33529,-0.06816,37.93711,32.02890
128.77200,10.73102,662.52737,-0.06816,38.00408,32.03819
128.97200,10.74770,662.49380,-0.06816,38.07080,32.03657
129.17202,10.76426,661.69002,-0.06816,38.13705,31.99770
129.37201,10.78100,662.32057,-0.06816,38.20401,32.02819
129.57201,10.79756,662.62614,-0.06816,38.27026,32.04297
129.77200,10.81430,662.28071,-0.06816,38.33722,32.02626
129.97200,10.83105,662.24257,-0.06816,38.40419,32.02442
130.17202,10.84773,661.65850,-0.06816,38.47091,31.99617
130.37201,10.86435,662.05137,-0.06816,38.53740,32.01517
130.57201,10.88097,662.90712,-0.06816,38.60389,32.05656
130.77200,10.89765,661.92406,-0.06816,38.67061,32.00902
130.97200,10.91427,661.78902,-0.06816,38.73710,32.00249
131.17202,10.93101,661.75819,-0.06816,38.80406,32.00100
131.37202,10.94764,661.77077,-0.06816,38.87055,32.00160
131.57200,10.96420,662.37748,-0.06816,38.93679,32.03094
131.77200,10.98094,662.10991,-0.06816,39.00375,32.01801
131.97200,10.99768,661.73677,-0.06816,39.07072,31.99996
132.17202,11.01436,662.10851,-0.06816,39.13744,32.01794
132.37202,11.03104,662.23545,-0.06816,39.20417,32.02407
132.57200,11.04766,662.33492,-0.06816,39.27066,32.02888
132.77200,11.06434,662.29156,-0.06816,39.33738,32.02679
132.97200,11.08097,661.90059,-0.06816,39.40387,32.00788
133.17202,11.09765,661.60308,-0.06816,39.47059,31.99350
133.37202,11.11445,661.65840,-0.06816,39.53780,31.99617
133.57200,11.13101,661.54278,-0.06816,39.60405,31.99058
133.77200,11.14763,661.59251,-0.06816,39.67053,31.99298
133.97200,11.16437,661.97999,-0.06816,39.73749,32.01172
134.17202,11.18093,661.84979,-0.06816,39.80374,32.00542
134.37202,11.19761,661.93053,-0.06816,39.87046,32.00933
134.57200,11.21442,661.76401,-0.06816,39.93767,32.00128
134.77200,11.23104,661.49090,-0.06816,40.00416,31.98807
134.97200,11.24760,662.05636,-0.06816,40.07040,32.01542
135.17202,11.26434,662.12853,-0.06816,40.13737,32.01891
135.37202,11.28108,661.96332,-0.06816,40.20433,32.01091
135.57200,11.29764,662.44756,-0.06816,40.27058,32.03433
135.77200,11.31426,661.69323,-0.06816,40.33706,31.99785
135.97200,11.33107,661.97370,-0.06816,40.40427,32.01142
136.17202,11.34769,662.53012,-0.06816,40.47076,32.03832
136.37202,11.36431,662.71634,-0.06816,40.53724,32.04733
136.57200,11.38105,662.33720,-0.06816,40.60420,32.02900
136.77200,11.39767,662.33473,-0.06816,40.67069,32.02888
136.97200,11.41423,662.79946,-0.06816,40.73693,32.05135
137.17202,11.43097,662.49934,-0.06816,40.80390,32.03683
137.37202,11.44771,662.64309,-0.06816,40.87086,32.04379
137.57200,11.46434,662.77883,-0.06816,40.93735,32.05035
137.77200,11.48102,662.84752,-0.06816,41.00408,32.05367
137.97200,11.49770,662.70651,-0.06816,41.07080,32.04686
138.17202,11.51426,663.56864,-0.06816,41.13705,32.08854
138.37202,11.53088,663.42200,-0.06816,41.20353,32.08146
138.57200,11.54768,662.92705,-0.06816,41.27074,32.05752
138.77200,11.56436,662.86460,-0.06816,41.33746,32.05450
138.97200,11.58093,663.49208,-0.06816,41.40371,32.08484
139.17202,11.59761,663.43234,-0.06816,41.47044,32.08195
139.37202,11.61429,663.56780,-0.06816,41.53716,32.08850
139.57200,11.63097,663.25301,-0.06816,41.60388,32.07328
139.77200,11.64771,663.45008,-0.06816,41.67085,32.08281
139.97200,11.66439,663.25548,-0.06816,41.73757,32.07340
140.17202,11.68095,662.83033,-0.06816,41.80382,32.05284
140.37202,11.69764,663.73381,-0.06816,41.87055,32.09653
140.57200,11.71438,663.84133,-0.06816,41.93751,32.10173
140.77200,11.73106,663.25730,-0.06816,42.00423,32.07349
140.97200,11.74762,664.52241,-0.06816,42.07048,32.13467
141.17202,11.76430,663.78056,-0.06816,42.13720,32.09879
141.37202,11.78098,664.14778,-0.06816,42.20393,32.11655
141.57200,11.79760,664.24864,-0.06816,42.27042,32.12143
141.77200,11.81434,664.23123,-0.06816,42.33738,32.12059
141.97200,11.83114,664.33144,-0.06816,42.40459,32.12543
142.17202,11.84759,664.73312,-0.06816,42.47035,32.14486
142.37202,11.86427,664.68031,-0.06816,42.53708,32.14230
142.57200,11.88113,664.36701,-0.06816,42.60452,32.12715
142.77200,11.89769,664.19733,-0.06816,42.67077,32.11895
142.97200,11.91425,664.71053,-0.06816,42.73701,32.14376
143.17202,11.93105,664.85270,-0.06816,42.80421,32.15064
143.37202,11.94767,664.61097,-0.06816,42.87070,32.13895
143.57200,11.96430,664.21679,-0.06816,42.93719,32.11989
143.77200,11.98098,664.74685,-0.06816,43.00391,32.14552
143.97200,11.99772,665.39464,-0.06816,43.07088,32.17685
144.17202,12.01428,665.47692,-0.06816,43.13713,32.18082
144.37202,12.03090,665.12334,-0.06816,43.20361,32.16373
144.57200,12.04770,665.29000,-0.06816,43.27081,32.17179
144.77200,12.06432,665.41382,-0.06816,43.33730,32.17777
144.97200,12.08100,665.07766,-0.06816,43.40402,32.16152
145.17202,12.09775,665.05778,-0.06816,43.47099,32.16056
145.37202,12.11431,665.27072,-0.06816,43.53724,32.17085
145.57200,12.13093,665.58393,-0.06816,43.60372,32.18600
145.77200,12.14767,664.80753,-0.06816,43.67069,32.14845
145.97200,12.16441,665.25768,-0.06816,43.73765,32.17022
146.17202,12.18109,665.64716,-0.06816,43.80438,32.18906
146.37202,12.19765,665.58039,-0.06816,43.87062,32.18583
146.57200,12.21439,665.45117,-0.06816,43.93758,32.17958
146.77200,12.23096,665.30784,-0.06816,44.00383,32.17265
146.97200,12.24764,666.34016,-0.06816,44.07056,32.22257
147.17202,12.26438,665.20944,-0.06816,44.13752,32.16789
147.37202,12.28100,665.79403,-0.06816,44.20401,32.19616
147.57200,12.29762,665.57918,-0.06816,44.27049,32.18577
147.77200,12.31430,665.51347,-0.06816,44.33722,32.18259
147.97200,12.33098,665.93075,-0.06816,44.40394,32.20277
148.17202,12.34767,665.67967,-0.06816,44.47067,32.19063
148.37202,12.36435,665.34113,-0.06816,44.53739,32.17426
148.57200,12.38103,666.22705,-0.06816,44.60412,32.21710
148.77200,12.39759,665.42248,-0.06816,44.67036,32.17819
148.97200,12.41433,665.64032,-0.06816,44.73733,32.18872
149.17202,12.43107,665.99129,-0.06816,44.80430,32.20570
149.37202,12.44763,666.16735,-0.06816,44.87054,32.21421
149.57200,12.46437,665.81839,-0.06816,44.93750,32.19734
149.77200,12.48100,666.10291,-0.06816,45.00399,32.21109
149.97200,12.49762,665.96186,-0.06816,45.07048,32.20427
150.17202,12.51430,665.57014,-0.06816,45.13720,32.18533
150.37202,12.53098,665.73652,-0.06816,45.20393,32.19338
150.57200,12.54772,665.18537,-0.06816,45.27089,32.16673
150.77200,12.56434,665.44292,-0.06816,45.33738,32.17918
150.97200,12.58096,664.96534,-0.06816,45.40386,32.15609
151.17202,12.59777,665.06146,-0.06816,45.47107,32.16073
151.37202,12.61433,665.18756,-0.06816,45.53731,32.16683
151.57200,12.63107,664.82318,-0.06816,45.60428,32.14921
151.77200,12.64769,664.69428,-0.06816,45.67077,32.14298
151.97200,12.66431,665.17447,-0.06816,45.73725,32.16620
152.17202,12.68093,665.24418,-0.06816,45.80373,32.16957
152.37202,12.69761,664.96590,-0.06816,45.87046,32.15611
152.57200,12.71429,664.94802,-0.06816,45.93718,32.15525
152.77200,12.73098,664.78439,-0.06816,46.00391,32.14734
152.97200,12.74760,665.11673,-0.06816,46.07040,32.16341
153.17202,12.76434,665.22951,-0.06816,46.13736,32.16886
153.37202,12.78096,665.22858,-0.06816,46.20385,32.16882
153.57200,12.79770,665.35710,-0.06816,46.27081,32.17503
153.77200,12.81438,664.42350,-0.06816,46.33754,32.12988
153.97200,12.83100,664.93126,-0.06816,46.40402,32.15444
154.17202,12.84769,664.99272,-0.06816,46.47075,32.15741
154.37202,12.86425,664.75384,-0.06816,46.53699,32.14586
154.57200,12.88105,664.98620,-0.06816,46.60420,32.15709
154.77200,12.89773,665.79129,-0.06816,46.67092,32.19603
154.97200,12.91429,665.20600,-0.06816,46.73717,32.16772
155.17202,12.93097,664.58308,-0.06816,46.80389,32.13760
155.37202,12.94759,665.18816,-0.06816,46.87038,32.16686
155.57200,12.96428,664.96809,-0.06816,46.93711,32.15622
155.77200,12.98108,665.14178,-0.06816,47.00431,32.16462
155.97200,12.99770,665.72493,-0.06816,47.07080,32.19282
156.17202,13.01432,665.05107,-0.06816,47.13728,32.16023
156.37202,13.03100,665.08087,-0.06816,47.20401,32.16167
156.57200,13.04768,665.34840,-0.06816,47.27073,32.17461
156.77200,13.06436,665.05582,-0.06816,47.33746,32.16046
156.97200,13.08104,664.82872,-0.06816,47.40418,32.14948
157.17202,13.09772,665.07212,-0.06816,47.47091,32.16125
157.37202,13.11429,664.61107,-0.06816,47.53715,32.13895
157.57200,13.13097,664.21004,-0.06816,47.60388,32.11956
157.77200,13.14771,664.92264,-0.06816,47.67084,32.15402
157.97200,13.16439,664.69256,-0.06816,47.73757,32.14289
158.17202,13.18101,664.53186,-0.06816,47.80405,32.13512
158.37202,13.19763,664.57116,-0.06816,47.87053,32.13702
158.57200,13.21431,664.62713,-0.06816,47.93727,32.13973
158.77200,13.23100,664.15789,-0.06816,48.00399,32.11704
158.97200,13.24768,664.00580,-0.06816,48.07071,32.10968
159.17202,13.26436,663.64664,-0.06816,48.13744,32.09232
159.37202,13.28098,663.35215,-0.06816,48.20393,32.07808
159.57200,13.29760,663.21446,-0.06816,48.27041,32.07142
159.77200,13.31428,663.29683,-0.06816,48.33714,32.07540
159.97200,13.33102,662.99355,-0.06816,48.40410,32.06073
160.17202,13.34765,662.42046,-0.06816,48.47059,32.03302
160.37202,13.36433,662.07508,-0.06816,48.53731,32.01632
160.57200,13.38095,662.29193,-0.06816,48.60380,32.02681
160.77200,13.39763,661.96220,-0.06816,48.67052,32.01086
160.97200,13.41431,661.82013,-0.06816,48.73725,32.00399
161.17202,13.43099,661.72057,-0.06816,48.80397,31.99918
161.37202,13.44767,661.62962,-0.06816,48.87070,31.99478
161.57200,13.46435,661.15605,-0.06816,48.93742,31.97188
161.77200,13.48098,661.35260,-0.06816,49.00391,31.98138
161.97200,13.49760,661.83382,-0.06816,49.07040,32.00465
162.17202,13.51434,660.48261,-0.06816,49.13736,31.93931
162.37202,13.53108,660.29648,-0.06816,49.20432,31.93031
162.57200,13.54758,660.37448,-0.06816,49.27033,31.93408
162.77200,13.56432,659.84563,-0.06816,49.33729,31.90851
162.97200,13.58106,659.95506,-0.06816,49.40426,31.91380
163.17202,13.59768,659.59399,-0.06816,49.47074,31.89634
163.37202,13.61437,658.60269,-0.06816,49.53747,31.84840
163.57200,13.63105,659.14434,-0.06816,49.60419,31.87460
163.77200,13.64767,658.84902,-0.06816,49.67068,31.86032
163.97202,13.66429,657.89605,-0.06816,49.73717,31.81423
164.17202,13.68097,657.81693,-0.06816,49.80389,31.81041
164.37202,13.69777,657.93884,-0.06816,49.87110,31.81630
164.57200,13.71433,657.75588,-0.06816,49.93735,31.80745
164.77200,13.73090,656.30125,-0.06816,50.00359,31.73711
164.97202,13.74770,655.92160,-0.06816,50.07079,31.71875
165.17202,13.76426,655.56532,-0.06816,50.13704,31.70152
165.37202,13.78094,655.26925,-0.06816,50.20376,31.68721
165.57200,13.79768,654.44750,-0.06816,50.27072,31.64747
165.77200,13.81430,654.21374,-0.06816,50.33722,31.63616
165.97202,13.83092,653.33904,-0.06816,50.40370,31.59387
166.17202,13.84760,652.70071,-0.06816,50.47042,31.56300
166.37202,13.86441,651.96073,-0.06816,50.53763,31.52721
166.57200,13.88103,650.78139,-0.06816,50.60412,31.47018
166.77200,13.89765,650.16625,-0.06816,50.67060,31.44044
166.97202,13.91433,649.48997,-0.06816,50.73733,31.40774
167.17202,13.93089,647.56740,-0.06816,50.80357,31.31476
167.37202,13.94769,646.63817,-0.06816,50.87077,31.26983
167.57200,13.96443,644.59485,-0.06816,50.93774,31.17102
167.77200,13.98106,642.91637,-0.06816,51.00423,31.08985
167.97202,13.99762,640.29433,-0.06816,51.07047,30.96306
168.17202,14.01430,638.23592,-0.06816,51.13720,30.86352
168.37202,14.03098,635.99087,-0.06816,51.20392,30.75495
168.57200,14.04766,633.78825,-0.06816,51.27065,30.64844
168.77200,14.06434,630.32219,-0.06816,51.33737,30.48083
168.97202,14.08108,627.34359,-0.06816,51.40434,30.33679
169.17202,14.09764,622.20176,-0.06816,51.47058,30.08814
169.37202,14.11427,616.72195,-0.06816,51.53707,29.82315
169.57200,14.13107,604.90817,-0.06816,51.60427,29.25187
169.77200,14.14769,577.41092,-0.06816,51.67076,27.92217
169.97202,14.16431,526.56899,-0.06816,51.73725,25.46358
170.17202,14.18099,442.99969,-0.06816,51.80397,21.42237
170.37202,14.19773,333.82250,-0.06816,51.87094,16.14283
170.56802,14.21393,8.16571,-0.06816,51.93574,0.39487