File: Manufatura Aditiva/Dados/Ensaios AMR/Ensaios/Ensaios FDM/Tracao_OLABI_18_03_2019_FDM_45.is_metal_RawData/Specimen_RawData_5.csv
Time,Extension,Load,Strain 1,Tensile strain,Tensile stress
(sec),(mm),(N),(mm/mm),(%),(MPa)
0.00000,0.00000,14.60663,0.00041,0.04101,0.70855
0.10000,0.00407,15.47316,0.00044,0.04395,0.75059
0.20000,0.01375,18.83574,0.00057,0.05682,0.91370
0.30000,0.02344,22.93877,0.00070,0.06979,1.11274
0.40000,0.03265,26.94678,0.00082,0.08222,1.30716
0.50000,0.04137,30.20796,0.00095,0.09491,1.46536
0.60000,0.04992,34.01419,0.00107,0.10681,1.64999
0.70000,0.05829,37.17930,0.00118,0.11827,1.80353
0.80000,0.06667,40.76874,0.00130,0.13026,1.97765
0.90000,0.07498,43.88906,0.00142,0.14218,2.12901
1.00000,0.08335,46.82319,0.00154,0.15406,2.27134
1.10000,0.09172,50.33871,0.00166,0.16603,2.44188
1.20000,0.09997,54.39443,0.00178,0.17800,2.63862
1.30000,0.10840,57.35350,0.00190,0.19001,2.78216
1.40000,0.11665,60.89960,0.00202,0.20196,2.95417
1.50000,0.12496,63.68322,0.00214,0.21389,3.08920
1.60000,0.13339,67.33381,0.00227,0.22689,3.26629
1.70000,0.14164,70.64376,0.00239,0.23881,3.42685
1.80000,0.14995,73.78902,0.00250,0.25049,3.57943
1.90000,0.15838,77.55734,0.00264,0.26364,3.76222
2.00000,0.16663,80.58712,0.00275,0.27539,3.90919
2.10000,0.17500,83.68372,0.00288,0.28792,4.05941
2.20000,0.18337,87.34640,0.00301,0.30059,4.23708
2.30000,0.19169,90.13313,0.00313,0.31269,4.37226
2.40000,0.20000,93.90766,0.00325,0.32550,4.55536
2.50000,0.20837,96.62520,0.00338,0.33780,4.68719
2.60000,0.21674,100.64454,0.00351,0.35088,4.88216
2.70000,0.22499,103.00634,0.00363,0.36300,4.99673
2.80000,0.23336,106.57604,0.00376,0.37599,5.16989
2.90000,0.24173,109.44841,0.00389,0.38871,5.30923
3.00000,0.25004,112.76248,0.00401,0.40086,5.46999
3.10000,0.25835,116.13999,0.00414,0.41396,5.63383
3.20000,0.26672,119.26854,0.00427,0.42652,5.78559
3.30000,0.27503,122.94308,0.00439,0.43934,5.96384
3.40000,0.28334,126.04053,0.00452,0.45213,6.11409
3.50000,0.29165,128.89554,0.00465,0.46470,6.25258
3.60000,0.29996,132.24601,0.00478,0.47811,6.41511
3.70000,0.30821,135.34048,0.00490,0.49050,6.56522
3.80000,0.31659,138.59821,0.00504,0.50356,6.72325
3.90000,0.32502,141.36586,0.00516,0.51620,6.85751
4.00000,0.33333,145.49930,0.00529,0.52930,7.05802
4.10000,0.34164,148.50385,0.00543,0.54257,7.20376
4.20000,0.35001,151.08524,0.00555,0.55520,7.32898
4.30000,0.35820,154.31048,0.00568,0.56800,7.48544
4.40000,0.36657,158.48632,0.00581,0.58112,7.68800
4.50000,0.37500,161.16941,0.00594,0.59436,7.81816
4.60000,0.38337,164.11697,0.00607,0.60739,7.96114
4.70000,0.39168,167.92513,0.00620,0.62048,8.14587
4.80000,0.40005,171.19233,0.00634,0.63375,8.30436
4.90000,0.40836,174.09074,0.00647,0.64680,8.44496
5.00000,0.41667,176.47203,0.00660,0.65979,8.56047
5.10000,0.42510,180.32014,0.00673,0.67313,8.74714
5.20000,0.43341,183.22098,0.00686,0.68574,8.88785
5.30000,0.44172,186.91634,0.00700,0.69968,9.06711
5.40000,0.45004,190.50288,0.00713,0.71254,9.24109
5.50000,0.45829,193.02298,0.00726,0.72600,9.36334
5.60000,0.46672,196.35162,0.00740,0.73951,9.52481
5.70000,0.47491,199.56178,0.00752,0.75218,9.68053
5.80000,0.48328,202.95165,0.00766,0.76580,9.84497
5.90000,0.49171,206.08881,0.00779,0.77927,9.99715
6.00000,0.49996,208.47195,0.00792,0.79244,10.11275
6.10000,0.50827,211.72555,0.00806,0.80617,10.27058
6.20000,0.51670,215.17291,0.00820,0.81976,10.43781
6.30000,0.52501,218.99228,0.00833,0.83346,10.62308
6.40000,0.53332,221.64378,0.00847,0.84694,10.75170
6.50000,0.54169,224.38511,0.00860,0.86021,10.88468
6.60000,0.54994,227.55330,0.00873,0.87339,11.03837
6.70000,0.55825,230.79375,0.00887,0.88665,11.19556
6.80000,0.56674,234.19322,0.00900,0.90041,11.36046
6.90000,0.57500,236.95247,0.00914,0.91403,11.49431
7.00000,0.58337,240.45517,0.00927,0.92734,11.66422
7.10000,0.59174,243.40297,0.00941,0.94073,11.80722
7.20000,0.59993,246.87825,0.00954,0.95444,11.97580
7.30000,0.60830,249.56295,0.00967,0.96745,12.10603
7.40000,0.61667,252.66423,0.00982,0.98177,12.25647
7.50000,0.62492,255.77329,0.00995,0.99450,12.40729
7.60000,0.63335,258.64381,0.01008,1.00826,12.54653
7.70000,0.64166,262.03664,0.01022,1.02186,12.71112
7.80000,0.64991,265.30528,0.01035,1.03530,12.86968
7.90000,0.65840,268.12225,0.01049,1.04897,13.00632
8.00000,0.66665,271.56877,0.01062,1.06232,13.17351
8.10000,0.67490,274.17373,0.01076,1.07613,13.29987
8.20000,0.68345,277.67243,0.01090,1.08982,13.46959
8.30000,0.69170,280.39508,0.01104,1.10368,13.60167
8.40000,0.70002,283.15161,0.01117,1.11723,13.73538
8.50000,0.70845,287.47451,0.01132,1.13204,13.94508
8.60000,0.71664,289.40488,0.01145,1.14533,14.03872
8.70000,0.72495,292.45166,0.01159,1.15896,14.18652
8.80000,0.73338,295.48132,0.01173,1.17276,14.33348
8.90000,0.74157,298.54442,0.01186,1.18613,14.48207
9.00000,0.75000,301.97734,0.01200,1.20007,14.64860
9.10000,0.75837,303.99519,0.01214,1.21395,14.74648
9.20000,0.76662,307.45592,0.01226,1.22642,14.91436
9.30000,0.77499,309.84320,0.01240,1.24007,15.03016
9.40000,0.78336,313.14958,0.01254,1.25377,15.19055
9.50000,0.79161,315.56387,0.01268,1.26768,15.30767
9.60000,0.79998,319.80227,0.01281,1.28134,15.51327
9.70000,0.80829,321.95707,0.01295,1.29521,15.61779
9.80000,0.81660,324.32610,0.01308,1.30843,15.73271
9.90000,0.82504,328.29060,0.01323,1.32258,15.92503
10.00000,0.83329,330.36827,0.01336,1.33630,16.02581
10.10000,0.84160,333.63407,0.01350,1.35021,16.18423
10.20000,0.85003,336.28207,0.01363,1.36336,16.31268
10.30000,0.85834,339.78180,0.01377,1.37744,16.48245
10.40000,0.86665,342.24014,0.01391,1.39150,16.60170
10.50000,0.87514,345.19809,0.01406,1.40589,16.74519
10.60000,0.88333,348.03364,0.01419,1.41949,16.88274
10.70000,0.89158,350.96270,0.01434,1.43365,17.02482
10.80000,0.90007,353.67217,0.01448,1.44751,17.15626
10.90000,0.90832,356.88023,0.01462,1.46153,17.31188
11.00000,0.91663,359.34495,0.01475,1.47516,17.43144
11.10000,0.92506,362.23638,0.01489,1.48899,17.57170
11.20000,0.93331,364.92448,0.01503,1.50304,17.70210
11.30000,0.94168,368.07470,0.01517,1.51701,17.85491
11.40000,0.95000,371.24695,0.01531,1.53087,18.00879
11.50000,0.95831,374.28052,0.01545,1.54473,18.15595
11.60000,0.96662,377.17351,0.01559,1.55858,18.29628
11.70000,0.97499,379.11015,0.01572,1.57240,18.39023
11.80000,0.98330,381.89718,0.01587,1.58666,18.52542
11.90000,0.99161,385.25301,0.01601,1.60059,18.68821
12.00000,0.99992,387.95734,0.01615,1.61479,18.81940
12.10000,1.00823,390.57699,0.01628,1.62806,18.94647
12.20000,1.01666,393.40830,0.01642,1.64196,19.08382
12.30000,1.02497,396.82160,0.01657,1.65652,19.24939
12.40000,1.03328,399.10250,0.01670,1.67017,19.36003
12.50000,1.04177,402.81769,0.01684,1.68448,19.54025
12.60000,1.05002,405.44923,0.01698,1.69829,19.66791
12.70000,1.05839,408.78807,0.01712,1.71248,19.82987
12.80000,1.06676,410.88122,0.01724,1.72352,19.93141
12.90000,1.07496,413.76497,0.01738,1.73783,20.07130
13.00000,1.08333,416.83624,0.01752,1.75185,20.22028
13.10000,1.09170,418.89991,0.01766,1.76585,20.32039
13.20000,1.09989,422.82371,0.01780,1.78019,20.51073
13.30000,1.10832,424.99718,0.01794,1.79403,20.61616
13.40000,1.11669,428.12251,0.01809,1.80861,20.76777
13.50000,1.12500,430.43904,0.01823,1.82264,20.88014
13.60000,1.13331,433.25019,0.01836,1.83623,21.01650
13.70000,1.14168,435.67847,0.01851,1.85061,21.13430
13.80000,1.14993,439.10407,0.01865,1.86521,21.30047
13.90000,1.15830,440.89714,0.01879,1.87876,21.38745
14.00000,1.16667,444.39374,0.01894,1.89364,21.55707
14.10000,1.17492,446.51437,0.01908,1.90762,21.65993
14.20000,1.18335,449.11262,0.01921,1.92106,21.78597
14.30000,1.19166,450.87710,0.01931,1.93077,21.87156
14.40000,1.19992,453.98790,0.01945,1.94503,22.02247
14.50000,1.20841,456.34639,0.01959,1.95946,22.13688
14.60000,1.21666,459.11763,0.01974,1.97387,22.27131
14.70000,1.22497,461.89013,0.01988,1.98775,22.40580
14.80000,1.23346,464.79627,0.02002,2.00180,22.54677
14.90000,1.24171,467.61418,0.02016,2.01632,22.68346
15.00000,1.24996,469.72469,0.02031,2.03058,22.78584
15.10000,1.25839,472.13850,0.02045,2.04486,22.90293
15.20000,1.26658,475.49028,0.02059,2.05935,23.06553
15.30000,1.27495,478.29091,0.02073,2.07330,23.20138
15.40000,1.28338,480.54112,0.02088,2.08800,23.31054
15.50000,1.29169,482.86803,0.02102,2.10230,23.42341
15.60000,1.29994,485.51406,0.02116,2.11609,23.55177
15.70000,1.30831,488.82389,0.02131,2.13136,23.71232
15.80000,1.31662,490.80057,0.02145,2.14512,23.80821
15.90000,1.32505,493.29465,0.02160,2.15988,23.92920
16.00000,1.33337,495.10002,0.02174,2.17428,24.01677
16.10000,1.34162,498.22046,0.02188,2.18846,24.16814
16.20000,1.35005,501.41774,0.02203,2.20286,24.32324
16.30000,1.35836,503.41925,0.02218,2.21760,24.42033
16.40000,1.36661,506.00967,0.02232,2.23212,24.54599
16.50000,1.37504,508.63577,0.02247,2.24672,24.67338
16.60000,1.38329,510.58857,0.02261,2.26121,24.76810
16.70000,1.39166,513.59804,0.02275,2.27547,24.91409
16.80000,1.40009,516.02866,0.02290,2.29039,25.03200
16.90000,1.40834,518.25200,0.02305,2.30500,25.13985
17.00000,1.41665,521.43969,0.02319,2.31916,25.29448
17.10000,1.42496,523.46732,0.02334,2.33371,25.39284
17.20000,1.43321,526.27441,0.02348,2.34845,25.52901
17.30000,1.44158,528.42144,0.02363,2.36303,25.63316
17.40000,1.45001,530.60693,0.02378,2.37763,25.73917
17.50000,1.45827,533.83568,0.02392,2.39209,25.89580
17.60000,1.46664,535.77451,0.02407,2.40663,25.98985
17.70000,1.47501,537.87781,0.02422,2.42157,26.09188
17.80000,1.48332,540.55527,0.02436,2.43619,26.22176
17.90000,1.49169,542.16571,0.02451,2.45106,26.29988
18.00000,1.50006,544.95763,0.02466,2.46563,26.43531
18.10000,1.50837,547.15928,0.02480,2.48015,26.54211
18.20000,1.51668,549.24237,0.02495,2.49533,26.64316
18.30000,1.52505,552.47550,0.02510,2.50994,26.80000
18.40000,1.53336,553.83788,0.02525,2.52511,26.86608
18.50000,1.54173,556.42445,0.02539,2.53932,26.99155
18.60000,1.54998,558.56900,0.02554,2.55433,27.09558
18.70000,1.55829,561.17065,0.02569,2.56893,27.22179
18.80000,1.56672,563.86390,0.02584,2.58383,27.35243
18.90000,1.57497,566.17269,0.02599,2.59883,27.46443
19.00000,1.58341,567.89792,0.02614,2.61356,27.54812
19.10000,1.59172,570.80709,0.02629,2.62902,27.68924
19.20000,1.59997,573.31151,0.02643,2.64318,27.81073
19.30000,1.60828,575.33542,0.02658,2.65850,27.90891
19.40000,1.61665,577.37529,0.02673,2.67308,28.00786
19.50000,1.62496,580.19832,0.02688,2.68799,28.14480
19.60000,1.63327,582.21589,0.02703,2.70295,28.24267
19.70000,1.64170,584.53833,0.02719,2.71861,28.35533
19.80000,1.64995,586.77867,0.02733,2.73304,28.46401
19.90000,1.65832,589.20295,0.02748,2.74815,28.58160
20.00000,1.66669,591.17093,0.02763,2.76310,28.67707
20.10000,1.67500,593.12508,0.02778,2.77767,28.77186
20.20000,1.68337,595.35755,0.02793,2.79319,28.88016
20.30000,1.69168,597.28357,0.02808,2.80808,28.97359
20.40000,1.69999,599.74813,0.02823,2.82253,29.09314
20.50000,1.70831,601.49692,0.02838,2.83757,29.17797
20.60000,1.71668,603.67128,0.02853,2.85283,29.28345
20.70000,1.72499,606.31889,0.02868,2.86785,29.41188
20.80000,1.73336,608.73902,0.02883,2.88338,29.52928
20.90000,1.74167,610.01154,0.02898,2.89846,29.59101
21.00000,1.74998,612.25207,0.02914,2.91404,29.69969
21.10000,1.75841,614.25366,0.02929,2.92892,29.79679
21.20000,1.76672,617.09387,0.02944,2.94436,29.93456
21.30000,1.77497,618.61845,0.02960,2.95984,30.00852
21.40000,1.78340,621.15556,0.02975,2.97533,30.13159
21.50000,1.79165,622.93042,0.02990,2.99045,30.21769
21.60000,1.79996,624.94525,0.03006,3.00567,30.31543
21.70000,1.80833,626.63397,0.03022,3.02158,30.39734
21.80000,1.81664,628.95403,0.03037,3.03706,30.50989
21.90000,1.82501,630.97696,0.03052,3.05225,30.60802
22.00000,1.83339,633.61018,0.03068,3.06766,30.73575
22.10000,1.84164,634.70844,0.03083,3.10066,30.78903
22.20000,1.84995,637.62073,0.03099,3.13391,30.93030
22.24400,1.85371,637.96425,0.03106,3.14897,30.94696
22.34400,1.86202,640.21810,0.03121,3.18222,31.05630
22.44400,1.87033,642.06286,0.03137,3.21546,31.14578
22.54400,1.87871,643.47871,0.03152,3.24894,31.21446
22.64400,1.88696,645.81572,0.03168,3.28194,31.32783
22.74400,1.89527,648.15390,0.03183,3.31519,31.44125
22.84400,1.90370,649.97603,0.03199,3.34891,31.52964
22.94400,1.91195,652.18462,0.03215,3.38191,31.63678
23.04400,1.92026,654.04214,0.03231,3.41516,31.72688
23.14400,1.92875,655.63964,0.03247,3.44912,31.80438
23.24400,1.93700,658.03332,0.03263,3.48212,31.92049
23.34400,1.94531,659.62416,0.03274,3.51536,31.99766
23.44400,1.95374,661.87060,0.03264,3.54908,32.10664
23.54400,1.96199,663.14512,0.03249,3.58209,32.16846
23.64400,1.97030,665.54127,0.03210,3.61533,32.28469
23.74400,1.97867,667.99773,0.02232,3.64881,32.40385
23.84400,1.98698,668.27191,0.00217,3.68206,32.41716
23.94400,1.99535,669.97088,0.00367,3.71554,32.49957
24.04400,2.00367,672.16298,0.00399,3.74878,32.60591
24.14400,2.01204,674.17175,0.00427,3.78226,32.70335
24.24400,2.02035,675.52803,0.00266,3.81551,32.76914
24.34400,2.02866,676.86173,0.00226,3.84875,32.83384
24.44400,2.03703,679.02170,0.00453,3.88223,32.93862
24.54400,2.04534,681.33981,0.00395,3.91547,33.05106
24.64400,2.05365,682.61088,0.00285,3.94872,33.11272
24.74400,2.06190,683.84670,0.00362,3.98172,33.17267
24.84400,2.07027,686.20760,0.00412,4.01520,33.28720
24.94400,2.07858,687.24956,0.00621,4.04845,33.33774
25.04400,2.08689,688.84525,0.00571,4.08169,33.41515
25.14400,2.09532,691.52634,0.00585,4.11541,33.54520
25.24400,2.10363,692.67089,0.00625,4.14865,33.60072
25.34400,2.11200,694.08338,0.00740,4.18213,33.66924
25.44400,2.12037,695.48809,0.00749,4.21562,33.73738
25.54400,2.12874,697.09541,0.00747,4.24910,33.81535
25.64400,2.13706,698.67214,0.00876,4.28234,33.89184
25.74400,2.14531,700.03616,-0.00046,4.31535,33.95800
25.84400,2.15368,701.51244,-0.01257,4.34883,34.02962
25.94400,2.16205,703.89663,-0.01573,4.38231,34.14527
26.04400,2.17036,705.24779,-0.03089,4.41555,34.21082
26.14400,2.17873,706.82094,-0.04739,4.44904,34.28713
26.24400,2.18704,707.44189,-0.05199,4.48228,34.31725
26.34400,2.19535,708.13927,-0.05443,4.51552,34.35108
26.44400,2.20378,710.08569,-0.05624,4.54924,34.44550
26.54400,2.21209,711.33296,-0.05461,4.58249,34.50600
26.64400,2.22034,713.03593,-0.05364,4.61549,34.58861
26.74400,2.22871,714.22337,-0.05494,4.64897,34.64621
26.84400,2.23702,715.62422,-0.05553,4.68221,34.71416
26.94400,2.24533,717.28411,-0.05421,4.71546,34.79469
27.04400,2.25359,718.43504,-0.05421,4.74846,34.85051
27.14400,2.26196,720.01005,-0.05514,4.78194,34.92692
27.24400,2.27027,721.89509,-0.05502,4.81519,35.01836
27.34400,2.27864,722.78390,-0.05427,4.84867,35.06147
27.44400,2.28701,723.59396,-0.05457,4.88215,35.10077
27.54400,2.29532,725.41418,-0.05513,4.91539,35.18907
27.64400,2.30357,727.32954,-0.05470,4.94840,35.28198
27.74400,2.31200,727.94133,-0.05446,4.98212,35.31165
27.84400,2.32025,729.10050,-0.05486,5.01512,35.36789
27.94400,2.32862,730.85129,-0.05495,5.04860,35.45282
28.04400,2.33699,731.76315,-0.05459,5.08209,35.49705
28.14400,2.34530,732.90579,-0.05461,5.11533,35.55247
28.24400,2.35367,734.11902,-0.05486,5.14881,35.61133
28.34400,2.36198,735.40388,-0.05476,5.18205,35.67366
28.44400,2.37035,736.44882,-0.05459,5.21554,35.72435
28.54400,2.37873,737.54340,-0.05473,5.24902,35.77744
28.64400,2.38704,739.22342,-0.05482,5.28226,35.85894
28.74400,2.39535,740.30231,-0.05467,5.31550,35.91127
28.84400,2.40372,741.59876,-0.05467,5.34899,35.97416
28.94400,2.41197,742.76836,-0.05479,5.38199,36.03090
29.04400,2.42034,743.97451,-0.05476,5.41547,36.08941
29.14400,2.42871,744.76320,-0.05467,5.44895,36.12767
29.24400,2.43696,745.70128,-0.05473,5.48196,36.17317
29.34400,2.44533,746.74012,-0.05479,5.51544,36.22356
29.44400,2.45370,747.77589,-0.05471,5.54892,36.27381
29.54400,2.46201,749.54676,-0.05467,5.58217,36.35971
29.64400,2.47032,749.57930,-0.05476,5.61541,36.36129
29.74400,2.47869,751.00083,-0.05475,5.64889,36.43025
29.84400,2.48700,752.18780,-0.05467,5.68213,36.48782
29.94400,2.49531,752.90422,-0.05471,5.71538,36.52258
30.04400,2.50368,752.92722,-0.05477,5.74886,36.52369
30.14400,2.51194,754.70312,-0.05470,5.78186,36.60984
30.24400,2.52031,755.66252,-0.05469,5.81534,36.65638
30.34400,2.52868,756.87151,-0.05474,5.84883,36.71503
30.44400,2.53699,757.15338,-0.05476,5.88207,36.72870
30.54400,2.54530,758.65821,-0.05472,5.91531,36.80170
30.64400,2.55361,759.66781,-0.05470,5.94856,36.85067
30.74400,2.56192,760.31862,-0.05477,5.98180,36.88224
30.84400,2.57035,760.79904,-0.05475,6.01552,36.90555
30.94400,2.57866,761.73441,-0.05469,6.04876,36.95092
31.04400,2.58703,762.05223,-0.05474,6.08225,36.96634
31.14400,2.59534,763.27920,-0.05476,6.11549,37.02586
31.24400,2.60359,764.42491,-0.05470,6.14849,37.08144
31.34400,2.61196,764.84317,-0.05472,6.18197,37.10172
31.44400,2.62033,765.64187,-0.05475,6.21546,37.14047
31.54400,2.62864,766.03740,-0.05473,6.24870,37.15966
31.64400,2.63696,766.70013,-0.05472,6.28194,37.19180
31.74400,2.64539,766.95876,-0.05473,6.31566,37.20435
31.84400,2.65370,768.39724,-0.05476,6.34891,37.27413
31.94400,2.66201,768.85591,-0.05473,6.38215,37.29638
32.04400,2.67038,769.29657,-0.05472,6.41563,37.31775
32.14400,2.67869,769.62602,-0.05475,6.44887,37.33374
32.24400,2.68700,770.55097,-0.05476,6.48212,37.37860
32.34400,2.69531,771.03167,-0.05471,6.51536,37.40192
32.44400,2.70368,771.19386,-0.05474,6.54884,37.40979
32.54400,2.71199,772.31890,-0.05477,6.58209,37.46436
32.64400,2.72030,772.59899,-0.05471,6.61533,37.47795
32.74400,2.72867,772.33715,-0.05474,6.64881,37.46525
32.84400,2.73704,773.20710,-0.05477,6.68229,37.50745
32.94400,2.74529,773.53590,-0.05474,6.71530,37.52340
33.04400,2.75366,774.24482,-0.05473,6.74878,37.55779
33.14400,2.76198,774.74103,-0.05476,6.78202,37.58186
33.24400,2.77029,774.75365,-0.05476,6.81526,37.58247
33.34400,2.77860,775.09750,-0.05474,6.84851,37.59915
33.44400,2.78697,775.89629,-0.05476,6.88199,37.63790
33.54400,2.79534,776.16880,-0.05478,6.91547,37.65112
33.64400,2.80365,775.87445,-0.05477,6.94871,37.63684
33.74400,2.81202,776.56172,-0.05476,6.98220,37.67018
33.84400,2.82039,776.66454,-0.05476,7.01568,37.67517
33.94400,2.82876,776.49495,-0.05478,7.04916,37.66694
34.04400,2.83713,776.94026,-0.05477,7.08264,37.68854
34.14400,2.84532,777.14361,-0.05478,7.11541,37.69841
34.24400,2.85363,777.38208,-0.05479,7.14865,37.70997
34.34400,2.86206,777.84788,-0.05480,7.18237,37.73257
34.44400,2.87031,777.44541,-0.05480,7.21538,37.71304
34.54400,2.87862,778.48942,-0.05479,7.24862,37.76369
34.64400,2.88700,777.53821,-0.05480,7.28210,37.71755
34.74400,2.89519,778.40588,-0.05485,7.31486,37.75964
34.84400,2.90368,778.11605,-0.05485,7.34883,37.74558
34.94400,2.91205,778.22851,-0.05482,7.38231,37.75103
35.04400,2.92036,778.01258,-0.05481,7.41555,37.74056
35.14400,2.92879,777.58110,-0.05479,7.44927,37.71963
35.24400,2.93704,778.09878,-0.05478,7.48227,37.74474
35.34400,2.94529,778.35936,-0.05475,7.51528,37.75738
35.44400,2.95372,777.63875,-0.05482,7.54900,37.72242
35.54400,2.96203,777.65551,-0.05477,7.58224,37.72324
35.64400,2.97028,778.15885,-0.05476,7.61525,37.74765
35.74400,2.97865,777.78101,-0.05480,7.64873,37.72932
35.84400,2.98696,777.69728,-0.05483,7.68197,37.72526
35.94400,2.99521,777.15148,-0.05482,7.71498,37.69879
36.04400,3.00376,777.47363,-0.05481,7.74918,37.71441
36.14400,3.01202,777.01863,-0.05484,7.78218,37.69234
36.24400,3.02033,776.56563,-0.05482,7.81542,37.67037
36.34400,3.02882,776.51776,-0.05475,7.84938,37.66805
36.44400,3.03695,776.30975,-0.05481,7.88191,37.65796
36.54400,3.04526,776.29406,-0.05480,7.91515,37.65720
36.64400,3.05369,776.21546,-0.05477,7.94887,37.65338
36.74400,3.06194,775.67962,-0.05479,7.98188,37.62739
36.84400,3.07031,775.47906,-0.05479,8.01536,37.61766
36.94400,3.07874,775.48479,-0.05475,8.04908,37.61794
37.04400,3.08693,774.82699,-0.05477,8.08185,37.58603
37.14400,3.09536,774.29647,-0.05477,8.11557,37.56029
37.24400,3.10379,774.59412,-0.05476,8.14929,37.57473
37.34400,3.11198,774.14308,-0.05478,8.18205,37.55285
37.44400,3.12035,773.87807,-0.05479,8.21553,37.54000
37.54400,3.12866,773.35932,-0.05478,8.24878,37.51483
37.64400,3.13686,773.45981,-0.05478,8.28154,37.51971
37.74400,3.14529,773.03983,-0.05479,8.31526,37.49934
37.84400,3.15366,772.53389,-0.05477,8.34874,37.47479
37.94400,3.16197,772.39056,-0.05477,8.38199,37.46784
38.04400,3.17034,772.10939,-0.05478,8.41547,37.45420
38.14400,3.17865,771.03409,-0.05477,8.44871,37.40204
38.24400,3.18696,770.85048,-0.05477,8.48196,37.39313
38.34400,3.19533,770.81048,-0.05482,8.51544,37.39119
38.44400,3.20358,770.47278,-0.05479,8.54844,37.37481
38.54400,3.21195,769.97504,-0.05481,8.58192,37.35067
38.64400,3.22032,769.60507,-0.05483,8.61541,37.33272
38.74400,3.22857,768.80851,-0.05481,8.64841,37.29408
38.84400,3.23694,768.72171,-0.05478,8.68189,37.28987
38.94400,3.24537,768.13865,-0.05483,8.71561,37.26159
39.04400,3.25368,768.31840,-0.05479,8.74886,37.27030
39.14400,3.26200,768.02005,-0.05478,8.78210,37.25583
39.24400,3.27031,767.30847,-0.05480,8.81534,37.22131
39.34400,3.27868,766.88374,-0.05477,8.84882,37.20071
39.44400,3.28705,765.99955,-0.05477,8.88231,37.15782
39.54400,3.29536,766.26525,-0.05477,8.91555,37.17071
39.64400,3.30367,765.35740,-0.05477,8.94879,37.12667
39.74400,3.31204,765.16243,-0.05477,8.98227,37.11721
39.84400,3.32029,764.67642,-0.05476,9.01528,37.09364
39.94400,3.32866,764.49919,-0.05480,9.04876,37.08504
40.04400,3.33697,763.98151,-0.05480,9.08200,37.05993
40.14400,3.34528,763.60689,-0.05479,9.11525,37.04175
40.24400,3.35365,763.11487,-0.05479,9.14873,37.01789
40.34400,3.36208,762.93000,-0.05483,9.18245,37.00892
40.44400,3.37033,762.46825,-0.05482,9.21545,36.98652
40.54400,3.37864,762.11146,-0.05478,9.24870,36.96921
40.64400,3.38702,761.32989,-0.05479,9.28218,36.93130
40.74400,3.39533,761.40580,-0.05482,9.31542,36.93498
40.84400,3.40358,760.80658,-0.05478,9.34843,36.90591
40.94400,3.41201,760.78111,-0.05478,9.38215,36.90468
41.04400,3.42032,759.80769,-0.05482,9.41539,36.85746
41.14400,3.42863,759.66245,-0.05480,9.44863,36.85041
41.24400,3.43706,759.30837,-0.05476,9.48235,36.83324
41.34400,3.44531,758.78031,-0.05480,9.51536,36.80762
41.44400,3.45368,758.31348,-0.05481,9.54884,36.78498
41.54400,3.46205,758.42985,-0.05478,9.58232,36.79062
41.64400,3.47030,758.22738,-0.05478,9.61533,36.78080
41.74400,3.47867,757.67473,-0.05482,9.64881,36.75399
41.84400,3.48698,757.33713,-0.05479,9.68205,36.73761
41.94400,3.49523,757.06919,-0.05477,9.71505,36.72462
42.04400,3.50366,756.25028,-0.05479,9.74878,36.68489
42.14400,3.51191,755.86890,-0.05480,9.78178,36.66639
42.24400,3.52029,756.16292,-0.05476,9.81526,36.68065
42.34400,3.52878,755.19471,-0.05477,9.84922,36.63369
42.44400,3.53709,754.97124,-0.05482,9.88247,36.62285
42.54400,3.54534,754.78693,-0.05476,9.91547,36.61391
42.64400,3.55377,754.61129,-0.05478,9.94919,36.60538
42.74400,3.56202,754.32374,-0.05482,9.98219,36.59144
42.84400,3.57027,753.54553,-0.05479,10.01520,36.55369
42.94400,3.57876,753.87112,-0.05480,10.04916,36.56948
43.04400,3.58689,753.10329,-0.05480,10.08168,36.53223
43.14400,3.59520,753.40709,-0.05482,10.11493,36.54697
43.24400,3.60369,752.49444,-0.05481,10.14889,36.50270
43.34400,3.61188,752.21574,-0.05480,10.18165,36.48918
43.44400,3.62025,752.36908,-0.05481,10.21513,36.49662
43.54400,3.62874,751.05089,-0.05479,10.24909,36.43267
43.64400,3.63693,751.31012,-0.05481,10.28186,36.44525
43.74400,3.64537,750.64087,-0.05484,10.31558,36.41278
43.84400,3.65374,750.53247,-0.05483,10.34906,36.40753
43.94400,3.66193,750.01251,-0.05480,10.38183,36.38231
44.04400,3.67036,749.81176,-0.05487,10.41555,36.37257
44.14400,3.67867,750.23775,-0.05488,10.44879,36.39323
44.24400,3.68698,749.18983,-0.05483,10.48203,36.34240
44.34400,3.69547,749.18699,-0.05490,10.51600,36.34226
44.44400,3.70366,748.58735,-0.05483,10.54876,36.31317
44.54400,3.71191,748.36942,-0.05476,10.58176,36.30260
44.64400,3.72046,748.18092,-0.05485,10.61596,36.29346
44.74400,3.72865,747.74646,-0.05487,10.64873,36.27238
44.84400,3.73696,747.02133,-0.05482,10.68197,36.23721
44.94400,3.74545,747.56867,-0.05483,10.71593,36.26376
45.04400,3.75364,746.73765,-0.05483,10.74870,36.22345
45.14400,3.76196,746.92159,-0.05486,10.78194,36.23237
45.24400,3.77044,746.81742,-0.05482,10.81590,36.22731
45.34400,3.77864,746.13532,-0.05483,10.84866,36.19423
45.44400,3.78695,745.63329,-0.05488,10.88191,36.16987
45.54400,3.79538,745.61383,-0.05482,10.91563,36.16893
45.64400,3.80363,745.10663,-0.05479,10.94863,36.14433
45.74400,3.81200,744.68642,-0.05482,10.98211,36.12394
45.84400,3.82037,744.96204,-0.05479,11.01559,36.13731
45.94400,3.82868,744.58108,-0.05478,11.04884,36.11883
46.04400,3.83699,744.07696,-0.05479,11.08208,36.09438
46.14400,3.84524,744.09992,-0.05480,11.11509,36.09549
46.24400,3.85361,743.85158,-0.05479,11.14857,36.08344
46.34400,3.86198,743.79966,-0.05480,11.18205,36.08092
46.44400,3.87035,743.10573,-0.05481,11.21553,36.04726
46.54400,3.87860,742.62400,-0.05480,11.24854,36.02390
46.64400,3.88703,742.54377,-0.05478,11.28226,36.02000
46.74400,3.89535,741.71401,-0.05480,11.31550,35.97975
46.84400,3.90366,741.97757,-0.05482,11.34874,35.99254
46.94400,3.91215,741.52355,-0.05478,11.38270,35.97051
47.04400,3.92034,741.20034,-0.05477,11.41547,35.95483
47.14400,3.92865,741.16685,-0.05482,11.44871,35.95321
47.24400,3.93702,741.17552,-0.05479,11.48219,35.95363
47.34400,3.94527,740.93929,-0.05478,11.51520,35.94217
47.44400,3.95364,740.70664,-0.05479,11.54868,35.93089
47.54400,3.96201,739.75860,-0.05479,11.58216,35.88490
47.64400,3.97032,740.13034,-0.05478,11.61540,35.90293
47.74400,3.97869,739.60409,-0.05477,11.64889,35.87740
47.84400,3.98706,739.43427,-0.05478,11.68237,35.86916
47.94400,3.99531,738.93936,-0.05478,11.71537,35.84516
48.04400,4.00368,738.89610,-0.05477,11.74885,35.84306
48.14400,4.01205,738.54588,-0.05478,11.78234,35.82607
48.24400,4.02037,738.22811,-0.05479,11.81558,35.81066
48.34400,4.02868,737.85358,-0.05477,11.84882,35.79249
48.44400,4.03699,737.63155,-0.05478,11.88206,35.78172
48.54400,4.04530,737.60618,-0.05478,11.91531,35.78049
48.64400,4.05367,736.96868,-0.05479,11.94879,35.74956
48.74400,4.06198,736.69278,-0.05476,11.98203,35.73618
48.84400,4.07029,736.59290,-0.05478,12.01528,35.73133
48.94400,4.07872,736.48519,-0.05481,12.04900,35.72611
49.04400,4.08697,736.33203,-0.05475,12.08200,35.71868
49.14400,4.09528,735.71126,-0.05479,12.11524,35.68856
49.24400,4.10371,734.66445,-0.05479,12.14896,35.63779
49.34400,4.11196,735.15484,-0.05478,12.18197,35.66158
49.44400,4.12027,735.15410,-0.05480,12.21521,35.66154
49.54400,4.12870,734.54692,-0.05479,12.24893,35.63208
49.64400,4.13689,734.40108,-0.05481,12.28170,35.62501
49.74400,4.14521,734.70999,-0.05479,12.31494,35.64000
49.84400,4.15370,733.88093,-0.05477,12.34890,35.59978
49.94400,4.16201,733.57006,-0.05480,12.38214,35.58470
50.04400,4.17032,733.33513,-0.05480,12.41539,35.57330
50.14400,4.17875,733.10011,-0.05476,12.44911,35.56190
50.24400,4.18694,732.37359,-0.05480,12.48187,35.52666
50.34400,4.19531,732.58751,-0.05482,12.51535,35.53704
50.44400,4.20362,731.83374,-0.05476,12.54860,35.50047
50.54400,4.21187,732.14937,-0.05481,12.58160,35.51578
50.64400,4.22036,731.43509,-0.05481,12.61556,35.48113
50.74400,4.22873,731.78238,-0.05478,12.64904,35.49798
50.84400,4.23698,731.25022,-0.05480,12.68205,35.47216
50.94400,4.24541,731.16277,-0.05480,12.71577,35.46792
51.04400,4.25366,730.74005,-0.05479,12.74877,35.44742
51.14400,4.26197,730.82605,-0.05478,12.78202,35.45159
51.24400,4.27046,730.06046,-0.05480,12.81598,35.41445
51.34400,4.27866,729.42176,-0.05481,12.84874,35.38347
51.44400,4.28697,729.74688,-0.05477,12.88198,35.39924
51.54400,4.29540,729.26921,-0.05478,12.91571,35.37607
51.64400,4.30365,728.88150,-0.05481,12.94871,35.35726
51.74400,4.31196,728.36988,-0.05479,12.98195,35.33244
51.84400,4.32045,728.11949,-0.05476,13.01591,35.32030
51.94400,4.32864,728.19996,-0.05480,13.04868,35.32420
52.04400,4.33695,727.79669,-0.05478,13.08192,35.30464
52.14400,4.34538,726.97145,-0.05477,13.11564,35.26461
52.24400,4.35369,727.10160,-0.05479,13.14888,35.27092
52.34400,4.36206,726.99026,-0.05479,13.18237,35.26552
52.44400,4.37037,727.90654,-0.05478,13.21561,35.30997
52.54400,4.37862,726.18588,-0.05478,13.24861,35.22650
52.64400,4.38699,726.32674,-0.05479,13.28209,35.23333
52.74400,4.39525,725.82737,-0.05479,13.31510,35.20911
52.84400,4.40362,725.93573,-0.05479,13.34858,35.21437
52.94400,4.41199,724.79807,-0.05479,13.38206,35.15918
53.04400,4.42030,725.35491,-0.05481,13.41531,35.18619
53.14400,4.42867,725.36678,-0.05478,13.44879,35.18677
53.24400,4.43704,725.31267,-0.05480,13.48227,35.18414
53.34400,4.44529,724.22544,-0.05482,13.51527,35.13140
53.44400,4.45360,724.40053,-0.05478,13.54852,35.13990
53.54400,4.46197,723.83462,-0.05482,13.58200,35.11244
53.64400,4.47022,723.76481,-0.05481,13.61500,35.10906
53.74400,4.47859,723.19475,-0.05479,13.64848,35.08140
53.84400,4.48702,723.28579,-0.05481,13.68221,35.08582
53.94400,4.49527,723.00495,-0.05479,13.71521,35.07220
54.04400,4.50358,722.73598,-0.05479,13.74845,35.05915
54.14400,4.51201,722.32098,-0.05480,13.78217,35.03902
54.24400,4.52032,722.11339,-0.05480,13.81542,35.02895
54.34400,4.52870,721.36433,-0.05479,13.84890,34.99261
54.44400,4.53701,721.63157,-0.05479,13.88214,35.00558
54.54400,4.54538,721.02854,-0.05479,13.91563,34.97632
54.64400,4.55369,720.60572,-0.05479,13.94887,34.95581
54.74400,4.56200,720.57871,-0.05478,13.98211,34.95450
54.84400,4.57037,720.65261,-0.05479,14.01559,34.95809
54.94400,4.57868,720.21922,-0.05481,14.04884,34.93707
55.04400,4.58699,718.88021,-0.05479,14.08208,34.87211
55.14400,4.59536,720.10565,-0.05479,14.11556,34.93155
55.24400,4.60373,719.20156,-0.05481,14.14904,34.88770
55.34400,4.61204,718.89721,-0.05479,14.18229,34.87294
55.44400,4.62035,718.76245,-0.05480,14.21553,34.86640
55.54400,4.62878,718.66852,-0.05481,14.24925,34.86184
55.64400,4.63703,718.26638,-0.05479,14.28225,34.84233
55.74400,4.64534,717.94307,-0.05479,14.31550,34.82665
55.84400,4.65372,717.55755,-0.05481,14.34898,34.80795
55.94400,4.66191,717.57981,-0.05480,14.38174,34.80903
56.04400,4.67028,717.09976,-0.05479,14.41523,34.78574
56.14400,4.67871,716.71871,-0.05479,14.44895,34.76726
56.24400,4.68696,716.87521,-0.05482,14.48195,34.77485
56.34400,4.69539,716.70022,-0.05480,14.51567,34.76636
56.44400,4.70370,716.27335,-0.05481,14.54892,34.74566
56.54400,4.71201,715.32875,-0.05483,14.58216,34.69983
56.64400,4.72038,715.37825,-0.05480,14.61564,34.70223
56.74400,4.72869,714.92619,-0.05481,14.64888,34.68031
56.84400,4.73694,714.86193,-0.05482,14.68189,34.67719
56.94400,4.74525,714.66318,-0.05481,14.71513,34.66755
57.04400,4.75362,713.75291,-0.05481,14.74861,34.62339
57.14400,4.76199,713.56087,-0.05481,14.78209,34.61407
57.24400,4.77036,713.69638,-0.05482,14.81558,34.62065
57.34400,4.77868,713.11290,-0.05481,14.84882,34.59234
57.44400,4.78699,713.55659,-0.05482,14.88206,34.61386
57.54400,4.79542,712.71984,-0.05483,14.91578,34.57328
57.64400,4.80367,712.60985,-0.05479,14.94879,34.56794
57.74400,4.81198,711.93790,-0.05479,14.98203,34.53535
57.84400,4.82041,711.79485,-0.05483,15.01575,34.52841
57.94400,4.82866,711.52113,-0.05479,15.04875,34.51513
58.04400,4.83703,711.42619,-0.05478,15.08224,34.51052
58.14400,4.84540,711.25268,-0.05482,15.11572,34.50211
58.24400,4.85359,710.92276,-0.05480,15.14848,34.48610
58.34400,4.86196,709.73812,-0.05477,15.18197,34.42864
58.44400,4.87033,709.91796,-0.05481,15.21545,34.43736
58.54400,4.87864,710.01174,-0.05481,15.24869,34.44191
58.64400,4.88701,709.29825,-0.05478,15.28217,34.40730
58.74400,4.89538,709.03418,-0.05479,15.31565,34.39449
58.84400,4.90370,708.66151,-0.05481,15.34890,34.37641
58.94400,4.91201,708.07766,-0.05480,15.38214,34.34809
59.04400,4.92026,708.42290,-0.05479,15.41515,34.36484
59.14400,4.92863,708.75366,-0.05480,15.44863,34.38088
59.24400,4.93694,707.50122,-0.05483,15.48187,34.32013
59.34400,4.94531,707.20930,-0.05479,15.51535,34.30597
59.44400,4.95362,707.42276,-0.05479,15.54860,34.31632
59.54400,4.96199,706.80697,-0.05483,15.58208,34.28645
59.64400,4.97036,706.40314,-0.05479,15.61556,34.26686
59.74400,4.97873,706.32729,-0.05479,15.64904,34.26318
59.84400,4.98710,706.05604,-0.05481,15.68252,34.25002
59.94400,4.99529,705.65948,-0.05479,15.71529,34.23079
60.04400,5.00366,704.99964,-0.05481,15.74877,34.19878
60.14400,5.01203,705.13911,-0.05480,15.78225,34.20554
60.24400,5.02034,705.32970,-0.05478,15.81549,34.21479
60.34400,5.02865,704.28634,-0.05480,15.84874,34.16418
60.44400,5.03703,704.38529,-0.05479,15.88222,34.16898
60.54400,5.04534,703.89491,-0.05479,15.91546,34.14519
60.64400,5.05371,703.74724,-0.05479,15.94895,34.13803
60.74400,5.06208,702.87520,-0.05478,15.98243,34.09572
60.84400,5.07039,703.03995,-0.05479,16.01567,34.10371
60.94400,5.07870,702.43422,-0.05482,16.04891,34.07433
61.04400,5.08695,702.60153,-0.05478,16.08192,34.08245
61.14400,5.09526,702.29266,-0.05479,16.11516,34.06747
61.24400,5.10363,702.02569,-0.05481,16.14864,34.05452
61.34400,5.11194,701.97517,-0.05479,16.18189,34.05206
61.44400,5.12031,700.61483,-0.05480,16.21537,33.98608
61.54400,5.12862,700.51490,-0.05481,16.24861,33.98123
61.64400,5.13693,701.08944,-0.05481,16.28185,34.00910
61.74400,5.14530,700.70755,-0.05480,16.31534,33.99057
61.84400,5.15367,700.37064,-0.05482,16.34882,33.97423
61.94400,5.16199,699.45506,-0.05480,16.38206,33.92982
62.04400,5.17030,699.59518,-0.05481,16.41530,33.93661
62.14400,5.17867,699.18041,-0.05481,16.44878,33.91649
62.24400,5.18698,698.54516,-0.05481,16.48203,33.88568
62.34400,5.19529,698.89678,-0.05482,16.51527,33.90274
62.44400,5.20366,698.75298,-0.05481,16.54875,33.89576
62.54400,5.21197,698.10920,-0.05482,16.58200,33.86453
62.64400,5.22034,697.74361,-0.05483,16.61548,33.84680
62.74400,5.22877,697.65397,-0.05482,16.64920,33.84245
62.84400,5.23696,697.48685,-0.05483,16.68196,33.83434
62.94400,5.24533,696.98598,-0.05481,16.71545,33.81004
63.04400,5.25376,696.45843,-0.05480,16.74917,33.78445
63.14400,5.26201,696.22635,-0.05482,16.78217,33.77320
63.24400,5.27038,696.27771,-0.05483,16.81565,33.77569
63.34400,5.27863,695.76702,-0.05483,16.84866,33.75092
63.44400,5.28695,695.70513,-0.05486,16.88190,33.74791
63.54400,5.29532,695.40590,-0.05486,16.91538,33.73339
63.64400,5.30363,694.62103,-0.05486,16.94863,33.69532
63.74400,5.31200,694.96338,-0.05484,16.98211,33.71193
63.84400,5.32031,694.10563,-0.05484,17.01535,33.67032
63.94400,5.32868,693.82489,-0.05477,17.04883,33.65670
64.04401,5.33699,693.31336,-0.05489,17.08207,33.63189
64.14400,5.34536,693.01855,-0.05476,17.11556,33.61759
64.24400,5.35367,692.79736,-0.05480,17.14880,33.60686
64.34400,5.36192,692.53338,-0.05485,17.18180,33.59405
64.44400,5.37029,692.31298,-0.05482,17.21529,33.58336
64.54401,5.37860,692.08918,-0.05472,17.24853,33.57251
64.64400,5.38691,691.73397,-0.05486,17.28177,33.55527
64.74400,5.39534,691.85826,-0.05469,17.31549,33.56130
64.84400,5.40359,691.17206,-0.05468,17.34850,33.52802
64.94400,5.41196,690.67711,-0.05518,17.38198,33.50401
65.04401,5.42046,690.21066,-0.05468,17.41594,33.48138
65.14400,5.42871,689.64134,-0.05446,17.44894,33.45376
65.24400,5.43702,689.15007,-0.05507,17.48219,33.42993
65.34400,5.44539,689.72972,-0.05496,17.51567,33.45805
65.44400,5.45364,688.79141,-0.05444,17.54867,33.41253
65.54401,5.46195,688.77903,-0.05484,17.58191,33.41193
65.64401,5.47038,688.54233,-0.05509,17.61564,33.40045
65.74400,5.47863,687.97306,-0.05465,17.64864,33.37284
65.84400,5.48700,687.72226,-0.05460,17.68212,33.36067
65.94400,5.49537,687.00784,-0.05501,17.71561,33.32602
66.04401,5.50368,686.75722,-0.05489,17.74885,33.31386
66.14401,5.51205,686.71796,-0.05457,17.78233,33.31195
66.24400,5.52042,686.02818,-0.05484,17.81581,33.27849
66.34400,5.52861,685.93221,-0.05496,17.84858,33.27384
66.44400,5.53699,685.42771,-0.05469,17.88206,33.24937
66.54401,5.54530,685.00764,-0.05469,17.91530,33.22899
66.64401,5.55361,685.19027,-0.05493,17.94855,33.23785
66.74400,5.56204,684.52661,-0.05481,17.98227,33.20565
66.84400,5.57029,684.11711,-0.05467,18.01527,33.18579
66.94400,5.57860,683.62271,-0.05482,18.04851,33.16181
67.04401,5.58703,683.52721,-0.05487,18.08224,33.15717
67.14401,5.59534,682.82117,-0.05474,18.11548,33.12292
67.24400,5.60365,683.05093,-0.05473,18.14872,33.13407
67.34400,5.61202,682.21660,-0.05487,18.18220,33.09360
67.44400,5.62027,681.98810,-0.05482,18.21520,33.08251
67.54401,5.62858,682.01465,-0.05471,18.24845,33.08380
67.64401,5.63695,681.47629,-0.05482,18.28193,33.05769
67.74400,5.64538,680.91173,-0.05486,18.31565,33.03030
67.84400,5.65363,680.67713,-0.05474,18.34866,33.01892
67.94400,5.66200,679.75693,-0.05478,18.38214,32.97428
68.04401,5.67032,679.65169,-0.05485,18.41538,32.96918
68.14401,5.67869,679.05220,-0.05480,18.44886,32.94009
68.24400,5.68700,679.08969,-0.05476,18.48211,32.94191
68.34400,5.69537,678.28167,-0.05481,18.51559,32.90272
68.44400,5.70368,677.91850,-0.05483,18.54883,32.88510
68.54401,5.71199,678.23506,-0.05478,18.58207,32.90046
68.64401,5.72030,677.12418,-0.05477,18.61532,32.84657
68.74400,5.72867,676.67947,-0.05484,18.64880,32.82500
68.84400,5.73692,676.48408,-0.05480,18.68180,32.81552
68.94400,5.74523,676.16608,-0.05476,18.71505,32.80009
69.04401,5.75366,675.49688,-0.05480,18.74877,32.76763
69.14401,5.76197,675.55727,-0.05485,18.78201,32.77056
69.24400,5.77034,675.05576,-0.05477,18.81549,32.74623
69.34400,5.77877,674.37105,-0.05476,18.84921,32.71302
69.44400,5.78702,673.92965,-0.05483,18.88222,32.69160
69.54401,5.79534,673.02412,-0.05486,18.91546,32.64768
69.64401,5.80371,672.81309,-0.05472,18.94894,32.63744
69.74400,5.81196,672.71623,-0.05480,18.98195,32.63274
69.84400,5.82033,672.62999,-0.05485,19.01543,32.62856
69.94400,5.82870,671.36995,-0.05479,19.04891,32.56744
70.04401,5.83695,671.80586,-0.05475,19.08191,32.58858
70.14401,5.84532,671.04986,-0.05485,19.11540,32.55191
70.24400,5.85369,670.67109,-0.05483,19.14888,32.53354
70.34400,5.86200,669.78806,-0.05476,19.18212,32.49070
70.44400,5.87037,669.72603,-0.05482,19.21560,32.48769
70.54401,5.87868,669.39173,-0.05485,19.24885,32.47148
70.64401,5.88693,668.65613,-0.05479,19.28185,32.43579
70.74400,5.89536,667.77710,-0.05479,19.31557,32.39315
70.84400,5.90361,668.43810,-0.05483,19.34858,32.42522
70.94400,5.91193,667.30753,-0.05481,19.38182,32.37037
71.04401,5.92042,666.33350,-0.05477,19.41578,32.32312
71.14401,5.92867,665.82235,-0.05480,19.44878,32.29833
71.24400,5.93698,665.19422,-0.05482,19.48203,32.26786
71.34400,5.94547,664.40324,-0.05479,19.51599,32.22949
71.44400,5.95372,664.26229,-0.05479,19.54899,32.22265
71.54401,5.96197,663.67877,-0.05481,19.58199,32.19435
71.64401,5.97046,662.98051,-0.05482,19.61595,32.16048
71.74400,5.97865,662.61124,-0.05478,19.64872,32.14256
71.84400,5.98690,662.45785,-0.05480,19.68172,32.13512
71.94400,5.99533,660.90040,-0.05483,19.71544,32.05957
72.04401,6.00358,660.80946,-0.05480,19.74845,32.05516
72.14401,6.01195,660.25592,-0.05480,19.78193,32.02831
72.24400,6.02038,659.31180,-0.05485,19.81565,31.98251
72.34400,6.02863,658.56399,-0.05481,19.84866,31.94623
72.44400,6.03700,657.49083,-0.05479,19.88214,31.89418
72.54401,6.04531,656.88766,-0.05484,19.91538,31.86492
72.64401,6.05363,656.42470,-0.05484,19.94862,31.84246
72.74400,6.06206,655.51186,-0.05481,19.98235,31.79818
72.84400,6.07031,654.39763,-0.05482,20.01535,31.74413
72.94400,6.07862,652.87617,-0.05483,20.04859,31.67032
73.04401,6.08705,651.62336,-0.05482,20.08231,31.60955
73.14401,6.09530,650.74894,-0.05481,20.11531,31.56713
73.24400,6.10361,649.06958,-0.05481,20.14856,31.48567
73.34400,6.11204,647.14006,-0.05483,20.18228,31.39207
73.44400,6.12029,644.69040,-0.05482,20.21528,31.27324
73.54401,6.12866,641.66524,-0.05480,20.24877,31.12649
73.64401,6.13715,635.65439,-0.05484,20.28273,30.83491
73.73801,6.14492,2.06905,-0.05487,20.31382,0.10037