File: Manufatura Aditiva/Dados/Ensaios AMR/Ensaios/Ensaios FDM/Tracao_OLABI_18_03_2019_FDM_45.is_metal_RawData/Specimen_RawData_6.csv
Time,Extension,Load,Strain 1,Tensile strain,Tensile stress
(sec),(mm),(N),(mm/mm),(%),(MPa)
0.00000,0.00006,0.56646,0.00000,0.00002,0.02748
0.10000,0.00407,1.14265,0.00002,0.00230,0.05543
0.20000,0.01375,4.61919,0.00015,0.01489,0.22407
0.30000,0.02344,9.19096,0.00028,0.02818,0.44584
0.40000,0.03265,13.21148,0.00040,0.04045,0.64087
0.50000,0.04137,16.25869,0.00052,0.05160,0.78869
0.60000,0.04986,20.08323,0.00063,0.06310,0.97422
0.70000,0.05829,23.27954,0.00074,0.07389,1.12927
0.80000,0.06667,27.12095,0.00085,0.08516,1.31561
0.90000,0.07498,30.51603,0.00097,0.09687,1.48030
1.00000,0.08335,33.70011,0.00108,0.10809,1.63476
1.10000,0.09172,37.53226,0.00120,0.11988,1.82065
1.20000,0.09997,40.20270,0.00131,0.13071,1.95019
1.30000,0.10840,43.62677,0.00143,0.14314,2.11629
1.40000,0.11665,46.93408,0.00154,0.15430,2.27672
1.50000,0.12496,51.14091,0.00166,0.16640,2.48079
1.60000,0.13339,53.56180,0.00179,0.17881,2.59823
1.70000,0.14164,57.38171,0.00190,0.19010,2.78353
1.80000,0.14995,60.68175,0.00202,0.20174,2.94361
1.90000,0.15838,64.11226,0.00214,0.21365,3.11002
2.00000,0.16663,67.40615,0.00226,0.22599,3.26980
2.10000,0.17500,71.14550,0.00238,0.23839,3.45119
2.20000,0.18337,74.22821,0.00250,0.25010,3.60073
2.30000,0.19169,78.06272,0.00263,0.26264,3.78674
2.40000,0.20000,80.90060,0.00275,0.27467,3.92440
2.50000,0.20837,84.19697,0.00287,0.28723,4.08431
2.60000,0.21674,87.50974,0.00299,0.29950,4.24500
2.70000,0.22499,91.31431,0.00312,0.31156,4.42956
2.80000,0.23336,94.57630,0.00324,0.32409,4.58779
2.90000,0.24173,98.03578,0.00336,0.33639,4.75561
3.00000,0.25004,101.30649,0.00349,0.34858,4.91427
3.10000,0.25835,104.47003,0.00361,0.36132,5.06773
3.20000,0.26666,107.67330,0.00374,0.37374,5.22312
3.30000,0.27503,110.53875,0.00386,0.38616,5.36212
3.40000,0.28334,113.82326,0.00399,0.39869,5.52144
3.50000,0.29159,117.02006,0.00411,0.41136,5.67652
3.60000,0.29996,120.75816,0.00424,0.42424,5.85785
3.70000,0.30821,123.77196,0.00437,0.43678,6.00405
3.80000,0.31659,127.92523,0.00449,0.44922,6.20552
3.90000,0.32502,130.23556,0.00462,0.46225,6.31759
4.00000,0.33333,133.71787,0.00475,0.47480,6.48651
4.10000,0.34164,136.86499,0.00487,0.48749,6.63917
4.20000,0.35001,139.44446,0.00500,0.50026,6.76430
4.30000,0.35820,143.45681,0.00513,0.51286,6.95894
4.40000,0.36657,146.46834,0.00526,0.52557,7.10502
4.50000,0.37500,150.37155,0.00538,0.53845,7.29436
4.60000,0.38337,153.31235,0.00552,0.55169,7.43702
4.70000,0.39168,156.35041,0.00564,0.56447,7.58439
4.80000,0.40005,159.76945,0.00577,0.57748,7.75025
4.90000,0.40836,163.13739,0.00590,0.59017,7.91362
5.00000,0.41667,166.41403,0.00604,0.60370,8.07257
5.10000,0.42510,170.01475,0.00617,0.61665,8.24723
5.20000,0.43335,173.54198,0.00630,0.63000,8.41834
5.30000,0.44172,176.39697,0.00643,0.64285,8.55683
5.40000,0.45004,179.70107,0.00656,0.65565,8.71711
5.50000,0.45829,182.94620,0.00669,0.66857,8.87452
5.60000,0.46666,185.82625,0.00682,0.68226,9.01423
5.70000,0.47491,188.92591,0.00695,0.69508,9.16459
5.80000,0.48328,192.20951,0.00708,0.70790,9.32388
5.90000,0.49171,195.43350,0.00721,0.72125,9.48027
6.00000,0.49996,198.48945,0.00735,0.73470,9.62851
6.10000,0.50833,202.33521,0.00748,0.74795,9.81506
6.20000,0.51670,205.15127,0.00761,0.76112,9.95167
6.30000,0.52501,208.16110,0.00775,0.77458,10.09767
6.40000,0.53332,211.84122,0.00788,0.78805,10.27619
6.50000,0.54169,214.88890,0.00802,0.80172,10.42403
6.60000,0.54994,217.70757,0.00815,0.81483,10.56076
6.70000,0.55825,221.14827,0.00828,0.82798,10.72767
6.80000,0.56674,224.67359,0.00842,0.84153,10.89867
6.90000,0.57500,227.48050,0.00855,0.85462,11.03484
7.00000,0.58337,231.04155,0.00868,0.86804,11.20758
7.10000,0.59174,234.67219,0.00882,0.88178,11.38370
7.20000,0.59993,237.77732,0.00895,0.89508,11.53432
7.30000,0.60830,241.10265,0.00908,0.90782,11.69563
7.40000,0.61667,243.79459,0.00922,0.92178,11.82621
7.50000,0.62492,247.23145,0.00935,0.93507,11.99293
7.60000,0.63335,250.65811,0.00949,0.94885,12.15916
7.70000,0.64166,254.28385,0.00962,0.96205,12.33504
7.80000,0.64997,256.70344,0.00975,0.97527,12.45241
7.90000,0.65840,259.92931,0.00989,0.98885,12.60889
8.00000,0.66665,263.05693,0.01002,1.00233,12.76061
8.10000,0.67490,266.31248,0.01016,1.01594,12.91853
8.20000,0.68345,269.88459,0.01030,1.03000,13.09181
8.30000,0.69170,272.88692,0.01043,1.04305,13.23745
8.40000,0.70002,274.76850,0.01056,1.05648,13.32873
8.50000,0.70845,278.80829,0.01071,1.07098,13.52469
8.60000,0.71664,281.27527,0.01085,1.08461,13.64436
8.70000,0.72495,284.67767,0.01098,1.09804,13.80941
8.80000,0.73338,287.81472,0.01112,1.11186,13.96158
8.90000,0.74157,291.67819,0.01126,1.12565,14.14900
9.00000,0.75000,294.69053,0.01139,1.13893,14.29512
9.10000,0.75837,297.13267,0.01153,1.15322,14.41359
9.20000,0.76662,300.63628,0.01166,1.16625,14.58354
9.30000,0.77499,303.36131,0.01180,1.17981,14.71573
9.40000,0.78336,306.70592,0.01194,1.19402,14.87798
9.50000,0.79161,309.62063,0.01207,1.20740,15.01937
9.60000,0.79998,312.94201,0.01221,1.22122,15.18048
9.70000,0.80829,315.39302,0.01235,1.23454,15.29938
9.80000,0.81660,318.89901,0.01248,1.24840,15.46945
9.90000,0.82504,322.06932,0.01262,1.26230,15.62324
10.00000,0.83329,324.90047,0.01275,1.27547,15.76057
10.10000,0.84160,328.11828,0.01290,1.28969,15.91667
10.20000,0.85003,330.85204,0.01304,1.30352,16.04928
10.30000,0.85834,333.49690,0.01317,1.31695,16.17758
10.40000,0.86671,337.02489,0.01331,1.33096,16.34872
10.50000,0.87514,339.81076,0.01345,1.34477,16.48386
10.60000,0.88333,342.61714,0.01359,1.35890,16.61999
10.70000,0.89158,346.01521,0.01372,1.37227,16.78483
10.80000,0.90007,348.64005,0.01386,1.38602,16.91216
10.90000,0.90832,351.44871,0.01400,1.39962,17.04840
11.00000,0.91663,354.46596,0.01414,1.41352,17.19477
11.10000,0.92506,357.27164,0.01427,1.42743,17.33086
11.20000,0.93331,360.46035,0.01442,1.44166,17.48555
11.30000,0.94168,362.87450,0.01455,1.45509,17.60265
11.40000,0.95000,366.41988,0.01469,1.46912,17.77464
11.50000,0.95831,369.31424,0.01483,1.48322,17.91504
11.60000,0.96662,372.00144,0.01497,1.49677,18.04539
11.70000,0.97499,375.25166,0.01511,1.51085,18.20306
11.80000,0.98330,378.04390,0.01525,1.52479,18.33850
11.90000,0.99161,380.91275,0.01539,1.53856,18.47767
12.00000,0.99992,383.39170,0.01553,1.55250,18.59792
12.10000,1.00823,387.04430,0.01566,1.56637,18.77510
12.20000,1.01666,389.12923,0.01580,1.58009,18.87624
12.30000,1.02497,392.76569,0.01594,1.59439,19.05264
12.40000,1.03328,395.06485,0.01608,1.60808,19.16417
12.50000,1.04177,398.02068,0.01622,1.62203,19.30756
12.60000,1.05002,401.50005,0.01636,1.63609,19.47634
12.70000,1.05839,404.28904,0.01650,1.65031,19.61163
12.80000,1.06676,407.03244,0.01664,1.66393,19.74471
12.90000,1.07496,409.34645,0.01679,1.67856,19.85696
13.00000,1.08333,412.99262,0.01692,1.69212,20.03383
13.10000,1.09170,415.92573,0.01707,1.70671,20.17611
13.20000,1.09989,419.01805,0.01720,1.72039,20.32612
13.30000,1.10832,422.00340,0.01735,1.73478,20.47093
13.40000,1.11675,424.80910,0.01749,1.74920,20.60703
13.50000,1.12500,427.93625,0.01763,1.76297,20.75873
13.60000,1.13331,430.90922,0.01777,1.77722,20.90294
13.70000,1.14168,434.57788,0.01791,1.79123,21.08091
13.80000,1.14993,437.14880,0.01806,1.80568,21.20562
13.90000,1.15830,439.36055,0.01820,1.81950,21.31291
14.00000,1.16667,442.45254,0.01834,1.83403,21.46290
14.10000,1.17492,445.36912,0.01848,1.84815,21.60438
14.20000,1.18335,448.10534,0.01862,1.86231,21.73711
14.30000,1.19166,451.00329,0.01877,1.87670,21.87769
14.40000,1.19992,453.87265,0.01891,1.89078,22.01688
14.50000,1.20841,456.22145,0.01905,1.90531,22.13081
14.60000,1.21666,458.94934,0.01919,1.91930,22.26314
14.70000,1.22497,461.81376,0.01934,1.93365,22.40209
14.80000,1.23346,464.31739,0.01948,1.94794,22.52354
14.90000,1.24171,467.25008,0.01961,1.96119,22.66580
15.00000,1.24996,469.43505,0.01974,1.97405,22.77179
15.10000,1.25839,471.97654,0.01988,1.98807,22.89508
15.20000,1.26658,474.81526,0.02002,2.00198,23.03278
15.30000,1.27495,477.95600,0.02017,2.01655,23.18513
15.40000,1.28338,480.10321,0.02031,2.03064,23.28929
15.50000,1.29169,482.97034,0.02045,2.04510,23.42837
15.60000,1.29994,486.00673,0.02060,2.05952,23.57567
15.70000,1.30831,488.41946,0.02074,2.07439,23.69271
15.80000,1.31662,490.79987,0.02089,2.08896,23.80818
15.90000,1.32505,494.25755,0.02103,2.10329,23.97590
16.00000,1.33337,496.11661,0.02117,2.11742,24.06609
16.10000,1.34162,499.01516,0.02132,2.13188,24.20669
16.20000,1.35005,502.36229,0.02146,2.14639,24.36906
16.30000,1.35836,504.42638,0.02161,2.16087,24.46918
16.40000,1.36661,507.06072,0.02175,2.17524,24.59697
16.50000,1.37504,509.72016,0.02190,2.19034,24.72598
16.60000,1.38329,512.14029,0.02205,2.20479,24.84338
16.70000,1.39166,514.47833,0.02219,2.21921,24.95679
16.80000,1.40009,517.30573,0.02234,2.23404,25.09395
16.90000,1.40834,520.24168,0.02248,2.24814,25.23637
17.00000,1.41665,522.55425,0.02262,2.26224,25.34855
17.10000,1.42496,524.81298,0.02277,2.27695,25.45812
17.20000,1.43321,526.90217,0.02288,2.28842,25.55946
17.30000,1.44158,529.10135,0.02303,2.30267,25.66614
17.40000,1.44995,531.68130,0.02317,2.31733,25.79129
17.50000,1.45827,534.48849,0.02332,2.33190,25.92747
17.60000,1.46664,536.97978,0.02347,2.34667,26.04832
17.70000,1.47501,538.97332,0.02361,2.36125,26.14502
17.80000,1.48332,541.67877,0.02376,2.37598,26.27626
17.90000,1.49169,544.07716,0.02391,2.39074,26.39260
18.00000,1.50006,546.49836,0.02405,2.40538,26.51005
18.10000,1.50831,549.70854,0.02420,2.41994,26.66577
18.20000,1.51668,551.62148,0.02435,2.43506,26.75857
18.30000,1.52505,554.32301,0.02450,2.45008,26.88962
18.40000,1.53336,556.39762,0.02465,2.46467,26.99025
18.50000,1.54173,558.70800,0.02479,2.47937,27.10233
18.60000,1.54998,561.46649,0.02494,2.49434,27.23614
18.70000,1.55829,563.43134,0.02509,2.50905,27.33145
18.80000,1.56672,566.30541,0.02524,2.52388,27.47087
18.90000,1.57497,568.67418,0.02539,2.53875,27.58578
19.00000,1.58341,571.13394,0.02554,2.55372,27.70510
19.10000,1.59172,572.51113,0.02569,2.56912,27.77190
19.20000,1.59997,575.73779,0.02584,2.58390,27.92842
19.30000,1.60828,578.45083,0.02599,2.59875,28.06003
19.40000,1.61665,580.68372,0.02614,2.61410,28.16835
19.50000,1.62496,583.06721,0.02628,2.62846,28.28397
19.60000,1.63327,585.35365,0.02644,2.64371,28.39488
19.70000,1.64170,587.25504,0.02659,2.65890,28.48711
19.80000,1.64995,589.79546,0.02674,2.67365,28.61035
19.90000,1.65832,592.18802,0.02689,2.68941,28.72641
20.00000,1.66669,594.59810,0.02704,2.70446,28.84332
20.10000,1.67500,597.04441,0.02719,2.71922,28.96198
20.20000,1.68337,598.94323,0.02734,2.73436,29.05410
20.30000,1.69168,601.31806,0.02749,2.74933,29.16930
20.40000,1.69993,604.00981,0.02765,2.76495,29.29987
20.50000,1.70831,605.77332,0.02780,2.77980,29.38542
20.60000,1.71668,608.14433,0.02795,2.79517,29.50043
20.70000,1.72499,610.43575,0.02811,2.81068,29.61159
20.80000,1.73336,612.09989,0.02826,2.82581,29.69231
20.90000,1.74167,614.94950,0.02841,2.84102,29.83054
21.00000,1.74998,616.61769,0.02856,2.85588,29.91146
21.10000,1.75841,618.73542,0.02872,2.87198,30.01419
21.20000,1.76672,621.05437,0.02887,2.88715,30.12668
21.30000,1.77497,623.14323,0.02902,2.90248,30.22801
21.40000,1.78340,625.56393,0.02918,2.91813,30.34544
21.50000,1.79165,627.71118,0.02934,2.93351,30.44960
21.60000,1.79996,630.52014,0.02949,2.94867,30.58586
21.70000,1.80839,632.31722,0.02964,2.96436,30.67303
21.80000,1.81664,633.84082,0.02980,2.98022,30.74694
21.90000,1.82501,636.33081,0.02995,2.99541,30.86773
22.00000,1.83339,638.68524,0.03011,3.01142,30.98194
22.10000,1.84164,640.46439,0.03027,3.02657,31.06824
22.20000,1.84995,642.89519,0.03042,3.04220,31.18616
22.30000,1.85844,644.49781,0.03058,3.05759,31.26390
22.40000,1.86663,646.87771,0.03074,3.07352,31.37934
22.50000,1.87500,648.71693,0.03089,3.10700,31.46856
22.60000,1.88337,650.97040,0.03105,3.14048,31.57788
22.69800,1.89144,653.20986,0.03120,3.17277,31.68651
22.79800,1.89981,655.28103,0.03136,3.20625,31.78698
22.89800,1.90812,656.63648,0.03152,3.23949,31.85273
22.99800,1.91643,658.88804,0.03167,3.27273,31.96195
23.09800,1.92486,661.09081,0.03183,3.30646,32.06881
23.19800,1.93317,662.81417,0.03199,3.33970,32.15240
23.29800,1.94148,665.82910,0.03215,3.37294,32.29866
23.39800,1.94991,667.15595,0.03231,3.40666,32.36302
23.49800,1.95811,669.13865,0.03247,3.43943,32.45920
23.59800,1.96642,670.61461,0.03263,3.47267,32.53080
23.69800,1.97485,672.96615,0.03286,3.50639,32.64487
23.79800,1.98316,674.27438,0.03338,3.53963,32.70833
23.89800,1.99147,676.98052,0.03219,3.57288,32.83960
23.99800,1.99984,679.67405,0.02830,3.60636,32.97026
24.09800,2.00821,680.41617,0.00432,3.63984,33.00626
24.19800,2.01652,681.34279,0.00710,3.67308,33.05121
24.29800,2.02489,683.87329,0.00697,3.70657,33.17396
24.39800,2.03320,685.66091,0.00618,3.73981,33.26068
24.49800,2.04145,687.29771,0.00300,3.77281,33.34008
24.59800,2.04982,689.42085,0.00642,3.80630,33.44307
24.69800,2.05813,691.40405,0.00597,3.83954,33.53927
24.79800,2.06644,692.29235,0.00350,3.87278,33.58236
24.89800,2.07476,694.12850,0.00948,3.90602,33.67143
24.99800,2.08313,696.13191,0.01022,3.93951,33.76862
25.09800,2.09144,697.96201,-0.00372,3.97275,33.85739
25.19800,2.09981,699.66908,-0.00377,4.00623,33.94020
25.29800,2.10818,701.30080,-0.00349,4.03971,34.01935
25.39800,2.11655,702.85886,0.00222,4.07320,34.09493
25.49800,2.12486,704.62674,0.00586,4.10644,34.18069
25.59800,2.13317,705.99015,0.00587,4.13968,34.24683
25.69800,2.14154,707.33950,0.00519,4.17316,34.31228
25.79800,2.14985,709.23707,0.00658,4.20641,34.40433
25.89800,2.15822,711.27033,-0.00979,4.23989,34.50296
25.99800,2.16653,712.54699,-0.01754,4.27313,34.56489
26.09800,2.17484,714.64726,-0.01902,4.30637,34.66677
26.19800,2.18321,715.52196,-0.08644,4.33986,34.70921
26.29800,2.19158,717.55978,-0.13841,4.37334,34.80806
26.39800,2.19989,718.57329,-0.13675,4.40658,34.85722
26.49800,2.20821,720.33517,-0.10091,4.43983,34.94269
26.59800,2.21658,722.21598,-0.05806,4.47331,35.03392
26.69800,2.22489,723.89911,-0.05862,4.50655,35.11557
26.79800,2.23320,725.21288,-0.05811,4.53979,35.17930
26.89800,2.24151,727.16153,-0.05107,4.57304,35.27383
26.99800,2.24976,728.40066,-0.05462,4.60604,35.33393
27.09800,2.25813,729.43023,-0.05515,4.63952,35.38388
27.19800,2.26644,730.78866,-0.05477,4.67277,35.44978
27.29800,2.27481,732.23840,-0.05488,4.70625,35.52010
27.39800,2.28318,733.78212,-0.05511,4.73973,35.59499
27.49800,2.29143,735.81496,-0.05511,4.77273,35.69360
27.59800,2.29980,736.97171,-0.05503,4.80622,35.74971
27.69800,2.30811,737.76166,-0.05505,4.83946,35.78803
27.79800,2.31642,740.02976,-0.05505,4.87270,35.89805
27.89800,2.32479,741.15586,-0.05507,4.90618,35.95268
27.99800,2.33317,742.27033,-0.05504,4.93967,36.00674
28.09800,2.34148,743.89968,-0.05507,4.97291,36.08578
28.19800,2.34979,744.97154,-0.05507,5.00615,36.13777
28.29800,2.35822,746.28387,-0.05505,5.03987,36.20143
28.39800,2.36647,747.43112,-0.05507,5.07288,36.25708
28.49800,2.37484,748.70028,-0.05507,5.10636,36.31865
28.59800,2.38321,749.89642,-0.05507,5.13984,36.37667
28.69800,2.39152,751.05485,-0.05508,5.17308,36.43287
28.79800,2.39983,752.60825,-0.05508,5.20633,36.50822
28.89800,2.40820,753.08383,-0.05508,5.23981,36.53129
28.99800,2.41645,754.62190,-0.05508,5.27281,36.60590
29.09800,2.42482,756.19766,-0.05509,5.30630,36.68234
29.19800,2.43319,757.14081,-0.05509,5.33978,36.72809
29.29800,2.44150,757.95250,-0.05510,5.37302,36.76746
29.39800,2.44987,759.40131,-0.05508,5.40650,36.83775
29.49800,2.45813,760.31340,-0.05509,5.43951,36.88199
29.59800,2.46650,761.25073,-0.05510,5.47299,36.92746
29.69800,2.47493,762.52269,-0.05508,5.50671,36.98916
29.79800,2.48324,763.69080,-0.05510,5.53995,37.04582
29.89800,2.49149,764.71395,-0.05511,5.57296,37.09546
29.99800,2.49986,765.17751,-0.05510,5.60644,37.11794
30.09800,2.50805,766.97860,-0.05510,5.63920,37.20531
30.19800,2.51642,767.23443,-0.05510,5.67268,37.21772
30.29800,2.52485,768.45922,-0.05511,5.70641,37.27713
30.39800,2.53310,769.33559,-0.05510,5.73941,37.31964
30.49800,2.54147,770.28610,-0.05509,5.77289,37.36575
30.59800,2.54984,771.21239,-0.05512,5.80637,37.41069
30.69800,2.55809,772.01091,-0.05511,5.83938,37.44942
30.79800,2.56646,773.63327,-0.05509,5.87286,37.52812
30.89800,2.57483,774.50229,-0.05511,5.90634,37.57028
30.99800,2.58315,775.66882,-0.05512,5.93958,37.62687
31.09800,2.59152,776.43967,-0.05510,5.97307,37.66426
31.19800,2.59983,776.89374,-0.05512,6.00631,37.68628
31.29800,2.60814,777.97687,-0.05512,6.03955,37.73883
31.39800,2.61645,778.58749,-0.05511,6.07280,37.76845
31.49800,2.62476,780.03658,-0.05513,6.10604,37.83874
31.59800,2.63319,780.49861,-0.05511,6.13976,37.86115
31.69800,2.64156,780.50159,-0.05515,6.17324,37.86130
31.79800,2.64987,781.64889,-0.05515,6.20649,37.91695
31.89800,2.65818,782.16735,-0.05514,6.23973,37.94210
31.99800,2.66655,782.04675,-0.05515,6.27321,37.93625
32.09800,2.67486,783.20801,-0.05516,6.30645,37.99258
32.19800,2.68317,783.81673,-0.05513,6.33970,38.02211
32.29800,2.69148,784.39955,-0.05513,6.37294,38.05038
32.39800,2.69979,784.64728,-0.05513,6.40618,38.06240
32.49800,2.70811,785.32435,-0.05511,6.43942,38.09525
32.59800,2.71654,785.37604,-0.05512,6.47315,38.09775
32.69800,2.72479,786.19989,-0.05512,6.50615,38.13771
32.79800,2.73316,786.37833,-0.05513,6.53963,38.14637
32.89800,2.74159,787.53317,-0.05512,6.57335,38.20239
32.99800,2.74978,787.86677,-0.05512,6.60612,38.21857
33.09800,2.75815,789.31553,-0.05515,6.63960,38.28885
33.19800,2.76646,788.87669,-0.05515,6.67284,38.26756
33.29800,2.77483,788.81700,-0.05516,6.70633,38.26467
33.39800,2.78308,789.68871,-0.05514,6.73933,38.30695
33.49800,2.79151,789.51400,-0.05515,6.77305,38.29848
33.59800,2.79982,790.45733,-0.05516,6.80629,38.34424
33.69800,2.80813,790.29733,-0.05514,6.83954,38.33648
33.79800,2.81656,790.98390,-0.05515,6.87326,38.36978
33.89800,2.82487,790.95364,-0.05514,6.90650,38.36831
33.99800,2.83324,791.66945,-0.05516,6.93998,38.40304
34.09800,2.84150,791.54465,-0.05516,6.97299,38.39698
34.19800,2.84981,791.89073,-0.05515,7.00623,38.41377
34.29800,2.85818,791.94447,-0.05518,7.03971,38.41638
34.39800,2.86643,792.16734,-0.05517,7.07272,38.42719
34.49800,2.87474,792.82578,-0.05517,7.10596,38.45913
34.59800,2.88317,792.25218,-0.05519,7.13968,38.43130
34.69800,2.89142,791.95946,-0.05518,7.17268,38.41711
34.79800,2.89979,793.10350,-0.05517,7.20617,38.47260
34.89800,2.90816,792.91500,-0.05517,7.23965,38.46346
34.99800,2.91653,792.13679,-0.05518,7.27313,38.42571
35.09800,2.92490,792.50252,-0.05517,7.30661,38.44345
35.19800,2.93327,792.85102,-0.05518,7.34009,38.46035
35.29800,2.94152,793.04269,-0.05516,7.37310,38.46965
35.39800,2.94983,792.14172,-0.05517,7.40634,38.42595
35.49800,2.95826,792.58168,-0.05518,7.44006,38.44729
35.59800,2.96646,793.06113,-0.05516,7.47283,38.47055
35.69800,2.97477,792.94164,-0.05515,7.50607,38.46475
35.79800,2.98320,792.45279,-0.05516,7.53979,38.44104
35.89800,2.99139,792.65106,-0.05515,7.57256,38.45066
35.99800,2.99976,792.40538,-0.05515,7.60604,38.43874
36.09800,3.00825,792.44729,-0.05516,7.64000,38.44077
36.19800,3.01650,791.52891,-0.05513,7.67300,38.39622
36.29800,3.02493,791.65986,-0.05515,7.70672,38.40257
36.39800,3.03318,791.56738,-0.05516,7.73973,38.39809
36.49800,3.04143,791.58489,-0.05515,7.77273,38.39894
36.59800,3.04986,791.27774,-0.05516,7.80645,38.38404
36.69800,3.05811,791.33203,-0.05517,7.83946,38.38667
36.79800,3.06648,790.61538,-0.05515,7.87294,38.35191
36.89800,3.07491,790.79941,-0.05516,7.90666,38.36083
36.99800,3.08316,790.23521,-0.05517,7.93966,38.33347
37.09800,3.09154,790.03228,-0.05516,7.97314,38.32362
37.19800,3.09997,790.04420,-0.05517,8.00687,38.32420
37.29800,3.10822,789.57276,-0.05517,8.03987,38.30133
37.39800,3.11647,789.32103,-0.05516,8.07287,38.28912
37.49800,3.12484,789.40270,-0.05517,8.10636,38.29308
37.59800,3.13309,788.76624,-0.05516,8.13936,38.26221
37.69800,3.14140,788.95977,-0.05516,8.17260,38.27160
37.79800,3.14983,788.24265,-0.05517,8.20632,38.23681
37.89800,3.15808,788.34994,-0.05517,8.23933,38.24201
37.99800,3.16645,787.01982,-0.05516,8.27281,38.17749
38.09800,3.17488,787.46518,-0.05516,8.30653,38.19909
38.19800,3.18313,786.44231,-0.05518,8.33953,38.14948
38.29800,3.19150,786.39686,-0.05516,8.37302,38.14727
38.39800,3.19975,786.28222,-0.05516,8.40602,38.14171
38.49800,3.20806,785.51015,-0.05517,8.43926,38.10426
38.59800,3.21650,785.62116,-0.05517,8.47299,38.10964
38.69800,3.22481,785.21315,-0.05515,8.50623,38.08985
38.79800,3.23312,784.24206,-0.05518,8.53947,38.04274
38.89800,3.24155,784.27875,-0.05517,8.57319,38.04453
38.99800,3.24980,784.33380,-0.05516,8.60620,38.04719
39.09800,3.25811,783.34380,-0.05518,8.63944,37.99917
39.19800,3.26654,783.72825,-0.05517,8.67316,38.01782
39.29800,3.27479,782.53094,-0.05517,8.70616,37.95974
39.39800,3.28316,782.27250,-0.05518,8.73965,37.94720
39.49800,3.29159,781.92009,-0.05518,8.77337,37.93011
39.59800,3.29990,781.42248,-0.05519,8.80661,37.90597
39.69800,3.30821,780.58285,-0.05520,8.83985,37.86524
39.79800,3.31652,781.47007,-0.05519,8.87310,37.90828
39.89800,3.32477,780.27504,-0.05520,8.90610,37.85031
39.99800,3.33314,779.87951,-0.05521,8.93958,37.83112
40.09800,3.34152,779.67937,-0.05520,8.97307,37.82141
40.19800,3.34983,779.43942,-0.05520,9.00631,37.80977
40.29800,3.35820,778.84207,-0.05518,9.03979,37.78080
40.39800,3.36651,778.22404,-0.05518,9.07303,37.75082
40.49800,3.37482,777.93957,-0.05518,9.10628,37.73701
40.59800,3.38313,777.16261,-0.05519,9.13952,37.69933
40.69800,3.39150,777.33048,-0.05518,9.17300,37.70747
40.79800,3.39981,777.04350,-0.05517,9.20624,37.69355
40.89800,3.40812,776.84806,-0.05519,9.23949,37.68407
40.99800,3.41649,776.09182,-0.05519,9.27297,37.64738
41.09800,3.42480,776.10854,-0.05518,9.30621,37.64819
41.19800,3.43323,775.05154,-0.05519,9.33993,37.59692
41.29800,3.44148,775.53471,-0.05517,9.37294,37.62036
41.39800,3.44979,774.65787,-0.05518,9.40618,37.57782
41.49800,3.45828,774.10708,-0.05518,9.44014,37.55111
41.59800,3.46648,773.33674,-0.05519,9.47291,37.51374
41.69800,3.47485,773.59201,-0.05518,9.50639,37.52612
41.79800,3.48328,773.36319,-0.05517,9.54011,37.51502
41.89800,3.49141,773.03075,-0.05519,9.57263,37.49889
41.99800,3.49978,772.78516,-0.05518,9.60612,37.48698
42.09800,3.50821,771.72890,-0.05516,9.63984,37.43575
42.19800,3.51646,771.61291,-0.05517,9.67284,37.43011
42.29800,3.52483,770.95302,-0.05519,9.70632,37.39811
42.39800,3.53326,770.31804,-0.05517,9.74004,37.36731
42.49800,3.54151,770.42370,-0.05517,9.77305,37.37243
42.59800,3.54988,770.11795,-0.05520,9.80653,37.35760
42.69800,3.55825,769.44618,-0.05518,9.84001,37.32501
42.79800,3.56644,769.69881,-0.05518,9.87278,37.33727
42.89800,3.57487,768.84590,-0.05518,9.90650,37.29589
42.99800,3.58312,769.09512,-0.05519,9.93950,37.30798
43.09800,3.59132,768.42653,-0.05518,9.97227,37.27555
43.19800,3.59987,768.46853,-0.05519,10.00647,37.27759
43.29800,3.60812,767.58037,-0.05519,10.03947,37.23450
43.39800,3.61637,767.85847,-0.05518,10.07247,37.24799
43.49800,3.62492,767.07187,-0.05519,10.10667,37.20984
43.59800,3.63311,766.51275,-0.05520,10.13944,37.18271
43.69800,3.64148,766.46158,-0.05519,10.17292,37.18023
43.79800,3.64997,765.87913,-0.05518,10.20688,37.15198
43.89800,3.65810,765.26315,-0.05519,10.23941,37.12210
43.99800,3.66647,765.19703,-0.05519,10.27289,37.11889
44.09800,3.67490,764.68345,-0.05518,10.30661,37.09398
44.19800,3.68315,764.57332,-0.05520,10.33961,37.08863
44.29800,3.69152,763.87608,-0.05519,10.37310,37.05481
44.39800,3.69989,762.95743,-0.05519,10.40658,37.01025
44.49800,3.70814,763.05084,-0.05519,10.43958,37.01478
44.59800,3.71651,762.42392,-0.05518,10.47306,36.98437
44.69800,3.72495,762.15304,-0.05520,10.50678,36.97123
44.79800,3.73314,762.13568,-0.05520,10.53955,36.97039
44.89800,3.74157,761.59416,-0.05518,10.57327,36.94412
44.99800,3.74988,761.19639,-0.05519,10.60651,36.92482
45.09800,3.75813,761.29767,-0.05520,10.63952,36.92974
45.19800,3.76656,760.33445,-0.05519,10.67324,36.88301
45.29800,3.77481,760.20733,-0.05519,10.70624,36.87684
45.39800,3.78312,760.38428,-0.05518,10.73949,36.88543
45.49800,3.79155,759.61621,-0.05519,10.77321,36.84817
45.59800,3.79980,759.24462,-0.05520,10.80621,36.83014
45.69800,3.80811,758.66207,-0.05518,10.83945,36.80188
45.79800,3.81654,758.54617,-0.05519,10.87317,36.79626
45.89800,3.82479,757.95152,-0.05520,10.90618,36.76742
45.99800,3.83310,757.46775,-0.05519,10.93942,36.74395
46.09800,3.84147,757.27776,-0.05520,10.97290,36.73473
46.19800,3.84973,757.11925,-0.05519,11.00591,36.72704
46.29800,3.85810,756.46602,-0.05518,11.03939,36.69536
46.39800,3.86653,756.15365,-0.05521,11.07311,36.68021
46.49800,3.87478,756.26946,-0.05520,11.10612,36.68582
46.59800,3.88315,755.71756,-0.05519,11.13960,36.65905
46.69800,3.89158,754.97027,-0.05520,11.17332,36.62280
46.79800,3.89983,755.26503,-0.05521,11.20632,36.63710
46.89800,3.90820,754.27787,-0.05517,11.23980,36.58921
46.99800,3.91651,754.40076,-0.05519,11.27305,36.59517
47.09800,3.92482,753.44066,-0.05524,11.30629,36.54860
47.19800,3.93319,753.22632,-0.05521,11.33977,36.53820
47.29800,3.94144,753.13612,-0.05518,11.37278,36.53383
47.39800,3.94975,752.76592,-0.05521,11.40602,36.51587
47.49800,3.95818,752.13728,-0.05523,11.43974,36.48537
47.59800,3.96649,751.57085,-0.05520,11.47298,36.45790
47.69800,3.97487,751.59539,-0.05521,11.50647,36.45909
47.79800,3.98318,751.47143,-0.05520,11.53971,36.45308
47.89800,3.99149,750.94379,-0.05521,11.57295,36.42748
47.99800,3.99986,750.28078,-0.05520,11.60643,36.39532
48.09800,4.00823,750.21512,-0.05521,11.63991,36.39213
48.19800,4.01654,749.52906,-0.05521,11.67316,36.35885
48.29800,4.02479,749.30480,-0.05521,11.70616,36.34797
48.39800,4.03322,749.27434,-0.05521,11.73988,36.34650
48.49800,4.04141,748.86354,-0.05520,11.77265,36.32657
48.59800,4.04984,748.33827,-0.05520,11.80637,36.30109
48.69800,4.05821,748.35951,-0.05520,11.83985,36.30212
48.79800,4.06646,747.77249,-0.05522,11.87285,36.27364
48.89800,4.07483,746.67865,-0.05522,11.90634,36.22058
48.99800,4.08320,747.35940,-0.05521,11.93982,36.25360
49.09800,4.09145,746.07856,-0.05523,11.97282,36.19147
49.19800,4.09982,745.96787,-0.05522,12.00630,36.18610
49.29800,4.10814,745.59543,-0.05523,12.03955,36.16804
49.39800,4.11645,744.77624,-0.05522,12.07279,36.12830
49.49800,4.12488,744.96684,-0.05523,12.10651,36.13754
49.59800,4.13319,744.82667,-0.05523,12.13976,36.13074
49.69800,4.14138,744.69480,-0.05522,12.17252,36.12435
49.79800,4.14981,744.09801,-0.05522,12.20624,36.09540
49.89800,4.15812,743.56366,-0.05522,12.23948,36.06948
49.99800,4.16649,743.33875,-0.05522,12.27297,36.05857
50.09800,4.17498,742.54964,-0.05522,12.30693,36.02029
50.19800,4.18317,742.52486,-0.05523,12.33969,36.01908
50.29800,4.19142,741.89925,-0.05519,12.37269,35.98874
50.39800,4.19985,741.58413,-0.05523,12.40641,35.97345
50.49800,4.20810,741.32700,-0.05521,12.43942,35.96098
50.59800,4.21647,741.03638,-0.05520,12.47290,35.94688
50.69800,4.22490,740.20578,-0.05521,12.50662,35.90659
50.79800,4.23316,739.83506,-0.05521,12.53963,35.88861
50.89800,4.24153,739.66999,-0.05519,12.57311,35.88060
50.99800,4.24990,739.26509,-0.05520,12.60659,35.86096
51.09800,4.25815,738.94397,-0.05520,12.63959,35.84538
51.19800,4.26652,738.93387,-0.05520,12.67308,35.84489
51.29800,4.27489,738.08092,-0.05519,12.70656,35.80352
51.39800,4.28314,737.93568,-0.05520,12.73956,35.79647
51.49800,4.29151,737.44571,-0.05521,12.77305,35.77270
51.59800,4.29982,737.10880,-0.05522,12.80629,35.75636
51.69800,4.30813,736.78116,-0.05520,12.83953,35.74047
51.79800,4.31650,736.05520,-0.05521,12.87301,35.70525
51.89800,4.32481,736.41413,-0.05520,12.90626,35.72266
51.99800,4.33312,735.34208,-0.05520,12.93950,35.67066
52.09800,4.34161,735.09365,-0.05522,12.97346,35.65861
52.19800,4.34986,734.64653,-0.05520,13.00646,35.63692
52.29800,4.35818,734.28228,-0.05521,13.03971,35.61925
52.39800,4.36661,733.47101,-0.05522,13.07343,35.57990
52.49800,4.37486,733.35092,-0.05521,13.10643,35.57407
52.59800,4.38317,732.68139,-0.05522,13.13968,35.54159
52.69800,4.39148,732.36474,-0.05522,13.17292,35.52623
52.79800,4.39973,732.49815,-0.05520,13.20592,35.53270
52.89800,4.40816,731.94718,-0.05524,13.23964,35.50597
52.99800,4.41653,731.57209,-0.05523,13.27312,35.48778
53.09800,4.42478,730.89697,-0.05523,13.30613,35.45503
53.19800,4.43321,729.87690,-0.05524,13.33985,35.40555
53.29800,4.44152,730.14614,-0.05523,13.37309,35.41861
53.39800,4.44983,729.64760,-0.05526,13.40633,35.39442
53.49800,4.45814,728.83214,-0.05523,13.43958,35.35487
53.59800,4.46645,729.12327,-0.05523,13.47282,35.36899
53.69800,4.47477,728.67167,-0.05525,13.50607,35.34708
53.79800,4.48314,727.88596,-0.05523,13.53955,35.30897
53.89800,4.49145,728.29342,-0.05522,13.57279,35.32874
53.99800,4.49976,726.66770,-0.05523,13.60603,35.24987
54.09800,4.50813,727.14123,-0.05524,13.63951,35.27284
54.19800,4.51644,726.83105,-0.05522,13.67276,35.25780
54.29800,4.52481,726.14346,-0.05523,13.70624,35.22444
54.39800,4.53324,726.08716,-0.05523,13.73996,35.22171
54.49800,4.54155,724.64622,-0.05522,13.77320,35.15181
54.59800,4.54986,724.18982,-0.05525,13.80645,35.12967
54.69800,4.55817,724.41292,-0.05524,13.83969,35.14050
54.79800,4.56648,723.66791,-0.05525,13.87293,35.10435
54.89800,4.57485,722.99470,-0.05523,13.90641,35.07170
54.99800,4.58322,722.98138,-0.05522,13.93990,35.07105
55.09800,4.59153,722.58087,-0.05525,13.97314,35.05162
55.19800,4.59984,721.98100,-0.05521,14.00638,35.02253
55.29800,4.60816,721.22510,-0.05523,14.03963,34.98586
55.39800,4.61659,720.80130,-0.05523,14.07335,34.96530
55.49800,4.62490,720.22541,-0.05521,14.10659,34.93736
55.59800,4.63327,720.41554,-0.05523,14.14007,34.94659
55.69800,4.64152,719.79612,-0.05525,14.17308,34.91654
55.79800,4.64983,719.04967,-0.05521,14.20632,34.88033
55.89800,4.65814,718.80319,-0.05514,14.23956,34.86837
55.99800,4.66645,718.42801,-0.05523,14.27280,34.85017
56.09800,4.67482,717.66973,-0.05529,14.30629,34.81339
56.19800,4.68307,717.62013,-0.05524,14.33929,34.81099
56.29800,4.69150,716.44322,-0.05518,14.37301,34.75389
56.39800,4.69987,716.20890,-0.05522,14.40649,34.74253
56.49800,4.70818,715.51302,-0.05524,14.43974,34.70877
56.59800,4.71655,715.01010,-0.05525,14.47322,34.68438
56.69800,4.72486,714.75636,-0.05522,14.50646,34.67207
56.79800,4.73312,713.85093,-0.05518,14.53947,34.62814
56.89800,4.74143,713.98034,-0.05523,14.57271,34.63442
56.99800,4.74986,712.96962,-0.05523,14.60643,34.58539
57.09800,4.75811,712.73269,-0.05520,14.63943,34.57390
57.19800,4.76648,712.18801,-0.05520,14.67292,34.54748
57.29800,4.77485,711.45841,-0.05522,14.70640,34.51208
57.39800,4.78316,710.92662,-0.05523,14.73964,34.48629
57.49800,4.79153,710.38995,-0.05521,14.77312,34.46025
57.59800,4.79990,710.35651,-0.05521,14.80660,34.45863
57.69800,4.80815,709.20661,-0.05521,14.83961,34.40285
57.79800,4.81652,709.27716,-0.05523,14.87309,34.40628
57.89800,4.82489,708.18197,-0.05522,14.90657,34.35315
57.99800,4.83320,707.58974,-0.05523,14.93982,34.32442
58.09800,4.84157,707.50914,-0.05522,14.97330,34.32051
58.19800,4.84982,707.03323,-0.05521,15.00630,34.29742
58.29800,4.85814,705.98871,-0.05523,15.03955,34.24676
58.39800,4.86651,705.87830,-0.05522,15.07303,34.24140
58.49800,4.87482,705.38591,-0.05523,15.10627,34.21751
58.59800,4.88319,704.15586,-0.05522,15.13975,34.15785
58.69800,4.89156,704.49603,-0.05522,15.17323,34.17435
58.79800,4.89981,703.22580,-0.05523,15.20624,34.11273
58.89800,4.90818,702.99879,-0.05522,15.23972,34.10172
58.99800,4.91649,702.13182,-0.05521,15.27296,34.05966
59.09800,4.92474,701.52367,-0.05522,15.30597,34.03016
59.19800,4.93311,700.38559,-0.05522,15.33945,33.97496
59.29800,4.94148,700.07551,-0.05521,15.37293,33.95992
59.39800,4.94979,699.50325,-0.05522,15.40617,33.93216
59.49800,4.95810,699.01724,-0.05521,15.43942,33.90858
59.59800,4.96653,698.31111,-0.05522,15.47314,33.87432
59.69800,4.97490,697.45099,-0.05523,15.50662,33.83260
59.79800,4.98321,696.90840,-0.05523,15.53986,33.80628
59.89800,4.99153,696.32521,-0.05524,15.57311,33.77799
59.99800,4.99984,695.51389,-0.05520,15.60635,33.73864
60.09800,5.00821,694.39765,-0.05523,15.63983,33.68449
60.19800,5.01646,693.49655,-0.05529,15.67284,33.64077
60.29800,5.02483,692.77645,-0.05523,15.70632,33.60584
60.39800,5.03320,692.27717,-0.05522,15.73980,33.58162
60.49800,5.04145,691.58445,-0.05528,15.77280,33.54802
60.59800,5.04988,691.28876,-0.05527,15.80652,33.53368
60.69800,5.05819,689.75161,-0.05525,15.83977,33.45911
60.79800,5.06650,688.71253,-0.05527,15.87301,33.40871
60.89800,5.07487,688.09893,-0.05525,15.90649,33.37894
60.99800,5.08312,686.53203,-0.05526,15.93950,33.30293
61.09800,5.09137,685.85635,-0.05527,15.97250,33.27016
61.19800,5.09974,684.66603,-0.05524,16.00598,33.21242
61.29800,5.10817,683.27272,-0.05524,16.03970,33.14483
61.39800,5.11649,682.63612,-0.05525,16.07295,33.11395
61.49800,5.12480,681.63541,-0.05524,16.10619,33.06540
61.59800,5.13317,680.43657,-0.05524,16.13967,33.00725
61.69800,5.14142,678.70379,-0.05524,16.17268,32.92319
61.79800,5.14979,677.16115,-0.05523,16.20616,32.84836
61.89800,5.15816,675.71248,-0.05523,16.23964,32.77809
61.99800,5.16647,673.62874,-0.05525,16.27288,32.67701
62.09800,5.17484,671.48199,-0.05524,16.30637,32.57287
62.19800,5.18315,668.50893,-0.05525,16.33961,32.42865
62.29800,5.19146,665.40861,-0.05523,16.37285,32.27826
62.39800,5.19983,659.30951,-0.05524,16.40633,31.98240
62.49800,5.20814,648.12037,-0.05526,16.43957,31.43963
62.59800,5.21651,457.70132,-0.05525,16.47306,22.20260
62.63600,5.21974,2.26787,-0.05527,16.48597,0.11001