File: Manufatura Aditiva/Dados/Ensaios AMR/Ensaios/Ensaios SLS/Tracao_OLABI_07_06_2018_SLS_YX5.is_metal_RawData/Specimen_RawData_1.csv
Time,Extension,Load,Strain 1,Tensile strain,Tensile stress
(sec),(mm),(N),(mm/mm),(%),(MPa)
0.00000,0.00006,23.25045,0.00103,0.10321,1.13221
0.20000,0.01381,29.48584,0.00121,0.12089,1.43585
0.40000,0.03270,40.13589,0.00152,0.15184,1.95446
0.60000,0.04986,49.22468,0.00180,0.18043,2.39705
0.80000,0.06673,57.75454,0.00208,0.20802,2.81242
1.00000,0.08335,65.85474,0.00235,0.23528,3.20687
1.20000,0.10003,74.43991,0.00262,0.26233,3.62494
1.40000,0.11683,83.50326,0.00290,0.29005,4.06629
1.60000,0.13339,90.40807,0.00318,0.31786,4.40253
1.80000,0.14995,98.29807,0.00345,0.34474,4.78674
2.00000,0.16657,106.61674,0.00372,0.37195,5.19183
2.20000,0.18331,113.86184,0.00400,0.39971,5.54463
2.40000,0.19994,120.26427,0.00424,0.42360,5.85641
2.60000,0.21668,128.57092,0.00451,0.45126,6.26091
2.80000,0.23336,136.22757,0.00478,0.47827,6.63376
3.00000,0.24998,143.71132,0.00505,0.50546,6.99819
3.20000,0.26672,150.74835,0.00533,0.53300,7.34087
3.40000,0.28340,158.94491,0.00560,0.56043,7.74001
3.60000,0.30002,165.77764,0.00587,0.58723,8.07273
3.80000,0.31665,170.91935,0.00606,0.60621,8.32312
4.00000,0.33327,177.82794,0.00633,0.63333,8.65954
4.20000,0.34995,184.83161,0.00661,0.66090,9.00059
4.40000,0.36663,192.26805,0.00688,0.68762,9.36272
4.60000,0.38331,199.66622,0.00715,0.71519,9.72298
4.80000,0.39999,206.82416,0.00742,0.74246,10.07154
5.00000,0.41661,213.40931,0.00770,0.76989,10.39221
5.20000,0.43335,220.43814,0.00797,0.79660,10.73449
5.40000,0.45010,227.56346,0.00824,0.82408,11.08147
5.60000,0.46672,234.53757,0.00852,0.85179,11.42108
5.80000,0.48334,241.66587,0.00879,0.87860,11.76820
6.00000,0.50002,246.26353,0.00900,0.89969,11.99209
6.20000,0.51664,253.17916,0.00927,0.92679,12.32885
6.40000,0.53326,260.59372,0.00955,0.95459,12.68991
6.60000,0.55000,267.31715,0.00982,0.98220,13.01732
6.80000,0.56674,273.74392,0.01009,1.00893,13.33028
7.00000,0.58331,280.79685,0.01036,1.03615,13.67373
7.20000,0.59993,287.46182,0.01064,1.06350,13.99829
7.40000,0.61673,294.36597,0.01091,1.09076,14.33449
7.60000,0.63329,300.39581,0.01118,1.11829,14.62812
7.80000,0.64997,304.86216,0.01139,1.13941,14.84562
8.00000,0.66671,311.22437,0.01167,1.16704,15.15543
8.20000,0.68333,317.92533,0.01194,1.19412,15.48174
8.40000,0.70002,323.90926,0.01222,1.22186,15.77314
8.60000,0.71664,330.18312,0.01250,1.25018,16.07865
8.80000,0.73344,336.13096,0.01278,1.27761,16.36829
9.00000,0.75000,342.55851,0.01305,1.30508,16.68128
9.20000,0.76662,348.20216,0.01333,1.33286,16.95611
9.40000,0.78336,352.21325,0.01354,1.35395,17.15143
9.60000,0.79992,358.37293,0.01382,1.38190,17.45139
9.80000,0.81660,363.92808,0.01409,1.40950,17.72190
10.00000,0.83341,369.86931,0.01437,1.43734,18.01122
10.20000,0.84997,375.54640,0.01465,1.46524,18.28767
10.40000,0.86671,381.53341,0.01493,1.49311,18.57921
10.60000,0.88333,384.37883,0.01514,1.51408,18.71777
10.80000,0.90007,390.00779,0.01542,1.54180,18.99188
11.00000,0.91669,395.54788,0.01570,1.56967,19.26166
11.20000,0.93331,400.72948,0.01598,1.59754,19.51399
11.40000,0.95000,406.05827,0.01625,1.62547,19.77348
11.60000,0.96656,409.86929,0.01648,1.64800,19.95906
11.80000,0.98330,414.98360,0.01675,1.67546,20.20811
12.00000,1.00010,420.33354,0.01703,1.70334,20.46863
12.20000,1.01666,425.69852,0.01731,1.73118,20.72988
12.40000,1.03328,430.59308,0.01760,1.75986,20.96823
12.60000,1.04996,432.89256,0.01782,1.78174,21.08021
12.80000,1.06664,438.16958,0.01810,1.80978,21.33718
13.00000,1.08333,442.67732,0.01838,1.83792,21.55669
13.20000,1.10001,447.73309,0.01866,1.86646,21.80288
13.40000,1.11675,451.03645,0.01890,1.89032,21.96374
13.60000,1.13325,455.91304,0.01918,1.91819,22.20121
13.80000,1.14993,460.76328,0.01947,1.94690,22.43740
14.00000,1.16679,464.87935,0.01976,1.97583,22.63784
14.20000,1.18329,468.67239,0.02003,2.00278,22.82255
14.40000,1.19998,472.86521,0.02029,2.02931,23.02672
14.60000,1.21672,476.96428,0.02057,2.05697,23.22633
14.80000,1.23334,480.96674,0.02085,2.08451,23.42123
15.00000,1.24990,484.92518,0.02112,2.11218,23.61399
15.20000,1.26664,488.71315,0.02140,2.13996,23.79845
15.40000,1.28344,492.38410,0.02168,2.16781,23.97721
15.60000,1.29994,496.03307,0.02195,2.19487,24.15491
15.80000,1.31656,499.34098,0.02222,2.22246,24.31599
16.00000,1.33343,503.59941,0.02250,2.25034,24.52336
16.20000,1.34993,506.67017,0.02278,2.27824,24.67289
16.40000,1.36667,510.45581,0.02306,2.30640,24.85724
16.60000,1.38341,513.76577,0.02335,2.33500,25.01842
16.80000,1.39997,517.02852,0.02364,2.36359,25.17730
17.00000,1.41659,520.13830,0.02392,2.39212,25.32874
17.20000,1.43333,524.76404,0.02422,2.42184,25.55399
17.40000,1.45001,527.22450,0.02451,2.45064,25.67381
17.60000,1.46664,530.54439,0.02480,2.48020,25.83547
17.80000,1.48320,534.19308,0.02510,2.50976,26.01315
18.00000,1.50006,534.94922,0.02532,2.53224,26.04997
18.20000,1.51656,539.00755,0.02562,2.56209,26.24760
18.40000,1.53330,542.36166,0.02594,2.59353,26.41093
18.60000,1.55004,545.36602,0.02625,2.62506,26.55723
18.80000,1.56666,549.32972,0.02657,2.65716,26.75025
19.00000,1.58341,552.61226,0.02689,2.68924,26.91010
19.20000,1.60003,556.46501,0.02721,2.72149,27.09771
19.40000,1.61671,559.68943,0.02753,2.75337,27.25473
19.60000,1.63333,562.73257,0.02786,2.78600,27.40292
19.80000,1.65007,566.19029,0.02819,2.81908,27.57129
20.00000,1.66663,566.33004,0.02839,2.83901,27.57810
20.20000,1.68325,569.21043,0.02872,2.87171,27.71836
20.40000,1.69993,573.16781,0.02904,2.90439,27.91107
20.60000,1.71674,576.71038,0.02938,2.93780,28.08358
20.80000,1.73330,579.02019,0.02970,2.97036,28.19606
21.00000,1.74992,582.24900,0.03004,3.00363,28.35329
21.20000,1.76672,584.89963,0.03037,3.03716,28.48237
21.40000,1.78334,587.55619,0.03071,3.07050,28.61173
21.60000,1.80002,590.14703,0.03104,3.12056,28.73789
21.77800,1.81503,593.42785,0.03134,3.18059,28.89766
21.97800,1.83153,595.95304,0.03167,3.24659,29.02062
22.17800,1.84809,594.91117,0.03188,3.31284,28.96989
22.37800,1.86483,597.32655,0.03219,3.37981,29.08751
22.57800,1.88152,600.56066,0.03253,3.44653,29.24500
22.77800,1.89814,603.11765,0.03286,3.51302,29.36951
22.97800,1.91476,605.83591,0.03321,3.57950,29.50188
23.17800,1.93150,608.64179,0.03183,3.64647,29.63852
23.37800,1.94812,610.79194,0.03468,3.71295,29.74322
23.57800,1.96486,613.47242,0.02473,3.77992,29.87375
23.77800,1.98160,614.95085,0.00247,3.84688,29.94575
23.97800,1.99822,618.54403,0.00186,3.91337,30.12072
24.17800,2.01485,621.04147,-0.00062,3.97985,30.24233
24.37800,2.03153,622.80749,-0.00031,4.04658,30.32833
24.57800,2.04821,622.35422,-0.00060,4.11330,30.30626
24.77800,2.06483,625.14627,-0.00056,4.17979,30.44222
24.97800,2.08145,627.41474,0.00147,4.24627,30.55269
25.17800,2.09813,629.90068,-0.00018,4.31300,30.67374
25.37800,2.11475,632.22791,0.00548,4.37948,30.78707
25.57800,2.13144,634.79142,0.00478,4.44621,30.91191
25.77800,2.14818,636.67884,-0.01303,4.51317,31.00381
25.97800,2.16486,638.38684,-0.05230,4.57990,31.08699
26.17800,2.18154,640.95142,-0.07921,4.64662,31.21187
26.37800,2.19816,643.04727,-0.06877,4.71311,31.31393
26.57800,2.21484,645.58089,-0.06628,4.77984,31.43731
26.77800,2.23158,647.27897,-0.06600,4.84680,31.52000
26.97800,2.24820,649.20667,-0.06444,4.91329,31.61387
27.17800,2.26489,648.78673,-0.06718,4.98001,31.59342
27.37800,2.28151,650.85310,-0.06420,5.04650,31.69405
27.57800,2.29813,653.15207,-0.06648,5.11298,31.80600
27.77800,2.31487,655.41626,-0.06551,5.17995,31.91626
27.97800,2.33149,657.64543,-0.06506,5.24643,32.02481
28.17800,2.34817,659.73066,-0.06664,5.31316,32.12635
28.37800,2.36479,661.07009,-0.06454,5.37964,32.19157
28.57800,2.38148,663.31178,-0.06644,5.44637,32.30074
28.77800,2.39816,665.74872,-0.06534,5.51309,32.41941
28.97800,2.41478,667.63712,-0.06541,5.57958,32.51136
29.17800,2.43152,669.19867,-0.06628,5.64654,32.58741
29.37800,2.44814,671.53005,-0.06483,5.71303,32.70094
29.57800,2.46482,672.33066,-0.06633,5.77975,32.73992
29.77800,2.48156,674.03023,-0.06526,5.84672,32.82269
29.97800,2.49812,676.29083,-0.06560,5.91297,32.93277
30.17800,2.51481,675.59201,-0.06602,5.97969,32.89874
30.37800,2.53155,677.41987,-0.06511,6.04666,32.98775
30.57800,2.54817,679.37439,-0.06614,6.11314,33.08292
30.77800,2.56479,681.18405,-0.06529,6.17963,33.17105
30.97800,2.58147,683.13181,-0.06572,6.24635,33.26590
31.17800,2.59815,684.37271,-0.06586,6.31308,33.32632
31.37800,2.61477,687.24076,-0.06529,6.37956,33.46599
31.57800,2.63151,687.98456,-0.06608,6.44653,33.50220
31.77800,2.64820,690.03543,-0.06537,6.51325,33.60208
31.97800,2.66476,691.19642,-0.06573,6.57950,33.65861
32.17800,2.68150,693.10870,-0.06574,6.64646,33.75173
32.37800,2.69818,694.17260,-0.06545,6.71319,33.80354
32.57800,2.71486,696.11236,-0.06595,6.77991,33.89800
32.77800,2.73154,697.72485,-0.06538,6.84664,33.97652
32.97800,2.74816,699.33739,-0.06578,6.91312,34.05505
33.17800,2.76485,700.96436,-0.06565,6.97985,34.13427
33.37800,2.78153,702.60335,-0.06551,7.04657,34.21408
33.57800,2.79815,703.79232,-0.06584,7.11306,34.27198
33.77800,2.81483,704.63801,-0.06540,7.17979,34.31316
33.97800,2.83145,704.02101,-0.06574,7.24627,34.28312
34.17800,2.84807,705.72966,-0.06567,7.31276,34.36633
34.37800,2.86481,706.81763,-0.06553,7.37972,34.41930
34.57800,2.88155,708.89029,-0.06578,7.44669,34.52024
34.77800,2.89818,709.54156,-0.06551,7.51317,34.55195
34.97800,2.91492,711.69739,-0.06571,7.58014,34.65693
35.17800,2.93154,713.11207,-0.06567,7.64662,34.72582
35.37800,2.94804,714.90756,-0.06555,7.71263,34.81325
35.57800,2.96490,716.34562,-0.06575,7.78007,34.88328
35.77800,2.98158,717.32784,-0.06556,7.84680,34.93111
35.97800,2.99808,718.74945,-0.06567,7.91280,35.00034
36.17800,3.01477,719.73498,-0.06564,7.97953,35.04833
36.37800,3.03151,721.12214,-0.06561,8.04649,35.11588
36.57800,3.04813,722.45551,-0.06569,8.11298,35.18081
36.77800,3.06481,724.05874,-0.06555,8.17970,35.25888
36.97800,3.08161,725.03290,-0.06571,8.24691,35.30632
37.17800,3.09817,726.69694,-0.06557,8.31315,35.38735
37.37800,3.11479,728.35251,-0.06562,8.37964,35.46797
37.57800,3.13159,729.30935,-0.06569,8.44684,35.51456
37.77800,3.14822,730.74372,-0.06556,8.51333,35.58442
37.97800,3.16478,730.56906,-0.06567,8.57958,35.57591
38.17800,3.18152,732.24143,-0.06560,8.64654,35.65734
38.37800,3.19814,733.46109,-0.06566,8.71303,35.71674
38.57800,3.21476,734.43712,-0.06567,8.77951,35.76427
38.77800,3.23144,735.94707,-0.06560,8.84624,35.83780
38.97800,3.24818,737.00515,-0.06572,8.91320,35.88932
39.17800,3.26481,738.27580,-0.06561,8.97969,35.95119
39.37800,3.28149,739.13201,-0.06566,9.04641,35.99289
39.57800,3.29817,736.39438,-0.06564,9.11314,35.85958
39.77800,3.31479,738.65391,-0.06562,9.17962,35.96961
39.97800,3.33153,740.24112,-0.06568,9.24659,36.04690
40.17800,3.34821,741.42520,-0.06559,9.31331,36.10456
40.37800,3.36489,742.45380,-0.06567,9.38004,36.15465
40.57800,3.38145,744.35901,-0.06566,9.44629,36.24743
40.77800,3.39814,744.89475,-0.06563,9.51301,36.27351
40.97800,3.41494,746.45816,-0.06567,9.58021,36.34965
41.17800,3.43150,747.06343,-0.06561,9.64646,36.37912
41.37800,3.44812,748.08006,-0.06565,9.71295,36.42863
41.57800,3.46486,749.08738,-0.06566,9.77991,36.47768
41.77800,3.48148,750.25330,-0.06564,9.84640,36.53445
41.97800,3.49816,751.53518,-0.06562,9.91312,36.59688
42.17800,3.51490,752.96499,-0.06565,9.98009,36.66650
42.37800,3.53159,753.48127,-0.06565,10.04681,36.69164
42.57800,3.54815,754.38786,-0.06566,10.11306,36.73579
42.77800,3.56477,755.41106,-0.06567,10.17954,36.78562
42.97800,3.58163,756.04157,-0.06561,10.24699,36.81632
43.17800,3.59807,757.63902,-0.06569,10.31275,36.89411
43.37800,3.61475,757.52763,-0.06565,10.37948,36.88869
43.57800,3.63155,759.50758,-0.06565,10.44668,36.98510
43.77800,3.64812,761.15094,-0.06566,10.51293,37.06513
43.97800,3.66480,761.57493,-0.06566,10.57966,37.08577
44.17800,3.68160,761.95835,-0.06568,10.64686,37.10445
44.37800,3.69822,762.86215,-0.06568,10.71334,37.14846
44.57800,3.71478,763.30882,-0.06563,10.77959,37.17021
44.77800,3.73146,764.45933,-0.06570,10.84632,37.22623
44.97800,3.74832,765.21635,-0.06561,10.91376,37.26310
45.17800,3.76476,766.56346,-0.06568,10.97953,37.32870
45.37800,3.78145,767.18167,-0.06567,11.04625,37.35880
45.57800,3.79825,767.31448,-0.06560,11.11346,37.36527
45.77800,3.81475,768.62909,-0.06570,11.17946,37.42929
45.97800,3.83143,769.68824,-0.06563,11.24619,37.48086
46.17800,3.84823,770.05010,-0.06565,11.31339,37.49848
46.37800,3.86485,771.15232,-0.06569,11.37988,37.55216
46.57800,3.88153,771.40960,-0.06561,11.44660,37.56469
46.77800,3.89810,772.02665,-0.06573,11.51285,37.59473
46.97800,3.91484,773.13581,-0.06560,11.57981,37.64875
47.17800,3.93146,769.49573,-0.06565,11.64630,37.47149
47.37800,3.94814,771.35540,-0.06565,11.71302,37.56205
47.57800,3.96494,772.83685,-0.06561,11.78023,37.63419
47.77800,3.98144,773.71350,-0.06568,11.84624,37.67688
47.97800,3.99812,774.53572,-0.06558,11.91296,37.71692
48.17800,4.01486,776.36540,-0.06570,11.97992,37.80602
48.37800,4.03149,776.83595,-0.06562,12.04641,37.82893
48.57800,4.04817,777.02291,-0.06566,12.11313,37.83803
48.77800,4.06485,777.83978,-0.06573,12.17986,37.87781
48.97800,4.08147,779.10400,-0.06561,12.24635,37.93937
49.17800,4.09809,779.83439,-0.06570,12.31283,37.97494
49.37800,4.11477,781.09177,-0.06563,12.37956,38.03617
49.57800,4.13157,781.63324,-0.06566,12.44676,38.06254
49.77800,4.14813,782.12824,-0.06569,12.51301,38.08664
49.97800,4.16476,783.16601,-0.06562,12.57949,38.13718
50.17800,4.18156,783.33076,-0.06571,12.64670,38.14520
50.37800,4.19806,784.43391,-0.06564,12.71271,38.19892
50.57800,4.21486,784.72625,-0.06565,12.77991,38.21315
50.77800,4.23160,785.85278,-0.06571,12.84687,38.26801
50.97800,4.24816,786.61712,-0.06564,12.91312,38.30523
51.17800,4.26472,786.74313,-0.06567,12.97937,38.31137
51.37800,4.28153,787.65443,-0.06564,13.04657,38.35575
51.57800,4.29821,788.41979,-0.06567,13.11329,38.39302
51.77800,4.31477,788.74873,-0.06567,13.17954,38.40903
51.97800,4.33145,788.91860,-0.06567,13.24627,38.41730
52.17800,4.34825,790.28420,-0.06567,13.31347,38.48381
52.37800,4.36481,791.13813,-0.06568,13.37972,38.52539
52.57800,4.38149,791.36742,-0.06566,13.44644,38.53656
52.77800,4.39817,791.24896,-0.06570,13.51317,38.53078
52.97800,4.41486,792.43677,-0.06569,13.57989,38.58863
53.17800,4.43148,792.94574,-0.06563,13.64638,38.61341
53.37800,4.44816,793.01195,-0.06568,13.71310,38.61664
53.57800,4.46490,793.66416,-0.06564,13.78007,38.64840
53.77800,4.48152,794.40204,-0.06567,13.84655,38.68433
53.97800,4.49814,794.84712,-0.06566,13.91304,38.70600
54.17800,4.51476,795.34845,-0.06566,13.97952,38.73042
54.37800,4.53145,795.50724,-0.06567,14.04625,38.73815
54.57800,4.54813,796.72663,-0.06568,14.11297,38.79753
54.77800,4.56481,797.02502,-0.06565,14.17970,38.81206
54.97800,4.58155,797.10670,-0.06565,14.24666,38.81604
55.17800,4.59823,798.48468,-0.06570,14.31339,38.88314
55.37800,4.61485,799.28916,-0.06564,14.37988,38.92231
55.57800,4.63147,798.37814,-0.06568,14.44636,38.87795
55.77800,4.64821,799.41591,-0.06568,14.51333,38.92849
55.97800,4.66490,799.83287,-0.06567,14.58005,38.94879
56.17800,4.68164,799.97825,-0.06570,14.64701,38.95587
56.37800,4.69814,801.22445,-0.06561,14.71302,39.01656
56.57800,4.71476,801.30631,-0.06568,14.77951,39.02054
56.77800,4.73150,801.56075,-0.06567,14.84647,39.03293
56.97800,4.74812,801.91959,-0.06568,14.91296,39.05040
57.17800,4.76480,802.49598,-0.06570,14.97968,39.07847
57.37800,4.78149,803.47201,-0.06562,15.04641,39.12600
57.57800,4.79811,803.22223,-0.06567,15.11290,39.11384
57.77800,4.81485,803.41641,-0.06568,15.17986,39.12329
57.97800,4.83153,804.13297,-0.06565,15.24658,39.15819
58.17800,4.84827,804.51304,-0.06569,15.31355,39.17670
58.37800,4.86483,805.05796,-0.06564,15.37980,39.20323
58.57800,4.88151,805.29964,-0.06569,15.44652,39.21500
58.77800,4.89819,805.59980,-0.06566,15.51324,39.22962
58.97800,4.91482,806.19752,-0.06566,15.57973,39.25872
59.17800,4.93150,806.54528,-0.06570,15.64645,39.27566
59.37800,4.94818,803.08896,-0.06564,15.71318,39.10735
59.57800,4.96480,804.01814,-0.06567,15.77967,39.15260
59.77800,4.98148,805.12827,-0.06566,15.84639,39.20665
59.97800,4.99816,805.16906,-0.06567,15.91312,39.20864
60.17800,5.01484,805.97233,-0.06568,15.97984,39.24776
60.37800,5.03152,806.70891,-0.06562,16.04657,39.28363
60.57800,5.04815,806.91064,-0.06569,16.11305,39.29345
60.77800,5.06483,807.34156,-0.06566,16.17978,39.31443
60.97800,5.08151,808.19819,-0.06563,16.24650,39.35615
61.17800,5.09813,808.87862,-0.06569,16.31299,39.38928
61.37800,5.11487,809.12765,-0.06567,16.37995,39.40141
61.57800,5.13149,809.12318,-0.06564,16.44644,39.40119
61.77800,5.14811,810.33260,-0.06567,16.51292,39.46009
61.97800,5.16480,810.38475,-0.06566,16.57965,39.46263
62.17800,5.18148,810.79146,-0.06568,16.64637,39.48243
62.37800,5.19816,811.08781,-0.06568,16.71310,39.49686
62.57800,5.21484,811.45354,-0.06567,16.77982,39.51467
62.77800,5.23146,812.18975,-0.06567,16.84631,39.55052
62.97800,5.24814,812.46588,-0.06566,16.91304,39.56397
63.17800,5.26476,813.05774,-0.06568,16.97952,39.59279
63.37800,5.28156,812.88600,-0.06565,17.04672,39.58443
63.57800,5.29819,813.56000,-0.06569,17.11321,39.61725
63.77800,5.31487,813.91940,-0.06565,17.17994,39.63475
63.97800,5.33149,813.99456,-0.06567,17.24642,39.63841
64.17800,5.34817,814.57663,-0.06569,17.31315,39.66676
64.37801,5.36479,814.60252,-0.06564,17.37963,39.66801
64.57800,5.38147,814.91414,-0.06572,17.44636,39.68319
64.77800,5.39821,814.94227,-0.06565,17.51332,39.68456
64.97800,5.41478,815.69366,-0.06567,17.57957,39.72115
65.17800,5.43146,816.22703,-0.06571,17.64630,39.74712
65.37801,5.44820,816.16528,-0.06565,17.71326,39.74411
65.57800,5.46476,815.93553,-0.06570,17.77951,39.73293
65.77800,5.48150,816.61893,-0.06562,17.84647,39.76620
65.97801,5.49824,817.18862,-0.06573,17.91343,39.79395
66.17800,5.51480,816.95085,-0.06567,17.97968,39.78237
66.37801,5.53148,817.19439,-0.06566,18.04641,39.79423
66.57800,5.54817,817.35281,-0.06576,18.11313,39.80194
66.77800,5.56491,817.65903,-0.06564,18.18009,39.81686
66.97801,5.58147,817.96208,-0.06570,18.24634,39.83161
67.17800,5.59815,818.29708,-0.06567,18.31307,39.84793
67.37801,5.61489,818.25042,-0.06568,18.38003,39.84565
67.57800,5.63145,818.50085,-0.06574,18.44628,39.85785
67.77800,5.64819,818.78621,-0.06562,18.51324,39.87175
67.97801,5.66481,818.83967,-0.06569,18.57973,39.87435
68.17800,5.68144,819.52652,-0.06569,18.64621,39.90779
68.37801,5.69812,819.71008,-0.06565,18.71294,39.91673
68.57800,5.71480,820.09016,-0.06573,18.77966,39.93524
68.77800,5.73148,819.68475,-0.06565,18.84639,39.91550
68.97801,5.74822,820.01733,-0.06570,18.91335,39.93169
69.17800,5.76484,820.09844,-0.06567,18.97984,39.93565
69.37801,5.78152,820.68145,-0.06564,19.04656,39.96404
69.57800,5.79809,820.32960,-0.06572,19.11281,39.94690
69.77800,5.81483,820.80141,-0.06563,19.17978,39.96988
69.97801,5.83157,820.87833,-0.06568,19.24674,39.97362
70.17800,5.84813,821.04662,-0.06568,19.31299,39.98182
70.37801,5.86481,821.15093,-0.06562,19.37971,39.98690
70.57800,5.88149,821.38674,-0.06569,19.44644,39.99838
70.77800,5.89817,821.71503,-0.06564,19.51316,40.01437
70.97801,5.91485,821.61557,-0.06568,19.57989,40.00953
71.17800,5.93148,821.73953,-0.06565,19.64637,40.01556
71.37801,5.94822,821.81077,-0.06566,19.71334,40.01903
71.57800,5.96478,821.76160,-0.06567,19.77958,40.01664
71.77800,5.98152,822.09939,-0.06567,19.84655,40.03308
71.97801,5.99826,822.49902,-0.06565,19.91351,40.05254
72.17800,6.01482,822.71462,-0.06565,19.97976,40.06304
72.37801,6.03150,822.88515,-0.06566,20.04648,40.07135
72.57800,6.04819,822.57260,-0.06567,20.11321,40.05613
72.77800,6.06481,823.32809,-0.06566,20.17969,40.09291
72.97801,6.08143,823.37800,-0.06571,20.24618,40.09535
73.17800,6.09817,823.04655,-0.06565,20.31315,40.07921
73.37801,6.11497,823.10615,-0.06566,20.38035,40.08211
73.57800,6.13141,823.58178,-0.06569,20.44612,40.10527
73.77800,6.14809,823.35696,-0.06565,20.51284,40.09432
73.97801,6.16489,823.76013,-0.06568,20.58005,40.11396
74.17800,6.18152,823.82355,-0.06565,20.64653,40.11704
74.37801,6.19814,823.28143,-0.06569,20.71302,40.09064
74.57800,6.21488,824.16413,-0.06565,20.77998,40.13363
74.77800,6.23144,824.56330,-0.06567,20.84623,40.15306
74.97801,6.24806,824.20064,-0.06567,20.91271,40.13541
75.17800,6.26486,824.05685,-0.06565,20.97992,40.12840
75.37801,6.28154,824.23538,-0.06568,21.04664,40.13710
75.57800,6.29811,824.04511,-0.06563,21.11289,40.12783
75.77800,6.31473,824.58891,-0.06570,21.17938,40.15431
75.97801,6.33153,823.77307,-0.06567,21.24658,40.11459
76.17800,6.34815,824.54039,-0.06563,21.31306,40.15195
76.37801,6.36489,824.12232,-0.06569,21.38003,40.13159
76.57800,6.38157,824.95948,-0.06564,21.44675,40.17236
76.77800,6.39807,825.25937,-0.06568,21.51276,40.18696
76.97801,6.41475,825.15553,-0.06567,21.57948,40.18191
77.17800,6.43156,825.10207,-0.06568,21.64669,40.17930
77.37801,6.44818,825.05457,-0.06570,21.71318,40.17699
77.57800,6.46486,824.49596,-0.06565,21.77990,40.14979
77.77801,6.48148,824.59673,-0.06571,21.84639,40.15469
77.97801,6.49816,825.64577,-0.06566,21.91311,40.20578
78.17800,6.51472,825.01089,-0.06565,21.97936,40.17486
78.37801,6.53140,825.26514,-0.06570,22.04608,40.18724
78.57800,6.54832,825.13150,-0.06564,22.11377,40.18074
78.77801,6.56483,825.05718,-0.06570,22.17977,40.17712
78.97801,6.58145,824.88162,-0.06566,22.24626,40.16857
79.17800,6.59825,825.67045,-0.06567,22.31346,40.20698
79.37801,6.61481,825.70910,-0.06570,22.37971,40.20886
79.57800,6.63143,825.28908,-0.06562,22.44619,40.18841
79.77801,6.64823,825.70361,-0.06572,22.51340,40.20860
79.97801,6.66491,825.66300,-0.06565,22.58012,40.20662
80.17800,6.68142,825.69970,-0.06567,22.64613,40.20840
80.37801,6.69810,825.18710,-0.06567,22.71286,40.18344
80.57800,6.71496,825.60936,-0.06565,22.78030,40.20401
80.77801,6.73146,825.27222,-0.06571,22.84631,40.18759
80.97801,6.74808,824.83208,-0.06563,22.91279,40.16616
81.17800,6.76488,825.21234,-0.06573,22.98000,40.18467
81.37801,6.78144,825.80503,-0.06564,23.04624,40.21354
81.57800,6.79813,825.62221,-0.06564,23.11297,40.20463
81.77801,6.81493,825.37830,-0.06573,23.18017,40.19275
81.97801,6.83149,825.40093,-0.06563,23.24642,40.19386
82.17800,6.84811,825.39087,-0.06571,23.31290,40.19337
82.37801,6.86479,825.42589,-0.06566,23.37963,40.19507
82.57800,6.88153,826.04680,-0.06565,23.44659,40.22531
82.77801,6.89821,825.24465,-0.06571,23.51332,40.18624
82.97801,6.91483,825.17611,-0.06565,23.57980,40.18291
83.17800,6.93146,826.25449,-0.06568,23.64629,40.23542
83.37801,6.94814,825.19874,-0.06570,23.71302,40.18401
83.57800,6.96476,825.98636,-0.06565,23.77950,40.22236
83.77801,6.98150,825.80270,-0.06569,23.84646,40.21342
83.97801,6.99818,825.42989,-0.06567,23.91319,40.19527
84.17800,7.01486,825.43045,-0.06567,23.97992,40.19529
84.37801,7.03148,824.55687,-0.06570,24.04640,40.15275
84.57800,7.04816,825.87423,-0.06562,24.11313,40.21690
84.77801,7.06485,825.68759,-0.06570,24.17985,40.20782
84.97801,7.08153,825.20396,-0.06565,24.24658,40.18427
85.17800,7.09827,825.59874,-0.06565,24.31354,40.20349
85.37801,7.11477,825.21150,-0.06571,24.37955,40.18463
85.57800,7.13145,825.24242,-0.06560,24.44627,40.18614
85.77801,7.14819,825.27082,-0.06570,24.51324,40.18752
85.97801,7.16481,825.83604,-0.06567,24.57972,40.21505
86.17800,7.18144,825.20889,-0.06566,24.64621,40.18451
86.37801,7.19812,824.93015,-0.06570,24.71293,40.17093
86.57800,7.21486,825.30454,-0.06565,24.77990,40.18916
86.77801,7.23142,825.45364,-0.06572,24.84615,40.19642
86.97801,7.24816,824.98183,-0.06569,24.91311,40.17345
87.17800,7.26496,824.95809,-0.06564,24.98031,40.17229
87.37801,7.28146,825.26673,-0.06573,25.04632,40.18732
87.57800,7.29814,824.75981,-0.06563,25.11305,40.16264
87.77801,7.31495,824.27897,-0.06567,25.18025,40.13922
87.97801,7.33151,825.08102,-0.06572,25.24650,40.17828
88.17800,7.34813,824.42891,-0.06568,25.31298,40.14652
88.37801,7.36481,825.25872,-0.06573,25.37971,40.18693
88.57800,7.38149,824.30979,-0.06566,25.44643,40.14072
88.77801,7.39811,824.81699,-0.06572,25.51292,40.16542
88.97801,7.41479,824.44875,-0.06571,25.57964,40.14749
89.17800,7.43154,824.54924,-0.06566,25.64661,40.15238
89.37801,7.44816,824.59711,-0.06573,25.71310,40.15471
89.57800,7.46484,824.11682,-0.06564,25.77982,40.13132
89.77801,7.48152,824.51636,-0.06571,25.84654,40.15078
89.97801,7.49814,823.87840,-0.06566,25.91303,40.11972
90.17800,7.51494,824.04157,-0.06566,25.98023,40.12766
90.37801,7.53156,823.59407,-0.06572,26.04672,40.10587
90.57800,7.54818,823.91622,-0.06560,26.11321,40.12156
90.77801,7.56487,823.82848,-0.06571,26.17993,40.11728
90.97801,7.58143,822.94289,-0.06569,26.24618,40.07416
91.17800,7.59817,823.27425,-0.06564,26.31314,40.09029
91.37801,7.61485,823.06480,-0.06573,26.37987,40.08010
91.57800,7.63141,823.83212,-0.06569,26.44611,40.11746
91.77801,7.64815,823.42038,-0.06573,26.51308,40.09741
91.97801,7.66483,823.10736,-0.06571,26.57980,40.08217
92.17800,7.68146,823.44972,-0.06570,26.64629,40.09884
92.37801,7.69820,823.30713,-0.06572,26.71325,40.09190
92.57800,7.71488,823.10345,-0.06569,26.77998,40.08198
92.77801,7.73150,822.59420,-0.06571,26.84646,40.05718
92.97801,7.74812,822.77330,-0.06570,26.91295,40.06590
93.17800,7.76486,822.83597,-0.06567,26.97991,40.06895
93.37801,7.78142,822.15024,-0.06573,27.04616,40.03556
93.57800,7.79816,822.47071,-0.06568,27.11312,40.05117
93.77801,7.81485,822.59420,-0.06566,27.17985,40.05718
93.97801,7.83141,822.34237,-0.06572,27.24610,40.04491
94.17800,7.84815,822.46903,-0.06567,27.31306,40.05108
94.37801,7.86489,821.98428,-0.06575,27.38002,40.02748
94.57800,7.88157,821.70516,-0.06565,27.44675,40.01389
94.77801,7.89813,821.60793,-0.06570,27.51299,40.00915
94.97801,7.91487,822.17027,-0.06570,27.57996,40.03653
95.17800,7.93149,821.82521,-0.06564,27.64644,40.01973
95.37801,7.94818,821.12253,-0.06571,27.71317,39.98552
95.57800,7.96480,821.34036,-0.06563,27.77966,39.99612
95.77801,7.98154,821.79736,-0.06563,27.84662,40.01838
95.97801,7.99816,821.18809,-0.06566,27.91311,39.98871
96.17800,8.01478,821.24528,-0.06561,27.97959,39.99149
96.37801,8.03152,820.76453,-0.06574,28.04656,39.96808
96.57800,8.04814,820.38641,-0.06570,28.11304,39.94967
96.77801,8.06483,820.67773,-0.06568,28.17977,39.96386
96.97801,8.08145,820.27335,-0.06574,28.24625,39.94416
97.17800,8.09813,820.40541,-0.06565,28.31298,39.95059
97.37801,8.11475,819.68335,-0.06569,28.37946,39.91543
97.57800,8.13149,819.64247,-0.06567,28.44643,39.91344
97.77801,8.14817,819.89272,-0.06564,28.51315,39.92563
97.97801,8.16485,819.58612,-0.06567,28.57988,39.91070
98.17800,8.18153,818.90374,-0.06564,28.64660,39.87747
98.37801,8.19815,819.42296,-0.06568,28.71309,39.90275
98.57800,8.21484,819.20130,-0.06565,28.77982,39.89196
98.77801,8.23146,818.97071,-0.06568,28.84630,39.88073
98.97801,8.24820,819.26715,-0.06564,28.91326,39.89516
99.17800,8.26488,818.96307,-0.06565,28.97999,39.88036
99.37801,8.28150,819.21602,-0.06567,29.04648,39.89267
99.57800,8.29806,818.70100,-0.06566,29.11272,39.86760
99.77801,8.31486,817.97894,-0.06569,29.17993,39.83243
99.97801,8.33155,817.79798,-0.06568,29.24665,39.82362
100.17800,8.34817,817.95715,-0.06570,29.31314,39.83137
100.37801,8.36485,817.81158,-0.06566,29.37986,39.82428
100.57800,8.38147,817.46439,-0.06571,29.44635,39.80738
100.77801,8.39809,817.73838,-0.06566,29.51283,39.82072
100.97801,8.41489,817.71631,-0.06567,29.58004,39.81964
101.17800,8.43151,817.13162,-0.06568,29.64652,39.79117
101.37801,8.44814,817.14597,-0.06567,29.71301,39.79187
101.57800,8.46488,816.87802,-0.06569,29.77997,39.77882
101.77801,8.48156,816.35471,-0.06567,29.84670,39.75334
101.97801,8.49806,816.87374,-0.06567,29.91270,39.77861
102.17800,8.51480,816.06638,-0.06567,29.97967,39.73930
102.37801,8.53154,816.36002,-0.06566,30.04664,39.75360
102.57800,8.54816,815.64821,-0.06570,30.11312,39.71894
102.77801,8.56472,815.62847,-0.06563,30.17937,39.71798
102.97801,8.58159,815.61981,-0.06567,30.24681,39.71755
103.17800,8.59821,815.62931,-0.06566,30.31330,39.71801
103.37801,8.61489,815.03708,-0.06564,30.38002,39.68917
103.57800,8.63157,814.99703,-0.06572,30.44674,39.68723
103.77801,8.64813,814.79941,-0.06563,30.51299,39.67760
103.97801,8.66481,814.72229,-0.06569,30.57972,39.67385
104.17800,8.68143,813.85802,-0.06569,30.64620,39.63176
104.37801,8.69818,814.27135,-0.06564,30.71317,39.65189
104.57800,8.71474,814.64155,-0.06569,30.77941,39.66991
104.77801,8.73142,813.59521,-0.06568,30.84614,39.61896
104.97801,8.74822,813.37634,-0.06562,30.91334,39.60830
105.17800,8.76484,813.18142,-0.06568,30.97983,39.59881
105.37801,8.78152,812.89085,-0.06564,31.04655,39.58466
105.57800,8.79826,812.60102,-0.06568,31.11352,39.57055
105.77801,8.81482,812.56358,-0.06567,31.17977,39.56873
105.97801,8.83145,811.85410,-0.06567,31.24625,39.53418
106.17800,8.84813,811.78183,-0.06570,31.31298,39.53066
106.37801,8.86487,812.34425,-0.06563,31.37994,39.55804
106.57800,8.88149,812.12418,-0.06569,31.44643,39.54733
106.77801,8.89805,811.20813,-0.06570,31.51267,39.50272
106.97801,8.91479,811.81312,-0.06565,31.57963,39.53218
107.17800,8.93141,810.97530,-0.06567,31.64613,39.49138
107.37801,8.94815,810.69395,-0.06566,31.71309,39.47768
107.57800,8.96496,810.67123,-0.06570,31.78029,39.47658
107.77801,8.98146,810.83318,-0.06568,31.84630,39.48446
107.97801,8.99808,809.82000,-0.06570,31.91279,39.43512
108.17800,9.01488,810.28668,-0.06568,31.97999,39.45785
108.37801,9.03150,809.76691,-0.06563,32.04648,39.43254
108.57800,9.04818,808.92369,-0.06564,32.11320,39.39148
108.77801,9.06486,809.00621,-0.06566,32.17993,39.39550
108.97801,9.08155,808.84770,-0.06564,32.24665,39.38778
109.17800,9.09805,807.98408,-0.06565,32.31266,39.34572
109.37801,9.11485,807.61742,-0.06561,32.37986,39.32787
109.57800,9.13165,807.48573,-0.06565,32.44706,39.32145
109.77801,9.14815,807.60932,-0.06563,32.51307,39.32747
109.97801,9.16471,807.12838,-0.06566,32.57932,39.30405
110.17801,9.18157,806.62249,-0.06569,32.64676,39.27942
110.37801,9.19819,806.89667,-0.06561,32.71325,39.29277
110.57800,9.21482,806.07962,-0.06570,32.77973,39.25298
110.77801,9.23156,805.90881,-0.06567,32.84670,39.24466
110.97801,9.24818,805.87249,-0.06567,32.91318,39.24290
111.17801,9.26474,805.45302,-0.06568,32.97943,39.22247
111.37801,9.28148,804.95188,-0.06563,33.04639,39.19807
111.57800,9.29822,805.01875,-0.06570,33.11336,39.20132
111.77801,9.31478,804.74587,-0.06566,33.17961,39.18803
111.97801,9.33153,804.22126,-0.06569,33.24657,39.16249
112.17801,9.34821,803.26702,-0.06569,33.31329,39.11602
112.37801,9.36477,803.82545,-0.06566,33.37954,39.14321
112.57800,9.38151,803.01259,-0.06571,33.44651,39.10363
112.77801,9.39819,803.16868,-0.06564,33.51323,39.11123
112.97801,9.41493,802.51917,-0.06570,33.58020,39.07960
113.17801,9.43149,801.54464,-0.06574,33.64644,39.03215
113.37801,9.44817,802.10399,-0.06561,33.71316,39.05938
113.57800,9.46486,801.26403,-0.06571,33.77989,39.01848
113.77801,9.48148,800.85704,-0.06565,33.84638,38.99866
113.97801,9.49822,800.08311,-0.06564,33.91334,38.96098
114.17801,9.51484,800.54654,-0.06569,33.97983,38.98354
114.37801,9.53140,799.89517,-0.06565,34.04607,38.95182
114.57800,9.54814,799.95533,-0.06566,34.11304,38.95475
114.77801,9.56488,799.57228,-0.06568,34.18000,38.93610
114.97801,9.58156,798.83691,-0.06566,34.24673,38.90029
115.17801,9.59813,798.50471,-0.06570,34.31298,38.88411
115.37801,9.61481,798.47686,-0.06568,34.37970,38.88276
115.57800,9.63155,797.89869,-0.06563,34.44666,38.85460
115.77801,9.64811,797.85129,-0.06570,34.51291,38.85229
115.97801,9.66485,796.66413,-0.06567,34.57987,38.79448
116.17801,9.68159,796.36527,-0.06563,34.64684,38.77993
116.37801,9.69809,796.31787,-0.06573,34.71285,38.77762
116.57800,9.71478,795.77183,-0.06563,34.77957,38.75103
116.77801,9.73158,795.00340,-0.06568,34.84678,38.71361
116.97801,9.74820,794.91781,-0.06567,34.91326,38.70945
117.17801,9.76482,794.49341,-0.06563,34.97975,38.68878
117.37801,9.78150,793.89438,-0.06569,35.04647,38.65961
117.57800,9.79812,793.79622,-0.06562,35.11296,38.65483
117.77801,9.81474,793.44781,-0.06566,35.17945,38.63786
117.97801,9.83148,792.39998,-0.06567,35.24641,38.58684
118.17801,9.84817,791.29962,-0.06563,35.31313,38.53325
118.37801,9.86485,791.99793,-0.06569,35.37986,38.56726
118.57800,9.88141,791.20919,-0.06563,35.44610,38.52885
118.77801,9.89815,790.35256,-0.06565,35.51307,38.48714
118.97801,9.91489,789.80075,-0.06568,35.58003,38.46026
119.17801,9.93157,789.87489,-0.06570,35.64676,38.46387
119.37801,9.94819,788.78803,-0.06565,35.71324,38.41095
119.57800,9.96482,787.93187,-0.06567,35.77973,38.36926
119.77801,9.98150,787.79506,-0.06569,35.84646,38.36259
119.97801,9.99812,787.40409,-0.06567,35.91294,38.34356
120.17801,10.01486,786.15565,-0.06570,35.97990,38.28276
120.37801,10.03142,786.49577,-0.06570,36.04615,38.29932
120.57800,10.04810,785.18121,-0.06567,36.11288,38.23531
120.77801,10.06484,785.01403,-0.06570,36.17984,38.22717
120.97801,10.08146,784.53692,-0.06564,36.24633,38.20393
121.17801,10.09815,783.72136,-0.06567,36.31305,38.16422
121.37801,10.11489,782.83707,-0.06569,36.38001,38.12116
121.57800,10.13151,782.25406,-0.06564,36.44650,38.09277
121.77801,10.14819,781.39827,-0.06571,36.51323,38.05109
121.97801,10.16481,780.87132,-0.06564,36.57971,38.02544
122.17801,10.18155,780.11020,-0.06568,36.64668,37.98837
122.37801,10.19811,779.40850,-0.06567,36.71292,37.95420
122.57800,10.21479,778.84789,-0.06565,36.77965,37.92690
122.77801,10.23154,778.24923,-0.06570,36.84661,37.89775
122.97801,10.24810,777.75032,-0.06562,36.91286,37.87346
123.17801,10.26478,776.15413,-0.06573,36.97958,37.79573
123.37801,10.28158,775.52069,-0.06565,37.04679,37.76488
123.57800,10.29820,775.07924,-0.06563,37.11328,37.74338
123.77801,10.31476,774.80325,-0.06578,37.17952,37.72994
123.97801,10.33150,773.91476,-0.06554,37.24649,37.68668
124.17801,10.34819,772.80360,-0.06576,37.31321,37.63257
124.37801,10.36487,772.08919,-0.06567,37.37994,37.59778
124.57800,10.38155,771.21421,-0.06558,37.44666,37.55517
124.77801,10.39823,770.64829,-0.06579,37.51338,37.52761
124.97801,10.41473,769.63627,-0.06557,37.57939,37.47833
125.17801,10.43147,768.76264,-0.06573,37.64636,37.43579
125.37801,10.44815,767.48263,-0.06573,37.71308,37.37346
125.57800,10.46477,767.28915,-0.06556,37.77957,37.36404
125.77801,10.48152,766.00593,-0.06580,37.84653,37.30155
125.97801,10.49814,765.28005,-0.06550,37.91302,37.26620
126.17801,10.51482,763.85126,-0.06574,37.97975,37.19662
126.37801,10.53150,762.74662,-0.06563,38.04646,37.14283
126.57800,10.54812,761.81763,-0.06555,38.11296,37.09760
126.77801,10.56486,760.56956,-0.06582,38.17992,37.03682
126.97801,10.58154,758.78333,-0.06552,38.24664,36.94983
127.17801,10.59811,757.36139,-0.06573,38.31289,36.88059
127.37801,10.61485,755.21474,-0.06568,38.37985,36.77606
127.57800,10.63147,753.26459,-0.06563,38.44634,36.68110
127.77801,10.64815,751.20796,-0.06576,38.51307,36.58094
127.97801,10.66483,747.13291,-0.06557,38.57979,36.38250
128.17801,10.68151,740.64392,-0.06572,38.64652,36.06651
128.35201,10.69604,5.50416,-0.06558,38.70463,0.26803